<?xml version='1.0' encoding='utf-8'?>
<robot name="partnet_dc4affd586bafbc8d45f502ecff9e44f">
	<link name="base" />
	<link name="link_0">
		<visual name="cabinet_door_surface-9">
			<origin xyz="-0.49729754559664285 -0.8376370072364807 -0.12554564080183467" />
			<geometry>
				<mesh filename="/home/blake/kitchen-worlds/assets/models/CabinetUpper/49182/textured_objs/original-9.obj" />/&gt;
			</geometry>
		</visual>
		<visual name="cabinet_door_surface-9">
			<origin xyz="-0.49729754559664285 -0.8376370072364807 -0.12554564080183467" />
			<geometry>
				<mesh filename="/home/blake/kitchen-worlds/assets/models/CabinetUpper/49182/textured_objs/original-7.obj" />/&gt;
			</geometry>
		</visual>
		<visual name="cabinet_door_surface-9">
			<origin xyz="-0.49729754559664285 -0.8376370072364807 -0.12554564080183467" />
			<geometry>
				<mesh filename="/home/blake/kitchen-worlds/assets/models/CabinetUpper/49182/textured_objs/original-6.obj" />/&gt;
			</geometry>
		</visual>
		<visual name="cabinet_door_surface-9">
			<origin xyz="-0.49729754559664285 -0.8376370072364807 -0.12554564080183467" />
			<geometry>
				<mesh filename="/home/blake/kitchen-worlds/assets/models/CabinetUpper/49182/textured_objs/original-8.obj" />/&gt;
			</geometry>
		</visual>
		<visual name="cabinet_door_surface-9">
			<origin xyz="-0.49729754559664285 -0.8376370072364807 -0.12554564080183467" />
			<geometry>
				<mesh filename="/home/blake/kitchen-worlds/assets/models/CabinetUpper/49182/textured_objs/original-12.obj" />/&gt;
			</geometry>
		</visual>
		<visual name="cabinet_door_surface-9">
			<origin xyz="-0.49729754559664285 -0.8376370072364807 -0.12554564080183467" />
			<geometry>
				<mesh filename="/home/blake/kitchen-worlds/assets/models/CabinetUpper/49182/textured_objs/original-13.obj" />/&gt;
			</geometry>
		</visual>
		<visual name="cabinet_door_surface-9">
			<origin xyz="-0.49729754559664285 -0.8376370072364807 -0.12554564080183467" />
			<geometry>
				<mesh filename="/home/blake/kitchen-worlds/assets/models/CabinetUpper/49182/textured_objs/original-14.obj" />/&gt;
			</geometry>
		</visual>
		<visual name="cabinet_door_surface-9">
			<origin xyz="-0.49729754559664285 -0.8376370072364807 -0.12554564080183467" />
			<geometry>
				<mesh filename="/home/blake/kitchen-worlds/assets/models/CabinetUpper/49182/textured_objs/original-11.obj" />/&gt;
			</geometry>
		</visual>
		<visual name="glass-10">
			<origin xyz="-0.49729754559664285 -0.8376370072364807 -0.12554564080183467" />
			<geometry>
				<mesh filename="/home/blake/kitchen-worlds/assets/models/CabinetUpper/49182/textured_objs/original-10.obj" />/&gt;
			</geometry>
		</visual>
		<collision>
			<origin xyz="-0.49729754559664285 -0.8376370072364807 -0.12554564080183467" />
			<geometry>
				<mesh filename="/home/blake/kitchen-worlds/assets/models/CabinetUpper/49182/textured_objs/original-9.obj" />/&gt;
			</geometry>
		</collision>
		<collision>
			<origin xyz="-0.49729754559664285 -0.8376370072364807 -0.12554564080183467" />
			<geometry>
				<mesh filename="/home/blake/kitchen-worlds/assets/models/CabinetUpper/49182/textured_objs/original-7.obj" />/&gt;
			</geometry>
		</collision>
		<collision>
			<origin xyz="-0.49729754559664285 -0.8376370072364807 -0.12554564080183467" />
			<geometry>
				<mesh filename="/home/blake/kitchen-worlds/assets/models/CabinetUpper/49182/textured_objs/original-6.obj" />/&gt;
			</geometry>
		</collision>
		<collision>
			<origin xyz="-0.49729754559664285 -0.8376370072364807 -0.12554564080183467" />
			<geometry>
				<mesh filename="/home/blake/kitchen-worlds/assets/models/CabinetUpper/49182/textured_objs/original-8.obj" />/&gt;
			</geometry>
		</collision>
		<collision>
			<origin xyz="-0.49729754559664285 -0.8376370072364807 -0.12554564080183467" />
			<geometry>
				<mesh filename="/home/blake/kitchen-worlds/assets/models/CabinetUpper/49182/textured_objs/original-12.obj" />/&gt;
			</geometry>
		</collision>
		<collision>
			<origin xyz="-0.49729754559664285 -0.8376370072364807 -0.12554564080183467" />
			<geometry>
				<mesh filename="/home/blake/kitchen-worlds/assets/models/CabinetUpper/49182/textured_objs/original-13.obj" />/&gt;
			</geometry>
		</collision>
		<collision>
			<origin xyz="-0.49729754559664285 -0.8376370072364807 -0.12554564080183467" />
			<geometry>
				<mesh filename="/home/blake/kitchen-worlds/assets/models/CabinetUpper/49182/textured_objs/original-14.obj" />/&gt;
			</geometry>
		</collision>
		<collision>
			<origin xyz="-0.49729754559664285 -0.8376370072364807 -0.12554564080183467" />
			<geometry>
				<mesh filename="/home/blake/kitchen-worlds/assets/models/CabinetUpper/49182/textured_objs/original-11.obj" />/&gt;
			</geometry>
		</collision>
		<collision>
			<origin xyz="-0.49729754559664285 -0.8376370072364807 -0.12554564080183467" />
			<geometry>
				<mesh filename="/home/blake/kitchen-worlds/assets/models/CabinetUpper/49182/textured_objs/original-10.obj" />/&gt;
			</geometry>
		</collision>
	</link>
	<joint name="joint_0" type="revolute">
		<origin xyz="0.49729754559664285 0.8376370072364807 0.12554564080183467" />
		<axis xyz="0 0.9999999999999999 0" />
		<child link="link_0" />
		<parent link="link_2" />
		<limit lower="0.0" upper="3.141592653589793" effort="10.0" velocity="1.0" />
	</joint>
	<link name="link_1">
		<visual name="cabinet_door_surface-7">
			<origin xyz="0.4875088141617112 -0.8376370072364807 -0.11599207339659609" />
			<geometry>
				<mesh filename="/home/blake/kitchen-worlds/assets/models/CabinetUpper/49182/textured_objs/original-16.obj" />/&gt;
			</geometry>
		</visual>
		<visual name="cabinet_door_surface-7">
			<origin xyz="0.4875088141617112 -0.8376370072364807 -0.11599207339659609" />
			<geometry>
				<mesh filename="/home/blake/kitchen-worlds/assets/models/CabinetUpper/49182/textured_objs/original-17.obj" />/&gt;
			</geometry>
		</visual>
		<visual name="cabinet_door_surface-7">
			<origin xyz="0.4875088141617112 -0.8376370072364807 -0.11599207339659609" />
			<geometry>
				<mesh filename="/home/blake/kitchen-worlds/assets/models/CabinetUpper/49182/textured_objs/original-22.obj" />/&gt;
			</geometry>
		</visual>
		<visual name="cabinet_door_surface-7">
			<origin xyz="0.4875088141617112 -0.8376370072364807 -0.11599207339659609" />
			<geometry>
				<mesh filename="/home/blake/kitchen-worlds/assets/models/CabinetUpper/49182/textured_objs/original-24.obj" />/&gt;
			</geometry>
		</visual>
		<visual name="cabinet_door_surface-7">
			<origin xyz="0.4875088141617112 -0.8376370072364807 -0.11599207339659609" />
			<geometry>
				<mesh filename="/home/blake/kitchen-worlds/assets/models/CabinetUpper/49182/textured_objs/original-18.obj" />/&gt;
			</geometry>
		</visual>
		<visual name="cabinet_door_surface-7">
			<origin xyz="0.4875088141617112 -0.8376370072364807 -0.11599207339659609" />
			<geometry>
				<mesh filename="/home/blake/kitchen-worlds/assets/models/CabinetUpper/49182/textured_objs/original-21.obj" />/&gt;
			</geometry>
		</visual>
		<visual name="cabinet_door_surface-7">
			<origin xyz="0.4875088141617112 -0.8376370072364807 -0.11599207339659609" />
			<geometry>
				<mesh filename="/home/blake/kitchen-worlds/assets/models/CabinetUpper/49182/textured_objs/original-23.obj" />/&gt;
			</geometry>
		</visual>
		<visual name="cabinet_door_surface-7">
			<origin xyz="0.4875088141617112 -0.8376370072364807 -0.11599207339659609" />
			<geometry>
				<mesh filename="/home/blake/kitchen-worlds/assets/models/CabinetUpper/49182/textured_objs/original-19.obj" />/&gt;
			</geometry>
		</visual>
		<visual name="glass-8">
			<origin xyz="0.4875088141617112 -0.8376370072364807 -0.11599207339659609" />
			<geometry>
				<mesh filename="/home/blake/kitchen-worlds/assets/models/CabinetUpper/49182/textured_objs/original-20.obj" />/&gt;
			</geometry>
		</visual>
		<collision>
			<origin xyz="0.4875088141617112 -0.8376370072364807 -0.11599207339659609" />
			<geometry>
				<mesh filename="/home/blake/kitchen-worlds/assets/models/CabinetUpper/49182/textured_objs/original-16.obj" />/&gt;
			</geometry>
		</collision>
		<collision>
			<origin xyz="0.4875088141617112 -0.8376370072364807 -0.11599207339659609" />
			<geometry>
				<mesh filename="/home/blake/kitchen-worlds/assets/models/CabinetUpper/49182/textured_objs/original-17.obj" />/&gt;
			</geometry>
		</collision>
		<collision>
			<origin xyz="0.4875088141617112 -0.8376370072364807 -0.11599207339659609" />
			<geometry>
				<mesh filename="/home/blake/kitchen-worlds/assets/models/CabinetUpper/49182/textured_objs/original-22.obj" />/&gt;
			</geometry>
		</collision>
		<collision>
			<origin xyz="0.4875088141617112 -0.8376370072364807 -0.11599207339659609" />
			<geometry>
				<mesh filename="/home/blake/kitchen-worlds/assets/models/CabinetUpper/49182/textured_objs/original-24.obj" />/&gt;
			</geometry>
		</collision>
		<collision>
			<origin xyz="0.4875088141617112 -0.8376370072364807 -0.11599207339659609" />
			<geometry>
				<mesh filename="/home/blake/kitchen-worlds/assets/models/CabinetUpper/49182/textured_objs/original-18.obj" />/&gt;
			</geometry>
		</collision>
		<collision>
			<origin xyz="0.4875088141617112 -0.8376370072364807 -0.11599207339659609" />
			<geometry>
				<mesh filename="/home/blake/kitchen-worlds/assets/models/CabinetUpper/49182/textured_objs/original-21.obj" />/&gt;
			</geometry>
		</collision>
		<collision>
			<origin xyz="0.4875088141617112 -0.8376370072364807 -0.11599207339659609" />
			<geometry>
				<mesh filename="/home/blake/kitchen-worlds/assets/models/CabinetUpper/49182/textured_objs/original-23.obj" />/&gt;
			</geometry>
		</collision>
		<collision>
			<origin xyz="0.4875088141617112 -0.8376370072364807 -0.11599207339659609" />
			<geometry>
				<mesh filename="/home/blake/kitchen-worlds/assets/models/CabinetUpper/49182/textured_objs/original-19.obj" />/&gt;
			</geometry>
		</collision>
		<collision>
			<origin xyz="0.4875088141617112 -0.8376370072364807 -0.11599207339659609" />
			<geometry>
				<mesh filename="/home/blake/kitchen-worlds/assets/models/CabinetUpper/49182/textured_objs/original-20.obj" />/&gt;
			</geometry>
		</collision>
	</link>
	<joint name="joint_1" type="revolute">
		<origin xyz="-0.4875088141617112 0.8376370072364807 0.11599207339659609" />
		<axis xyz="0 -0.9999999999999999 0" />
		<child link="link_1" />
		<parent link="link_2" />
		<limit lower="-0.0" upper="3.141592653589793" effort="10.0" velocity="1.0" />
	</joint>
	<link name="link_2">
		<visual name="shelf-3">
			<origin xyz="0 0 0" />
			<geometry>
				<mesh filename="/home/blake/kitchen-worlds/assets/models/CabinetUpper/49182/textured_objs/original-31.obj" />/&gt;
			</geometry>
		</visual>
		<visual name="shelf-4">
			<origin xyz="0 0 0" />
			<geometry>
				<mesh filename="/home/blake/kitchen-worlds/assets/models/CabinetUpper/49182/textured_objs/original-32.obj" />/&gt;
			</geometry>
		</visual>
		<visual name="shelf-12">
			<origin xyz="0 0 0" />
			<geometry>
				<mesh filename="/home/blake/kitchen-worlds/assets/models/CabinetUpper/49182/textured_objs/original-30.obj" />/&gt;
			</geometry>
		</visual>
		<visual name="vertical_side_panel-13">
			<origin xyz="0 0 0" />
			<geometry>
				<mesh filename="/home/blake/kitchen-worlds/assets/models/CabinetUpper/49182/textured_objs/original-3.obj" />/&gt;
			</geometry>
		</visual>
		<visual name="vertical_side_panel-14">
			<origin xyz="0 0 0" />
			<geometry>
				<mesh filename="/home/blake/kitchen-worlds/assets/models/CabinetUpper/49182/textured_objs/original-4.obj" />/&gt;
			</geometry>
		</visual>
		<visual name="back_panel-15">
			<origin xyz="0 0 0" />
			<geometry>
				<mesh filename="/home/blake/kitchen-worlds/assets/models/CabinetUpper/49182/textured_objs/original-25.obj" />/&gt;
			</geometry>
		</visual>
		<visual name="back_panel-15">
			<origin xyz="0 0 0" />
			<geometry>
				<mesh filename="/home/blake/kitchen-worlds/assets/models/CabinetUpper/49182/textured_objs/original-28.obj" />/&gt;
			</geometry>
		</visual>
		<visual name="back_panel-15">
			<origin xyz="0 0 0" />
			<geometry>
				<mesh filename="/home/blake/kitchen-worlds/assets/models/CabinetUpper/49182/textured_objs/original-26.obj" />/&gt;
			</geometry>
		</visual>
		<visual name="back_panel-15">
			<origin xyz="0 0 0" />
			<geometry>
				<mesh filename="/home/blake/kitchen-worlds/assets/models/CabinetUpper/49182/textured_objs/original-29.obj" />/&gt;
			</geometry>
		</visual>
		<visual name="back_panel-15">
			<origin xyz="0 0 0" />
			<geometry>
				<mesh filename="/home/blake/kitchen-worlds/assets/models/CabinetUpper/49182/textured_objs/original-27.obj" />/&gt;
			</geometry>
		</visual>
		<visual name="bottom_panel-16">
			<origin xyz="0 0 0" />
			<geometry>
				<mesh filename="/home/blake/kitchen-worlds/assets/models/CabinetUpper/49182/textured_objs/original-1.obj" />/&gt;
			</geometry>
		</visual>
		<visual name="top_panel-17">
			<origin xyz="0 0 0" />
			<geometry>
				<mesh filename="/home/blake/kitchen-worlds/assets/models/CabinetUpper/49182/textured_objs/original-2.obj" />/&gt;
			</geometry>
		</visual>
		<collision>
			<origin xyz="0 0 0" />
			<geometry>
				<mesh filename="/home/blake/kitchen-worlds/assets/models/CabinetUpper/49182/textured_objs/original-31.obj" />/&gt;
			</geometry>
		</collision>
		<collision>
			<origin xyz="0 0 0" />
			<geometry>
				<mesh filename="/home/blake/kitchen-worlds/assets/models/CabinetUpper/49182/textured_objs/original-32.obj" />/&gt;
			</geometry>
		</collision>
		<collision>
			<origin xyz="0 0 0" />
			<geometry>
				<mesh filename="/home/blake/kitchen-worlds/assets/models/CabinetUpper/49182/textured_objs/original-30.obj" />/&gt;
			</geometry>
		</collision>
		<collision>
			<origin xyz="0 0 0" />
			<geometry>
				<mesh filename="/home/blake/kitchen-worlds/assets/models/CabinetUpper/49182/textured_objs/original-3.obj" />/&gt;
			</geometry>
		</collision>
		<collision>
			<origin xyz="0 0 0" />
			<geometry>
				<mesh filename="/home/blake/kitchen-worlds/assets/models/CabinetUpper/49182/textured_objs/original-4.obj" />/&gt;
			</geometry>
		</collision>
		<collision>
			<origin xyz="0 0 0" />
			<geometry>
				<mesh filename="/home/blake/kitchen-worlds/assets/models/CabinetUpper/49182/textured_objs/original-25.obj" />/&gt;
			</geometry>
		</collision>
		<collision>
			<origin xyz="0 0 0" />
			<geometry>
				<mesh filename="/home/blake/kitchen-worlds/assets/models/CabinetUpper/49182/textured_objs/original-28.obj" />/&gt;
			</geometry>
		</collision>
		<collision>
			<origin xyz="0 0 0" />
			<geometry>
				<mesh filename="/home/blake/kitchen-worlds/assets/models/CabinetUpper/49182/textured_objs/original-26.obj" />/&gt;
			</geometry>
		</collision>
		<collision>
			<origin xyz="0 0 0" />
			<geometry>
				<mesh filename="/home/blake/kitchen-worlds/assets/models/CabinetUpper/49182/textured_objs/original-29.obj" />/&gt;
			</geometry>
		</collision>
		<collision>
			<origin xyz="0 0 0" />
			<geometry>
				<mesh filename="/home/blake/kitchen-worlds/assets/models/CabinetUpper/49182/textured_objs/original-27.obj" />/&gt;
			</geometry>
		</collision>
		<collision>
			<origin xyz="0 0 0" />
			<geometry>
				<mesh filename="/home/blake/kitchen-worlds/assets/models/CabinetUpper/49182/textured_objs/original-1.obj" />/&gt;
			</geometry>
		</collision>
		<collision>
			<origin xyz="0 0 0" />
			<geometry>
				<mesh filename="/home/blake/kitchen-worlds/assets/models/CabinetUpper/49182/textured_objs/original-2.obj" />/&gt;
			</geometry>
		</collision>
	</link>
	<joint name="joint_2" type="fixed">
		<origin rpy="1.570796326794897 0 -1.570796326794897" xyz="0 0 0" />
		<child link="link_2" />
		<parent link="base" />
	</joint>
</robot>