<?xml version='1.0' encoding='utf-8'?>
<robot name="partnet_8c2491e5245804d1ffc6e457221b9271">
	<link name="base" />
	<link name="link_0">
		<visual name="door-1">
			<origin xyz="0.6382359999999996 0.442321324292263 -0.41942801523467216" />
			<geometry>
				<mesh filename="/home/blake/kitchen-worlds/assets/models/OvenCounter/101917/textured_objs/original-78.obj" />/&gt;
			</geometry>
		</visual>
		<visual name="door-1">
			<origin xyz="0.6382359999999996 0.442321324292263 -0.41942801523467216" />
			<geometry>
				<mesh filename="/home/blake/kitchen-worlds/assets/models/OvenCounter/101917/textured_objs/original-4.obj" />/&gt;
			</geometry>
		</visual>
		<visual name="door-1">
			<origin xyz="0.6382359999999996 0.442321324292263 -0.41942801523467216" />
			<geometry>
				<mesh filename="/home/blake/kitchen-worlds/assets/models/OvenCounter/101917/textured_objs/original-79.obj" />/&gt;
			</geometry>
		</visual>
		<visual name="door-1">
			<origin xyz="0.6382359999999996 0.442321324292263 -0.41942801523467216" />
			<geometry>
				<mesh filename="/home/blake/kitchen-worlds/assets/models/OvenCounter/101917/textured_objs/original-91.obj" />/&gt;
			</geometry>
		</visual>
		<collision>
			<origin xyz="0.6382359999999996 0.442321324292263 -0.41942801523467216" />
			<geometry>
				<mesh filename="/home/blake/kitchen-worlds/assets/models/OvenCounter/101917/textured_objs/original-78.obj" />/&gt;
			</geometry>
		</collision>
		<collision>
			<origin xyz="0.6382359999999996 0.442321324292263 -0.41942801523467216" />
			<geometry>
				<mesh filename="/home/blake/kitchen-worlds/assets/models/OvenCounter/101917/textured_objs/original-4.obj" />/&gt;
			</geometry>
		</collision>
		<collision>
			<origin xyz="0.6382359999999996 0.442321324292263 -0.41942801523467216" />
			<geometry>
				<mesh filename="/home/blake/kitchen-worlds/assets/models/OvenCounter/101917/textured_objs/original-79.obj" />/&gt;
			</geometry>
		</collision>
		<collision>
			<origin xyz="0.6382359999999996 0.442321324292263 -0.41942801523467216" />
			<geometry>
				<mesh filename="/home/blake/kitchen-worlds/assets/models/OvenCounter/101917/textured_objs/original-91.obj" />/&gt;
			</geometry>
		</collision>
	</link>
	<joint name="joint_0" type="revolute">
		<origin xyz="-0.6382359999999996 -0.442321324292263 0.41942801523467216" />
		<axis xyz="1 0 0" />
		<child link="link_0" />
		<parent link="link_8" />
		<limit lower="0.0" upper="1.5707963267948966" effort="10.0" velocity="1.0" />
	</joint>
	<link name="link_1">
		<visual name="knob-2">
			<origin xyz="-0.5279359630874578 -0.4083835309958324 0.0004391043249808836" />
			<geometry>
				<mesh filename="/home/blake/kitchen-worlds/assets/models/OvenCounter/101917/textured_objs/original-112.obj" />/&gt;
			</geometry>
		</visual>
		<visual name="knob-2">
			<origin xyz="-0.5279359630874578 -0.4083835309958324 0.0004391043249808836" />
			<geometry>
				<mesh filename="/home/blake/kitchen-worlds/assets/models/OvenCounter/101917/textured_objs/original-111.obj" />/&gt;
			</geometry>
		</visual>
		<collision>
			<origin xyz="-0.5279359630874578 -0.4083835309958324 0.0004391043249808836" />
			<geometry>
				<mesh filename="/home/blake/kitchen-worlds/assets/models/OvenCounter/101917/textured_objs/original-112.obj" />/&gt;
			</geometry>
		</collision>
		<collision>
			<origin xyz="-0.5279359630874578 -0.4083835309958324 0.0004391043249808836" />
			<geometry>
				<mesh filename="/home/blake/kitchen-worlds/assets/models/OvenCounter/101917/textured_objs/original-111.obj" />/&gt;
			</geometry>
		</collision>
	</link>
	<joint name="joint_1" type="continuous">
		<origin xyz="0.5279359630874578 0.4083835309958324 -0.0004391043249808836" />
		<axis xyz="-9.926254200770128e-06 0.0010880567762528118 0.9999994080167854" />
		<child link="link_1" />
		<parent link="link_8" />
	</joint>
	<link name="link_2">
		<visual name="knob-3">
			<origin xyz="-0.3936376441099773 -0.4081314991254458 0.0006633374896435461" />
			<geometry>
				<mesh filename="/home/blake/kitchen-worlds/assets/models/OvenCounter/101917/textured_objs/original-102.obj" />/&gt;
			</geometry>
		</visual>
		<visual name="knob-3">
			<origin xyz="-0.3936376441099773 -0.4081314991254458 0.0006633374896435461" />
			<geometry>
				<mesh filename="/home/blake/kitchen-worlds/assets/models/OvenCounter/101917/textured_objs/original-103.obj" />/&gt;
			</geometry>
		</visual>
		<collision>
			<origin xyz="-0.3936376441099773 -0.4081314991254458 0.0006633374896435461" />
			<geometry>
				<mesh filename="/home/blake/kitchen-worlds/assets/models/OvenCounter/101917/textured_objs/original-102.obj" />/&gt;
			</geometry>
		</collision>
		<collision>
			<origin xyz="-0.3936376441099773 -0.4081314991254458 0.0006633374896435461" />
			<geometry>
				<mesh filename="/home/blake/kitchen-worlds/assets/models/OvenCounter/101917/textured_objs/original-103.obj" />/&gt;
			</geometry>
		</collision>
	</link>
	<joint name="joint_2" type="continuous">
		<origin xyz="0.3936376441099773 0.4081314991254458 -0.0006633374896435461" />
		<axis xyz="-1.4959745792036126e-05 0.0016397295493396943 0.9999986555307018" />
		<child link="link_2" />
		<parent link="link_8" />
	</joint>
	<link name="link_3">
		<visual name="knob-4">
			<origin xyz="-0.25789281744188264 -0.4082611783237433 0.0005503261980142317" />
			<geometry>
				<mesh filename="/home/blake/kitchen-worlds/assets/models/OvenCounter/101917/textured_objs/original-105.obj" />/&gt;
			</geometry>
		</visual>
		<visual name="knob-4">
			<origin xyz="-0.25789281744188264 -0.4082611783237433 0.0005503261980142317" />
			<geometry>
				<mesh filename="/home/blake/kitchen-worlds/assets/models/OvenCounter/101917/textured_objs/original-106.obj" />/&gt;
			</geometry>
		</visual>
		<collision>
			<origin xyz="-0.25789281744188264 -0.4082611783237433 0.0005503261980142317" />
			<geometry>
				<mesh filename="/home/blake/kitchen-worlds/assets/models/OvenCounter/101917/textured_objs/original-105.obj" />/&gt;
			</geometry>
		</collision>
		<collision>
			<origin xyz="-0.25789281744188264 -0.4082611783237433 0.0005503261980142317" />
			<geometry>
				<mesh filename="/home/blake/kitchen-worlds/assets/models/OvenCounter/101917/textured_objs/original-106.obj" />/&gt;
			</geometry>
		</collision>
	</link>
	<joint name="joint_3" type="continuous">
		<origin xyz="0.25789281744188264 0.4082611783237433 -0.0005503261980142317" />
		<axis xyz="-1.2354121449358792e-05 0.0013557785572692015 0.9999990808555173" />
		<child link="link_3" />
		<parent link="link_8" />
	</joint>
	<link name="link_4">
		<visual name="knob-5">
			<origin xyz="-0.1221521634412283 -0.4079608551447811 0.000818675267315887" />
			<geometry>
				<mesh filename="/home/blake/kitchen-worlds/assets/models/OvenCounter/101917/textured_objs/original-108.obj" />/&gt;
			</geometry>
		</visual>
		<visual name="knob-5">
			<origin xyz="-0.1221521634412283 -0.4079608551447811 0.000818675267315887" />
			<geometry>
				<mesh filename="/home/blake/kitchen-worlds/assets/models/OvenCounter/101917/textured_objs/original-109.obj" />/&gt;
			</geometry>
		</visual>
		<collision>
			<origin xyz="-0.1221521634412283 -0.4079608551447811 0.000818675267315887" />
			<geometry>
				<mesh filename="/home/blake/kitchen-worlds/assets/models/OvenCounter/101917/textured_objs/original-108.obj" />/&gt;
			</geometry>
		</collision>
		<collision>
			<origin xyz="-0.1221521634412283 -0.4079608551447811 0.000818675267315887" />
			<geometry>
				<mesh filename="/home/blake/kitchen-worlds/assets/models/OvenCounter/101917/textured_objs/original-109.obj" />/&gt;
			</geometry>
		</collision>
	</link>
	<joint name="joint_4" type="continuous">
		<origin xyz="0.1221521634412283 0.4079608551447811 -0.000818675267315887" />
		<axis xyz="-1.8376085426153664e-05 0.00201224777374971 0.9999979752585585" />
		<child link="link_4" />
		<parent link="link_8" />
	</joint>
	<link name="link_5">
		<visual name="knob-6">
			<origin xyz="0.2520115152106967 -0.40796059379703353 0.0008256871908699473" />
			<geometry>
				<mesh filename="/home/blake/kitchen-worlds/assets/models/OvenCounter/101917/textured_objs/original-100.obj" />/&gt;
			</geometry>
		</visual>
		<visual name="knob-6">
			<origin xyz="0.2520115152106967 -0.40796059379703353 0.0008256871908699473" />
			<geometry>
				<mesh filename="/home/blake/kitchen-worlds/assets/models/OvenCounter/101917/textured_objs/original-99.obj" />/&gt;
			</geometry>
		</visual>
		<collision>
			<origin xyz="0.2520115152106967 -0.40796059379703353 0.0008256871908699473" />
			<geometry>
				<mesh filename="/home/blake/kitchen-worlds/assets/models/OvenCounter/101917/textured_objs/original-100.obj" />/&gt;
			</geometry>
		</collision>
		<collision>
			<origin xyz="0.2520115152106967 -0.40796059379703353 0.0008256871908699473" />
			<geometry>
				<mesh filename="/home/blake/kitchen-worlds/assets/models/OvenCounter/101917/textured_objs/original-99.obj" />/&gt;
			</geometry>
		</collision>
	</link>
	<joint name="joint_5" type="continuous">
		<origin xyz="-0.2520115152106967 0.40796059379703353 -0.0008256871908699473" />
		<axis xyz="1.8363239884593445e-05 -0.0020125909119670863 -0.9999979745682551" />
		<child link="link_5" />
		<parent link="link_8" />
	</joint>
	<link name="link_6">
		<visual name="knob-7">
			<origin xyz="0.38775517069454707 -0.407960597833469 0.0008280445203390807" />
			<geometry>
				<mesh filename="/home/blake/kitchen-worlds/assets/models/OvenCounter/101917/textured_objs/original-96.obj" />/&gt;
			</geometry>
		</visual>
		<visual name="knob-7">
			<origin xyz="0.38775517069454707 -0.407960597833469 0.0008280445203390807" />
			<geometry>
				<mesh filename="/home/blake/kitchen-worlds/assets/models/OvenCounter/101917/textured_objs/original-97.obj" />/&gt;
			</geometry>
		</visual>
		<collision>
			<origin xyz="0.38775517069454707 -0.407960597833469 0.0008280445203390807" />
			<geometry>
				<mesh filename="/home/blake/kitchen-worlds/assets/models/OvenCounter/101917/textured_objs/original-96.obj" />/&gt;
			</geometry>
		</collision>
		<collision>
			<origin xyz="0.38775517069454707 -0.407960597833469 0.0008280445203390807" />
			<geometry>
				<mesh filename="/home/blake/kitchen-worlds/assets/models/OvenCounter/101917/textured_objs/original-97.obj" />/&gt;
			</geometry>
		</collision>
	</link>
	<joint name="joint_6" type="continuous">
		<origin xyz="-0.38775517069454707 0.407960597833469 -0.0008280445203390807" />
		<axis xyz="1.8375675945989576e-05 -0.0020122472129289115 -0.9999979752596946" />
		<child link="link_6" />
		<parent link="link_8" />
	</joint>
	<link name="link_7">
		<visual name="knob-8">
			<origin xyz="0.5234985105905582 -0.4079607797012221 0.0008304912171875477" />
			<geometry>
				<mesh filename="/home/blake/kitchen-worlds/assets/models/OvenCounter/101917/textured_objs/original-93.obj" />/&gt;
			</geometry>
		</visual>
		<visual name="knob-8">
			<origin xyz="0.5234985105905582 -0.4079607797012221 0.0008304912171875477" />
			<geometry>
				<mesh filename="/home/blake/kitchen-worlds/assets/models/OvenCounter/101917/textured_objs/original-94.obj" />/&gt;
			</geometry>
		</visual>
		<collision>
			<origin xyz="0.5234985105905582 -0.4079607797012221 0.0008304912171875477" />
			<geometry>
				<mesh filename="/home/blake/kitchen-worlds/assets/models/OvenCounter/101917/textured_objs/original-93.obj" />/&gt;
			</geometry>
		</collision>
		<collision>
			<origin xyz="0.5234985105905582 -0.4079607797012221 0.0008304912171875477" />
			<geometry>
				<mesh filename="/home/blake/kitchen-worlds/assets/models/OvenCounter/101917/textured_objs/original-94.obj" />/&gt;
			</geometry>
		</collision>
	</link>
	<joint name="joint_7" type="continuous">
		<origin xyz="-0.5234985105905582 0.4079607797012221 -0.0008304912171875477" />
		<axis xyz="1.833124623741794e-05 -0.0020121863623509227 -0.9999979753829549" />
		<child link="link_7" />
		<parent link="link_8" />
	</joint>
	<link name="link_8">
		<visual name="base_body-9">
			<origin xyz="0 0 0" />
			<geometry>
				<mesh filename="/home/blake/kitchen-worlds/assets/models/OvenCounter/101917/textured_objs/original-29.obj" />/&gt;
			</geometry>
		</visual>
		<visual name="base_body-9">
			<origin xyz="0 0 0" />
			<geometry>
				<mesh filename="/home/blake/kitchen-worlds/assets/models/OvenCounter/101917/textured_objs/original-21.obj" />/&gt;
			</geometry>
		</visual>
		<visual name="base_body-9">
			<origin xyz="0 0 0" />
			<geometry>
				<mesh filename="/home/blake/kitchen-worlds/assets/models/OvenCounter/101917/textured_objs/original-30.obj" />/&gt;
			</geometry>
		</visual>
		<visual name="base_body-9">
			<origin xyz="0 0 0" />
			<geometry>
				<mesh filename="/home/blake/kitchen-worlds/assets/models/OvenCounter/101917/textured_objs/original-36.obj" />/&gt;
			</geometry>
		</visual>
		<visual name="base_body-9">
			<origin xyz="0 0 0" />
			<geometry>
				<mesh filename="/home/blake/kitchen-worlds/assets/models/OvenCounter/101917/textured_objs/original-41.obj" />/&gt;
			</geometry>
		</visual>
		<visual name="base_body-9">
			<origin xyz="0 0 0" />
			<geometry>
				<mesh filename="/home/blake/kitchen-worlds/assets/models/OvenCounter/101917/textured_objs/original-28.obj" />/&gt;
			</geometry>
		</visual>
		<visual name="base_body-9">
			<origin xyz="0 0 0" />
			<geometry>
				<mesh filename="/home/blake/kitchen-worlds/assets/models/OvenCounter/101917/textured_objs/original-64.obj" />/&gt;
			</geometry>
		</visual>
		<visual name="base_body-9">
			<origin xyz="0 0 0" />
			<geometry>
				<mesh filename="/home/blake/kitchen-worlds/assets/models/OvenCounter/101917/textured_objs/original-43.obj" />/&gt;
			</geometry>
		</visual>
		<visual name="base_body-9">
			<origin xyz="0 0 0" />
			<geometry>
				<mesh filename="/home/blake/kitchen-worlds/assets/models/OvenCounter/101917/textured_objs/original-71.obj" />/&gt;
			</geometry>
		</visual>
		<visual name="base_body-9">
			<origin xyz="0 0 0" />
			<geometry>
				<mesh filename="/home/blake/kitchen-worlds/assets/models/OvenCounter/101917/textured_objs/original-52.obj" />/&gt;
			</geometry>
		</visual>
		<visual name="base_body-9">
			<origin xyz="0 0 0" />
			<geometry>
				<mesh filename="/home/blake/kitchen-worlds/assets/models/OvenCounter/101917/textured_objs/original-83.obj" />/&gt;
			</geometry>
		</visual>
		<visual name="base_body-9">
			<origin xyz="0 0 0" />
			<geometry>
				<mesh filename="/home/blake/kitchen-worlds/assets/models/OvenCounter/101917/textured_objs/original-22.obj" />/&gt;
			</geometry>
		</visual>
		<visual name="base_body-9">
			<origin xyz="0 0 0" />
			<geometry>
				<mesh filename="/home/blake/kitchen-worlds/assets/models/OvenCounter/101917/textured_objs/original-26.obj" />/&gt;
			</geometry>
		</visual>
		<visual name="base_body-9">
			<origin xyz="0 0 0" />
			<geometry>
				<mesh filename="/home/blake/kitchen-worlds/assets/models/OvenCounter/101917/textured_objs/original-117.obj" />/&gt;
			</geometry>
		</visual>
		<visual name="base_body-9">
			<origin xyz="0 0 0" />
			<geometry>
				<mesh filename="/home/blake/kitchen-worlds/assets/models/OvenCounter/101917/textured_objs/original-3.obj" />/&gt;
			</geometry>
		</visual>
		<visual name="base_body-9">
			<origin xyz="0 0 0" />
			<geometry>
				<mesh filename="/home/blake/kitchen-worlds/assets/models/OvenCounter/101917/textured_objs/original-65.obj" />/&gt;
			</geometry>
		</visual>
		<visual name="base_body-9">
			<origin xyz="0 0 0" />
			<geometry>
				<mesh filename="/home/blake/kitchen-worlds/assets/models/OvenCounter/101917/textured_objs/original-2.obj" />/&gt;
			</geometry>
		</visual>
		<visual name="base_body-9">
			<origin xyz="0 0 0" />
			<geometry>
				<mesh filename="/home/blake/kitchen-worlds/assets/models/OvenCounter/101917/textured_objs/original-44.obj" />/&gt;
			</geometry>
		</visual>
		<visual name="base_body-9">
			<origin xyz="0 0 0" />
			<geometry>
				<mesh filename="/home/blake/kitchen-worlds/assets/models/OvenCounter/101917/textured_objs/original-16.obj" />/&gt;
			</geometry>
		</visual>
		<visual name="base_body-9">
			<origin xyz="0 0 0" />
			<geometry>
				<mesh filename="/home/blake/kitchen-worlds/assets/models/OvenCounter/101917/textured_objs/original-86.obj" />/&gt;
			</geometry>
		</visual>
		<visual name="base_body-9">
			<origin xyz="0 0 0" />
			<geometry>
				<mesh filename="/home/blake/kitchen-worlds/assets/models/OvenCounter/101917/textured_objs/original-8.obj" />/&gt;
			</geometry>
		</visual>
		<visual name="base_body-9">
			<origin xyz="0 0 0" />
			<geometry>
				<mesh filename="/home/blake/kitchen-worlds/assets/models/OvenCounter/101917/textured_objs/original-13.obj" />/&gt;
			</geometry>
		</visual>
		<visual name="base_body-9">
			<origin xyz="0 0 0" />
			<geometry>
				<mesh filename="/home/blake/kitchen-worlds/assets/models/OvenCounter/101917/textured_objs/original-9.obj" />/&gt;
			</geometry>
		</visual>
		<visual name="base_body-9">
			<origin xyz="0 0 0" />
			<geometry>
				<mesh filename="/home/blake/kitchen-worlds/assets/models/OvenCounter/101917/textured_objs/original-45.obj" />/&gt;
			</geometry>
		</visual>
		<visual name="base_body-9">
			<origin xyz="0 0 0" />
			<geometry>
				<mesh filename="/home/blake/kitchen-worlds/assets/models/OvenCounter/101917/textured_objs/original-35.obj" />/&gt;
			</geometry>
		</visual>
		<visual name="base_body-9">
			<origin xyz="0 0 0" />
			<geometry>
				<mesh filename="/home/blake/kitchen-worlds/assets/models/OvenCounter/101917/textured_objs/original-49.obj" />/&gt;
			</geometry>
		</visual>
		<visual name="base_body-9">
			<origin xyz="0 0 0" />
			<geometry>
				<mesh filename="/home/blake/kitchen-worlds/assets/models/OvenCounter/101917/textured_objs/original-61.obj" />/&gt;
			</geometry>
		</visual>
		<visual name="base_body-9">
			<origin xyz="0 0 0" />
			<geometry>
				<mesh filename="/home/blake/kitchen-worlds/assets/models/OvenCounter/101917/textured_objs/original-39.obj" />/&gt;
			</geometry>
		</visual>
		<visual name="base_body-9">
			<origin xyz="0 0 0" />
			<geometry>
				<mesh filename="/home/blake/kitchen-worlds/assets/models/OvenCounter/101917/textured_objs/original-59.obj" />/&gt;
			</geometry>
		</visual>
		<visual name="base_body-9">
			<origin xyz="0 0 0" />
			<geometry>
				<mesh filename="/home/blake/kitchen-worlds/assets/models/OvenCounter/101917/textured_objs/original-5.obj" />/&gt;
			</geometry>
		</visual>
		<visual name="base_body-9">
			<origin xyz="0 0 0" />
			<geometry>
				<mesh filename="/home/blake/kitchen-worlds/assets/models/OvenCounter/101917/textured_objs/original-77.obj" />/&gt;
			</geometry>
		</visual>
		<visual name="base_body-9">
			<origin xyz="0 0 0" />
			<geometry>
				<mesh filename="/home/blake/kitchen-worlds/assets/models/OvenCounter/101917/textured_objs/original-114.obj" />/&gt;
			</geometry>
		</visual>
		<visual name="base_body-9">
			<origin xyz="0 0 0" />
			<geometry>
				<mesh filename="/home/blake/kitchen-worlds/assets/models/OvenCounter/101917/textured_objs/original-54.obj" />/&gt;
			</geometry>
		</visual>
		<visual name="base_body-9">
			<origin xyz="0 0 0" />
			<geometry>
				<mesh filename="/home/blake/kitchen-worlds/assets/models/OvenCounter/101917/textured_objs/original-63.obj" />/&gt;
			</geometry>
		</visual>
		<visual name="base_body-9">
			<origin xyz="0 0 0" />
			<geometry>
				<mesh filename="/home/blake/kitchen-worlds/assets/models/OvenCounter/101917/textured_objs/original-27.obj" />/&gt;
			</geometry>
		</visual>
		<visual name="base_body-9">
			<origin xyz="0 0 0" />
			<geometry>
				<mesh filename="/home/blake/kitchen-worlds/assets/models/OvenCounter/101917/textured_objs/original-87.obj" />/&gt;
			</geometry>
		</visual>
		<visual name="base_body-9">
			<origin xyz="0 0 0" />
			<geometry>
				<mesh filename="/home/blake/kitchen-worlds/assets/models/OvenCounter/101917/textured_objs/original-55.obj" />/&gt;
			</geometry>
		</visual>
		<visual name="base_body-9">
			<origin xyz="0 0 0" />
			<geometry>
				<mesh filename="/home/blake/kitchen-worlds/assets/models/OvenCounter/101917/textured_objs/original-113.obj" />/&gt;
			</geometry>
		</visual>
		<visual name="base_body-9">
			<origin xyz="0 0 0" />
			<geometry>
				<mesh filename="/home/blake/kitchen-worlds/assets/models/OvenCounter/101917/textured_objs/original-50.obj" />/&gt;
			</geometry>
		</visual>
		<visual name="base_body-9">
			<origin xyz="0 0 0" />
			<geometry>
				<mesh filename="/home/blake/kitchen-worlds/assets/models/OvenCounter/101917/textured_objs/original-6.obj" />/&gt;
			</geometry>
		</visual>
		<visual name="base_body-9">
			<origin xyz="0 0 0" />
			<geometry>
				<mesh filename="/home/blake/kitchen-worlds/assets/models/OvenCounter/101917/textured_objs/original-31.obj" />/&gt;
			</geometry>
		</visual>
		<visual name="base_body-9">
			<origin xyz="0 0 0" />
			<geometry>
				<mesh filename="/home/blake/kitchen-worlds/assets/models/OvenCounter/101917/textured_objs/original-37.obj" />/&gt;
			</geometry>
		</visual>
		<visual name="base_body-9">
			<origin xyz="0 0 0" />
			<geometry>
				<mesh filename="/home/blake/kitchen-worlds/assets/models/OvenCounter/101917/textured_objs/original-48.obj" />/&gt;
			</geometry>
		</visual>
		<visual name="base_body-9">
			<origin xyz="0 0 0" />
			<geometry>
				<mesh filename="/home/blake/kitchen-worlds/assets/models/OvenCounter/101917/textured_objs/original-116.obj" />/&gt;
			</geometry>
		</visual>
		<visual name="base_body-9">
			<origin xyz="0 0 0" />
			<geometry>
				<mesh filename="/home/blake/kitchen-worlds/assets/models/OvenCounter/101917/textured_objs/original-85.obj" />/&gt;
			</geometry>
		</visual>
		<visual name="base_body-9">
			<origin xyz="0 0 0" />
			<geometry>
				<mesh filename="/home/blake/kitchen-worlds/assets/models/OvenCounter/101917/textured_objs/original-56.obj" />/&gt;
			</geometry>
		</visual>
		<visual name="base_body-9">
			<origin xyz="0 0 0" />
			<geometry>
				<mesh filename="/home/blake/kitchen-worlds/assets/models/OvenCounter/101917/textured_objs/original-76.obj" />/&gt;
			</geometry>
		</visual>
		<visual name="base_body-9">
			<origin xyz="0 0 0" />
			<geometry>
				<mesh filename="/home/blake/kitchen-worlds/assets/models/OvenCounter/101917/textured_objs/original-72.obj" />/&gt;
			</geometry>
		</visual>
		<visual name="base_body-9">
			<origin xyz="0 0 0" />
			<geometry>
				<mesh filename="/home/blake/kitchen-worlds/assets/models/OvenCounter/101917/textured_objs/original-62.obj" />/&gt;
			</geometry>
		</visual>
		<visual name="base_body-9">
			<origin xyz="0 0 0" />
			<geometry>
				<mesh filename="/home/blake/kitchen-worlds/assets/models/OvenCounter/101917/textured_objs/original-75.obj" />/&gt;
			</geometry>
		</visual>
		<visual name="base_body-9">
			<origin xyz="0 0 0" />
			<geometry>
				<mesh filename="/home/blake/kitchen-worlds/assets/models/OvenCounter/101917/textured_objs/original-23.obj" />/&gt;
			</geometry>
		</visual>
		<visual name="base_body-9">
			<origin xyz="0 0 0" />
			<geometry>
				<mesh filename="/home/blake/kitchen-worlds/assets/models/OvenCounter/101917/textured_objs/original-66.obj" />/&gt;
			</geometry>
		</visual>
		<visual name="base_body-9">
			<origin xyz="0 0 0" />
			<geometry>
				<mesh filename="/home/blake/kitchen-worlds/assets/models/OvenCounter/101917/textured_objs/original-58.obj" />/&gt;
			</geometry>
		</visual>
		<visual name="base_body-9">
			<origin xyz="0 0 0" />
			<geometry>
				<mesh filename="/home/blake/kitchen-worlds/assets/models/OvenCounter/101917/textured_objs/original-67.obj" />/&gt;
			</geometry>
		</visual>
		<visual name="base_body-9">
			<origin xyz="0 0 0" />
			<geometry>
				<mesh filename="/home/blake/kitchen-worlds/assets/models/OvenCounter/101917/textured_objs/original-69.obj" />/&gt;
			</geometry>
		</visual>
		<visual name="base_body-9">
			<origin xyz="0 0 0" />
			<geometry>
				<mesh filename="/home/blake/kitchen-worlds/assets/models/OvenCounter/101917/textured_objs/original-38.obj" />/&gt;
			</geometry>
		</visual>
		<visual name="base_body-9">
			<origin xyz="0 0 0" />
			<geometry>
				<mesh filename="/home/blake/kitchen-worlds/assets/models/OvenCounter/101917/textured_objs/original-68.obj" />/&gt;
			</geometry>
		</visual>
		<visual name="base_body-9">
			<origin xyz="0 0 0" />
			<geometry>
				<mesh filename="/home/blake/kitchen-worlds/assets/models/OvenCounter/101917/textured_objs/original-34.obj" />/&gt;
			</geometry>
		</visual>
		<visual name="base_body-9">
			<origin xyz="0 0 0" />
			<geometry>
				<mesh filename="/home/blake/kitchen-worlds/assets/models/OvenCounter/101917/textured_objs/original-18.obj" />/&gt;
			</geometry>
		</visual>
		<visual name="base_body-9">
			<origin xyz="0 0 0" />
			<geometry>
				<mesh filename="/home/blake/kitchen-worlds/assets/models/OvenCounter/101917/textured_objs/original-118.obj" />/&gt;
			</geometry>
		</visual>
		<visual name="base_body-9">
			<origin xyz="0 0 0" />
			<geometry>
				<mesh filename="/home/blake/kitchen-worlds/assets/models/OvenCounter/101917/textured_objs/original-25.obj" />/&gt;
			</geometry>
		</visual>
		<visual name="base_body-9">
			<origin xyz="0 0 0" />
			<geometry>
				<mesh filename="/home/blake/kitchen-worlds/assets/models/OvenCounter/101917/textured_objs/original-17.obj" />/&gt;
			</geometry>
		</visual>
		<visual name="base_body-9">
			<origin xyz="0 0 0" />
			<geometry>
				<mesh filename="/home/blake/kitchen-worlds/assets/models/OvenCounter/101917/textured_objs/original-73.obj" />/&gt;
			</geometry>
		</visual>
		<visual name="base_body-9">
			<origin xyz="0 0 0" />
			<geometry>
				<mesh filename="/home/blake/kitchen-worlds/assets/models/OvenCounter/101917/textured_objs/original-12.obj" />/&gt;
			</geometry>
		</visual>
		<visual name="base_body-9">
			<origin xyz="0 0 0" />
			<geometry>
				<mesh filename="/home/blake/kitchen-worlds/assets/models/OvenCounter/101917/textured_objs/original-20.obj" />/&gt;
			</geometry>
		</visual>
		<visual name="base_body-9">
			<origin xyz="0 0 0" />
			<geometry>
				<mesh filename="/home/blake/kitchen-worlds/assets/models/OvenCounter/101917/textured_objs/original-88.obj" />/&gt;
			</geometry>
		</visual>
		<visual name="base_body-9">
			<origin xyz="0 0 0" />
			<geometry>
				<mesh filename="/home/blake/kitchen-worlds/assets/models/OvenCounter/101917/textured_objs/original-115.obj" />/&gt;
			</geometry>
		</visual>
		<visual name="base_body-9">
			<origin xyz="0 0 0" />
			<geometry>
				<mesh filename="/home/blake/kitchen-worlds/assets/models/OvenCounter/101917/textured_objs/original-32.obj" />/&gt;
			</geometry>
		</visual>
		<visual name="base_body-9">
			<origin xyz="0 0 0" />
			<geometry>
				<mesh filename="/home/blake/kitchen-worlds/assets/models/OvenCounter/101917/textured_objs/original-47.obj" />/&gt;
			</geometry>
		</visual>
		<visual name="base_body-9">
			<origin xyz="0 0 0" />
			<geometry>
				<mesh filename="/home/blake/kitchen-worlds/assets/models/OvenCounter/101917/textured_objs/original-53.obj" />/&gt;
			</geometry>
		</visual>
		
		<visual name="base_body-9">
			<origin xyz="0 0 0" />
			<geometry>
				<mesh filename="/home/blake/kitchen-worlds/assets/models/OvenCounter/101917/textured_objs/original-81.obj" />/&gt;
			</geometry>
		</visual>
		<visual name="base_body-9">
			<origin xyz="0 0 0" />
			<geometry>
				<mesh filename="/home/blake/kitchen-worlds/assets/models/OvenCounter/101917/textured_objs/original-84.obj" />/&gt;
			</geometry>
		</visual>
		<visual name="base_body-9">
			<origin xyz="0 0 0" />
			<geometry>
				<mesh filename="/home/blake/kitchen-worlds/assets/models/OvenCounter/101917/textured_objs/original-89.obj" />/&gt;
			</geometry>
		</visual>
		<visual name="base_body-9">
			<origin xyz="0 0 0" />
			<geometry>
				<mesh filename="/home/blake/kitchen-worlds/assets/models/OvenCounter/101917/textured_objs/original-10.obj" />/&gt;
			</geometry>
		</visual>
		<visual name="base_body-9">
			<origin xyz="0 0 0" />
			<geometry>
				<mesh filename="/home/blake/kitchen-worlds/assets/models/OvenCounter/101917/textured_objs/original-14.obj" />/&gt;
			</geometry>
		</visual>
		<visual name="base_body-9">
			<origin xyz="0 0 0" />
			<geometry>
				<mesh filename="/home/blake/kitchen-worlds/assets/models/OvenCounter/101917/textured_objs/original-82.obj" />/&gt;
			</geometry>
		</visual>
		<visual name="base_body-9">
			<origin xyz="0 0 0" />
			<geometry>
				<mesh filename="/home/blake/kitchen-worlds/assets/models/OvenCounter/101917/textured_objs/original-19.obj" />/&gt;
			</geometry>
		</visual>
		<visual name="base_body-9">
			<origin xyz="0 0 0" />
			<geometry>
				<mesh filename="/home/blake/kitchen-worlds/assets/models/OvenCounter/101917/textured_objs/original-90.obj" />/&gt;
			</geometry>
		</visual>
		<visual name="base_body-9">
			<origin xyz="0 0 0" />
			<geometry>
				<mesh filename="/home/blake/kitchen-worlds/assets/models/OvenCounter/101917/textured_objs/original-40.obj" />/&gt;
			</geometry>
		</visual>
		<visual name="base_body-9">
			<origin xyz="0 0 0" />
			<geometry>
				<mesh filename="/home/blake/kitchen-worlds/assets/models/OvenCounter/101917/textured_objs/original-46.obj" />/&gt;
			</geometry>
		</visual>
		<visual name="base_body-9">
			<origin xyz="0 0 0" />
			<geometry>
				<mesh filename="/home/blake/kitchen-worlds/assets/models/OvenCounter/101917/textured_objs/original-57.obj" />/&gt;
			</geometry>
		</visual>
		<collision>
			<origin xyz="0 0 0" />
			<geometry>
				<mesh filename="/home/blake/kitchen-worlds/assets/models/OvenCounter/101917/textured_objs/original-29.obj" />/&gt;
			</geometry>
		</collision>
		<collision>
			<origin xyz="0 0 0" />
			<geometry>
				<mesh filename="/home/blake/kitchen-worlds/assets/models/OvenCounter/101917/textured_objs/original-21.obj" />/&gt;
			</geometry>
		</collision>
		<collision>
			<origin xyz="0 0 0" />
			<geometry>
				<mesh filename="/home/blake/kitchen-worlds/assets/models/OvenCounter/101917/textured_objs/original-30.obj" />/&gt;
			</geometry>
		</collision>
		<collision>
			<origin xyz="0 0 0" />
			<geometry>
				<mesh filename="/home/blake/kitchen-worlds/assets/models/OvenCounter/101917/textured_objs/original-36.obj" />/&gt;
			</geometry>
		</collision>
		<collision>
			<origin xyz="0 0 0" />
			<geometry>
				<mesh filename="/home/blake/kitchen-worlds/assets/models/OvenCounter/101917/textured_objs/original-41.obj" />/&gt;
			</geometry>
		</collision>
		<collision>
			<origin xyz="0 0 0" />
			<geometry>
				<mesh filename="/home/blake/kitchen-worlds/assets/models/OvenCounter/101917/textured_objs/original-28.obj" />/&gt;
			</geometry>
		</collision>
		<collision>
			<origin xyz="0 0 0" />
			<geometry>
				<mesh filename="/home/blake/kitchen-worlds/assets/models/OvenCounter/101917/textured_objs/original-64.obj" />/&gt;
			</geometry>
		</collision>
		<collision>
			<origin xyz="0 0 0" />
			<geometry>
				<mesh filename="/home/blake/kitchen-worlds/assets/models/OvenCounter/101917/textured_objs/original-43.obj" />/&gt;
			</geometry>
		</collision>
		<collision>
			<origin xyz="0 0 0" />
			<geometry>
				<mesh filename="/home/blake/kitchen-worlds/assets/models/OvenCounter/101917/textured_objs/original-71.obj" />/&gt;
			</geometry>
		</collision>
		<collision>
			<origin xyz="0 0 0" />
			<geometry>
				<mesh filename="/home/blake/kitchen-worlds/assets/models/OvenCounter/101917/textured_objs/original-52.obj" />/&gt;
			</geometry>
		</collision>
		<collision>
			<origin xyz="0 0 0" />
			<geometry>
				<mesh filename="/home/blake/kitchen-worlds/assets/models/OvenCounter/101917/textured_objs/original-83.obj" />/&gt;
			</geometry>
		</collision>
		<collision>
			<origin xyz="0 0 0" />
			<geometry>
				<mesh filename="/home/blake/kitchen-worlds/assets/models/OvenCounter/101917/textured_objs/original-22.obj" />/&gt;
			</geometry>
		</collision>
		<collision>
			<origin xyz="0 0 0" />
			<geometry>
				<mesh filename="/home/blake/kitchen-worlds/assets/models/OvenCounter/101917/textured_objs/original-26.obj" />/&gt;
			</geometry>
		</collision>
		<collision>
			<origin xyz="0 0 0" />
			<geometry>
				<mesh filename="/home/blake/kitchen-worlds/assets/models/OvenCounter/101917/textured_objs/original-117.obj" />/&gt;
			</geometry>
		</collision>
		<collision>
			<origin xyz="0 0 0" />
			<geometry>
				<mesh filename="/home/blake/kitchen-worlds/assets/models/OvenCounter/101917/textured_objs/original-3.obj" />/&gt;
			</geometry>
		</collision>
		<collision>
			<origin xyz="0 0 0" />
			<geometry>
				<mesh filename="/home/blake/kitchen-worlds/assets/models/OvenCounter/101917/textured_objs/original-65.obj" />/&gt;
			</geometry>
		</collision>
		<collision>
			<origin xyz="0 0 0" />
			<geometry>
				<mesh filename="/home/blake/kitchen-worlds/assets/models/OvenCounter/101917/textured_objs/original-2.obj" />/&gt;
			</geometry>
		</collision>
		<collision>
			<origin xyz="0 0 0" />
			<geometry>
				<mesh filename="/home/blake/kitchen-worlds/assets/models/OvenCounter/101917/textured_objs/original-44.obj" />/&gt;
			</geometry>
		</collision>
		<collision>
			<origin xyz="0 0 0" />
			<geometry>
				<mesh filename="/home/blake/kitchen-worlds/assets/models/OvenCounter/101917/textured_objs/original-16.obj" />/&gt;
			</geometry>
		</collision>
		<collision>
			<origin xyz="0 0 0" />
			<geometry>
				<mesh filename="/home/blake/kitchen-worlds/assets/models/OvenCounter/101917/textured_objs/original-86.obj" />/&gt;
			</geometry>
		</collision>
		<collision>
			<origin xyz="0 0 0" />
			<geometry>
				<mesh filename="/home/blake/kitchen-worlds/assets/models/OvenCounter/101917/textured_objs/original-8.obj" />/&gt;
			</geometry>
		</collision>
		<collision>
			<origin xyz="0 0 0" />
			<geometry>
				<mesh filename="/home/blake/kitchen-worlds/assets/models/OvenCounter/101917/textured_objs/original-13.obj" />/&gt;
			</geometry>
		</collision>
		<collision>
			<origin xyz="0 0 0" />
			<geometry>
				<mesh filename="/home/blake/kitchen-worlds/assets/models/OvenCounter/101917/textured_objs/original-9.obj" />/&gt;
			</geometry>
		</collision>
		<collision>
			<origin xyz="0 0 0" />
			<geometry>
				<mesh filename="/home/blake/kitchen-worlds/assets/models/OvenCounter/101917/textured_objs/original-45.obj" />/&gt;
			</geometry>
		</collision>
		<collision>
			<origin xyz="0 0 0" />
			<geometry>
				<mesh filename="/home/blake/kitchen-worlds/assets/models/OvenCounter/101917/textured_objs/original-35.obj" />/&gt;
			</geometry>
		</collision>
		<collision>
			<origin xyz="0 0 0" />
			<geometry>
				<mesh filename="/home/blake/kitchen-worlds/assets/models/OvenCounter/101917/textured_objs/original-49.obj" />/&gt;
			</geometry>
		</collision>
		<collision>
			<origin xyz="0 0 0" />
			<geometry>
				<mesh filename="/home/blake/kitchen-worlds/assets/models/OvenCounter/101917/textured_objs/original-61.obj" />/&gt;
			</geometry>
		</collision>
		<collision>
			<origin xyz="0 0 0" />
			<geometry>
				<mesh filename="/home/blake/kitchen-worlds/assets/models/OvenCounter/101917/textured_objs/original-39.obj" />/&gt;
			</geometry>
		</collision>
		<collision>
			<origin xyz="0 0 0" />
			<geometry>
				<mesh filename="/home/blake/kitchen-worlds/assets/models/OvenCounter/101917/textured_objs/original-59.obj" />/&gt;
			</geometry>
		</collision>
		<collision>
			<origin xyz="0 0 0" />
			<geometry>
				<mesh filename="/home/blake/kitchen-worlds/assets/models/OvenCounter/101917/textured_objs/original-5.obj" />/&gt;
			</geometry>
		</collision>
		<collision>
			<origin xyz="0 0 0" />
			<geometry>
				<mesh filename="/home/blake/kitchen-worlds/assets/models/OvenCounter/101917/textured_objs/original-77.obj" />/&gt;
			</geometry>
		</collision>
		<collision>
			<origin xyz="0 0 0" />
			<geometry>
				<mesh filename="/home/blake/kitchen-worlds/assets/models/OvenCounter/101917/textured_objs/original-114.obj" />/&gt;
			</geometry>
		</collision>
		<collision>
			<origin xyz="0 0 0" />
			<geometry>
				<mesh filename="/home/blake/kitchen-worlds/assets/models/OvenCounter/101917/textured_objs/original-54.obj" />/&gt;
			</geometry>
		</collision>
		<collision>
			<origin xyz="0 0 0" />
			<geometry>
				<mesh filename="/home/blake/kitchen-worlds/assets/models/OvenCounter/101917/textured_objs/original-63.obj" />/&gt;
			</geometry>
		</collision>
		<collision>
			<origin xyz="0 0 0" />
			<geometry>
				<mesh filename="/home/blake/kitchen-worlds/assets/models/OvenCounter/101917/textured_objs/original-27.obj" />/&gt;
			</geometry>
		</collision>
		<collision>
			<origin xyz="0 0 0" />
			<geometry>
				<mesh filename="/home/blake/kitchen-worlds/assets/models/OvenCounter/101917/textured_objs/original-87.obj" />/&gt;
			</geometry>
		</collision>
		<collision>
			<origin xyz="0 0 0" />
			<geometry>
				<mesh filename="/home/blake/kitchen-worlds/assets/models/OvenCounter/101917/textured_objs/original-55.obj" />/&gt;
			</geometry>
		</collision>
		<collision>
			<origin xyz="0 0 0" />
			<geometry>
				<mesh filename="/home/blake/kitchen-worlds/assets/models/OvenCounter/101917/textured_objs/original-113.obj" />/&gt;
			</geometry>
		</collision>
		<collision>
			<origin xyz="0 0 0" />
			<geometry>
				<mesh filename="/home/blake/kitchen-worlds/assets/models/OvenCounter/101917/textured_objs/original-50.obj" />/&gt;
			</geometry>
		</collision>
		<collision>
			<origin xyz="0 0 0" />
			<geometry>
				<mesh filename="/home/blake/kitchen-worlds/assets/models/OvenCounter/101917/textured_objs/original-6.obj" />/&gt;
			</geometry>
		</collision>
		<collision>
			<origin xyz="0 0 0" />
			<geometry>
				<mesh filename="/home/blake/kitchen-worlds/assets/models/OvenCounter/101917/textured_objs/original-31.obj" />/&gt;
			</geometry>
		</collision>
		<collision>
			<origin xyz="0 0 0" />
			<geometry>
				<mesh filename="/home/blake/kitchen-worlds/assets/models/OvenCounter/101917/textured_objs/original-37.obj" />/&gt;
			</geometry>
		</collision>
		<collision>
			<origin xyz="0 0 0" />
			<geometry>
				<mesh filename="/home/blake/kitchen-worlds/assets/models/OvenCounter/101917/textured_objs/original-48.obj" />/&gt;
			</geometry>
		</collision>
		<collision>
			<origin xyz="0 0 0" />
			<geometry>
				<mesh filename="/home/blake/kitchen-worlds/assets/models/OvenCounter/101917/textured_objs/original-116.obj" />/&gt;
			</geometry>
		</collision>
		<collision>
			<origin xyz="0 0 0" />
			<geometry>
				<mesh filename="/home/blake/kitchen-worlds/assets/models/OvenCounter/101917/textured_objs/original-85.obj" />/&gt;
			</geometry>
		</collision>
		<collision>
			<origin xyz="0 0 0" />
			<geometry>
				<mesh filename="/home/blake/kitchen-worlds/assets/models/OvenCounter/101917/textured_objs/original-56.obj" />/&gt;
			</geometry>
		</collision>
		<collision>
			<origin xyz="0 0 0" />
			<geometry>
				<mesh filename="/home/blake/kitchen-worlds/assets/models/OvenCounter/101917/textured_objs/original-76.obj" />/&gt;
			</geometry>
		</collision>
		<collision>
			<origin xyz="0 0 0" />
			<geometry>
				<mesh filename="/home/blake/kitchen-worlds/assets/models/OvenCounter/101917/textured_objs/original-72.obj" />/&gt;
			</geometry>
		</collision>
		<collision>
			<origin xyz="0 0 0" />
			<geometry>
				<mesh filename="/home/blake/kitchen-worlds/assets/models/OvenCounter/101917/textured_objs/original-62.obj" />/&gt;
			</geometry>
		</collision>
		<collision>
			<origin xyz="0 0 0" />
			<geometry>
				<mesh filename="/home/blake/kitchen-worlds/assets/models/OvenCounter/101917/textured_objs/original-75.obj" />/&gt;
			</geometry>
		</collision>
		<collision>
			<origin xyz="0 0 0" />
			<geometry>
				<mesh filename="/home/blake/kitchen-worlds/assets/models/OvenCounter/101917/textured_objs/original-23.obj" />/&gt;
			</geometry>
		</collision>
		<collision>
			<origin xyz="0 0 0" />
			<geometry>
				<mesh filename="/home/blake/kitchen-worlds/assets/models/OvenCounter/101917/textured_objs/original-66.obj" />/&gt;
			</geometry>
		</collision>
		<collision>
			<origin xyz="0 0 0" />
			<geometry>
				<mesh filename="/home/blake/kitchen-worlds/assets/models/OvenCounter/101917/textured_objs/original-58.obj" />/&gt;
			</geometry>
		</collision>
		<collision>
			<origin xyz="0 0 0" />
			<geometry>
				<mesh filename="/home/blake/kitchen-worlds/assets/models/OvenCounter/101917/textured_objs/original-67.obj" />/&gt;
			</geometry>
		</collision>
		<collision>
			<origin xyz="0 0 0" />
			<geometry>
				<mesh filename="/home/blake/kitchen-worlds/assets/models/OvenCounter/101917/textured_objs/original-69.obj" />/&gt;
			</geometry>
		</collision>
		<collision>
			<origin xyz="0 0 0" />
			<geometry>
				<mesh filename="/home/blake/kitchen-worlds/assets/models/OvenCounter/101917/textured_objs/original-38.obj" />/&gt;
			</geometry>
		</collision>
		<collision>
			<origin xyz="0 0 0" />
			<geometry>
				<mesh filename="/home/blake/kitchen-worlds/assets/models/OvenCounter/101917/textured_objs/original-68.obj" />/&gt;
			</geometry>
		</collision>
		<collision>
			<origin xyz="0 0 0" />
			<geometry>
				<mesh filename="/home/blake/kitchen-worlds/assets/models/OvenCounter/101917/textured_objs/original-34.obj" />/&gt;
			</geometry>
		</collision>
		<collision>
			<origin xyz="0 0 0" />
			<geometry>
				<mesh filename="/home/blake/kitchen-worlds/assets/models/OvenCounter/101917/textured_objs/original-18.obj" />/&gt;
			</geometry>
		</collision>
		<collision>
			<origin xyz="0 0 0" />
			<geometry>
				<mesh filename="/home/blake/kitchen-worlds/assets/models/OvenCounter/101917/textured_objs/original-118.obj" />/&gt;
			</geometry>
		</collision>
		<collision>
			<origin xyz="0 0 0" />
			<geometry>
				<mesh filename="/home/blake/kitchen-worlds/assets/models/OvenCounter/101917/textured_objs/original-25.obj" />/&gt;
			</geometry>
		</collision>
		<collision>
			<origin xyz="0 0 0" />
			<geometry>
				<mesh filename="/home/blake/kitchen-worlds/assets/models/OvenCounter/101917/textured_objs/original-17.obj" />/&gt;
			</geometry>
		</collision>
		<collision>
			<origin xyz="0 0 0" />
			<geometry>
				<mesh filename="/home/blake/kitchen-worlds/assets/models/OvenCounter/101917/textured_objs/original-73.obj" />/&gt;
			</geometry>
		</collision>
		<collision>
			<origin xyz="0 0 0" />
			<geometry>
				<mesh filename="/home/blake/kitchen-worlds/assets/models/OvenCounter/101917/textured_objs/original-12.obj" />/&gt;
			</geometry>
		</collision>
		<collision>
			<origin xyz="0 0 0" />
			<geometry>
				<mesh filename="/home/blake/kitchen-worlds/assets/models/OvenCounter/101917/textured_objs/original-20.obj" />/&gt;
			</geometry>
		</collision>
		<collision>
			<origin xyz="0 0 0" />
			<geometry>
				<mesh filename="/home/blake/kitchen-worlds/assets/models/OvenCounter/101917/textured_objs/original-88.obj" />/&gt;
			</geometry>
		</collision>
		<collision>
			<origin xyz="0 0 0" />
			<geometry>
				<mesh filename="/home/blake/kitchen-worlds/assets/models/OvenCounter/101917/textured_objs/original-115.obj" />/&gt;
			</geometry>
		</collision>
		<collision>
			<origin xyz="0 0 0" />
			<geometry>
				<mesh filename="/home/blake/kitchen-worlds/assets/models/OvenCounter/101917/textured_objs/original-32.obj" />/&gt;
			</geometry>
		</collision>
		<collision>
			<origin xyz="0 0 0" />
			<geometry>
				<mesh filename="/home/blake/kitchen-worlds/assets/models/OvenCounter/101917/textured_objs/original-47.obj" />/&gt;
			</geometry>
		</collision>
		<collision>
			<origin xyz="0 0 0" />
			<geometry>
				<mesh filename="/home/blake/kitchen-worlds/assets/models/OvenCounter/101917/textured_objs/original-53.obj" />/&gt;
			</geometry>
		</collision>
		
		<collision>
			<origin xyz="0 0 0" />
			<geometry>
				<mesh filename="/home/blake/kitchen-worlds/assets/models/OvenCounter/101917/textured_objs/original-81.obj" />/&gt;
			</geometry>
		</collision>
		<collision>
			<origin xyz="0 0 0" />
			<geometry>
				<mesh filename="/home/blake/kitchen-worlds/assets/models/OvenCounter/101917/textured_objs/original-84.obj" />/&gt;
			</geometry>
		</collision>
		<collision>
			<origin xyz="0 0 0" />
			<geometry>
				<mesh filename="/home/blake/kitchen-worlds/assets/models/OvenCounter/101917/textured_objs/original-89.obj" />/&gt;
			</geometry>
		</collision>
		<collision>
			<origin xyz="0 0 0" />
			<geometry>
				<mesh filename="/home/blake/kitchen-worlds/assets/models/OvenCounter/101917/textured_objs/original-10.obj" />/&gt;
			</geometry>
		</collision>
		<collision>
			<origin xyz="0 0 0" />
			<geometry>
				<mesh filename="/home/blake/kitchen-worlds/assets/models/OvenCounter/101917/textured_objs/original-14.obj" />/&gt;
			</geometry>
		</collision>
		<collision>
			<origin xyz="0 0 0" />
			<geometry>
				<mesh filename="/home/blake/kitchen-worlds/assets/models/OvenCounter/101917/textured_objs/original-82.obj" />/&gt;
			</geometry>
		</collision>
		<collision>
			<origin xyz="0 0 0" />
			<geometry>
				<mesh filename="/home/blake/kitchen-worlds/assets/models/OvenCounter/101917/textured_objs/original-19.obj" />/&gt;
			</geometry>
		</collision>
		<collision>
			<origin xyz="0 0 0" />
			<geometry>
				<mesh filename="/home/blake/kitchen-worlds/assets/models/OvenCounter/101917/textured_objs/original-90.obj" />/&gt;
			</geometry>
		</collision>
		<collision>
			<origin xyz="0 0 0" />
			<geometry>
				<mesh filename="/home/blake/kitchen-worlds/assets/models/OvenCounter/101917/textured_objs/original-40.obj" />/&gt;
			</geometry>
		</collision>
		<collision>
			<origin xyz="0 0 0" />
			<geometry>
				<mesh filename="/home/blake/kitchen-worlds/assets/models/OvenCounter/101917/textured_objs/original-46.obj" />/&gt;
			</geometry>
		</collision>
		<collision>
			<origin xyz="0 0 0" />
			<geometry>
				<mesh filename="/home/blake/kitchen-worlds/assets/models/OvenCounter/101917/textured_objs/original-57.obj" />/&gt;
			</geometry>
		</collision>
	</link>
	<joint name="joint_8" type="fixed">
		<origin rpy="1.570796326794897 0 -1.570796326794897" xyz="0 0 0" />
		<child link="link_8" />
		<parent link="base" />
	</joint>
</robot>