<?xml version='1.0' encoding='utf-8'?>
<robot name="partnet_3943db3b9d84b10a353b1de88cb6758">
	<link name="base" />
	<link name="link_0">
		<visual name="button-2">
			<origin xyz="0 0 0" />
			<geometry>
				<mesh filename="/home/blake/kitchen-worlds/assets/models/Camera/102411/textured_objs/original-54.obj" />/&gt;
			</geometry>
		</visual>
		<visual name="button-2">
			<origin xyz="0 0 0" />
			<geometry>
				<mesh filename="/home/blake/kitchen-worlds/assets/models/Camera/102411/textured_objs/original-55.obj" />/&gt;
			</geometry>
		</visual>
		<visual name="button-2">
			<origin xyz="0 0 0" />
			<geometry>
				<mesh filename="/home/blake/kitchen-worlds/assets/models/Camera/102411/textured_objs/original-52.obj" />/&gt;
			</geometry>
		</visual>
		<visual name="button-2">
			<origin xyz="0 0 0" />
			<geometry>
				<mesh filename="/home/blake/kitchen-worlds/assets/models/Camera/102411/textured_objs/original-53.obj" />/&gt;
			</geometry>
		</visual>
		<visual name="button-2">
			<origin xyz="0 0 0" />
			<geometry>
				<mesh filename="/home/blake/kitchen-worlds/assets/models/Camera/102411/textured_objs/original-56.obj" />/&gt;
			</geometry>
		</visual>
		<collision>
			<origin xyz="0 0 0" />
			<geometry>
				<mesh filename="/home/blake/kitchen-worlds/assets/models/Camera/102411/textured_objs/original-54.obj" />/&gt;
			</geometry>
		</collision>
		<collision>
			<origin xyz="0 0 0" />
			<geometry>
				<mesh filename="/home/blake/kitchen-worlds/assets/models/Camera/102411/textured_objs/original-55.obj" />/&gt;
			</geometry>
		</collision>
		<collision>
			<origin xyz="0 0 0" />
			<geometry>
				<mesh filename="/home/blake/kitchen-worlds/assets/models/Camera/102411/textured_objs/original-52.obj" />/&gt;
			</geometry>
		</collision>
		<collision>
			<origin xyz="0 0 0" />
			<geometry>
				<mesh filename="/home/blake/kitchen-worlds/assets/models/Camera/102411/textured_objs/original-53.obj" />/&gt;
			</geometry>
		</collision>
		<collision>
			<origin xyz="0 0 0" />
			<geometry>
				<mesh filename="/home/blake/kitchen-worlds/assets/models/Camera/102411/textured_objs/original-56.obj" />/&gt;
			</geometry>
		</collision>
	</link>
	<joint name="joint_0" type="prismatic">
		<origin xyz="0 0 0" />
		<axis xyz="0 -1 0" />
		<child link="link_0" />
		<parent link="link_12" />
		<limit lower="0" upper="0.008000000000000007" effort="10.0" velocity="1.0" />
	</joint>
	<link name="link_1">
		<visual name="button-3">
			<origin xyz="0 0 0" />
			<geometry>
				<mesh filename="/home/blake/kitchen-worlds/assets/models/Camera/102411/textured_objs/original-11.obj" />/&gt;
			</geometry>
		</visual>
		<collision>
			<origin xyz="0 0 0" />
			<geometry>
				<mesh filename="/home/blake/kitchen-worlds/assets/models/Camera/102411/textured_objs/original-11.obj" />/&gt;
			</geometry>
		</collision>
	</link>
	<joint name="joint_1" type="prismatic">
		<origin xyz="0 0 0" />
		<axis xyz="0 -1 0" />
		<child link="link_1" />
		<parent link="link_12" />
		<limit lower="0" upper="0.008000000000000007" effort="10.0" velocity="1.0" />
	</joint>
	<link name="link_2">
		<visual name="button-4">
			<origin xyz="0 0 0" />
			<geometry>
				<mesh filename="/home/blake/kitchen-worlds/assets/models/Camera/102411/textured_objs/original-58.obj" />/&gt;
			</geometry>
		</visual>
		<visual name="button-4">
			<origin xyz="0 0 0" />
			<geometry>
				<mesh filename="/home/blake/kitchen-worlds/assets/models/Camera/102411/textured_objs/original-57.obj" />/&gt;
			</geometry>
		</visual>
		<collision>
			<origin xyz="0 0 0" />
			<geometry>
				<mesh filename="/home/blake/kitchen-worlds/assets/models/Camera/102411/textured_objs/original-58.obj" />/&gt;
			</geometry>
		</collision>
		<collision>
			<origin xyz="0 0 0" />
			<geometry>
				<mesh filename="/home/blake/kitchen-worlds/assets/models/Camera/102411/textured_objs/original-57.obj" />/&gt;
			</geometry>
		</collision>
	</link>
	<joint name="joint_2" type="prismatic">
		<origin xyz="0 0 0" />
		<axis xyz="0 0 1" />
		<child link="link_2" />
		<parent link="link_12" />
		<limit lower="0" upper="0.0020000000000000035" effort="10.0" velocity="1.0" />
	</joint>
	<link name="link_3">
		<visual name="button-5">
			<origin xyz="0 0 0" />
			<geometry>
				<mesh filename="/home/blake/kitchen-worlds/assets/models/Camera/102411/textured_objs/original-34.obj" />/&gt;
			</geometry>
		</visual>
		<visual name="button-5">
			<origin xyz="0 0 0" />
			<geometry>
				<mesh filename="/home/blake/kitchen-worlds/assets/models/Camera/102411/textured_objs/original-35.obj" />/&gt;
			</geometry>
		</visual>
		<visual name="button-5">
			<origin xyz="0 0 0" />
			<geometry>
				<mesh filename="/home/blake/kitchen-worlds/assets/models/Camera/102411/textured_objs/original-36.obj" />/&gt;
			</geometry>
		</visual>
		<visual name="button-5">
			<origin xyz="0 0 0" />
			<geometry>
				<mesh filename="/home/blake/kitchen-worlds/assets/models/Camera/102411/textured_objs/original-44.obj" />/&gt;
			</geometry>
		</visual>
		<visual name="button-5">
			<origin xyz="0 0 0" />
			<geometry>
				<mesh filename="/home/blake/kitchen-worlds/assets/models/Camera/102411/textured_objs/original-37.obj" />/&gt;
			</geometry>
		</visual>
		<collision>
			<origin xyz="0 0 0" />
			<geometry>
				<mesh filename="/home/blake/kitchen-worlds/assets/models/Camera/102411/textured_objs/original-34.obj" />/&gt;
			</geometry>
		</collision>
		<collision>
			<origin xyz="0 0 0" />
			<geometry>
				<mesh filename="/home/blake/kitchen-worlds/assets/models/Camera/102411/textured_objs/original-35.obj" />/&gt;
			</geometry>
		</collision>
		<collision>
			<origin xyz="0 0 0" />
			<geometry>
				<mesh filename="/home/blake/kitchen-worlds/assets/models/Camera/102411/textured_objs/original-36.obj" />/&gt;
			</geometry>
		</collision>
		<collision>
			<origin xyz="0 0 0" />
			<geometry>
				<mesh filename="/home/blake/kitchen-worlds/assets/models/Camera/102411/textured_objs/original-44.obj" />/&gt;
			</geometry>
		</collision>
		<collision>
			<origin xyz="0 0 0" />
			<geometry>
				<mesh filename="/home/blake/kitchen-worlds/assets/models/Camera/102411/textured_objs/original-37.obj" />/&gt;
			</geometry>
		</collision>
	</link>
	<joint name="joint_3" type="prismatic">
		<origin xyz="0 0 0" />
		<axis xyz="0 0 1" />
		<child link="link_3" />
		<parent link="link_12" />
		<limit lower="0" upper="0.0020000000000000035" effort="10.0" velocity="1.0" />
	</joint>
	<link name="link_4">
		<visual name="button-6">
			<origin xyz="0 0 0" />
			<geometry>
				<mesh filename="/home/blake/kitchen-worlds/assets/models/Camera/102411/textured_objs/original-25.obj" />/&gt;
			</geometry>
		</visual>
		<visual name="button-6">
			<origin xyz="0 0 0" />
			<geometry>
				<mesh filename="/home/blake/kitchen-worlds/assets/models/Camera/102411/textured_objs/original-24.obj" />/&gt;
			</geometry>
		</visual>
		<visual name="button-6">
			<origin xyz="0 0 0" />
			<geometry>
				<mesh filename="/home/blake/kitchen-worlds/assets/models/Camera/102411/textured_objs/original-23.obj" />/&gt;
			</geometry>
		</visual>
		<visual name="button-6">
			<origin xyz="0 0 0" />
			<geometry>
				<mesh filename="/home/blake/kitchen-worlds/assets/models/Camera/102411/textured_objs/original-45.obj" />/&gt;
			</geometry>
		</visual>
		<visual name="button-6">
			<origin xyz="0 0 0" />
			<geometry>
				<mesh filename="/home/blake/kitchen-worlds/assets/models/Camera/102411/textured_objs/original-26.obj" />/&gt;
			</geometry>
		</visual>
		<collision>
			<origin xyz="0 0 0" />
			<geometry>
				<mesh filename="/home/blake/kitchen-worlds/assets/models/Camera/102411/textured_objs/original-25.obj" />/&gt;
			</geometry>
		</collision>
		<collision>
			<origin xyz="0 0 0" />
			<geometry>
				<mesh filename="/home/blake/kitchen-worlds/assets/models/Camera/102411/textured_objs/original-24.obj" />/&gt;
			</geometry>
		</collision>
		<collision>
			<origin xyz="0 0 0" />
			<geometry>
				<mesh filename="/home/blake/kitchen-worlds/assets/models/Camera/102411/textured_objs/original-23.obj" />/&gt;
			</geometry>
		</collision>
		<collision>
			<origin xyz="0 0 0" />
			<geometry>
				<mesh filename="/home/blake/kitchen-worlds/assets/models/Camera/102411/textured_objs/original-45.obj" />/&gt;
			</geometry>
		</collision>
		<collision>
			<origin xyz="0 0 0" />
			<geometry>
				<mesh filename="/home/blake/kitchen-worlds/assets/models/Camera/102411/textured_objs/original-26.obj" />/&gt;
			</geometry>
		</collision>
	</link>
	<joint name="joint_4" type="prismatic">
		<origin xyz="0 0 0" />
		<axis xyz="0 0 1" />
		<child link="link_4" />
		<parent link="link_12" />
		<limit lower="0" upper="0.0020000000000000035" effort="10.0" velocity="1.0" />
	</joint>
	<link name="link_5">
		<visual name="button-7">
			<origin xyz="0 0 0" />
			<geometry>
				<mesh filename="/home/blake/kitchen-worlds/assets/models/Camera/102411/textured_objs/original-40.obj" />/&gt;
			</geometry>
		</visual>
		<visual name="button-7">
			<origin xyz="0 0 0" />
			<geometry>
				<mesh filename="/home/blake/kitchen-worlds/assets/models/Camera/102411/textured_objs/original-27.obj" />/&gt;
			</geometry>
		</visual>
		<collision>
			<origin xyz="0 0 0" />
			<geometry>
				<mesh filename="/home/blake/kitchen-worlds/assets/models/Camera/102411/textured_objs/original-40.obj" />/&gt;
			</geometry>
		</collision>
		<collision>
			<origin xyz="0 0 0" />
			<geometry>
				<mesh filename="/home/blake/kitchen-worlds/assets/models/Camera/102411/textured_objs/original-27.obj" />/&gt;
			</geometry>
		</collision>
	</link>
	<joint name="joint_5" type="prismatic">
		<origin xyz="0 0 0" />
		<axis xyz="0 0 1" />
		<child link="link_5" />
		<parent link="link_12" />
		<limit lower="0" upper="0.0020000000000000035" effort="10.0" velocity="1.0" />
	</joint>
	<link name="link_6">
		<visual name="button-8">
			<origin xyz="0 0 0" />
			<geometry>
				<mesh filename="/home/blake/kitchen-worlds/assets/models/Camera/102411/textured_objs/original-29.obj" />/&gt;
			</geometry>
		</visual>
		<visual name="button-8">
			<origin xyz="0 0 0" />
			<geometry>
				<mesh filename="/home/blake/kitchen-worlds/assets/models/Camera/102411/textured_objs/original-42.obj" />/&gt;
			</geometry>
		</visual>
		<collision>
			<origin xyz="0 0 0" />
			<geometry>
				<mesh filename="/home/blake/kitchen-worlds/assets/models/Camera/102411/textured_objs/original-29.obj" />/&gt;
			</geometry>
		</collision>
		<collision>
			<origin xyz="0 0 0" />
			<geometry>
				<mesh filename="/home/blake/kitchen-worlds/assets/models/Camera/102411/textured_objs/original-42.obj" />/&gt;
			</geometry>
		</collision>
	</link>
	<joint name="joint_6" type="prismatic">
		<origin xyz="0 0 0" />
		<axis xyz="0 0 1" />
		<child link="link_6" />
		<parent link="link_12" />
		<limit lower="0" upper="0.0020000000000000035" effort="10.0" velocity="1.0" />
	</joint>
	<link name="link_7">
		<visual name="button-9">
			<origin xyz="0 0 0" />
			<geometry>
				<mesh filename="/home/blake/kitchen-worlds/assets/models/Camera/102411/textured_objs/original-28.obj" />/&gt;
			</geometry>
		</visual>
		<visual name="button-9">
			<origin xyz="0 0 0" />
			<geometry>
				<mesh filename="/home/blake/kitchen-worlds/assets/models/Camera/102411/textured_objs/original-43.obj" />/&gt;
			</geometry>
		</visual>
		<collision>
			<origin xyz="0 0 0" />
			<geometry>
				<mesh filename="/home/blake/kitchen-worlds/assets/models/Camera/102411/textured_objs/original-28.obj" />/&gt;
			</geometry>
		</collision>
		<collision>
			<origin xyz="0 0 0" />
			<geometry>
				<mesh filename="/home/blake/kitchen-worlds/assets/models/Camera/102411/textured_objs/original-43.obj" />/&gt;
			</geometry>
		</collision>
	</link>
	<joint name="joint_7" type="prismatic">
		<origin xyz="0 0 0" />
		<axis xyz="0 0 1" />
		<child link="link_7" />
		<parent link="link_12" />
		<limit lower="0" upper="0.0020000000000000035" effort="10.0" velocity="1.0" />
	</joint>
	<link name="link_8">
		<visual name="button-10">
			<origin xyz="0 0 0" />
			<geometry>
				<mesh filename="/home/blake/kitchen-worlds/assets/models/Camera/102411/textured_objs/original-32.obj" />/&gt;
			</geometry>
		</visual>
		<visual name="button-10">
			<origin xyz="0 0 0" />
			<geometry>
				<mesh filename="/home/blake/kitchen-worlds/assets/models/Camera/102411/textured_objs/original-31.obj" />/&gt;
			</geometry>
		</visual>
		<visual name="button-10">
			<origin xyz="0 0 0" />
			<geometry>
				<mesh filename="/home/blake/kitchen-worlds/assets/models/Camera/102411/textured_objs/original-41.obj" />/&gt;
			</geometry>
		</visual>
		<collision>
			<origin xyz="0 0 0" />
			<geometry>
				<mesh filename="/home/blake/kitchen-worlds/assets/models/Camera/102411/textured_objs/original-32.obj" />/&gt;
			</geometry>
		</collision>
		<collision>
			<origin xyz="0 0 0" />
			<geometry>
				<mesh filename="/home/blake/kitchen-worlds/assets/models/Camera/102411/textured_objs/original-31.obj" />/&gt;
			</geometry>
		</collision>
		<collision>
			<origin xyz="0 0 0" />
			<geometry>
				<mesh filename="/home/blake/kitchen-worlds/assets/models/Camera/102411/textured_objs/original-41.obj" />/&gt;
			</geometry>
		</collision>
	</link>
	<joint name="joint_8" type="prismatic">
		<origin xyz="0 0 0" />
		<axis xyz="0 0 1" />
		<child link="link_8" />
		<parent link="link_12" />
		<limit lower="0" upper="0.0020000000000000035" effort="10.0" velocity="1.0" />
	</joint>
	<link name="link_9">
		<visual name="button-11">
			<origin xyz="0 0 0" />
			<geometry>
				<mesh filename="/home/blake/kitchen-worlds/assets/models/Camera/102411/textured_objs/original-39.obj" />/&gt;
			</geometry>
		</visual>
		<visual name="button-11">
			<origin xyz="0 0 0" />
			<geometry>
				<mesh filename="/home/blake/kitchen-worlds/assets/models/Camera/102411/textured_objs/original-38.obj" />/&gt;
			</geometry>
		</visual>
		<collision>
			<origin xyz="0 0 0" />
			<geometry>
				<mesh filename="/home/blake/kitchen-worlds/assets/models/Camera/102411/textured_objs/original-39.obj" />/&gt;
			</geometry>
		</collision>
		<collision>
			<origin xyz="0 0 0" />
			<geometry>
				<mesh filename="/home/blake/kitchen-worlds/assets/models/Camera/102411/textured_objs/original-38.obj" />/&gt;
			</geometry>
		</collision>
	</link>
	<joint name="joint_9" type="prismatic">
		<origin xyz="0 0 0" />
		<axis xyz="0 0 1" />
		<child link="link_9" />
		<parent link="link_12" />
		<limit lower="0" upper="0.0020000000000000035" effort="10.0" velocity="1.0" />
	</joint>
	<link name="link_10">
		<visual name="lens-12">
			<origin xyz="-0.3377775 -0.0020549999999999943 0" />
			<geometry>
				<mesh filename="/home/blake/kitchen-worlds/assets/models/Camera/102411/textured_objs/original-66.obj" />/&gt;
			</geometry>
		</visual>
		<visual name="lens-12">
			<origin xyz="-0.3377775 -0.0020549999999999943 0" />
			<geometry>
				<mesh filename="/home/blake/kitchen-worlds/assets/models/Camera/102411/textured_objs/original-67.obj" />/&gt;
			</geometry>
		</visual>
		<visual name="lens-12">
			<origin xyz="-0.3377775 -0.0020549999999999943 0" />
			<geometry>
				<mesh filename="/home/blake/kitchen-worlds/assets/models/Camera/102411/textured_objs/original-71.obj" />/&gt;
			</geometry>
		</visual>
		<visual name="lens-12">
			<origin xyz="-0.3377775 -0.0020549999999999943 0" />
			<geometry>
				<mesh filename="/home/blake/kitchen-worlds/assets/models/Camera/102411/textured_objs/original-69.obj" />/&gt;
			</geometry>
		</visual>
		<visual name="lens-12">
			<origin xyz="-0.3377775 -0.0020549999999999943 0" />
			<geometry>
				<mesh filename="/home/blake/kitchen-worlds/assets/models/Camera/102411/textured_objs/original-72.obj" />/&gt;
			</geometry>
		</visual>
		<visual name="lens-12">
			<origin xyz="-0.3377775 -0.0020549999999999943 0" />
			<geometry>
				<mesh filename="/home/blake/kitchen-worlds/assets/models/Camera/102411/textured_objs/original-62.obj" />/&gt;
			</geometry>
		</visual>
		<collision>
			<origin xyz="-0.3377775 -0.0020549999999999943 0" />
			<geometry>
				<mesh filename="/home/blake/kitchen-worlds/assets/models/Camera/102411/textured_objs/original-66.obj" />/&gt;
			</geometry>
		</collision>
		<collision>
			<origin xyz="-0.3377775 -0.0020549999999999943 0" />
			<geometry>
				<mesh filename="/home/blake/kitchen-worlds/assets/models/Camera/102411/textured_objs/original-67.obj" />/&gt;
			</geometry>
		</collision>
		<collision>
			<origin xyz="-0.3377775 -0.0020549999999999943 0" />
			<geometry>
				<mesh filename="/home/blake/kitchen-worlds/assets/models/Camera/102411/textured_objs/original-71.obj" />/&gt;
			</geometry>
		</collision>
		<collision>
			<origin xyz="-0.3377775 -0.0020549999999999943 0" />
			<geometry>
				<mesh filename="/home/blake/kitchen-worlds/assets/models/Camera/102411/textured_objs/original-69.obj" />/&gt;
			</geometry>
		</collision>
		<collision>
			<origin xyz="-0.3377775 -0.0020549999999999943 0" />
			<geometry>
				<mesh filename="/home/blake/kitchen-worlds/assets/models/Camera/102411/textured_objs/original-72.obj" />/&gt;
			</geometry>
		</collision>
		<collision>
			<origin xyz="-0.3377775 -0.0020549999999999943 0" />
			<geometry>
				<mesh filename="/home/blake/kitchen-worlds/assets/models/Camera/102411/textured_objs/original-62.obj" />/&gt;
			</geometry>
		</collision>
	</link>
	<joint name="joint_10" type="continuous">
		<origin xyz="0.3377775 0.0020549999999999943 0" />
		<axis xyz="0 0 1" />
		<child link="link_10" />
		<parent link="link_12" />
	</joint>
	<link name="link_11">
		<visual name="button-13">
			<origin xyz="0.7519234875417385 0 0.041457287013894256" />
			<geometry>
				<mesh filename="/home/blake/kitchen-worlds/assets/models/Camera/102411/textured_objs/original-50.obj" />/&gt;
			</geometry>
		</visual>
		<visual name="button-13">
			<origin xyz="0.7519234875417385 0 0.041457287013894256" />
			<geometry>
				<mesh filename="/home/blake/kitchen-worlds/assets/models/Camera/102411/textured_objs/original-49.obj" />/&gt;
			</geometry>
		</visual>
		<collision>
			<origin xyz="0.7519234875417385 0 0.041457287013894256" />
			<geometry>
				<mesh filename="/home/blake/kitchen-worlds/assets/models/Camera/102411/textured_objs/original-50.obj" />/&gt;
			</geometry>
		</collision>
		<collision>
			<origin xyz="0.7519234875417385 0 0.041457287013894256" />
			<geometry>
				<mesh filename="/home/blake/kitchen-worlds/assets/models/Camera/102411/textured_objs/original-49.obj" />/&gt;
			</geometry>
		</collision>
	</link>
	<joint name="joint_11" type="continuous">
		<origin xyz="-0.7519234875417385 0 -0.041457287013894256" />
		<axis xyz="0 1 0" />
		<child link="link_11" />
		<parent link="link_12" />
	</joint>
	<link name="link_12">
		<visual name="base_body-14">
			<origin xyz="0 0 0" />
			<geometry>
				<mesh filename="/home/blake/kitchen-worlds/assets/models/Camera/102411/textured_objs/original-64.obj" />/&gt;
			</geometry>
		</visual>
		<visual name="base_body-14">
			<origin xyz="0 0 0" />
			<geometry>
				<mesh filename="/home/blake/kitchen-worlds/assets/models/Camera/102411/textured_objs/original-4.obj" />/&gt;
			</geometry>
		</visual>
		<visual name="base_body-14">
			<origin xyz="0 0 0" />
			<geometry>
				<mesh filename="/home/blake/kitchen-worlds/assets/models/Camera/102411/textured_objs/original-3.obj" />/&gt;
			</geometry>
		</visual>
		<visual name="base_body-14">
			<origin xyz="0 0 0" />
			<geometry>
				<mesh filename="/home/blake/kitchen-worlds/assets/models/Camera/102411/textured_objs/original-65.obj" />/&gt;
			</geometry>
		</visual>
		<visual name="base_body-14">
			<origin xyz="0 0 0" />
			<geometry>
				<mesh filename="/home/blake/kitchen-worlds/assets/models/Camera/102411/textured_objs/original-2.obj" />/&gt;
			</geometry>
		</visual>
		<visual name="base_body-14">
			<origin xyz="0 0 0" />
			<geometry>
				<mesh filename="/home/blake/kitchen-worlds/assets/models/Camera/102411/textured_objs/original-16.obj" />/&gt;
			</geometry>
		</visual>
		<visual name="base_body-14">
			<origin xyz="0 0 0" />
			<geometry>
				<mesh filename="/home/blake/kitchen-worlds/assets/models/Camera/102411/textured_objs/original-13.obj" />/&gt;
			</geometry>
		</visual>
		<visual name="base_body-14">
			<origin xyz="0 0 0" />
			<geometry>
				<mesh filename="/home/blake/kitchen-worlds/assets/models/Camera/102411/textured_objs/original-61.obj" />/&gt;
			</geometry>
		</visual>
		<visual name="base_body-14">
			<origin xyz="0 0 0" />
			<geometry>
				<mesh filename="/home/blake/kitchen-worlds/assets/models/Camera/102411/textured_objs/original-59.obj" />/&gt;
			</geometry>
		</visual>
		<visual name="base_body-14">
			<origin xyz="0 0 0" />
			<geometry>
				<mesh filename="/home/blake/kitchen-worlds/assets/models/Camera/102411/textured_objs/original-5.obj" />/&gt;
			</geometry>
		</visual>
		<visual name="base_body-14">
			<origin xyz="0 0 0" />
			<geometry>
				<mesh filename="/home/blake/kitchen-worlds/assets/models/Camera/102411/textured_objs/original-63.obj" />/&gt;
			</geometry>
		</visual>
		<visual name="base_body-14">
			<origin xyz="0 0 0" />
			<geometry>
				<mesh filename="/home/blake/kitchen-worlds/assets/models/Camera/102411/textured_objs/original-51.obj" />/&gt;
			</geometry>
		</visual>
		<visual name="base_body-14">
			<origin xyz="0 0 0" />
			<geometry>
				<mesh filename="/home/blake/kitchen-worlds/assets/models/Camera/102411/textured_objs/original-6.obj" />/&gt;
			</geometry>
		</visual>
		<visual name="base_body-14">
			<origin xyz="0 0 0" />
			<geometry>
				<mesh filename="/home/blake/kitchen-worlds/assets/models/Camera/102411/textured_objs/original-48.obj" />/&gt;
			</geometry>
		</visual>
		<visual name="base_body-14">
			<origin xyz="0 0 0" />
			<geometry>
				<mesh filename="/home/blake/kitchen-worlds/assets/models/Camera/102411/textured_objs/original-15.obj" />/&gt;
			</geometry>
		</visual>
		<visual name="base_body-14">
			<origin xyz="0 0 0" />
			<geometry>
				<mesh filename="/home/blake/kitchen-worlds/assets/models/Camera/102411/textured_objs/original-68.obj" />/&gt;
			</geometry>
		</visual>
		<visual name="base_body-14">
			<origin xyz="0 0 0" />
			<geometry>
				<mesh filename="/home/blake/kitchen-worlds/assets/models/Camera/102411/textured_objs/original-18.obj" />/&gt;
			</geometry>
		</visual>
		<visual name="base_body-14">
			<origin xyz="0 0 0" />
			<geometry>
				<mesh filename="/home/blake/kitchen-worlds/assets/models/Camera/102411/textured_objs/original-70.obj" />/&gt;
			</geometry>
		</visual>
		<visual name="base_body-14">
			<origin xyz="0 0 0" />
			<geometry>
				<mesh filename="/home/blake/kitchen-worlds/assets/models/Camera/102411/textured_objs/original-17.obj" />/&gt;
			</geometry>
		</visual>
		<visual name="base_body-14">
			<origin xyz="0 0 0" />
			<geometry>
				<mesh filename="/home/blake/kitchen-worlds/assets/models/Camera/102411/textured_objs/original-73.obj" />/&gt;
			</geometry>
		</visual>
		<visual name="base_body-14">
			<origin xyz="0 0 0" />
			<geometry>
				<mesh filename="/home/blake/kitchen-worlds/assets/models/Camera/102411/textured_objs/original-20.obj" />/&gt;
			</geometry>
		</visual>
		<visual name="base_body-14">
			<origin xyz="0 0 0" />
			<geometry>
				<mesh filename="/home/blake/kitchen-worlds/assets/models/Camera/102411/textured_objs/original-7.obj" />/&gt;
			</geometry>
		</visual>
		<visual name="base_body-14">
			<origin xyz="0 0 0" />
			<geometry>
				<mesh filename="/home/blake/kitchen-worlds/assets/models/Camera/102411/textured_objs/original-14.obj" />/&gt;
			</geometry>
		</visual>
		<visual name="base_body-14">
			<origin xyz="0 0 0" />
			<geometry>
				<mesh filename="/home/blake/kitchen-worlds/assets/models/Camera/102411/textured_objs/original-60.obj" />/&gt;
			</geometry>
		</visual>
		<visual name="base_body-14">
			<origin xyz="0 0 0" />
			<geometry>
				<mesh filename="/home/blake/kitchen-worlds/assets/models/Camera/102411/textured_objs/original-19.obj" />/&gt;
			</geometry>
		</visual>
		<collision>
			<origin xyz="0 0 0" />
			<geometry>
				<mesh filename="/home/blake/kitchen-worlds/assets/models/Camera/102411/textured_objs/original-64.obj" />/&gt;
			</geometry>
		</collision>
		<collision>
			<origin xyz="0 0 0" />
			<geometry>
				<mesh filename="/home/blake/kitchen-worlds/assets/models/Camera/102411/textured_objs/original-4.obj" />/&gt;
			</geometry>
		</collision>
		<collision>
			<origin xyz="0 0 0" />
			<geometry>
				<mesh filename="/home/blake/kitchen-worlds/assets/models/Camera/102411/textured_objs/original-3.obj" />/&gt;
			</geometry>
		</collision>
		<collision>
			<origin xyz="0 0 0" />
			<geometry>
				<mesh filename="/home/blake/kitchen-worlds/assets/models/Camera/102411/textured_objs/original-65.obj" />/&gt;
			</geometry>
		</collision>
		<collision>
			<origin xyz="0 0 0" />
			<geometry>
				<mesh filename="/home/blake/kitchen-worlds/assets/models/Camera/102411/textured_objs/original-2.obj" />/&gt;
			</geometry>
		</collision>
		<collision>
			<origin xyz="0 0 0" />
			<geometry>
				<mesh filename="/home/blake/kitchen-worlds/assets/models/Camera/102411/textured_objs/original-16.obj" />/&gt;
			</geometry>
		</collision>
		<collision>
			<origin xyz="0 0 0" />
			<geometry>
				<mesh filename="/home/blake/kitchen-worlds/assets/models/Camera/102411/textured_objs/original-13.obj" />/&gt;
			</geometry>
		</collision>
		<collision>
			<origin xyz="0 0 0" />
			<geometry>
				<mesh filename="/home/blake/kitchen-worlds/assets/models/Camera/102411/textured_objs/original-61.obj" />/&gt;
			</geometry>
		</collision>
		<collision>
			<origin xyz="0 0 0" />
			<geometry>
				<mesh filename="/home/blake/kitchen-worlds/assets/models/Camera/102411/textured_objs/original-59.obj" />/&gt;
			</geometry>
		</collision>
		<collision>
			<origin xyz="0 0 0" />
			<geometry>
				<mesh filename="/home/blake/kitchen-worlds/assets/models/Camera/102411/textured_objs/original-5.obj" />/&gt;
			</geometry>
		</collision>
		<collision>
			<origin xyz="0 0 0" />
			<geometry>
				<mesh filename="/home/blake/kitchen-worlds/assets/models/Camera/102411/textured_objs/original-63.obj" />/&gt;
			</geometry>
		</collision>
		<collision>
			<origin xyz="0 0 0" />
			<geometry>
				<mesh filename="/home/blake/kitchen-worlds/assets/models/Camera/102411/textured_objs/original-51.obj" />/&gt;
			</geometry>
		</collision>
		<collision>
			<origin xyz="0 0 0" />
			<geometry>
				<mesh filename="/home/blake/kitchen-worlds/assets/models/Camera/102411/textured_objs/original-6.obj" />/&gt;
			</geometry>
		</collision>
		<collision>
			<origin xyz="0 0 0" />
			<geometry>
				<mesh filename="/home/blake/kitchen-worlds/assets/models/Camera/102411/textured_objs/original-48.obj" />/&gt;
			</geometry>
		</collision>
		<collision>
			<origin xyz="0 0 0" />
			<geometry>
				<mesh filename="/home/blake/kitchen-worlds/assets/models/Camera/102411/textured_objs/original-15.obj" />/&gt;
			</geometry>
		</collision>
		<collision>
			<origin xyz="0 0 0" />
			<geometry>
				<mesh filename="/home/blake/kitchen-worlds/assets/models/Camera/102411/textured_objs/original-68.obj" />/&gt;
			</geometry>
		</collision>
		<collision>
			<origin xyz="0 0 0" />
			<geometry>
				<mesh filename="/home/blake/kitchen-worlds/assets/models/Camera/102411/textured_objs/original-18.obj" />/&gt;
			</geometry>
		</collision>
		<collision>
			<origin xyz="0 0 0" />
			<geometry>
				<mesh filename="/home/blake/kitchen-worlds/assets/models/Camera/102411/textured_objs/original-70.obj" />/&gt;
			</geometry>
		</collision>
		<collision>
			<origin xyz="0 0 0" />
			<geometry>
				<mesh filename="/home/blake/kitchen-worlds/assets/models/Camera/102411/textured_objs/original-17.obj" />/&gt;
			</geometry>
		</collision>
		<collision>
			<origin xyz="0 0 0" />
			<geometry>
				<mesh filename="/home/blake/kitchen-worlds/assets/models/Camera/102411/textured_objs/original-73.obj" />/&gt;
			</geometry>
		</collision>
		<collision>
			<origin xyz="0 0 0" />
			<geometry>
				<mesh filename="/home/blake/kitchen-worlds/assets/models/Camera/102411/textured_objs/original-20.obj" />/&gt;
			</geometry>
		</collision>
		<collision>
			<origin xyz="0 0 0" />
			<geometry>
				<mesh filename="/home/blake/kitchen-worlds/assets/models/Camera/102411/textured_objs/original-7.obj" />/&gt;
			</geometry>
		</collision>
		<collision>
			<origin xyz="0 0 0" />
			<geometry>
				<mesh filename="/home/blake/kitchen-worlds/assets/models/Camera/102411/textured_objs/original-14.obj" />/&gt;
			</geometry>
		</collision>
		<collision>
			<origin xyz="0 0 0" />
			<geometry>
				<mesh filename="/home/blake/kitchen-worlds/assets/models/Camera/102411/textured_objs/original-60.obj" />/&gt;
			</geometry>
		</collision>
		<collision>
			<origin xyz="0 0 0" />
			<geometry>
				<mesh filename="/home/blake/kitchen-worlds/assets/models/Camera/102411/textured_objs/original-19.obj" />/&gt;
			</geometry>
		</collision>
	</link>
	<joint name="joint_12" type="fixed">
		<origin rpy="1.570796326794897 0 -1.570796326794897" xyz="0 0 0" />
		<child link="link_12" />
		<parent link="base" />
	</joint>
</robot>