<?xml version='1.0' encoding='utf-8'?>
<robot name="partnet_2976131e4621231655bf395569b6fd5">
	<link name="base" />
	<link name="link_0">
		<visual name="lid-8">
			<origin xyz="0.0007946263496638418 0 0.00018853385499460838" />
			<geometry>
				<mesh filename="/home/blake/kitchen-worlds/assets/models/VinegarBottle/3615/textured_objs/original-2.obj" />/&gt;
			</geometry>
		</visual>
		<collision>
			<origin xyz="0.0007946263496638418 0 0.00018853385499460838" />
			<geometry>
				<mesh filename="/home/blake/kitchen-worlds/assets/models/VinegarBottle/3615/textured_objs/original-2.obj" />/&gt;
			</geometry>
		</collision>
	</link>
	<joint name="joint_0" type="continuous">
		<origin xyz="0.0 0 0.0" />
		<axis xyz="0 1 0" />
		<child link="link_0" />
		<parent link="link_0_helper" />
	</joint>
	<link name="link_1">
		<visual name="body-6">
			<origin xyz="0 0 0" />
			<geometry>
				<mesh filename="/home/blake/kitchen-worlds/assets/models/VinegarBottle/3615/textured_objs/new-3.obj" />/&gt;
			</geometry>
		</visual>
		<visual name="neck-7">
			<origin xyz="0 0 0" />
			<geometry>
				<mesh filename="/home/blake/kitchen-worlds/assets/models/VinegarBottle/3615/textured_objs/new-0.obj" />/&gt;
			</geometry>
		</visual>
		<visual name="neck-7">
			<origin xyz="0 0 0" />
			<geometry>
				<mesh filename="/home/blake/kitchen-worlds/assets/models/VinegarBottle/3615/textured_objs/new-1.obj" />/&gt;
			</geometry>
		</visual>
		<collision>
			<origin xyz="0 0 0" />
			<geometry>
				<mesh filename="/home/blake/kitchen-worlds/assets/models/VinegarBottle/3615/textured_objs/new-3.obj" />/&gt;
			</geometry>
		</collision>
		<collision>
			<origin xyz="0 0 0" />
			<geometry>
				<mesh filename="/home/blake/kitchen-worlds/assets/models/VinegarBottle/3615/textured_objs/new-0.obj" />/&gt;
			</geometry>
		</collision>
		<collision>
			<origin xyz="0 0 0" />
			<geometry>
				<mesh filename="/home/blake/kitchen-worlds/assets/models/VinegarBottle/3615/textured_objs/new-1.obj" />/&gt;
			</geometry>
		</collision>
	</link>
	<joint name="joint_1" type="fixed">
		<origin rpy="1.570796326794897 0 -1.570796326794897" xyz="0 0 0" />
		<child link="link_1" />
		<parent link="base" />
	</joint>
	<link name="link_0_helper" />
	<joint name="joint_2" type="prismatic">
		<origin xyz="-0.0007946263496638418 0 -0.00018853385499460838" />
		<axis xyz="0 1 0" />
		<child link="link_0_helper" />
		<parent link="link_1" />
		<limit lower="-0.05600000000000005" upper="0" effort="10.0" velocity="1.0" />
	</joint>
</robot>