<?xml version='1.0' encoding='utf-8'?>
<robot name="partnet_1bee7b073a38d30a4c3aee8e9d3a6ffa">
	<link name="base" />
	<link name="link_0">
		<visual name="handle-9">
			<origin xyz="0 0 0" />
			<geometry>
				<mesh filename="/home/blake/kitchen-worlds/assets/models/MiniFridgeBase/45261/textured_objs/original-95.obj" />/&gt;
			</geometry>
		</visual>
		<visual name="handle-9">
			<origin xyz="0 0 0" />
			<geometry>
				<mesh filename="/home/blake/kitchen-worlds/assets/models/MiniFridgeBase/45261/textured_objs/original-96.obj" />/&gt;
			</geometry>
		</visual>
		<visual name="handle-9">
			<origin xyz="0 0 0" />
			<geometry>
				<mesh filename="/home/blake/kitchen-worlds/assets/models/MiniFridgeBase/45261/textured_objs/original-94.obj" />/&gt;
			</geometry>
		</visual>
		<visual name="drawer_front-10">
			<origin xyz="0 0 0" />
			<geometry>
				<mesh filename="/home/blake/kitchen-worlds/assets/models/MiniFridgeBase/45261/textured_objs/original-88.obj" />/&gt;
			</geometry>
		</visual>
		<visual name="drawer_front-10">
			<origin xyz="0 0 0" />
			<geometry>
				<mesh filename="/home/blake/kitchen-worlds/assets/models/MiniFridgeBase/45261/textured_objs/original-92.obj" />/&gt;
			</geometry>
		</visual>
		<visual name="drawer_side-11">
			<origin xyz="0 0 0" />
			<geometry>
				<mesh filename="/home/blake/kitchen-worlds/assets/models/MiniFridgeBase/45261/textured_objs/original-86.obj" />/&gt;
			</geometry>
		</visual>
		<visual name="drawer_side-12">
			<origin xyz="0 0 0" />
			<geometry>
				<mesh filename="/home/blake/kitchen-worlds/assets/models/MiniFridgeBase/45261/textured_objs/original-87.obj" />/&gt;
			</geometry>
		</visual>
		<visual name="drawer_back-13">
			<origin xyz="0 0 0" />
			<geometry>
				<mesh filename="/home/blake/kitchen-worlds/assets/models/MiniFridgeBase/45261/textured_objs/original-89.obj" />/&gt;
			</geometry>
		</visual>
		<visual name="drawer_bottom-21">
			<origin xyz="0 0 0" />
			<geometry>
				<mesh filename="/home/blake/kitchen-worlds/assets/models/MiniFridgeBase/45261/textured_objs/original-84.obj" />/&gt;
			</geometry>
		</visual>
		<visual name="drawer_bottom-21">
			<origin xyz="0 0 0" />
			<geometry>
				<mesh filename="/home/blake/kitchen-worlds/assets/models/MiniFridgeBase/45261/textured_objs/original-85.obj" />/&gt;
			</geometry>
		</visual>
		<collision>
			<origin xyz="0 0 0" />
			<geometry>
				<mesh filename="/home/blake/kitchen-worlds/assets/models/MiniFridgeBase/45261/textured_objs/original-95.obj" />/&gt;
			</geometry>
		</collision>
		<collision>
			<origin xyz="0 0 0" />
			<geometry>
				<mesh filename="/home/blake/kitchen-worlds/assets/models/MiniFridgeBase/45261/textured_objs/original-96.obj" />/&gt;
			</geometry>
		</collision>
		<collision>
			<origin xyz="0 0 0" />
			<geometry>
				<mesh filename="/home/blake/kitchen-worlds/assets/models/MiniFridgeBase/45261/textured_objs/original-94.obj" />/&gt;
			</geometry>
		</collision>
		<collision>
			<origin xyz="0 0 0" />
			<geometry>
				<mesh filename="/home/blake/kitchen-worlds/assets/models/MiniFridgeBase/45261/textured_objs/original-88.obj" />/&gt;
			</geometry>
		</collision>
		<collision>
			<origin xyz="0 0 0" />
			<geometry>
				<mesh filename="/home/blake/kitchen-worlds/assets/models/MiniFridgeBase/45261/textured_objs/original-92.obj" />/&gt;
			</geometry>
		</collision>
		<collision>
			<origin xyz="0 0 0" />
			<geometry>
				<mesh filename="/home/blake/kitchen-worlds/assets/models/MiniFridgeBase/45261/textured_objs/original-86.obj" />/&gt;
			</geometry>
		</collision>
		<collision>
			<origin xyz="0 0 0" />
			<geometry>
				<mesh filename="/home/blake/kitchen-worlds/assets/models/MiniFridgeBase/45261/textured_objs/original-87.obj" />/&gt;
			</geometry>
		</collision>
		<collision>
			<origin xyz="0 0 0" />
			<geometry>
				<mesh filename="/home/blake/kitchen-worlds/assets/models/MiniFridgeBase/45261/textured_objs/original-89.obj" />/&gt;
			</geometry>
		</collision>
		<collision>
			<origin xyz="0 0 0" />
			<geometry>
				<mesh filename="/home/blake/kitchen-worlds/assets/models/MiniFridgeBase/45261/textured_objs/original-84.obj" />/&gt;
			</geometry>
		</collision>
		<collision>
			<origin xyz="0 0 0" />
			<geometry>
				<mesh filename="/home/blake/kitchen-worlds/assets/models/MiniFridgeBase/45261/textured_objs/original-85.obj" />/&gt;
			</geometry>
		</collision>
	</link>
	<joint name="joint_0" type="prismatic">
		<origin xyz="0 0 0" />
		<axis xyz="0 0 1" />
		<child link="link_0" />
		<parent link="link_5" />
		<limit lower="0" upper="0.87" effort="10.0" velocity="1.0" />
	</joint>
	<link name="link_1">
		<visual name="handle-25">
			<origin xyz="0 0 0" />
			<geometry>
				<mesh filename="/home/blake/kitchen-worlds/assets/models/MiniFridgeBase/45261/textured_objs/original-79.obj" />/&gt;
			</geometry>
		</visual>
		<visual name="handle-25">
			<origin xyz="0 0 0" />
			<geometry>
				<mesh filename="/home/blake/kitchen-worlds/assets/models/MiniFridgeBase/45261/textured_objs/original-80.obj" />/&gt;
			</geometry>
		</visual>
		<visual name="handle-25">
			<origin xyz="0 0 0" />
			<geometry>
				<mesh filename="/home/blake/kitchen-worlds/assets/models/MiniFridgeBase/45261/textured_objs/original-78.obj" />/&gt;
			</geometry>
		</visual>
		<visual name="drawer_front-28">
			<origin xyz="0 0 0" />
			<geometry>
				<mesh filename="/home/blake/kitchen-worlds/assets/models/MiniFridgeBase/45261/textured_objs/original-72.obj" />/&gt;
			</geometry>
		</visual>
		<visual name="drawer_front-28">
			<origin xyz="0 0 0" />
			<geometry>
				<mesh filename="/home/blake/kitchen-worlds/assets/models/MiniFridgeBase/45261/textured_objs/original-76.obj" />/&gt;
			</geometry>
		</visual>
		<visual name="drawer_side-29">
			<origin xyz="0 0 0" />
			<geometry>
				<mesh filename="/home/blake/kitchen-worlds/assets/models/MiniFridgeBase/45261/textured_objs/original-70.obj" />/&gt;
			</geometry>
		</visual>
		<visual name="drawer_side-30">
			<origin xyz="0 0 0" />
			<geometry>
				<mesh filename="/home/blake/kitchen-worlds/assets/models/MiniFridgeBase/45261/textured_objs/original-71.obj" />/&gt;
			</geometry>
		</visual>
		<visual name="drawer_back-31">
			<origin xyz="0 0 0" />
			<geometry>
				<mesh filename="/home/blake/kitchen-worlds/assets/models/MiniFridgeBase/45261/textured_objs/original-73.obj" />/&gt;
			</geometry>
		</visual>
		<visual name="drawer_bottom-32">
			<origin xyz="0 0 0" />
			<geometry>
				<mesh filename="/home/blake/kitchen-worlds/assets/models/MiniFridgeBase/45261/textured_objs/original-69.obj" />/&gt;
			</geometry>
		</visual>
		<visual name="drawer_bottom-32">
			<origin xyz="0 0 0" />
			<geometry>
				<mesh filename="/home/blake/kitchen-worlds/assets/models/MiniFridgeBase/45261/textured_objs/original-68.obj" />/&gt;
			</geometry>
		</visual>
		<collision>
			<origin xyz="0 0 0" />
			<geometry>
				<mesh filename="/home/blake/kitchen-worlds/assets/models/MiniFridgeBase/45261/textured_objs/original-79.obj" />/&gt;
			</geometry>
		</collision>
		<collision>
			<origin xyz="0 0 0" />
			<geometry>
				<mesh filename="/home/blake/kitchen-worlds/assets/models/MiniFridgeBase/45261/textured_objs/original-80.obj" />/&gt;
			</geometry>
		</collision>
		<collision>
			<origin xyz="0 0 0" />
			<geometry>
				<mesh filename="/home/blake/kitchen-worlds/assets/models/MiniFridgeBase/45261/textured_objs/original-78.obj" />/&gt;
			</geometry>
		</collision>
		<collision>
			<origin xyz="0 0 0" />
			<geometry>
				<mesh filename="/home/blake/kitchen-worlds/assets/models/MiniFridgeBase/45261/textured_objs/original-72.obj" />/&gt;
			</geometry>
		</collision>
		<collision>
			<origin xyz="0 0 0" />
			<geometry>
				<mesh filename="/home/blake/kitchen-worlds/assets/models/MiniFridgeBase/45261/textured_objs/original-76.obj" />/&gt;
			</geometry>
		</collision>
		<collision>
			<origin xyz="0 0 0" />
			<geometry>
				<mesh filename="/home/blake/kitchen-worlds/assets/models/MiniFridgeBase/45261/textured_objs/original-70.obj" />/&gt;
			</geometry>
		</collision>
		<collision>
			<origin xyz="0 0 0" />
			<geometry>
				<mesh filename="/home/blake/kitchen-worlds/assets/models/MiniFridgeBase/45261/textured_objs/original-71.obj" />/&gt;
			</geometry>
		</collision>
		<collision>
			<origin xyz="0 0 0" />
			<geometry>
				<mesh filename="/home/blake/kitchen-worlds/assets/models/MiniFridgeBase/45261/textured_objs/original-73.obj" />/&gt;
			</geometry>
		</collision>
		<collision>
			<origin xyz="0 0 0" />
			<geometry>
				<mesh filename="/home/blake/kitchen-worlds/assets/models/MiniFridgeBase/45261/textured_objs/original-69.obj" />/&gt;
			</geometry>
		</collision>
		<collision>
			<origin xyz="0 0 0" />
			<geometry>
				<mesh filename="/home/blake/kitchen-worlds/assets/models/MiniFridgeBase/45261/textured_objs/original-68.obj" />/&gt;
			</geometry>
		</collision>
	</link>
	<joint name="joint_1" type="prismatic">
		<origin xyz="0 0 0" />
		<axis xyz="0 0 1" />
		<child link="link_1" />
		<parent link="link_5" />
		<limit lower="0" upper="0.87" effort="10.0" velocity="1.0" />
	</joint>
	<link name="link_2">
		<visual name="handle-34">
			<origin xyz="0 0 0" />
			<geometry>
				<mesh filename="/home/blake/kitchen-worlds/assets/models/MiniFridgeBase/45261/textured_objs/original-63.obj" />/&gt;
			</geometry>
		</visual>
		<visual name="handle-34">
			<origin xyz="0 0 0" />
			<geometry>
				<mesh filename="/home/blake/kitchen-worlds/assets/models/MiniFridgeBase/45261/textured_objs/original-64.obj" />/&gt;
			</geometry>
		</visual>
		<visual name="handle-34">
			<origin xyz="0 0 0" />
			<geometry>
				<mesh filename="/home/blake/kitchen-worlds/assets/models/MiniFridgeBase/45261/textured_objs/original-62.obj" />/&gt;
			</geometry>
		</visual>
		<visual name="drawer_front-37">
			<origin xyz="0 0 0" />
			<geometry>
				<mesh filename="/home/blake/kitchen-worlds/assets/models/MiniFridgeBase/45261/textured_objs/original-60.obj" />/&gt;
			</geometry>
		</visual>
		<visual name="drawer_front-37">
			<origin xyz="0 0 0" />
			<geometry>
				<mesh filename="/home/blake/kitchen-worlds/assets/models/MiniFridgeBase/45261/textured_objs/original-56.obj" />/&gt;
			</geometry>
		</visual>
		<visual name="drawer_side-38">
			<origin xyz="0 0 0" />
			<geometry>
				<mesh filename="/home/blake/kitchen-worlds/assets/models/MiniFridgeBase/45261/textured_objs/original-55.obj" />/&gt;
			</geometry>
		</visual>
		<visual name="drawer_side-39">
			<origin xyz="0 0 0" />
			<geometry>
				<mesh filename="/home/blake/kitchen-worlds/assets/models/MiniFridgeBase/45261/textured_objs/original-54.obj" />/&gt;
			</geometry>
		</visual>
		<visual name="drawer_back-40">
			<origin xyz="0 0 0" />
			<geometry>
				<mesh filename="/home/blake/kitchen-worlds/assets/models/MiniFridgeBase/45261/textured_objs/original-57.obj" />/&gt;
			</geometry>
		</visual>
		<visual name="drawer_bottom-41">
			<origin xyz="0 0 0" />
			<geometry>
				<mesh filename="/home/blake/kitchen-worlds/assets/models/MiniFridgeBase/45261/textured_objs/original-52.obj" />/&gt;
			</geometry>
		</visual>
		<visual name="drawer_bottom-41">
			<origin xyz="0 0 0" />
			<geometry>
				<mesh filename="/home/blake/kitchen-worlds/assets/models/MiniFridgeBase/45261/textured_objs/original-53.obj" />/&gt;
			</geometry>
		</visual>
		<collision>
			<origin xyz="0 0 0" />
			<geometry>
				<mesh filename="/home/blake/kitchen-worlds/assets/models/MiniFridgeBase/45261/textured_objs/original-63.obj" />/&gt;
			</geometry>
		</collision>
		<collision>
			<origin xyz="0 0 0" />
			<geometry>
				<mesh filename="/home/blake/kitchen-worlds/assets/models/MiniFridgeBase/45261/textured_objs/original-64.obj" />/&gt;
			</geometry>
		</collision>
		<collision>
			<origin xyz="0 0 0" />
			<geometry>
				<mesh filename="/home/blake/kitchen-worlds/assets/models/MiniFridgeBase/45261/textured_objs/original-62.obj" />/&gt;
			</geometry>
		</collision>
		<collision>
			<origin xyz="0 0 0" />
			<geometry>
				<mesh filename="/home/blake/kitchen-worlds/assets/models/MiniFridgeBase/45261/textured_objs/original-60.obj" />/&gt;
			</geometry>
		</collision>
		<collision>
			<origin xyz="0 0 0" />
			<geometry>
				<mesh filename="/home/blake/kitchen-worlds/assets/models/MiniFridgeBase/45261/textured_objs/original-56.obj" />/&gt;
			</geometry>
		</collision>
		<collision>
			<origin xyz="0 0 0" />
			<geometry>
				<mesh filename="/home/blake/kitchen-worlds/assets/models/MiniFridgeBase/45261/textured_objs/original-55.obj" />/&gt;
			</geometry>
		</collision>
		<collision>
			<origin xyz="0 0 0" />
			<geometry>
				<mesh filename="/home/blake/kitchen-worlds/assets/models/MiniFridgeBase/45261/textured_objs/original-54.obj" />/&gt;
			</geometry>
		</collision>
		<collision>
			<origin xyz="0 0 0" />
			<geometry>
				<mesh filename="/home/blake/kitchen-worlds/assets/models/MiniFridgeBase/45261/textured_objs/original-57.obj" />/&gt;
			</geometry>
		</collision>
		<collision>
			<origin xyz="0 0 0" />
			<geometry>
				<mesh filename="/home/blake/kitchen-worlds/assets/models/MiniFridgeBase/45261/textured_objs/original-52.obj" />/&gt;
			</geometry>
		</collision>
		<collision>
			<origin xyz="0 0 0" />
			<geometry>
				<mesh filename="/home/blake/kitchen-worlds/assets/models/MiniFridgeBase/45261/textured_objs/original-53.obj" />/&gt;
			</geometry>
		</collision>
	</link>
	<joint name="joint_2" type="prismatic">
		<origin xyz="0 0 0" />
		<axis xyz="0 0 1" />
		<child link="link_2" />
		<parent link="link_5" />
		<limit lower="0" upper="0.87" effort="10.0" velocity="1.0" />
	</joint>
	<link name="link_3">
		<visual name="handle-43">
			<origin xyz="0 0 0" />
			<geometry>
				<mesh filename="/home/blake/kitchen-worlds/assets/models/MiniFridgeBase/45261/textured_objs/original-46.obj" />/&gt;
			</geometry>
		</visual>
		<visual name="handle-43">
			<origin xyz="0 0 0" />
			<geometry>
				<mesh filename="/home/blake/kitchen-worlds/assets/models/MiniFridgeBase/45261/textured_objs/original-47.obj" />/&gt;
			</geometry>
		</visual>
		<visual name="handle-43">
			<origin xyz="0 0 0" />
			<geometry>
				<mesh filename="/home/blake/kitchen-worlds/assets/models/MiniFridgeBase/45261/textured_objs/original-48.obj" />/&gt;
			</geometry>
		</visual>
		<visual name="drawer_front-46">
			<origin xyz="0 0 0" />
			<geometry>
				<mesh filename="/home/blake/kitchen-worlds/assets/models/MiniFridgeBase/45261/textured_objs/original-44.obj" />/&gt;
			</geometry>
		</visual>
		<visual name="drawer_front-46">
			<origin xyz="0 0 0" />
			<geometry>
				<mesh filename="/home/blake/kitchen-worlds/assets/models/MiniFridgeBase/45261/textured_objs/original-40.obj" />/&gt;
			</geometry>
		</visual>
		<visual name="drawer_side-47">
			<origin xyz="0 0 0" />
			<geometry>
				<mesh filename="/home/blake/kitchen-worlds/assets/models/MiniFridgeBase/45261/textured_objs/original-39.obj" />/&gt;
			</geometry>
		</visual>
		<visual name="drawer_side-48">
			<origin xyz="0 0 0" />
			<geometry>
				<mesh filename="/home/blake/kitchen-worlds/assets/models/MiniFridgeBase/45261/textured_objs/original-38.obj" />/&gt;
			</geometry>
		</visual>
		<visual name="drawer_back-49">
			<origin xyz="0 0 0" />
			<geometry>
				<mesh filename="/home/blake/kitchen-worlds/assets/models/MiniFridgeBase/45261/textured_objs/original-41.obj" />/&gt;
			</geometry>
		</visual>
		<visual name="drawer_bottom-50">
			<origin xyz="0 0 0" />
			<geometry>
				<mesh filename="/home/blake/kitchen-worlds/assets/models/MiniFridgeBase/45261/textured_objs/original-36.obj" />/&gt;
			</geometry>
		</visual>
		<visual name="drawer_bottom-50">
			<origin xyz="0 0 0" />
			<geometry>
				<mesh filename="/home/blake/kitchen-worlds/assets/models/MiniFridgeBase/45261/textured_objs/original-37.obj" />/&gt;
			</geometry>
		</visual>
		<collision>
			<origin xyz="0 0 0" />
			<geometry>
				<mesh filename="/home/blake/kitchen-worlds/assets/models/MiniFridgeBase/45261/textured_objs/original-46.obj" />/&gt;
			</geometry>
		</collision>
		<collision>
			<origin xyz="0 0 0" />
			<geometry>
				<mesh filename="/home/blake/kitchen-worlds/assets/models/MiniFridgeBase/45261/textured_objs/original-47.obj" />/&gt;
			</geometry>
		</collision>
		<collision>
			<origin xyz="0 0 0" />
			<geometry>
				<mesh filename="/home/blake/kitchen-worlds/assets/models/MiniFridgeBase/45261/textured_objs/original-48.obj" />/&gt;
			</geometry>
		</collision>
		<collision>
			<origin xyz="0 0 0" />
			<geometry>
				<mesh filename="/home/blake/kitchen-worlds/assets/models/MiniFridgeBase/45261/textured_objs/original-44.obj" />/&gt;
			</geometry>
		</collision>
		<collision>
			<origin xyz="0 0 0" />
			<geometry>
				<mesh filename="/home/blake/kitchen-worlds/assets/models/MiniFridgeBase/45261/textured_objs/original-40.obj" />/&gt;
			</geometry>
		</collision>
		<collision>
			<origin xyz="0 0 0" />
			<geometry>
				<mesh filename="/home/blake/kitchen-worlds/assets/models/MiniFridgeBase/45261/textured_objs/original-39.obj" />/&gt;
			</geometry>
		</collision>
		<collision>
			<origin xyz="0 0 0" />
			<geometry>
				<mesh filename="/home/blake/kitchen-worlds/assets/models/MiniFridgeBase/45261/textured_objs/original-38.obj" />/&gt;
			</geometry>
		</collision>
		<collision>
			<origin xyz="0 0 0" />
			<geometry>
				<mesh filename="/home/blake/kitchen-worlds/assets/models/MiniFridgeBase/45261/textured_objs/original-41.obj" />/&gt;
			</geometry>
		</collision>
		<collision>
			<origin xyz="0 0 0" />
			<geometry>
				<mesh filename="/home/blake/kitchen-worlds/assets/models/MiniFridgeBase/45261/textured_objs/original-36.obj" />/&gt;
			</geometry>
		</collision>
		<collision>
			<origin xyz="0 0 0" />
			<geometry>
				<mesh filename="/home/blake/kitchen-worlds/assets/models/MiniFridgeBase/45261/textured_objs/original-37.obj" />/&gt;
			</geometry>
		</collision>
	</link>
	<joint name="joint_3" type="prismatic">
		<origin xyz="0 0 0" />
		<axis xyz="0 0 1" />
		<child link="link_3" />
		<parent link="link_5" />
		<limit lower="0" upper="0.87" effort="10.0" velocity="1.0" />
	</joint>
	<link name="link_4">
		<visual name="handle-52">
			<origin xyz="0 0 0" />
			<geometry>
				<mesh filename="/home/blake/kitchen-worlds/assets/models/MiniFridgeBase/45261/textured_objs/original-30.obj" />/&gt;
			</geometry>
		</visual>
		<visual name="handle-52">
			<origin xyz="0 0 0" />
			<geometry>
				<mesh filename="/home/blake/kitchen-worlds/assets/models/MiniFridgeBase/45261/textured_objs/original-31.obj" />/&gt;
			</geometry>
		</visual>
		<visual name="handle-52">
			<origin xyz="0 0 0" />
			<geometry>
				<mesh filename="/home/blake/kitchen-worlds/assets/models/MiniFridgeBase/45261/textured_objs/original-32.obj" />/&gt;
			</geometry>
		</visual>
		<visual name="drawer_front-55">
			<origin xyz="0 0 0" />
			<geometry>
				<mesh filename="/home/blake/kitchen-worlds/assets/models/MiniFridgeBase/45261/textured_objs/original-18.obj" />/&gt;
			</geometry>
		</visual>
		<visual name="drawer_front-55">
			<origin xyz="0 0 0" />
			<geometry>
				<mesh filename="/home/blake/kitchen-worlds/assets/models/MiniFridgeBase/45261/textured_objs/original-25.obj" />/&gt;
			</geometry>
		</visual>
		<visual name="drawer_side-56">
			<origin xyz="0 0 0" />
			<geometry>
				<mesh filename="/home/blake/kitchen-worlds/assets/models/MiniFridgeBase/45261/textured_objs/original-24.obj" />/&gt;
			</geometry>
		</visual>
		<visual name="drawer_side-57">
			<origin xyz="0 0 0" />
			<geometry>
				<mesh filename="/home/blake/kitchen-worlds/assets/models/MiniFridgeBase/45261/textured_objs/original-23.obj" />/&gt;
			</geometry>
		</visual>
		<visual name="drawer_back-58">
			<origin xyz="0 0 0" />
			<geometry>
				<mesh filename="/home/blake/kitchen-worlds/assets/models/MiniFridgeBase/45261/textured_objs/original-26.obj" />/&gt;
			</geometry>
		</visual>
		<visual name="drawer_bottom-59">
			<origin xyz="0 0 0" />
			<geometry>
				<mesh filename="/home/blake/kitchen-worlds/assets/models/MiniFridgeBase/45261/textured_objs/original-21.obj" />/&gt;
			</geometry>
		</visual>
		<visual name="drawer_bottom-59">
			<origin xyz="0 0 0" />
			<geometry>
				<mesh filename="/home/blake/kitchen-worlds/assets/models/MiniFridgeBase/45261/textured_objs/original-22.obj" />/&gt;
			</geometry>
		</visual>
		<collision>
			<origin xyz="0 0 0" />
			<geometry>
				<mesh filename="/home/blake/kitchen-worlds/assets/models/MiniFridgeBase/45261/textured_objs/original-30.obj" />/&gt;
			</geometry>
		</collision>
		<collision>
			<origin xyz="0 0 0" />
			<geometry>
				<mesh filename="/home/blake/kitchen-worlds/assets/models/MiniFridgeBase/45261/textured_objs/original-31.obj" />/&gt;
			</geometry>
		</collision>
		<collision>
			<origin xyz="0 0 0" />
			<geometry>
				<mesh filename="/home/blake/kitchen-worlds/assets/models/MiniFridgeBase/45261/textured_objs/original-32.obj" />/&gt;
			</geometry>
		</collision>
		<collision>
			<origin xyz="0 0 0" />
			<geometry>
				<mesh filename="/home/blake/kitchen-worlds/assets/models/MiniFridgeBase/45261/textured_objs/original-18.obj" />/&gt;
			</geometry>
		</collision>
		<collision>
			<origin xyz="0 0 0" />
			<geometry>
				<mesh filename="/home/blake/kitchen-worlds/assets/models/MiniFridgeBase/45261/textured_objs/original-25.obj" />/&gt;
			</geometry>
		</collision>
		<collision>
			<origin xyz="0 0 0" />
			<geometry>
				<mesh filename="/home/blake/kitchen-worlds/assets/models/MiniFridgeBase/45261/textured_objs/original-24.obj" />/&gt;
			</geometry>
		</collision>
		<collision>
			<origin xyz="0 0 0" />
			<geometry>
				<mesh filename="/home/blake/kitchen-worlds/assets/models/MiniFridgeBase/45261/textured_objs/original-23.obj" />/&gt;
			</geometry>
		</collision>
		<collision>
			<origin xyz="0 0 0" />
			<geometry>
				<mesh filename="/home/blake/kitchen-worlds/assets/models/MiniFridgeBase/45261/textured_objs/original-26.obj" />/&gt;
			</geometry>
		</collision>
		<collision>
			<origin xyz="0 0 0" />
			<geometry>
				<mesh filename="/home/blake/kitchen-worlds/assets/models/MiniFridgeBase/45261/textured_objs/original-21.obj" />/&gt;
			</geometry>
		</collision>
		<collision>
			<origin xyz="0 0 0" />
			<geometry>
				<mesh filename="/home/blake/kitchen-worlds/assets/models/MiniFridgeBase/45261/textured_objs/original-22.obj" />/&gt;
			</geometry>
		</collision>
	</link>
	<joint name="joint_4" type="prismatic">
		<origin xyz="0 0 0" />
		<axis xyz="0 0 1" />
		<child link="link_4" />
		<parent link="link_5" />
		<limit lower="0" upper="0.87" effort="10.0" velocity="1.0" />
	</joint>
	<link name="link_5">
		<visual name="vertical_side_panel-16">
			<origin xyz="0 0 0" />
			<geometry>
				<mesh filename="/home/blake/kitchen-worlds/assets/models/MiniFridgeBase/45261/textured_objs/original-7.obj" />/&gt;
			</geometry>
		</visual>
		<visual name="vertical_side_panel-17">
			<origin xyz="0 0 0" />
			<geometry>
				<mesh filename="/home/blake/kitchen-worlds/assets/models/MiniFridgeBase/45261/textured_objs/original-4.obj" />/&gt;
			</geometry>
		</visual>
		<visual name="back_panel-18">
			<origin xyz="0 0 0" />
			<geometry>
				<mesh filename="/home/blake/kitchen-worlds/assets/models/MiniFridgeBase/45261/textured_objs/original-15.obj" />/&gt;
			</geometry>
		</visual>
		<visual name="back_panel-18">
			<origin xyz="0 0 0" />
			<geometry>
				<mesh filename="/home/blake/kitchen-worlds/assets/models/MiniFridgeBase/45261/textured_objs/original-14.obj" />/&gt;
			</geometry>
		</visual>
		<visual name="back_panel-18">
			<origin xyz="0 0 0" />
			<geometry>
				<mesh filename="/home/blake/kitchen-worlds/assets/models/MiniFridgeBase/45261/textured_objs/original-16.obj" />/&gt;
			</geometry>
		</visual>
		<visual name="bottom_panel-19">
			<origin xyz="0 0 0" />
			<geometry>
				<mesh filename="/home/blake/kitchen-worlds/assets/models/MiniFridgeBase/45261/textured_objs/original-10.obj" />/&gt;
			</geometry>
		</visual>
		<visual name="top_panel-20">
			<origin xyz="0 0 0" />
			<geometry>
				<mesh filename="/home/blake/kitchen-worlds/assets/models/MiniFridgeBase/45261/textured_objs/original-13.obj" />/&gt;
			</geometry>
		</visual>
		<visual name="frame_vertical_bar-60">
			<origin xyz="0 0 0" />
			<geometry>
				<mesh filename="/home/blake/kitchen-worlds/assets/models/MiniFridgeBase/45261/textured_objs/original-6.obj" />/&gt;
			</geometry>
		</visual>
		<visual name="frame_vertical_bar-61">
			<origin xyz="0 0 0" />
			<geometry>
				<mesh filename="/home/blake/kitchen-worlds/assets/models/MiniFridgeBase/45261/textured_objs/original-3.obj" />/&gt;
			</geometry>
		</visual>
		<visual name="frame_horizontal_bar-62">
			<origin xyz="0 0 0" />
			<geometry>
				<mesh filename="/home/blake/kitchen-worlds/assets/models/MiniFridgeBase/45261/textured_objs/original-9.obj" />/&gt;
			</geometry>
		</visual>
		<visual name="frame_horizontal_bar-63">
			<origin xyz="0 0 0" />
			<geometry>
				<mesh filename="/home/blake/kitchen-worlds/assets/models/MiniFridgeBase/45261/textured_objs/original-12.obj" />/&gt;
			</geometry>
		</visual>
		<visual name="drawer_rails-53">
			<origin xyz="0 0 0" />
			<geometry>
				<mesh filename="/home/blake/kitchen-worlds/assets/models/MiniFridgeBase/45261/textured_objs/original-27.obj" />/&gt;
			</geometry>
		</visual>
		<visual name="drawer_rails-54">
			<origin xyz="0 0 0" />
			<geometry>
				<mesh filename="/home/blake/kitchen-worlds/assets/models/MiniFridgeBase/45261/textured_objs/original-28.obj" />/&gt;
			</geometry>
		</visual>
		<visual name="drawer_rails-44">
			<origin xyz="0 0 0" />
			<geometry>
				<mesh filename="/home/blake/kitchen-worlds/assets/models/MiniFridgeBase/45261/textured_objs/original-42.obj" />/&gt;
			</geometry>
		</visual>
		<visual name="drawer_rails-45">
			<origin xyz="0 0 0" />
			<geometry>
				<mesh filename="/home/blake/kitchen-worlds/assets/models/MiniFridgeBase/45261/textured_objs/original-43.obj" />/&gt;
			</geometry>
		</visual>
		<visual name="drawer_rails-35">
			<origin xyz="0 0 0" />
			<geometry>
				<mesh filename="/home/blake/kitchen-worlds/assets/models/MiniFridgeBase/45261/textured_objs/original-58.obj" />/&gt;
			</geometry>
		</visual>
		<visual name="drawer_rails-36">
			<origin xyz="0 0 0" />
			<geometry>
				<mesh filename="/home/blake/kitchen-worlds/assets/models/MiniFridgeBase/45261/textured_objs/original-59.obj" />/&gt;
			</geometry>
		</visual>
		<visual name="drawer_rails-26">
			<origin xyz="0 0 0" />
			<geometry>
				<mesh filename="/home/blake/kitchen-worlds/assets/models/MiniFridgeBase/45261/textured_objs/original-74.obj" />/&gt;
			</geometry>
		</visual>
		<visual name="drawer_rails-27">
			<origin xyz="0 0 0" />
			<geometry>
				<mesh filename="/home/blake/kitchen-worlds/assets/models/MiniFridgeBase/45261/textured_objs/original-75.obj" />/&gt;
			</geometry>
		</visual>
		<visual name="drawer_rails-22">
			<origin xyz="0 0 0" />
			<geometry>
				<mesh filename="/home/blake/kitchen-worlds/assets/models/MiniFridgeBase/45261/textured_objs/original-90.obj" />/&gt;
			</geometry>
		</visual>
		<visual name="drawer_rails-23">
			<origin xyz="0 0 0" />
			<geometry>
				<mesh filename="/home/blake/kitchen-worlds/assets/models/MiniFridgeBase/45261/textured_objs/original-91.obj" />/&gt;
			</geometry>
		</visual>
		<collision>
			<origin xyz="0 0 0" />
			<geometry>
				<mesh filename="/home/blake/kitchen-worlds/assets/models/MiniFridgeBase/45261/textured_objs/original-7.obj" />/&gt;
			</geometry>
		</collision>
		<collision>
			<origin xyz="0 0 0" />
			<geometry>
				<mesh filename="/home/blake/kitchen-worlds/assets/models/MiniFridgeBase/45261/textured_objs/original-4.obj" />/&gt;
			</geometry>
		</collision>
		<collision>
			<origin xyz="0 0 0" />
			<geometry>
				<mesh filename="/home/blake/kitchen-worlds/assets/models/MiniFridgeBase/45261/textured_objs/original-15.obj" />/&gt;
			</geometry>
		</collision>
		<collision>
			<origin xyz="0 0 0" />
			<geometry>
				<mesh filename="/home/blake/kitchen-worlds/assets/models/MiniFridgeBase/45261/textured_objs/original-14.obj" />/&gt;
			</geometry>
		</collision>
		<collision>
			<origin xyz="0 0 0" />
			<geometry>
				<mesh filename="/home/blake/kitchen-worlds/assets/models/MiniFridgeBase/45261/textured_objs/original-16.obj" />/&gt;
			</geometry>
		</collision>
		<collision>
			<origin xyz="0 0 0" />
			<geometry>
				<mesh filename="/home/blake/kitchen-worlds/assets/models/MiniFridgeBase/45261/textured_objs/original-10.obj" />/&gt;
			</geometry>
		</collision>
		<collision>
			<origin xyz="0 0 0" />
			<geometry>
				<mesh filename="/home/blake/kitchen-worlds/assets/models/MiniFridgeBase/45261/textured_objs/original-13.obj" />/&gt;
			</geometry>
		</collision>
		<collision>
			<origin xyz="0 0 0" />
			<geometry>
				<mesh filename="/home/blake/kitchen-worlds/assets/models/MiniFridgeBase/45261/textured_objs/original-6.obj" />/&gt;
			</geometry>
		</collision>
		<collision>
			<origin xyz="0 0 0" />
			<geometry>
				<mesh filename="/home/blake/kitchen-worlds/assets/models/MiniFridgeBase/45261/textured_objs/original-3.obj" />/&gt;
			</geometry>
		</collision>
		<collision>
			<origin xyz="0 0 0" />
			<geometry>
				<mesh filename="/home/blake/kitchen-worlds/assets/models/MiniFridgeBase/45261/textured_objs/original-9.obj" />/&gt;
			</geometry>
		</collision>
		<collision>
			<origin xyz="0 0 0" />
			<geometry>
				<mesh filename="/home/blake/kitchen-worlds/assets/models/MiniFridgeBase/45261/textured_objs/original-12.obj" />/&gt;
			</geometry>
		</collision>
		<collision>
			<origin xyz="0 0 0" />
			<geometry>
				<mesh filename="/home/blake/kitchen-worlds/assets/models/MiniFridgeBase/45261/textured_objs/original-27.obj" />/&gt;
			</geometry>
		</collision>
		<collision>
			<origin xyz="0 0 0" />
			<geometry>
				<mesh filename="/home/blake/kitchen-worlds/assets/models/MiniFridgeBase/45261/textured_objs/original-28.obj" />/&gt;
			</geometry>
		</collision>
		<collision>
			<origin xyz="0 0 0" />
			<geometry>
				<mesh filename="/home/blake/kitchen-worlds/assets/models/MiniFridgeBase/45261/textured_objs/original-42.obj" />/&gt;
			</geometry>
		</collision>
		<collision>
			<origin xyz="0 0 0" />
			<geometry>
				<mesh filename="/home/blake/kitchen-worlds/assets/models/MiniFridgeBase/45261/textured_objs/original-43.obj" />/&gt;
			</geometry>
		</collision>
		<collision>
			<origin xyz="0 0 0" />
			<geometry>
				<mesh filename="/home/blake/kitchen-worlds/assets/models/MiniFridgeBase/45261/textured_objs/original-58.obj" />/&gt;
			</geometry>
		</collision>
		<collision>
			<origin xyz="0 0 0" />
			<geometry>
				<mesh filename="/home/blake/kitchen-worlds/assets/models/MiniFridgeBase/45261/textured_objs/original-59.obj" />/&gt;
			</geometry>
		</collision>
		<collision>
			<origin xyz="0 0 0" />
			<geometry>
				<mesh filename="/home/blake/kitchen-worlds/assets/models/MiniFridgeBase/45261/textured_objs/original-74.obj" />/&gt;
			</geometry>
		</collision>
		<collision>
			<origin xyz="0 0 0" />
			<geometry>
				<mesh filename="/home/blake/kitchen-worlds/assets/models/MiniFridgeBase/45261/textured_objs/original-75.obj" />/&gt;
			</geometry>
		</collision>
		<collision>
			<origin xyz="0 0 0" />
			<geometry>
				<mesh filename="/home/blake/kitchen-worlds/assets/models/MiniFridgeBase/45261/textured_objs/original-90.obj" />/&gt;
			</geometry>
		</collision>
		<collision>
			<origin xyz="0 0 0" />
			<geometry>
				<mesh filename="/home/blake/kitchen-worlds/assets/models/MiniFridgeBase/45261/textured_objs/original-91.obj" />/&gt;
			</geometry>
		</collision>
	</link>
	<joint name="joint_5" type="fixed">
		<origin rpy="1.570796326794897 0 -1.570796326794897" xyz="0 0 0" />
		<child link="link_5" />
		<parent link="base" />
	</joint>
</robot>