<?xml version='1.0' encoding='utf-8'?>
<robot name="partnet_79b7bd0c910e833ba5dde908aa701435">
	<link name="base" />
	<link name="link_0">
		<visual name="drawer_front-70">
			<origin xyz="0 0 0" />
			<geometry>
				<mesh filename="/home/blake/kitchen-worlds/assets/models/KitchenCounter/26608/textured_objs/original-28.obj" />/&gt;
			</geometry>
		</visual>
		<visual name="drawer_side-71">
			<origin xyz="0 0 0" />
			<geometry>
				<mesh filename="/home/blake/kitchen-worlds/assets/models/KitchenCounter/26608/textured_objs/original-17.obj" />/&gt;
			</geometry>
		</visual>
		<visual name="drawer_side-72">
			<origin xyz="0 0 0" />
			<geometry>
				<mesh filename="/home/blake/kitchen-worlds/assets/models/KitchenCounter/26608/textured_objs/original-32.obj" />/&gt;
			</geometry>
		</visual>
		<visual name="drawer_bottom-73">
			<origin xyz="0 0 0" />
			<geometry>
				<mesh filename="/home/blake/kitchen-worlds/assets/models/KitchenCounter/26608/textured_objs/original-23.obj" />/&gt;
			</geometry>
		</visual>
		<collision>
			<origin xyz="0 0 0" />
			<geometry>
				<mesh filename="/home/blake/kitchen-worlds/assets/models/KitchenCounter/26608/textured_objs/original-28.obj" />/&gt;
			</geometry>
		</collision>
		<collision>
			<origin xyz="0 0 0" />
			<geometry>
				<mesh filename="/home/blake/kitchen-worlds/assets/models/KitchenCounter/26608/textured_objs/original-17.obj" />/&gt;
			</geometry>
		</collision>
		<collision>
			<origin xyz="0 0 0" />
			<geometry>
				<mesh filename="/home/blake/kitchen-worlds/assets/models/KitchenCounter/26608/textured_objs/original-32.obj" />/&gt;
			</geometry>
		</collision>
		<collision>
			<origin xyz="0 0 0" />
			<geometry>
				<mesh filename="/home/blake/kitchen-worlds/assets/models/KitchenCounter/26608/textured_objs/original-23.obj" />/&gt;
			</geometry>
		</collision>
	</link>
	<joint name="joint_0" type="prismatic">
		<origin xyz="0 0 0" />
		<axis xyz="0 0 -1" />
		<child link="link_0" />
		<parent link="link_8" />
		<limit lower="0" upper="0.23199999999999998" effort="10.0" velocity="1.0" />
	</joint>
	<link name="link_1">
		<visual name="drawer_front-65">
			<origin xyz="0 0 0" />
			<geometry>
				<mesh filename="/home/blake/kitchen-worlds/assets/models/KitchenCounter/26608/textured_objs/original-27.obj" />/&gt;
			</geometry>
		</visual>
		<visual name="drawer_side-66">
			<origin xyz="0 0 0" />
			<geometry>
				<mesh filename="/home/blake/kitchen-worlds/assets/models/KitchenCounter/26608/textured_objs/original-8.obj" />/&gt;
			</geometry>
		</visual>
		<visual name="drawer_side-67">
			<origin xyz="0 0 0" />
			<geometry>
				<mesh filename="/home/blake/kitchen-worlds/assets/models/KitchenCounter/26608/textured_objs/original-30.obj" />/&gt;
			</geometry>
		</visual>
		<visual name="drawer_bottom-68">
			<origin xyz="0 0 0" />
			<geometry>
				<mesh filename="/home/blake/kitchen-worlds/assets/models/KitchenCounter/26608/textured_objs/original-14.obj" />/&gt;
			</geometry>
		</visual>
		<collision>
			<origin xyz="0 0 0" />
			<geometry>
				<mesh filename="/home/blake/kitchen-worlds/assets/models/KitchenCounter/26608/textured_objs/original-27.obj" />/&gt;
			</geometry>
		</collision>
		<collision>
			<origin xyz="0 0 0" />
			<geometry>
				<mesh filename="/home/blake/kitchen-worlds/assets/models/KitchenCounter/26608/textured_objs/original-8.obj" />/&gt;
			</geometry>
		</collision>
		<collision>
			<origin xyz="0 0 0" />
			<geometry>
				<mesh filename="/home/blake/kitchen-worlds/assets/models/KitchenCounter/26608/textured_objs/original-30.obj" />/&gt;
			</geometry>
		</collision>
		<collision>
			<origin xyz="0 0 0" />
			<geometry>
				<mesh filename="/home/blake/kitchen-worlds/assets/models/KitchenCounter/26608/textured_objs/original-14.obj" />/&gt;
			</geometry>
		</collision>
	</link>
	<joint name="joint_1" type="prismatic">
		<origin xyz="0 0 0" />
		<axis xyz="0 0 -1" />
		<child link="link_1" />
		<parent link="link_8" />
		<limit lower="0" upper="0.23199999999999998" effort="10.0" velocity="1.0" />
	</joint>
	<link name="link_2">
		<visual name="drawer_front-60">
			<origin xyz="0 0 0" />
			<geometry>
				<mesh filename="/home/blake/kitchen-worlds/assets/models/KitchenCounter/26608/textured_objs/original-26.obj" />/&gt;
			</geometry>
		</visual>
		<visual name="drawer_side-61">
			<origin xyz="0 0 0" />
			<geometry>
				<mesh filename="/home/blake/kitchen-worlds/assets/models/KitchenCounter/26608/textured_objs/original-77.obj" />/&gt;
			</geometry>
		</visual>
		<visual name="drawer_side-62">
			<origin xyz="0 0 0" />
			<geometry>
				<mesh filename="/home/blake/kitchen-worlds/assets/models/KitchenCounter/26608/textured_objs/original-64.obj" />/&gt;
			</geometry>
		</visual>
		<visual name="drawer_bottom-63">
			<origin xyz="0 0 0" />
			<geometry>
				<mesh filename="/home/blake/kitchen-worlds/assets/models/KitchenCounter/26608/textured_objs/original-83.obj" />/&gt;
			</geometry>
		</visual>
		<collision>
			<origin xyz="0 0 0" />
			<geometry>
				<mesh filename="/home/blake/kitchen-worlds/assets/models/KitchenCounter/26608/textured_objs/original-26.obj" />/&gt;
			</geometry>
		</collision>
		<collision>
			<origin xyz="0 0 0" />
			<geometry>
				<mesh filename="/home/blake/kitchen-worlds/assets/models/KitchenCounter/26608/textured_objs/original-77.obj" />/&gt;
			</geometry>
		</collision>
		<collision>
			<origin xyz="0 0 0" />
			<geometry>
				<mesh filename="/home/blake/kitchen-worlds/assets/models/KitchenCounter/26608/textured_objs/original-64.obj" />/&gt;
			</geometry>
		</collision>
		<collision>
			<origin xyz="0 0 0" />
			<geometry>
				<mesh filename="/home/blake/kitchen-worlds/assets/models/KitchenCounter/26608/textured_objs/original-83.obj" />/&gt;
			</geometry>
		</collision>
	</link>
	<joint name="joint_2" type="prismatic">
		<origin xyz="0 0 0" />
		<axis xyz="0 0 -1" />
		<child link="link_2" />
		<parent link="link_8" />
		<limit lower="0" upper="0.23199999999999998" effort="10.0" velocity="1.0" />
	</joint>
	<link name="link_3">
		<visual name="drawer_front-55">
			<origin xyz="0 0 0" />
			<geometry>
				<mesh filename="/home/blake/kitchen-worlds/assets/models/KitchenCounter/26608/textured_objs/original-52.obj" />/&gt;
			</geometry>
		</visual>
		<visual name="drawer_side-56">
			<origin xyz="0 0 0" />
			<geometry>
				<mesh filename="/home/blake/kitchen-worlds/assets/models/KitchenCounter/26608/textured_objs/original-62.obj" />/&gt;
			</geometry>
		</visual>
		<visual name="drawer_side-57">
			<origin xyz="0 0 0" />
			<geometry>
				<mesh filename="/home/blake/kitchen-worlds/assets/models/KitchenCounter/26608/textured_objs/original-66.obj" />/&gt;
			</geometry>
		</visual>
		<visual name="drawer_bottom-58">
			<origin xyz="0 0 0" />
			<geometry>
				<mesh filename="/home/blake/kitchen-worlds/assets/models/KitchenCounter/26608/textured_objs/original-51.obj" />/&gt;
			</geometry>
		</visual>
		<collision>
			<origin xyz="0 0 0" />
			<geometry>
				<mesh filename="/home/blake/kitchen-worlds/assets/models/KitchenCounter/26608/textured_objs/original-52.obj" />/&gt;
			</geometry>
		</collision>
		<collision>
			<origin xyz="0 0 0" />
			<geometry>
				<mesh filename="/home/blake/kitchen-worlds/assets/models/KitchenCounter/26608/textured_objs/original-62.obj" />/&gt;
			</geometry>
		</collision>
		<collision>
			<origin xyz="0 0 0" />
			<geometry>
				<mesh filename="/home/blake/kitchen-worlds/assets/models/KitchenCounter/26608/textured_objs/original-66.obj" />/&gt;
			</geometry>
		</collision>
		<collision>
			<origin xyz="0 0 0" />
			<geometry>
				<mesh filename="/home/blake/kitchen-worlds/assets/models/KitchenCounter/26608/textured_objs/original-51.obj" />/&gt;
			</geometry>
		</collision>
	</link>
	<joint name="joint_3" type="prismatic">
		<origin xyz="0 0 0" />
		<axis xyz="0 0 -1" />
		<child link="link_3" />
		<parent link="link_8" />
		<limit lower="0" upper="0.23199999999999998" effort="10.0" velocity="1.0" />
	</joint>
	<link name="link_4">
		<visual name="drawer_front-50">
			<origin xyz="0 0 0" />
			<geometry>
				<mesh filename="/home/blake/kitchen-worlds/assets/models/KitchenCounter/26608/textured_objs/original-53.obj" />/&gt;
			</geometry>
		</visual>
		<visual name="drawer_side-51">
			<origin xyz="0 0 0" />
			<geometry>
				<mesh filename="/home/blake/kitchen-worlds/assets/models/KitchenCounter/26608/textured_objs/original-110.obj" />/&gt;
			</geometry>
		</visual>
		<visual name="drawer_side-52">
			<origin xyz="0 0 0" />
			<geometry>
				<mesh filename="/home/blake/kitchen-worlds/assets/models/KitchenCounter/26608/textured_objs/original-106.obj" />/&gt;
			</geometry>
		</visual>
		<visual name="drawer_bottom-53">
			<origin xyz="0 0 0" />
			<geometry>
				<mesh filename="/home/blake/kitchen-worlds/assets/models/KitchenCounter/26608/textured_objs/original-59.obj" />/&gt;
			</geometry>
		</visual>
		<collision>
			<origin xyz="0 0 0" />
			<geometry>
				<mesh filename="/home/blake/kitchen-worlds/assets/models/KitchenCounter/26608/textured_objs/original-53.obj" />/&gt;
			</geometry>
		</collision>
		<collision>
			<origin xyz="0 0 0" />
			<geometry>
				<mesh filename="/home/blake/kitchen-worlds/assets/models/KitchenCounter/26608/textured_objs/original-110.obj" />/&gt;
			</geometry>
		</collision>
		<collision>
			<origin xyz="0 0 0" />
			<geometry>
				<mesh filename="/home/blake/kitchen-worlds/assets/models/KitchenCounter/26608/textured_objs/original-106.obj" />/&gt;
			</geometry>
		</collision>
		<collision>
			<origin xyz="0 0 0" />
			<geometry>
				<mesh filename="/home/blake/kitchen-worlds/assets/models/KitchenCounter/26608/textured_objs/original-59.obj" />/&gt;
			</geometry>
		</collision>
	</link>
	<joint name="joint_4" type="prismatic">
		<origin xyz="0 0 0" />
		<axis xyz="0 0 1" />
		<child link="link_4" />
		<parent link="link_8" />
		<limit lower="0" upper="0.23199999999999998" effort="10.0" velocity="1.0" />
	</joint>
	<link name="link_5">
		<visual name="drawer_front-45">
			<origin xyz="0 0 0" />
			<geometry>
				<mesh filename="/home/blake/kitchen-worlds/assets/models/KitchenCounter/26608/textured_objs/original-76.obj" />/&gt;
			</geometry>
		</visual>
		<visual name="drawer_side-46">
			<origin xyz="0 0 0" />
			<geometry>
				<mesh filename="/home/blake/kitchen-worlds/assets/models/KitchenCounter/26608/textured_objs/original-108.obj" />/&gt;
			</geometry>
		</visual>
		<visual name="drawer_side-47">
			<origin xyz="0 0 0" />
			<geometry>
				<mesh filename="/home/blake/kitchen-worlds/assets/models/KitchenCounter/26608/textured_objs/original-114.obj" />/&gt;
			</geometry>
		</visual>
		<visual name="drawer_bottom-48">
			<origin xyz="0 0 0" />
			<geometry>
				<mesh filename="/home/blake/kitchen-worlds/assets/models/KitchenCounter/26608/textured_objs/original-75.obj" />/&gt;
			</geometry>
		</visual>
		<collision>
			<origin xyz="0 0 0" />
			<geometry>
				<mesh filename="/home/blake/kitchen-worlds/assets/models/KitchenCounter/26608/textured_objs/original-76.obj" />/&gt;
			</geometry>
		</collision>
		<collision>
			<origin xyz="0 0 0" />
			<geometry>
				<mesh filename="/home/blake/kitchen-worlds/assets/models/KitchenCounter/26608/textured_objs/original-108.obj" />/&gt;
			</geometry>
		</collision>
		<collision>
			<origin xyz="0 0 0" />
			<geometry>
				<mesh filename="/home/blake/kitchen-worlds/assets/models/KitchenCounter/26608/textured_objs/original-114.obj" />/&gt;
			</geometry>
		</collision>
		<collision>
			<origin xyz="0 0 0" />
			<geometry>
				<mesh filename="/home/blake/kitchen-worlds/assets/models/KitchenCounter/26608/textured_objs/original-75.obj" />/&gt;
			</geometry>
		</collision>
	</link>
	<joint name="joint_5" type="prismatic">
		<origin xyz="0 0 0" />
		<axis xyz="0 0 1" />
		<child link="link_5" />
		<parent link="link_8" />
		<limit lower="0" upper="0.23199999999999998" effort="10.0" velocity="1.0" />
	</joint>
	<link name="link_6">
		<visual name="drawer_front-37">
			<origin xyz="0 0 0" />
			<geometry>
				<mesh filename="/home/blake/kitchen-worlds/assets/models/KitchenCounter/26608/textured_objs/original-85.obj" />/&gt;
			</geometry>
		</visual>
		<visual name="drawer_side-38">
			<origin xyz="0 0 0" />
			<geometry>
				<mesh filename="/home/blake/kitchen-worlds/assets/models/KitchenCounter/26608/textured_objs/original-101.obj" />/&gt;
			</geometry>
		</visual>
		<visual name="drawer_side-39">
			<origin xyz="0 0 0" />
			<geometry>
				<mesh filename="/home/blake/kitchen-worlds/assets/models/KitchenCounter/26608/textured_objs/original-116.obj" />/&gt;
			</geometry>
		</visual>
		<visual name="drawer_bottom-40">
			<origin xyz="0 0 0" />
			<geometry>
				<mesh filename="/home/blake/kitchen-worlds/assets/models/KitchenCounter/26608/textured_objs/original-91.obj" />/&gt;
			</geometry>
		</visual>
		<collision>
			<origin xyz="0 0 0" />
			<geometry>
				<mesh filename="/home/blake/kitchen-worlds/assets/models/KitchenCounter/26608/textured_objs/original-85.obj" />/&gt;
			</geometry>
		</collision>
		<collision>
			<origin xyz="0 0 0" />
			<geometry>
				<mesh filename="/home/blake/kitchen-worlds/assets/models/KitchenCounter/26608/textured_objs/original-101.obj" />/&gt;
			</geometry>
		</collision>
		<collision>
			<origin xyz="0 0 0" />
			<geometry>
				<mesh filename="/home/blake/kitchen-worlds/assets/models/KitchenCounter/26608/textured_objs/original-116.obj" />/&gt;
			</geometry>
		</collision>
		<collision>
			<origin xyz="0 0 0" />
			<geometry>
				<mesh filename="/home/blake/kitchen-worlds/assets/models/KitchenCounter/26608/textured_objs/original-91.obj" />/&gt;
			</geometry>
		</collision>
	</link>
	<joint name="joint_6" type="prismatic">
		<origin xyz="0 0 0" />
		<axis xyz="0 0 1" />
		<child link="link_6" />
		<parent link="link_8" />
		<limit lower="0" upper="0.23199999999999998" effort="10.0" velocity="1.0" />
	</joint>
	<link name="link_7">
		<visual name="drawer_front-31">
			<origin xyz="0 0 0" />
			<geometry>
				<mesh filename="/home/blake/kitchen-worlds/assets/models/KitchenCounter/26608/textured_objs/original-16.obj" />/&gt;
			</geometry>
		</visual>
		<visual name="drawer_front-31">
			<origin xyz="0 0 0" />
			<geometry>
				<mesh filename="/home/blake/kitchen-worlds/assets/models/KitchenCounter/26608/textured_objs/original-94.obj" />/&gt;
			</geometry>
		</visual>
		<visual name="drawer_side-32">
			<origin xyz="0 0 0" />
			<geometry>
				<mesh filename="/home/blake/kitchen-worlds/assets/models/KitchenCounter/26608/textured_objs/original-93.obj" />/&gt;
			</geometry>
		</visual>
		<visual name="drawer_side-33">
			<origin xyz="0 0 0" />
			<geometry>
				<mesh filename="/home/blake/kitchen-worlds/assets/models/KitchenCounter/26608/textured_objs/original-95.obj" />/&gt;
			</geometry>
		</visual>
		<visual name="drawer_back-34">
			<origin xyz="0 0 0" />
			<geometry>
				<mesh filename="/home/blake/kitchen-worlds/assets/models/KitchenCounter/26608/textured_objs/original-96.obj" />/&gt;
			</geometry>
		</visual>
		<visual name="drawer_bottom-35">
			<origin xyz="0 0 0" />
			<geometry>
				<mesh filename="/home/blake/kitchen-worlds/assets/models/KitchenCounter/26608/textured_objs/original-97.obj" />/&gt;
			</geometry>
		</visual>
		<collision>
			<origin xyz="0 0 0" />
			<geometry>
				<mesh filename="/home/blake/kitchen-worlds/assets/models/KitchenCounter/26608/textured_objs/original-16.obj" />/&gt;
			</geometry>
		</collision>
		<collision>
			<origin xyz="0 0 0" />
			<geometry>
				<mesh filename="/home/blake/kitchen-worlds/assets/models/KitchenCounter/26608/textured_objs/original-94.obj" />/&gt;
			</geometry>
		</collision>
		<collision>
			<origin xyz="0 0 0" />
			<geometry>
				<mesh filename="/home/blake/kitchen-worlds/assets/models/KitchenCounter/26608/textured_objs/original-93.obj" />/&gt;
			</geometry>
		</collision>
		<collision>
			<origin xyz="0 0 0" />
			<geometry>
				<mesh filename="/home/blake/kitchen-worlds/assets/models/KitchenCounter/26608/textured_objs/original-95.obj" />/&gt;
			</geometry>
		</collision>
		<collision>
			<origin xyz="0 0 0" />
			<geometry>
				<mesh filename="/home/blake/kitchen-worlds/assets/models/KitchenCounter/26608/textured_objs/original-96.obj" />/&gt;
			</geometry>
		</collision>
		<collision>
			<origin xyz="0 0 0" />
			<geometry>
				<mesh filename="/home/blake/kitchen-worlds/assets/models/KitchenCounter/26608/textured_objs/original-97.obj" />/&gt;
			</geometry>
		</collision>
	</link>
	<joint name="joint_7" type="prismatic">
		<origin xyz="0 0 0" />
		<axis xyz="0 0 1" />
		<child link="link_7" />
		<parent link="link_8" />
		<limit lower="0" upper="0.23199999999999998" effort="10.0" velocity="1.0" />
		
	</joint>
	<link name="link_8">
		<visual name="board-84">
			<origin xyz="0 0 0" />
			<geometry>
				<mesh filename="/home/blake/kitchen-worlds/assets/models/KitchenCounter/26608/textured_objs/original-1.obj" />/&gt;
			</geometry>
		</visual>
		<visual name="vertical_side_panel-19">
			<origin xyz="0 0 0" />
			<geometry>
				<mesh filename="/home/blake/kitchen-worlds/assets/models/KitchenCounter/26608/textured_objs/original-45.obj" />/&gt;
			</geometry>
		</visual>
		<visual name="vertical_side_panel-20">
			<origin xyz="0 0 0" />
			<geometry>
				<mesh filename="/home/blake/kitchen-worlds/assets/models/KitchenCounter/26608/textured_objs/original-42.obj" />/&gt;
			</geometry>
		</visual>
		<visual name="leg-21">
			<origin xyz="0 0 0" />
			<geometry>
				<mesh filename="/home/blake/kitchen-worlds/assets/models/KitchenCounter/26608/textured_objs/original-5.obj" />/&gt;
			</geometry>
		</visual>
		<visual name="leg-22">
			<origin xyz="0 0 0" />
			<geometry>
				<mesh filename="/home/blake/kitchen-worlds/assets/models/KitchenCounter/26608/textured_objs/original-4.obj" />/&gt;
			</geometry>
		</visual>
		<visual name="leg-23">
			<origin xyz="0 0 0" />
			<geometry>
				<mesh filename="/home/blake/kitchen-worlds/assets/models/KitchenCounter/26608/textured_objs/original-2.obj" />/&gt;
			</geometry>
		</visual>
		<visual name="leg-24">
			<origin xyz="0 0 0" />
			<geometry>
				<mesh filename="/home/blake/kitchen-worlds/assets/models/KitchenCounter/26608/textured_objs/original-3.obj" />/&gt;
			</geometry>
		</visual>
		<visual name="tabletop_connector-25">
			<origin xyz="0 0 0" />
			<geometry>
				<mesh filename="/home/blake/kitchen-worlds/assets/models/KitchenCounter/26608/textured_objs/original-25.obj" />/&gt;
			</geometry>
		</visual>
		<visual name="tabletop_connector-25">
			<origin xyz="0 0 0" />
			<geometry>
				<mesh filename="/home/blake/kitchen-worlds/assets/models/KitchenCounter/26608/textured_objs/original-99.obj" />/&gt;
			</geometry>
		</visual>
		<visual name="tabletop_connector-74">
			<origin xyz="0 0 0" />
			<geometry>
				<mesh filename="/home/blake/kitchen-worlds/assets/models/KitchenCounter/26608/textured_objs/original-84.obj" />/&gt;
			</geometry>
		</visual>
		<visual name="tabletop_connector-74">
			<origin xyz="0 0 0" />
			<geometry>
				<mesh filename="/home/blake/kitchen-worlds/assets/models/KitchenCounter/26608/textured_objs/original-115.obj" />/&gt;
			</geometry>
		</visual>
		<visual name="tabletop_connector-75">
			<origin xyz="0 0 0" />
			<geometry>
				<mesh filename="/home/blake/kitchen-worlds/assets/models/KitchenCounter/26608/textured_objs/original-68.obj" />/&gt;
			</geometry>
		</visual>
		<visual name="tabletop_connector-75">
			<origin xyz="0 0 0" />
			<geometry>
				<mesh filename="/home/blake/kitchen-worlds/assets/models/KitchenCounter/26608/textured_objs/original-112.obj" />/&gt;
			</geometry>
		</visual>
		<visual name="tabletop_connector-76">
			<origin xyz="0 0 0" />
			<geometry>
				<mesh filename="/home/blake/kitchen-worlds/assets/models/KitchenCounter/26608/textured_objs/original-60.obj" />/&gt;
			</geometry>
		</visual>
		<visual name="tabletop_connector-76">
			<origin xyz="0 0 0" />
			<geometry>
				<mesh filename="/home/blake/kitchen-worlds/assets/models/KitchenCounter/26608/textured_objs/original-104.obj" />/&gt;
			</geometry>
		</visual>
		<visual name="tabletop_connector-77">
			<origin xyz="0 0 0" />
			<geometry>
				<mesh filename="/home/blake/kitchen-worlds/assets/models/KitchenCounter/26608/textured_objs/original-109.obj" />/&gt;
			</geometry>
		</visual>
		<visual name="tabletop_connector-77">
			<origin xyz="0 0 0" />
			<geometry>
				<mesh filename="/home/blake/kitchen-worlds/assets/models/KitchenCounter/26608/textured_objs/original-65.obj" />/&gt;
			</geometry>
		</visual>
		<visual name="tabletop_connector-80">
			<origin xyz="0 0 0" />
			<geometry>
				<mesh filename="/home/blake/kitchen-worlds/assets/models/KitchenCounter/26608/textured_objs/original-82.obj" />/&gt;
			</geometry>
		</visual>
		<visual name="tabletop_connector-80">
			<origin xyz="0 0 0" />
			<geometry>
				<mesh filename="/home/blake/kitchen-worlds/assets/models/KitchenCounter/26608/textured_objs/original-119.obj" />/&gt;
			</geometry>
		</visual>
		<visual name="vertical_side_panel-81">
			<origin xyz="0 0 0" />
			<geometry>
				<mesh filename="/home/blake/kitchen-worlds/assets/models/KitchenCounter/26608/textured_objs/original-43.obj" />/&gt;
			</geometry>
		</visual>
		<visual name="vertical_side_panel-82">
			<origin xyz="0 0 0" />
			<geometry>
				<mesh filename="/home/blake/kitchen-worlds/assets/models/KitchenCounter/26608/textured_objs/original-44.obj" />/&gt;
			</geometry>
		</visual>
		<visual name="other_leaf-86">
			<origin xyz="0 0 0" />
			<geometry>
				<mesh filename="/home/blake/kitchen-worlds/assets/models/KitchenCounter/26608/textured_objs/original-57.obj" />/&gt;
			</geometry>
		</visual>
		<visual name="other_leaf-86">
			<origin xyz="0 0 0" />
			<geometry>
				<mesh filename="/home/blake/kitchen-worlds/assets/models/KitchenCounter/26608/textured_objs/original-107.obj" />/&gt;
			</geometry>
		</visual>
		<visual name="other_leaf-86">
			<origin xyz="0 0 0" />
			<geometry>
				<mesh filename="/home/blake/kitchen-worlds/assets/models/KitchenCounter/26608/textured_objs/original-55.obj" />/&gt;
			</geometry>
		</visual>
		<visual name="other_leaf-86">
			<origin xyz="0 0 0" />
			<geometry>
				<mesh filename="/home/blake/kitchen-worlds/assets/models/KitchenCounter/26608/textured_objs/original-111.obj" />/&gt;
			</geometry>
		</visual>
		<visual name="other_leaf-86">
			<origin xyz="0 0 0" />
			<geometry>
				<mesh filename="/home/blake/kitchen-worlds/assets/models/KitchenCounter/26608/textured_objs/original-56.obj" />/&gt;
			</geometry>
		</visual>
		<visual name="other_leaf-86">
			<origin xyz="0 0 0" />
			<geometry>
				<mesh filename="/home/blake/kitchen-worlds/assets/models/KitchenCounter/26608/textured_objs/original-58.obj" />/&gt;
			</geometry>
		</visual>
		<visual name="other_leaf-86">
			<origin xyz="0 0 0" />
			<geometry>
				<mesh filename="/home/blake/kitchen-worlds/assets/models/KitchenCounter/26608/textured_objs/original-67.obj" />/&gt;
			</geometry>
		</visual>
		<visual name="other_leaf-86">
			<origin xyz="0 0 0" />
			<geometry>
				<mesh filename="/home/blake/kitchen-worlds/assets/models/KitchenCounter/26608/textured_objs/original-50.obj" />/&gt;
			</geometry>
		</visual>
		<visual name="other_leaf-86">
			<origin xyz="0 0 0" />
			<geometry>
				<mesh filename="/home/blake/kitchen-worlds/assets/models/KitchenCounter/26608/textured_objs/original-47.obj" />/&gt;
			</geometry>
		</visual>
		<visual name="other_leaf-86">
			<origin xyz="0 0 0" />
			<geometry>
				<mesh filename="/home/blake/kitchen-worlds/assets/models/KitchenCounter/26608/textured_objs/original-48.obj" />/&gt;
			</geometry>
		</visual>
		<visual name="other_leaf-86">
			<origin xyz="0 0 0" />
			<geometry>
				<mesh filename="/home/blake/kitchen-worlds/assets/models/KitchenCounter/26608/textured_objs/original-49.obj" />/&gt;
			</geometry>
		</visual>
		<visual name="other_leaf-86">
			<origin xyz="0 0 0" />
			<geometry>
				<mesh filename="/home/blake/kitchen-worlds/assets/models/KitchenCounter/26608/textured_objs/original-80.obj" />/&gt;
			</geometry>
		</visual>
		<visual name="other_leaf-86">
			<origin xyz="0 0 0" />
			<geometry>
				<mesh filename="/home/blake/kitchen-worlds/assets/models/KitchenCounter/26608/textured_objs/original-79.obj" />/&gt;
			</geometry>
		</visual>
		<visual name="other_leaf-86">
			<origin xyz="0 0 0" />
			<geometry>
				<mesh filename="/home/blake/kitchen-worlds/assets/models/KitchenCounter/26608/textured_objs/original-105.obj" />/&gt;
			</geometry>
		</visual>
		<visual name="other_leaf-86">
			<origin xyz="0 0 0" />
			<geometry>
				<mesh filename="/home/blake/kitchen-worlds/assets/models/KitchenCounter/26608/textured_objs/original-72.obj" />/&gt;
			</geometry>
		</visual>
		<visual name="other_leaf-86">
			<origin xyz="0 0 0" />
			<geometry>
				<mesh filename="/home/blake/kitchen-worlds/assets/models/KitchenCounter/26608/textured_objs/original-74.obj" />/&gt;
			</geometry>
		</visual>
		<visual name="other_leaf-86">
			<origin xyz="0 0 0" />
			<geometry>
				<mesh filename="/home/blake/kitchen-worlds/assets/models/KitchenCounter/26608/textured_objs/original-71.obj" />/&gt;
			</geometry>
		</visual>
		<visual name="other_leaf-86">
			<origin xyz="0 0 0" />
			<geometry>
				<mesh filename="/home/blake/kitchen-worlds/assets/models/KitchenCounter/26608/textured_objs/original-88.obj" />/&gt;
			</geometry>
		</visual>
		<visual name="other_leaf-86">
			<origin xyz="0 0 0" />
			<geometry>
				<mesh filename="/home/blake/kitchen-worlds/assets/models/KitchenCounter/26608/textured_objs/original-73.obj" />/&gt;
			</geometry>
		</visual>
		<visual name="other_leaf-86">
			<origin xyz="0 0 0" />
			<geometry>
				<mesh filename="/home/blake/kitchen-worlds/assets/models/KitchenCounter/26608/textured_objs/original-113.obj" />/&gt;
			</geometry>
		</visual>
		<visual name="other_leaf-86">
			<origin xyz="0 0 0" />
			<geometry>
				<mesh filename="/home/blake/kitchen-worlds/assets/models/KitchenCounter/26608/textured_objs/original-87.obj" />/&gt;
			</geometry>
		</visual>
		<visual name="other_leaf-86">
			<origin xyz="0 0 0" />
			<geometry>
				<mesh filename="/home/blake/kitchen-worlds/assets/models/KitchenCounter/26608/textured_objs/original-90.obj" />/&gt;
			</geometry>
		</visual>
		<visual name="other_leaf-86">
			<origin xyz="0 0 0" />
			<geometry>
				<mesh filename="/home/blake/kitchen-worlds/assets/models/KitchenCounter/26608/textured_objs/original-89.obj" />/&gt;
			</geometry>
		</visual>
		<visual name="other_leaf-86">
			<origin xyz="0 0 0" />
			<geometry>
				<mesh filename="/home/blake/kitchen-worlds/assets/models/KitchenCounter/26608/textured_objs/original-117.obj" />/&gt;
			</geometry>
		</visual>
		<visual name="other_leaf-86">
			<origin xyz="0 0 0" />
			<geometry>
				<mesh filename="/home/blake/kitchen-worlds/assets/models/KitchenCounter/26608/textured_objs/original-22.obj" />/&gt;
			</geometry>
		</visual>
		<visual name="other_leaf-86">
			<origin xyz="0 0 0" />
			<geometry>
				<mesh filename="/home/blake/kitchen-worlds/assets/models/KitchenCounter/26608/textured_objs/original-15.obj" />/&gt;
			</geometry>
		</visual>
		<visual name="other_leaf-86">
			<origin xyz="0 0 0" />
			<geometry>
				<mesh filename="/home/blake/kitchen-worlds/assets/models/KitchenCounter/26608/textured_objs/original-19.obj" />/&gt;
			</geometry>
		</visual>
		<visual name="other_leaf-86">
			<origin xyz="0 0 0" />
			<geometry>
				<mesh filename="/home/blake/kitchen-worlds/assets/models/KitchenCounter/26608/textured_objs/original-31.obj" />/&gt;
			</geometry>
		</visual>
		<visual name="other_leaf-86">
			<origin xyz="0 0 0" />
			<geometry>
				<mesh filename="/home/blake/kitchen-worlds/assets/models/KitchenCounter/26608/textured_objs/original-11.obj" />/&gt;
			</geometry>
		</visual>
		<visual name="other_leaf-86">
			<origin xyz="0 0 0" />
			<geometry>
				<mesh filename="/home/blake/kitchen-worlds/assets/models/KitchenCounter/26608/textured_objs/original-12.obj" />/&gt;
			</geometry>
		</visual>
		<visual name="other_leaf-86">
			<origin xyz="0 0 0" />
			<geometry>
				<mesh filename="/home/blake/kitchen-worlds/assets/models/KitchenCounter/26608/textured_objs/original-10.obj" />/&gt;
			</geometry>
		</visual>
		<visual name="other_leaf-86">
			<origin xyz="0 0 0" />
			<geometry>
				<mesh filename="/home/blake/kitchen-worlds/assets/models/KitchenCounter/26608/textured_objs/original-69.obj" />/&gt;
			</geometry>
		</visual>
		<visual name="other_leaf-86">
			<origin xyz="0 0 0" />
			<geometry>
				<mesh filename="/home/blake/kitchen-worlds/assets/models/KitchenCounter/26608/textured_objs/original-29.obj" />/&gt;
			</geometry>
		</visual>
		<visual name="other_leaf-86">
			<origin xyz="0 0 0" />
			<geometry>
				<mesh filename="/home/blake/kitchen-worlds/assets/models/KitchenCounter/26608/textured_objs/original-100.obj" />/&gt;
			</geometry>
		</visual>
		<visual name="other_leaf-86">
			<origin xyz="0 0 0" />
			<geometry>
				<mesh filename="/home/blake/kitchen-worlds/assets/models/KitchenCounter/26608/textured_objs/original-61.obj" />/&gt;
			</geometry>
		</visual>
		<visual name="other_leaf-86">
			<origin xyz="0 0 0" />
			<geometry>
				<mesh filename="/home/blake/kitchen-worlds/assets/models/KitchenCounter/26608/textured_objs/original-63.obj" />/&gt;
			</geometry>
		</visual>
		<visual name="other_leaf-86">
			<origin xyz="0 0 0" />
			<geometry>
				<mesh filename="/home/blake/kitchen-worlds/assets/models/KitchenCounter/26608/textured_objs/original-13.obj" />/&gt;
			</geometry>
		</visual>
		<visual name="other_leaf-86">
			<origin xyz="0 0 0" />
			<geometry>
				<mesh filename="/home/blake/kitchen-worlds/assets/models/KitchenCounter/26608/textured_objs/original-20.obj" />/&gt;
			</geometry>
		</visual>
		<visual name="other_leaf-86">
			<origin xyz="0 0 0" />
			<geometry>
				<mesh filename="/home/blake/kitchen-worlds/assets/models/KitchenCounter/26608/textured_objs/original-81.obj" />/&gt;
			</geometry>
		</visual>
		<visual name="other_leaf-86">
			<origin xyz="0 0 0" />
			<geometry>
				<mesh filename="/home/blake/kitchen-worlds/assets/models/KitchenCounter/26608/textured_objs/original-41.obj" />/&gt;
			</geometry>
		</visual>
		<visual name="other_leaf-86">
			<origin xyz="0 0 0" />
			<geometry>
				<mesh filename="/home/blake/kitchen-worlds/assets/models/KitchenCounter/26608/textured_objs/original-6.obj" />/&gt;
			</geometry>
		</visual>
		<visual name="other_leaf-86">
			<origin xyz="0 0 0" />
			<geometry>
				<mesh filename="/home/blake/kitchen-worlds/assets/models/KitchenCounter/26608/textured_objs/original-40.obj" />/&gt;
			</geometry>
		</visual>
		<visual name="other_leaf-86">
			<origin xyz="0 0 0" />
			<geometry>
				<mesh filename="/home/blake/kitchen-worlds/assets/models/KitchenCounter/26608/textured_objs/original-92.obj" />/&gt;
			</geometry>
		</visual>
		<visual name="other_leaf-86">
			<origin xyz="0 0 0" />
			<geometry>
				<mesh filename="/home/blake/kitchen-worlds/assets/models/KitchenCounter/26608/textured_objs/original-38.obj" />/&gt;
			</geometry>
		</visual>
		<visual name="other_leaf-86">
			<origin xyz="0 0 0" />
			<geometry>
				<mesh filename="/home/blake/kitchen-worlds/assets/models/KitchenCounter/26608/textured_objs/original-39.obj" />/&gt;
			</geometry>
		</visual>
		<visual name="other_leaf-86">
			<origin xyz="0 0 0" />
			<geometry>
				<mesh filename="/home/blake/kitchen-worlds/assets/models/KitchenCounter/26608/textured_objs/original-24.obj" />/&gt;
			</geometry>
		</visual>
		<visual name="other_leaf-86">
			<origin xyz="0 0 0" />
			<geometry>
				<mesh filename="/home/blake/kitchen-worlds/assets/models/KitchenCounter/26608/textured_objs/original-21.obj" />/&gt;
			</geometry>
		</visual>
		<visual name="other_leaf-86">
			<origin xyz="0 0 0" />
			<geometry>
				<mesh filename="/home/blake/kitchen-worlds/assets/models/KitchenCounter/26608/textured_objs/original-7.obj" />/&gt;
			</geometry>
		</visual>
		<visual name="other_leaf-86">
			<origin xyz="0 0 0" />
			<geometry>
				<mesh filename="/home/blake/kitchen-worlds/assets/models/KitchenCounter/26608/textured_objs/original-33.obj" />/&gt;
			</geometry>
		</visual>
		<visual name="other_leaf-86">
			<origin xyz="0 0 0" />
			<geometry>
				<mesh filename="/home/blake/kitchen-worlds/assets/models/KitchenCounter/26608/textured_objs/original-34.obj" />/&gt;
			</geometry>
		</visual>
		<visual name="other_leaf-86">
			<origin xyz="0 0 0" />
			<geometry>
				<mesh filename="/home/blake/kitchen-worlds/assets/models/KitchenCounter/26608/textured_objs/original-35.obj" />/&gt;
			</geometry>
		</visual>
		<visual name="other_leaf-86">
			<origin xyz="0 0 0" />
			<geometry>
				<mesh filename="/home/blake/kitchen-worlds/assets/models/KitchenCounter/26608/textured_objs/original-36.obj" />/&gt;
			</geometry>
		</visual>
		<visual name="other_leaf-86">
			<origin xyz="0 0 0" />
			<geometry>
				<mesh filename="/home/blake/kitchen-worlds/assets/models/KitchenCounter/26608/textured_objs/original-37.obj" />/&gt;
			</geometry>
		</visual>
		<visual name="drawer_rails-78">
			<origin xyz="0 0 0" />
			<geometry>
				<mesh filename="/home/blake/kitchen-worlds/assets/models/KitchenCounter/26608/textured_objs/original-98.obj" />/&gt;
			</geometry>
		</visual>
		<visual name="drawer_rails-78">
			<origin xyz="0 0 0" />
			<geometry>
				<mesh filename="/home/blake/kitchen-worlds/assets/models/KitchenCounter/26608/textured_objs/original-118.obj" />/&gt;
			</geometry>
		</visual>
		<visual name="drawer_rails-79">
			<origin xyz="0 0 0" />
			<geometry>
				<mesh filename="/home/blake/kitchen-worlds/assets/models/KitchenCounter/26608/textured_objs/original-103.obj" />/&gt;
			</geometry>
		</visual>
		<visual name="drawer_rails-79">
			<origin xyz="0 0 0" />
			<geometry>
				<mesh filename="/home/blake/kitchen-worlds/assets/models/KitchenCounter/26608/textured_objs/original-102.obj" />/&gt;
			</geometry>
		</visual>
		<collision>
			<origin xyz="0 0 0" />
			<geometry>
				<mesh filename="/home/blake/kitchen-worlds/assets/models/KitchenCounter/26608/textured_objs/original-1.obj" />/&gt;
			</geometry>
		</collision>
		<collision>
			<origin xyz="0 0 0" />
			<geometry>
				<mesh filename="/home/blake/kitchen-worlds/assets/models/KitchenCounter/26608/textured_objs/original-45.obj" />/&gt;
			</geometry>
		</collision>
		<collision>
			<origin xyz="0 0 0" />
			<geometry>
				<mesh filename="/home/blake/kitchen-worlds/assets/models/KitchenCounter/26608/textured_objs/original-42.obj" />/&gt;
			</geometry>
		</collision>
		<collision>
			<origin xyz="0 0 0" />
			<geometry>
				<mesh filename="/home/blake/kitchen-worlds/assets/models/KitchenCounter/26608/textured_objs/original-5.obj" />/&gt;
			</geometry>
		</collision>
		<collision>
			<origin xyz="0 0 0" />
			<geometry>
				<mesh filename="/home/blake/kitchen-worlds/assets/models/KitchenCounter/26608/textured_objs/original-4.obj" />/&gt;
			</geometry>
		</collision>
		<collision>
			<origin xyz="0 0 0" />
			<geometry>
				<mesh filename="/home/blake/kitchen-worlds/assets/models/KitchenCounter/26608/textured_objs/original-2.obj" />/&gt;
			</geometry>
		</collision>
		<collision>
			<origin xyz="0 0 0" />
			<geometry>
				<mesh filename="/home/blake/kitchen-worlds/assets/models/KitchenCounter/26608/textured_objs/original-3.obj" />/&gt;
			</geometry>
		</collision>
		<collision>
			<origin xyz="0 0 0" />
			<geometry>
				<mesh filename="/home/blake/kitchen-worlds/assets/models/KitchenCounter/26608/textured_objs/original-25.obj" />/&gt;
			</geometry>
		</collision>
		<collision>
			<origin xyz="0 0 0" />
			<geometry>
				<mesh filename="/home/blake/kitchen-worlds/assets/models/KitchenCounter/26608/textured_objs/original-99.obj" />/&gt;
			</geometry>
		</collision>
		<collision>
			<origin xyz="0 0 0" />
			<geometry>
				<mesh filename="/home/blake/kitchen-worlds/assets/models/KitchenCounter/26608/textured_objs/original-84.obj" />/&gt;
			</geometry>
		</collision>
		<collision>
			<origin xyz="0 0 0" />
			<geometry>
				<mesh filename="/home/blake/kitchen-worlds/assets/models/KitchenCounter/26608/textured_objs/original-115.obj" />/&gt;
			</geometry>
		</collision>
		<collision>
			<origin xyz="0 0 0" />
			<geometry>
				<mesh filename="/home/blake/kitchen-worlds/assets/models/KitchenCounter/26608/textured_objs/original-68.obj" />/&gt;
			</geometry>
		</collision>
		<collision>
			<origin xyz="0 0 0" />
			<geometry>
				<mesh filename="/home/blake/kitchen-worlds/assets/models/KitchenCounter/26608/textured_objs/original-112.obj" />/&gt;
			</geometry>
		</collision>
		<collision>
			<origin xyz="0 0 0" />
			<geometry>
				<mesh filename="/home/blake/kitchen-worlds/assets/models/KitchenCounter/26608/textured_objs/original-60.obj" />/&gt;
			</geometry>
		</collision>
		<collision>
			<origin xyz="0 0 0" />
			<geometry>
				<mesh filename="/home/blake/kitchen-worlds/assets/models/KitchenCounter/26608/textured_objs/original-104.obj" />/&gt;
			</geometry>
		</collision>
		<collision>
			<origin xyz="0 0 0" />
			<geometry>
				<mesh filename="/home/blake/kitchen-worlds/assets/models/KitchenCounter/26608/textured_objs/original-109.obj" />/&gt;
			</geometry>
		</collision>
		<collision>
			<origin xyz="0 0 0" />
			<geometry>
				<mesh filename="/home/blake/kitchen-worlds/assets/models/KitchenCounter/26608/textured_objs/original-65.obj" />/&gt;
			</geometry>
		</collision>
		<collision>
			<origin xyz="0 0 0" />
			<geometry>
				<mesh filename="/home/blake/kitchen-worlds/assets/models/KitchenCounter/26608/textured_objs/original-82.obj" />/&gt;
			</geometry>
		</collision>
		<collision>
			<origin xyz="0 0 0" />
			<geometry>
				<mesh filename="/home/blake/kitchen-worlds/assets/models/KitchenCounter/26608/textured_objs/original-119.obj" />/&gt;
			</geometry>
		</collision>
		<collision>
			<origin xyz="0 0 0" />
			<geometry>
				<mesh filename="/home/blake/kitchen-worlds/assets/models/KitchenCounter/26608/textured_objs/original-43.obj" />/&gt;
			</geometry>
		</collision>
		<collision>
			<origin xyz="0 0 0" />
			<geometry>
				<mesh filename="/home/blake/kitchen-worlds/assets/models/KitchenCounter/26608/textured_objs/original-44.obj" />/&gt;
			</geometry>
		</collision>
		<collision>
			<origin xyz="0 0 0" />
			<geometry>
				<mesh filename="/home/blake/kitchen-worlds/assets/models/KitchenCounter/26608/textured_objs/original-57.obj" />/&gt;
			</geometry>
		</collision>
		<collision>
			<origin xyz="0 0 0" />
			<geometry>
				<mesh filename="/home/blake/kitchen-worlds/assets/models/KitchenCounter/26608/textured_objs/original-107.obj" />/&gt;
			</geometry>
		</collision>
		<collision>
			<origin xyz="0 0 0" />
			<geometry>
				<mesh filename="/home/blake/kitchen-worlds/assets/models/KitchenCounter/26608/textured_objs/original-55.obj" />/&gt;
			</geometry>
		</collision>
		<collision>
			<origin xyz="0 0 0" />
			<geometry>
				<mesh filename="/home/blake/kitchen-worlds/assets/models/KitchenCounter/26608/textured_objs/original-111.obj" />/&gt;
			</geometry>
		</collision>
		<collision>
			<origin xyz="0 0 0" />
			<geometry>
				<mesh filename="/home/blake/kitchen-worlds/assets/models/KitchenCounter/26608/textured_objs/original-56.obj" />/&gt;
			</geometry>
		</collision>
		<collision>
			<origin xyz="0 0 0" />
			<geometry>
				<mesh filename="/home/blake/kitchen-worlds/assets/models/KitchenCounter/26608/textured_objs/original-58.obj" />/&gt;
			</geometry>
		</collision>
		<collision>
			<origin xyz="0 0 0" />
			<geometry>
				<mesh filename="/home/blake/kitchen-worlds/assets/models/KitchenCounter/26608/textured_objs/original-67.obj" />/&gt;
			</geometry>
		</collision>
		<collision>
			<origin xyz="0 0 0" />
			<geometry>
				<mesh filename="/home/blake/kitchen-worlds/assets/models/KitchenCounter/26608/textured_objs/original-50.obj" />/&gt;
			</geometry>
		</collision>
		<collision>
			<origin xyz="0 0 0" />
			<geometry>
				<mesh filename="/home/blake/kitchen-worlds/assets/models/KitchenCounter/26608/textured_objs/original-47.obj" />/&gt;
			</geometry>
		</collision>
		<collision>
			<origin xyz="0 0 0" />
			<geometry>
				<mesh filename="/home/blake/kitchen-worlds/assets/models/KitchenCounter/26608/textured_objs/original-48.obj" />/&gt;
			</geometry>
		</collision>
		<collision>
			<origin xyz="0 0 0" />
			<geometry>
				<mesh filename="/home/blake/kitchen-worlds/assets/models/KitchenCounter/26608/textured_objs/original-49.obj" />/&gt;
			</geometry>
		</collision>
		<collision>
			<origin xyz="0 0 0" />
			<geometry>
				<mesh filename="/home/blake/kitchen-worlds/assets/models/KitchenCounter/26608/textured_objs/original-80.obj" />/&gt;
			</geometry>
		</collision>
		<collision>
			<origin xyz="0 0 0" />
			<geometry>
				<mesh filename="/home/blake/kitchen-worlds/assets/models/KitchenCounter/26608/textured_objs/original-79.obj" />/&gt;
			</geometry>
		</collision>
		<collision>
			<origin xyz="0 0 0" />
			<geometry>
				<mesh filename="/home/blake/kitchen-worlds/assets/models/KitchenCounter/26608/textured_objs/original-105.obj" />/&gt;
			</geometry>
		</collision>
		<collision>
			<origin xyz="0 0 0" />
			<geometry>
				<mesh filename="/home/blake/kitchen-worlds/assets/models/KitchenCounter/26608/textured_objs/original-72.obj" />/&gt;
			</geometry>
		</collision>
		<collision>
			<origin xyz="0 0 0" />
			<geometry>
				<mesh filename="/home/blake/kitchen-worlds/assets/models/KitchenCounter/26608/textured_objs/original-74.obj" />/&gt;
			</geometry>
		</collision>
		<collision>
			<origin xyz="0 0 0" />
			<geometry>
				<mesh filename="/home/blake/kitchen-worlds/assets/models/KitchenCounter/26608/textured_objs/original-71.obj" />/&gt;
			</geometry>
		</collision>
		<collision>
			<origin xyz="0 0 0" />
			<geometry>
				<mesh filename="/home/blake/kitchen-worlds/assets/models/KitchenCounter/26608/textured_objs/original-88.obj" />/&gt;
			</geometry>
		</collision>
		<collision>
			<origin xyz="0 0 0" />
			<geometry>
				<mesh filename="/home/blake/kitchen-worlds/assets/models/KitchenCounter/26608/textured_objs/original-73.obj" />/&gt;
			</geometry>
		</collision>
		<collision>
			<origin xyz="0 0 0" />
			<geometry>
				<mesh filename="/home/blake/kitchen-worlds/assets/models/KitchenCounter/26608/textured_objs/original-113.obj" />/&gt;
			</geometry>
		</collision>
		<collision>
			<origin xyz="0 0 0" />
			<geometry>
				<mesh filename="/home/blake/kitchen-worlds/assets/models/KitchenCounter/26608/textured_objs/original-87.obj" />/&gt;
			</geometry>
		</collision>
		<collision>
			<origin xyz="0 0 0" />
			<geometry>
				<mesh filename="/home/blake/kitchen-worlds/assets/models/KitchenCounter/26608/textured_objs/original-90.obj" />/&gt;
			</geometry>
		</collision>
		<collision>
			<origin xyz="0 0 0" />
			<geometry>
				<mesh filename="/home/blake/kitchen-worlds/assets/models/KitchenCounter/26608/textured_objs/original-89.obj" />/&gt;
			</geometry>
		</collision>
		<collision>
			<origin xyz="0 0 0" />
			<geometry>
				<mesh filename="/home/blake/kitchen-worlds/assets/models/KitchenCounter/26608/textured_objs/original-117.obj" />/&gt;
			</geometry>
		</collision>
		<collision>
			<origin xyz="0 0 0" />
			<geometry>
				<mesh filename="/home/blake/kitchen-worlds/assets/models/KitchenCounter/26608/textured_objs/original-22.obj" />/&gt;
			</geometry>
		</collision>
		<collision>
			<origin xyz="0 0 0" />
			<geometry>
				<mesh filename="/home/blake/kitchen-worlds/assets/models/KitchenCounter/26608/textured_objs/original-15.obj" />/&gt;
			</geometry>
		</collision>
		<collision>
			<origin xyz="0 0 0" />
			<geometry>
				<mesh filename="/home/blake/kitchen-worlds/assets/models/KitchenCounter/26608/textured_objs/original-19.obj" />/&gt;
			</geometry>
		</collision>
		<collision>
			<origin xyz="0 0 0" />
			<geometry>
				<mesh filename="/home/blake/kitchen-worlds/assets/models/KitchenCounter/26608/textured_objs/original-31.obj" />/&gt;
			</geometry>
		</collision>
		<collision>
			<origin xyz="0 0 0" />
			<geometry>
				<mesh filename="/home/blake/kitchen-worlds/assets/models/KitchenCounter/26608/textured_objs/original-11.obj" />/&gt;
			</geometry>
		</collision>
		<collision>
			<origin xyz="0 0 0" />
			<geometry>
				<mesh filename="/home/blake/kitchen-worlds/assets/models/KitchenCounter/26608/textured_objs/original-12.obj" />/&gt;
			</geometry>
		</collision>
		<collision>
			<origin xyz="0 0 0" />
			<geometry>
				<mesh filename="/home/blake/kitchen-worlds/assets/models/KitchenCounter/26608/textured_objs/original-10.obj" />/&gt;
			</geometry>
		</collision>
		<collision>
			<origin xyz="0 0 0" />
			<geometry>
				<mesh filename="/home/blake/kitchen-worlds/assets/models/KitchenCounter/26608/textured_objs/original-69.obj" />/&gt;
			</geometry>
		</collision>
		<collision>
			<origin xyz="0 0 0" />
			<geometry>
				<mesh filename="/home/blake/kitchen-worlds/assets/models/KitchenCounter/26608/textured_objs/original-29.obj" />/&gt;
			</geometry>
		</collision>
		<collision>
			<origin xyz="0 0 0" />
			<geometry>
				<mesh filename="/home/blake/kitchen-worlds/assets/models/KitchenCounter/26608/textured_objs/original-100.obj" />/&gt;
			</geometry>
		</collision>
		<collision>
			<origin xyz="0 0 0" />
			<geometry>
				<mesh filename="/home/blake/kitchen-worlds/assets/models/KitchenCounter/26608/textured_objs/original-61.obj" />/&gt;
			</geometry>
		</collision>
		<collision>
			<origin xyz="0 0 0" />
			<geometry>
				<mesh filename="/home/blake/kitchen-worlds/assets/models/KitchenCounter/26608/textured_objs/original-63.obj" />/&gt;
			</geometry>
		</collision>
		<collision>
			<origin xyz="0 0 0" />
			<geometry>
				<mesh filename="/home/blake/kitchen-worlds/assets/models/KitchenCounter/26608/textured_objs/original-13.obj" />/&gt;
			</geometry>
		</collision>
		<collision>
			<origin xyz="0 0 0" />
			<geometry>
				<mesh filename="/home/blake/kitchen-worlds/assets/models/KitchenCounter/26608/textured_objs/original-20.obj" />/&gt;
			</geometry>
		</collision>
		<collision>
			<origin xyz="0 0 0" />
			<geometry>
				<mesh filename="/home/blake/kitchen-worlds/assets/models/KitchenCounter/26608/textured_objs/original-81.obj" />/&gt;
			</geometry>
		</collision>
		<collision>
			<origin xyz="0 0 0" />
			<geometry>
				<mesh filename="/home/blake/kitchen-worlds/assets/models/KitchenCounter/26608/textured_objs/original-41.obj" />/&gt;
			</geometry>
		</collision>
		<collision>
			<origin xyz="0 0 0" />
			<geometry>
				<mesh filename="/home/blake/kitchen-worlds/assets/models/KitchenCounter/26608/textured_objs/original-6.obj" />/&gt;
			</geometry>
		</collision>
		<collision>
			<origin xyz="0 0 0" />
			<geometry>
				<mesh filename="/home/blake/kitchen-worlds/assets/models/KitchenCounter/26608/textured_objs/original-40.obj" />/&gt;
			</geometry>
		</collision>
		<collision>
			<origin xyz="0 0 0" />
			<geometry>
				<mesh filename="/home/blake/kitchen-worlds/assets/models/KitchenCounter/26608/textured_objs/original-92.obj" />/&gt;
			</geometry>
		</collision>
		<collision>
			<origin xyz="0 0 0" />
			<geometry>
				<mesh filename="/home/blake/kitchen-worlds/assets/models/KitchenCounter/26608/textured_objs/original-38.obj" />/&gt;
			</geometry>
		</collision>
		<collision>
			<origin xyz="0 0 0" />
			<geometry>
				<mesh filename="/home/blake/kitchen-worlds/assets/models/KitchenCounter/26608/textured_objs/original-39.obj" />/&gt;
			</geometry>
		</collision>
		<collision>
			<origin xyz="0 0 0" />
			<geometry>
				<mesh filename="/home/blake/kitchen-worlds/assets/models/KitchenCounter/26608/textured_objs/original-24.obj" />/&gt;
			</geometry>
		</collision>
		<collision>
			<origin xyz="0 0 0" />
			<geometry>
				<mesh filename="/home/blake/kitchen-worlds/assets/models/KitchenCounter/26608/textured_objs/original-21.obj" />/&gt;
			</geometry>
		</collision>
		<collision>
			<origin xyz="0 0 0" />
			<geometry>
				<mesh filename="/home/blake/kitchen-worlds/assets/models/KitchenCounter/26608/textured_objs/original-7.obj" />/&gt;
			</geometry>
		</collision>
		<collision>
			<origin xyz="0 0 0" />
			<geometry>
				<mesh filename="/home/blake/kitchen-worlds/assets/models/KitchenCounter/26608/textured_objs/original-33.obj" />/&gt;
			</geometry>
		</collision>
		<collision>
			<origin xyz="0 0 0" />
			<geometry>
				<mesh filename="/home/blake/kitchen-worlds/assets/models/KitchenCounter/26608/textured_objs/original-34.obj" />/&gt;
			</geometry>
		</collision>
		<collision>
			<origin xyz="0 0 0" />
			<geometry>
				<mesh filename="/home/blake/kitchen-worlds/assets/models/KitchenCounter/26608/textured_objs/original-35.obj" />/&gt;
			</geometry>
		</collision>
		<collision>
			<origin xyz="0 0 0" />
			<geometry>
				<mesh filename="/home/blake/kitchen-worlds/assets/models/KitchenCounter/26608/textured_objs/original-36.obj" />/&gt;
			</geometry>
		</collision>
		<collision>
			<origin xyz="0 0 0" />
			<geometry>
				<mesh filename="/home/blake/kitchen-worlds/assets/models/KitchenCounter/26608/textured_objs/original-37.obj" />/&gt;
			</geometry>
		</collision>
		<collision>
			<origin xyz="0 0 0" />
			<geometry>
				<mesh filename="/home/blake/kitchen-worlds/assets/models/KitchenCounter/26608/textured_objs/original-98.obj" />/&gt;
			</geometry>
		</collision>
		<collision>
			<origin xyz="0 0 0" />
			<geometry>
				<mesh filename="/home/blake/kitchen-worlds/assets/models/KitchenCounter/26608/textured_objs/original-118.obj" />/&gt;
			</geometry>
		</collision>
		<collision>
			<origin xyz="0 0 0" />
			<geometry>
				<mesh filename="/home/blake/kitchen-worlds/assets/models/KitchenCounter/26608/textured_objs/original-103.obj" />/&gt;
			</geometry>
		</collision>
		<collision>
			<origin xyz="0 0 0" />
			<geometry>
				<mesh filename="/home/blake/kitchen-worlds/assets/models/KitchenCounter/26608/textured_objs/original-102.obj" />/&gt;
			</geometry>
		</collision>
	</link>
	<joint name="joint_8" type="fixed">
		<origin rpy="1.570796326794897 0 -1.570796326794897" xyz="0 0 0" />
		<child link="link_8" />
		<parent link="base" />
	</joint>
</robot>