<?xml version='1.0' encoding='utf-8'?>
<robot name="partnet_902f4ee7655514ba109dc73fee74b150">
	<link name="base" />
	<link name="link_0">
		<visual name="knob-1">
			<origin xyz="0.4438307019266087 -0.3557899195812319 0" />
			<geometry>
				<mesh filename="/home/blake/kitchen-worlds/assets/models/OvenCounter/101921/textured_objs/original-36.obj" />/&gt;
			</geometry>
		</visual>
		<collision>
			<origin xyz="0.4438307019266087 -0.3557899195812319 0" />
			<geometry>
				<mesh filename="/home/blake/kitchen-worlds/assets/models/OvenCounter/101921/textured_objs/original-36.obj" />/&gt;
			</geometry>
		</collision>
	</link>
	<joint name="joint_0" type="prismatic">
		<origin xyz="-0.4438307019266087 0.3557899195812319 0" />
		<axis xyz="0 0 -1" />
		<child link="link_0" />
		<parent link="link_9" />
		<limit lower="0" upper="0.002000000000000007" effort="10.0" velocity="1.0" />
	</joint>
	<link name="link_1">
		<visual name="knob-2">
			<origin xyz="0.2704053403934484 -0.3102552595837572 0" />
			<geometry>
				<mesh filename="/home/blake/kitchen-worlds/assets/models/OvenCounter/101921/textured_objs/original-2.obj" />/&gt;
			</geometry>
		</visual>
		<visual name="knob-2">
			<origin xyz="0.2704053403934484 -0.3102552595837572 0" />
			<geometry>
				<mesh filename="/home/blake/kitchen-worlds/assets/models/OvenCounter/101921/textured_objs/original-3.obj" />/&gt;
			</geometry>
		</visual>
		<collision>
			<origin xyz="0.2704053403934484 -0.3102552595837572 0" />
			<geometry>
				<mesh filename="/home/blake/kitchen-worlds/assets/models/OvenCounter/101921/textured_objs/original-2.obj" />/&gt;
			</geometry>
		</collision>
		<collision>
			<origin xyz="0.2704053403934484 -0.3102552595837572 0" />
			<geometry>
				<mesh filename="/home/blake/kitchen-worlds/assets/models/OvenCounter/101921/textured_objs/original-3.obj" />/&gt;
			</geometry>
		</collision>
	</link>
	<joint name="joint_1" type="continuous">
		<origin xyz="-0.2704053403934484 0.3102552595837572 0" />
		<axis xyz="0 0 -1" />
		<child link="link_1" />
		<parent link="link_9" />
	</joint>
	<link name="link_2">
		<visual name="knob-3">
			<origin xyz="0.18158144516063662 -0.3102552953567844 0" />
			<geometry>
				<mesh filename="/home/blake/kitchen-worlds/assets/models/OvenCounter/101921/textured_objs/original-9.obj" />/&gt;
			</geometry>
		</visual>
		<visual name="knob-3">
			<origin xyz="0.18158144516063662 -0.3102552953567844 0" />
			<geometry>
				<mesh filename="/home/blake/kitchen-worlds/assets/models/OvenCounter/101921/textured_objs/original-8.obj" />/&gt;
			</geometry>
		</visual>
		<collision>
			<origin xyz="0.18158144516063662 -0.3102552953567844 0" />
			<geometry>
				<mesh filename="/home/blake/kitchen-worlds/assets/models/OvenCounter/101921/textured_objs/original-9.obj" />/&gt;
			</geometry>
		</collision>
		<collision>
			<origin xyz="0.18158144516063662 -0.3102552953567844 0" />
			<geometry>
				<mesh filename="/home/blake/kitchen-worlds/assets/models/OvenCounter/101921/textured_objs/original-8.obj" />/&gt;
			</geometry>
		</collision>
	</link>
	<joint name="joint_2" type="continuous">
		<origin xyz="-0.18158144516063662 0.3102552953567844 0" />
		<axis xyz="0 0 1" />
		<child link="link_2" />
		<parent link="link_9" />
	</joint>
	<link name="link_3">
		<visual name="knob-4">
			<origin xyz="-0.009619259583757218 -0.3102553403934484 0" />
			<geometry>
				<mesh filename="/home/blake/kitchen-worlds/assets/models/OvenCounter/101921/textured_objs/original-14.obj" />/&gt;
			</geometry>
		</visual>
		<visual name="knob-4">
			<origin xyz="-0.009619259583757218 -0.3102553403934484 0" />
			<geometry>
				<mesh filename="/home/blake/kitchen-worlds/assets/models/OvenCounter/101921/textured_objs/original-15.obj" />/&gt;
			</geometry>
		</visual>
		<collision>
			<origin xyz="-0.009619259583757218 -0.3102553403934484 0" />
			<geometry>
				<mesh filename="/home/blake/kitchen-worlds/assets/models/OvenCounter/101921/textured_objs/original-14.obj" />/&gt;
			</geometry>
		</collision>
		<collision>
			<origin xyz="-0.009619259583757218 -0.3102553403934484 0" />
			<geometry>
				<mesh filename="/home/blake/kitchen-worlds/assets/models/OvenCounter/101921/textured_objs/original-15.obj" />/&gt;
			</geometry>
		</collision>
	</link>
	<joint name="joint_3" type="continuous">
		<origin xyz="0.009619259583757218 0.3102553403934484 0" />
		<axis xyz="0 0 1" />
		<child link="link_3" />
		<parent link="link_9" />
	</joint>
	<link name="link_4">
		<visual name="knob-5">
			<origin xyz="-0.09844315821244892 -0.3102553607462417 0" />
			<geometry>
				<mesh filename="/home/blake/kitchen-worlds/assets/models/OvenCounter/101921/textured_objs/original-5.obj" />/&gt;
			</geometry>
		</visual>
		<visual name="knob-5">
			<origin xyz="-0.09844315821244892 -0.3102553607462417 0" />
			<geometry>
				<mesh filename="/home/blake/kitchen-worlds/assets/models/OvenCounter/101921/textured_objs/original-6.obj" />/&gt;
			</geometry>
		</visual>
		<collision>
			<origin xyz="-0.09844315821244892 -0.3102553607462417 0" />
			<geometry>
				<mesh filename="/home/blake/kitchen-worlds/assets/models/OvenCounter/101921/textured_objs/original-5.obj" />/&gt;
			</geometry>
		</collision>
		<collision>
			<origin xyz="-0.09844315821244892 -0.3102553607462417 0" />
			<geometry>
				<mesh filename="/home/blake/kitchen-worlds/assets/models/OvenCounter/101921/textured_objs/original-6.obj" />/&gt;
			</geometry>
		</collision>
	</link>
	<joint name="joint_4" type="continuous">
		<origin xyz="0.09844315821244892 0.3102553607462417 0" />
		<axis xyz="0 0 1" />
		<child link="link_4" />
		<parent link="link_9" />
	</joint>
	<link name="link_5">
		<visual name="knob-6">
			<origin xyz="-0.1872669896436654 -0.3102554992328876 0" />
			<geometry>
				<mesh filename="/home/blake/kitchen-worlds/assets/models/OvenCounter/101921/textured_objs/original-18.obj" />/&gt;
			</geometry>
		</visual>
		<visual name="knob-6">
			<origin xyz="-0.1872669896436654 -0.3102554992328876 0" />
			<geometry>
				<mesh filename="/home/blake/kitchen-worlds/assets/models/OvenCounter/101921/textured_objs/original-17.obj" />/&gt;
			</geometry>
		</visual>
		<collision>
			<origin xyz="-0.1872669896436654 -0.3102554992328876 0" />
			<geometry>
				<mesh filename="/home/blake/kitchen-worlds/assets/models/OvenCounter/101921/textured_objs/original-18.obj" />/&gt;
			</geometry>
		</collision>
		<collision>
			<origin xyz="-0.1872669896436654 -0.3102554992328876 0" />
			<geometry>
				<mesh filename="/home/blake/kitchen-worlds/assets/models/OvenCounter/101921/textured_objs/original-17.obj" />/&gt;
			</geometry>
		</collision>
	</link>
	<joint name="joint_5" type="continuous">
		<origin xyz="0.1872669896436654 0.3102554992328876 0" />
		<axis xyz="0 0 -1" />
		<child link="link_5" />
		<parent link="link_9" />
	</joint>
	<link name="link_6">
		<visual name="knob-7">
			<origin xyz="-0.27609065960655166 -0.3102552595837572 0" />
			<geometry>
				<mesh filename="/home/blake/kitchen-worlds/assets/models/OvenCounter/101921/textured_objs/original-11.obj" />/&gt;
			</geometry>
		</visual>
		<visual name="knob-7">
			<origin xyz="-0.27609065960655166 -0.3102552595837572 0" />
			<geometry>
				<mesh filename="/home/blake/kitchen-worlds/assets/models/OvenCounter/101921/textured_objs/original-12.obj" />/&gt;
			</geometry>
		</visual>
		<collision>
			<origin xyz="-0.27609065960655166 -0.3102552595837572 0" />
			<geometry>
				<mesh filename="/home/blake/kitchen-worlds/assets/models/OvenCounter/101921/textured_objs/original-11.obj" />/&gt;
			</geometry>
		</collision>
		<collision>
			<origin xyz="-0.27609065960655166 -0.3102552595837572 0" />
			<geometry>
				<mesh filename="/home/blake/kitchen-worlds/assets/models/OvenCounter/101921/textured_objs/original-12.obj" />/&gt;
			</geometry>
		</collision>
	</link>
	<joint name="joint_6" type="continuous">
		<origin xyz="0.27609065960655166 0.3102552595837572 0" />
		<axis xyz="0 0 -1" />
		<child link="link_6" />
		<parent link="link_9" />
	</joint>
	<link name="link_7">
		<visual name="knob-8">
			<origin xyz="-0.3649144889120604 -0.31025510524137095 0" />
			<geometry>
				<mesh filename="/home/blake/kitchen-worlds/assets/models/OvenCounter/101921/textured_objs/original-23.obj" />/&gt;
			</geometry>
		</visual>
		<visual name="knob-8">
			<origin xyz="-0.3649144889120604 -0.31025510524137095 0" />
			<geometry>
				<mesh filename="/home/blake/kitchen-worlds/assets/models/OvenCounter/101921/textured_objs/original-24.obj" />/&gt;
			</geometry>
		</visual>
		<collision>
			<origin xyz="-0.3649144889120604 -0.31025510524137095 0" />
			<geometry>
				<mesh filename="/home/blake/kitchen-worlds/assets/models/OvenCounter/101921/textured_objs/original-23.obj" />/&gt;
			</geometry>
		</collision>
		<collision>
			<origin xyz="-0.3649144889120604 -0.31025510524137095 0" />
			<geometry>
				<mesh filename="/home/blake/kitchen-worlds/assets/models/OvenCounter/101921/textured_objs/original-24.obj" />/&gt;
			</geometry>
		</collision>
	</link>
	<joint name="joint_7" type="continuous">
		<origin xyz="0.3649144889120604 0.31025510524137095 0" />
		<axis xyz="0 0 1" />
		<child link="link_7" />
		<parent link="link_9" />
	</joint>
	<link name="link_8">
		<visual name="knob-9">
			<origin xyz="-0.45373825958375724 -0.3102553403934484 0" />
			<geometry>
				<mesh filename="/home/blake/kitchen-worlds/assets/models/OvenCounter/101921/textured_objs/original-21.obj" />/&gt;
			</geometry>
		</visual>
		<visual name="knob-9">
			<origin xyz="-0.45373825958375724 -0.3102553403934484 0" />
			<geometry>
				<mesh filename="/home/blake/kitchen-worlds/assets/models/OvenCounter/101921/textured_objs/original-20.obj" />/&gt;
			</geometry>
		</visual>
		<collision>
			<origin xyz="-0.45373825958375724 -0.3102553403934484 0" />
			<geometry>
				<mesh filename="/home/blake/kitchen-worlds/assets/models/OvenCounter/101921/textured_objs/original-21.obj" />/&gt;
			</geometry>
		</collision>
		<collision>
			<origin xyz="-0.45373825958375724 -0.3102553403934484 0" />
			<geometry>
				<mesh filename="/home/blake/kitchen-worlds/assets/models/OvenCounter/101921/textured_objs/original-20.obj" />/&gt;
			</geometry>
		</collision>
	</link>
	<joint name="joint_8" type="continuous">
		<origin xyz="0.45373825958375724 0.3102553403934484 0" />
		<axis xyz="0 0 1" />
		<child link="link_8" />
		<parent link="link_9" />
	</joint>
	<link name="link_9">
		<visual name="base_body-10">
			<origin xyz="0 0 0" />
			<geometry>
				<mesh filename="/home/blake/kitchen-worlds/assets/models/OvenCounter/101921/textured_objs/original-41.obj" />/&gt;
			</geometry>
		</visual>
		<visual name="base_body-10">
			<origin xyz="0 0 0" />
			<geometry>
				<mesh filename="/home/blake/kitchen-worlds/assets/models/OvenCounter/101921/textured_objs/original-43.obj" />/&gt;
			</geometry>
		</visual>
		<visual name="base_body-10">
			<origin xyz="0 0 0" />
			<geometry>
				<mesh filename="/home/blake/kitchen-worlds/assets/models/OvenCounter/101921/textured_objs/original-52.obj" />/&gt;
			</geometry>
		</visual>
		<visual name="base_body-10">
			<origin xyz="0 0 0" />
			<geometry>
				<mesh filename="/home/blake/kitchen-worlds/assets/models/OvenCounter/101921/textured_objs/original-33.obj" />/&gt;
			</geometry>
		</visual>
		<visual name="base_body-10">
			<origin xyz="0 0 0" />
			<geometry>
				<mesh filename="/home/blake/kitchen-worlds/assets/models/OvenCounter/101921/textured_objs/original-44.obj" />/&gt;
			</geometry>
		</visual>
		<visual name="base_body-10">
			<origin xyz="0 0 0" />
			<geometry>
				<mesh filename="/home/blake/kitchen-worlds/assets/models/OvenCounter/101921/textured_objs/original-45.obj" />/&gt;
			</geometry>
		</visual>
		<visual name="base_body-10">
			<origin xyz="0 0 0" />
			<geometry>
				<mesh filename="/home/blake/kitchen-worlds/assets/models/OvenCounter/101921/textured_objs/original-35.obj" />/&gt;
			</geometry>
		</visual>
		<visual name="base_body-10">
			<origin xyz="0 0 0" />
			<geometry>
				<mesh filename="/home/blake/kitchen-worlds/assets/models/OvenCounter/101921/textured_objs/original-49.obj" />/&gt;
			</geometry>
		</visual>
		<visual name="base_body-10">
			<origin xyz="0 0 0" />
			<geometry>
				<mesh filename="/home/blake/kitchen-worlds/assets/models/OvenCounter/101921/textured_objs/original-39.obj" />/&gt;
			</geometry>
		</visual>
		<visual name="base_body-10">
			<origin xyz="0 0 0" />
			<geometry>
				<mesh filename="/home/blake/kitchen-worlds/assets/models/OvenCounter/101921/textured_objs/original-54.obj" />/&gt;
			</geometry>
		</visual>
		<visual name="base_body-10">
			<origin xyz="0 0 0" />
			<geometry>
				<mesh filename="/home/blake/kitchen-worlds/assets/models/OvenCounter/101921/textured_objs/original-51.obj" />/&gt;
			</geometry>
		</visual>
		<visual name="base_body-10">
			<origin xyz="0 0 0" />
			<geometry>
				<mesh filename="/home/blake/kitchen-worlds/assets/models/OvenCounter/101921/textured_objs/original-55.obj" />/&gt;
			</geometry>
		</visual>
		<visual name="base_body-10">
			<origin xyz="0 0 0" />
			<geometry>
				<mesh filename="/home/blake/kitchen-worlds/assets/models/OvenCounter/101921/textured_objs/original-50.obj" />/&gt;
			</geometry>
		</visual>
		<visual name="base_body-10">
			<origin xyz="0 0 0" />
			<geometry>
				<mesh filename="/home/blake/kitchen-worlds/assets/models/OvenCounter/101921/textured_objs/original-37.obj" />/&gt;
			</geometry>
		</visual>
		<visual name="base_body-10">
			<origin xyz="0 0 0" />
			<geometry>
				<mesh filename="/home/blake/kitchen-worlds/assets/models/OvenCounter/101921/textured_objs/original-48.obj" />/&gt;
			</geometry>
		</visual>
		<visual name="base_body-10">
			<origin xyz="0 0 0" />
			<geometry>
				<mesh filename="/home/blake/kitchen-worlds/assets/models/OvenCounter/101921/textured_objs/original-56.obj" />/&gt;
			</geometry>
		</visual>
		<visual name="base_body-10">
			<origin xyz="0 0 0" />
			<geometry>
				<mesh filename="/home/blake/kitchen-worlds/assets/models/OvenCounter/101921/textured_objs/original-38.obj" />/&gt;
			</geometry>
		</visual>
		<visual name="base_body-10">
			<origin xyz="0 0 0" />
			<geometry>
				<mesh filename="/home/blake/kitchen-worlds/assets/models/OvenCounter/101921/textured_objs/original-34.obj" />/&gt;
			</geometry>
		</visual>
		<visual name="base_body-10">
			<origin xyz="0 0 0" />
			<geometry>
				<mesh filename="/home/blake/kitchen-worlds/assets/models/OvenCounter/101921/textured_objs/original-42.obj" />/&gt;
			</geometry>
		</visual>
		<visual name="base_body-10">
			<origin xyz="0 0 0" />
			<geometry>
				<mesh filename="/home/blake/kitchen-worlds/assets/models/OvenCounter/101921/textured_objs/original-47.obj" />/&gt;
			</geometry>
		</visual>
		<visual name="base_body-10">
			<origin xyz="0 0 0" />
			<geometry>
				<mesh filename="/home/blake/kitchen-worlds/assets/models/OvenCounter/101921/textured_objs/original-53.obj" />/&gt;
			</geometry>
		</visual>
		<visual name="base_body-10">
			<origin xyz="0 0 0" />
			<geometry>
				<mesh filename="/home/blake/kitchen-worlds/assets/models/OvenCounter/101921/textured_objs/original-40.obj" />/&gt;
			</geometry>
		</visual>
		<visual name="base_body-10">
			<origin xyz="0 0 0" />
			<geometry>
				<mesh filename="/home/blake/kitchen-worlds/assets/models/OvenCounter/101921/textured_objs/original-46.obj" />/&gt;
			</geometry>
		</visual>
		<collision>
			<origin xyz="0 0 0" />
			<geometry>
				<mesh filename="/home/blake/kitchen-worlds/assets/models/OvenCounter/101921/textured_objs/original-41.obj" />/&gt;
			</geometry>
		</collision>
		<collision>
			<origin xyz="0 0 0" />
			<geometry>
				<mesh filename="/home/blake/kitchen-worlds/assets/models/OvenCounter/101921/textured_objs/original-43.obj" />/&gt;
			</geometry>
		</collision>
		<collision>
			<origin xyz="0 0 0" />
			<geometry>
				<mesh filename="/home/blake/kitchen-worlds/assets/models/OvenCounter/101921/textured_objs/original-52.obj" />/&gt;
			</geometry>
		</collision>
		<collision>
			<origin xyz="0 0 0" />
			<geometry>
				<mesh filename="/home/blake/kitchen-worlds/assets/models/OvenCounter/101921/textured_objs/original-33.obj" />/&gt;
			</geometry>
		</collision>
		<collision>
			<origin xyz="0 0 0" />
			<geometry>
				<mesh filename="/home/blake/kitchen-worlds/assets/models/OvenCounter/101921/textured_objs/original-44.obj" />/&gt;
			</geometry>
		</collision>
		<collision>
			<origin xyz="0 0 0" />
			<geometry>
				<mesh filename="/home/blake/kitchen-worlds/assets/models/OvenCounter/101921/textured_objs/original-45.obj" />/&gt;
			</geometry>
		</collision>
		<collision>
			<origin xyz="0 0 0" />
			<geometry>
				<mesh filename="/home/blake/kitchen-worlds/assets/models/OvenCounter/101921/textured_objs/original-35.obj" />/&gt;
			</geometry>
		</collision>
		<collision>
			<origin xyz="0 0 0" />
			<geometry>
				<mesh filename="/home/blake/kitchen-worlds/assets/models/OvenCounter/101921/textured_objs/original-49.obj" />/&gt;
			</geometry>
		</collision>
		<collision>
			<origin xyz="0 0 0" />
			<geometry>
				<mesh filename="/home/blake/kitchen-worlds/assets/models/OvenCounter/101921/textured_objs/original-39-collision.obj" />/&gt;
			</geometry>
		</collision>
		<collision>
			<origin xyz="0 0 0" />
			<geometry>
				<mesh filename="/home/blake/kitchen-worlds/assets/models/OvenCounter/101921/textured_objs/original-54.obj" />/&gt;
			</geometry>
		</collision>
		<collision>
			<origin xyz="0 0 0" />
			<geometry>
				<mesh filename="/home/blake/kitchen-worlds/assets/models/OvenCounter/101921/textured_objs/original-51.obj" />/&gt;
			</geometry>
		</collision>
		<collision>
			<origin xyz="0 0 0" />
			<geometry>
				<mesh filename="/home/blake/kitchen-worlds/assets/models/OvenCounter/101921/textured_objs/original-55.obj" />/&gt;
			</geometry>
		</collision>
		<collision>
			<origin xyz="0 0 0" />
			<geometry>
				<mesh filename="/home/blake/kitchen-worlds/assets/models/OvenCounter/101921/textured_objs/original-50.obj" />/&gt;
			</geometry>
		</collision>
		<collision>
			<origin xyz="0 0 0" />
			<geometry>
				<mesh filename="/home/blake/kitchen-worlds/assets/models/OvenCounter/101921/textured_objs/original-37.obj" />/&gt;
			</geometry>
		</collision>
		<collision>
			<origin xyz="0 0 0" />
			<geometry>
				<mesh filename="/home/blake/kitchen-worlds/assets/models/OvenCounter/101921/textured_objs/original-48.obj" />/&gt;
			</geometry>
		</collision>
		<collision>
			<origin xyz="0 0 0" />
			<geometry>
				<mesh filename="/home/blake/kitchen-worlds/assets/models/OvenCounter/101921/textured_objs/original-56.obj" />/&gt;
			</geometry>
		</collision>
		<collision>
			<origin xyz="0 0 0" />
			<geometry>
				<mesh filename="/home/blake/kitchen-worlds/assets/models/OvenCounter/101921/textured_objs/original-38.obj" />/&gt;
			</geometry>
		</collision>
		<collision>
			<origin xyz="0 0 0" />
			<geometry>
				<mesh filename="/home/blake/kitchen-worlds/assets/models/OvenCounter/101921/textured_objs/original-34.obj" />/&gt;
			</geometry>
		</collision>
		<collision>
			<origin xyz="0 0 0" />
			<geometry>
				<mesh filename="/home/blake/kitchen-worlds/assets/models/OvenCounter/101921/textured_objs/original-42.obj" />/&gt;
			</geometry>
		</collision>
		<collision>
			<origin xyz="0 0 0" />
			<geometry>
				<mesh filename="/home/blake/kitchen-worlds/assets/models/OvenCounter/101921/textured_objs/original-47.obj" />/&gt;
			</geometry>
		</collision>
		<collision>
			<origin xyz="0 0 0" />
			<geometry>
				<mesh filename="/home/blake/kitchen-worlds/assets/models/OvenCounter/101921/textured_objs/original-53.obj" />/&gt;
			</geometry>
		</collision>
		<collision>
			<origin xyz="0 0 0" />
			<geometry>
				<mesh filename="/home/blake/kitchen-worlds/assets/models/OvenCounter/101921/textured_objs/original-40.obj" />/&gt;
			</geometry>
		</collision>
		<collision>
			<origin xyz="0 0 0" />
			<geometry>
				<mesh filename="/home/blake/kitchen-worlds/assets/models/OvenCounter/101921/textured_objs/original-46.obj" />/&gt;
			</geometry>
		</collision>
	</link>
	<joint name="joint_9" type="fixed">
		<origin rpy="1.570796326794897 0 -1.570796326794897" xyz="0 0 0" />
		<child link="link_9" />
		<parent link="base" />
	</joint>
</robot>