<?xml version='1.0' encoding='utf-8'?>
<robot name="partnet_6b8b2cb01c376064c8724d5673a063a6">
	<link name="base"><inertial><mass value="0.1" /><inertia ixx="0.01" iyy="0.01" izz="0.01" ixy="0" ixz="0" iyz="0" /></inertial></link>
	<link name="link_0">
		<visual name="lid-7">
			<origin xyz="0.005474442099535147 0 0.001057485751011103" />
			<geometry>
				<mesh filename="BottleTest/3763/textured_objs/original-2.obj"/>
			</geometry>
		</visual>
		<collision>
			<origin xyz="0.005474442099535147 0 0.001057485751011103" />
			<geometry>
				<mesh filename="BottleTest/3763/textured_objs/original-2.obj"/>
			</geometry>
		</collision>
	<inertial><mass value="0.1" /><inertia ixx="0.01" iyy="0.01" izz="0.01" ixy="0" ixz="0" iyz="0" /></inertial></link>
	<joint name="joint_0" type="continuous">
		<origin xyz="0.0 0 0.0" />
		<axis xyz="0 1 0" />
		<child link="link_0" />
		<parent link="link_0_helper" />
	</joint>
	<link name="link_1">
		<visual name="body-5">
			<origin xyz="0 0 0" />
			<geometry>
				<mesh filename="BottleTest/3763/textured_objs/original-3.obj"/>
			</geometry>
		</visual>
		<visual name="neck-6">
			<origin xyz="0 0 0" />
			<geometry>
				<mesh filename="BottleTest/3763/textured_objs/original-1.obj"/>
			</geometry>
		</visual>
		<collision>
			<origin xyz="0 0 0" />
			<geometry>
				<mesh filename="BottleTest/3763/textured_objs/original-3.obj"/>
			</geometry>
		</collision>
		<collision>
			<origin xyz="0 0 0" />
			<geometry>
				<mesh filename="BottleTest/3763/textured_objs/original-1.obj"/>
			</geometry>
		</collision>
	<inertial><mass value="0.1" /><inertia ixx="0.01" iyy="0.01" izz="0.01" ixy="0" ixz="0" iyz="0" /></inertial></link>
	<joint name="joint_1" type="fixed">
		<origin rpy="1.570796326794897 0 -1.570796326794897" xyz="0 0 0" />
		<child link="link_1" />
		<parent link="base" />
	</joint>
	<link name="link_0_helper"><inertial><mass value="0.1" /><inertia ixx="0.01" iyy="0.01" izz="0.01" ixy="0" ixz="0" iyz="0" /></inertial></link>
	<joint name="joint_2" type="prismatic">
		<origin xyz="-0.005474442099535147 0 -0.001057485751011103" />
		<axis xyz="0 1 0" />
		<child link="link_0_helper" />
		<parent link="link_1" />
		<limit lower="-0.1080000000000001" upper="-0.008000000000000007" effort="10.0" velocity="1.0" />
	</joint>
</robot>