<?xml version='1.0' encoding='utf-8'?>
<robot name="partnet_57cdb436bd641de67e1c85c5c15da7fb">
	<link name="base" />
	<link name="link_0">
		<visual name="lens-1">
			<origin xyz="-0.37291799999999997 0.043791500000000004 0" />
			<geometry>
				<mesh filename="/home/blake/kitchen-worlds/assets/models/Camera/102472/textured_objs/original-125.obj" />/&gt;
			</geometry>
		</visual>
		<visual name="lens-1">
			<origin xyz="-0.37291799999999997 0.043791500000000004 0" />
			<geometry>
				<mesh filename="/home/blake/kitchen-worlds/assets/models/Camera/102472/textured_objs/original-127.obj" />/&gt;
			</geometry>
		</visual>
		<visual name="lens-1">
			<origin xyz="-0.37291799999999997 0.043791500000000004 0" />
			<geometry>
				<mesh filename="/home/blake/kitchen-worlds/assets/models/Camera/102472/textured_objs/original-12.obj" />/&gt;
			</geometry>
		</visual>
		<visual name="lens-1">
			<origin xyz="-0.37291799999999997 0.043791500000000004 0" />
			<geometry>
				<mesh filename="/home/blake/kitchen-worlds/assets/models/Camera/102472/textured_objs/original-13.obj" />/&gt;
			</geometry>
		</visual>
		<visual name="lens-1">
			<origin xyz="-0.37291799999999997 0.043791500000000004 0" />
			<geometry>
				<mesh filename="/home/blake/kitchen-worlds/assets/models/Camera/102472/textured_objs/original-14.obj" />/&gt;
			</geometry>
		</visual>
		<visual name="lens-1">
			<origin xyz="-0.37291799999999997 0.043791500000000004 0" />
			<geometry>
				<mesh filename="/home/blake/kitchen-worlds/assets/models/Camera/102472/textured_objs/original-21.obj" />/&gt;
			</geometry>
		</visual>
		<visual name="lens-1">
			<origin xyz="-0.37291799999999997 0.043791500000000004 0" />
			<geometry>
				<mesh filename="/home/blake/kitchen-worlds/assets/models/Camera/102472/textured_objs/original-6.obj" />/&gt;
			</geometry>
		</visual>
		<visual name="lens-1">
			<origin xyz="-0.37291799999999997 0.043791500000000004 0" />
			<geometry>
				<mesh filename="/home/blake/kitchen-worlds/assets/models/Camera/102472/textured_objs/original-7.obj" />/&gt;
			</geometry>
		</visual>
		<visual name="lens-1">
			<origin xyz="-0.37291799999999997 0.043791500000000004 0" />
			<geometry>
				<mesh filename="/home/blake/kitchen-worlds/assets/models/Camera/102472/textured_objs/original-8.obj" />/&gt;
			</geometry>
		</visual>
		<visual name="lens-1">
			<origin xyz="-0.37291799999999997 0.043791500000000004 0" />
			<geometry>
				<mesh filename="/home/blake/kitchen-worlds/assets/models/Camera/102472/textured_objs/original-9.obj" />/&gt;
			</geometry>
		</visual>
		<visual name="lens-1">
			<origin xyz="-0.37291799999999997 0.043791500000000004 0" />
			<geometry>
				<mesh filename="/home/blake/kitchen-worlds/assets/models/Camera/102472/textured_objs/original-10.obj" />/&gt;
			</geometry>
		</visual>
		<visual name="lens-1">
			<origin xyz="-0.37291799999999997 0.043791500000000004 0" />
			<geometry>
				<mesh filename="/home/blake/kitchen-worlds/assets/models/Camera/102472/textured_objs/original-11.obj" />/&gt;
			</geometry>
		</visual>
		<visual name="lens-1">
			<origin xyz="-0.37291799999999997 0.043791500000000004 0" />
			<geometry>
				<mesh filename="/home/blake/kitchen-worlds/assets/models/Camera/102472/textured_objs/original-15.obj" />/&gt;
			</geometry>
		</visual>
		<visual name="lens-1">
			<origin xyz="-0.37291799999999997 0.043791500000000004 0" />
			<geometry>
				<mesh filename="/home/blake/kitchen-worlds/assets/models/Camera/102472/textured_objs/original-16.obj" />/&gt;
			</geometry>
		</visual>
		<visual name="lens-1">
			<origin xyz="-0.37291799999999997 0.043791500000000004 0" />
			<geometry>
				<mesh filename="/home/blake/kitchen-worlds/assets/models/Camera/102472/textured_objs/original-17.obj" />/&gt;
			</geometry>
		</visual>
		<visual name="lens-1">
			<origin xyz="-0.37291799999999997 0.043791500000000004 0" />
			<geometry>
				<mesh filename="/home/blake/kitchen-worlds/assets/models/Camera/102472/textured_objs/original-18.obj" />/&gt;
			</geometry>
		</visual>
		<visual name="lens-1">
			<origin xyz="-0.37291799999999997 0.043791500000000004 0" />
			<geometry>
				<mesh filename="/home/blake/kitchen-worlds/assets/models/Camera/102472/textured_objs/original-19.obj" />/&gt;
			</geometry>
		</visual>
		<visual name="lens-1">
			<origin xyz="-0.37291799999999997 0.043791500000000004 0" />
			<geometry>
				<mesh filename="/home/blake/kitchen-worlds/assets/models/Camera/102472/textured_objs/original-20.obj" />/&gt;
			</geometry>
		</visual>
		<visual name="lens-1">
			<origin xyz="-0.37291799999999997 0.043791500000000004 0" />
			<geometry>
				<mesh filename="/home/blake/kitchen-worlds/assets/models/Camera/102472/textured_objs/original-22.obj" />/&gt;
			</geometry>
		</visual>
		<visual name="lens-1">
			<origin xyz="-0.37291799999999997 0.043791500000000004 0" />
			<geometry>
				<mesh filename="/home/blake/kitchen-worlds/assets/models/Camera/102472/textured_objs/original-24.obj" />/&gt;
			</geometry>
		</visual>
		<visual name="lens-1">
			<origin xyz="-0.37291799999999997 0.043791500000000004 0" />
			<geometry>
				<mesh filename="/home/blake/kitchen-worlds/assets/models/Camera/102472/textured_objs/original-25.obj" />/&gt;
			</geometry>
		</visual>
		<visual name="lens-1">
			<origin xyz="-0.37291799999999997 0.043791500000000004 0" />
			<geometry>
				<mesh filename="/home/blake/kitchen-worlds/assets/models/Camera/102472/textured_objs/original-26.obj" />/&gt;
			</geometry>
		</visual>
		<visual name="lens-1">
			<origin xyz="-0.37291799999999997 0.043791500000000004 0" />
			<geometry>
				<mesh filename="/home/blake/kitchen-worlds/assets/models/Camera/102472/textured_objs/original-27.obj" />/&gt;
			</geometry>
		</visual>
		<visual name="lens-1">
			<origin xyz="-0.37291799999999997 0.043791500000000004 0" />
			<geometry>
				<mesh filename="/home/blake/kitchen-worlds/assets/models/Camera/102472/textured_objs/original-28.obj" />/&gt;
			</geometry>
		</visual>
		<visual name="lens-1">
			<origin xyz="-0.37291799999999997 0.043791500000000004 0" />
			<geometry>
				<mesh filename="/home/blake/kitchen-worlds/assets/models/Camera/102472/textured_objs/original-29.obj" />/&gt;
			</geometry>
		</visual>
		<visual name="lens-1">
			<origin xyz="-0.37291799999999997 0.043791500000000004 0" />
			<geometry>
				<mesh filename="/home/blake/kitchen-worlds/assets/models/Camera/102472/textured_objs/original-30.obj" />/&gt;
			</geometry>
		</visual>
		<visual name="lens-1">
			<origin xyz="-0.37291799999999997 0.043791500000000004 0" />
			<geometry>
				<mesh filename="/home/blake/kitchen-worlds/assets/models/Camera/102472/textured_objs/original-31.obj" />/&gt;
			</geometry>
		</visual>
		<visual name="lens-1">
			<origin xyz="-0.37291799999999997 0.043791500000000004 0" />
			<geometry>
				<mesh filename="/home/blake/kitchen-worlds/assets/models/Camera/102472/textured_objs/original-32.obj" />/&gt;
			</geometry>
		</visual>
		<visual name="lens-1">
			<origin xyz="-0.37291799999999997 0.043791500000000004 0" />
			<geometry>
				<mesh filename="/home/blake/kitchen-worlds/assets/models/Camera/102472/textured_objs/original-33.obj" />/&gt;
			</geometry>
		</visual>
		<visual name="lens-1">
			<origin xyz="-0.37291799999999997 0.043791500000000004 0" />
			<geometry>
				<mesh filename="/home/blake/kitchen-worlds/assets/models/Camera/102472/textured_objs/original-34.obj" />/&gt;
			</geometry>
		</visual>
		<visual name="lens-1">
			<origin xyz="-0.37291799999999997 0.043791500000000004 0" />
			<geometry>
				<mesh filename="/home/blake/kitchen-worlds/assets/models/Camera/102472/textured_objs/original-35.obj" />/&gt;
			</geometry>
		</visual>
		<visual name="lens-1">
			<origin xyz="-0.37291799999999997 0.043791500000000004 0" />
			<geometry>
				<mesh filename="/home/blake/kitchen-worlds/assets/models/Camera/102472/textured_objs/original-36.obj" />/&gt;
			</geometry>
		</visual>
		<visual name="lens-1">
			<origin xyz="-0.37291799999999997 0.043791500000000004 0" />
			<geometry>
				<mesh filename="/home/blake/kitchen-worlds/assets/models/Camera/102472/textured_objs/original-37.obj" />/&gt;
			</geometry>
		</visual>
		<visual name="lens-1">
			<origin xyz="-0.37291799999999997 0.043791500000000004 0" />
			<geometry>
				<mesh filename="/home/blake/kitchen-worlds/assets/models/Camera/102472/textured_objs/original-38.obj" />/&gt;
			</geometry>
		</visual>
		<visual name="lens-1">
			<origin xyz="-0.37291799999999997 0.043791500000000004 0" />
			<geometry>
				<mesh filename="/home/blake/kitchen-worlds/assets/models/Camera/102472/textured_objs/original-39.obj" />/&gt;
			</geometry>
		</visual>
		<visual name="lens-1">
			<origin xyz="-0.37291799999999997 0.043791500000000004 0" />
			<geometry>
				<mesh filename="/home/blake/kitchen-worlds/assets/models/Camera/102472/textured_objs/original-40.obj" />/&gt;
			</geometry>
		</visual>
		<visual name="lens-1">
			<origin xyz="-0.37291799999999997 0.043791500000000004 0" />
			<geometry>
				<mesh filename="/home/blake/kitchen-worlds/assets/models/Camera/102472/textured_objs/original-41.obj" />/&gt;
			</geometry>
		</visual>
		<visual name="lens-1">
			<origin xyz="-0.37291799999999997 0.043791500000000004 0" />
			<geometry>
				<mesh filename="/home/blake/kitchen-worlds/assets/models/Camera/102472/textured_objs/original-42.obj" />/&gt;
			</geometry>
		</visual>
		<visual name="lens-1">
			<origin xyz="-0.37291799999999997 0.043791500000000004 0" />
			<geometry>
				<mesh filename="/home/blake/kitchen-worlds/assets/models/Camera/102472/textured_objs/original-43.obj" />/&gt;
			</geometry>
		</visual>
		<visual name="lens-1">
			<origin xyz="-0.37291799999999997 0.043791500000000004 0" />
			<geometry>
				<mesh filename="/home/blake/kitchen-worlds/assets/models/Camera/102472/textured_objs/original-44.obj" />/&gt;
			</geometry>
		</visual>
		<visual name="lens-1">
			<origin xyz="-0.37291799999999997 0.043791500000000004 0" />
			<geometry>
				<mesh filename="/home/blake/kitchen-worlds/assets/models/Camera/102472/textured_objs/original-46.obj" />/&gt;
			</geometry>
		</visual>
		<visual name="lens-1">
			<origin xyz="-0.37291799999999997 0.043791500000000004 0" />
			<geometry>
				<mesh filename="/home/blake/kitchen-worlds/assets/models/Camera/102472/textured_objs/original-45.obj" />/&gt;
			</geometry>
		</visual>
		<visual name="lens-1">
			<origin xyz="-0.37291799999999997 0.043791500000000004 0" />
			<geometry>
				<mesh filename="/home/blake/kitchen-worlds/assets/models/Camera/102472/textured_objs/original-47.obj" />/&gt;
			</geometry>
		</visual>
		<visual name="lens-1">
			<origin xyz="-0.37291799999999997 0.043791500000000004 0" />
			<geometry>
				<mesh filename="/home/blake/kitchen-worlds/assets/models/Camera/102472/textured_objs/original-48.obj" />/&gt;
			</geometry>
		</visual>
		<visual name="lens-1">
			<origin xyz="-0.37291799999999997 0.043791500000000004 0" />
			<geometry>
				<mesh filename="/home/blake/kitchen-worlds/assets/models/Camera/102472/textured_objs/original-49.obj" />/&gt;
			</geometry>
		</visual>
		<visual name="lens-1">
			<origin xyz="-0.37291799999999997 0.043791500000000004 0" />
			<geometry>
				<mesh filename="/home/blake/kitchen-worlds/assets/models/Camera/102472/textured_objs/original-50.obj" />/&gt;
			</geometry>
		</visual>
		<visual name="lens-1">
			<origin xyz="-0.37291799999999997 0.043791500000000004 0" />
			<geometry>
				<mesh filename="/home/blake/kitchen-worlds/assets/models/Camera/102472/textured_objs/original-51.obj" />/&gt;
			</geometry>
		</visual>
		<visual name="lens-1">
			<origin xyz="-0.37291799999999997 0.043791500000000004 0" />
			<geometry>
				<mesh filename="/home/blake/kitchen-worlds/assets/models/Camera/102472/textured_objs/original-52.obj" />/&gt;
			</geometry>
		</visual>
		<visual name="lens-1">
			<origin xyz="-0.37291799999999997 0.043791500000000004 0" />
			<geometry>
				<mesh filename="/home/blake/kitchen-worlds/assets/models/Camera/102472/textured_objs/original-105.obj" />/&gt;
			</geometry>
		</visual>
		<visual name="lens-1">
			<origin xyz="-0.37291799999999997 0.043791500000000004 0" />
			<geometry>
				<mesh filename="/home/blake/kitchen-worlds/assets/models/Camera/102472/textured_objs/original-53.obj" />/&gt;
			</geometry>
		</visual>
		<visual name="lens-1">
			<origin xyz="-0.37291799999999997 0.043791500000000004 0" />
			<geometry>
				<mesh filename="/home/blake/kitchen-worlds/assets/models/Camera/102472/textured_objs/original-131.obj" />/&gt;
			</geometry>
		</visual>
		<visual name="lens-1">
			<origin xyz="-0.37291799999999997 0.043791500000000004 0" />
			<geometry>
				<mesh filename="/home/blake/kitchen-worlds/assets/models/Camera/102472/textured_objs/original-1.obj" />/&gt;
			</geometry>
		</visual>
		<visual name="lens-1">
			<origin xyz="-0.37291799999999997 0.043791500000000004 0" />
			<geometry>
				<mesh filename="/home/blake/kitchen-worlds/assets/models/Camera/102472/textured_objs/original-114.obj" />/&gt;
			</geometry>
		</visual>
		<visual name="lens-1">
			<origin xyz="-0.37291799999999997 0.043791500000000004 0" />
			<geometry>
				<mesh filename="/home/blake/kitchen-worlds/assets/models/Camera/102472/textured_objs/original-117.obj" />/&gt;
			</geometry>
		</visual>
		<visual name="lens-1">
			<origin xyz="-0.37291799999999997 0.043791500000000004 0" />
			<geometry>
				<mesh filename="/home/blake/kitchen-worlds/assets/models/Camera/102472/textured_objs/original-129.obj" />/&gt;
			</geometry>
		</visual>
		<collision>
			<origin xyz="-0.37291799999999997 0.043791500000000004 0" />
			<geometry>
				<mesh filename="/home/blake/kitchen-worlds/assets/models/Camera/102472/textured_objs/original-125.obj" />/&gt;
			</geometry>
		</collision>
		<collision>
			<origin xyz="-0.37291799999999997 0.043791500000000004 0" />
			<geometry>
				<mesh filename="/home/blake/kitchen-worlds/assets/models/Camera/102472/textured_objs/original-127.obj" />/&gt;
			</geometry>
		</collision>
		<collision>
			<origin xyz="-0.37291799999999997 0.043791500000000004 0" />
			<geometry>
				<mesh filename="/home/blake/kitchen-worlds/assets/models/Camera/102472/textured_objs/original-12.obj" />/&gt;
			</geometry>
		</collision>
		<collision>
			<origin xyz="-0.37291799999999997 0.043791500000000004 0" />
			<geometry>
				<mesh filename="/home/blake/kitchen-worlds/assets/models/Camera/102472/textured_objs/original-13.obj" />/&gt;
			</geometry>
		</collision>
		<collision>
			<origin xyz="-0.37291799999999997 0.043791500000000004 0" />
			<geometry>
				<mesh filename="/home/blake/kitchen-worlds/assets/models/Camera/102472/textured_objs/original-14.obj" />/&gt;
			</geometry>
		</collision>
		<collision>
			<origin xyz="-0.37291799999999997 0.043791500000000004 0" />
			<geometry>
				<mesh filename="/home/blake/kitchen-worlds/assets/models/Camera/102472/textured_objs/original-21.obj" />/&gt;
			</geometry>
		</collision>
		<collision>
			<origin xyz="-0.37291799999999997 0.043791500000000004 0" />
			<geometry>
				<mesh filename="/home/blake/kitchen-worlds/assets/models/Camera/102472/textured_objs/original-6.obj" />/&gt;
			</geometry>
		</collision>
		<collision>
			<origin xyz="-0.37291799999999997 0.043791500000000004 0" />
			<geometry>
				<mesh filename="/home/blake/kitchen-worlds/assets/models/Camera/102472/textured_objs/original-7.obj" />/&gt;
			</geometry>
		</collision>
		<collision>
			<origin xyz="-0.37291799999999997 0.043791500000000004 0" />
			<geometry>
				<mesh filename="/home/blake/kitchen-worlds/assets/models/Camera/102472/textured_objs/original-8.obj" />/&gt;
			</geometry>
		</collision>
		<collision>
			<origin xyz="-0.37291799999999997 0.043791500000000004 0" />
			<geometry>
				<mesh filename="/home/blake/kitchen-worlds/assets/models/Camera/102472/textured_objs/original-9.obj" />/&gt;
			</geometry>
		</collision>
		<collision>
			<origin xyz="-0.37291799999999997 0.043791500000000004 0" />
			<geometry>
				<mesh filename="/home/blake/kitchen-worlds/assets/models/Camera/102472/textured_objs/original-10.obj" />/&gt;
			</geometry>
		</collision>
		<collision>
			<origin xyz="-0.37291799999999997 0.043791500000000004 0" />
			<geometry>
				<mesh filename="/home/blake/kitchen-worlds/assets/models/Camera/102472/textured_objs/original-11.obj" />/&gt;
			</geometry>
		</collision>
		<collision>
			<origin xyz="-0.37291799999999997 0.043791500000000004 0" />
			<geometry>
				<mesh filename="/home/blake/kitchen-worlds/assets/models/Camera/102472/textured_objs/original-15.obj" />/&gt;
			</geometry>
		</collision>
		<collision>
			<origin xyz="-0.37291799999999997 0.043791500000000004 0" />
			<geometry>
				<mesh filename="/home/blake/kitchen-worlds/assets/models/Camera/102472/textured_objs/original-16.obj" />/&gt;
			</geometry>
		</collision>
		<collision>
			<origin xyz="-0.37291799999999997 0.043791500000000004 0" />
			<geometry>
				<mesh filename="/home/blake/kitchen-worlds/assets/models/Camera/102472/textured_objs/original-17.obj" />/&gt;
			</geometry>
		</collision>
		<collision>
			<origin xyz="-0.37291799999999997 0.043791500000000004 0" />
			<geometry>
				<mesh filename="/home/blake/kitchen-worlds/assets/models/Camera/102472/textured_objs/original-18.obj" />/&gt;
			</geometry>
		</collision>
		<collision>
			<origin xyz="-0.37291799999999997 0.043791500000000004 0" />
			<geometry>
				<mesh filename="/home/blake/kitchen-worlds/assets/models/Camera/102472/textured_objs/original-19.obj" />/&gt;
			</geometry>
		</collision>
		<collision>
			<origin xyz="-0.37291799999999997 0.043791500000000004 0" />
			<geometry>
				<mesh filename="/home/blake/kitchen-worlds/assets/models/Camera/102472/textured_objs/original-20.obj" />/&gt;
			</geometry>
		</collision>
		<collision>
			<origin xyz="-0.37291799999999997 0.043791500000000004 0" />
			<geometry>
				<mesh filename="/home/blake/kitchen-worlds/assets/models/Camera/102472/textured_objs/original-22.obj" />/&gt;
			</geometry>
		</collision>
		<collision>
			<origin xyz="-0.37291799999999997 0.043791500000000004 0" />
			<geometry>
				<mesh filename="/home/blake/kitchen-worlds/assets/models/Camera/102472/textured_objs/original-24.obj" />/&gt;
			</geometry>
		</collision>
		<collision>
			<origin xyz="-0.37291799999999997 0.043791500000000004 0" />
			<geometry>
				<mesh filename="/home/blake/kitchen-worlds/assets/models/Camera/102472/textured_objs/original-25.obj" />/&gt;
			</geometry>
		</collision>
		<collision>
			<origin xyz="-0.37291799999999997 0.043791500000000004 0" />
			<geometry>
				<mesh filename="/home/blake/kitchen-worlds/assets/models/Camera/102472/textured_objs/original-26.obj" />/&gt;
			</geometry>
		</collision>
		<collision>
			<origin xyz="-0.37291799999999997 0.043791500000000004 0" />
			<geometry>
				<mesh filename="/home/blake/kitchen-worlds/assets/models/Camera/102472/textured_objs/original-27.obj" />/&gt;
			</geometry>
		</collision>
		<collision>
			<origin xyz="-0.37291799999999997 0.043791500000000004 0" />
			<geometry>
				<mesh filename="/home/blake/kitchen-worlds/assets/models/Camera/102472/textured_objs/original-28.obj" />/&gt;
			</geometry>
		</collision>
		<collision>
			<origin xyz="-0.37291799999999997 0.043791500000000004 0" />
			<geometry>
				<mesh filename="/home/blake/kitchen-worlds/assets/models/Camera/102472/textured_objs/original-29.obj" />/&gt;
			</geometry>
		</collision>
		<collision>
			<origin xyz="-0.37291799999999997 0.043791500000000004 0" />
			<geometry>
				<mesh filename="/home/blake/kitchen-worlds/assets/models/Camera/102472/textured_objs/original-30.obj" />/&gt;
			</geometry>
		</collision>
		<collision>
			<origin xyz="-0.37291799999999997 0.043791500000000004 0" />
			<geometry>
				<mesh filename="/home/blake/kitchen-worlds/assets/models/Camera/102472/textured_objs/original-31.obj" />/&gt;
			</geometry>
		</collision>
		<collision>
			<origin xyz="-0.37291799999999997 0.043791500000000004 0" />
			<geometry>
				<mesh filename="/home/blake/kitchen-worlds/assets/models/Camera/102472/textured_objs/original-32.obj" />/&gt;
			</geometry>
		</collision>
		<collision>
			<origin xyz="-0.37291799999999997 0.043791500000000004 0" />
			<geometry>
				<mesh filename="/home/blake/kitchen-worlds/assets/models/Camera/102472/textured_objs/original-33.obj" />/&gt;
			</geometry>
		</collision>
		<collision>
			<origin xyz="-0.37291799999999997 0.043791500000000004 0" />
			<geometry>
				<mesh filename="/home/blake/kitchen-worlds/assets/models/Camera/102472/textured_objs/original-34.obj" />/&gt;
			</geometry>
		</collision>
		<collision>
			<origin xyz="-0.37291799999999997 0.043791500000000004 0" />
			<geometry>
				<mesh filename="/home/blake/kitchen-worlds/assets/models/Camera/102472/textured_objs/original-35.obj" />/&gt;
			</geometry>
		</collision>
		<collision>
			<origin xyz="-0.37291799999999997 0.043791500000000004 0" />
			<geometry>
				<mesh filename="/home/blake/kitchen-worlds/assets/models/Camera/102472/textured_objs/original-36.obj" />/&gt;
			</geometry>
		</collision>
		<collision>
			<origin xyz="-0.37291799999999997 0.043791500000000004 0" />
			<geometry>
				<mesh filename="/home/blake/kitchen-worlds/assets/models/Camera/102472/textured_objs/original-37.obj" />/&gt;
			</geometry>
		</collision>
		<collision>
			<origin xyz="-0.37291799999999997 0.043791500000000004 0" />
			<geometry>
				<mesh filename="/home/blake/kitchen-worlds/assets/models/Camera/102472/textured_objs/original-38.obj" />/&gt;
			</geometry>
		</collision>
		<collision>
			<origin xyz="-0.37291799999999997 0.043791500000000004 0" />
			<geometry>
				<mesh filename="/home/blake/kitchen-worlds/assets/models/Camera/102472/textured_objs/original-39.obj" />/&gt;
			</geometry>
		</collision>
		<collision>
			<origin xyz="-0.37291799999999997 0.043791500000000004 0" />
			<geometry>
				<mesh filename="/home/blake/kitchen-worlds/assets/models/Camera/102472/textured_objs/original-40.obj" />/&gt;
			</geometry>
		</collision>
		<collision>
			<origin xyz="-0.37291799999999997 0.043791500000000004 0" />
			<geometry>
				<mesh filename="/home/blake/kitchen-worlds/assets/models/Camera/102472/textured_objs/original-41.obj" />/&gt;
			</geometry>
		</collision>
		<collision>
			<origin xyz="-0.37291799999999997 0.043791500000000004 0" />
			<geometry>
				<mesh filename="/home/blake/kitchen-worlds/assets/models/Camera/102472/textured_objs/original-42.obj" />/&gt;
			</geometry>
		</collision>
		<collision>
			<origin xyz="-0.37291799999999997 0.043791500000000004 0" />
			<geometry>
				<mesh filename="/home/blake/kitchen-worlds/assets/models/Camera/102472/textured_objs/original-43.obj" />/&gt;
			</geometry>
		</collision>
		<collision>
			<origin xyz="-0.37291799999999997 0.043791500000000004 0" />
			<geometry>
				<mesh filename="/home/blake/kitchen-worlds/assets/models/Camera/102472/textured_objs/original-44.obj" />/&gt;
			</geometry>
		</collision>
		<collision>
			<origin xyz="-0.37291799999999997 0.043791500000000004 0" />
			<geometry>
				<mesh filename="/home/blake/kitchen-worlds/assets/models/Camera/102472/textured_objs/original-46.obj" />/&gt;
			</geometry>
		</collision>
		<collision>
			<origin xyz="-0.37291799999999997 0.043791500000000004 0" />
			<geometry>
				<mesh filename="/home/blake/kitchen-worlds/assets/models/Camera/102472/textured_objs/original-45.obj" />/&gt;
			</geometry>
		</collision>
		<collision>
			<origin xyz="-0.37291799999999997 0.043791500000000004 0" />
			<geometry>
				<mesh filename="/home/blake/kitchen-worlds/assets/models/Camera/102472/textured_objs/original-47.obj" />/&gt;
			</geometry>
		</collision>
		<collision>
			<origin xyz="-0.37291799999999997 0.043791500000000004 0" />
			<geometry>
				<mesh filename="/home/blake/kitchen-worlds/assets/models/Camera/102472/textured_objs/original-48.obj" />/&gt;
			</geometry>
		</collision>
		<collision>
			<origin xyz="-0.37291799999999997 0.043791500000000004 0" />
			<geometry>
				<mesh filename="/home/blake/kitchen-worlds/assets/models/Camera/102472/textured_objs/original-49.obj" />/&gt;
			</geometry>
		</collision>
		<collision>
			<origin xyz="-0.37291799999999997 0.043791500000000004 0" />
			<geometry>
				<mesh filename="/home/blake/kitchen-worlds/assets/models/Camera/102472/textured_objs/original-50.obj" />/&gt;
			</geometry>
		</collision>
		<collision>
			<origin xyz="-0.37291799999999997 0.043791500000000004 0" />
			<geometry>
				<mesh filename="/home/blake/kitchen-worlds/assets/models/Camera/102472/textured_objs/original-51.obj" />/&gt;
			</geometry>
		</collision>
		<collision>
			<origin xyz="-0.37291799999999997 0.043791500000000004 0" />
			<geometry>
				<mesh filename="/home/blake/kitchen-worlds/assets/models/Camera/102472/textured_objs/original-52.obj" />/&gt;
			</geometry>
		</collision>
		<collision>
			<origin xyz="-0.37291799999999997 0.043791500000000004 0" />
			<geometry>
				<mesh filename="/home/blake/kitchen-worlds/assets/models/Camera/102472/textured_objs/original-105.obj" />/&gt;
			</geometry>
		</collision>
		<collision>
			<origin xyz="-0.37291799999999997 0.043791500000000004 0" />
			<geometry>
				<mesh filename="/home/blake/kitchen-worlds/assets/models/Camera/102472/textured_objs/original-53.obj" />/&gt;
			</geometry>
		</collision>
		<collision>
			<origin xyz="-0.37291799999999997 0.043791500000000004 0" />
			<geometry>
				<mesh filename="/home/blake/kitchen-worlds/assets/models/Camera/102472/textured_objs/original-131.obj" />/&gt;
			</geometry>
		</collision>
		<collision>
			<origin xyz="-0.37291799999999997 0.043791500000000004 0" />
			<geometry>
				<mesh filename="/home/blake/kitchen-worlds/assets/models/Camera/102472/textured_objs/original-1.obj" />/&gt;
			</geometry>
		</collision>
		<collision>
			<origin xyz="-0.37291799999999997 0.043791500000000004 0" />
			<geometry>
				<mesh filename="/home/blake/kitchen-worlds/assets/models/Camera/102472/textured_objs/original-114.obj" />/&gt;
			</geometry>
		</collision>
		<collision>
			<origin xyz="-0.37291799999999997 0.043791500000000004 0" />
			<geometry>
				<mesh filename="/home/blake/kitchen-worlds/assets/models/Camera/102472/textured_objs/original-117.obj" />/&gt;
			</geometry>
		</collision>
		<collision>
			<origin xyz="-0.37291799999999997 0.043791500000000004 0" />
			<geometry>
				<mesh filename="/home/blake/kitchen-worlds/assets/models/Camera/102472/textured_objs/original-129.obj" />/&gt;
			</geometry>
		</collision>
	</link>
	<joint name="joint_0" type="continuous">
		<origin xyz="0.37291799999999997 -0.043791500000000004 0" />
		<axis xyz="0 0 1" />
		<child link="link_0" />
		<parent link="link_6" />
	</joint>
	<link name="link_1">
		<visual name="button-4">
			<origin xyz="0.7240979999999999 0 0.164351" />
			<geometry>
				<mesh filename="/home/blake/kitchen-worlds/assets/models/Camera/102472/textured_objs/original-64.obj" />/&gt;
			</geometry>
		</visual>
		<visual name="button-4">
			<origin xyz="0.7240979999999999 0 0.164351" />
			<geometry>
				<mesh filename="/home/blake/kitchen-worlds/assets/models/Camera/102472/textured_objs/original-63.obj" />/&gt;
			</geometry>
		</visual>
		<visual name="button-4">
			<origin xyz="0.7240979999999999 0 0.164351" />
			<geometry>
				<mesh filename="/home/blake/kitchen-worlds/assets/models/Camera/102472/textured_objs/original-107.obj" />/&gt;
			</geometry>
		</visual>
		<visual name="button-4">
			<origin xyz="0.7240979999999999 0 0.164351" />
			<geometry>
				<mesh filename="/home/blake/kitchen-worlds/assets/models/Camera/102472/textured_objs/original-122.obj" />/&gt;
			</geometry>
		</visual>
		<visual name="button-4">
			<origin xyz="0.7240979999999999 0 0.164351" />
			<geometry>
				<mesh filename="/home/blake/kitchen-worlds/assets/models/Camera/102472/textured_objs/original-123.obj" />/&gt;
			</geometry>
		</visual>
		<collision>
			<origin xyz="0.7240979999999999 0 0.164351" />
			<geometry>
				<mesh filename="/home/blake/kitchen-worlds/assets/models/Camera/102472/textured_objs/original-64.obj" />/&gt;
			</geometry>
		</collision>
		<collision>
			<origin xyz="0.7240979999999999 0 0.164351" />
			<geometry>
				<mesh filename="/home/blake/kitchen-worlds/assets/models/Camera/102472/textured_objs/original-63.obj" />/&gt;
			</geometry>
		</collision>
		<collision>
			<origin xyz="0.7240979999999999 0 0.164351" />
			<geometry>
				<mesh filename="/home/blake/kitchen-worlds/assets/models/Camera/102472/textured_objs/original-107.obj" />/&gt;
			</geometry>
		</collision>
		<collision>
			<origin xyz="0.7240979999999999 0 0.164351" />
			<geometry>
				<mesh filename="/home/blake/kitchen-worlds/assets/models/Camera/102472/textured_objs/original-122.obj" />/&gt;
			</geometry>
		</collision>
		<collision>
			<origin xyz="0.7240979999999999 0 0.164351" />
			<geometry>
				<mesh filename="/home/blake/kitchen-worlds/assets/models/Camera/102472/textured_objs/original-123.obj" />/&gt;
			</geometry>
		</collision>
	</link>
	<joint name="joint_1" type="revolute">
		<origin xyz="-0.7240979999999999 0 -0.164351" />
		<axis xyz="0 -1 0" />
		<child link="link_1" />
		<parent link="link_6" />
		<limit lower="-0.0439822971502571" upper="0.0439822971502571" effort="10.0" velocity="1.0" />
	</joint>
	<link name="link_2">
		<visual name="button-5">
			<origin xyz="0.6652515639895923 0.12295643601040779 0" />
			<geometry>
				<mesh filename="/home/blake/kitchen-worlds/assets/models/Camera/102472/textured_objs/original-90.obj" />/&gt;
			</geometry>
		</visual>
		<visual name="button-5">
			<origin xyz="0.6652515639895923 0.12295643601040779 0" />
			<geometry>
				<mesh filename="/home/blake/kitchen-worlds/assets/models/Camera/102472/textured_objs/original-89.obj" />/&gt;
			</geometry>
		</visual>
		<visual name="button-5">
			<origin xyz="0.6652515639895923 0.12295643601040779 0" />
			<geometry>
				<mesh filename="/home/blake/kitchen-worlds/assets/models/Camera/102472/textured_objs/original-88.obj" />/&gt;
			</geometry>
		</visual>
		<visual name="button-5">
			<origin xyz="0.6652515639895923 0.12295643601040779 0" />
			<geometry>
				<mesh filename="/home/blake/kitchen-worlds/assets/models/Camera/102472/textured_objs/original-94.obj" />/&gt;
			</geometry>
		</visual>
		<visual name="button-5">
			<origin xyz="0.6652515639895923 0.12295643601040779 0" />
			<geometry>
				<mesh filename="/home/blake/kitchen-worlds/assets/models/Camera/102472/textured_objs/original-93.obj" />/&gt;
			</geometry>
		</visual>
		<visual name="button-5">
			<origin xyz="0.6652515639895923 0.12295643601040779 0" />
			<geometry>
				<mesh filename="/home/blake/kitchen-worlds/assets/models/Camera/102472/textured_objs/original-92.obj" />/&gt;
			</geometry>
		</visual>
		<visual name="button-5">
			<origin xyz="0.6652515639895923 0.12295643601040779 0" />
			<geometry>
				<mesh filename="/home/blake/kitchen-worlds/assets/models/Camera/102472/textured_objs/original-91.obj" />/&gt;
			</geometry>
		</visual>
		<visual name="button-5">
			<origin xyz="0.6652515639895923 0.12295643601040779 0" />
			<geometry>
				<mesh filename="/home/blake/kitchen-worlds/assets/models/Camera/102472/textured_objs/original-121.obj" />/&gt;
			</geometry>
		</visual>
		<visual name="button-5">
			<origin xyz="0.6652515639895923 0.12295643601040779 0" />
			<geometry>
				<mesh filename="/home/blake/kitchen-worlds/assets/models/Camera/102472/textured_objs/original-111.obj" />/&gt;
			</geometry>
		</visual>
		<collision>
			<origin xyz="0.6652515639895923 0.12295643601040779 0" />
			<geometry>
				<mesh filename="/home/blake/kitchen-worlds/assets/models/Camera/102472/textured_objs/original-90.obj" />/&gt;
			</geometry>
		</collision>
		<collision>
			<origin xyz="0.6652515639895923 0.12295643601040779 0" />
			<geometry>
				<mesh filename="/home/blake/kitchen-worlds/assets/models/Camera/102472/textured_objs/original-89.obj" />/&gt;
			</geometry>
		</collision>
		<collision>
			<origin xyz="0.6652515639895923 0.12295643601040779 0" />
			<geometry>
				<mesh filename="/home/blake/kitchen-worlds/assets/models/Camera/102472/textured_objs/original-88.obj" />/&gt;
			</geometry>
		</collision>
		<collision>
			<origin xyz="0.6652515639895923 0.12295643601040779 0" />
			<geometry>
				<mesh filename="/home/blake/kitchen-worlds/assets/models/Camera/102472/textured_objs/original-94.obj" />/&gt;
			</geometry>
		</collision>
		<collision>
			<origin xyz="0.6652515639895923 0.12295643601040779 0" />
			<geometry>
				<mesh filename="/home/blake/kitchen-worlds/assets/models/Camera/102472/textured_objs/original-93.obj" />/&gt;
			</geometry>
		</collision>
		<collision>
			<origin xyz="0.6652515639895923 0.12295643601040779 0" />
			<geometry>
				<mesh filename="/home/blake/kitchen-worlds/assets/models/Camera/102472/textured_objs/original-92.obj" />/&gt;
			</geometry>
		</collision>
		<collision>
			<origin xyz="0.6652515639895923 0.12295643601040779 0" />
			<geometry>
				<mesh filename="/home/blake/kitchen-worlds/assets/models/Camera/102472/textured_objs/original-91.obj" />/&gt;
			</geometry>
		</collision>
		<collision>
			<origin xyz="0.6652515639895923 0.12295643601040779 0" />
			<geometry>
				<mesh filename="/home/blake/kitchen-worlds/assets/models/Camera/102472/textured_objs/original-121.obj" />/&gt;
			</geometry>
		</collision>
		<collision>
			<origin xyz="0.6652515639895923 0.12295643601040779 0" />
			<geometry>
				<mesh filename="/home/blake/kitchen-worlds/assets/models/Camera/102472/textured_objs/original-111.obj" />/&gt;
			</geometry>
		</collision>
	</link>
	<joint name="joint_2" type="prismatic">
		<origin xyz="-0.6652515639895923 -0.12295643601040779 0" />
		<axis xyz="0 0 1" />
		<child link="link_2" />
		<parent link="link_6" />
		<limit lower="0" upper="0.020000000000000018" effort="10.0" velocity="1.0" />
	</joint>
	<link name="link_3">
		<visual name="button-6">
			<origin xyz="0.6652515639895923 0.12295643601040779 0" />
			<geometry>
				<mesh filename="/home/blake/kitchen-worlds/assets/models/Camera/102472/textured_objs/original-110.obj" />/&gt;
			</geometry>
		</visual>
		<collision>
			<origin xyz="0.6652515639895923 0.12295643601040779 0" />
			<geometry>
				<mesh filename="/home/blake/kitchen-worlds/assets/models/Camera/102472/textured_objs/original-110.obj" />/&gt;
			</geometry>
		</collision>
	</link>
	<joint name="joint_3" type="prismatic">
		<origin xyz="-0.6652515639895923 -0.12295643601040779 0" />
		<axis xyz="0 0 1" />
		<child link="link_3" />
		<parent link="link_6" />
		<limit lower="0" upper="0.008000000000000007" effort="10.0" velocity="1.0" />
	</joint>
	<link name="link_4">
		<visual name="button-7">
			<origin xyz="0.6652515639895923 0.12295643601040779 0" />
			<geometry>
				<mesh filename="/home/blake/kitchen-worlds/assets/models/Camera/102472/textured_objs/original-112.obj" />/&gt;
			</geometry>
		</visual>
		<visual name="button-7">
			<origin xyz="0.6652515639895923 0.12295643601040779 0" />
			<geometry>
				<mesh filename="/home/blake/kitchen-worlds/assets/models/Camera/102472/textured_objs/original-95.obj" />/&gt;
			</geometry>
		</visual>
		<collision>
			<origin xyz="0.6652515639895923 0.12295643601040779 0" />
			<geometry>
				<mesh filename="/home/blake/kitchen-worlds/assets/models/Camera/102472/textured_objs/original-112.obj" />/&gt;
			</geometry>
		</collision>
		<collision>
			<origin xyz="0.6652515639895923 0.12295643601040779 0" />
			<geometry>
				<mesh filename="/home/blake/kitchen-worlds/assets/models/Camera/102472/textured_objs/original-95.obj" />/&gt;
			</geometry>
		</collision>
	</link>
	<joint name="joint_4" type="prismatic">
		<origin xyz="-0.6652515639895923 -0.12295643601040779 0" />
		<axis xyz="0 0 1" />
		<child link="link_4" />
		<parent link="link_6" />
		<limit lower="0" upper="0.008000000000000007" effort="10.0" velocity="1.0" />
	</joint>
	<link name="link_5">
		<visual name="button-10">
			<origin xyz="0.6652515639895923 0.12295643601040779 0" />
			<geometry>
				<mesh filename="/home/blake/kitchen-worlds/assets/models/Camera/102472/textured_objs/original-109.obj" />/&gt;
			</geometry>
		</visual>
		<visual name="button-10">
			<origin xyz="0.6652515639895923 0.12295643601040779 0" />
			<geometry>
				<mesh filename="/home/blake/kitchen-worlds/assets/models/Camera/102472/textured_objs/original-118.obj" />/&gt;
			</geometry>
		</visual>
		<collision>
			<origin xyz="0.6652515639895923 0.12295643601040779 0" />
			<geometry>
				<mesh filename="/home/blake/kitchen-worlds/assets/models/Camera/102472/textured_objs/original-109.obj" />/&gt;
			</geometry>
		</collision>
		<collision>
			<origin xyz="0.6652515639895923 0.12295643601040779 0" />
			<geometry>
				<mesh filename="/home/blake/kitchen-worlds/assets/models/Camera/102472/textured_objs/original-118.obj" />/&gt;
			</geometry>
		</collision>
	</link>
	<joint name="joint_5" type="prismatic">
		<origin xyz="-0.6652515639895923 -0.12295643601040779 0" />
		<axis xyz="0 0 1" />
		<child link="link_5" />
		<parent link="link_6" />
		<limit lower="0" upper="0.020000000000000018" effort="10.0" velocity="1.0" />
	</joint>
	<link name="link_6">
		<visual name="base_body-11">
			<origin xyz="0 0 0" />
			<geometry>
				<mesh filename="/home/blake/kitchen-worlds/assets/models/Camera/102472/textured_objs/original-100.obj" />/&gt;
			</geometry>
		</visual>
		<visual name="base_body-11">
			<origin xyz="0 0 0" />
			<geometry>
				<mesh filename="/home/blake/kitchen-worlds/assets/models/Camera/102472/textured_objs/original-132.obj" />/&gt;
			</geometry>
		</visual>
		<visual name="base_body-11">
			<origin xyz="0 0 0" />
			<geometry>
				<mesh filename="/home/blake/kitchen-worlds/assets/models/Camera/102472/textured_objs/original-126.obj" />/&gt;
			</geometry>
		</visual>
		<visual name="base_body-11">
			<origin xyz="0 0 0" />
			<geometry>
				<mesh filename="/home/blake/kitchen-worlds/assets/models/Camera/102472/textured_objs/original-119.obj" />/&gt;
			</geometry>
		</visual>
		<visual name="base_body-11">
			<origin xyz="0 0 0" />
			<geometry>
				<mesh filename="/home/blake/kitchen-worlds/assets/models/Camera/102472/textured_objs/original-124.obj" />/&gt;
			</geometry>
		</visual>
		<visual name="base_body-11">
			<origin xyz="0 0 0" />
			<geometry>
				<mesh filename="/home/blake/kitchen-worlds/assets/models/Camera/102472/textured_objs/original-134.obj" />/&gt;
			</geometry>
		</visual>
		<visual name="base_body-11">
			<origin xyz="0 0 0" />
			<geometry>
				<mesh filename="/home/blake/kitchen-worlds/assets/models/Camera/102472/textured_objs/original-71.obj" />/&gt;
			</geometry>
		</visual>
		<visual name="base_body-11">
			<origin xyz="0 0 0" />
			<geometry>
				<mesh filename="/home/blake/kitchen-worlds/assets/models/Camera/102472/textured_objs/original-83.obj" />/&gt;
			</geometry>
		</visual>
		<visual name="base_body-11">
			<origin xyz="0 0 0" />
			<geometry>
				<mesh filename="/home/blake/kitchen-worlds/assets/models/Camera/102472/textured_objs/original-4.obj" />/&gt;
			</geometry>
		</visual>
		<visual name="base_body-11">
			<origin xyz="0 0 0" />
			<geometry>
				<mesh filename="/home/blake/kitchen-worlds/assets/models/Camera/102472/textured_objs/original-3.obj" />/&gt;
			</geometry>
		</visual>
		<visual name="base_body-11">
			<origin xyz="0 0 0" />
			<geometry>
				<mesh filename="/home/blake/kitchen-worlds/assets/models/Camera/102472/textured_objs/original-128.obj" />/&gt;
			</geometry>
		</visual>
		<visual name="base_body-11">
			<origin xyz="0 0 0" />
			<geometry>
				<mesh filename="/home/blake/kitchen-worlds/assets/models/Camera/102472/textured_objs/original-2.obj" />/&gt;
			</geometry>
		</visual>
		<visual name="base_body-11">
			<origin xyz="0 0 0" />
			<geometry>
				<mesh filename="/home/blake/kitchen-worlds/assets/models/Camera/102472/textured_objs/original-130.obj" />/&gt;
			</geometry>
		</visual>
		<visual name="base_body-11">
			<origin xyz="0 0 0" />
			<geometry>
				<mesh filename="/home/blake/kitchen-worlds/assets/models/Camera/102472/textured_objs/original-106.obj" />/&gt;
			</geometry>
		</visual>
		<visual name="base_body-11">
			<origin xyz="0 0 0" />
			<geometry>
				<mesh filename="/home/blake/kitchen-worlds/assets/models/Camera/102472/textured_objs/original-86.obj" />/&gt;
			</geometry>
		</visual>
		<visual name="base_body-11">
			<origin xyz="0 0 0" />
			<geometry>
				<mesh filename="/home/blake/kitchen-worlds/assets/models/Camera/102472/textured_objs/original-61.obj" />/&gt;
			</geometry>
		</visual>
		<visual name="base_body-11">
			<origin xyz="0 0 0" />
			<geometry>
				<mesh filename="/home/blake/kitchen-worlds/assets/models/Camera/102472/textured_objs/original-120.obj" />/&gt;
			</geometry>
		</visual>
		<visual name="base_body-11">
			<origin xyz="0 0 0" />
			<geometry>
				<mesh filename="/home/blake/kitchen-worlds/assets/models/Camera/102472/textured_objs/original-59.obj" />/&gt;
			</geometry>
		</visual>
		<visual name="base_body-11">
			<origin xyz="0 0 0" />
			<geometry>
				<mesh filename="/home/blake/kitchen-worlds/assets/models/Camera/102472/textured_objs/original-77.obj" />/&gt;
			</geometry>
		</visual>
		<visual name="base_body-11">
			<origin xyz="0 0 0" />
			<geometry>
				<mesh filename="/home/blake/kitchen-worlds/assets/models/Camera/102472/textured_objs/original-55.obj" />/&gt;
			</geometry>
		</visual>
		<visual name="base_body-11">
			<origin xyz="0 0 0" />
			<geometry>
				<mesh filename="/home/blake/kitchen-worlds/assets/models/Camera/102472/textured_objs/original-113.obj" />/&gt;
			</geometry>
		</visual>
		<visual name="base_body-11">
			<origin xyz="0 0 0" />
			<geometry>
				<mesh filename="/home/blake/kitchen-worlds/assets/models/Camera/102472/textured_objs/original-116.obj" />/&gt;
			</geometry>
		</visual>
		<visual name="base_body-11">
			<origin xyz="0 0 0" />
			<geometry>
				<mesh filename="/home/blake/kitchen-worlds/assets/models/Camera/102472/textured_objs/original-85.obj" />/&gt;
			</geometry>
		</visual>
		<visual name="base_body-11">
			<origin xyz="0 0 0" />
			<geometry>
				<mesh filename="/home/blake/kitchen-worlds/assets/models/Camera/102472/textured_objs/original-56.obj" />/&gt;
			</geometry>
		</visual>
		<visual name="base_body-11">
			<origin xyz="0 0 0" />
			<geometry>
				<mesh filename="/home/blake/kitchen-worlds/assets/models/Camera/102472/textured_objs/original-135.obj" />/&gt;
			</geometry>
		</visual>
		<visual name="base_body-11">
			<origin xyz="0 0 0" />
			<geometry>
				<mesh filename="/home/blake/kitchen-worlds/assets/models/Camera/102472/textured_objs/original-76.obj" />/&gt;
			</geometry>
		</visual>
		<visual name="base_body-11">
			<origin xyz="0 0 0" />
			<geometry>
				<mesh filename="/home/blake/kitchen-worlds/assets/models/Camera/102472/textured_objs/original-108.obj" />/&gt;
			</geometry>
		</visual>
		<visual name="base_body-11">
			<origin xyz="0 0 0" />
			<geometry>
				<mesh filename="/home/blake/kitchen-worlds/assets/models/Camera/102472/textured_objs/original-72.obj" />/&gt;
			</geometry>
		</visual>
		<visual name="base_body-11">
			<origin xyz="0 0 0" />
			<geometry>
				<mesh filename="/home/blake/kitchen-worlds/assets/models/Camera/102472/textured_objs/original-99.obj" />/&gt;
			</geometry>
		</visual>
		<visual name="base_body-11">
			<origin xyz="0 0 0" />
			<geometry>
				<mesh filename="/home/blake/kitchen-worlds/assets/models/Camera/102472/textured_objs/original-136.obj" />/&gt;
			</geometry>
		</visual>
		<visual name="base_body-11">
			<origin xyz="0 0 0" />
			<geometry>
				<mesh filename="/home/blake/kitchen-worlds/assets/models/Camera/102472/textured_objs/original-62.obj" />/&gt;
			</geometry>
		</visual>
		<visual name="base_body-11">
			<origin xyz="0 0 0" />
			<geometry>
				<mesh filename="/home/blake/kitchen-worlds/assets/models/Camera/102472/textured_objs/original-75.obj" />/&gt;
			</geometry>
		</visual>
		<visual name="base_body-11">
			<origin xyz="0 0 0" />
			<geometry>
				<mesh filename="/home/blake/kitchen-worlds/assets/models/Camera/102472/textured_objs/original-133.obj" />/&gt;
			</geometry>
		</visual>
		<visual name="base_body-11">
			<origin xyz="0 0 0" />
			<geometry>
				<mesh filename="/home/blake/kitchen-worlds/assets/models/Camera/102472/textured_objs/original-66.obj" />/&gt;
			</geometry>
		</visual>
		<visual name="base_body-11">
			<origin xyz="0 0 0" />
			<geometry>
				<mesh filename="/home/blake/kitchen-worlds/assets/models/Camera/102472/textured_objs/original-58.obj" />/&gt;
			</geometry>
		</visual>
		<visual name="base_body-11">
			<origin xyz="0 0 0" />
			<geometry>
				<mesh filename="/home/blake/kitchen-worlds/assets/models/Camera/102472/textured_objs/original-98.obj" />/&gt;
			</geometry>
		</visual>
		<visual name="base_body-11">
			<origin xyz="0 0 0" />
			<geometry>
				<mesh filename="/home/blake/kitchen-worlds/assets/models/Camera/102472/textured_objs/original-67.obj" />/&gt;
			</geometry>
		</visual>
		<visual name="base_body-11">
			<origin xyz="0 0 0" />
			<geometry>
				<mesh filename="/home/blake/kitchen-worlds/assets/models/Camera/102472/textured_objs/original-69.obj" />/&gt;
			</geometry>
		</visual>
		<visual name="base_body-11">
			<origin xyz="0 0 0" />
			<geometry>
				<mesh filename="/home/blake/kitchen-worlds/assets/models/Camera/102472/textured_objs/original-68.obj" />/&gt;
			</geometry>
		</visual>
		<visual name="base_body-11">
			<origin xyz="0 0 0" />
			<geometry>
				<mesh filename="/home/blake/kitchen-worlds/assets/models/Camera/102472/textured_objs/original-80.obj" />/&gt;
			</geometry>
		</visual>
		<visual name="base_body-11">
			<origin xyz="0 0 0" />
			<geometry>
				<mesh filename="/home/blake/kitchen-worlds/assets/models/Camera/102472/textured_objs/original-70.obj" />/&gt;
			</geometry>
		</visual>
		<visual name="base_body-11">
			<origin xyz="0 0 0" />
			<geometry>
				<mesh filename="/home/blake/kitchen-worlds/assets/models/Camera/102472/textured_objs/original-74.obj" />/&gt;
			</geometry>
		</visual>
		<visual name="base_body-11">
			<origin xyz="0 0 0" />
			<geometry>
				<mesh filename="/home/blake/kitchen-worlds/assets/models/Camera/102472/textured_objs/original-73.obj" />/&gt;
			</geometry>
		</visual>
		<visual name="base_body-11">
			<origin xyz="0 0 0" />
			<geometry>
				<mesh filename="/home/blake/kitchen-worlds/assets/models/Camera/102472/textured_objs/original-79.obj" />/&gt;
			</geometry>
		</visual>
		<visual name="base_body-11">
			<origin xyz="0 0 0" />
			<geometry>
				<mesh filename="/home/blake/kitchen-worlds/assets/models/Camera/102472/textured_objs/original-102.obj" />/&gt;
			</geometry>
		</visual>
		<visual name="base_body-11">
			<origin xyz="0 0 0" />
			<geometry>
				<mesh filename="/home/blake/kitchen-worlds/assets/models/Camera/102472/textured_objs/original-115.obj" />/&gt;
			</geometry>
		</visual>
		<visual name="base_body-11">
			<origin xyz="0 0 0" />
			<geometry>
				<mesh filename="/home/blake/kitchen-worlds/assets/models/Camera/102472/textured_objs/original-101.obj" />/&gt;
			</geometry>
		</visual>
		<visual name="base_body-11">
			<origin xyz="0 0 0" />
			<geometry>
				<mesh filename="/home/blake/kitchen-worlds/assets/models/Camera/102472/textured_objs/original-81.obj" />/&gt;
			</geometry>
		</visual>
		<visual name="base_body-11">
			<origin xyz="0 0 0" />
			<geometry>
				<mesh filename="/home/blake/kitchen-worlds/assets/models/Camera/102472/textured_objs/original-84.obj" />/&gt;
			</geometry>
		</visual>
		<visual name="base_body-11">
			<origin xyz="0 0 0" />
			<geometry>
				<mesh filename="/home/blake/kitchen-worlds/assets/models/Camera/102472/textured_objs/original-97.obj" />/&gt;
			</geometry>
		</visual>
		<visual name="base_body-11">
			<origin xyz="0 0 0" />
			<geometry>
				<mesh filename="/home/blake/kitchen-worlds/assets/models/Camera/102472/textured_objs/original-82.obj" />/&gt;
			</geometry>
		</visual>
		<visual name="base_body-11">
			<origin xyz="0 0 0" />
			<geometry>
				<mesh filename="/home/blake/kitchen-worlds/assets/models/Camera/102472/textured_objs/original-60.obj" />/&gt;
			</geometry>
		</visual>
		<visual name="base_body-11">
			<origin xyz="0 0 0" />
			<geometry>
				<mesh filename="/home/blake/kitchen-worlds/assets/models/Camera/102472/textured_objs/original-57.obj" />/&gt;
			</geometry>
		</visual>
		<collision>
			<origin xyz="0 0 0" />
			<geometry>
				<mesh filename="/home/blake/kitchen-worlds/assets/models/Camera/102472/textured_objs/original-100.obj" />/&gt;
			</geometry>
		</collision>
		<collision>
			<origin xyz="0 0 0" />
			<geometry>
				<mesh filename="/home/blake/kitchen-worlds/assets/models/Camera/102472/textured_objs/original-132.obj" />/&gt;
			</geometry>
		</collision>
		<collision>
			<origin xyz="0 0 0" />
			<geometry>
				<mesh filename="/home/blake/kitchen-worlds/assets/models/Camera/102472/textured_objs/original-126.obj" />/&gt;
			</geometry>
		</collision>
		<collision>
			<origin xyz="0 0 0" />
			<geometry>
				<mesh filename="/home/blake/kitchen-worlds/assets/models/Camera/102472/textured_objs/original-119.obj" />/&gt;
			</geometry>
		</collision>
		<collision>
			<origin xyz="0 0 0" />
			<geometry>
				<mesh filename="/home/blake/kitchen-worlds/assets/models/Camera/102472/textured_objs/original-124.obj" />/&gt;
			</geometry>
		</collision>
		<collision>
			<origin xyz="0 0 0" />
			<geometry>
				<mesh filename="/home/blake/kitchen-worlds/assets/models/Camera/102472/textured_objs/original-134.obj" />/&gt;
			</geometry>
		</collision>
		<collision>
			<origin xyz="0 0 0" />
			<geometry>
				<mesh filename="/home/blake/kitchen-worlds/assets/models/Camera/102472/textured_objs/original-71.obj" />/&gt;
			</geometry>
		</collision>
		<collision>
			<origin xyz="0 0 0" />
			<geometry>
				<mesh filename="/home/blake/kitchen-worlds/assets/models/Camera/102472/textured_objs/original-83.obj" />/&gt;
			</geometry>
		</collision>
		<collision>
			<origin xyz="0 0 0" />
			<geometry>
				<mesh filename="/home/blake/kitchen-worlds/assets/models/Camera/102472/textured_objs/original-4.obj" />/&gt;
			</geometry>
		</collision>
		<collision>
			<origin xyz="0 0 0" />
			<geometry>
				<mesh filename="/home/blake/kitchen-worlds/assets/models/Camera/102472/textured_objs/original-3.obj" />/&gt;
			</geometry>
		</collision>
		<collision>
			<origin xyz="0 0 0" />
			<geometry>
				<mesh filename="/home/blake/kitchen-worlds/assets/models/Camera/102472/textured_objs/original-128.obj" />/&gt;
			</geometry>
		</collision>
		<collision>
			<origin xyz="0 0 0" />
			<geometry>
				<mesh filename="/home/blake/kitchen-worlds/assets/models/Camera/102472/textured_objs/original-2.obj" />/&gt;
			</geometry>
		</collision>
		<collision>
			<origin xyz="0 0 0" />
			<geometry>
				<mesh filename="/home/blake/kitchen-worlds/assets/models/Camera/102472/textured_objs/original-130.obj" />/&gt;
			</geometry>
		</collision>
		<collision>
			<origin xyz="0 0 0" />
			<geometry>
				<mesh filename="/home/blake/kitchen-worlds/assets/models/Camera/102472/textured_objs/original-106.obj" />/&gt;
			</geometry>
		</collision>
		<collision>
			<origin xyz="0 0 0" />
			<geometry>
				<mesh filename="/home/blake/kitchen-worlds/assets/models/Camera/102472/textured_objs/original-86.obj" />/&gt;
			</geometry>
		</collision>
		<collision>
			<origin xyz="0 0 0" />
			<geometry>
				<mesh filename="/home/blake/kitchen-worlds/assets/models/Camera/102472/textured_objs/original-61.obj" />/&gt;
			</geometry>
		</collision>
		<collision>
			<origin xyz="0 0 0" />
			<geometry>
				<mesh filename="/home/blake/kitchen-worlds/assets/models/Camera/102472/textured_objs/original-120.obj" />/&gt;
			</geometry>
		</collision>
		<collision>
			<origin xyz="0 0 0" />
			<geometry>
				<mesh filename="/home/blake/kitchen-worlds/assets/models/Camera/102472/textured_objs/original-59.obj" />/&gt;
			</geometry>
		</collision>
		<collision>
			<origin xyz="0 0 0" />
			<geometry>
				<mesh filename="/home/blake/kitchen-worlds/assets/models/Camera/102472/textured_objs/original-77.obj" />/&gt;
			</geometry>
		</collision>
		<collision>
			<origin xyz="0 0 0" />
			<geometry>
				<mesh filename="/home/blake/kitchen-worlds/assets/models/Camera/102472/textured_objs/original-55.obj" />/&gt;
			</geometry>
		</collision>
		<collision>
			<origin xyz="0 0 0" />
			<geometry>
				<mesh filename="/home/blake/kitchen-worlds/assets/models/Camera/102472/textured_objs/original-113.obj" />/&gt;
			</geometry>
		</collision>
		<collision>
			<origin xyz="0 0 0" />
			<geometry>
				<mesh filename="/home/blake/kitchen-worlds/assets/models/Camera/102472/textured_objs/original-116.obj" />/&gt;
			</geometry>
		</collision>
		<collision>
			<origin xyz="0 0 0" />
			<geometry>
				<mesh filename="/home/blake/kitchen-worlds/assets/models/Camera/102472/textured_objs/original-85.obj" />/&gt;
			</geometry>
		</collision>
		<collision>
			<origin xyz="0 0 0" />
			<geometry>
				<mesh filename="/home/blake/kitchen-worlds/assets/models/Camera/102472/textured_objs/original-56.obj" />/&gt;
			</geometry>
		</collision>
		<collision>
			<origin xyz="0 0 0" />
			<geometry>
				<mesh filename="/home/blake/kitchen-worlds/assets/models/Camera/102472/textured_objs/original-135.obj" />/&gt;
			</geometry>
		</collision>
		<collision>
			<origin xyz="0 0 0" />
			<geometry>
				<mesh filename="/home/blake/kitchen-worlds/assets/models/Camera/102472/textured_objs/original-76.obj" />/&gt;
			</geometry>
		</collision>
		<collision>
			<origin xyz="0 0 0" />
			<geometry>
				<mesh filename="/home/blake/kitchen-worlds/assets/models/Camera/102472/textured_objs/original-108.obj" />/&gt;
			</geometry>
		</collision>
		<collision>
			<origin xyz="0 0 0" />
			<geometry>
				<mesh filename="/home/blake/kitchen-worlds/assets/models/Camera/102472/textured_objs/original-72.obj" />/&gt;
			</geometry>
		</collision>
		<collision>
			<origin xyz="0 0 0" />
			<geometry>
				<mesh filename="/home/blake/kitchen-worlds/assets/models/Camera/102472/textured_objs/original-99.obj" />/&gt;
			</geometry>
		</collision>
		<collision>
			<origin xyz="0 0 0" />
			<geometry>
				<mesh filename="/home/blake/kitchen-worlds/assets/models/Camera/102472/textured_objs/original-136.obj" />/&gt;
			</geometry>
		</collision>
		<collision>
			<origin xyz="0 0 0" />
			<geometry>
				<mesh filename="/home/blake/kitchen-worlds/assets/models/Camera/102472/textured_objs/original-62.obj" />/&gt;
			</geometry>
		</collision>
		<collision>
			<origin xyz="0 0 0" />
			<geometry>
				<mesh filename="/home/blake/kitchen-worlds/assets/models/Camera/102472/textured_objs/original-75.obj" />/&gt;
			</geometry>
		</collision>
		<collision>
			<origin xyz="0 0 0" />
			<geometry>
				<mesh filename="/home/blake/kitchen-worlds/assets/models/Camera/102472/textured_objs/original-133.obj" />/&gt;
			</geometry>
		</collision>
		<collision>
			<origin xyz="0 0 0" />
			<geometry>
				<mesh filename="/home/blake/kitchen-worlds/assets/models/Camera/102472/textured_objs/original-66.obj" />/&gt;
			</geometry>
		</collision>
		<collision>
			<origin xyz="0 0 0" />
			<geometry>
				<mesh filename="/home/blake/kitchen-worlds/assets/models/Camera/102472/textured_objs/original-58.obj" />/&gt;
			</geometry>
		</collision>
		<collision>
			<origin xyz="0 0 0" />
			<geometry>
				<mesh filename="/home/blake/kitchen-worlds/assets/models/Camera/102472/textured_objs/original-98.obj" />/&gt;
			</geometry>
		</collision>
		<collision>
			<origin xyz="0 0 0" />
			<geometry>
				<mesh filename="/home/blake/kitchen-worlds/assets/models/Camera/102472/textured_objs/original-67.obj" />/&gt;
			</geometry>
		</collision>
		<collision>
			<origin xyz="0 0 0" />
			<geometry>
				<mesh filename="/home/blake/kitchen-worlds/assets/models/Camera/102472/textured_objs/original-69.obj" />/&gt;
			</geometry>
		</collision>
		<collision>
			<origin xyz="0 0 0" />
			<geometry>
				<mesh filename="/home/blake/kitchen-worlds/assets/models/Camera/102472/textured_objs/original-68.obj" />/&gt;
			</geometry>
		</collision>
		<collision>
			<origin xyz="0 0 0" />
			<geometry>
				<mesh filename="/home/blake/kitchen-worlds/assets/models/Camera/102472/textured_objs/original-80.obj" />/&gt;
			</geometry>
		</collision>
		<collision>
			<origin xyz="0 0 0" />
			<geometry>
				<mesh filename="/home/blake/kitchen-worlds/assets/models/Camera/102472/textured_objs/original-70.obj" />/&gt;
			</geometry>
		</collision>
		<collision>
			<origin xyz="0 0 0" />
			<geometry>
				<mesh filename="/home/blake/kitchen-worlds/assets/models/Camera/102472/textured_objs/original-74.obj" />/&gt;
			</geometry>
		</collision>
		<collision>
			<origin xyz="0 0 0" />
			<geometry>
				<mesh filename="/home/blake/kitchen-worlds/assets/models/Camera/102472/textured_objs/original-73.obj" />/&gt;
			</geometry>
		</collision>
		<collision>
			<origin xyz="0 0 0" />
			<geometry>
				<mesh filename="/home/blake/kitchen-worlds/assets/models/Camera/102472/textured_objs/original-79.obj" />/&gt;
			</geometry>
		</collision>
		<collision>
			<origin xyz="0 0 0" />
			<geometry>
				<mesh filename="/home/blake/kitchen-worlds/assets/models/Camera/102472/textured_objs/original-102.obj" />/&gt;
			</geometry>
		</collision>
		<collision>
			<origin xyz="0 0 0" />
			<geometry>
				<mesh filename="/home/blake/kitchen-worlds/assets/models/Camera/102472/textured_objs/original-115.obj" />/&gt;
			</geometry>
		</collision>
		<collision>
			<origin xyz="0 0 0" />
			<geometry>
				<mesh filename="/home/blake/kitchen-worlds/assets/models/Camera/102472/textured_objs/original-101.obj" />/&gt;
			</geometry>
		</collision>
		<collision>
			<origin xyz="0 0 0" />
			<geometry>
				<mesh filename="/home/blake/kitchen-worlds/assets/models/Camera/102472/textured_objs/original-81.obj" />/&gt;
			</geometry>
		</collision>
		<collision>
			<origin xyz="0 0 0" />
			<geometry>
				<mesh filename="/home/blake/kitchen-worlds/assets/models/Camera/102472/textured_objs/original-84.obj" />/&gt;
			</geometry>
		</collision>
		<collision>
			<origin xyz="0 0 0" />
			<geometry>
				<mesh filename="/home/blake/kitchen-worlds/assets/models/Camera/102472/textured_objs/original-97.obj" />/&gt;
			</geometry>
		</collision>
		<collision>
			<origin xyz="0 0 0" />
			<geometry>
				<mesh filename="/home/blake/kitchen-worlds/assets/models/Camera/102472/textured_objs/original-82.obj" />/&gt;
			</geometry>
		</collision>
		<collision>
			<origin xyz="0 0 0" />
			<geometry>
				<mesh filename="/home/blake/kitchen-worlds/assets/models/Camera/102472/textured_objs/original-60.obj" />/&gt;
			</geometry>
		</collision>
		<collision>
			<origin xyz="0 0 0" />
			<geometry>
				<mesh filename="/home/blake/kitchen-worlds/assets/models/Camera/102472/textured_objs/original-57.obj" />/&gt;
			</geometry>
		</collision>
	</link>
	<joint name="joint_6" type="fixed">
		<origin rpy="1.570796326794897 0 -1.570796326794897" xyz="0 0 0" />
		<child link="link_6" />
		<parent link="base" />
	</joint>
</robot>