<?xml version='1.0' encoding='utf-8'?>
<robot name="partnet_f844d0a2f4e28c5e4f9794688920aecc">
	<link name="base" />
	<link name="link_0">
		<visual name="rotation_lid-1">
			<origin xyz="0.08444495054915124 -0.3310890000000001 0.48781000000000024" />
			<geometry>
				<mesh filename="/home/blake/kitchen-worlds/assets/models/Box/100676/textured_objs/original-3.obj" />/&gt;
			</geometry>
		</visual>
		<collision>
			<origin xyz="0.08444495054915124 -0.3310890000000001 0.48781000000000024" />
			<geometry>
				<mesh filename="/home/blake/kitchen-worlds/assets/models/Box/100676/textured_objs/original-3.obj" />/&gt;
			</geometry>
		</collision>
	</link>
	<joint name="joint_0" type="revolute">
		<origin xyz="-0.08444495054915124 0.3310890000000001 -0.48781000000000024" />
		<axis xyz="-0.6156619104201522 0 0" />
		<child link="link_0" />
		<parent link="link_4" />
		<limit lower="-2.2305307840487525" upper="2.475575011028757" effort="10.0" velocity="1.0" />
	</joint>
	<link name="link_1">
		<visual name="rotation_lid-2">
			<origin xyz="0.4086159999999994 -0.33698332201064085 0.04031029578474025" />
			<geometry>
				<mesh filename="/home/blake/kitchen-worlds/assets/models/Box/100676/textured_objs/original-2.obj" />/&gt;
			</geometry>
		</visual>
		<collision>
			<origin xyz="0.4086159999999994 -0.33698332201064085 0.04031029578474025" />
			<geometry>
				<mesh filename="/home/blake/kitchen-worlds/assets/models/Box/100676/textured_objs/original-2.obj" />/&gt;
			</geometry>
		</collision>
	</link>
	<joint name="joint_1" type="revolute">
		<origin xyz="-0.4086159999999994 0.33698332201064085 -0.04031029578474025" />
		<axis xyz="0 0.003358814679379616 0.9622118586912968" />
		<child link="link_1" />
		<parent link="link_4" />
		<limit lower="-3.4243359924128742" upper="1.2629202467430969" effort="10.0" velocity="1.0" />
	</joint>
	<link name="link_2">
		<visual name="rotation_lid-3">
			<origin xyz="0.11829292135430186 -0.3365678037685762 -0.48263947649633876" />
			<geometry>
				<mesh filename="/home/blake/kitchen-worlds/assets/models/Box/100676/textured_objs/original-1.obj" />/&gt;
			</geometry>
		</visual>
		<collision>
			<origin xyz="0.11829292135430186 -0.3365678037685762 -0.48263947649633876" />
			<geometry>
				<mesh filename="/home/blake/kitchen-worlds/assets/models/Box/100676/textured_objs/original-1.obj" />/&gt;
			</geometry>
		</collision>
	</link>
	<joint name="joint_2" type="revolute">
		<origin xyz="-0.11829292135430186 0.3365678037685762 0.48263947649633876" />
		<axis xyz="0.8480473934658241 0 0" />
		<child link="link_2" />
		<parent link="link_4" />
		<limit lower="-2.5761059759436304" upper="2.0483184101405447" effort="10.0" velocity="1.0" />
	</joint>
	<link name="link_3">
		<visual name="rotation_lid-4">
			<origin xyz="-0.39177699999999993 -0.3304813420477989 0.03543925556249006" />
			<geometry>
				<mesh filename="/home/blake/kitchen-worlds/assets/models/Box/100676/textured_objs/original-4.obj" />/&gt;
			</geometry>
		</visual>
		<collision>
			<origin xyz="-0.39177699999999993 -0.3304813420477989 0.03543925556249006" />
			<geometry>
				<mesh filename="/home/blake/kitchen-worlds/assets/models/Box/100676/textured_objs/original-4.obj" />/&gt;
			</geometry>
		</collision>
	</link>
	<joint name="joint_3" type="revolute">
		<origin xyz="0.39177699999999993 0.3304813420477989 -0.03543925556249006" />
		<axis xyz="0 0 -0.13917310763295226" />
		<child link="link_3" />
		<parent link="link_4" />
		<limit lower="-1.6022122533307945" upper="3.07177948351002" effort="10.0" velocity="1.0" />
	</joint>
	<link name="link_4">
		<visual name="base_body-5">
			<origin xyz="0 0 0" />
			<geometry>
				<mesh filename="/home/blake/kitchen-worlds/assets/models/Box/100676/textured_objs/original-29.obj" />/&gt;
			</geometry>
		</visual>
		<visual name="base_body-5">
			<origin xyz="0 0 0" />
			<geometry>
				<mesh filename="/home/blake/kitchen-worlds/assets/models/Box/100676/textured_objs/original-21.obj" />/&gt;
			</geometry>
		</visual>
		<visual name="base_body-5">
			<origin xyz="0 0 0" />
			<geometry>
				<mesh filename="/home/blake/kitchen-worlds/assets/models/Box/100676/textured_objs/original-30.obj" />/&gt;
			</geometry>
		</visual>
		<visual name="base_body-5">
			<origin xyz="0 0 0" />
			<geometry>
				<mesh filename="/home/blake/kitchen-worlds/assets/models/Box/100676/textured_objs/original-28.obj" />/&gt;
			</geometry>
		</visual>
		<visual name="base_body-5">
			<origin xyz="0 0 0" />
			<geometry>
				<mesh filename="/home/blake/kitchen-worlds/assets/models/Box/100676/textured_objs/original-22.obj" />/&gt;
			</geometry>
		</visual>
		<visual name="base_body-5">
			<origin xyz="0 0 0" />
			<geometry>
				<mesh filename="/home/blake/kitchen-worlds/assets/models/Box/100676/textured_objs/original-26.obj" />/&gt;
			</geometry>
		</visual>
		<visual name="base_body-5">
			<origin xyz="0 0 0" />
			<geometry>
				<mesh filename="/home/blake/kitchen-worlds/assets/models/Box/100676/textured_objs/original-33.obj" />/&gt;
			</geometry>
		</visual>
		<visual name="base_body-5">
			<origin xyz="0 0 0" />
			<geometry>
				<mesh filename="/home/blake/kitchen-worlds/assets/models/Box/100676/textured_objs/original-16.obj" />/&gt;
			</geometry>
		</visual>
		<visual name="base_body-5">
			<origin xyz="0 0 0" />
			<geometry>
				<mesh filename="/home/blake/kitchen-worlds/assets/models/Box/100676/textured_objs/original-8.obj" />/&gt;
			</geometry>
		</visual>
		<visual name="base_body-5">
			<origin xyz="0 0 0" />
			<geometry>
				<mesh filename="/home/blake/kitchen-worlds/assets/models/Box/100676/textured_objs/original-13.obj" />/&gt;
			</geometry>
		</visual>
		<visual name="base_body-5">
			<origin xyz="0 0 0" />
			<geometry>
				<mesh filename="/home/blake/kitchen-worlds/assets/models/Box/100676/textured_objs/original-9.obj" />/&gt;
			</geometry>
		</visual>
		<visual name="base_body-5">
			<origin xyz="0 0 0" />
			<geometry>
				<mesh filename="/home/blake/kitchen-worlds/assets/models/Box/100676/textured_objs/original-27.obj" />/&gt;
			</geometry>
		</visual>
		<visual name="base_body-5">
			<origin xyz="0 0 0" />
			<geometry>
				<mesh filename="/home/blake/kitchen-worlds/assets/models/Box/100676/textured_objs/original-6.obj" />/&gt;
			</geometry>
		</visual>
		<visual name="base_body-5">
			<origin xyz="0 0 0" />
			<geometry>
				<mesh filename="/home/blake/kitchen-worlds/assets/models/Box/100676/textured_objs/original-31.obj" />/&gt;
			</geometry>
		</visual>
		<visual name="base_body-5">
			<origin xyz="0 0 0" />
			<geometry>
				<mesh filename="/home/blake/kitchen-worlds/assets/models/Box/100676/textured_objs/original-15.obj" />/&gt;
			</geometry>
		</visual>
		<visual name="base_body-5">
			<origin xyz="0 0 0" />
			<geometry>
				<mesh filename="/home/blake/kitchen-worlds/assets/models/Box/100676/textured_objs/original-23.obj" />/&gt;
			</geometry>
		</visual>
		<visual name="base_body-5">
			<origin xyz="0 0 0" />
			<geometry>
				<mesh filename="/home/blake/kitchen-worlds/assets/models/Box/100676/textured_objs/original-11.obj" />/&gt;
			</geometry>
		</visual>
		<visual name="base_body-5">
			<origin xyz="0 0 0" />
			<geometry>
				<mesh filename="/home/blake/kitchen-worlds/assets/models/Box/100676/textured_objs/original-18.obj" />/&gt;
			</geometry>
		</visual>
		<visual name="base_body-5">
			<origin xyz="0 0 0" />
			<geometry>
				<mesh filename="/home/blake/kitchen-worlds/assets/models/Box/100676/textured_objs/original-25.obj" />/&gt;
			</geometry>
		</visual>
		<visual name="base_body-5">
			<origin xyz="0 0 0" />
			<geometry>
				<mesh filename="/home/blake/kitchen-worlds/assets/models/Box/100676/textured_objs/original-17.obj" />/&gt;
			</geometry>
		</visual>
		<visual name="base_body-5">
			<origin xyz="0 0 0" />
			<geometry>
				<mesh filename="/home/blake/kitchen-worlds/assets/models/Box/100676/textured_objs/original-12.obj" />/&gt;
			</geometry>
		</visual>
		<visual name="base_body-5">
			<origin xyz="0 0 0" />
			<geometry>
				<mesh filename="/home/blake/kitchen-worlds/assets/models/Box/100676/textured_objs/original-24.obj" />/&gt;
			</geometry>
		</visual>
		<visual name="base_body-5">
			<origin xyz="0 0 0" />
			<geometry>
				<mesh filename="/home/blake/kitchen-worlds/assets/models/Box/100676/textured_objs/original-20.obj" />/&gt;
			</geometry>
		</visual>
		<visual name="base_body-5">
			<origin xyz="0 0 0" />
			<geometry>
				<mesh filename="/home/blake/kitchen-worlds/assets/models/Box/100676/textured_objs/original-32.obj" />/&gt;
			</geometry>
		</visual>
		<visual name="base_body-5">
			<origin xyz="0 0 0" />
			<geometry>
				<mesh filename="/home/blake/kitchen-worlds/assets/models/Box/100676/textured_objs/original-7.obj" />/&gt;
			</geometry>
		</visual>
		<visual name="base_body-5">
			<origin xyz="0 0 0" />
			<geometry>
				<mesh filename="/home/blake/kitchen-worlds/assets/models/Box/100676/textured_objs/original-10.obj" />/&gt;
			</geometry>
		</visual>
		<visual name="base_body-5">
			<origin xyz="0 0 0" />
			<geometry>
				<mesh filename="/home/blake/kitchen-worlds/assets/models/Box/100676/textured_objs/original-14.obj" />/&gt;
			</geometry>
		</visual>
		<visual name="base_body-5">
			<origin xyz="0 0 0" />
			<geometry>
				<mesh filename="/home/blake/kitchen-worlds/assets/models/Box/100676/textured_objs/original-19.obj" />/&gt;
			</geometry>
		</visual>
		<collision>
			<origin xyz="0 0 0" />
			<geometry>
				<mesh filename="/home/blake/kitchen-worlds/assets/models/Box/100676/textured_objs/original-29.obj" />/&gt;
			</geometry>
		</collision>
		<collision>
			<origin xyz="0 0 0" />
			<geometry>
				<mesh filename="/home/blake/kitchen-worlds/assets/models/Box/100676/textured_objs/original-21.obj" />/&gt;
			</geometry>
		</collision>
		<collision>
			<origin xyz="0 0 0" />
			<geometry>
				<mesh filename="/home/blake/kitchen-worlds/assets/models/Box/100676/textured_objs/original-30.obj" />/&gt;
			</geometry>
		</collision>
		<collision>
			<origin xyz="0 0 0" />
			<geometry>
				<mesh filename="/home/blake/kitchen-worlds/assets/models/Box/100676/textured_objs/original-28.obj" />/&gt;
			</geometry>
		</collision>
		<collision>
			<origin xyz="0 0 0" />
			<geometry>
				<mesh filename="/home/blake/kitchen-worlds/assets/models/Box/100676/textured_objs/original-22.obj" />/&gt;
			</geometry>
		</collision>
		<collision>
			<origin xyz="0 0 0" />
			<geometry>
				<mesh filename="/home/blake/kitchen-worlds/assets/models/Box/100676/textured_objs/original-26.obj" />/&gt;
			</geometry>
		</collision>
		<collision>
			<origin xyz="0 0 0" />
			<geometry>
				<mesh filename="/home/blake/kitchen-worlds/assets/models/Box/100676/textured_objs/original-33.obj" />/&gt;
			</geometry>
		</collision>
		<collision>
			<origin xyz="0 0 0" />
			<geometry>
				<mesh filename="/home/blake/kitchen-worlds/assets/models/Box/100676/textured_objs/original-16.obj" />/&gt;
			</geometry>
		</collision>
		<collision>
			<origin xyz="0 0 0" />
			<geometry>
				<mesh filename="/home/blake/kitchen-worlds/assets/models/Box/100676/textured_objs/original-8.obj" />/&gt;
			</geometry>
		</collision>
		<collision>
			<origin xyz="0 0 0" />
			<geometry>
				<mesh filename="/home/blake/kitchen-worlds/assets/models/Box/100676/textured_objs/original-13.obj" />/&gt;
			</geometry>
		</collision>
		<collision>
			<origin xyz="0 0 0" />
			<geometry>
				<mesh filename="/home/blake/kitchen-worlds/assets/models/Box/100676/textured_objs/original-9.obj" />/&gt;
			</geometry>
		</collision>
		<collision>
			<origin xyz="0 0 0" />
			<geometry>
				<mesh filename="/home/blake/kitchen-worlds/assets/models/Box/100676/textured_objs/original-27.obj" />/&gt;
			</geometry>
		</collision>
		<collision>
			<origin xyz="0 0 0" />
			<geometry>
				<mesh filename="/home/blake/kitchen-worlds/assets/models/Box/100676/textured_objs/original-6.obj" />/&gt;
			</geometry>
		</collision>
		<collision>
			<origin xyz="0 0 0" />
			<geometry>
				<mesh filename="/home/blake/kitchen-worlds/assets/models/Box/100676/textured_objs/original-31.obj" />/&gt;
			</geometry>
		</collision>
		<collision>
			<origin xyz="0 0 0" />
			<geometry>
				<mesh filename="/home/blake/kitchen-worlds/assets/models/Box/100676/textured_objs/original-15.obj" />/&gt;
			</geometry>
		</collision>
		<collision>
			<origin xyz="0 0 0" />
			<geometry>
				<mesh filename="/home/blake/kitchen-worlds/assets/models/Box/100676/textured_objs/original-23.obj" />/&gt;
			</geometry>
		</collision>
		<collision>
			<origin xyz="0 0 0" />
			<geometry>
				<mesh filename="/home/blake/kitchen-worlds/assets/models/Box/100676/textured_objs/original-11.obj" />/&gt;
			</geometry>
		</collision>
		<collision>
			<origin xyz="0 0 0" />
			<geometry>
				<mesh filename="/home/blake/kitchen-worlds/assets/models/Box/100676/textured_objs/original-18.obj" />/&gt;
			</geometry>
		</collision>
		<collision>
			<origin xyz="0 0 0" />
			<geometry>
				<mesh filename="/home/blake/kitchen-worlds/assets/models/Box/100676/textured_objs/original-25.obj" />/&gt;
			</geometry>
		</collision>
		<collision>
			<origin xyz="0 0 0" />
			<geometry>
				<mesh filename="/home/blake/kitchen-worlds/assets/models/Box/100676/textured_objs/original-17.obj" />/&gt;
			</geometry>
		</collision>
		<collision>
			<origin xyz="0 0 0" />
			<geometry>
				<mesh filename="/home/blake/kitchen-worlds/assets/models/Box/100676/textured_objs/original-12.obj" />/&gt;
			</geometry>
		</collision>
		<collision>
			<origin xyz="0 0 0" />
			<geometry>
				<mesh filename="/home/blake/kitchen-worlds/assets/models/Box/100676/textured_objs/original-24.obj" />/&gt;
			</geometry>
		</collision>
		<collision>
			<origin xyz="0 0 0" />
			<geometry>
				<mesh filename="/home/blake/kitchen-worlds/assets/models/Box/100676/textured_objs/original-20.obj" />/&gt;
			</geometry>
		</collision>
		<collision>
			<origin xyz="0 0 0" />
			<geometry>
				<mesh filename="/home/blake/kitchen-worlds/assets/models/Box/100676/textured_objs/original-32.obj" />/&gt;
			</geometry>
		</collision>
		<collision>
			<origin xyz="0 0 0" />
			<geometry>
				<mesh filename="/home/blake/kitchen-worlds/assets/models/Box/100676/textured_objs/original-7.obj" />/&gt;
			</geometry>
		</collision>
		<collision>
			<origin xyz="0 0 0" />
			<geometry>
				<mesh filename="/home/blake/kitchen-worlds/assets/models/Box/100676/textured_objs/original-10.obj" />/&gt;
			</geometry>
		</collision>
		<collision>
			<origin xyz="0 0 0" />
			<geometry>
				<mesh filename="/home/blake/kitchen-worlds/assets/models/Box/100676/textured_objs/original-14.obj" />/&gt;
			</geometry>
		</collision>
		<collision>
			<origin xyz="0 0 0" />
			<geometry>
				<mesh filename="/home/blake/kitchen-worlds/assets/models/Box/100676/textured_objs/original-19.obj" />/&gt;
			</geometry>
		</collision>
	</link>
	<joint name="joint_4" type="fixed">
		<origin rpy="1.570796326794897 0 -1.570796326794897" xyz="0 0 0" />
		<child link="link_4" />
		<parent link="base" />
	</joint>
</robot>