<?xml version='1.0' encoding='utf-8'?>
<robot name="partnet_1f51bf7da8ae7d40b9c80942c0a95e18">
	<link name="base" />


	<link name="handle_link_2">
		<inertial>
	      <origin rpy="0 0 0" xyz="0 0 0" />
	      <mass value="10.0" />
	      <inertia ixx="0.0001" ixy="0" ixz="0" iyy="0.0001" iyz="0" izz="0.0001" />
	    </inertial>
	    <visual name="xx">
	      <geometry>
	        <box size="0.1 0.2 0.02" />
	      </geometry>
	      <material name="Gray" />
	    </visual>
	    <collision>
	      <geometry>
	        <box size="0.1 0.2 0.02" />
	      </geometry>
	    </collision>
	</link>
	<joint name="handle_joint_2" type="fixed">
		<origin xyz="-0.65 -0.45 0.03" rpy="0 1.57 0" />
		<child link="handle_link_2" />
		<parent link="link_0" />
	</joint>

	<link name="handle_link_1">
		<inertial>
	      <origin rpy="0 0 0" xyz="0 0 0" />
	      <mass value="10.0" />
	      <inertia ixx="0.0001" ixy="0" ixz="0" iyy="0.0001" iyz="0" izz="0.0001" />
	    </inertial>
	    <visual name="xx">
	      <geometry>
	        <box size="0.1 0.2 0.02" />
	      </geometry>
	      <material name="Gray" />
	    </visual>
	    <collision>
	      <geometry>
	        <box size="0.1 0.2 0.02" />
	      </geometry>
	    </collision>
	</link>
	<joint name="handle_joint_1" type="fixed">
		<origin xyz="-0.65 -0.75 0.03" rpy="0 1.57 0" />
		<child link="handle_link_1" />
		<parent link="link_1" />
	</joint>

	<link name="link_0">
		<visual name="door_frame-14">
			<origin xyz="-0.32343233815052264 -0.8303490281105042 -0.3031162308561899" />
			<geometry>
				<mesh filename="/home/blake/kitchen-worlds/assets/models/Fridge/12248/textured_objs/original-5.obj" />/&gt;
			</geometry>
		</visual>
		<visual name="door_frame-14">
			<origin xyz="-0.32343233815052264 -0.8303490281105042 -0.3031162308561899" />
			<geometry>
				<mesh filename="/home/blake/kitchen-worlds/assets/models/Fridge/12248/textured_objs/original-17.obj" />/&gt;
			</geometry>
		</visual>
		<visual name="door_frame-14">
			<origin xyz="-0.32343233815052264 -0.8303490281105042 -0.3031162308561899" />
			<geometry>
				<mesh filename="/home/blake/kitchen-worlds/assets/models/Fridge/12248/textured_objs/original-11.obj" />/&gt;
			</geometry>
		</visual>
		<visual name="door_frame-14">
			<origin xyz="-0.32343233815052264 -0.8303490281105042 -0.3031162308561899" />
			<geometry>
				<mesh filename="/home/blake/kitchen-worlds/assets/models/Fridge/12248/textured_objs/original-6.obj" />/&gt;
			</geometry>
		</visual>
		<collision>
			<origin xyz="-0.32343233815052264 -0.8303490281105042 -0.3031162308561899" />
			<geometry>
				<mesh filename="/home/blake/kitchen-worlds/assets/models/Fridge/12248/textured_objs/original-5.obj" />/&gt;
			</geometry>
		</collision>
		<collision>
			<origin xyz="-0.32343233815052264 -0.8303490281105042 -0.3031162308561899" />
			<geometry>
				<mesh filename="/home/blake/kitchen-worlds/assets/models/Fridge/12248/textured_objs/original-17.obj" />/&gt;
			</geometry>
		</collision>
		<collision>
			<origin xyz="-0.32343233815052264 -0.8303490281105042 -0.3031162308561899" />
			<geometry>
				<mesh filename="/home/blake/kitchen-worlds/assets/models/Fridge/12248/textured_objs/original-11.obj" />/&gt;
			</geometry>
		</collision>
		<collision>
			<origin xyz="-0.32343233815052264 -0.8303490281105042 -0.3031162308561899" />
			<geometry>
				<mesh filename="/home/blake/kitchen-worlds/assets/models/Fridge/12248/textured_objs/original-6.obj" />/&gt;
			</geometry>
		</collision>
	</link>
	<joint name="joint_0" type="revolute">
		<origin xyz="0.32343233815052264 0.8303490281105042 0.3031162308561899" />
		<axis xyz="0 1 0" />
		<child link="link_0" />
		<parent link="link_2" />
		<limit lower="0.0" upper="2.412743157956961" effort="10.0" velocity="1.0" />
	</joint>
	<link name="link_1">
		<visual name="door_frame-13">
			<origin xyz="-0.32343233815052264 -0.8303490281105042 -0.3031162308561899" />
			<geometry>
				<mesh filename="/home/blake/kitchen-worlds/assets/models/Fridge/12248/textured_objs/original-7.obj" />/&gt;
			</geometry>
		</visual>
		<visual name="door_frame-13">
			<origin xyz="-0.32343233815052264 -0.8303490281105042 -0.3031162308561899" />
			<geometry>
				<mesh filename="/home/blake/kitchen-worlds/assets/models/Fridge/12248/textured_objs/original-15.obj" />/&gt;
			</geometry>
		</visual>
		<visual name="door_frame-13">
			<origin xyz="-0.32343233815052264 -0.8303490281105042 -0.3031162308561899" />
			<geometry>
				<mesh filename="/home/blake/kitchen-worlds/assets/models/Fridge/12248/textured_objs/original-10.obj" />/&gt;
			</geometry>
		</visual>
		<visual name="door_frame-13">
			<origin xyz="-0.32343233815052264 -0.8303490281105042 -0.3031162308561899" />
			<geometry>
				<mesh filename="/home/blake/kitchen-worlds/assets/models/Fridge/12248/textured_objs/original-13.obj" />/&gt;
			</geometry>
		</visual>
		<visual name="door_frame-13">
			<origin xyz="-0.32343233815052264 -0.8303490281105042 -0.3031162308561899" />
			<geometry>
				<mesh filename="/home/blake/kitchen-worlds/assets/models/Fridge/12248/textured_objs/original-9.obj" />/&gt;
			</geometry>
		</visual>
		<visual name="door_frame-13">
			<origin xyz="-0.32343233815052264 -0.8303490281105042 -0.3031162308561899" />
			<geometry>
				<mesh filename="/home/blake/kitchen-worlds/assets/models/Fridge/12248/textured_objs/original-12.obj" />/&gt;
			</geometry>
		</visual>
		<visual name="door_frame-13">
			<origin xyz="-0.32343233815052264 -0.8303490281105042 -0.3031162308561899" />
			<geometry>
				<mesh filename="/home/blake/kitchen-worlds/assets/models/Fridge/12248/textured_objs/original-14.obj" />/&gt;
			</geometry>
		</visual>
		<collision>
			<origin xyz="-0.32343233815052264 -0.8303490281105042 -0.3031162308561899" />
			<geometry>
				<mesh filename="/home/blake/kitchen-worlds/assets/models/Fridge/12248/textured_objs/original-7.obj" />/&gt;
			</geometry>
		</collision>
		<collision>
			<origin xyz="-0.32343233815052264 -0.8303490281105042 -0.3031162308561899" />
			<geometry>
				<mesh filename="/home/blake/kitchen-worlds/assets/models/Fridge/12248/textured_objs/original-15.obj" />/&gt;
			</geometry>
		</collision>
		<collision>
			<origin xyz="-0.32343233815052264 -0.8303490281105042 -0.3031162308561899" />
			<geometry>
				<mesh filename="/home/blake/kitchen-worlds/assets/models/Fridge/12248/textured_objs/original-10.obj" />/&gt;
			</geometry>
		</collision>
		<collision>
			<origin xyz="-0.32343233815052264 -0.8303490281105042 -0.3031162308561899" />
			<geometry>
				<mesh filename="/home/blake/kitchen-worlds/assets/models/Fridge/12248/textured_objs/original-13.obj" />/&gt;
			</geometry>
		</collision>
		<collision>
			<origin xyz="-0.32343233815052264 -0.8303490281105042 -0.3031162308561899" />
			<geometry>
				<mesh filename="/home/blake/kitchen-worlds/assets/models/Fridge/12248/textured_objs/original-9.obj" />/&gt;
			</geometry>
		</collision>
		<collision>
			<origin xyz="-0.32343233815052264 -0.8303490281105042 -0.3031162308561899" />
			<geometry>
				<mesh filename="/home/blake/kitchen-worlds/assets/models/Fridge/12248/textured_objs/original-12.obj" />/&gt;
			</geometry>
		</collision>
		<collision>
			<origin xyz="-0.32343233815052264 -0.8303490281105042 -0.3031162308561899" />
			<geometry>
				<mesh filename="/home/blake/kitchen-worlds/assets/models/Fridge/12248/textured_objs/original-14.obj" />/&gt;
			</geometry>
		</collision>
	</link>
	<joint name="joint_1" type="revolute">
		<origin xyz="0.32343233815052264 0.8303490281105042 0.3031162308561899" />
		<axis xyz="0 1 0" />
		<child link="link_1" />
		<parent link="link_2" />
		<limit lower="0.0" upper="2.4378758991856797" effort="10.0" velocity="1.0" />
	</joint>
	<link name="link_2">
		<visual name="frame-8">
			<origin xyz="0 0 0" />
			<geometry>
				<mesh filename="/home/blake/kitchen-worlds/assets/models/Fridge/12248/textured_objs/original-16.obj" />/&gt;
			</geometry>
		</visual>
		<visual name="frame-8">
			<origin xyz="0 0 0" />
			<geometry>
				<mesh filename="/home/blake/kitchen-worlds/assets/models/Fridge/12248/textured_objs/original-8.obj" />/&gt;
			</geometry>
		</visual>
		<visual name="foot-4">
			<origin xyz="0 0 0" />
			<geometry>
				<mesh filename="/home/blake/kitchen-worlds/assets/models/Fridge/12248/textured_objs/original-3.obj" />/&gt;
			</geometry>
		</visual>
		<visual name="foot-5">
			<origin xyz="0 0 0" />
			<geometry>
				<mesh filename="/home/blake/kitchen-worlds/assets/models/Fridge/12248/textured_objs/original-2.obj" />/&gt;
			</geometry>
		</visual>
		<visual name="foot-6">
			<origin xyz="0 0 0" />
			<geometry>
				<mesh filename="/home/blake/kitchen-worlds/assets/models/Fridge/12248/textured_objs/original-1.obj" />/&gt;
			</geometry>
		</visual>
		<visual name="foot-7">
			<origin xyz="0 0 0" />
			<geometry>
				<mesh filename="/home/blake/kitchen-worlds/assets/models/Fridge/12248/textured_objs/original-4.obj" />/&gt;
			</geometry>
		</visual>
		<collision>
			<origin xyz="0 0 0" />
			<geometry>
				<mesh filename="/home/blake/kitchen-worlds/assets/models/Fridge/12248/textured_objs/original-16.obj" />/&gt;
			</geometry>
		</collision>
		<collision>
			<origin xyz="0 0 0" />
			<geometry>
				<mesh filename="/home/blake/kitchen-worlds/assets/models/Fridge/12248/textured_objs/original-8.obj" />/&gt;
			</geometry>
		</collision>
		<collision>
			<origin xyz="0 0 0" />
			<geometry>
				<mesh filename="/home/blake/kitchen-worlds/assets/models/Fridge/12248/textured_objs/original-3.obj" />/&gt;
			</geometry>
		</collision>
		<collision>
			<origin xyz="0 0 0" />
			<geometry>
				<mesh filename="/home/blake/kitchen-worlds/assets/models/Fridge/12248/textured_objs/original-2.obj" />/&gt;
			</geometry>
		</collision>
		<collision>
			<origin xyz="0 0 0" />
			<geometry>
				<mesh filename="/home/blake/kitchen-worlds/assets/models/Fridge/12248/textured_objs/original-1.obj" />/&gt;
			</geometry>
		</collision>
		<collision>
			<origin xyz="0 0 0" />
			<geometry>
				<mesh filename="/home/blake/kitchen-worlds/assets/models/Fridge/12248/textured_objs/original-4.obj" />/&gt;
			</geometry>
		</collision>
	</link>
	<joint name="joint_2" type="fixed">
		<origin rpy="1.570796326794897 0 -1.570796326794897" xyz="0 0 0" />
		<child link="link_2" />
		<parent link="base" />
	</joint>
</robot>