<?xml version='1.0' encoding='utf-8'?>
<robot name="partnet_640da7c995f9fcdeab571431db8834c7">
	<link name="base" />
	<link name="link_0">
		<visual name="cabinet_door_surface-14">
			<origin xyz="-0.22069594667286369 0.5647149999999999 0.23656584976974582" />
			<geometry>
				<mesh filename="/home/blake/kitchen-worlds/assets/models/DiningTable/23782/textured_objs/original-10.obj" />/&gt;
			</geometry>
		</visual>
		<visual name="handle-15">
			<origin xyz="-0.22069594667286369 0.5647149999999999 0.23656584976974582" />
			<geometry>
				<mesh filename="/home/blake/kitchen-worlds/assets/models/DiningTable/23782/textured_objs/original-9.obj" />/&gt;
			</geometry>
		</visual>
		<collision>
			<origin xyz="-0.22069594667286369 0.5647149999999999 0.23656584976974582" />
			<geometry>
				<mesh filename="/home/blake/kitchen-worlds/assets/models/DiningTable/23782/textured_objs/original-10.obj" />/&gt;
			</geometry>
		</collision>
		<collision>
			<origin xyz="-0.22069594667286369 0.5647149999999999 0.23656584976974582" />
			<geometry>
				<mesh filename="/home/blake/kitchen-worlds/assets/models/DiningTable/23782/textured_objs/original-9.obj" />/&gt;
			</geometry>
		</collision>
	</link>
	<joint name="joint_0" type="revolute">
		<origin xyz="0.22069594667286369 -0.5647149999999999 -0.23656584976974582" />
		<axis xyz="0 1 0" />
		<child link="link_0" />
		<parent link="link_2" />
		<limit lower="0.0" upper="1.5707963267948966" effort="10.0" velocity="1.0" />
	</joint>
	<link name="link_1">
		<visual name="cabinet_door_surface-12">
			<origin xyz="-0.35967206909502736 0.5647149999999996 -0.22012615797576596" />
			<geometry>
				<mesh filename="/home/blake/kitchen-worlds/assets/models/DiningTable/23782/textured_objs/original-12.obj" />/&gt;
			</geometry>
		</visual>
		<visual name="handle-13">
			<origin xyz="-0.35967206909502736 0.5647149999999996 -0.22012615797576596" />
			<geometry>
				<mesh filename="/home/blake/kitchen-worlds/assets/models/DiningTable/23782/textured_objs/original-8.obj" />/&gt;
			</geometry>
		</visual>
		<collision>
			<origin xyz="-0.35967206909502736 0.5647149999999996 -0.22012615797576596" />
			<geometry>
				<mesh filename="/home/blake/kitchen-worlds/assets/models/DiningTable/23782/textured_objs/original-12.obj" />/&gt;
			</geometry>
		</collision>
		<collision>
			<origin xyz="-0.35967206909502736 0.5647149999999996 -0.22012615797576596" />
			<geometry>
				<mesh filename="/home/blake/kitchen-worlds/assets/models/DiningTable/23782/textured_objs/original-8.obj" />/&gt;
			</geometry>
		</collision>
	</link>
	<joint name="joint_1" type="revolute">
		<origin xyz="0.35967206909502736 -0.5647149999999996 0.22012615797576596" />
		<axis xyz="0 1 0" />
		<child link="link_1" />
		<parent link="link_2" />
		<limit lower="0.0" upper="1.5707963267948966" effort="10.0" velocity="1.0" />
	</joint>
	<link name="link_2">
		<visual name="board-17">
			<origin xyz="0 0 0" />
			<geometry>
				<mesh filename="/home/blake/kitchen-worlds/assets/models/DiningTable/23782/textured_objs/original-14.obj" />/&gt;
			</geometry>
		</visual>
		<visual name="vertical_side_panel-7">
			<origin xyz="0 0 0" />
			<geometry>
				<mesh filename="/home/blake/kitchen-worlds/assets/models/DiningTable/23782/textured_objs/original-11.obj" />/&gt;
			</geometry>
		</visual>
		<visual name="vertical_side_panel-8">
			<origin xyz="0 0 0" />
			<geometry>
				<mesh filename="/home/blake/kitchen-worlds/assets/models/DiningTable/23782/textured_objs/original-4.obj" />/&gt;
			</geometry>
		</visual>
		<visual name="bottom_panel-9">
			<origin xyz="0 0 0" />
			<geometry>
				<mesh filename="/home/blake/kitchen-worlds/assets/models/DiningTable/23782/textured_objs/original-7.obj" />/&gt;
			</geometry>
		</visual>
		<visual name="leg-10">
			<origin xyz="0 0 0" />
			<geometry>
				<mesh filename="/home/blake/kitchen-worlds/assets/models/DiningTable/23782/textured_objs/original-6.obj" />/&gt;
			</geometry>
		</visual>
		<visual name="leg-10">
			<origin xyz="0 0 0" />
			<geometry>
				<mesh filename="/home/blake/kitchen-worlds/assets/models/DiningTable/23782/textured_objs/original-2.obj" />/&gt;
			</geometry>
		</visual>
		<visual name="leg-11">
			<origin xyz="0 0 0" />
			<geometry>
				<mesh filename="/home/blake/kitchen-worlds/assets/models/DiningTable/23782/textured_objs/original-5.obj" />/&gt;
			</geometry>
		</visual>
		<visual name="leg-11">
			<origin xyz="0 0 0" />
			<geometry>
				<mesh filename="/home/blake/kitchen-worlds/assets/models/DiningTable/23782/textured_objs/original-3.obj" />/&gt;
			</geometry>
		</visual>
		<visual name="other_leaf-19">
			<origin xyz="0 0 0" />
			<geometry>
				<mesh filename="/home/blake/kitchen-worlds/assets/models/DiningTable/23782/textured_objs/original-13.obj" />/&gt;
			</geometry>
		</visual>
		<collision>
			<origin xyz="0 0 0" />
			<geometry>
				<mesh filename="/home/blake/kitchen-worlds/assets/models/DiningTable/23782/textured_objs/original-14.obj" />/&gt;
			</geometry>
		</collision>
		<collision>
			<origin xyz="0 0 0" />
			<geometry>
				<mesh filename="/home/blake/kitchen-worlds/assets/models/DiningTable/23782/textured_objs/original-11.obj" />/&gt;
			</geometry>
		</collision>
		<collision>
			<origin xyz="0 0 0" />
			<geometry>
				<mesh filename="/home/blake/kitchen-worlds/assets/models/DiningTable/23782/textured_objs/original-4.obj" />/&gt;
			</geometry>
		</collision>
		<collision>
			<origin xyz="0 0 0" />
			<geometry>
				<mesh filename="/home/blake/kitchen-worlds/assets/models/DiningTable/23782/textured_objs/original-7.obj" />/&gt;
			</geometry>
		</collision>
		<collision>
			<origin xyz="0 0 0" />
			<geometry>
				<mesh filename="/home/blake/kitchen-worlds/assets/models/DiningTable/23782/textured_objs/original-6.obj" />/&gt;
			</geometry>
		</collision>
		<collision>
			<origin xyz="0 0 0" />
			<geometry>
				<mesh filename="/home/blake/kitchen-worlds/assets/models/DiningTable/23782/textured_objs/original-2.obj" />/&gt;
			</geometry>
		</collision>
		<collision>
			<origin xyz="0 0 0" />
			<geometry>
				<mesh filename="/home/blake/kitchen-worlds/assets/models/DiningTable/23782/textured_objs/original-5.obj" />/&gt;
			</geometry>
		</collision>
		<collision>
			<origin xyz="0 0 0" />
			<geometry>
				<mesh filename="/home/blake/kitchen-worlds/assets/models/DiningTable/23782/textured_objs/original-3.obj" />/&gt;
			</geometry>
		</collision>
		<collision>
			<origin xyz="0 0 0" />
			<geometry>
				<mesh filename="/home/blake/kitchen-worlds/assets/models/DiningTable/23782/textured_objs/original-13.obj" />/&gt;
			</geometry>
		</collision>
	</link>
	<joint name="joint_2" type="fixed">
		<origin rpy="1.570796326794897 0 -1.570796326794897" xyz="0 0 0" />
		<child link="link_2" />
		<parent link="base" />
	</joint>
</robot>