<?xml version='1.0' encoding='utf-8'?>
<robot name="partnet_453034dc-b04a-4415-8c43-16d6d23c47b2">
	<link name="base" />
	<link name="link_0">
		<visual name="body-1">
			<origin xyz="-0.0 -0.0677290172544402 0.728057998017902" />
			<geometry>
				<mesh filename="/home/blake/kitchen-worlds/assets/models/Stapler/103104/textured_objs/original-29.obj" />/&gt;
			</geometry>
		</visual>
		<visual name="body-1">
			<origin xyz="-0.0 -0.0677290172544402 0.728057998017902" />
			<geometry>
				<mesh filename="/home/blake/kitchen-worlds/assets/models/Stapler/103104/textured_objs/original-24.obj" />/&gt;
			</geometry>
		</visual>
		<visual name="body-1">
			<origin xyz="-0.0 -0.0677290172544402 0.728057998017902" />
			<geometry>
				<mesh filename="/home/blake/kitchen-worlds/assets/models/Stapler/103104/textured_objs/original-27.obj" />/&gt;
			</geometry>
		</visual>
		<visual name="body-1">
			<origin xyz="-0.0 -0.0677290172544402 0.728057998017902" />
			<geometry>
				<mesh filename="/home/blake/kitchen-worlds/assets/models/Stapler/103104/textured_objs/original-26.obj" />/&gt;
			</geometry>
		</visual>
		<visual name="body-1">
			<origin xyz="-0.0 -0.0677290172544402 0.728057998017902" />
			<geometry>
				<mesh filename="/home/blake/kitchen-worlds/assets/models/Stapler/103104/textured_objs/original-25.obj" />/&gt;
			</geometry>
		</visual>
		<visual name="body-1">
			<origin xyz="-0.0 -0.0677290172544402 0.728057998017902" />
			<geometry>
				<mesh filename="/home/blake/kitchen-worlds/assets/models/Stapler/103104/textured_objs/original-28.obj" />/&gt;
			</geometry>
		</visual>
		<visual name="body-1">
			<origin xyz="-0.0 -0.0677290172544402 0.728057998017902" />
			<geometry>
				<mesh filename="/home/blake/kitchen-worlds/assets/models/Stapler/103104/textured_objs/original-31.obj" />/&gt;
			</geometry>
		</visual>
		<visual name="body-1">
			<origin xyz="-0.0 -0.0677290172544402 0.728057998017902" />
			<geometry>
				<mesh filename="/home/blake/kitchen-worlds/assets/models/Stapler/103104/textured_objs/original-23.obj" />/&gt;
			</geometry>
		</visual>
		<visual name="body-1">
			<origin xyz="-0.0 -0.0677290172544402 0.728057998017902" />
			<geometry>
				<mesh filename="/home/blake/kitchen-worlds/assets/models/Stapler/103104/textured_objs/original-22.obj" />/&gt;
			</geometry>
		</visual>
		<visual name="body-1">
			<origin xyz="-0.0 -0.0677290172544402 0.728057998017902" />
			<geometry>
				<mesh filename="/home/blake/kitchen-worlds/assets/models/Stapler/103104/textured_objs/original-32.obj" />/&gt;
			</geometry>
		</visual>
		<collision>
			<origin xyz="-0.0 -0.0677290172544402 0.728057998017902" />
			<geometry>
				<mesh filename="/home/blake/kitchen-worlds/assets/models/Stapler/103104/textured_objs/original-29.obj" />/&gt;
			</geometry>
		</collision>
		<collision>
			<origin xyz="-0.0 -0.0677290172544402 0.728057998017902" />
			<geometry>
				<mesh filename="/home/blake/kitchen-worlds/assets/models/Stapler/103104/textured_objs/original-24.obj" />/&gt;
			</geometry>
		</collision>
		<collision>
			<origin xyz="-0.0 -0.0677290172544402 0.728057998017902" />
			<geometry>
				<mesh filename="/home/blake/kitchen-worlds/assets/models/Stapler/103104/textured_objs/original-27.obj" />/&gt;
			</geometry>
		</collision>
		<collision>
			<origin xyz="-0.0 -0.0677290172544402 0.728057998017902" />
			<geometry>
				<mesh filename="/home/blake/kitchen-worlds/assets/models/Stapler/103104/textured_objs/original-26.obj" />/&gt;
			</geometry>
		</collision>
		<collision>
			<origin xyz="-0.0 -0.0677290172544402 0.728057998017902" />
			<geometry>
				<mesh filename="/home/blake/kitchen-worlds/assets/models/Stapler/103104/textured_objs/original-25.obj" />/&gt;
			</geometry>
		</collision>
		<collision>
			<origin xyz="-0.0 -0.0677290172544402 0.728057998017902" />
			<geometry>
				<mesh filename="/home/blake/kitchen-worlds/assets/models/Stapler/103104/textured_objs/original-28.obj" />/&gt;
			</geometry>
		</collision>
		<collision>
			<origin xyz="-0.0 -0.0677290172544402 0.728057998017902" />
			<geometry>
				<mesh filename="/home/blake/kitchen-worlds/assets/models/Stapler/103104/textured_objs/original-31.obj" />/&gt;
			</geometry>
		</collision>
		<collision>
			<origin xyz="-0.0 -0.0677290172544402 0.728057998017902" />
			<geometry>
				<mesh filename="/home/blake/kitchen-worlds/assets/models/Stapler/103104/textured_objs/original-23.obj" />/&gt;
			</geometry>
		</collision>
		<collision>
			<origin xyz="-0.0 -0.0677290172544402 0.728057998017902" />
			<geometry>
				<mesh filename="/home/blake/kitchen-worlds/assets/models/Stapler/103104/textured_objs/original-22.obj" />/&gt;
			</geometry>
		</collision>
		<collision>
			<origin xyz="-0.0 -0.0677290172544402 0.728057998017902" />
			<geometry>
				<mesh filename="/home/blake/kitchen-worlds/assets/models/Stapler/103104/textured_objs/original-32.obj" />/&gt;
			</geometry>
		</collision>
	</link>
	<joint name="joint_0" type="revolute">
		<origin xyz="0.0 0.0 0.0" />
		<axis xyz="1.0 0.0 0.0" />
		<child link="link_0" />
		<parent link="link_1" />
		<limit lower="0.0" upper="2.670353755551324" effort="10.0" velocity="1.0" />
	</joint>
	<link name="link_1">
		<visual name="lid-2">
			<origin xyz="-0.0 -0.0677290172544402 0.728057998017902" />
			<geometry>
				<mesh filename="/home/blake/kitchen-worlds/assets/models/Stapler/103104/textured_objs/original-19.obj" />/&gt;
			</geometry>
		</visual>
		<visual name="lid-2">
			<origin xyz="-0.0 -0.0677290172544402 0.728057998017902" />
			<geometry>
				<mesh filename="/home/blake/kitchen-worlds/assets/models/Stapler/103104/textured_objs/original-18.obj" />/&gt;
			</geometry>
		</visual>
		<visual name="lid-2">
			<origin xyz="-0.0 -0.0677290172544402 0.728057998017902" />
			<geometry>
				<mesh filename="/home/blake/kitchen-worlds/assets/models/Stapler/103104/textured_objs/original-20.obj" />/&gt;
			</geometry>
		</visual>
		<collision>
			<origin xyz="-0.0 -0.0677290172544402 0.728057998017902" />
			<geometry>
				<mesh filename="/home/blake/kitchen-worlds/assets/models/Stapler/103104/textured_objs/original-19.obj" />/&gt;
			</geometry>
		</collision>
		<collision>
			<origin xyz="-0.0 -0.0677290172544402 0.728057998017902" />
			<geometry>
				<mesh filename="/home/blake/kitchen-worlds/assets/models/Stapler/103104/textured_objs/original-18.obj" />/&gt;
			</geometry>
		</collision>
		<collision>
			<origin xyz="-0.0 -0.0677290172544402 0.728057998017902" />
			<geometry>
				<mesh filename="/home/blake/kitchen-worlds/assets/models/Stapler/103104/textured_objs/original-20.obj" />/&gt;
			</geometry>
		</collision>
	</link>
	<joint name="joint_1" type="revolute">
		<origin xyz="0.0 0.0677290172544402 -0.728057998017902" />
		<axis xyz="-1.0 -0.0 -0.0" />
		<child link="link_1" />
		<parent link="link_2" />
		<limit lower="-0.03769911184307752" upper="2.305929007734908" effort="10.0" velocity="1.0" />
	</joint>
	<link name="link_2">
		<visual name="base_body-3">
			<origin xyz="0 0 0" />
			<geometry>
				<mesh filename="/home/blake/kitchen-worlds/assets/models/Stapler/103104/textured_objs/original-4.obj" />/&gt;
			</geometry>
		</visual>
		<visual name="base_body-3">
			<origin xyz="0 0 0" />
			<geometry>
				<mesh filename="/home/blake/kitchen-worlds/assets/models/Stapler/103104/textured_objs/original-2.obj" />/&gt;
			</geometry>
		</visual>
		<visual name="base_body-3">
			<origin xyz="0 0 0" />
			<geometry>
				<mesh filename="/home/blake/kitchen-worlds/assets/models/Stapler/103104/textured_objs/original-16.obj" />/&gt;
			</geometry>
		</visual>
		<visual name="base_body-3">
			<origin xyz="0 0 0" />
			<geometry>
				<mesh filename="/home/blake/kitchen-worlds/assets/models/Stapler/103104/textured_objs/original-8.obj" />/&gt;
			</geometry>
		</visual>
		<visual name="base_body-3">
			<origin xyz="0 0 0" />
			<geometry>
				<mesh filename="/home/blake/kitchen-worlds/assets/models/Stapler/103104/textured_objs/original-13.obj" />/&gt;
			</geometry>
		</visual>
		<visual name="base_body-3">
			<origin xyz="0 0 0" />
			<geometry>
				<mesh filename="/home/blake/kitchen-worlds/assets/models/Stapler/103104/textured_objs/original-9.obj" />/&gt;
			</geometry>
		</visual>
		<visual name="base_body-3">
			<origin xyz="0 0 0" />
			<geometry>
				<mesh filename="/home/blake/kitchen-worlds/assets/models/Stapler/103104/textured_objs/original-5.obj" />/&gt;
			</geometry>
		</visual>
		<visual name="base_body-3">
			<origin xyz="0 0 0" />
			<geometry>
				<mesh filename="/home/blake/kitchen-worlds/assets/models/Stapler/103104/textured_objs/original-6.obj" />/&gt;
			</geometry>
		</visual>
		<visual name="base_body-3">
			<origin xyz="0 0 0" />
			<geometry>
				<mesh filename="/home/blake/kitchen-worlds/assets/models/Stapler/103104/textured_objs/original-15.obj" />/&gt;
			</geometry>
		</visual>
		<visual name="base_body-3">
			<origin xyz="0 0 0" />
			<geometry>
				<mesh filename="/home/blake/kitchen-worlds/assets/models/Stapler/103104/textured_objs/original-11.obj" />/&gt;
			</geometry>
		</visual>
		<visual name="base_body-3">
			<origin xyz="0 0 0" />
			<geometry>
				<mesh filename="/home/blake/kitchen-worlds/assets/models/Stapler/103104/textured_objs/original-12.obj" />/&gt;
			</geometry>
		</visual>
		<visual name="base_body-3">
			<origin xyz="0 0 0" />
			<geometry>
				<mesh filename="/home/blake/kitchen-worlds/assets/models/Stapler/103104/textured_objs/original-7.obj" />/&gt;
			</geometry>
		</visual>
		<visual name="base_body-3">
			<origin xyz="0 0 0" />
			<geometry>
				<mesh filename="/home/blake/kitchen-worlds/assets/models/Stapler/103104/textured_objs/original-1.obj" />/&gt;
			</geometry>
		</visual>
		<visual name="base_body-3">
			<origin xyz="0 0 0" />
			<geometry>
				<mesh filename="/home/blake/kitchen-worlds/assets/models/Stapler/103104/textured_objs/original-10.obj" />/&gt;
			</geometry>
		</visual>
		<visual name="base_body-3">
			<origin xyz="0 0 0" />
			<geometry>
				<mesh filename="/home/blake/kitchen-worlds/assets/models/Stapler/103104/textured_objs/original-14.obj" />/&gt;
			</geometry>
		</visual>
		<collision>
			<origin xyz="0 0 0" />
			<geometry>
				<mesh filename="/home/blake/kitchen-worlds/assets/models/Stapler/103104/textured_objs/original-4.obj" />/&gt;
			</geometry>
		</collision>
		<collision>
			<origin xyz="0 0 0" />
			<geometry>
				<mesh filename="/home/blake/kitchen-worlds/assets/models/Stapler/103104/textured_objs/original-2.obj" />/&gt;
			</geometry>
		</collision>
		<collision>
			<origin xyz="0 0 0" />
			<geometry>
				<mesh filename="/home/blake/kitchen-worlds/assets/models/Stapler/103104/textured_objs/original-16.obj" />/&gt;
			</geometry>
		</collision>
		<collision>
			<origin xyz="0 0 0" />
			<geometry>
				<mesh filename="/home/blake/kitchen-worlds/assets/models/Stapler/103104/textured_objs/original-8.obj" />/&gt;
			</geometry>
		</collision>
		<collision>
			<origin xyz="0 0 0" />
			<geometry>
				<mesh filename="/home/blake/kitchen-worlds/assets/models/Stapler/103104/textured_objs/original-13.obj" />/&gt;
			</geometry>
		</collision>
		<collision>
			<origin xyz="0 0 0" />
			<geometry>
				<mesh filename="/home/blake/kitchen-worlds/assets/models/Stapler/103104/textured_objs/original-9.obj" />/&gt;
			</geometry>
		</collision>
		<collision>
			<origin xyz="0 0 0" />
			<geometry>
				<mesh filename="/home/blake/kitchen-worlds/assets/models/Stapler/103104/textured_objs/original-5.obj" />/&gt;
			</geometry>
		</collision>
		<collision>
			<origin xyz="0 0 0" />
			<geometry>
				<mesh filename="/home/blake/kitchen-worlds/assets/models/Stapler/103104/textured_objs/original-6.obj" />/&gt;
			</geometry>
		</collision>
		<collision>
			<origin xyz="0 0 0" />
			<geometry>
				<mesh filename="/home/blake/kitchen-worlds/assets/models/Stapler/103104/textured_objs/original-15.obj" />/&gt;
			</geometry>
		</collision>
		<collision>
			<origin xyz="0 0 0" />
			<geometry>
				<mesh filename="/home/blake/kitchen-worlds/assets/models/Stapler/103104/textured_objs/original-11.obj" />/&gt;
			</geometry>
		</collision>
		<collision>
			<origin xyz="0 0 0" />
			<geometry>
				<mesh filename="/home/blake/kitchen-worlds/assets/models/Stapler/103104/textured_objs/original-12.obj" />/&gt;
			</geometry>
		</collision>
		<collision>
			<origin xyz="0 0 0" />
			<geometry>
				<mesh filename="/home/blake/kitchen-worlds/assets/models/Stapler/103104/textured_objs/original-7.obj" />/&gt;
			</geometry>
		</collision>
		<collision>
			<origin xyz="0 0 0" />
			<geometry>
				<mesh filename="/home/blake/kitchen-worlds/assets/models/Stapler/103104/textured_objs/original-1.obj" />/&gt;
			</geometry>
		</collision>
		<collision>
			<origin xyz="0 0 0" />
			<geometry>
				<mesh filename="/home/blake/kitchen-worlds/assets/models/Stapler/103104/textured_objs/original-10.obj" />/&gt;
			</geometry>
		</collision>
		<collision>
			<origin xyz="0 0 0" />
			<geometry>
				<mesh filename="/home/blake/kitchen-worlds/assets/models/Stapler/103104/textured_objs/original-14.obj" />/&gt;
			</geometry>
		</collision>
	</link>
	<joint name="joint_2" type="fixed">
		<origin rpy="1.570796326794897 0 -1.570796326794897" xyz="0 0 0" />
		<child link="link_2" />
		<parent link="base" />
	</joint>
</robot>