<?xml version='1.0' encoding='utf-8'?>
<robot name="partnet_8ed3447275de7695149c1768202b4e64">
	<link name="base" />

	<link name="handle_1">
		<visual name="handle-14">
			<origin xyz="0.5038798779540579 -0.757308 -0.3910896986000594" />
			<geometry>
				<mesh filename="/home/blake/kitchen-worlds/assets/models/MiniFridge/11178/textured_objs/new-4.obj" />/&gt;
			</geometry>
		</visual>
		<collision>
			<origin xyz="0.5038798779540579 -0.757308 -0.3910896986000594" />
			<geometry>
				<mesh filename="/home/blake/kitchen-worlds/assets/models/MiniFridge/11178/textured_objs/new-4-fixed.obj" />/&gt;
			</geometry>
		</collision>
	</link>
	<joint name="joint_handle_1" type="fixed">
		<origin xyz="0 0 0" />
		<axis xyz="0 -1 0" />
		<child link="handle_1" />
		<parent link="link_0" />
	</joint>

	<link name="link_0">
		<visual name="door_frame-13">
			<origin xyz="0.5038798779540579 -0.757308 -0.3910896986000594" />
			<geometry>
				<mesh filename="/home/blake/kitchen-worlds/assets/models/MiniFridge/11178/textured_objs/new-8.obj" />/&gt;
			</geometry>
		</visual>
		<collision>
			<origin xyz="0.5038798779540579 -0.757308 -0.3910896986000594" />
			<geometry>
				<mesh filename="/home/blake/kitchen-worlds/assets/models/MiniFridge/11178/textured_objs/new-8.obj" />/&gt;
			</geometry>
		</collision>
	</link>
	<joint name="joint_0" type="revolute">
		<origin xyz="-0.5038798779540579 0.757308 0.3910896986000594" />
		<axis xyz="0 -1 0" />
		<child link="link_0" />
		<parent link="link_2" />
		<limit lower="0.0" upper="3.141592653589793" effort="10.0" velocity="1.0" />
	</joint>


	<link name="handle_2">
		<visual name="handle-12">
			<origin xyz="-0.4877117157723351 -0.7573079999999996 -0.38152655059947566" />
			<geometry>
				<mesh filename="/home/blake/kitchen-worlds/assets/models/MiniFridge/11178/textured_objs/new-5.obj" />/&gt;
			</geometry>
		</visual>
		<collision>
			<origin xyz="-0.4877117157723351 -0.7573079999999996 -0.38152655059947566" />
			<geometry>
				<mesh filename="/home/blake/kitchen-worlds/assets/models/MiniFridge/11178/textured_objs/new-5.obj" />/&gt;
			</geometry>
		</collision>
	</link>
	<joint name="joint_handle_2" type="fixed">
		<origin xyz="0 0 0" />
		<axis xyz="0 1 0" />
		<child link="handle_2" />
		<parent link="link_1" />
	</joint>


	<link name="link_1">
		<visual name="door_frame-11">
			<origin xyz="-0.4877117157723351 -0.7573079999999996 -0.38152655059947566" />
			<geometry>
				<mesh filename="/home/blake/kitchen-worlds/assets/models/MiniFridge/11178/textured_objs/new-6.obj" />/&gt;
			</geometry>
		</visual>
		<collision>
			<origin xyz="-0.4877117157723351 -0.7573079999999996 -0.38152655059947566" />
			<geometry>
				<mesh filename="/home/blake/kitchen-worlds/assets/models/MiniFridge/11178/textured_objs/new-6.obj" />/&gt;
			</geometry>
		</collision>
	</link>
	<joint name="joint_1" type="revolute">
		<origin xyz="0.4877117157723351 0.7573079999999996 0.38152655059947566" />
		<axis xyz="0 1 0" />
		<child link="link_1" />
		<parent link="link_2" />
		<limit lower="-0.0" upper="3.141592653589793" effort="10.0" velocity="1.0" />
	</joint>
	<link name="link_2">
		<visual name="frame-8">
			<origin xyz="0 0 0" />
			<geometry>
				<mesh filename="/home/blake/kitchen-worlds/assets/models/MiniFridge/11178/textured_objs/new-7-fixed.obj" />/&gt;
			</geometry>
		</visual>
		<visual name="foot-4">
			<origin xyz="0 0 0" />
			<geometry>
				<mesh filename="/home/blake/kitchen-worlds/assets/models/MiniFridge/11178/textured_objs/new-1.obj" />/&gt;
			</geometry>
		</visual>
		<visual name="foot-5">
			<origin xyz="0 0 0" />
			<geometry>
				<mesh filename="/home/blake/kitchen-worlds/assets/models/MiniFridge/11178/textured_objs/new-2.obj" />/&gt;
			</geometry>
		</visual>
		<visual name="foot-6">
			<origin xyz="0 0 0" />
			<geometry>
				<mesh filename="/home/blake/kitchen-worlds/assets/models/MiniFridge/11178/textured_objs/new-0.obj" />/&gt;
			</geometry>
		</visual>
		<visual name="foot-7">
			<origin xyz="0 0 0" />
			<geometry>
				<mesh filename="/home/blake/kitchen-worlds/assets/models/MiniFridge/11178/textured_objs/new-3.obj" />/&gt;
			</geometry>
		</visual>

		
		<collision>
			<origin xyz="0 0 0" />
			<geometry>
				<mesh filename="/home/blake/kitchen-worlds/assets/models/MiniFridge/11178/textured_objs/new-7-left.obj" />/&gt;
			</geometry>
		</collision>
		<collision>
			<origin xyz="0 0 0" />
			<geometry>
				<mesh filename="/home/blake/kitchen-worlds/assets/models/MiniFridge/11178/textured_objs/new-7-right.obj" />/&gt;
			</geometry>
		</collision>
		<collision>
			<origin xyz="0 0 0" />
			<geometry>
				<mesh filename="/home/blake/kitchen-worlds/assets/models/MiniFridge/11178/textured_objs/new-7-top.obj" />/&gt;
			</geometry>
		</collision>
		<collision>
			<origin xyz="0 0 0" />
			<geometry>
				<mesh filename="/home/blake/kitchen-worlds/assets/models/MiniFridge/11178/textured_objs/new-7-bottom.obj" />/&gt;
			</geometry>
		</collision>
		<collision>
			<origin xyz="0 0 0" />
			<geometry>
				<mesh filename="/home/blake/kitchen-worlds/assets/models/MiniFridge/11178/textured_objs/new-7-back.obj" />/&gt;
			</geometry>
		</collision>
		<collision>
			<origin xyz="0 0 0" />
			<geometry>
				<mesh filename="/home/blake/kitchen-worlds/assets/models/MiniFridge/11178/textured_objs/new-1.obj" />/&gt;
			</geometry>
		</collision>
		<collision>
			<origin xyz="0 0 0" />
			<geometry>
				<mesh filename="/home/blake/kitchen-worlds/assets/models/MiniFridge/11178/textured_objs/new-2.obj" />/&gt;
			</geometry>
		</collision>
		<collision>
			<origin xyz="0 0 0" />
			<geometry>
				<mesh filename="/home/blake/kitchen-worlds/assets/models/MiniFridge/11178/textured_objs/new-0.obj" />/&gt;
			</geometry>
		</collision>
		<collision>
			<origin xyz="0 0 0" />
			<geometry>
				<mesh filename="/home/blake/kitchen-worlds/assets/models/MiniFridge/11178/textured_objs/new-3.obj" />/&gt;
			</geometry>
		</collision>
	</link>
	<joint name="joint_2" type="fixed">
		<origin rpy="1.570796326794897 0 -1.570796326794897" xyz="0 0 0" />
		<child link="link_2" />
		<parent link="base" />
	</joint>
</robot>