<?xml version='1.0' encoding='utf-8'?>
<robot name="kitchen_part_right">
	<material name="White">
    <color rgba="0.85 0.85 0.85 1.0" />
  </material>
  <material name="Grey">
    <color rgba="0.4 0.4 0.4 1.0" />
  </material>
  <material name="Red">
    <color rgba="1.0 0 0 1.0" />
  </material>

	<link name="base"><inertial><mass value="0.1" /><inertia ixx="0.01" iyy="0.01" izz="0.01" ixy="0" ixz="0" iyz="0" /></inertial></link>
	<joint name="joint_1" type="fixed">
		<origin rpy="0 0 -3.14159265359" xyz="-0.32 0 0" />
		<child link="dagger" />
		<parent link="base" />
	</joint>

	<link name="dagger">
    <inertial>
      <origin rpy="0 0 0" xyz="0 0 0" />
      <mass value="10.0" />
      <inertia ixx="0.0001" ixy="0" ixz="0" iyy="0.0001" iyz="0" izz="0.0001" />
    </inertial>
    <visual name="dagger_visual">
      <origin rpy="0  0  0" xyz="0  0  0" />
      <geometry>
        <mesh filename="CabinetTop/00002/textured_objs/sektion_top_two_glass.obj" /> scale="1.0 1.0 1.0"/&gt;
      </geometry>
      <material name="White" />
    </visual>
    <collision>
      <geometry>
        <mesh filename="CabinetTop/00002/textured_objs/sektion_top_two_glass.obj" /> scale="1.0 1.0 1.0"/&gt;
      </geometry>
    </collision>
  </link>
  
  <joint name="dagger_door_left_joint_fixed" type="fixed">
    <parent link="dagger" />
    <child link="dagger_door_left_anchor_link" />
    <origin rpy="0 0 3.14159265359" xyz="0 0 0" />
  </joint>
  <link name="dagger_door_left_anchor_link"><inertial><mass value="0.1" /><inertia ixx="0.01" iyy="0.01" izz="0.01" ixy="0" ixz="0" iyz="0" /></inertial></link>
  <joint name="dagger_door_left_joint" type="revolute">
    <parent link="dagger_door_left_anchor_link" />
    <child link="dagger_door_left_link_tmp" />
    <origin rpy="0 0 0" xyz="0 0 0" />
    <axis xyz="0 0 1" />
    <limit effort="1000.0" lower="-1.57" upper="0" velocity="0.1" />
  </joint>
  <link name="dagger_door_left_link_tmp"><inertial><mass value="0.1" /><inertia ixx="0.01" iyy="0.01" izz="0.01" ixy="0" ixz="0" iyz="0" /></inertial></link>
  <joint name="dagger_door_left_joint_fixed_2" type="fixed">
    <parent link="dagger_door_left_link_tmp" />
    <child link="dagger_door_left_link" />
    <origin rpy="0 0 0" xyz="-0.01 -0.19 0.38" />
  </joint>
  <link name="dagger_door_left_link">
    <inertial>
      <origin rpy="0 0 0" xyz="0 0 0" />
      <mass value="1.0" />
      <inertia ixx="0.0001" ixy="0" ixz="0" iyy="0.0001" iyz="0" izz="0.0001" />
    </inertial>
    <visual name="dagger_door_left_visual">
      <origin rpy="0 0 0" xyz="0 0 0" />
      <geometry>
        <mesh filename="CabinetTop/00002/textured_objs/front_vertical_left.obj" /> scale="1.0 1.0 1.0"/&gt;
      </geometry>
      <material name="Grey" />
    </visual>
    <collision>
      <geometry>
        <mesh filename="CabinetTop/00002/textured_objs/front_vertical_left.obj" /> scale="1.0 1.0 1.0"/&gt;
      </geometry>
    </collision>
  </link>
  <joint name="dagger_door_left_handle_transform" type="fixed">
    <parent link="dagger_door_left_link_tmp" />
    <child link="dagger_door_left_handle" />
    <origin rpy="0 0 0" xyz="-0.05905 -0.33 0.38" />
    <axis xyz="0 0 1" />
  </joint>
  <link name="dagger_door_left_handle">
    <inertial>
      <origin rpy="0 0 0" xyz="0 0 0" />
      <mass value="1.0" />
      <inertia ixx="0.0001" ixy="0" ixz="0" iyy="0.0001" iyz="0" izz="0.0001" />
    </inertial>
    <visual name="dagger_door_left_handle_visual">
      <origin rpy="0  0  0" xyz="0  0  0" />
      <geometry>
        <mesh filename="CabinetTop/00002/textured_objs/handle_new.obj" /> scale="1.0 1.0 1.0"/&gt;
      </geometry>
      <material name="White" />
    </visual>
    <collision>
      <geometry>
        <mesh filename="CabinetTop/00002/textured_objs/handle_new.obj" /> scale="1.0 1.0 1.0"/&gt;
      </geometry>
    </collision>
  </link>
  
  <joint name="dagger_door_right_joint_fixed" type="fixed">
    <parent link="dagger" />
    <child link="dagger_door_right_anchor_link" />
    <origin rpy="0 0 3.14159265359" xyz="0 0.762 0" />
  </joint>
  <link name="dagger_door_right_anchor_link"><inertial><mass value="0.1" /><inertia ixx="0.01" iyy="0.01" izz="0.01" ixy="0" ixz="0" iyz="0" /></inertial></link>
  <joint name="dagger_door_right_joint" type="revolute">
    <parent link="dagger_door_right_anchor_link" />
    <child link="dagger_door_right_link_tmp" />
    <origin rpy="0 0 0" xyz="0 0 0" />
    <axis xyz="0 0 1" />
    <limit effort="1000.0" lower="0" upper="1.57" velocity="0.1" />
  </joint>
  <link name="dagger_door_right_link_tmp"><inertial><mass value="0.1" /><inertia ixx="0.01" iyy="0.01" izz="0.01" ixy="0" ixz="0" iyz="0" /></inertial></link>
  <joint name="dagger_door_right_joint_fixed_2" type="fixed">
    <parent link="dagger_door_right_link_tmp" />
    <child link="dagger_door_right_link" />
    <origin rpy="0 0 0" xyz="-0.01 0.19 0.38" />
  </joint>
  <link name="dagger_door_right_link">
    <inertial>
      <origin rpy="0 0 0" xyz="0 0 0" />
      <mass value="1.0" />
      <inertia ixx="0.0001" ixy="0" ixz="0" iyy="0.0001" iyz="0" izz="0.0001" />
    </inertial>
    <visual name="dagger_door_right_visual">
      <origin rpy="0 0 0" xyz="0 0 0" />
      <geometry>
        <mesh filename="CabinetTop/00002/textured_objs/front_vertical_right.obj" /> scale="1.0 1.0 1.0"/&gt;
      </geometry>
      <material name="Grey" />
    </visual>
    <collision>
      <geometry>
        <mesh filename="CabinetTop/00002/textured_objs/front_vertical_right.obj" /> scale="1.0 1.0 1.0"/&gt;
      </geometry>
    </collision>
  </link>
  <joint name="dagger_door_right_handle_transform" type="fixed">
    <parent link="dagger_door_right_link_tmp" />
    <child link="dagger_door_right_handle" />
    <origin rpy="0 0 0" xyz="-0.05905 0.33 0.38" />
    <axis xyz="0 0 1" />
  </joint>
  <link name="dagger_door_right_handle">
    <inertial>
      <origin rpy="0 0 0" xyz="0 0 0" />
      <mass value="1.0" />
      <inertia ixx="0.0001" ixy="0" ixz="0" iyy="0.0001" iyz="0" izz="0.0001" />
    </inertial>
    <visual name="dagger_door_right_handle_visual">
      <origin rpy="0  0  0" xyz="0  0  0" />
      <geometry>
        <mesh filename="CabinetTop/00002/textured_objs/handle_new.obj" /> scale="1.0 1.0 1.0"/&gt;
      </geometry>
      <material name="White" />
    </visual>
    <collision>
      <geometry>
        <mesh filename="CabinetTop/00002/textured_objs/handle_new.obj" /> scale="1.0 1.0 1.0"/&gt;
      </geometry>
    </collision>
  </link>



</robot>