<?xml version='1.0' encoding='utf-8'?>
<robot name="partnet_19dd35ef180808c38f1735145fdf5c5c">
	<link name="base" />
	<link name="link_0">
		<visual name="cabinet_door_surface-5">
			<origin xyz="0.3819207002901245 0.385549992322922 -0.49295108382251" />
			<geometry>
				<mesh filename="/home/blake/kitchen-worlds/assets/models/CabinetLower/45213/textured_objs/original-40.obj" />/&gt;
			</geometry>
		</visual>
		<visual name="cabinet_door_surface-5">
			<origin xyz="0.3819207002901245 0.385549992322922 -0.49295108382251" />
			<geometry>
				<mesh filename="/home/blake/kitchen-worlds/assets/models/CabinetLower/45213/textured_objs/original-44.obj" />/&gt;
			</geometry>
		</visual>
		<visual name="cabinet_door_surface-5">
			<origin xyz="0.3819207002901245 0.385549992322922 -0.49295108382251" />
			<geometry>
				<mesh filename="/home/blake/kitchen-worlds/assets/models/CabinetLower/45213/textured_objs/original-6.obj" />/&gt;
			</geometry>
		</visual>
		<visual name="cabinet_door_surface-5">
			<origin xyz="0.3819207002901245 0.385549992322922 -0.49295108382251" />
			<geometry>
				<mesh filename="/home/blake/kitchen-worlds/assets/models/CabinetLower/45213/textured_objs/original-45.obj" />/&gt;
			</geometry>
		</visual>
		<visual name="cabinet_door_surface-5">
			<origin xyz="0.3819207002901245 0.385549992322922 -0.49295108382251" />
			<geometry>
				<mesh filename="/home/blake/kitchen-worlds/assets/models/CabinetLower/45213/textured_objs/original-36.obj" />/&gt;
			</geometry>
		</visual>
		<visual name="cabinet_door_surface-5">
			<origin xyz="0.3819207002901245 0.385549992322922 -0.49295108382251" />
			<geometry>
				<mesh filename="/home/blake/kitchen-worlds/assets/models/CabinetLower/45213/textured_objs/original-7.obj" />/&gt;
			</geometry>
		</visual>
		<visual name="cabinet_door_surface-5">
			<origin xyz="0.3819207002901245 0.385549992322922 -0.49295108382251" />
			<geometry>
				<mesh filename="/home/blake/kitchen-worlds/assets/models/CabinetLower/45213/textured_objs/original-3.obj" />/&gt;
			</geometry>
		</visual>
		<visual name="cabinet_door_surface-5">
			<origin xyz="0.3819207002901245 0.385549992322922 -0.49295108382251" />
			<geometry>
				<mesh filename="/home/blake/kitchen-worlds/assets/models/CabinetLower/45213/textured_objs/original-37.obj" />/&gt;
			</geometry>
		</visual>
		<visual name="cabinet_door_surface-5">
			<origin xyz="0.3819207002901245 0.385549992322922 -0.49295108382251" />
			<geometry>
				<mesh filename="/home/blake/kitchen-worlds/assets/models/CabinetLower/45213/textured_objs/original-46.obj" />/&gt;
			</geometry>
		</visual>
		<visual name="cabinet_door_surface-5">
			<origin xyz="0.3819207002901245 0.385549992322922 -0.49295108382251" />
			<geometry>
				<mesh filename="/home/blake/kitchen-worlds/assets/models/CabinetLower/45213/textured_objs/original-41.obj" />/&gt;
			</geometry>
		</visual>
		<visual name="cabinet_door_surface-5">
			<origin xyz="0.3819207002901245 0.385549992322922 -0.49295108382251" />
			<geometry>
				<mesh filename="/home/blake/kitchen-worlds/assets/models/CabinetLower/45213/textured_objs/original-39.obj" />/&gt;
			</geometry>
		</visual>
		<visual name="cabinet_door_surface-5">
			<origin xyz="0.3819207002901245 0.385549992322922 -0.49295108382251" />
			<geometry>
				<mesh filename="/home/blake/kitchen-worlds/assets/models/CabinetLower/45213/textured_objs/original-38.obj" />/&gt;
			</geometry>
		</visual>
		<visual name="cabinet_door_surface-5">
			<origin xyz="0.3819207002901245 0.385549992322922 -0.49295108382251" />
			<geometry>
				<mesh filename="/home/blake/kitchen-worlds/assets/models/CabinetLower/45213/textured_objs/original-8.obj" />/&gt;
			</geometry>
		</visual>
		<visual name="cabinet_door_surface-5">
			<origin xyz="0.3819207002901245 0.385549992322922 -0.49295108382251" />
			<geometry>
				<mesh filename="/home/blake/kitchen-worlds/assets/models/CabinetLower/45213/textured_objs/original-43.obj" />/&gt;
			</geometry>
		</visual>
		<visual name="handle-6">
			<origin xyz="0.3819207002901245 0.385549992322922 -0.49295108382251" />
			<geometry>
				<mesh filename="/home/blake/kitchen-worlds/assets/models/CabinetLower/45213/textured_objs/original-47.obj" />/&gt;
			</geometry>
		</visual>
		<collision>
			<origin xyz="0.3819207002901245 0.385549992322922 -0.49295108382251" />
			<geometry>
				<mesh filename="/home/blake/kitchen-worlds/assets/models/CabinetLower/45213/textured_objs/original-40.obj" />/&gt;
			</geometry>
		</collision>
		<collision>
			<origin xyz="0.3819207002901245 0.385549992322922 -0.49295108382251" />
			<geometry>
				<mesh filename="/home/blake/kitchen-worlds/assets/models/CabinetLower/45213/textured_objs/original-44.obj" />/&gt;
			</geometry>
		</collision>
		<collision>
			<origin xyz="0.3819207002901245 0.385549992322922 -0.49295108382251" />
			<geometry>
				<mesh filename="/home/blake/kitchen-worlds/assets/models/CabinetLower/45213/textured_objs/original-6.obj" />/&gt;
			</geometry>
		</collision>
		<collision>
			<origin xyz="0.3819207002901245 0.385549992322922 -0.49295108382251" />
			<geometry>
				<mesh filename="/home/blake/kitchen-worlds/assets/models/CabinetLower/45213/textured_objs/original-45.obj" />/&gt;
			</geometry>
		</collision>
		<collision>
			<origin xyz="0.3819207002901245 0.385549992322922 -0.49295108382251" />
			<geometry>
				<mesh filename="/home/blake/kitchen-worlds/assets/models/CabinetLower/45213/textured_objs/original-36.obj" />/&gt;
			</geometry>
		</collision>
		<collision>
			<origin xyz="0.3819207002901245 0.385549992322922 -0.49295108382251" />
			<geometry>
				<mesh filename="/home/blake/kitchen-worlds/assets/models/CabinetLower/45213/textured_objs/original-7.obj" />/&gt;
			</geometry>
		</collision>
		<collision>
			<origin xyz="0.3819207002901245 0.385549992322922 -0.49295108382251" />
			<geometry>
				<mesh filename="/home/blake/kitchen-worlds/assets/models/CabinetLower/45213/textured_objs/original-3.obj" />/&gt;
			</geometry>
		</collision>
		<collision>
			<origin xyz="0.3819207002901245 0.385549992322922 -0.49295108382251" />
			<geometry>
				<mesh filename="/home/blake/kitchen-worlds/assets/models/CabinetLower/45213/textured_objs/original-37.obj" />/&gt;
			</geometry>
		</collision>
		<collision>
			<origin xyz="0.3819207002901245 0.385549992322922 -0.49295108382251" />
			<geometry>
				<mesh filename="/home/blake/kitchen-worlds/assets/models/CabinetLower/45213/textured_objs/original-46.obj" />/&gt;
			</geometry>
		</collision>
		<collision>
			<origin xyz="0.3819207002901245 0.385549992322922 -0.49295108382251" />
			<geometry>
				<mesh filename="/home/blake/kitchen-worlds/assets/models/CabinetLower/45213/textured_objs/original-41.obj" />/&gt;
			</geometry>
		</collision>
		<collision>
			<origin xyz="0.3819207002901245 0.385549992322922 -0.49295108382251" />
			<geometry>
				<mesh filename="/home/blake/kitchen-worlds/assets/models/CabinetLower/45213/textured_objs/original-39.obj" />/&gt;
			</geometry>
		</collision>
		<collision>
			<origin xyz="0.3819207002901245 0.385549992322922 -0.49295108382251" />
			<geometry>
				<mesh filename="/home/blake/kitchen-worlds/assets/models/CabinetLower/45213/textured_objs/original-38.obj" />/&gt;
			</geometry>
		</collision>
		<collision>
			<origin xyz="0.3819207002901245 0.385549992322922 -0.49295108382251" />
			<geometry>
				<mesh filename="/home/blake/kitchen-worlds/assets/models/CabinetLower/45213/textured_objs/original-8.obj" />/&gt;
			</geometry>
		</collision>
		<collision>
			<origin xyz="0.3819207002901245 0.385549992322922 -0.49295108382251" />
			<geometry>
				<mesh filename="/home/blake/kitchen-worlds/assets/models/CabinetLower/45213/textured_objs/original-43.obj" />/&gt;
			</geometry>
		</collision>
		<collision>
			<origin xyz="0.3819207002901245 0.385549992322922 -0.49295108382251" />
			<geometry>
				<mesh filename="/home/blake/kitchen-worlds/assets/models/CabinetLower/45213/textured_objs/original-47.obj" />/&gt;
			</geometry>
		</collision>
	</link>
	<joint name="joint_0" type="revolute">
		<origin xyz="-0.3819207002901245 -0.385549992322922 0.49295108382251" />
		<axis xyz="0 -1 0" />
		<child link="link_0" />
		<parent link="link_3" />
		<limit lower="0.0" upper="2.261946710584651" effort="10.0" velocity="1.0" />
	</joint>
	<link name="link_1">
		<visual name="drawer_front-20">
			<origin xyz="-0.05147622330807422 -0.17906995331356582 -0.5304319858551028" />
			<geometry>
				<mesh filename="/home/blake/kitchen-worlds/assets/models/CabinetLower/45213/textured_objs/original-23.obj" />/&gt;
			</geometry>
		</visual>
		<visual name="drawer_side-21">
			<origin xyz="-0.05147622330807422 -0.17906995331356582 -0.5304319858551028" />
			<geometry>
				<mesh filename="/home/blake/kitchen-worlds/assets/models/CabinetLower/45213/textured_objs/original-22.obj" />/&gt;
			</geometry>
		</visual>
		<visual name="drawer_side-22">
			<origin xyz="-0.05147622330807422 -0.17906995331356582 -0.5304319858551028" />
			<geometry>
				<mesh filename="/home/blake/kitchen-worlds/assets/models/CabinetLower/45213/textured_objs/original-25.obj" />/&gt;
			</geometry>
		</visual>
		<visual name="drawer_back-23">
			<origin xyz="-0.05147622330807422 -0.17906995331356582 -0.5304319858551028" />
			<geometry>
				<mesh filename="/home/blake/kitchen-worlds/assets/models/CabinetLower/45213/textured_objs/original-26.obj" />/&gt;
			</geometry>
		</visual>
		<visual name="drawer_bottom-24">
			<origin xyz="-0.05147622330807422 -0.17906995331356582 -0.5304319858551028" />
			<geometry>
				<mesh filename="/home/blake/kitchen-worlds/assets/models/CabinetLower/45213/textured_objs/original-24.obj" />/&gt;
			</geometry>
		</visual>
		<visual name="other_leaf-26">
			<origin xyz="-0.05147622330807422 -0.17906995331356582 -0.5304319858551028" />
			<geometry>
				<mesh filename="/home/blake/kitchen-worlds/assets/models/CabinetLower/45213/textured_objs/original-27.obj" />/&gt;
			</geometry>
		</visual>
		<collision>
			<origin xyz="-0.05147622330807422 -0.17906995331356582 -0.5304319858551028" />
			<geometry>
				<mesh filename="/home/blake/kitchen-worlds/assets/models/CabinetLower/45213/textured_objs/original-23.obj" />/&gt;
			</geometry>
		</collision>
		<collision>
			<origin xyz="-0.05147622330807422 -0.17906995331356582 -0.5304319858551028" />
			<geometry>
				<mesh filename="/home/blake/kitchen-worlds/assets/models/CabinetLower/45213/textured_objs/original-22.obj" />/&gt;
			</geometry>
		</collision>
		<collision>
			<origin xyz="-0.05147622330807422 -0.17906995331356582 -0.5304319858551028" />
			<geometry>
				<mesh filename="/home/blake/kitchen-worlds/assets/models/CabinetLower/45213/textured_objs/original-25.obj" />/&gt;
			</geometry>
		</collision>
		<collision>
			<origin xyz="-0.05147622330807422 -0.17906995331356582 -0.5304319858551028" />
			<geometry>
				<mesh filename="/home/blake/kitchen-worlds/assets/models/CabinetLower/45213/textured_objs/original-26.obj" />/&gt;
			</geometry>
		</collision>
		<collision>
			<origin xyz="-0.05147622330807422 -0.17906995331356582 -0.5304319858551028" />
			<geometry>
				<mesh filename="/home/blake/kitchen-worlds/assets/models/CabinetLower/45213/textured_objs/original-24.obj" />/&gt;
			</geometry>
		</collision>
		<collision>
			<origin xyz="-0.05147622330807422 -0.17906995331356582 -0.5304319858551028" />
			<geometry>
				<mesh filename="/home/blake/kitchen-worlds/assets/models/CabinetLower/45213/textured_objs/original-27.obj" />/&gt;
			</geometry>
		</collision>
	</link>
	<joint name="joint_1" type="prismatic">
		<origin xyz="0.05147622330807422 0.17906995331356582 0.5304319858551028" />
		<axis xyz="0 0 0.1" />
		<child link="link_1" />
		<parent link="link_3" />
		<limit lower="0" upper="0.8799999999999999" effort="10.0" velocity="1.0" />
	</joint>
	<link name="link_2">
		<visual name="drawer_front-12">
			<origin xyz="0.07146379942078879 0.27498618663455315 -0.5495139956474304" />
			<geometry>
				<mesh filename="/home/blake/kitchen-worlds/assets/models/CabinetLower/45213/textured_objs/original-30.obj" />/&gt;
			</geometry>
		</visual>
		<visual name="drawer_side-13">
			<origin xyz="0.07146379942078879 0.27498618663455315 -0.5495139956474304" />
			<geometry>
				<mesh filename="/home/blake/kitchen-worlds/assets/models/CabinetLower/45213/textured_objs/original-29.obj" />/&gt;
			</geometry>
		</visual>
		<visual name="drawer_side-14">
			<origin xyz="0.07146379942078879 0.27498618663455315 -0.5495139956474304" />
			<geometry>
				<mesh filename="/home/blake/kitchen-worlds/assets/models/CabinetLower/45213/textured_objs/original-32.obj" />/&gt;
			</geometry>
		</visual>
		<visual name="drawer_back-15">
			<origin xyz="0.07146379942078879 0.27498618663455315 -0.5495139956474304" />
			<geometry>
				<mesh filename="/home/blake/kitchen-worlds/assets/models/CabinetLower/45213/textured_objs/original-33.obj" />/&gt;
			</geometry>
		</visual>
		<visual name="drawer_bottom-16">
			<origin xyz="0.07146379942078879 0.27498618663455315 -0.5495139956474304" />
			<geometry>
				<mesh filename="/home/blake/kitchen-worlds/assets/models/CabinetLower/45213/textured_objs/original-31.obj" />/&gt;
			</geometry>
		</visual>
		<visual name="other_leaf-18">
			<origin xyz="0.07146379942078879 0.27498618663455315 -0.5495139956474304" />
			<geometry>
				<mesh filename="/home/blake/kitchen-worlds/assets/models/CabinetLower/45213/textured_objs/original-34.obj" />/&gt;
			</geometry>
		</visual>
		<collision>
			<origin xyz="0.07146379942078879 0.27498618663455315 -0.5495139956474304" />
			<geometry>
				<mesh filename="/home/blake/kitchen-worlds/assets/models/CabinetLower/45213/textured_objs/original-30.obj" />/&gt;
			</geometry>
		</collision>
		<collision>
			<origin xyz="0.07146379942078879 0.27498618663455315 -0.5495139956474304" />
			<geometry>
				<mesh filename="/home/blake/kitchen-worlds/assets/models/CabinetLower/45213/textured_objs/original-29.obj" />/&gt;
			</geometry>
		</collision>
		<collision>
			<origin xyz="0.07146379942078879 0.27498618663455315 -0.5495139956474304" />
			<geometry>
				<mesh filename="/home/blake/kitchen-worlds/assets/models/CabinetLower/45213/textured_objs/original-32.obj" />/&gt;
			</geometry>
		</collision>
		<collision>
			<origin xyz="0.07146379942078879 0.27498618663455315 -0.5495139956474304" />
			<geometry>
				<mesh filename="/home/blake/kitchen-worlds/assets/models/CabinetLower/45213/textured_objs/original-33.obj" />/&gt;
			</geometry>
		</collision>
		<collision>
			<origin xyz="0.07146379942078879 0.27498618663455315 -0.5495139956474304" />
			<geometry>
				<mesh filename="/home/blake/kitchen-worlds/assets/models/CabinetLower/45213/textured_objs/original-31.obj" />/&gt;
			</geometry>
		</collision>
		<collision>
			<origin xyz="0.07146379942078879 0.27498618663455315 -0.5495139956474304" />
			<geometry>
				<mesh filename="/home/blake/kitchen-worlds/assets/models/CabinetLower/45213/textured_objs/original-34.obj" />/&gt;
			</geometry>
		</collision>
	</link>
	<joint name="joint_2" type="prismatic">
		<origin xyz="-0.07146379942078879 -0.27498618663455315 0.5495139956474304" />
		<axis xyz="0 0 1" />
		<child link="link_2" />
		<parent link="link_3" />
		<limit lower="0" upper="0.8799999999999999" effort="10.0" velocity="1.0" />
	</joint>
	<link name="link_3">
		<visual name="vertical_side_panel-32">
			<origin xyz="0 0 0" />
			<geometry>
				<mesh filename="/home/blake/kitchen-worlds/assets/models/CabinetLower/45213/textured_objs/original-11.obj" />/&gt;
			</geometry>
		</visual>
		<visual name="vertical_side_panel-32">
			<origin xyz="0 0 0" />
			<geometry>
				<mesh filename="/home/blake/kitchen-worlds/assets/models/CabinetLower/45213/textured_objs/original-10.obj" />/&gt;
			</geometry>
		</visual>
		<visual name="vertical_side_panel-33">
			<origin xyz="0 0 0" />
			<geometry>
				<mesh filename="/home/blake/kitchen-worlds/assets/models/CabinetLower/45213/textured_objs/original-15.obj" />/&gt;
			</geometry>
		</visual>
		<visual name="vertical_side_panel-33">
			<origin xyz="0 0 0" />
			<geometry>
				<mesh filename="/home/blake/kitchen-worlds/assets/models/CabinetLower/45213/textured_objs/original-14.obj" />/&gt;
			</geometry>
		</visual>
		<visual name="back_panel-34">
			<origin xyz="0 0 0" />
			<geometry>
				<mesh filename="/home/blake/kitchen-worlds/assets/models/CabinetLower/45213/textured_objs/original-5.obj" />/&gt;
			</geometry>
		</visual>
		<visual name="bottom_panel-35">
			<origin xyz="0 0 0" />
			<geometry>
				<mesh filename="/home/blake/kitchen-worlds/assets/models/CabinetLower/45213/textured_objs/original-2.obj" />/&gt;
			</geometry>
		</visual>
		<visual name="frame_horizontal_bar-36">
			<origin xyz="0 0 0" />
			<geometry>
				<mesh filename="/home/blake/kitchen-worlds/assets/models/CabinetLower/45213/textured_objs/original-20.obj" />/&gt;
			</geometry>
		</visual>
		<visual name="frame_horizontal_bar-37">
			<origin xyz="0 0 0" />
			<geometry>
				<mesh filename="/home/blake/kitchen-worlds/assets/models/CabinetLower/45213/textured_objs/original-19.obj" />/&gt;
			</geometry>
		</visual>
		<visual name="other_leaf-39">
			<origin xyz="0 0 0" />
			<geometry>
				<mesh filename="/home/blake/kitchen-worlds/assets/models/CabinetLower/45213/textured_objs/original-48.obj" />/&gt;
			</geometry>
		</visual>
		<visual name="frame_horizontal_bar-40">
			<origin xyz="0 0 0" />
			<geometry>
				<mesh filename="/home/blake/kitchen-worlds/assets/models/CabinetLower/45213/textured_objs/original-4.obj" />/&gt;
			</geometry>
		</visual>
		<visual name="base_side_panel-28">
			<origin xyz="0 0 0" />
			<geometry>
				<mesh filename="/home/blake/kitchen-worlds/assets/models/CabinetLower/45213/textured_objs/original-16.obj" />/&gt;
			</geometry>
		</visual>
		<visual name="base_side_panel-29">
			<origin xyz="0 0 0" />
			<geometry>
				<mesh filename="/home/blake/kitchen-worlds/assets/models/CabinetLower/45213/textured_objs/original-17.obj" />/&gt;
			</geometry>
		</visual>
		<visual name="base_side_panel-30">
			<origin xyz="0 0 0" />
			<geometry>
				<mesh filename="/home/blake/kitchen-worlds/assets/models/CabinetLower/45213/textured_objs/original-12.obj" />/&gt;
			</geometry>
		</visual>
		<visual name="base_side_panel-31">
			<origin xyz="0 0 0" />
			<geometry>
				<mesh filename="/home/blake/kitchen-worlds/assets/models/CabinetLower/45213/textured_objs/original-18.obj" />/&gt;
			</geometry>
		</visual>
		<collision>
			<origin xyz="0 0 0" />
			<geometry>
				<mesh filename="/home/blake/kitchen-worlds/assets/models/CabinetLower/45213/textured_objs/original-11.obj" />/&gt;
			</geometry>
		</collision>
		<collision>
			<origin xyz="0 0 0" />
			<geometry>
				<mesh filename="/home/blake/kitchen-worlds/assets/models/CabinetLower/45213/textured_objs/original-10.obj" />/&gt;
			</geometry>
		</collision>
		<collision>
			<origin xyz="0 0 0" />
			<geometry>
				<mesh filename="/home/blake/kitchen-worlds/assets/models/CabinetLower/45213/textured_objs/original-15.obj" />/&gt;
			</geometry>
		</collision>
		<collision>
			<origin xyz="0 0 0" />
			<geometry>
				<mesh filename="/home/blake/kitchen-worlds/assets/models/CabinetLower/45213/textured_objs/original-14.obj" />/&gt;
			</geometry>
		</collision>
		<collision>
			<origin xyz="0 0 0" />
			<geometry>
				<mesh filename="/home/blake/kitchen-worlds/assets/models/CabinetLower/45213/textured_objs/original-5.obj" />/&gt;
			</geometry>
		</collision>
		<collision>
			<origin xyz="0 0 0" />
			<geometry>
				<mesh filename="/home/blake/kitchen-worlds/assets/models/CabinetLower/45213/textured_objs/original-2.obj" />/&gt;
			</geometry>
		</collision>
		<collision>
			<origin xyz="0 0 0" />
			<geometry>
				<mesh filename="/home/blake/kitchen-worlds/assets/models/CabinetLower/45213/textured_objs/original-20.obj" />/&gt;
			</geometry>
		</collision>
		<collision>
			<origin xyz="0 0 0" />
			<geometry>
				<mesh filename="/home/blake/kitchen-worlds/assets/models/CabinetLower/45213/textured_objs/original-19.obj" />/&gt;
			</geometry>
		</collision>
		<collision>
			<origin xyz="0 0 0" />
			<geometry>
				<mesh filename="/home/blake/kitchen-worlds/assets/models/CabinetLower/45213/textured_objs/original-48.obj" />/&gt;
			</geometry>
		</collision>
		<collision>
			<origin xyz="0 0 0" />
			<geometry>
				<mesh filename="/home/blake/kitchen-worlds/assets/models/CabinetLower/45213/textured_objs/original-4.obj" />/&gt;
			</geometry>
		</collision>
		<collision>
			<origin xyz="0 0 0" />
			<geometry>
				<mesh filename="/home/blake/kitchen-worlds/assets/models/CabinetLower/45213/textured_objs/original-16.obj" />/&gt;
			</geometry>
		</collision>
		<collision>
			<origin xyz="0 0 0" />
			<geometry>
				<mesh filename="/home/blake/kitchen-worlds/assets/models/CabinetLower/45213/textured_objs/original-17.obj" />/&gt;
			</geometry>
		</collision>
		<collision>
			<origin xyz="0 0 0" />
			<geometry>
				<mesh filename="/home/blake/kitchen-worlds/assets/models/CabinetLower/45213/textured_objs/original-12.obj" />/&gt;
			</geometry>
		</collision>
		<collision>
			<origin xyz="0 0 0" />
			<geometry>
				<mesh filename="/home/blake/kitchen-worlds/assets/models/CabinetLower/45213/textured_objs/original-18.obj" />/&gt;
			</geometry>
		</collision>
	</link>
	<joint name="joint_3" type="fixed">
		<origin rpy="1.570796326794897 0 -1.570796326794897" xyz="0 0 0" />
		<child link="link_3" />
		<parent link="base" />
	</joint>
</robot>