<?xml version='1.0' encoding='utf-8'?>
<robot name="partnet_1ec5e12f2b5684a24da5feafe6f1c8fc">
	<link name="base" />
	<link name="link_0">
		<visual name="cabinet_door_surface-9">
			<origin xyz="-0.7130134511490828 -0.5398004848060416 -0.47620010651538197" />
			<geometry>
				<mesh filename="/home/blake/kitchen-worlds/assets/models/SinkBase/45332/textured_objs/original-68.obj" />/&gt;
			</geometry>
		</visual>
		<visual name="cabinet_door_surface-9">
			<origin xyz="-0.7130134511490828 -0.5398004848060416 -0.47620010651538197" />
			<geometry>
				<mesh filename="/home/blake/kitchen-worlds/assets/models/SinkBase/45332/textured_objs/original-58.obj" />/&gt;
			</geometry>
		</visual>
		<visual name="cabinet_door_surface-9">
			<origin xyz="-0.7130134511490828 -0.5398004848060416 -0.47620010651538197" />
			<geometry>
				<mesh filename="/home/blake/kitchen-worlds/assets/models/SinkBase/45332/textured_objs/original-62.obj" />/&gt;
			</geometry>
		</visual>
		<visual name="cabinet_door_surface-9">
			<origin xyz="-0.7130134511490828 -0.5398004848060416 -0.47620010651538197" />
			<geometry>
				<mesh filename="/home/blake/kitchen-worlds/assets/models/SinkBase/45332/textured_objs/original-59.obj" />/&gt;
			</geometry>
		</visual>
		<visual name="cabinet_door_surface-9">
			<origin xyz="-0.7130134511490828 -0.5398004848060416 -0.47620010651538197" />
			<geometry>
				<mesh filename="/home/blake/kitchen-worlds/assets/models/SinkBase/45332/textured_objs/original-65.obj" />/&gt;
			</geometry>
		</visual>
		<visual name="cabinet_door_surface-9">
			<origin xyz="-0.7130134511490828 -0.5398004848060416 -0.47620010651538197" />
			<geometry>
				<mesh filename="/home/blake/kitchen-worlds/assets/models/SinkBase/45332/textured_objs/original-61.obj" />/&gt;
			</geometry>
		</visual>
		<visual name="cabinet_door_surface-9">
			<origin xyz="-0.7130134511490828 -0.5398004848060416 -0.47620010651538197" />
			<geometry>
				<mesh filename="/home/blake/kitchen-worlds/assets/models/SinkBase/45332/textured_objs/original-63.obj" />/&gt;
			</geometry>
		</visual>
		<visual name="cabinet_door_surface-9">
			<origin xyz="-0.7130134511490828 -0.5398004848060416 -0.47620010651538197" />
			<geometry>
				<mesh filename="/home/blake/kitchen-worlds/assets/models/SinkBase/45332/textured_objs/original-60.obj" />/&gt;
			</geometry>
		</visual>
		<visual name="cabinet_door_surface-9">
			<origin xyz="-0.7130134511490828 -0.5398004848060416 -0.47620010651538197" />
			<geometry>
				<mesh filename="/home/blake/kitchen-worlds/assets/models/SinkBase/45332/textured_objs/original-64.obj" />/&gt;
			</geometry>
		</visual>
		<visual name="cabinet_door_surface-9">
			<origin xyz="-0.7130134511490828 -0.5398004848060416 -0.47620010651538197" />
			<geometry>
				<mesh filename="/home/blake/kitchen-worlds/assets/models/SinkBase/45332/textured_objs/original-67.obj" />/&gt;
			</geometry>
		</visual>
		<visual name="handle-10">
			<origin xyz="-0.7130134511490828 -0.5398004848060416 -0.47620010651538197" />
			<geometry>
				<mesh filename="/home/blake/kitchen-worlds/assets/models/SinkBase/45332/textured_objs/original-71.obj" />/&gt;
			</geometry>
		</visual>
		<visual name="handle-10">
			<origin xyz="-0.7130134511490828 -0.5398004848060416 -0.47620010651538197" />
			<geometry>
				<mesh filename="/home/blake/kitchen-worlds/assets/models/SinkBase/45332/textured_objs/original-72.obj" />/&gt;
			</geometry>
		</visual>
		<visual name="handle-10">
			<origin xyz="-0.7130134511490828 -0.5398004848060416 -0.47620010651538197" />
			<geometry>
				<mesh filename="/home/blake/kitchen-worlds/assets/models/SinkBase/45332/textured_objs/original-76.obj" />/&gt;
			</geometry>
		</visual>
		<visual name="handle-10">
			<origin xyz="-0.7130134511490828 -0.5398004848060416 -0.47620010651538197" />
			<geometry>
				<mesh filename="/home/blake/kitchen-worlds/assets/models/SinkBase/45332/textured_objs/original-75.obj" />/&gt;
			</geometry>
		</visual>
		<visual name="handle-10">
			<origin xyz="-0.7130134511490828 -0.5398004848060416 -0.47620010651538197" />
			<geometry>
				<mesh filename="/home/blake/kitchen-worlds/assets/models/SinkBase/45332/textured_objs/original-74.obj" />/&gt;
			</geometry>
		</visual>
		<collision>
			<origin xyz="-0.7130134511490828 -0.5398004848060416 -0.47620010651538197" />
			<geometry>
				<mesh filename="/home/blake/kitchen-worlds/assets/models/SinkBase/45332/textured_objs/original-68.obj" />/&gt;
			</geometry>
		</collision>
		<collision>
			<origin xyz="-0.7130134511490828 -0.5398004848060416 -0.47620010651538197" />
			<geometry>
				<mesh filename="/home/blake/kitchen-worlds/assets/models/SinkBase/45332/textured_objs/original-58.obj" />/&gt;
			</geometry>
		</collision>
		<collision>
			<origin xyz="-0.7130134511490828 -0.5398004848060416 -0.47620010651538197" />
			<geometry>
				<mesh filename="/home/blake/kitchen-worlds/assets/models/SinkBase/45332/textured_objs/original-62.obj" />/&gt;
			</geometry>
		</collision>
		<collision>
			<origin xyz="-0.7130134511490828 -0.5398004848060416 -0.47620010651538197" />
			<geometry>
				<mesh filename="/home/blake/kitchen-worlds/assets/models/SinkBase/45332/textured_objs/original-59.obj" />/&gt;
			</geometry>
		</collision>
		<collision>
			<origin xyz="-0.7130134511490828 -0.5398004848060416 -0.47620010651538197" />
			<geometry>
				<mesh filename="/home/blake/kitchen-worlds/assets/models/SinkBase/45332/textured_objs/original-65.obj" />/&gt;
			</geometry>
		</collision>
		<collision>
			<origin xyz="-0.7130134511490828 -0.5398004848060416 -0.47620010651538197" />
			<geometry>
				<mesh filename="/home/blake/kitchen-worlds/assets/models/SinkBase/45332/textured_objs/original-61.obj" />/&gt;
			</geometry>
		</collision>
		<collision>
			<origin xyz="-0.7130134511490828 -0.5398004848060416 -0.47620010651538197" />
			<geometry>
				<mesh filename="/home/blake/kitchen-worlds/assets/models/SinkBase/45332/textured_objs/original-63.obj" />/&gt;
			</geometry>
		</collision>
		<collision>
			<origin xyz="-0.7130134511490828 -0.5398004848060416 -0.47620010651538197" />
			<geometry>
				<mesh filename="/home/blake/kitchen-worlds/assets/models/SinkBase/45332/textured_objs/original-60.obj" />/&gt;
			</geometry>
		</collision>
		<collision>
			<origin xyz="-0.7130134511490828 -0.5398004848060416 -0.47620010651538197" />
			<geometry>
				<mesh filename="/home/blake/kitchen-worlds/assets/models/SinkBase/45332/textured_objs/original-64.obj" />/&gt;
			</geometry>
		</collision>
		<collision>
			<origin xyz="-0.7130134511490828 -0.5398004848060416 -0.47620010651538197" />
			<geometry>
				<mesh filename="/home/blake/kitchen-worlds/assets/models/SinkBase/45332/textured_objs/original-67.obj" />/&gt;
			</geometry>
		</collision>
		<collision>
			<origin xyz="-0.7130134511490828 -0.5398004848060416 -0.47620010651538197" />
			<geometry>
				<mesh filename="/home/blake/kitchen-worlds/assets/models/SinkBase/45332/textured_objs/original-71.obj" />/&gt;
			</geometry>
		</collision>
		<collision>
			<origin xyz="-0.7130134511490828 -0.5398004848060416 -0.47620010651538197" />
			<geometry>
				<mesh filename="/home/blake/kitchen-worlds/assets/models/SinkBase/45332/textured_objs/original-72.obj" />/&gt;
			</geometry>
		</collision>
		<collision>
			<origin xyz="-0.7130134511490828 -0.5398004848060416 -0.47620010651538197" />
			<geometry>
				<mesh filename="/home/blake/kitchen-worlds/assets/models/SinkBase/45332/textured_objs/original-76.obj" />/&gt;
			</geometry>
		</collision>
		<collision>
			<origin xyz="-0.7130134511490828 -0.5398004848060416 -0.47620010651538197" />
			<geometry>
				<mesh filename="/home/blake/kitchen-worlds/assets/models/SinkBase/45332/textured_objs/original-75.obj" />/&gt;
			</geometry>
		</collision>
		<collision>
			<origin xyz="-0.7130134511490828 -0.5398004848060416 -0.47620010651538197" />
			<geometry>
				<mesh filename="/home/blake/kitchen-worlds/assets/models/SinkBase/45332/textured_objs/original-74.obj" />/&gt;
			</geometry>
		</collision>
	</link>
	<joint name="joint_0" type="revolute">
		<origin xyz="0.7130134511490828 0.5398004848060416 0.47620010651538197" />
		<axis xyz="0 0.9999997700613202 -0.000678142541459935" />
		<child link="link_0" />
		<parent link="link_4" />
		<limit lower="0.0" upper="1.8409732950036186" effort="10.0" velocity="1.0" />
	</joint>
	<link name="link_1">
		<visual name="cabinet_door_surface-7">
			<origin xyz="0.674567971434532 0.2759116911513315 -0.47648214727952237" />
			<geometry>
				<mesh filename="/home/blake/kitchen-worlds/assets/models/SinkBase/45332/textured_objs/original-48.obj" />/&gt;
			</geometry>
		</visual>
		<visual name="cabinet_door_surface-7">
			<origin xyz="0.674567971434532 0.2759116911513315 -0.47648214727952237" />
			<geometry>
				<mesh filename="/home/blake/kitchen-worlds/assets/models/SinkBase/45332/textured_objs/original-44.obj" />/&gt;
			</geometry>
		</visual>
		<visual name="cabinet_door_surface-7">
			<origin xyz="0.674567971434532 0.2759116911513315 -0.47648214727952237" />
			<geometry>
				<mesh filename="/home/blake/kitchen-worlds/assets/models/SinkBase/45332/textured_objs/original-42.obj" />/&gt;
			</geometry>
		</visual>
		<visual name="cabinet_door_surface-7">
			<origin xyz="0.674567971434532 0.2759116911513315 -0.47648214727952237" />
			<geometry>
				<mesh filename="/home/blake/kitchen-worlds/assets/models/SinkBase/45332/textured_objs/original-38.obj" />/&gt;
			</geometry>
		</visual>
		<visual name="cabinet_door_surface-7">
			<origin xyz="0.674567971434532 0.2759116911513315 -0.47648214727952237" />
			<geometry>
				<mesh filename="/home/blake/kitchen-worlds/assets/models/SinkBase/45332/textured_objs/original-39.obj" />/&gt;
			</geometry>
		</visual>
		<visual name="cabinet_door_surface-7">
			<origin xyz="0.674567971434532 0.2759116911513315 -0.47648214727952237" />
			<geometry>
				<mesh filename="/home/blake/kitchen-worlds/assets/models/SinkBase/45332/textured_objs/original-45.obj" />/&gt;
			</geometry>
		</visual>
		<visual name="cabinet_door_surface-7">
			<origin xyz="0.674567971434532 0.2759116911513315 -0.47648214727952237" />
			<geometry>
				<mesh filename="/home/blake/kitchen-worlds/assets/models/SinkBase/45332/textured_objs/original-41.obj" />/&gt;
			</geometry>
		</visual>
		<visual name="cabinet_door_surface-7">
			<origin xyz="0.674567971434532 0.2759116911513315 -0.47648214727952237" />
			<geometry>
				<mesh filename="/home/blake/kitchen-worlds/assets/models/SinkBase/45332/textured_objs/original-43.obj" />/&gt;
			</geometry>
		</visual>
		<visual name="cabinet_door_surface-7">
			<origin xyz="0.674567971434532 0.2759116911513315 -0.47648214727952237" />
			<geometry>
				<mesh filename="/home/blake/kitchen-worlds/assets/models/SinkBase/45332/textured_objs/original-40.obj" />/&gt;
			</geometry>
		</visual>
		<visual name="cabinet_door_surface-7">
			<origin xyz="0.674567971434532 0.2759116911513315 -0.47648214727952237" />
			<geometry>
				<mesh filename="/home/blake/kitchen-worlds/assets/models/SinkBase/45332/textured_objs/original-47.obj" />/&gt;
			</geometry>
		</visual>
		<visual name="handle-8">
			<origin xyz="0.674567971434532 0.2759116911513315 -0.47648214727952237" />
			<geometry>
				<mesh filename="/home/blake/kitchen-worlds/assets/models/SinkBase/45332/textured_objs/original-56.obj" />/&gt;
			</geometry>
		</visual>
		<visual name="handle-8">
			<origin xyz="0.674567971434532 0.2759116911513315 -0.47648214727952237" />
			<geometry>
				<mesh filename="/home/blake/kitchen-worlds/assets/models/SinkBase/45332/textured_objs/original-52.obj" />/&gt;
			</geometry>
		</visual>
		<visual name="handle-8">
			<origin xyz="0.674567971434532 0.2759116911513315 -0.47648214727952237" />
			<geometry>
				<mesh filename="/home/blake/kitchen-worlds/assets/models/SinkBase/45332/textured_objs/original-55.obj" />/&gt;
			</geometry>
		</visual>
		<visual name="handle-8">
			<origin xyz="0.674567971434532 0.2759116911513315 -0.47648214727952237" />
			<geometry>
				<mesh filename="/home/blake/kitchen-worlds/assets/models/SinkBase/45332/textured_objs/original-51.obj" />/&gt;
			</geometry>
		</visual>
		<visual name="handle-8">
			<origin xyz="0.674567971434532 0.2759116911513315 -0.47648214727952237" />
			<geometry>
				<mesh filename="/home/blake/kitchen-worlds/assets/models/SinkBase/45332/textured_objs/original-54.obj" />/&gt;
			</geometry>
		</visual>
		<collision>
			<origin xyz="0.674567971434532 0.2759116911513315 -0.47648214727952237" />
			<geometry>
				<mesh filename="/home/blake/kitchen-worlds/assets/models/SinkBase/45332/textured_objs/original-48.obj" />/&gt;
			</geometry>
		</collision>
		<collision>
			<origin xyz="0.674567971434532 0.2759116911513315 -0.47648214727952237" />
			<geometry>
				<mesh filename="/home/blake/kitchen-worlds/assets/models/SinkBase/45332/textured_objs/original-44.obj" />/&gt;
			</geometry>
		</collision>
		<collision>
			<origin xyz="0.674567971434532 0.2759116911513315 -0.47648214727952237" />
			<geometry>
				<mesh filename="/home/blake/kitchen-worlds/assets/models/SinkBase/45332/textured_objs/original-42.obj" />/&gt;
			</geometry>
		</collision>
		<collision>
			<origin xyz="0.674567971434532 0.2759116911513315 -0.47648214727952237" />
			<geometry>
				<mesh filename="/home/blake/kitchen-worlds/assets/models/SinkBase/45332/textured_objs/original-38.obj" />/&gt;
			</geometry>
		</collision>
		<collision>
			<origin xyz="0.674567971434532 0.2759116911513315 -0.47648214727952237" />
			<geometry>
				<mesh filename="/home/blake/kitchen-worlds/assets/models/SinkBase/45332/textured_objs/original-39.obj" />/&gt;
			</geometry>
		</collision>
		<collision>
			<origin xyz="0.674567971434532 0.2759116911513315 -0.47648214727952237" />
			<geometry>
				<mesh filename="/home/blake/kitchen-worlds/assets/models/SinkBase/45332/textured_objs/original-45.obj" />/&gt;
			</geometry>
		</collision>
		<collision>
			<origin xyz="0.674567971434532 0.2759116911513315 -0.47648214727952237" />
			<geometry>
				<mesh filename="/home/blake/kitchen-worlds/assets/models/SinkBase/45332/textured_objs/original-41.obj" />/&gt;
			</geometry>
		</collision>
		<collision>
			<origin xyz="0.674567971434532 0.2759116911513315 -0.47648214727952237" />
			<geometry>
				<mesh filename="/home/blake/kitchen-worlds/assets/models/SinkBase/45332/textured_objs/original-43.obj" />/&gt;
			</geometry>
		</collision>
		<collision>
			<origin xyz="0.674567971434532 0.2759116911513315 -0.47648214727952237" />
			<geometry>
				<mesh filename="/home/blake/kitchen-worlds/assets/models/SinkBase/45332/textured_objs/original-40.obj" />/&gt;
			</geometry>
		</collision>
		<collision>
			<origin xyz="0.674567971434532 0.2759116911513315 -0.47648214727952237" />
			<geometry>
				<mesh filename="/home/blake/kitchen-worlds/assets/models/SinkBase/45332/textured_objs/original-47.obj" />/&gt;
			</geometry>
		</collision>
		<collision>
			<origin xyz="0.674567971434532 0.2759116911513315 -0.47648214727952237" />
			<geometry>
				<mesh filename="/home/blake/kitchen-worlds/assets/models/SinkBase/45332/textured_objs/original-56.obj" />/&gt;
			</geometry>
		</collision>
		<collision>
			<origin xyz="0.674567971434532 0.2759116911513315 -0.47648214727952237" />
			<geometry>
				<mesh filename="/home/blake/kitchen-worlds/assets/models/SinkBase/45332/textured_objs/original-52.obj" />/&gt;
			</geometry>
		</collision>
		<collision>
			<origin xyz="0.674567971434532 0.2759116911513315 -0.47648214727952237" />
			<geometry>
				<mesh filename="/home/blake/kitchen-worlds/assets/models/SinkBase/45332/textured_objs/original-55.obj" />/&gt;
			</geometry>
		</collision>
		<collision>
			<origin xyz="0.674567971434532 0.2759116911513315 -0.47648214727952237" />
			<geometry>
				<mesh filename="/home/blake/kitchen-worlds/assets/models/SinkBase/45332/textured_objs/original-51.obj" />/&gt;
			</geometry>
		</collision>
		<collision>
			<origin xyz="0.674567971434532 0.2759116911513315 -0.47648214727952237" />
			<geometry>
				<mesh filename="/home/blake/kitchen-worlds/assets/models/SinkBase/45332/textured_objs/original-54.obj" />/&gt;
			</geometry>
		</collision>
	</link>
	<joint name="joint_1" type="revolute">
		<origin xyz="-0.674567971434532 -0.2759116911513315 0.47648214727952237" />
		<axis xyz="0 -0.9999997700613203 -0.0006781425414599351" />
		<child link="link_1" />
		<parent link="link_4" />
		<limit lower="0.0" upper="1.8158405537749003" effort="10.0" velocity="1.0" />
	</joint>
	<link name="link_2">
		<visual name="drawer_front-25">
			<origin xyz="-0.38088184223371396 0.20525192503246686 -0.4952349960803988" />
			<geometry>
				<mesh filename="/home/blake/kitchen-worlds/assets/models/SinkBase/45332/textured_objs/original-32.obj" />/&gt;
			</geometry>
		</visual>
		<visual name="drawer_side-26">
			<origin xyz="-0.38088184223371396 0.20525192503246686 -0.4952349960803988" />
			<geometry>
				<mesh filename="/home/blake/kitchen-worlds/assets/models/SinkBase/45332/textured_objs/original-31.obj" />/&gt;
			</geometry>
		</visual>
		<visual name="drawer_side-27">
			<origin xyz="-0.38088184223371396 0.20525192503246686 -0.4952349960803988" />
			<geometry>
				<mesh filename="/home/blake/kitchen-worlds/assets/models/SinkBase/45332/textured_objs/original-34.obj" />/&gt;
			</geometry>
		</visual>
		<visual name="drawer_back-28">
			<origin xyz="-0.38088184223371396 0.20525192503246686 -0.4952349960803988" />
			<geometry>
				<mesh filename="/home/blake/kitchen-worlds/assets/models/SinkBase/45332/textured_objs/original-35.obj" />/&gt;
			</geometry>
		</visual>
		<visual name="drawer_bottom-29">
			<origin xyz="-0.38088184223371396 0.20525192503246686 -0.4952349960803988" />
			<geometry>
				<mesh filename="/home/blake/kitchen-worlds/assets/models/SinkBase/45332/textured_objs/original-33.obj" />/&gt;
			</geometry>
		</visual>
		<visual name="other_leaf-31">
			<origin xyz="-0.38088184223371396 0.20525192503246686 -0.4952349960803988" />
			<geometry>
				<mesh filename="/home/blake/kitchen-worlds/assets/models/SinkBase/45332/textured_objs/original-36.obj" />/&gt;
			</geometry>
		</visual>
		<collision>
			<origin xyz="-0.38088184223371396 0.20525192503246686 -0.4952349960803988" />
			<geometry>
				<mesh filename="/home/blake/kitchen-worlds/assets/models/SinkBase/45332/textured_objs/original-32.obj" />/&gt;
			</geometry>
		</collision>
		<collision>
			<origin xyz="-0.38088184223371396 0.20525192503246686 -0.4952349960803988" />
			<geometry>
				<mesh filename="/home/blake/kitchen-worlds/assets/models/SinkBase/45332/textured_objs/original-31.obj" />/&gt;
			</geometry>
		</collision>
		<collision>
			<origin xyz="-0.38088184223371396 0.20525192503246686 -0.4952349960803988" />
			<geometry>
				<mesh filename="/home/blake/kitchen-worlds/assets/models/SinkBase/45332/textured_objs/original-34.obj" />/&gt;
			</geometry>
		</collision>
		<collision>
			<origin xyz="-0.38088184223371396 0.20525192503246686 -0.4952349960803988" />
			<geometry>
				<mesh filename="/home/blake/kitchen-worlds/assets/models/SinkBase/45332/textured_objs/original-35.obj" />/&gt;
			</geometry>
		</collision>
		<collision>
			<origin xyz="-0.38088184223371396 0.20525192503246686 -0.4952349960803988" />
			<geometry>
				<mesh filename="/home/blake/kitchen-worlds/assets/models/SinkBase/45332/textured_objs/original-33.obj" />/&gt;
			</geometry>
		</collision>
		<collision>
			<origin xyz="-0.38088184223371396 0.20525192503246686 -0.4952349960803988" />
			<geometry>
				<mesh filename="/home/blake/kitchen-worlds/assets/models/SinkBase/45332/textured_objs/original-36.obj" />/&gt;
			</geometry>
		</collision>
	</link>
	<joint name="joint_2" type="prismatic">
		<origin xyz="0.38088184223371396 -0.20525192503246686 0.4952349960803988" />
		<axis xyz="0 0 1" />
		<child link="link_2" />
		<parent link="link_4" />
		<limit lower="0" upper="0.7240000000000002" effort="10.0" velocity="1.0" />
	</joint>
	<link name="link_3">
		<visual name="drawer_front-17">
			<origin xyz="0.36730260895927747 0.20486946987863303 -0.49523499608039856" />
			<geometry>
				<mesh filename="/home/blake/kitchen-worlds/assets/models/SinkBase/45332/textured_objs/original-25.obj" />/&gt;
			</geometry>
		</visual>
		<visual name="drawer_side-18">
			<origin xyz="0.36730260895927747 0.20486946987863303 -0.49523499608039856" />
			<geometry>
				<mesh filename="/home/blake/kitchen-worlds/assets/models/SinkBase/45332/textured_objs/original-24.obj" />/&gt;
			</geometry>
		</visual>
		<visual name="drawer_side-19">
			<origin xyz="0.36730260895927747 0.20486946987863303 -0.49523499608039856" />
			<geometry>
				<mesh filename="/home/blake/kitchen-worlds/assets/models/SinkBase/45332/textured_objs/original-27.obj" />/&gt;
			</geometry>
		</visual>
		<visual name="drawer_back-20">
			<origin xyz="0.36730260895927747 0.20486946987863303 -0.49523499608039856" />
			<geometry>
				<mesh filename="/home/blake/kitchen-worlds/assets/models/SinkBase/45332/textured_objs/original-28.obj" />/&gt;
			</geometry>
		</visual>
		<visual name="drawer_bottom-21">
			<origin xyz="0.36730260895927747 0.20486946987863303 -0.49523499608039856" />
			<geometry>
				<mesh filename="/home/blake/kitchen-worlds/assets/models/SinkBase/45332/textured_objs/original-26.obj" />/&gt;
			</geometry>
		</visual>
		<visual name="other_leaf-23">
			<origin xyz="0.36730260895927747 0.20486946987863303 -0.49523499608039856" />
			<geometry>
				<mesh filename="/home/blake/kitchen-worlds/assets/models/SinkBase/45332/textured_objs/original-29.obj" />/&gt;
			</geometry>
		</visual>
		<collision>
			<origin xyz="0.36730260895927747 0.20486946987863303 -0.49523499608039856" />
			<geometry>
				<mesh filename="/home/blake/kitchen-worlds/assets/models/SinkBase/45332/textured_objs/original-25.obj" />/&gt;
			</geometry>
		</collision>
		<collision>
			<origin xyz="0.36730260895927747 0.20486946987863303 -0.49523499608039856" />
			<geometry>
				<mesh filename="/home/blake/kitchen-worlds/assets/models/SinkBase/45332/textured_objs/original-24.obj" />/&gt;
			</geometry>
		</collision>
		<collision>
			<origin xyz="0.36730260895927747 0.20486946987863303 -0.49523499608039856" />
			<geometry>
				<mesh filename="/home/blake/kitchen-worlds/assets/models/SinkBase/45332/textured_objs/original-27.obj" />/&gt;
			</geometry>
		</collision>
		<collision>
			<origin xyz="0.36730260895927747 0.20486946987863303 -0.49523499608039856" />
			<geometry>
				<mesh filename="/home/blake/kitchen-worlds/assets/models/SinkBase/45332/textured_objs/original-28.obj" />/&gt;
			</geometry>
		</collision>
		<collision>
			<origin xyz="0.36730260895927747 0.20486946987863303 -0.49523499608039856" />
			<geometry>
				<mesh filename="/home/blake/kitchen-worlds/assets/models/SinkBase/45332/textured_objs/original-26.obj" />/&gt;
			</geometry>
		</collision>
		<collision>
			<origin xyz="0.36730260895927747 0.20486946987863303 -0.49523499608039856" />
			<geometry>
				<mesh filename="/home/blake/kitchen-worlds/assets/models/SinkBase/45332/textured_objs/original-29.obj" />/&gt;
			</geometry>
		</collision>
	</link>
	<joint name="joint_3" type="prismatic">
		<origin xyz="-0.36730260895927747 -0.20486946987863303 0.49523499608039856" />
		<axis xyz="0 0 0.9999999999999999" />
		<child link="link_3" />
		<parent link="link_4" />
		<limit lower="0" upper="0.7360000000000002" effort="10.0" velocity="1.0" />
	</joint>
	<link name="link_4">
		<visual name="shelf-13">
			<origin xyz="0 0 0" />
			<geometry>
				<mesh filename="/home/blake/kitchen-worlds/assets/models/SinkBase/45332/textured_objs/original-22.obj" />/&gt;
			</geometry>
		</visual>
		<visual name="vertical_side_panel-37">
			<origin xyz="0 0 0" />
			<geometry>
				<mesh filename="/home/blake/kitchen-worlds/assets/models/SinkBase/45332/textured_objs/original-15.obj" />/&gt;
			</geometry>
		</visual>
		<visual name="vertical_side_panel-37">
			<origin xyz="0 0 0" />
			<geometry>
				<mesh filename="/home/blake/kitchen-worlds/assets/models/SinkBase/45332/textured_objs/original-14.obj" />/&gt;
			</geometry>
		</visual>
		<visual name="vertical_side_panel-38">
			<origin xyz="0 0 0" />
			<geometry>
				<mesh filename="/home/blake/kitchen-worlds/assets/models/SinkBase/45332/textured_objs/original-11.obj" />/&gt;
			</geometry>
		</visual>
		<visual name="vertical_side_panel-38">
			<origin xyz="0 0 0" />
			<geometry>
				<mesh filename="/home/blake/kitchen-worlds/assets/models/SinkBase/45332/textured_objs/original-10.obj" />/&gt;
			</geometry>
		</visual>
		<visual name="back_panel-39">
			<origin xyz="0 0 0" />
			<geometry>
				<mesh filename="/home/blake/kitchen-worlds/assets/models/SinkBase/45332/textured_objs/original-5.obj" />/&gt;
			</geometry>
		</visual>
		<visual name="back_panel-39">
			<origin xyz="0 0 0" />
			<geometry>
				<mesh filename="/home/blake/kitchen-worlds/assets/models/SinkBase/45332/textured_objs/original-4.obj" />/&gt;
			</geometry>
		</visual>
		<visual name="bottom_panel-40">
			<origin xyz="0 0 0" />
			<geometry>
				<mesh filename="/home/blake/kitchen-worlds/assets/models/SinkBase/45332/textured_objs/original-2.obj" />/&gt;
			</geometry>
		</visual>
		<visual name="frame_vertical_bar-41">
			<origin xyz="0 0 0" />
			<geometry>
				<mesh filename="/home/blake/kitchen-worlds/assets/models/SinkBase/45332/textured_objs/original-3.obj" />/&gt;
			</geometry>
		</visual>
		<visual name="frame_vertical_bar-42">
			<origin xyz="0 0 0" />
			<geometry>
				<mesh filename="/home/blake/kitchen-worlds/assets/models/SinkBase/45332/textured_objs/original-21.obj" />/&gt;
			</geometry>
		</visual>
		<visual name="frame_vertical_bar-43">
			<origin xyz="0 0 0" />
			<geometry>
				<mesh filename="/home/blake/kitchen-worlds/assets/models/SinkBase/45332/textured_objs/original-7.obj" />/&gt;
			</geometry>
		</visual>
		<visual name="frame_horizontal_bar-44">
			<origin xyz="0 0 0" />
			<geometry>
				<mesh filename="/home/blake/kitchen-worlds/assets/models/SinkBase/45332/textured_objs/original-8.obj" />/&gt;
			</geometry>
		</visual>
		<visual name="frame_horizontal_bar-45">
			<origin xyz="0 0 0" />
			<geometry>
				<mesh filename="/home/blake/kitchen-worlds/assets/models/SinkBase/45332/textured_objs/original-6.obj" />/&gt;
			</geometry>
		</visual>
		<visual name="frame_horizontal_bar-46">
			<origin xyz="0 0 0" />
			<geometry>
				<mesh filename="/home/blake/kitchen-worlds/assets/models/SinkBase/45332/textured_objs/original-20.obj" />/&gt;
			</geometry>
		</visual>
		<visual name="frame_horizontal_bar-47">
			<origin xyz="0 0 0" />
			<geometry>
				<mesh filename="/home/blake/kitchen-worlds/assets/models/SinkBase/45332/textured_objs/original-19.obj" />/&gt;
			</geometry>
		</visual>
		<visual name="other_leaf-49">
			<origin xyz="0 0 0" />
			<geometry>
				<mesh filename="/home/blake/kitchen-worlds/assets/models/SinkBase/45332/textured_objs/original-77.obj" />/&gt;
			</geometry>
		</visual>
		<visual name="base_side_panel-33">
			<origin xyz="0 0 0" />
			<geometry>
				<mesh filename="/home/blake/kitchen-worlds/assets/models/SinkBase/45332/textured_objs/original-12.obj" />/&gt;
			</geometry>
		</visual>
		<visual name="base_side_panel-34">
			<origin xyz="0 0 0" />
			<geometry>
				<mesh filename="/home/blake/kitchen-worlds/assets/models/SinkBase/45332/textured_objs/original-17.obj" />/&gt;
			</geometry>
		</visual>
		<visual name="base_side_panel-35">
			<origin xyz="0 0 0" />
			<geometry>
				<mesh filename="/home/blake/kitchen-worlds/assets/models/SinkBase/45332/textured_objs/original-16.obj" />/&gt;
			</geometry>
		</visual>
		<visual name="base_side_panel-36">
			<origin xyz="0 0 0" />
			<geometry>
				<mesh filename="/home/blake/kitchen-worlds/assets/models/SinkBase/45332/textured_objs/original-18.obj" />/&gt;
			</geometry>
		</visual>
		<collision>
			<origin xyz="0 0 0" />
			<geometry>
				<mesh filename="/home/blake/kitchen-worlds/assets/models/SinkBase/45332/textured_objs/original-22.obj" />/&gt;
			</geometry>
		</collision>
		<collision>
			<origin xyz="0 0 0" />
			<geometry>
				<mesh filename="/home/blake/kitchen-worlds/assets/models/SinkBase/45332/textured_objs/original-15.obj" />/&gt;
			</geometry>
		</collision>
		<collision>
			<origin xyz="0 0 0" />
			<geometry>
				<mesh filename="/home/blake/kitchen-worlds/assets/models/SinkBase/45332/textured_objs/original-14.obj" />/&gt;
			</geometry>
		</collision>
		<collision>
			<origin xyz="0 0 0" />
			<geometry>
				<mesh filename="/home/blake/kitchen-worlds/assets/models/SinkBase/45332/textured_objs/original-11.obj" />/&gt;
			</geometry>
		</collision>
		<collision>
			<origin xyz="0 0 0" />
			<geometry>
				<mesh filename="/home/blake/kitchen-worlds/assets/models/SinkBase/45332/textured_objs/original-10.obj" />/&gt;
			</geometry>
		</collision>
		<collision>
			<origin xyz="0 0 0" />
			<geometry>
				<mesh filename="/home/blake/kitchen-worlds/assets/models/SinkBase/45332/textured_objs/original-5.obj" />/&gt;
			</geometry>
		</collision>
		<collision>
			<origin xyz="0 0 0" />
			<geometry>
				<mesh filename="/home/blake/kitchen-worlds/assets/models/SinkBase/45332/textured_objs/original-4.obj" />/&gt;
			</geometry>
		</collision>
		<collision>
			<origin xyz="0 0 0" />
			<geometry>
				<mesh filename="/home/blake/kitchen-worlds/assets/models/SinkBase/45332/textured_objs/original-2.obj" />/&gt;
			</geometry>
		</collision>
		<collision>
			<origin xyz="0 0 0" />
			<geometry>
				<mesh filename="/home/blake/kitchen-worlds/assets/models/SinkBase/45332/textured_objs/original-3.obj" />/&gt;
			</geometry>
		</collision>
		<collision>
			<origin xyz="0 0 0" />
			<geometry>
				<mesh filename="/home/blake/kitchen-worlds/assets/models/SinkBase/45332/textured_objs/original-21.obj" />/&gt;
			</geometry>
		</collision>
		<collision>
			<origin xyz="0 0 0" />
			<geometry>
				<mesh filename="/home/blake/kitchen-worlds/assets/models/SinkBase/45332/textured_objs/original-7.obj" />/&gt;
			</geometry>
		</collision>
		<collision>
			<origin xyz="0 0 0" />
			<geometry>
				<mesh filename="/home/blake/kitchen-worlds/assets/models/SinkBase/45332/textured_objs/original-8.obj" />/&gt;
			</geometry>
		</collision>
		<collision>
			<origin xyz="0 0 0" />
			<geometry>
				<mesh filename="/home/blake/kitchen-worlds/assets/models/SinkBase/45332/textured_objs/original-6.obj" />/&gt;
			</geometry>
		</collision>
		<collision>
			<origin xyz="0 0 0" />
			<geometry>
				<mesh filename="/home/blake/kitchen-worlds/assets/models/SinkBase/45332/textured_objs/original-20.obj" />/&gt;
			</geometry>
		</collision>
		<collision>
			<origin xyz="0 0 0" />
			<geometry>
				<mesh filename="/home/blake/kitchen-worlds/assets/models/SinkBase/45332/textured_objs/original-19.obj" />/&gt;
			</geometry>
		</collision>
		<collision>
			<origin xyz="0 0 0" />
			<geometry>
				<mesh filename="/home/blake/kitchen-worlds/assets/models/SinkBase/45332/textured_objs/original-77.obj" />/&gt;
			</geometry>
		</collision>
		<collision>
			<origin xyz="0 0 0" />
			<geometry>
				<mesh filename="/home/blake/kitchen-worlds/assets/models/SinkBase/45332/textured_objs/original-12.obj" />/&gt;
			</geometry>
		</collision>
		<collision>
			<origin xyz="0 0 0" />
			<geometry>
				<mesh filename="/home/blake/kitchen-worlds/assets/models/SinkBase/45332/textured_objs/original-17.obj" />/&gt;
			</geometry>
		</collision>
		<collision>
			<origin xyz="0 0 0" />
			<geometry>
				<mesh filename="/home/blake/kitchen-worlds/assets/models/SinkBase/45332/textured_objs/original-16.obj" />/&gt;
			</geometry>
		</collision>
		<collision>
			<origin xyz="0 0 0" />
			<geometry>
				<mesh filename="/home/blake/kitchen-worlds/assets/models/SinkBase/45332/textured_objs/original-18.obj" />/&gt;
			</geometry>
		</collision>
	</link>
	<joint name="joint_4" type="fixed">
		<origin rpy="1.570796326794897 0 -1.570796326794897" xyz="0 0 0" />
		<child link="link_4" />
		<parent link="base" />
	</joint>
</robot>