<?xml version='1.0' encoding='utf-8'?>
<robot name="partnet_3158fd17e409d38a732208e596b26ebc">
	<link name="base"><inertial><mass value="0.1" /><inertia ixx="0.01" iyy="0.01" izz="0.01" ixy="0" ixz="0" iyz="0" /></inertial></link>

	<link name="handle">
		<visual name="door_frame-7">
			<origin xyz="-0.4767337469989671 -0.780485987663269 -0.45759143604256247" />
			<geometry>
				<mesh filename="MiniFridge/12249/textured_objs/original-2.obj"/>
			</geometry>
		</visual>
		<collision>
			<origin xyz="-0.4767337469989671 -0.780485987663269 -0.43759143604256247" />
			<geometry>
				<mesh filename="MiniFridge/12249/textured_objs/original-2-new.obj"/>
			</geometry>
		</collision>
	<inertial><mass value="0.1" /><inertia ixx="0.01" iyy="0.01" izz="0.01" ixy="0" ixz="0" iyz="0" /></inertial></link>
	<joint name="joint_handle" type="fixed">
		
		<origin xyz="0 0 0.04" />
		<axis xyz="0 0.9999999999999999 0" />
		<child link="handle" />
		<parent link="link_0" />
	</joint>


	<link name="link_0">
		<visual name="door_frame-7">
			<origin xyz="-0.4767337469989671 -0.780485987663269 -0.45759143604256247" />
			<geometry>
				<mesh filename="MiniFridge/12249/textured_objs/original-2.obj"/>
			</geometry>
		</visual>
		<visual name="door_frame-7">
			<origin xyz="-0.4767337469989671 -0.780485987663269 -0.45759143604256247" />
			<geometry>
				<mesh filename="MiniFridge/12249/textured_objs/original-3.obj"/>
			</geometry>
		</visual>
		<collision>
			<origin xyz="-0.4767337469989671 -0.780485987663269 -0.45759143604256247" />
			<geometry>
				<mesh filename="MiniFridge/12249/textured_objs/original-2.obj"/>
			</geometry>
		</collision>
		<collision>
			<origin xyz="-0.4767337469989671 -0.780485987663269 -0.45759143604256247" />
			<geometry>
				<mesh filename="MiniFridge/12249/textured_objs/original-3.obj"/>
			</geometry>
		</collision>
	<inertial><mass value="0.1" /><inertia ixx="0.01" iyy="0.01" izz="0.01" ixy="0" ixz="0" iyz="0" /></inertial></link>
	<joint name="joint_0" type="revolute">
		<origin xyz="0.4767337469989671 0.780485987663269 0.45759143604256247" />
		<axis xyz="0 0.9999999999999999 0" />
		<child link="link_0" />
		<parent link="link_1" />
		<limit lower="0.0" upper="2.0943951023931953" effort="10.0" velocity="1.0" />
	</joint>
	<link name="link_1">
		<visual name="surface-4">
			<origin xyz="0 0 0" />
			<geometry>
				<mesh filename="MiniFridge/12249/textured_objs/original-5.obj"/>
			</geometry>
		</visual>
		<visual name="frame-5">
			<origin xyz="0 0 0" />
			<geometry>
				<mesh filename="MiniFridge/12249/textured_objs/original-4.obj"/>
			</geometry>
		</visual>
		<collision>
			<origin xyz="0 0 0" />
			<geometry>
				<mesh filename="MiniFridge/12249/textured_objs/original-5.obj"/>
			</geometry>
		</collision>
		
		<collision>
			<origin xyz="0 0 0" />
			<geometry>
				<mesh filename="MiniFridge/12249/textured_objs/original-4-left.obj"/>
			</geometry>
		</collision>
		<collision>
			<origin xyz="0 0 0" />
			<geometry>
				<mesh filename="MiniFridge/12249/textured_objs/original-4-right.obj"/>
			</geometry>
		</collision>
		<collision>
			<origin xyz="0 0 0" />
			<geometry>
				<mesh filename="MiniFridge/12249/textured_objs/original-4-top.obj"/>
			</geometry>
		</collision>
		<collision>
			<origin xyz="0 0 0" />
			<geometry>
				<mesh filename="MiniFridge/12249/textured_objs/original-4-bottom.obj"/>
			</geometry>
		</collision>
		<collision>
			<origin xyz="0 0 0" />
			<geometry>
				<mesh filename="MiniFridge/12249/textured_objs/original-4-back.obj"/>
			</geometry>
		</collision>
	<inertial><mass value="0.1" /><inertia ixx="0.01" iyy="0.01" izz="0.01" ixy="0" ixz="0" iyz="0" /></inertial></link>
	<joint name="joint_1" type="fixed">
		<origin rpy="1.570796326794897 0 -1.570796326794897" xyz="0 0 0" />
		<child link="link_1" />
		<parent link="base" />
	</joint>
</robot>