<?xml version='1.0' encoding='utf-8'?>
<robot name="partnet_59514f197c4984483d2dd82a57bb3bd7">
	<link name="base" />
	<link name="link_0">
		<visual name="leg-1">
			<origin xyz="0.6191767688279016 -0.1356937248580672 -0.2351828612194744" />
			<geometry>
				<mesh filename="/home/blake/kitchen-worlds/assets/models/EyeGlasses/101328/textured_objs/original-5.obj" />/&gt;
			</geometry>
		</visual>
		<collision>
			<origin xyz="0.6191767688279016 -0.1356937248580672 -0.2351828612194744" />
			<geometry>
				<mesh filename="/home/blake/kitchen-worlds/assets/models/EyeGlasses/101328/textured_objs/original-5.obj" />/&gt;
			</geometry>
		</collision>
	</link>
	<joint name="joint_0" type="revolute">
		<origin xyz="-0.6191767688279016 0.1356937248580672 0.2351828612194744" />
		<axis xyz="0 -1 0" />
		<child link="link_0" />
		<parent link="link_2" />
		<limit lower="-0.0" upper="1.300619358586174" effort="10.0" velocity="1.0" />
	</joint>
	<link name="link_1">
		<visual name="leg-2">
			<origin xyz="-0.7039502006397401 0 -0.3298219580308154" />
			<geometry>
				<mesh filename="/home/blake/kitchen-worlds/assets/models/EyeGlasses/101328/textured_objs/original-6.obj" />/&gt;
			</geometry>
		</visual>
		<collision>
			<origin xyz="-0.7039502006397401 0 -0.3298219580308154" />
			<geometry>
				<mesh filename="/home/blake/kitchen-worlds/assets/models/EyeGlasses/101328/textured_objs/original-6.obj" />/&gt;
			</geometry>
		</collision>
	</link>
	<joint name="joint_1" type="revolute">
		<origin xyz="0.7039502006397401 0 0.3298219580308154" />
		<axis xyz="0 1 0" />
		<child link="link_1" />
		<parent link="link_2" />
		<limit lower="0.0" upper="1.1812388377497622" effort="10.0" velocity="1.0" />
	</joint>
	<link name="link_2">
		<visual name="base_body-3">
			<origin xyz="0 0 0" />
			<geometry>
				<mesh filename="/home/blake/kitchen-worlds/assets/models/EyeGlasses/101328/textured_objs/original-4.obj" />/&gt;
			</geometry>
		</visual>
		<visual name="base_body-3">
			<origin xyz="0 0 0" />
			<geometry>
				<mesh filename="/home/blake/kitchen-worlds/assets/models/EyeGlasses/101328/textured_objs/original-3.obj" />/&gt;
			</geometry>
		</visual>
		<visual name="base_body-3">
			<origin xyz="0 0 0" />
			<geometry>
				<mesh filename="/home/blake/kitchen-worlds/assets/models/EyeGlasses/101328/textured_objs/original-2.obj" />/&gt;
			</geometry>
		</visual>
		<collision>
			<origin xyz="0 0 0" />
			<geometry>
				<mesh filename="/home/blake/kitchen-worlds/assets/models/EyeGlasses/101328/textured_objs/original-4.obj" />/&gt;
			</geometry>
		</collision>
		<collision>
			<origin xyz="0 0 0" />
			<geometry>
				<mesh filename="/home/blake/kitchen-worlds/assets/models/EyeGlasses/101328/textured_objs/original-3.obj" />/&gt;
			</geometry>
		</collision>
		<collision>
			<origin xyz="0 0 0" />
			<geometry>
				<mesh filename="/home/blake/kitchen-worlds/assets/models/EyeGlasses/101328/textured_objs/original-2.obj" />/&gt;
			</geometry>
		</collision>
	</link>
	<joint name="joint_2" type="fixed">
		<origin rpy="1.570796326794897 0 -1.570796326794897" xyz="0 0 0" />
		<child link="link_2" />
		<parent link="base" />
	</joint>
</robot>