<?xml version='1.0' encoding='utf-8'?>
<robot name="partnet_594a7dedea7abb21f77e460087130a90">
	<link name="base" />
	<link name="link_0">
		<visual name="drawer_front-52">
			<origin xyz="0 0 0" />
			<geometry>
				<mesh filename="/home/blake/kitchen-worlds/assets/models/DiningTable/23372/textured_objs/original-79.obj" />/&gt;
			</geometry>
		</visual>
		<visual name="drawer_side-53">
			<origin xyz="0 0 0" />
			<geometry>
				<mesh filename="/home/blake/kitchen-worlds/assets/models/DiningTable/23372/textured_objs/original-75.obj" />/&gt;
			</geometry>
		</visual>
		<visual name="drawer_side-54">
			<origin xyz="0 0 0" />
			<geometry>
				<mesh filename="/home/blake/kitchen-worlds/assets/models/DiningTable/23372/textured_objs/original-78.obj" />/&gt;
			</geometry>
		</visual>
		<visual name="drawer_back-55">
			<origin xyz="0 0 0" />
			<geometry>
				<mesh filename="/home/blake/kitchen-worlds/assets/models/DiningTable/23372/textured_objs/original-77.obj" />/&gt;
			</geometry>
		</visual>
		<visual name="drawer_bottom-56">
			<origin xyz="0 0 0" />
			<geometry>
				<mesh filename="/home/blake/kitchen-worlds/assets/models/DiningTable/23372/textured_objs/original-76.obj" />/&gt;
			</geometry>
		</visual>
		<visual name="handle-51">
			<origin xyz="0 0 0" />
			<geometry>
				<mesh filename="/home/blake/kitchen-worlds/assets/models/DiningTable/23372/textured_objs/original-80.obj" />/&gt;
			</geometry>
		</visual>
		<collision>
			<origin xyz="0 0 0" />
			<geometry>
				<mesh filename="/home/blake/kitchen-worlds/assets/models/DiningTable/23372/textured_objs/original-79.obj" />/&gt;
			</geometry>
		</collision>
		<collision>
			<origin xyz="0 0 0" />
			<geometry>
				<mesh filename="/home/blake/kitchen-worlds/assets/models/DiningTable/23372/textured_objs/original-75.obj" />/&gt;
			</geometry>
		</collision>
		<collision>
			<origin xyz="0 0 0" />
			<geometry>
				<mesh filename="/home/blake/kitchen-worlds/assets/models/DiningTable/23372/textured_objs/original-78.obj" />/&gt;
			</geometry>
		</collision>
		<collision>
			<origin xyz="0 0 0" />
			<geometry>
				<mesh filename="/home/blake/kitchen-worlds/assets/models/DiningTable/23372/textured_objs/original-77.obj" />/&gt;
			</geometry>
		</collision>
		<collision>
			<origin xyz="0 0 0" />
			<geometry>
				<mesh filename="/home/blake/kitchen-worlds/assets/models/DiningTable/23372/textured_objs/original-76.obj" />/&gt;
			</geometry>
		</collision>
		<collision>
			<origin xyz="0 0 0" />
			<geometry>
				<mesh filename="/home/blake/kitchen-worlds/assets/models/DiningTable/23372/textured_objs/original-80.obj" />/&gt;
			</geometry>
		</collision>
	</link>
	<joint name="joint_0" type="prismatic">
		<origin xyz="0 0 0" />
		<axis xyz="0 0 1" />
		<child link="link_0" />
		<parent link="link_4" />
		<limit lower="0" upper="0.3599999999999999" effort="10.0" velocity="1.0" />
	</joint>
	<link name="link_1">
		<visual name="drawer_front-45">
			<origin xyz="0 0 0" />
			<geometry>
				<mesh filename="/home/blake/kitchen-worlds/assets/models/DiningTable/23372/textured_objs/original-72.obj" />/&gt;
			</geometry>
		</visual>
		<visual name="drawer_side-46">
			<origin xyz="0 0 0" />
			<geometry>
				<mesh filename="/home/blake/kitchen-worlds/assets/models/DiningTable/23372/textured_objs/original-68.obj" />/&gt;
			</geometry>
		</visual>
		<visual name="drawer_side-47">
			<origin xyz="0 0 0" />
			<geometry>
				<mesh filename="/home/blake/kitchen-worlds/assets/models/DiningTable/23372/textured_objs/original-71.obj" />/&gt;
			</geometry>
		</visual>
		<visual name="drawer_back-48">
			<origin xyz="0 0 0" />
			<geometry>
				<mesh filename="/home/blake/kitchen-worlds/assets/models/DiningTable/23372/textured_objs/original-70.obj" />/&gt;
			</geometry>
		</visual>
		<visual name="drawer_bottom-49">
			<origin xyz="0 0 0" />
			<geometry>
				<mesh filename="/home/blake/kitchen-worlds/assets/models/DiningTable/23372/textured_objs/original-69.obj" />/&gt;
			</geometry>
		</visual>
		<visual name="handle-44">
			<origin xyz="0 0 0" />
			<geometry>
				<mesh filename="/home/blake/kitchen-worlds/assets/models/DiningTable/23372/textured_objs/original-73.obj" />/&gt;
			</geometry>
		</visual>
		<collision>
			<origin xyz="0 0 0" />
			<geometry>
				<mesh filename="/home/blake/kitchen-worlds/assets/models/DiningTable/23372/textured_objs/original-72.obj" />/&gt;
			</geometry>
		</collision>
		<collision>
			<origin xyz="0 0 0" />
			<geometry>
				<mesh filename="/home/blake/kitchen-worlds/assets/models/DiningTable/23372/textured_objs/original-68.obj" />/&gt;
			</geometry>
		</collision>
		<collision>
			<origin xyz="0 0 0" />
			<geometry>
				<mesh filename="/home/blake/kitchen-worlds/assets/models/DiningTable/23372/textured_objs/original-71.obj" />/&gt;
			</geometry>
		</collision>
		<collision>
			<origin xyz="0 0 0" />
			<geometry>
				<mesh filename="/home/blake/kitchen-worlds/assets/models/DiningTable/23372/textured_objs/original-70.obj" />/&gt;
			</geometry>
		</collision>
		<collision>
			<origin xyz="0 0 0" />
			<geometry>
				<mesh filename="/home/blake/kitchen-worlds/assets/models/DiningTable/23372/textured_objs/original-69.obj" />/&gt;
			</geometry>
		</collision>
		<collision>
			<origin xyz="0 0 0" />
			<geometry>
				<mesh filename="/home/blake/kitchen-worlds/assets/models/DiningTable/23372/textured_objs/original-73.obj" />/&gt;
			</geometry>
		</collision>
	</link>
	<joint name="joint_1" type="prismatic">
		<origin xyz="0 0 0" />
		<axis xyz="0 0 1" />
		<child link="link_1" />
		<parent link="link_4" />
		<limit lower="0" upper="0.3599999999999999" effort="10.0" velocity="1.0" />
	</joint>
	<link name="link_2">
		<visual name="cabinet_door_surface-19">
			<origin xyz="-0.7354781085937212 -0.404153 -0.20415488142776383" />
			<geometry>
				<mesh filename="/home/blake/kitchen-worlds/assets/models/DiningTable/23372/textured_objs/original-64.obj" />/&gt;
			</geometry>
		</visual>
		<visual name="cabinet_door_surface-19">
			<origin xyz="-0.7354781085937212 -0.404153 -0.20415488142776383" />
			<geometry>
				<mesh filename="/home/blake/kitchen-worlds/assets/models/DiningTable/23372/textured_objs/original-65.obj" />/&gt;
			</geometry>
		</visual>
		<visual name="cabinet_door_surface-19">
			<origin xyz="-0.7354781085937212 -0.404153 -0.20415488142776383" />
			<geometry>
				<mesh filename="/home/blake/kitchen-worlds/assets/models/DiningTable/23372/textured_objs/original-62.obj" />/&gt;
			</geometry>
		</visual>
		<visual name="cabinet_door_surface-19">
			<origin xyz="-0.7354781085937212 -0.404153 -0.20415488142776383" />
			<geometry>
				<mesh filename="/home/blake/kitchen-worlds/assets/models/DiningTable/23372/textured_objs/original-61.obj" />/&gt;
			</geometry>
		</visual>
		<visual name="cabinet_door_surface-19">
			<origin xyz="-0.7354781085937212 -0.404153 -0.20415488142776383" />
			<geometry>
				<mesh filename="/home/blake/kitchen-worlds/assets/models/DiningTable/23372/textured_objs/original-63.obj" />/&gt;
			</geometry>
		</visual>
		<visual name="handle-20">
			<origin xyz="-0.7354781085937212 -0.404153 -0.20415488142776383" />
			<geometry>
				<mesh filename="/home/blake/kitchen-worlds/assets/models/DiningTable/23372/textured_objs/original-66.obj" />/&gt;
			</geometry>
		</visual>
		<visual name="hinge-57">
			<origin xyz="-0.7354781085937212 -0.404153 -0.20415488142776383" />
			<geometry>
				<mesh filename="/home/blake/kitchen-worlds/assets/models/DiningTable/23372/textured_objs/original-24.obj" />/&gt;
			</geometry>
		</visual>
		<visual name="hinge-57">
			<origin xyz="-0.7354781085937212 -0.404153 -0.20415488142776383" />
			<geometry>
				<mesh filename="/home/blake/kitchen-worlds/assets/models/DiningTable/23372/textured_objs/original-25.obj" />/&gt;
			</geometry>
		</visual>
		<visual name="hinge-57">
			<origin xyz="-0.7354781085937212 -0.404153 -0.20415488142776383" />
			<geometry>
				<mesh filename="/home/blake/kitchen-worlds/assets/models/DiningTable/23372/textured_objs/original-27.obj" />/&gt;
			</geometry>
		</visual>
		<visual name="hinge-57">
			<origin xyz="-0.7354781085937212 -0.404153 -0.20415488142776383" />
			<geometry>
				<mesh filename="/home/blake/kitchen-worlds/assets/models/DiningTable/23372/textured_objs/original-28.obj" />/&gt;
			</geometry>
		</visual>
		<visual name="hinge-58">
			<origin xyz="-0.7354781085937212 -0.404153 -0.20415488142776383" />
			<geometry>
				<mesh filename="/home/blake/kitchen-worlds/assets/models/DiningTable/23372/textured_objs/original-30.obj" />/&gt;
			</geometry>
		</visual>
		<visual name="hinge-58">
			<origin xyz="-0.7354781085937212 -0.404153 -0.20415488142776383" />
			<geometry>
				<mesh filename="/home/blake/kitchen-worlds/assets/models/DiningTable/23372/textured_objs/original-31.obj" />/&gt;
			</geometry>
		</visual>
		<visual name="hinge-58">
			<origin xyz="-0.7354781085937212 -0.404153 -0.20415488142776383" />
			<geometry>
				<mesh filename="/home/blake/kitchen-worlds/assets/models/DiningTable/23372/textured_objs/original-34.obj" />/&gt;
			</geometry>
		</visual>
		<visual name="hinge-58">
			<origin xyz="-0.7354781085937212 -0.404153 -0.20415488142776383" />
			<geometry>
				<mesh filename="/home/blake/kitchen-worlds/assets/models/DiningTable/23372/textured_objs/original-33.obj" />/&gt;
			</geometry>
		</visual>
		<collision>
			<origin xyz="-0.7354781085937212 -0.404153 -0.20415488142776383" />
			<geometry>
				<mesh filename="/home/blake/kitchen-worlds/assets/models/DiningTable/23372/textured_objs/original-64.obj" />/&gt;
			</geometry>
		</collision>
		<collision>
			<origin xyz="-0.7354781085937212 -0.404153 -0.20415488142776383" />
			<geometry>
				<mesh filename="/home/blake/kitchen-worlds/assets/models/DiningTable/23372/textured_objs/original-65.obj" />/&gt;
			</geometry>
		</collision>
		<collision>
			<origin xyz="-0.7354781085937212 -0.404153 -0.20415488142776383" />
			<geometry>
				<mesh filename="/home/blake/kitchen-worlds/assets/models/DiningTable/23372/textured_objs/original-62.obj" />/&gt;
			</geometry>
		</collision>
		<collision>
			<origin xyz="-0.7354781085937212 -0.404153 -0.20415488142776383" />
			<geometry>
				<mesh filename="/home/blake/kitchen-worlds/assets/models/DiningTable/23372/textured_objs/original-61.obj" />/&gt;
			</geometry>
		</collision>
		<collision>
			<origin xyz="-0.7354781085937212 -0.404153 -0.20415488142776383" />
			<geometry>
				<mesh filename="/home/blake/kitchen-worlds/assets/models/DiningTable/23372/textured_objs/original-63.obj" />/&gt;
			</geometry>
		</collision>
		<collision>
			<origin xyz="-0.7354781085937212 -0.404153 -0.20415488142776383" />
			<geometry>
				<mesh filename="/home/blake/kitchen-worlds/assets/models/DiningTable/23372/textured_objs/original-66.obj" />/&gt;
			</geometry>
		</collision>
		<collision>
			<origin xyz="-0.7354781085937212 -0.404153 -0.20415488142776383" />
			<geometry>
				<mesh filename="/home/blake/kitchen-worlds/assets/models/DiningTable/23372/textured_objs/original-24.obj" />/&gt;
			</geometry>
		</collision>
		<collision>
			<origin xyz="-0.7354781085937212 -0.404153 -0.20415488142776383" />
			<geometry>
				<mesh filename="/home/blake/kitchen-worlds/assets/models/DiningTable/23372/textured_objs/original-25.obj" />/&gt;
			</geometry>
		</collision>
		<collision>
			<origin xyz="-0.7354781085937212 -0.404153 -0.20415488142776383" />
			<geometry>
				<mesh filename="/home/blake/kitchen-worlds/assets/models/DiningTable/23372/textured_objs/original-27.obj" />/&gt;
			</geometry>
		</collision>
		<collision>
			<origin xyz="-0.7354781085937212 -0.404153 -0.20415488142776383" />
			<geometry>
				<mesh filename="/home/blake/kitchen-worlds/assets/models/DiningTable/23372/textured_objs/original-28.obj" />/&gt;
			</geometry>
		</collision>
		<collision>
			<origin xyz="-0.7354781085937212 -0.404153 -0.20415488142776383" />
			<geometry>
				<mesh filename="/home/blake/kitchen-worlds/assets/models/DiningTable/23372/textured_objs/original-30.obj" />/&gt;
			</geometry>
		</collision>
		<collision>
			<origin xyz="-0.7354781085937212 -0.404153 -0.20415488142776383" />
			<geometry>
				<mesh filename="/home/blake/kitchen-worlds/assets/models/DiningTable/23372/textured_objs/original-31.obj" />/&gt;
			</geometry>
		</collision>
		<collision>
			<origin xyz="-0.7354781085937212 -0.404153 -0.20415488142776383" />
			<geometry>
				<mesh filename="/home/blake/kitchen-worlds/assets/models/DiningTable/23372/textured_objs/original-34.obj" />/&gt;
			</geometry>
		</collision>
		<collision>
			<origin xyz="-0.7354781085937212 -0.404153 -0.20415488142776383" />
			<geometry>
				<mesh filename="/home/blake/kitchen-worlds/assets/models/DiningTable/23372/textured_objs/original-33.obj" />/&gt;
			</geometry>
		</collision>
	</link>
	<joint name="joint_2" type="revolute">
		<origin xyz="0.7354781085937212 0.404153 0.20415488142776383" />
		<axis xyz="0 1 0" />
		<child link="link_2" />
		<parent link="link_4" />
		<limit lower="0.0" upper="1.5707963267948966" effort="10.0" velocity="1.0" />
	</joint>
	<link name="link_3">
		<visual name="cabinet_door_surface-17">
			<origin xyz="0.7021093134973193 -0.404153 -0.20361219397007435" />
			<geometry>
				<mesh filename="/home/blake/kitchen-worlds/assets/models/DiningTable/23372/textured_objs/original-58.obj" />/&gt;
			</geometry>
		</visual>
		<visual name="cabinet_door_surface-17">
			<origin xyz="0.7021093134973193 -0.404153 -0.20361219397007435" />
			<geometry>
				<mesh filename="/home/blake/kitchen-worlds/assets/models/DiningTable/23372/textured_objs/original-57.obj" />/&gt;
			</geometry>
		</visual>
		<visual name="cabinet_door_surface-17">
			<origin xyz="0.7021093134973193 -0.404153 -0.20361219397007435" />
			<geometry>
				<mesh filename="/home/blake/kitchen-worlds/assets/models/DiningTable/23372/textured_objs/original-55.obj" />/&gt;
			</geometry>
		</visual>
		<visual name="cabinet_door_surface-17">
			<origin xyz="0.7021093134973193 -0.404153 -0.20361219397007435" />
			<geometry>
				<mesh filename="/home/blake/kitchen-worlds/assets/models/DiningTable/23372/textured_objs/original-54.obj" />/&gt;
			</geometry>
		</visual>
		<visual name="cabinet_door_surface-17">
			<origin xyz="0.7021093134973193 -0.404153 -0.20361219397007435" />
			<geometry>
				<mesh filename="/home/blake/kitchen-worlds/assets/models/DiningTable/23372/textured_objs/original-56.obj" />/&gt;
			</geometry>
		</visual>
		<visual name="handle-18">
			<origin xyz="0.7021093134973193 -0.404153 -0.20361219397007435" />
			<geometry>
				<mesh filename="/home/blake/kitchen-worlds/assets/models/DiningTable/23372/textured_objs/original-59.obj" />/&gt;
			</geometry>
		</visual>
		<visual name="hinge-60">
			<origin xyz="0.7021093134973193 -0.404153 -0.20361219397007435" />
			<geometry>
				<mesh filename="/home/blake/kitchen-worlds/assets/models/DiningTable/23372/textured_objs/original-43.obj" />/&gt;
			</geometry>
		</visual>
		<visual name="hinge-60">
			<origin xyz="0.7021093134973193 -0.404153 -0.20361219397007435" />
			<geometry>
				<mesh filename="/home/blake/kitchen-worlds/assets/models/DiningTable/23372/textured_objs/original-42.obj" />/&gt;
			</geometry>
		</visual>
		<visual name="hinge-60">
			<origin xyz="0.7021093134973193 -0.404153 -0.20361219397007435" />
			<geometry>
				<mesh filename="/home/blake/kitchen-worlds/assets/models/DiningTable/23372/textured_objs/original-45.obj" />/&gt;
			</geometry>
		</visual>
		<visual name="hinge-60">
			<origin xyz="0.7021093134973193 -0.404153 -0.20361219397007435" />
			<geometry>
				<mesh filename="/home/blake/kitchen-worlds/assets/models/DiningTable/23372/textured_objs/original-46.obj" />/&gt;
			</geometry>
		</visual>
		<visual name="hinge-61">
			<origin xyz="0.7021093134973193 -0.404153 -0.20361219397007435" />
			<geometry>
				<mesh filename="/home/blake/kitchen-worlds/assets/models/DiningTable/23372/textured_objs/original-36.obj" />/&gt;
			</geometry>
		</visual>
		<visual name="hinge-61">
			<origin xyz="0.7021093134973193 -0.404153 -0.20361219397007435" />
			<geometry>
				<mesh filename="/home/blake/kitchen-worlds/assets/models/DiningTable/23372/textured_objs/original-37.obj" />/&gt;
			</geometry>
		</visual>
		<visual name="hinge-61">
			<origin xyz="0.7021093134973193 -0.404153 -0.20361219397007435" />
			<geometry>
				<mesh filename="/home/blake/kitchen-worlds/assets/models/DiningTable/23372/textured_objs/original-39.obj" />/&gt;
			</geometry>
		</visual>
		<visual name="hinge-61">
			<origin xyz="0.7021093134973193 -0.404153 -0.20361219397007435" />
			<geometry>
				<mesh filename="/home/blake/kitchen-worlds/assets/models/DiningTable/23372/textured_objs/original-40.obj" />/&gt;
			</geometry>
		</visual>
		<collision>
			<origin xyz="0.7021093134973193 -0.404153 -0.20361219397007435" />
			<geometry>
				<mesh filename="/home/blake/kitchen-worlds/assets/models/DiningTable/23372/textured_objs/original-58.obj" />/&gt;
			</geometry>
		</collision>
		<collision>
			<origin xyz="0.7021093134973193 -0.404153 -0.20361219397007435" />
			<geometry>
				<mesh filename="/home/blake/kitchen-worlds/assets/models/DiningTable/23372/textured_objs/original-57.obj" />/&gt;
			</geometry>
		</collision>
		<collision>
			<origin xyz="0.7021093134973193 -0.404153 -0.20361219397007435" />
			<geometry>
				<mesh filename="/home/blake/kitchen-worlds/assets/models/DiningTable/23372/textured_objs/original-55.obj" />/&gt;
			</geometry>
		</collision>
		<collision>
			<origin xyz="0.7021093134973193 -0.404153 -0.20361219397007435" />
			<geometry>
				<mesh filename="/home/blake/kitchen-worlds/assets/models/DiningTable/23372/textured_objs/original-54.obj" />/&gt;
			</geometry>
		</collision>
		<collision>
			<origin xyz="0.7021093134973193 -0.404153 -0.20361219397007435" />
			<geometry>
				<mesh filename="/home/blake/kitchen-worlds/assets/models/DiningTable/23372/textured_objs/original-56.obj" />/&gt;
			</geometry>
		</collision>
		<collision>
			<origin xyz="0.7021093134973193 -0.404153 -0.20361219397007435" />
			<geometry>
				<mesh filename="/home/blake/kitchen-worlds/assets/models/DiningTable/23372/textured_objs/original-59.obj" />/&gt;
			</geometry>
		</collision>
		<collision>
			<origin xyz="0.7021093134973193 -0.404153 -0.20361219397007435" />
			<geometry>
				<mesh filename="/home/blake/kitchen-worlds/assets/models/DiningTable/23372/textured_objs/original-43.obj" />/&gt;
			</geometry>
		</collision>
		<collision>
			<origin xyz="0.7021093134973193 -0.404153 -0.20361219397007435" />
			<geometry>
				<mesh filename="/home/blake/kitchen-worlds/assets/models/DiningTable/23372/textured_objs/original-42.obj" />/&gt;
			</geometry>
		</collision>
		<collision>
			<origin xyz="0.7021093134973193 -0.404153 -0.20361219397007435" />
			<geometry>
				<mesh filename="/home/blake/kitchen-worlds/assets/models/DiningTable/23372/textured_objs/original-45.obj" />/&gt;
			</geometry>
		</collision>
		<collision>
			<origin xyz="0.7021093134973193 -0.404153 -0.20361219397007435" />
			<geometry>
				<mesh filename="/home/blake/kitchen-worlds/assets/models/DiningTable/23372/textured_objs/original-46.obj" />/&gt;
			</geometry>
		</collision>
		<collision>
			<origin xyz="0.7021093134973193 -0.404153 -0.20361219397007435" />
			<geometry>
				<mesh filename="/home/blake/kitchen-worlds/assets/models/DiningTable/23372/textured_objs/original-36.obj" />/&gt;
			</geometry>
		</collision>
		<collision>
			<origin xyz="0.7021093134973193 -0.404153 -0.20361219397007435" />
			<geometry>
				<mesh filename="/home/blake/kitchen-worlds/assets/models/DiningTable/23372/textured_objs/original-37.obj" />/&gt;
			</geometry>
		</collision>
		<collision>
			<origin xyz="0.7021093134973193 -0.404153 -0.20361219397007435" />
			<geometry>
				<mesh filename="/home/blake/kitchen-worlds/assets/models/DiningTable/23372/textured_objs/original-39.obj" />/&gt;
			</geometry>
		</collision>
		<collision>
			<origin xyz="0.7021093134973193 -0.404153 -0.20361219397007435" />
			<geometry>
				<mesh filename="/home/blake/kitchen-worlds/assets/models/DiningTable/23372/textured_objs/original-40.obj" />/&gt;
			</geometry>
		</collision>
	</link>
	<joint name="joint_3" type="revolute">
		<origin xyz="-0.7021093134973193 0.404153 0.20361219397007435" />
		<axis xyz="0 -1 0" />
		<child link="link_3" />
		<parent link="link_4" />
		<limit lower="-0.0" upper="1.5707963267948966" effort="10.0" velocity="1.0" />
	</joint>
	<link name="link_4">
		<visual name="board-34">
			<origin xyz="0 0 0" />
			<geometry>
				<mesh filename="/home/blake/kitchen-worlds/assets/models/DiningTable/23372/textured_objs/original-7.obj" />/&gt;
			</geometry>
		</visual>
		<visual name="board-34">
			<origin xyz="0 0 0" />
			<geometry>
				<mesh filename="/home/blake/kitchen-worlds/assets/models/DiningTable/23372/textured_objs/original-50.obj" />/&gt;
			</geometry>
		</visual>
		<visual name="back_panel-9">
			<origin xyz="0 0 0" />
			<geometry>
				<mesh filename="/home/blake/kitchen-worlds/assets/models/DiningTable/23372/textured_objs/original-20.obj" />/&gt;
			</geometry>
		</visual>
		<visual name="back_panel-9">
			<origin xyz="0 0 0" />
			<geometry>
				<mesh filename="/home/blake/kitchen-worlds/assets/models/DiningTable/23372/textured_objs/original-49.obj" />/&gt;
			</geometry>
		</visual>
		<visual name="back_panel-9">
			<origin xyz="0 0 0" />
			<geometry>
				<mesh filename="/home/blake/kitchen-worlds/assets/models/DiningTable/23372/textured_objs/original-47.obj" />/&gt;
			</geometry>
		</visual>
		<visual name="vertical_side_panel-10">
			<origin xyz="0 0 0" />
			<geometry>
				<mesh filename="/home/blake/kitchen-worlds/assets/models/DiningTable/23372/textured_objs/original-6.obj" />/&gt;
			</geometry>
		</visual>
		<visual name="vertical_side_panel-10">
			<origin xyz="0 0 0" />
			<geometry>
				<mesh filename="/home/blake/kitchen-worlds/assets/models/DiningTable/23372/textured_objs/original-2.obj" />/&gt;
			</geometry>
		</visual>
		<visual name="vertical_side_panel-10">
			<origin xyz="0 0 0" />
			<geometry>
				<mesh filename="/home/blake/kitchen-worlds/assets/models/DiningTable/23372/textured_objs/original-4.obj" />/&gt;
			</geometry>
		</visual>
		<visual name="vertical_side_panel-11">
			<origin xyz="0 0 0" />
			<geometry>
				<mesh filename="/home/blake/kitchen-worlds/assets/models/DiningTable/23372/textured_objs/original-5.obj" />/&gt;
			</geometry>
		</visual>
		<visual name="vertical_side_panel-11">
			<origin xyz="0 0 0" />
			<geometry>
				<mesh filename="/home/blake/kitchen-worlds/assets/models/DiningTable/23372/textured_objs/original-8.obj" />/&gt;
			</geometry>
		</visual>
		<visual name="vertical_side_panel-11">
			<origin xyz="0 0 0" />
			<geometry>
				<mesh filename="/home/blake/kitchen-worlds/assets/models/DiningTable/23372/textured_objs/original-3.obj" />/&gt;
			</geometry>
		</visual>
		<visual name="bottom_panel-12">
			<origin xyz="0 0 0" />
			<geometry>
				<mesh filename="/home/blake/kitchen-worlds/assets/models/DiningTable/23372/textured_objs/original-13.obj" />/&gt;
			</geometry>
		</visual>
		<visual name="bottom_panel-12">
			<origin xyz="0 0 0" />
			<geometry>
				<mesh filename="/home/blake/kitchen-worlds/assets/models/DiningTable/23372/textured_objs/original-51.obj" />/&gt;
			</geometry>
		</visual>
		<visual name="bottom_panel-12">
			<origin xyz="0 0 0" />
			<geometry>
				<mesh filename="/home/blake/kitchen-worlds/assets/models/DiningTable/23372/textured_objs/original-12.obj" />/&gt;
			</geometry>
		</visual>
		<visual name="bottom_panel-12">
			<origin xyz="0 0 0" />
			<geometry>
				<mesh filename="/home/blake/kitchen-worlds/assets/models/DiningTable/23372/textured_objs/original-48.obj" />/&gt;
			</geometry>
		</visual>
		<visual name="bottom_panel-12">
			<origin xyz="0 0 0" />
			<geometry>
				<mesh filename="/home/blake/kitchen-worlds/assets/models/DiningTable/23372/textured_objs/original-11.obj" />/&gt;
			</geometry>
		</visual>
		<visual name="leg-13">
			<origin xyz="0 0 0" />
			<geometry>
				<mesh filename="/home/blake/kitchen-worlds/assets/models/DiningTable/23372/textured_objs/original-17.obj" />/&gt;
			</geometry>
		</visual>
		<visual name="leg-14">
			<origin xyz="0 0 0" />
			<geometry>
				<mesh filename="/home/blake/kitchen-worlds/assets/models/DiningTable/23372/textured_objs/original-16.obj" />/&gt;
			</geometry>
		</visual>
		<visual name="leg-15">
			<origin xyz="0 0 0" />
			<geometry>
				<mesh filename="/home/blake/kitchen-worlds/assets/models/DiningTable/23372/textured_objs/original-14.obj" />/&gt;
			</geometry>
		</visual>
		<visual name="leg-16">
			<origin xyz="0 0 0" />
			<geometry>
				<mesh filename="/home/blake/kitchen-worlds/assets/models/DiningTable/23372/textured_objs/original-15.obj" />/&gt;
			</geometry>
		</visual>
		<visual name="bar_stretcher-27">
			<origin xyz="0 0 0" />
			<geometry>
				<mesh filename="/home/blake/kitchen-worlds/assets/models/DiningTable/23372/textured_objs/original-19.obj" />/&gt;
			</geometry>
		</visual>
		<visual name="bar_stretcher-28">
			<origin xyz="0 0 0" />
			<geometry>
				<mesh filename="/home/blake/kitchen-worlds/assets/models/DiningTable/23372/textured_objs/original-22.obj" />/&gt;
			</geometry>
		</visual>
		<visual name="bar_stretcher-29">
			<origin xyz="0 0 0" />
			<geometry>
				<mesh filename="/home/blake/kitchen-worlds/assets/models/DiningTable/23372/textured_objs/original-18.obj" />/&gt;
			</geometry>
		</visual>
		<visual name="bar_stretcher-30">
			<origin xyz="0 0 0" />
			<geometry>
				<mesh filename="/home/blake/kitchen-worlds/assets/models/DiningTable/23372/textured_objs/original-52.obj" />/&gt;
			</geometry>
		</visual>
		<visual name="vertical_side_panel-35">
			<origin xyz="0 0 0" />
			<geometry>
				<mesh filename="/home/blake/kitchen-worlds/assets/models/DiningTable/23372/textured_objs/original-10.obj" />/&gt;
			</geometry>
		</visual>
		<visual name="vertical_side_panel-36">
			<origin xyz="0 0 0" />
			<geometry>
				<mesh filename="/home/blake/kitchen-worlds/assets/models/DiningTable/23372/textured_objs/original-9.obj" />/&gt;
			</geometry>
		</visual>
		<visual name="bottom_panel-37">
			<origin xyz="0 0 0" />
			<geometry>
				<mesh filename="/home/blake/kitchen-worlds/assets/models/DiningTable/23372/textured_objs/original-21.obj" />/&gt;
			</geometry>
		</visual>
		<visual name="bottom_panel-38">
			<origin xyz="0 0 0" />
			<geometry>
				<mesh filename="/home/blake/kitchen-worlds/assets/models/DiningTable/23372/textured_objs/original-1.obj" />/&gt;
			</geometry>
		</visual>
		<collision>
			<origin xyz="0 0 0" />
			<geometry>
				<mesh filename="/home/blake/kitchen-worlds/assets/models/DiningTable/23372/textured_objs/original-7.obj" />/&gt;
			</geometry>
		</collision>
		<collision>
			<origin xyz="0 0 0" />
			<geometry>
				<mesh filename="/home/blake/kitchen-worlds/assets/models/DiningTable/23372/textured_objs/original-50.obj" />/&gt;
			</geometry>
		</collision>
		<collision>
			<origin xyz="0 0 0" />
			<geometry>
				<mesh filename="/home/blake/kitchen-worlds/assets/models/DiningTable/23372/textured_objs/original-20.obj" />/&gt;
			</geometry>
		</collision>
		<collision>
			<origin xyz="0 0 0" />
			<geometry>
				<mesh filename="/home/blake/kitchen-worlds/assets/models/DiningTable/23372/textured_objs/original-49.obj" />/&gt;
			</geometry>
		</collision>
		<collision>
			<origin xyz="0 0 0" />
			<geometry>
				<mesh filename="/home/blake/kitchen-worlds/assets/models/DiningTable/23372/textured_objs/original-47.obj" />/&gt;
			</geometry>
		</collision>
		<collision>
			<origin xyz="0 0 0" />
			<geometry>
				<mesh filename="/home/blake/kitchen-worlds/assets/models/DiningTable/23372/textured_objs/original-6.obj" />/&gt;
			</geometry>
		</collision>
		<collision>
			<origin xyz="0 0 0" />
			<geometry>
				<mesh filename="/home/blake/kitchen-worlds/assets/models/DiningTable/23372/textured_objs/original-2.obj" />/&gt;
			</geometry>
		</collision>
		<collision>
			<origin xyz="0 0 0" />
			<geometry>
				<mesh filename="/home/blake/kitchen-worlds/assets/models/DiningTable/23372/textured_objs/original-4.obj" />/&gt;
			</geometry>
		</collision>
		<collision>
			<origin xyz="0 0 0" />
			<geometry>
				<mesh filename="/home/blake/kitchen-worlds/assets/models/DiningTable/23372/textured_objs/original-5.obj" />/&gt;
			</geometry>
		</collision>
		<collision>
			<origin xyz="0 0 0" />
			<geometry>
				<mesh filename="/home/blake/kitchen-worlds/assets/models/DiningTable/23372/textured_objs/original-8.obj" />/&gt;
			</geometry>
		</collision>
		<collision>
			<origin xyz="0 0 0" />
			<geometry>
				<mesh filename="/home/blake/kitchen-worlds/assets/models/DiningTable/23372/textured_objs/original-3.obj" />/&gt;
			</geometry>
		</collision>
		<collision>
			<origin xyz="0 0 0" />
			<geometry>
				<mesh filename="/home/blake/kitchen-worlds/assets/models/DiningTable/23372/textured_objs/original-13.obj" />/&gt;
			</geometry>
		</collision>
		<collision>
			<origin xyz="0 0 0" />
			<geometry>
				<mesh filename="/home/blake/kitchen-worlds/assets/models/DiningTable/23372/textured_objs/original-51.obj" />/&gt;
			</geometry>
		</collision>
		<collision>
			<origin xyz="0 0 0" />
			<geometry>
				<mesh filename="/home/blake/kitchen-worlds/assets/models/DiningTable/23372/textured_objs/original-12.obj" />/&gt;
			</geometry>
		</collision>
		<collision>
			<origin xyz="0 0 0" />
			<geometry>
				<mesh filename="/home/blake/kitchen-worlds/assets/models/DiningTable/23372/textured_objs/original-48.obj" />/&gt;
			</geometry>
		</collision>
		<collision>
			<origin xyz="0 0 0" />
			<geometry>
				<mesh filename="/home/blake/kitchen-worlds/assets/models/DiningTable/23372/textured_objs/original-11.obj" />/&gt;
			</geometry>
		</collision>
		<collision>
			<origin xyz="0 0 0" />
			<geometry>
				<mesh filename="/home/blake/kitchen-worlds/assets/models/DiningTable/23372/textured_objs/original-17.obj" />/&gt;
			</geometry>
		</collision>
		<collision>
			<origin xyz="0 0 0" />
			<geometry>
				<mesh filename="/home/blake/kitchen-worlds/assets/models/DiningTable/23372/textured_objs/original-16.obj" />/&gt;
			</geometry>
		</collision>
		<collision>
			<origin xyz="0 0 0" />
			<geometry>
				<mesh filename="/home/blake/kitchen-worlds/assets/models/DiningTable/23372/textured_objs/original-14.obj" />/&gt;
			</geometry>
		</collision>
		<collision>
			<origin xyz="0 0 0" />
			<geometry>
				<mesh filename="/home/blake/kitchen-worlds/assets/models/DiningTable/23372/textured_objs/original-15.obj" />/&gt;
			</geometry>
		</collision>
		<collision>
			<origin xyz="0 0 0" />
			<geometry>
				<mesh filename="/home/blake/kitchen-worlds/assets/models/DiningTable/23372/textured_objs/original-19.obj" />/&gt;
			</geometry>
		</collision>
		<collision>
			<origin xyz="0 0 0" />
			<geometry>
				<mesh filename="/home/blake/kitchen-worlds/assets/models/DiningTable/23372/textured_objs/original-22.obj" />/&gt;
			</geometry>
		</collision>
		<collision>
			<origin xyz="0 0 0" />
			<geometry>
				<mesh filename="/home/blake/kitchen-worlds/assets/models/DiningTable/23372/textured_objs/original-18.obj" />/&gt;
			</geometry>
		</collision>
		<collision>
			<origin xyz="0 0 0" />
			<geometry>
				<mesh filename="/home/blake/kitchen-worlds/assets/models/DiningTable/23372/textured_objs/original-52.obj" />/&gt;
			</geometry>
		</collision>
		<collision>
			<origin xyz="0 0 0" />
			<geometry>
				<mesh filename="/home/blake/kitchen-worlds/assets/models/DiningTable/23372/textured_objs/original-10.obj" />/&gt;
			</geometry>
		</collision>
		<collision>
			<origin xyz="0 0 0" />
			<geometry>
				<mesh filename="/home/blake/kitchen-worlds/assets/models/DiningTable/23372/textured_objs/original-9.obj" />/&gt;
			</geometry>
		</collision>
		<collision>
			<origin xyz="0 0 0" />
			<geometry>
				<mesh filename="/home/blake/kitchen-worlds/assets/models/DiningTable/23372/textured_objs/original-21.obj" />/&gt;
			</geometry>
		</collision>
		<collision>
			<origin xyz="0 0 0" />
			<geometry>
				<mesh filename="/home/blake/kitchen-worlds/assets/models/DiningTable/23372/textured_objs/original-1.obj" />/&gt;
			</geometry>
		</collision>
	</link>
	<joint name="joint_4" type="fixed">
		<origin rpy="1.570796326794897 0 -1.570796326794897" xyz="0 0 0" />
		<child link="link_4" />
		<parent link="base" />
	</joint>
</robot>