<?xml version='1.0' encoding='utf-8'?>
<robot name="partnet_1fde7ce0a20f1502f54e1b6f41fdd78a">
	<link name="base" />

	<link name="handle_link">
		<visual name="lid-1">
			<origin xyz="0 0 0" />
			<geometry>
				<mesh filename="/home/blake/kitchen-worlds/assets/models/BraiserLid/100021/textured_objs/original-10-top.obj" />/&gt;
			</geometry>
			<material name="Transparent">
				<color rgba="1 1 1 0" />
			</material>
		</visual>
		<collision>
			<origin xyz="0 0 0" />
			<geometry>
				<mesh filename="/home/blake/kitchen-worlds/assets/models/BraiserLid/100021/textured_objs/original-10-top.obj" />/&gt;
			</geometry>
			<material name="Transparent">
				<color rgba="1 1 1 0" />
			</material>
		</collision>
	</link>
	<joint name="handle_joint" type="prismatic">
		<origin xyz="0 0 0" />
		<axis xyz="0 1 0" />
		<child link="handle_link" />
		<parent link="link_0" />
		<limit lower="0" upper="0.05" effort="10.0" velocity="1.0" />
	</joint>

	<link name="link_0">
		<visual name="lid-1">
			<origin xyz="0 0 0" />
			<geometry>
				<mesh filename="/home/blake/kitchen-worlds/assets/models/BraiserLid/100021/textured_objs/original-10.obj" />/&gt;
			</geometry>
		</visual>
		<collision>
			<origin xyz="0 0 0" />
			<geometry>
				<mesh filename="/home/blake/kitchen-worlds/assets/models/BraiserLid/100021/textured_objs/original-10-bottom.obj" />/&gt;
			</geometry>
		</collision>
	</link>

	
	<joint name="joint_1" type="fixed">
		
		<origin rpy="1.570796326794897 0 -1.570796326794897" xyz="0 0 0" />
		<child link="link_0" />
		<parent link="base" />
	</joint>
</robot>