<?xml version='1.0' encoding='utf-8'?>
<robot name="partnet_fdc47f5f8dff184830eaaf40a8a562c1">
	<link name="base" />
	<link name="link_0">
		<visual name="lid-19">
			<origin xyz="0.002291089456653725 0 0.014289999999999997" />
			<geometry>
				<mesh filename="/home/blake/kitchen-worlds/assets/models/Medicine/4084/textured_objs/original-1.obj" />/&gt;
			</geometry>
		</visual>
		<collision>
			<origin xyz="0.002291089456653725 0 0.014289999999999997" />
			<geometry>
				<mesh filename="/home/blake/kitchen-worlds/assets/models/Medicine/4084/textured_objs/original-1.obj" />/&gt;
			</geometry>
		</collision>
	</link>
	<joint name="joint_0" type="continuous">
		<origin xyz="0.0 0 0.0" />
		<axis xyz="0 1 0" />
		<child link="link_0" />
		<parent link="link_0_helper" />
	</joint>
	<link name="link_1">
		<visual name="body-13">
			<origin xyz="0 0 0" />
			<geometry>
				<mesh filename="/home/blake/kitchen-worlds/assets/models/Medicine/4084/textured_objs/new-1.obj" />/&gt;
			</geometry>
		</visual>
		<visual name="neck-14">
			<origin xyz="0 0 0" />
			<geometry>
				<mesh filename="/home/blake/kitchen-worlds/assets/models/Medicine/4084/textured_objs/new-3.obj" />/&gt;
			</geometry>
		</visual>
		<visual name="other_leaf-18">
			<origin xyz="0 0 0" />
			<geometry>
				<mesh filename="/home/blake/kitchen-worlds/assets/models/Medicine/4084/textured_objs/original-4.obj" />/&gt;
			</geometry>
		</visual>
		<visual name="other_leaf-18">
			<origin xyz="0 0 0" />
			<geometry>
				<mesh filename="/home/blake/kitchen-worlds/assets/models/Medicine/4084/textured_objs/original-39.obj" />/&gt;
			</geometry>
		</visual>
		<visual name="other_leaf-18">
			<origin xyz="0 0 0" />
			<geometry>
				<mesh filename="/home/blake/kitchen-worlds/assets/models/Medicine/4084/textured_objs/original-18.obj" />/&gt;
			</geometry>
		</visual>
		<visual name="other_leaf-18">
			<origin xyz="0 0 0" />
			<geometry>
				<mesh filename="/home/blake/kitchen-worlds/assets/models/Medicine/4084/textured_objs/original-32.obj" />/&gt;
			</geometry>
		</visual>
		<visual name="other_leaf-18">
			<origin xyz="0 0 0" />
			<geometry>
				<mesh filename="/home/blake/kitchen-worlds/assets/models/Medicine/4084/textured_objs/original-25.obj" />/&gt;
			</geometry>
		</visual>
		<visual name="other_leaf-18">
			<origin xyz="0 0 0" />
			<geometry>
				<mesh filename="/home/blake/kitchen-worlds/assets/models/Medicine/4084/textured_objs/original-11.obj" />/&gt;
			</geometry>
		</visual>
		<collision>
			<origin xyz="0 0 0" />
			<geometry>
				<mesh filename="/home/blake/kitchen-worlds/assets/models/Medicine/4084/textured_objs/new-1.obj" />/&gt;
			</geometry>
		</collision>
		<collision>
			<origin xyz="0 0 0" />
			<geometry>
				<mesh filename="/home/blake/kitchen-worlds/assets/models/Medicine/4084/textured_objs/new-3.obj" />/&gt;
			</geometry>
		</collision>
		<collision>
			<origin xyz="0 0 0" />
			<geometry>
				<mesh filename="/home/blake/kitchen-worlds/assets/models/Medicine/4084/textured_objs/original-4.obj" />/&gt;
			</geometry>
		</collision>
		<collision>
			<origin xyz="0 0 0" />
			<geometry>
				<mesh filename="/home/blake/kitchen-worlds/assets/models/Medicine/4084/textured_objs/original-39.obj" />/&gt;
			</geometry>
		</collision>
		<collision>
			<origin xyz="0 0 0" />
			<geometry>
				<mesh filename="/home/blake/kitchen-worlds/assets/models/Medicine/4084/textured_objs/original-18.obj" />/&gt;
			</geometry>
		</collision>
		<collision>
			<origin xyz="0 0 0" />
			<geometry>
				<mesh filename="/home/blake/kitchen-worlds/assets/models/Medicine/4084/textured_objs/original-32.obj" />/&gt;
			</geometry>
		</collision>
		<collision>
			<origin xyz="0 0 0" />
			<geometry>
				<mesh filename="/home/blake/kitchen-worlds/assets/models/Medicine/4084/textured_objs/original-25.obj" />/&gt;
			</geometry>
		</collision>
		<collision>
			<origin xyz="0 0 0" />
			<geometry>
				<mesh filename="/home/blake/kitchen-worlds/assets/models/Medicine/4084/textured_objs/original-11.obj" />/&gt;
			</geometry>
		</collision>
	</link>
	<joint name="joint_1" type="fixed">
		<origin rpy="1.570796326794897 0 -1.570796326794897" xyz="0 0 0" />
		<child link="link_1" />
		<parent link="base" />
	</joint>
	<link name="link_0_helper" />
	<joint name="joint_2" type="prismatic">
		<origin xyz="-0.002291089456653725 0 -0.014289999999999997" />
		<axis xyz="0 1 0" />
		<child link="link_0_helper" />
		<parent link="link_1" />
		<limit lower="-0.06400000000000006" upper="0.2639999999999998" effort="10.0" velocity="1.0" />
	</joint>
</robot>