<?xml version='1.0' encoding='utf-8'?>
<robot name="partnet_6bcdb7c7755840b9e9dcad0af9466535">
	<link name="base" />

	<link name="handle_link">
		<inertial>
	      <origin rpy="0 0 0" xyz="0 0 0" />
	      <mass value="10.0" />
	      <inertia ixx="0.0001" ixy="0" ixz="0" iyy="0.0001" iyz="0" izz="0.0001" />
	    </inertial>
	    <visual name="xx">
	      <geometry>
	        <box size="0.1 0.2 0.02" />
	      </geometry>
	      <material name="White" />
	    </visual>
	    <collision>
	      <geometry>
	        <box size="0.1 0.2 0.02" />
	      </geometry>
	    </collision>
	</link>
	<joint name="handle_joint" type="fixed">
		<origin xyz="0.25 -0.4 0.6" rpy="0 3.489862177 0" />
		<child link="handle_link" />
		<parent link="link_0" />
	</joint>

	<link name="link_0">
		<visual name="door_frame-13">
			<origin xyz="-0.2269176666855262 -0.456948 -0.1669124355111414" />
			<geometry>
				<mesh filename="/home/blake/kitchen-worlds/assets/models/Fridge/10905/textured_objs/original-10.obj" />/&gt;
			</geometry>
		</visual>
		<visual name="door_frame-13">
			<origin xyz="-0.2269176666855262 -0.456948 -0.1669124355111414" />
			<geometry>
				<mesh filename="/home/blake/kitchen-worlds/assets/models/Fridge/10905/textured_objs/new-7.obj" />/&gt;
			</geometry>
		</visual>
		<visual name="door_frame-13">
			<origin xyz="-0.2269176666855262 -0.456948 -0.1669124355111414" />
			<geometry>
				<mesh filename="/home/blake/kitchen-worlds/assets/models/Fridge/10905/textured_objs/new-8.obj" />/&gt;
			</geometry>
		</visual>
		<visual name="other_leaf-15">
			<origin xyz="-0.2269176666855262 -0.456948 -0.1669124355111414" />
			<geometry>
				<mesh filename="/home/blake/kitchen-worlds/assets/models/Fridge/10905/textured_objs/new-9.obj" />/&gt;
			</geometry>
		</visual>
		<visual name="other_leaf-16">
			<origin xyz="-0.2269176666855262 -0.456948 -0.1669124355111414" />
			<geometry>
				<mesh filename="/home/blake/kitchen-worlds/assets/models/Fridge/10905/textured_objs/original-9.obj" />/&gt;
			</geometry>
		</visual>
		<collision>
			<origin xyz="-0.2269176666855262 -0.456948 -0.1669124355111414" />
			<geometry>
				<mesh filename="/home/blake/kitchen-worlds/assets/models/Fridge/10905/textured_objs/original-10.obj" />/&gt;
			</geometry>
		</collision>
		<collision>
			<origin xyz="-0.2269176666855262 -0.456948 -0.1669124355111414" />
			<geometry>
				<mesh filename="/home/blake/kitchen-worlds/assets/models/Fridge/10905/textured_objs/new-7.obj" />/&gt;
			</geometry>
		</collision>
		<collision>
			<origin xyz="-0.2269176666855262 -0.456948 -0.1669124355111414" />
			<geometry>
				<mesh filename="/home/blake/kitchen-worlds/assets/models/Fridge/10905/textured_objs/new-8.obj" />/&gt;
			</geometry>
		</collision>
		<collision>
			<origin xyz="-0.2269176666855262 -0.456948 -0.1669124355111414" />
			<geometry>
				<mesh filename="/home/blake/kitchen-worlds/assets/models/Fridge/10905/textured_objs/new-9.obj" />/&gt;
			</geometry>
		</collision>
		<collision>
			<origin xyz="-0.2269176666855262 -0.456948 -0.1669124355111414" />
			<geometry>
				<mesh filename="/home/blake/kitchen-worlds/assets/models/Fridge/10905/textured_objs/original-9.obj" />/&gt;
			</geometry>
		</collision>
	</link>
	<joint name="joint_0" type="revolute">
		<origin xyz="0.2269176666855262 0.456948 0.1669124355111414" />
		<axis xyz="0 1 0" />
		<child link="link_0" />
		<parent link="link_1" />
		<limit lower="-1.9198621771937625" upper="1.0471975511965976" effort="10.0" velocity="1.0" />
	</joint>
	<link name="link_1">
		<visual name="surface-9">
			<origin xyz="0 0 0" />
			<geometry>
				<mesh filename="/home/blake/kitchen-worlds/assets/models/Fridge/10905/textured_objs/new-2.obj" />/&gt;
			</geometry>
		</visual>
		<visual name="frame-10">
			<origin xyz="0 0 0" />
			<geometry>
				<mesh filename="/home/blake/kitchen-worlds/assets/models/Fridge/10905/textured_objs/new-6.obj" />/&gt;
			</geometry>
		</visual>
		<visual name="frame-10">
			<origin xyz="0 0 0" />
			<geometry>
				<mesh filename="/home/blake/kitchen-worlds/assets/models/Fridge/10905/textured_objs/original-3.obj" />/&gt;
			</geometry>
		</visual>
		<visual name="frame-10">
			<origin xyz="0 0 0" />
			<geometry>
				<mesh filename="/home/blake/kitchen-worlds/assets/models/Fridge/10905/textured_objs/original-2.obj" />/&gt;
			</geometry>
		</visual>
		<visual name="other_leaf-6">
			<origin xyz="0 0 0" />
			<geometry>
				<mesh filename="/home/blake/kitchen-worlds/assets/models/Fridge/10905/textured_objs/new-1.obj" />/&gt;
			</geometry>
		</visual>
		<visual name="other_leaf-7">
			<origin xyz="0 0 0" />
			<geometry>
				<mesh filename="/home/blake/kitchen-worlds/assets/models/Fridge/10905/textured_objs/new-0.obj" />/&gt;
			</geometry>
		</visual>
		<visual name="shelf-17">
			<origin xyz="0 0 0" />
			<geometry>
				<mesh filename="/home/blake/kitchen-worlds/assets/models/Fridge/10905/textured_objs/new-3.obj" />/&gt;
			</geometry>
		</visual>
		<visual name="shelf-18">
			<origin xyz="0 0 0" />
			<geometry>
				<mesh filename="/home/blake/kitchen-worlds/assets/models/Fridge/10905/textured_objs/new-4.obj" />/&gt;
			</geometry>
		</visual>
		<visual name="other_leaf-20">
			<origin xyz="0 0 0" />
			<geometry>
				<mesh filename="/home/blake/kitchen-worlds/assets/models/Fridge/10905/textured_objs/new-5.obj" />/&gt;
			</geometry>
		</visual>
		<visual name="other_leaf-20">
			<origin xyz="0 0 0" />
			<geometry>
				<mesh filename="/home/blake/kitchen-worlds/assets/models/Fridge/10905/textured_objs/original-6.obj" />/&gt;
			</geometry>
		</visual>
		<collision>
			<origin xyz="0 0 0" />
			<geometry>
				<mesh filename="/home/blake/kitchen-worlds/assets/models/Fridge/10905/textured_objs/new-2.obj" />/&gt;
			</geometry>
		</collision>
		<collision>
			<origin xyz="0 0 0" />
			<geometry>
				<mesh filename="/home/blake/kitchen-worlds/assets/models/Fridge/10905/textured_objs/new-6.obj" />/&gt;
			</geometry>
		</collision>
		<collision>
			<origin xyz="0 0 0" />
			<geometry>
				<mesh filename="/home/blake/kitchen-worlds/assets/models/Fridge/10905/textured_objs/original-3.obj" />/&gt;
			</geometry>
		</collision>
		<collision>
			<origin xyz="0 0 0" />
			<geometry>
				<mesh filename="/home/blake/kitchen-worlds/assets/models/Fridge/10905/textured_objs/original-2.obj" />/&gt;
			</geometry>
		</collision>
		<collision>
			<origin xyz="0 0 0" />
			<geometry>
				<mesh filename="/home/blake/kitchen-worlds/assets/models/Fridge/10905/textured_objs/new-1.obj" />/&gt;
			</geometry>
		</collision>
		<collision>
			<origin xyz="0 0 0" />
			<geometry>
				<mesh filename="/home/blake/kitchen-worlds/assets/models/Fridge/10905/textured_objs/new-0.obj" />/&gt;
			</geometry>
		</collision>
		<collision>
			<origin xyz="0 0 0" />
			<geometry>
				<mesh filename="/home/blake/kitchen-worlds/assets/models/Fridge/10905/textured_objs/new-3.obj" />/&gt;
			</geometry>
		</collision>
		<collision>
			<origin xyz="0 0 0" />
			<geometry>
				<mesh filename="/home/blake/kitchen-worlds/assets/models/Fridge/10905/textured_objs/new-4.obj" />/&gt;
			</geometry>
		</collision>
		<collision>
			<origin xyz="0 0 0" />
			<geometry>
				<mesh filename="/home/blake/kitchen-worlds/assets/models/Fridge/10905/textured_objs/new-5.obj" />/&gt;
			</geometry>
		</collision>
		<collision>
			<origin xyz="0 0 0" />
			<geometry>
				<mesh filename="/home/blake/kitchen-worlds/assets/models/Fridge/10905/textured_objs/original-6.obj" />/&gt;
			</geometry>
		</collision>
	</link>
	<joint name="joint_1" type="fixed">
		<origin rpy="1.570796326794897 0 -1.570796326794897" xyz="0 0 0" />
		<child link="link_1" />
		<parent link="base" />
	</joint>
</robot>