<?xml version='1.0' encoding='utf-8'?>
<robot name="partnet_c3bb5f3c842a6c2d178e7d331e641179">
	<link name="base" />
	<link name="link_0">
		<visual name="door_frame-6">
			<origin xyz="0.6430403380134146 0.42593899369239807 -0.5477944794777341" />
			<geometry>
				<mesh filename="/home/blake/kitchen-worlds/assets/models/Microwave/7310/textured_objs/original-1.obj" />/&gt;
			</geometry>
		</visual>
		<visual name="door_frame-6">
			<origin xyz="0.6430403380134146 0.42593899369239807 -0.5477944794777341" />
			<geometry>
				<mesh filename="/home/blake/kitchen-worlds/assets/models/Microwave/7310/textured_objs/original-8.obj" />/&gt;
			</geometry>
		</visual>
		<visual name="door_frame-6">
			<origin xyz="0.6430403380134146 0.42593899369239807 -0.5477944794777341" />
			<geometry>
				<mesh filename="/home/blake/kitchen-worlds/assets/models/Microwave/7310/textured_objs/original-16.obj" />/&gt;
			</geometry>
		</visual>
		<visual name="door_frame-6">
			<origin xyz="0.6430403380134146 0.42593899369239807 -0.5477944794777341" />
			<geometry>
				<mesh filename="/home/blake/kitchen-worlds/assets/models/Microwave/7310/textured_objs/original-9.obj" />/&gt;
			</geometry>
		</visual>
		<visual name="door_frame-6">
			<origin xyz="0.6430403380134146 0.42593899369239807 -0.5477944794777341" />
			<geometry>
				<mesh filename="/home/blake/kitchen-worlds/assets/models/Microwave/7310/textured_objs/original-10.obj" />/&gt;
			</geometry>
		</visual>
		<visual name="door_frame-6">
			<origin xyz="0.6430403380134146 0.42593899369239807 -0.5477944794777341" />
			<geometry>
				<mesh filename="/home/blake/kitchen-worlds/assets/models/Microwave/7310/textured_objs/original-11.obj" />/&gt;
			</geometry>
		</visual>
		<visual name="door_frame-6">
			<origin xyz="0.6430403380134146 0.42593899369239807 -0.5477944794777341" />
			<geometry>
				<mesh filename="/home/blake/kitchen-worlds/assets/models/Microwave/7310/textured_objs/original-12.obj" />/&gt;
			</geometry>
		</visual>
		<visual name="door_frame-6">
			<origin xyz="0.6430403380134146 0.42593899369239807 -0.5477944794777341" />
			<geometry>
				<mesh filename="/home/blake/kitchen-worlds/assets/models/Microwave/7310/textured_objs/original-13.obj" />/&gt;
			</geometry>
		</visual>
		<visual name="door_frame-6">
			<origin xyz="0.6430403380134146 0.42593899369239807 -0.5477944794777341" />
			<geometry>
				<mesh filename="/home/blake/kitchen-worlds/assets/models/Microwave/7310/textured_objs/original-14.obj" />/&gt;
			</geometry>
		</visual>
		<visual name="door_frame-6">
			<origin xyz="0.6430403380134146 0.42593899369239807 -0.5477944794777341" />
			<geometry>
				<mesh filename="/home/blake/kitchen-worlds/assets/models/Microwave/7310/textured_objs/original-15.obj" />/&gt;
			</geometry>
		</visual>
		<visual name="door_frame-6">
			<origin xyz="0.6430403380134146 0.42593899369239807 -0.5477944794777341" />
			<geometry>
				<mesh filename="/home/blake/kitchen-worlds/assets/models/Microwave/7310/textured_objs/original-3.obj" />/&gt;
			</geometry>
		</visual>
		<visual name="glass-7">
			<origin xyz="0.6430403380134146 0.42593899369239807 -0.5477944794777341" />
			<geometry>
				<mesh filename="/home/blake/kitchen-worlds/assets/models/Microwave/7310/textured_objs/original-6.obj" />/&gt;
			</geometry>
		</visual>
		<visual name="handle-8">
			<origin xyz="0.6430403380134146 0.42593899369239807 -0.5477944794777341" />
			<geometry>
				<mesh filename="/home/blake/kitchen-worlds/assets/models/Microwave/7310/textured_objs/original-18.obj" />/&gt;
			</geometry>
		</visual>
		<visual name="handle-8">
			<origin xyz="0.6430403380134146 0.42593899369239807 -0.5477944794777341" />
			<geometry>
				<mesh filename="/home/blake/kitchen-worlds/assets/models/Microwave/7310/textured_objs/original-20.obj" />/&gt;
			</geometry>
		</visual>
		<visual name="handle-8">
			<origin xyz="0.6430403380134146 0.42593899369239807 -0.5477944794777341" />
			<geometry>
				<mesh filename="/home/blake/kitchen-worlds/assets/models/Microwave/7310/textured_objs/original-19.obj" />/&gt;
			</geometry>
		</visual>
		<collision>
			<origin xyz="0.6430403380134146 0.42593899369239807 -0.5477944794777341" />
			<geometry>
				<mesh filename="/home/blake/kitchen-worlds/assets/models/Microwave/7310/textured_objs/original-1.obj" />/&gt;
			</geometry>
		</collision>
		<collision>
			<origin xyz="0.6430403380134146 0.42593899369239807 -0.5477944794777341" />
			<geometry>
				<mesh filename="/home/blake/kitchen-worlds/assets/models/Microwave/7310/textured_objs/original-8.obj" />/&gt;
			</geometry>
		</collision>
		<collision>
			<origin xyz="0.6430403380134146 0.42593899369239807 -0.5477944794777341" />
			<geometry>
				<mesh filename="/home/blake/kitchen-worlds/assets/models/Microwave/7310/textured_objs/original-16.obj" />/&gt;
			</geometry>
		</collision>
		<collision>
			<origin xyz="0.6430403380134146 0.42593899369239807 -0.5477944794777341" />
			<geometry>
				<mesh filename="/home/blake/kitchen-worlds/assets/models/Microwave/7310/textured_objs/original-9.obj" />/&gt;
			</geometry>
		</collision>
		<collision>
			<origin xyz="0.6430403380134146 0.42593899369239807 -0.5477944794777341" />
			<geometry>
				<mesh filename="/home/blake/kitchen-worlds/assets/models/Microwave/7310/textured_objs/original-10.obj" />/&gt;
			</geometry>
		</collision>
		<collision>
			<origin xyz="0.6430403380134146 0.42593899369239807 -0.5477944794777341" />
			<geometry>
				<mesh filename="/home/blake/kitchen-worlds/assets/models/Microwave/7310/textured_objs/original-11.obj" />/&gt;
			</geometry>
		</collision>
		<collision>
			<origin xyz="0.6430403380134146 0.42593899369239807 -0.5477944794777341" />
			<geometry>
				<mesh filename="/home/blake/kitchen-worlds/assets/models/Microwave/7310/textured_objs/original-12.obj" />/&gt;
			</geometry>
		</collision>
		<collision>
			<origin xyz="0.6430403380134146 0.42593899369239807 -0.5477944794777341" />
			<geometry>
				<mesh filename="/home/blake/kitchen-worlds/assets/models/Microwave/7310/textured_objs/original-13.obj" />/&gt;
			</geometry>
		</collision>
		<collision>
			<origin xyz="0.6430403380134146 0.42593899369239807 -0.5477944794777341" />
			<geometry>
				<mesh filename="/home/blake/kitchen-worlds/assets/models/Microwave/7310/textured_objs/original-14.obj" />/&gt;
			</geometry>
		</collision>
		<collision>
			<origin xyz="0.6430403380134146 0.42593899369239807 -0.5477944794777341" />
			<geometry>
				<mesh filename="/home/blake/kitchen-worlds/assets/models/Microwave/7310/textured_objs/original-15.obj" />/&gt;
			</geometry>
		</collision>
		<collision>
			<origin xyz="0.6430403380134146 0.42593899369239807 -0.5477944794777341" />
			<geometry>
				<mesh filename="/home/blake/kitchen-worlds/assets/models/Microwave/7310/textured_objs/original-3.obj" />/&gt;
			</geometry>
		</collision>
		<collision>
			<origin xyz="0.6430403380134146 0.42593899369239807 -0.5477944794777341" />
			<geometry>
				<mesh filename="/home/blake/kitchen-worlds/assets/models/Microwave/7310/textured_objs/original-6.obj" />/&gt;
			</geometry>
		</collision>
		<collision>
			<origin xyz="0.6430403380134146 0.42593899369239807 -0.5477944794777341" />
			<geometry>
				<mesh filename="/home/blake/kitchen-worlds/assets/models/Microwave/7310/textured_objs/original-18.obj" />/&gt;
			</geometry>
		</collision>
		<collision>
			<origin xyz="0.6430403380134146 0.42593899369239807 -0.5477944794777341" />
			<geometry>
				<mesh filename="/home/blake/kitchen-worlds/assets/models/Microwave/7310/textured_objs/original-20.obj" />/&gt;
			</geometry>
		</collision>
		<collision>
			<origin xyz="0.6430403380134146 0.42593899369239807 -0.5477944794777341" />
			<geometry>
				<mesh filename="/home/blake/kitchen-worlds/assets/models/Microwave/7310/textured_objs/original-19.obj" />/&gt;
			</geometry>
		</collision>
	</link>
	<joint name="joint_0" type="revolute">
		<origin xyz="-0.6430403380134146 -0.42593899369239807 0.5477944794777341" />
		<axis xyz="0 -1 0" />
		<child link="link_0" />
		<parent link="link_1" />
		<limit lower="0.0" upper="1.5707963267948966" effort="10.0" velocity="1.0" />
	</joint>
	<link name="link_1">
		<visual name="frame-2">
			<origin xyz="0 0 0" />
			<geometry>
				<mesh filename="/home/blake/kitchen-worlds/assets/models/Microwave/7310/textured_objs/original-4.obj" />/&gt;
			</geometry>
		</visual>
		<visual name="frame-2">
			<origin xyz="0 0 0" />
			<geometry>
				<mesh filename="/home/blake/kitchen-worlds/assets/models/Microwave/7310/textured_objs/original-2.obj" />/&gt;
			</geometry>
		</visual>
		<visual name="display_panel-5">
			<origin xyz="0 0 0" />
			<geometry>
				<mesh filename="/home/blake/kitchen-worlds/assets/models/Microwave/7310/textured_objs/original-5.obj" />/&gt;
			</geometry>
		</visual>
		<collision>
			<origin xyz="0 0 0" />
			<geometry>
				<mesh filename="/home/blake/kitchen-worlds/assets/models/Microwave/7310/textured_objs/original-4.obj" />/&gt;
			</geometry>
		</collision>
		<collision>
			<origin xyz="0 0 0" />
			<geometry>
				<mesh filename="/home/blake/kitchen-worlds/assets/models/Microwave/7310/textured_objs/original-2.obj" />/&gt;
			</geometry>
		</collision>
		<collision>
			<origin xyz="0 0 0" />
			<geometry>
				<mesh filename="/home/blake/kitchen-worlds/assets/models/Microwave/7310/textured_objs/original-5.obj" />/&gt;
			</geometry>
		</collision>
	</link>
	<joint name="joint_1" type="fixed">
		<origin rpy="1.570796326794897 0 -1.570796326794897" xyz="0 0 0" />
		<child link="link_1" />
		<parent link="base" />
	</joint>
</robot>