<?xml version='1.0' encoding='utf-8'?>
<robot name="partnet_3ea1ace396f6ccae48407a54b1fbfda8">
	<link name="base" />

	

	<link name="link_0">
		<visual name="door-1">
			<origin xyz="-0.58423 0.6423879359070063 -0.5040723291093724" />
			<geometry>
				<mesh filename="/home/blake/kitchen-worlds/assets/models/OvenCounter/101773/textured_objs/original-48.obj" />/&gt;
			</geometry>
		</visual>
		<visual name="door-1">
			<origin xyz="-0.58423 0.6423879359070063 -0.5040723291093724" />
			<geometry>
				<mesh filename="/home/blake/kitchen-worlds/assets/models/OvenCounter/101773/textured_objs/original-54.obj" />/&gt;
			</geometry>
		</visual>
		<visual name="door-1">
			<origin xyz="-0.58423 0.6423879359070063 -0.5040723291093724" />
			<geometry>
				<mesh filename="/home/blake/kitchen-worlds/assets/models/OvenCounter/101773/textured_objs/original-53.obj" />/&gt;
			</geometry>
		</visual>
		<visual name="door-1">
			<origin xyz="-0.58423 0.6423879359070063 -0.5040723291093724" />
			<geometry>
				<mesh filename="/home/blake/kitchen-worlds/assets/models/OvenCounter/101773/textured_objs/original-52.obj" />/&gt;
			</geometry>
		</visual>
		<visual name="door-1">
			<origin xyz="-0.58423 0.6423879359070063 -0.5040723291093724" />
			<geometry>
				<mesh filename="/home/blake/kitchen-worlds/assets/models/OvenCounter/101773/textured_objs/original-3.obj" />/&gt;
			</geometry>
		</visual>
		<visual name="door-1">
			<origin xyz="-0.58423 0.6423879359070063 -0.5040723291093724" />
			<geometry>
				<mesh filename="/home/blake/kitchen-worlds/assets/models/OvenCounter/101773/textured_objs/original-49.obj" />/&gt;
			</geometry>
		</visual>
		<collision>
			<origin xyz="-0.58423 0.6423879359070063 -0.5040723291093724" />
			<geometry>
				<mesh filename="/home/blake/kitchen-worlds/assets/models/OvenCounter/101773/textured_objs/original-48.obj" />/&gt;
			</geometry>
		</collision>
		<collision>
			<origin xyz="-0.58423 0.6423879359070063 -0.5040723291093724" />
			<geometry>
				<mesh filename="/home/blake/kitchen-worlds/assets/models/OvenCounter/101773/textured_objs/original-54.obj" />/&gt;
			</geometry>
		</collision>
		<collision>
			<origin xyz="-0.58423 0.6423879359070063 -0.5040723291093724" />
			<geometry>
				<mesh filename="/home/blake/kitchen-worlds/assets/models/OvenCounter/101773/textured_objs/original-53.obj" />/&gt;
			</geometry>
		</collision>
		<collision>
			<origin xyz="-0.58423 0.6423879359070063 -0.5040723291093724" />
			<geometry>
				<mesh filename="/home/blake/kitchen-worlds/assets/models/OvenCounter/101773/textured_objs/original-52.obj" />/&gt;
			</geometry>
		</collision>
		<collision>
			<origin xyz="-0.58423 0.6423879359070063 -0.5040723291093724" />
			<geometry>
				<mesh filename="/home/blake/kitchen-worlds/assets/models/OvenCounter/101773/textured_objs/original-3.obj" />/&gt;
			</geometry>
		</collision>
		<collision>
			<origin xyz="-0.58423 0.6423879359070063 -0.5040723291093724" />
			<geometry>
				<mesh filename="/home/blake/kitchen-worlds/assets/models/OvenCounter/101773/textured_objs/original-49.obj" />/&gt;
			</geometry>
		</collision>
	</link>
	<joint name="joint_0" type="revolute">
		<origin xyz="0.58423 -0.6423879359070063 0.5040723291093724" />
		<axis xyz="1 0 0" />
		<child link="link_0" />
		<parent link="link_9" />
		<limit lower="0.0" upper="1.5707963267948966" effort="10.0" velocity="1.0" />
	</joint>
	<link name="link_1">
		<visual name="knob-2">
			<origin xyz="0.48916950000000003 -0.5199065 0" />
			<geometry>
				<mesh filename="/home/blake/kitchen-worlds/assets/models/OvenCounter/101773/textured_objs/original-9.obj" />/&gt;
			</geometry>
		</visual>
		<collision>
			<origin xyz="0.48916950000000003 -0.5199065 0" />
			<geometry>
				<mesh filename="/home/blake/kitchen-worlds/assets/models/OvenCounter/101773/textured_objs/original-9.obj" />/&gt;
			</geometry>
		</collision>
	</link>
	<joint name="joint_1" type="continuous">
		<origin xyz="-0.48916950000000003 0.5199065 0" />
		<axis xyz="0 0 1" />
		<child link="link_1" />
		<parent link="link_9" />
	</joint>
	<link name="link_2">
		<visual name="knob-3">
			<origin xyz="0.37333099999999997 -0.5199065 0" />
			<geometry>
				<mesh filename="/home/blake/kitchen-worlds/assets/models/OvenCounter/101773/textured_objs/original-12.obj" />/&gt;
			</geometry>
		</visual>
		<collision>
			<origin xyz="0.37333099999999997 -0.5199065 0" />
			<geometry>
				<mesh filename="/home/blake/kitchen-worlds/assets/models/OvenCounter/101773/textured_objs/original-12.obj" />/&gt;
			</geometry>
		</collision>
	</link>
	<joint name="joint_2" type="continuous">
		<origin xyz="-0.37333099999999997 0.5199065 0" />
		<axis xyz="0 0 1" />
		<child link="link_2" />
		<parent link="link_9" />
	</joint>
	<link name="link_3">
		<visual name="knob-4">
			<origin xyz="0.25749299999999997 -0.5199065 0" />
			<geometry>
				<mesh filename="/home/blake/kitchen-worlds/assets/models/OvenCounter/101773/textured_objs/original-15.obj" />/&gt;
			</geometry>
		</visual>
		<collision>
			<origin xyz="0.25749299999999997 -0.5199065 0" />
			<geometry>
				<mesh filename="/home/blake/kitchen-worlds/assets/models/OvenCounter/101773/textured_objs/original-15.obj" />/&gt;
			</geometry>
		</collision>
	</link>
	<joint name="joint_3" type="continuous">
		<origin xyz="-0.25749299999999997 0.5199065 0" />
		<axis xyz="0 0 1" />
		<child link="link_3" />
		<parent link="link_9" />
	</joint>
	<link name="link_4">
		<visual name="button-5">
			<origin xyz="0.076329 -0.518193 0" />
			<geometry>
				<mesh filename="/home/blake/kitchen-worlds/assets/models/OvenCounter/101773/textured_objs/original-101.obj" />/&gt;
			</geometry>
		</visual>
		<collision>
			<origin xyz="0.076329 -0.518193 0" />
			<geometry>
				<mesh filename="/home/blake/kitchen-worlds/assets/models/OvenCounter/101773/textured_objs/original-101.obj" />/&gt;
			</geometry>
		</collision>
	</link>
	<joint name="joint_4" type="prismatic">
		<origin xyz="-0.076329 0.518193 0" />
		<axis xyz="0 0 -1" />
		<child link="link_4" />
		<parent link="link_9" />
		<limit lower="0" upper="0.008000000000000007" effort="10.0" velocity="1.0" />
	</joint>
	<link name="link_5">
		<visual name="button-6">
			<origin xyz="0.076329 -0.518193 0" />
			<geometry>
				<mesh filename="/home/blake/kitchen-worlds/assets/models/OvenCounter/101773/textured_objs/original-102.obj" />/&gt;
			</geometry>
		</visual>
		<collision>
			<origin xyz="0.076329 -0.518193 0" />
			<geometry>
				<mesh filename="/home/blake/kitchen-worlds/assets/models/OvenCounter/101773/textured_objs/original-102.obj" />/&gt;
			</geometry>
		</collision>
	</link>
	<joint name="joint_5" type="prismatic">
		<origin xyz="-0.076329 0.518193 0" />
		<axis xyz="0 0 -1" />
		<child link="link_5" />
		<parent link="link_9" />
		<limit lower="0" upper="0.008000000000000007" effort="10.0" velocity="1.0" />
	</joint>
	<link name="link_6">
		<visual name="button-7">
			<origin xyz="0.076329 -0.518193 0" />
			<geometry>
				<mesh filename="/home/blake/kitchen-worlds/assets/models/OvenCounter/101773/textured_objs/original-109.obj" />/&gt;
			</geometry>
		</visual>
		<collision>
			<origin xyz="0.076329 -0.518193 0" />
			<geometry>
				<mesh filename="/home/blake/kitchen-worlds/assets/models/OvenCounter/101773/textured_objs/original-109.obj" />/&gt;
			</geometry>
		</collision>
	</link>
	<joint name="joint_6" type="prismatic">
		<origin xyz="-0.076329 0.518193 0" />
		<axis xyz="0 0 -1" />
		<child link="link_6" />
		<parent link="link_9" />
		<limit lower="0" upper="0.008000000000000007" effort="10.0" velocity="1.0" />
	</joint>
	<link name="link_7">
		<visual name="button-8">
			<origin xyz="0.076329 -0.518193 0" />
			<geometry>
				<mesh filename="/home/blake/kitchen-worlds/assets/models/OvenCounter/101773/textured_objs/original-100.obj" />/&gt;
			</geometry>
		</visual>
		<collision>
			<origin xyz="0.076329 -0.518193 0" />
			<geometry>
				<mesh filename="/home/blake/kitchen-worlds/assets/models/OvenCounter/101773/textured_objs/original-100.obj" />/&gt;
			</geometry>
		</collision>
	</link>
	<joint name="joint_7" type="prismatic">
		<origin xyz="-0.076329 0.518193 0" />
		<axis xyz="0 0 -1" />
		<child link="link_7" />
		<parent link="link_9" />
		<limit lower="0" upper="0.008000000000000007" effort="10.0" velocity="1.0" />
	</joint>
	<link name="link_8">
		<visual name="button-9">
			<origin xyz="0.076329 -0.518193 0" />
			<geometry>
				<mesh filename="/home/blake/kitchen-worlds/assets/models/OvenCounter/101773/textured_objs/original-107.obj" />/&gt;
			</geometry>
		</visual>
		<collision>
			<origin xyz="0.076329 -0.518193 0" />
			<geometry>
				<mesh filename="/home/blake/kitchen-worlds/assets/models/OvenCounter/101773/textured_objs/original-107.obj" />/&gt;
			</geometry>
		</collision>
	</link>
	<joint name="joint_8" type="prismatic">
		<origin xyz="-0.076329 0.518193 0" />
		<axis xyz="0 0 -1" />
		<child link="link_8" />
		<parent link="link_9" />
		<limit lower="0" upper="0.008000000000000007" effort="10.0" velocity="1.0" />
	</joint>
	<link name="link_9">
		<visual name="base_body-10">
			<origin xyz="0 0 0" />
			<geometry>
				<mesh filename="/home/blake/kitchen-worlds/assets/models/OvenCounter/101773/textured_objs/original-103.obj" />/&gt;
			</geometry>
		</visual>
		<visual name="base_body-10">
			<origin xyz="0 0 0" />
			<geometry>
				<mesh filename="/home/blake/kitchen-worlds/assets/models/OvenCounter/101773/textured_objs/original-21.obj" />/&gt;
			</geometry>
		</visual>
		<visual name="base_body-10">
			<origin xyz="0 0 0" />
			<geometry>
				<mesh filename="/home/blake/kitchen-worlds/assets/models/OvenCounter/101773/textured_objs/original-30.obj" />/&gt;
			</geometry>
		</visual>
		<visual name="base_body-10">
			<origin xyz="0 0 0" />
			<geometry>
				<mesh filename="/home/blake/kitchen-worlds/assets/models/OvenCounter/101773/textured_objs/original-36.obj" />/&gt;
			</geometry>
		</visual>
		<visual name="base_body-10">
			<origin xyz="0 0 0" />
			<geometry>
				<mesh filename="/home/blake/kitchen-worlds/assets/models/OvenCounter/101773/textured_objs/original-28.obj" />/&gt;
			</geometry>
		</visual>
		<visual name="base_body-10">
			<origin xyz="0 0 0" />
			<geometry>
				<mesh filename="/home/blake/kitchen-worlds/assets/models/OvenCounter/101773/textured_objs/original-96.obj" />/&gt;
			</geometry>
		</visual>
		<visual name="base_body-10">
			<origin xyz="0 0 0" />
			<geometry>
				<mesh filename="/home/blake/kitchen-worlds/assets/models/OvenCounter/101773/textured_objs/original-64.obj" />/&gt;
			</geometry>
		</visual>
		<visual name="base_body-10">
			<origin xyz="0 0 0" />
			<geometry>
				<mesh filename="/home/blake/kitchen-worlds/assets/models/OvenCounter/101773/textured_objs/original-43.obj" />/&gt;
			</geometry>
		</visual>
		<visual name="base_body-10">
			<origin xyz="0 0 0" />
			<geometry>
				<mesh filename="/home/blake/kitchen-worlds/assets/models/OvenCounter/101773/textured_objs/original-71.obj" />/&gt;
			</geometry>
		</visual>
		<visual name="base_body-10">
			<origin xyz="0 0 0" />
			<geometry>
				<mesh filename="/home/blake/kitchen-worlds/assets/models/OvenCounter/101773/textured_objs/original-83.obj" />/&gt;
			</geometry>
		</visual>
		<visual name="base_body-10">
			<origin xyz="0 0 0" />
			<geometry>
				<mesh filename="/home/blake/kitchen-worlds/assets/models/OvenCounter/101773/textured_objs/original-22.obj" />/&gt;
			</geometry>
		</visual>
		<visual name="base_body-10">
			<origin xyz="0 0 0" />
			<geometry>
				<mesh filename="/home/blake/kitchen-worlds/assets/models/OvenCounter/101773/textured_objs/original-26.obj" />/&gt;
			</geometry>
		</visual>
		<visual name="base_body-10">
			<origin xyz="0 0 0" />
			<geometry>
				<mesh filename="/home/blake/kitchen-worlds/assets/models/OvenCounter/101773/textured_objs/original-104.obj" />/&gt;
			</geometry>
		</visual>
		<visual name="base_body-10">
			<origin xyz="0 0 0" />
			<geometry>
				<mesh filename="/home/blake/kitchen-worlds/assets/models/OvenCounter/101773/textured_objs/original-65.obj" />/&gt;
			</geometry>
		</visual>
		<visual name="base_body-10">
			<origin xyz="0 0 0" />
			<geometry>
				<mesh filename="/home/blake/kitchen-worlds/assets/models/OvenCounter/101773/textured_objs/original-33.obj" />/&gt;
			</geometry>
		</visual>
		<visual name="base_body-10">
			<origin xyz="0 0 0" />
			<geometry>
				<mesh filename="/home/blake/kitchen-worlds/assets/models/OvenCounter/101773/textured_objs/original-44.obj" />/&gt;
			</geometry>
		</visual>
		<visual name="base_body-10">
			<origin xyz="0 0 0" />
			<geometry>
				<mesh filename="/home/blake/kitchen-worlds/assets/models/OvenCounter/101773/textured_objs/original-106.obj" />/&gt;
			</geometry>
		</visual>
		<visual name="base_body-10">
			<origin xyz="0 0 0" />
			<geometry>
				<mesh filename="/home/blake/kitchen-worlds/assets/models/OvenCounter/101773/textured_objs/original-16.obj" />/&gt;
			</geometry>
		</visual>
		<visual name="base_body-10">
			<origin xyz="0 0 0" />
			<geometry>
				<mesh filename="/home/blake/kitchen-worlds/assets/models/OvenCounter/101773/textured_objs/original-86.obj" />/&gt;
			</geometry>
		</visual>
		<visual name="base_body-10">
			<origin xyz="0 0 0" />
			<geometry>
				<mesh filename="/home/blake/kitchen-worlds/assets/models/OvenCounter/101773/textured_objs/original-13.obj" />/&gt;
			</geometry>
		</visual>
		<visual name="base_body-10">
			<origin xyz="0 0 0" />
			<geometry>
				<mesh filename="/home/blake/kitchen-worlds/assets/models/OvenCounter/101773/textured_objs/original-45.obj" />/&gt;
			</geometry>
		</visual>
		<visual name="base_body-10">
			<origin xyz="0 0 0" />
			<geometry>
				<mesh filename="/home/blake/kitchen-worlds/assets/models/OvenCounter/101773/textured_objs/original-35.obj" />/&gt;
			</geometry>
		</visual>
		<visual name="base_body-10">
			<origin xyz="0 0 0" />
			<geometry>
				<mesh filename="/home/blake/kitchen-worlds/assets/models/OvenCounter/101773/textured_objs/original-93.obj" />/&gt;
			</geometry>
		</visual>
		<visual name="base_body-10">
			<origin xyz="0 0 0" />
			<geometry>
				<mesh filename="/home/blake/kitchen-worlds/assets/models/OvenCounter/101773/textured_objs/original-61.obj" />/&gt;
			</geometry>
		</visual>
		<visual name="base_body-10">
			<origin xyz="0 0 0" />
			<geometry>
				<mesh filename="/home/blake/kitchen-worlds/assets/models/OvenCounter/101773/textured_objs/original-39.obj" />/&gt;
			</geometry>
		</visual>
		<visual name="base_body-10">
			<origin xyz="0 0 0" />
			<geometry>
				<mesh filename="/home/blake/kitchen-worlds/assets/models/OvenCounter/101773/textured_objs/original-59.obj" />/&gt;
			</geometry>
		</visual>
		<visual name="base_body-10">
			<origin xyz="0 0 0" />
			<geometry>
				<mesh filename="/home/blake/kitchen-worlds/assets/models/OvenCounter/101773/textured_objs/original-77.obj" />/&gt;
			</geometry>
		</visual>
		<visual name="base_body-10">
			<origin xyz="0 0 0" />
			<geometry>
				<mesh filename="/home/blake/kitchen-worlds/assets/models/OvenCounter/101773/textured_objs/original-63.obj" />/&gt;
			</geometry>
		</visual>
		<visual name="base_body-10">
			<origin xyz="0 0 0" />
			<geometry>
				<mesh filename="/home/blake/kitchen-worlds/assets/models/OvenCounter/101773/textured_objs/original-27.obj" />/&gt;
			</geometry>
		</visual>
		<visual name="base_body-10">
			<origin xyz="0 0 0" />
			<geometry>
				<mesh filename="/home/blake/kitchen-worlds/assets/models/OvenCounter/101773/textured_objs/original-87.obj" />/&gt;
			</geometry>
		</visual>
		<visual name="base_body-10">
			<origin xyz="0 0 0" />
			<geometry>
				<mesh filename="/home/blake/kitchen-worlds/assets/models/OvenCounter/101773/textured_objs/original-51.obj" />/&gt;
			</geometry>
		</visual>
		<visual name="base_body-10">
			<origin xyz="0 0 0" />
			<geometry>
				<mesh filename="/home/blake/kitchen-worlds/assets/models/OvenCounter/101773/textured_objs/original-55.obj" />/&gt;
			</geometry>
		</visual>
		<visual name="base_body-10">
			<origin xyz="0 0 0" />
			<geometry>
				<mesh filename="/home/blake/kitchen-worlds/assets/models/OvenCounter/101773/textured_objs/original-50.obj" />/&gt;
			</geometry>
		</visual>
		<visual name="base_body-10">
			<origin xyz="0 0 0" />
			<geometry>
				<mesh filename="/home/blake/kitchen-worlds/assets/models/OvenCounter/101773/textured_objs/original-31.obj" />/&gt;
			</geometry>
		</visual>
		<visual name="base_body-10">
			<origin xyz="0 0 0" />
			<geometry>
				<mesh filename="/home/blake/kitchen-worlds/assets/models/OvenCounter/101773/textured_objs/original-85.obj" />/&gt;
			</geometry>
		</visual>
		<visual name="base_body-10">
			<origin xyz="0 0 0" />
			<geometry>
				<mesh filename="/home/blake/kitchen-worlds/assets/models/OvenCounter/101773/textured_objs/original-56.obj" />/&gt;
			</geometry>
		</visual>
		<visual name="base_body-10">
			<origin xyz="0 0 0" />
			<geometry>
				<mesh filename="/home/blake/kitchen-worlds/assets/models/OvenCounter/101773/textured_objs/original-76.obj" />/&gt;
			</geometry>
		</visual>
		<visual name="base_body-10">
			<origin xyz="0 0 0" />
			<geometry>
				<mesh filename="/home/blake/kitchen-worlds/assets/models/OvenCounter/101773/textured_objs/original-108.obj" />/&gt;
			</geometry>
		</visual>
		<visual name="base_body-10">
			<origin xyz="0 0 0" />
			<geometry>
				<mesh filename="/home/blake/kitchen-worlds/assets/models/OvenCounter/101773/textured_objs/original-72.obj" />/&gt;
			</geometry>
		</visual>
		<visual name="base_body-10">
			<origin xyz="0 0 0" />
			<geometry>
				<mesh filename="/home/blake/kitchen-worlds/assets/models/OvenCounter/101773/textured_objs/original-99.obj" />/&gt;
			</geometry>
		</visual>
		<visual name="base_body-10">
			<origin xyz="0 0 0" />
			<geometry>
				<mesh filename="/home/blake/kitchen-worlds/assets/models/OvenCounter/101773/textured_objs/original-62.obj" />/&gt;
			</geometry>
		</visual>
		<visual name="base_body-10">
			<origin xyz="0 0 0" />
			<geometry>
				<mesh filename="/home/blake/kitchen-worlds/assets/models/OvenCounter/101773/textured_objs/original-75.obj" />/&gt;
			</geometry>
		</visual>
		<visual name="base_body-10">
			<origin xyz="0 0 0" />
			<geometry>
				<mesh filename="/home/blake/kitchen-worlds/assets/models/OvenCounter/101773/textured_objs/original-23.obj" />/&gt;
			</geometry>
		</visual>
		<visual name="base_body-10">
			<origin xyz="0 0 0" />
			<geometry>
				<mesh filename="/home/blake/kitchen-worlds/assets/models/OvenCounter/101773/textured_objs/original-66.obj" />/&gt;
			</geometry>
		</visual>
		<visual name="base_body-10">
			<origin xyz="0 0 0" />
			<geometry>
				<mesh filename="/home/blake/kitchen-worlds/assets/models/OvenCounter/101773/textured_objs/original-58.obj" />/&gt;
			</geometry>
		</visual>
		<visual name="base_body-10">
			<origin xyz="0 0 0" />
			<geometry>
				<mesh filename="/home/blake/kitchen-worlds/assets/models/OvenCounter/101773/textured_objs/original-98.obj" />/&gt;
			</geometry>
		</visual>
		<visual name="base_body-10">
			<origin xyz="0 0 0" />
			<geometry>
				<mesh filename="/home/blake/kitchen-worlds/assets/models/OvenCounter/101773/textured_objs/original-67.obj" />/&gt;
			</geometry>
		</visual>
		<visual name="base_body-10">
			<origin xyz="0 0 0" />
			<geometry>
				<mesh filename="/home/blake/kitchen-worlds/assets/models/OvenCounter/101773/textured_objs/original-69.obj" />/&gt;
			</geometry>
		</visual>
		<visual name="base_body-10">
			<origin xyz="0 0 0" />
			<geometry>
				<mesh filename="/home/blake/kitchen-worlds/assets/models/OvenCounter/101773/textured_objs/original-38.obj" />/&gt;
			</geometry>
		</visual>
		<visual name="base_body-10">
			<origin xyz="0 0 0" />
			<geometry>
				<mesh filename="/home/blake/kitchen-worlds/assets/models/OvenCounter/101773/textured_objs/original-68.obj" />/&gt;
			</geometry>
		</visual>
		<visual name="base_body-10">
			<origin xyz="0 0 0" />
			<geometry>
				<mesh filename="/home/blake/kitchen-worlds/assets/models/OvenCounter/101773/textured_objs/original-80.obj" />/&gt;
			</geometry>
		</visual>
		<visual name="base_body-10">
			<origin xyz="0 0 0" />
			<geometry>
				<mesh filename="/home/blake/kitchen-worlds/assets/models/OvenCounter/101773/textured_objs/original-34.obj" />/&gt;
			</geometry>
		</visual>
		<visual name="base_body-10">
			<origin xyz="0 0 0" />
			<geometry>
				<mesh filename="/home/blake/kitchen-worlds/assets/models/OvenCounter/101773/textured_objs/original-18.obj" />/&gt;
			</geometry>
		</visual>
		<visual name="base_body-10">
			<origin xyz="0 0 0" />
			<geometry>
				<mesh filename="/home/blake/kitchen-worlds/assets/models/OvenCounter/101773/textured_objs/original-70.obj" />/&gt;
			</geometry>
		</visual>
		<visual name="base_body-10">
			<origin xyz="0 0 0" />
			<geometry>
				<mesh filename="/home/blake/kitchen-worlds/assets/models/OvenCounter/101773/textured_objs/original-74.obj" />/&gt;
			</geometry>
		</visual>
		<visual name="base_body-10">
			<origin xyz="0 0 0" />
			<geometry>
				<mesh filename="/home/blake/kitchen-worlds/assets/models/OvenCounter/101773/textured_objs/original-91.obj" />/&gt;
			</geometry>
		</visual>
		<visual name="base_body-10">
			<origin xyz="0 0 0" />
			<geometry>
				<mesh filename="/home/blake/kitchen-worlds/assets/models/OvenCounter/101773/textured_objs/original-25.obj" />/&gt;
			</geometry>
		</visual>
		<visual name="base_body-10">
			<origin xyz="0 0 0" />
			<geometry>
				<mesh filename="/home/blake/kitchen-worlds/assets/models/OvenCounter/101773/textured_objs/original-73.obj" />/&gt;
			</geometry>
		</visual>
		<visual name="base_body-10">
			<origin xyz="0 0 0" />
			<geometry>
				<mesh filename="/home/blake/kitchen-worlds/assets/models/OvenCounter/101773/textured_objs/original-92.obj" />/&gt;
			</geometry>
		</visual>
		<visual name="base_body-10">
			<origin xyz="0 0 0" />
			<geometry>
				<mesh filename="/home/blake/kitchen-worlds/assets/models/OvenCounter/101773/textured_objs/original-79.obj" />/&gt;
			</geometry>
		</visual>
		<visual name="base_body-10">
			<origin xyz="0 0 0" />
			<geometry>
				<mesh filename="/home/blake/kitchen-worlds/assets/models/OvenCounter/101773/textured_objs/original-20.obj" />/&gt;
			</geometry>
		</visual>
		<visual name="base_body-10">
			<origin xyz="0 0 0" />
			<geometry>
				<mesh filename="/home/blake/kitchen-worlds/assets/models/OvenCounter/101773/textured_objs/original-88.obj" />/&gt;
			</geometry>
		</visual>
		<visual name="base_body-10">
			<origin xyz="0 0 0" />
			<geometry>
				<mesh filename="/home/blake/kitchen-worlds/assets/models/OvenCounter/101773/textured_objs/original-32.obj" />/&gt;
			</geometry>
		</visual>
		<visual name="base_body-10">
			<origin xyz="0 0 0" />
			<geometry>
				<mesh filename="/home/blake/kitchen-worlds/assets/models/OvenCounter/101773/textured_objs/original-95.obj" />/&gt;
			</geometry>
		</visual>
		<visual name="base_body-10">
			<origin xyz="0 0 0" />
			<geometry>
				<mesh filename="/home/blake/kitchen-worlds/assets/models/OvenCounter/101773/textured_objs/original-105.obj" />/&gt;
			</geometry>
		</visual>
		<visual name="base_body-10">
			<origin xyz="0 0 0" />
			<geometry>
				<mesh filename="/home/blake/kitchen-worlds/assets/models/OvenCounter/101773/textured_objs/original-81.obj" />/&gt;
			</geometry>
		</visual>
		<visual name="base_body-10">
			<origin xyz="0 0 0" />
			<geometry>
				<mesh filename="/home/blake/kitchen-worlds/assets/models/OvenCounter/101773/textured_objs/original-84.obj" />/&gt;
			</geometry>
		</visual>
		<visual name="base_body-10">
			<origin xyz="0 0 0" />
			<geometry>
				<mesh filename="/home/blake/kitchen-worlds/assets/models/OvenCounter/101773/textured_objs/original-94.obj" />/&gt;
			</geometry>
		</visual>
		<visual name="base_body-10">
			<origin xyz="0 0 0" />
			<geometry>
				<mesh filename="/home/blake/kitchen-worlds/assets/models/OvenCounter/101773/textured_objs/original-78.obj" />/&gt;
			</geometry>
		</visual>
		<visual name="base_body-10">
			<origin xyz="0 0 0" />
			<geometry>
				<mesh filename="/home/blake/kitchen-worlds/assets/models/OvenCounter/101773/textured_objs/original-97.obj" />/&gt;
			</geometry>
		</visual>
		<visual name="base_body-10">
			<origin xyz="0 0 0" />
			<geometry>
				<mesh filename="/home/blake/kitchen-worlds/assets/models/OvenCounter/101773/textured_objs/original-89.obj" />/&gt;
			</geometry>
		</visual>
		<visual name="base_body-10">
			<origin xyz="0 0 0" />
			<geometry>
				<mesh filename="/home/blake/kitchen-worlds/assets/models/OvenCounter/101773/textured_objs/original-10.obj" />/&gt;
			</geometry>
		</visual>
		<visual name="base_body-10">
			<origin xyz="0 0 0" />
			<geometry>
				<mesh filename="/home/blake/kitchen-worlds/assets/models/OvenCounter/101773/textured_objs/original-82.obj" />/&gt;
			</geometry>
		</visual>
		<visual name="base_body-10">
			<origin xyz="0 0 0" />
			<geometry>
				<mesh filename="/home/blake/kitchen-worlds/assets/models/OvenCounter/101773/textured_objs/original-60.obj" />/&gt;
			</geometry>
		</visual>
		<visual name="base_body-10">
			<origin xyz="0 0 0" />
			<geometry>
				<mesh filename="/home/blake/kitchen-worlds/assets/models/OvenCounter/101773/textured_objs/original-19.obj" />/&gt;
			</geometry>
		</visual>
		<visual name="base_body-10">
			<origin xyz="0 0 0" />
			<geometry>
				<mesh filename="/home/blake/kitchen-worlds/assets/models/OvenCounter/101773/textured_objs/original-90.obj" />/&gt;
			</geometry>
		</visual>
		<visual name="base_body-10">
			<origin xyz="0 0 0" />
			<geometry>
				<mesh filename="/home/blake/kitchen-worlds/assets/models/OvenCounter/101773/textured_objs/original-40.obj" />/&gt;
			</geometry>
		</visual>
		<visual name="base_body-10">
			<origin xyz="0 0 0" />
			<geometry>
				<mesh filename="/home/blake/kitchen-worlds/assets/models/OvenCounter/101773/textured_objs/original-57.obj" />/&gt;
			</geometry>
		</visual>
		<collision>
			<origin xyz="0 0 0" />
			<geometry>
				<mesh filename="/home/blake/kitchen-worlds/assets/models/OvenCounter/101773/textured_objs/original-103.obj" />/&gt;
			</geometry>
		</collision>
		<collision>
			<origin xyz="0 0 0" />
			<geometry>
				<mesh filename="/home/blake/kitchen-worlds/assets/models/OvenCounter/101773/textured_objs/original-21.obj" />/&gt;
			</geometry>
		</collision>
		<collision>
			<origin xyz="0 0 0" />
			<geometry>
				<mesh filename="/home/blake/kitchen-worlds/assets/models/OvenCounter/101773/textured_objs/original-30.obj" />/&gt;
			</geometry>
		</collision>
		<collision>
			<origin xyz="0 0 0" />
			<geometry>
				<mesh filename="/home/blake/kitchen-worlds/assets/models/OvenCounter/101773/textured_objs/original-36.obj" />/&gt;
			</geometry>
		</collision>
		<collision>
			<origin xyz="0 0 0" />
			<geometry>
				<mesh filename="/home/blake/kitchen-worlds/assets/models/OvenCounter/101773/textured_objs/original-28.obj" />/&gt;
			</geometry>
		</collision>
		<collision>
			<origin xyz="0 0 0" />
			<geometry>
				<mesh filename="/home/blake/kitchen-worlds/assets/models/OvenCounter/101773/textured_objs/original-96.obj" />/&gt;
			</geometry>
		</collision>
		<collision>
			<origin xyz="0 0 0" />
			<geometry>
				<mesh filename="/home/blake/kitchen-worlds/assets/models/OvenCounter/101773/textured_objs/original-64.obj" />/&gt;
			</geometry>
		</collision>
		<collision>
			<origin xyz="0 0 0" />
			<geometry>
				<mesh filename="/home/blake/kitchen-worlds/assets/models/OvenCounter/101773/textured_objs/original-43.obj" />/&gt;
			</geometry>
		</collision>
		<collision>
			<origin xyz="0 0 0" />
			<geometry>
				<mesh filename="/home/blake/kitchen-worlds/assets/models/OvenCounter/101773/textured_objs/original-71.obj" />/&gt;
			</geometry>
		</collision>
		<collision>
			<origin xyz="0 0 0" />
			<geometry>
				<mesh filename="/home/blake/kitchen-worlds/assets/models/OvenCounter/101773/textured_objs/original-83.obj" />/&gt;
			</geometry>
		</collision>
		<collision>
			<origin xyz="0 0 0" />
			<geometry>
				<mesh filename="/home/blake/kitchen-worlds/assets/models/OvenCounter/101773/textured_objs/original-22.obj" />/&gt;
			</geometry>
		</collision>
		<collision>
			<origin xyz="0 0 0" />
			<geometry>
				<mesh filename="/home/blake/kitchen-worlds/assets/models/OvenCounter/101773/textured_objs/original-26.obj" />/&gt;
			</geometry>
		</collision>
		<collision>
			<origin xyz="0 0 0" />
			<geometry>
				<mesh filename="/home/blake/kitchen-worlds/assets/models/OvenCounter/101773/textured_objs/original-104.obj" />/&gt;
			</geometry>
		</collision>
		<collision>
			<origin xyz="0 0 0" />
			<geometry>
				<mesh filename="/home/blake/kitchen-worlds/assets/models/OvenCounter/101773/textured_objs/original-65.obj" />/&gt;
			</geometry>
		</collision>
		<collision>
			<origin xyz="0 0 0" />
			<geometry>
				<mesh filename="/home/blake/kitchen-worlds/assets/models/OvenCounter/101773/textured_objs/original-33.obj" />/&gt;
			</geometry>
		</collision>
		<collision>
			<origin xyz="0 0 0" />
			<geometry>
				<mesh filename="/home/blake/kitchen-worlds/assets/models/OvenCounter/101773/textured_objs/original-44.obj" />/&gt;
			</geometry>
		</collision>
		<collision>
			<origin xyz="0 0 0" />
			<geometry>
				<mesh filename="/home/blake/kitchen-worlds/assets/models/OvenCounter/101773/textured_objs/original-106.obj" />/&gt;
			</geometry>
		</collision>
		<collision>
			<origin xyz="0 0 0" />
			<geometry>
				<mesh filename="/home/blake/kitchen-worlds/assets/models/OvenCounter/101773/textured_objs/original-16.obj" />/&gt;
			</geometry>
		</collision>
		<collision>
			<origin xyz="0 0 0" />
			<geometry>
				<mesh filename="/home/blake/kitchen-worlds/assets/models/OvenCounter/101773/textured_objs/original-86.obj" />/&gt;
			</geometry>
		</collision>
		<collision>
			<origin xyz="0 0 0" />
			<geometry>
				<mesh filename="/home/blake/kitchen-worlds/assets/models/OvenCounter/101773/textured_objs/original-13.obj" />/&gt;
			</geometry>
		</collision>
		<collision>
			<origin xyz="0 0 0" />
			<geometry>
				<mesh filename="/home/blake/kitchen-worlds/assets/models/OvenCounter/101773/textured_objs/original-45.obj" />/&gt;
			</geometry>
		</collision>
		<collision>
			<origin xyz="0 0 0" />
			<geometry>
				<mesh filename="/home/blake/kitchen-worlds/assets/models/OvenCounter/101773/textured_objs/original-35.obj" />/&gt;
			</geometry>
		</collision>
		<collision>
			<origin xyz="0 0 0" />
			<geometry>
				<mesh filename="/home/blake/kitchen-worlds/assets/models/OvenCounter/101773/textured_objs/original-93.obj" />/&gt;
			</geometry>
		</collision>
		<collision>
			<origin xyz="0 0 0" />
			<geometry>
				<mesh filename="/home/blake/kitchen-worlds/assets/models/OvenCounter/101773/textured_objs/original-61.obj" />/&gt;
			</geometry>
		</collision>
		<collision>
			<origin xyz="0 0 0" />
			<geometry>
				<mesh filename="/home/blake/kitchen-worlds/assets/models/OvenCounter/101773/textured_objs/original-39.obj" />/&gt;
			</geometry>
		</collision>
		<collision>
			<origin xyz="0 0 0" />
			<geometry>
				<mesh filename="/home/blake/kitchen-worlds/assets/models/OvenCounter/101773/textured_objs/original-59.obj" />/&gt;
			</geometry>
		</collision>
		<collision>
			<origin xyz="0 0 0" />
			<geometry>
				<mesh filename="/home/blake/kitchen-worlds/assets/models/OvenCounter/101773/textured_objs/original-77.obj" />/&gt;
			</geometry>
		</collision>
		<collision>
			<origin xyz="0 0 0" />
			<geometry>
				<mesh filename="/home/blake/kitchen-worlds/assets/models/OvenCounter/101773/textured_objs/original-63.obj" />/&gt;
			</geometry>
		</collision>
		<collision>
			<origin xyz="0 0 0" />
			<geometry>
				<mesh filename="/home/blake/kitchen-worlds/assets/models/OvenCounter/101773/textured_objs/original-27.obj" />/&gt;
			</geometry>
		</collision>
		<collision>
			<origin xyz="0 0 0" />
			<geometry>
				<mesh filename="/home/blake/kitchen-worlds/assets/models/OvenCounter/101773/textured_objs/original-87.obj" />/&gt;
			</geometry>
		</collision>
		<collision>
			<origin xyz="0 0 0" />
			<geometry>
				<mesh filename="/home/blake/kitchen-worlds/assets/models/OvenCounter/101773/textured_objs/original-51.obj" />/&gt;
			</geometry>
		</collision>
		<collision>
			<origin xyz="0 0 0" />
			<geometry>
				<mesh filename="/home/blake/kitchen-worlds/assets/models/OvenCounter/101773/textured_objs/original-55.obj" />/&gt;
			</geometry>
		</collision>
		<collision>
			<origin xyz="0 0 0" />
			<geometry>
				<mesh filename="/home/blake/kitchen-worlds/assets/models/OvenCounter/101773/textured_objs/original-50.obj" />/&gt;
			</geometry>
		</collision>
		<collision>
			<origin xyz="0 0 0" />
			<geometry>
				<mesh filename="/home/blake/kitchen-worlds/assets/models/OvenCounter/101773/textured_objs/original-31.obj" />/&gt;
			</geometry>
		</collision>
		<collision>
			<origin xyz="0 0 0" />
			<geometry>
				<mesh filename="/home/blake/kitchen-worlds/assets/models/OvenCounter/101773/textured_objs/original-85.obj" />/&gt;
			</geometry>
		</collision>
		<collision>
			<origin xyz="0 0 0" />
			<geometry>
				<mesh filename="/home/blake/kitchen-worlds/assets/models/OvenCounter/101773/textured_objs/original-56.obj" />/&gt;
			</geometry>
		</collision>
		<collision>
			<origin xyz="0 0 0" />
			<geometry>
				<mesh filename="/home/blake/kitchen-worlds/assets/models/OvenCounter/101773/textured_objs/original-76.obj" />/&gt;
			</geometry>
		</collision>
		<collision>
			<origin xyz="0 0 0" />
			<geometry>
				<mesh filename="/home/blake/kitchen-worlds/assets/models/OvenCounter/101773/textured_objs/original-108.obj" />/&gt;
			</geometry>
		</collision>
		<collision>
			<origin xyz="0 0 0" />
			<geometry>
				<mesh filename="/home/blake/kitchen-worlds/assets/models/OvenCounter/101773/textured_objs/original-72.obj" />/&gt;
			</geometry>
		</collision>
		<collision>
			<origin xyz="0 0 0" />
			<geometry>
				<mesh filename="/home/blake/kitchen-worlds/assets/models/OvenCounter/101773/textured_objs/original-99.obj" />/&gt;
			</geometry>
		</collision>
		<collision>
			<origin xyz="0 0 0" />
			<geometry>
				<mesh filename="/home/blake/kitchen-worlds/assets/models/OvenCounter/101773/textured_objs/original-62.obj" />/&gt;
			</geometry>
		</collision>
		<collision>
			<origin xyz="0 0 0" />
			<geometry>
				<mesh filename="/home/blake/kitchen-worlds/assets/models/OvenCounter/101773/textured_objs/original-75.obj" />/&gt;
			</geometry>
		</collision>
		<collision>
			<origin xyz="0 0 0" />
			<geometry>
				<mesh filename="/home/blake/kitchen-worlds/assets/models/OvenCounter/101773/textured_objs/original-23.obj" />/&gt;
			</geometry>
		</collision>
		<collision>
			<origin xyz="0 0 0" />
			<geometry>
				<mesh filename="/home/blake/kitchen-worlds/assets/models/OvenCounter/101773/textured_objs/original-66.obj" />/&gt;
			</geometry>
		</collision>
		<collision>
			<origin xyz="0 0 0" />
			<geometry>
				<mesh filename="/home/blake/kitchen-worlds/assets/models/OvenCounter/101773/textured_objs/original-58.obj" />/&gt;
			</geometry>
		</collision>
		<collision>
			<origin xyz="0 0 0" />
			<geometry>
				<mesh filename="/home/blake/kitchen-worlds/assets/models/OvenCounter/101773/textured_objs/original-98.obj" />/&gt;
			</geometry>
		</collision>
		<collision>
			<origin xyz="0 0 0" />
			<geometry>
				<mesh filename="/home/blake/kitchen-worlds/assets/models/OvenCounter/101773/textured_objs/original-67.obj" />/&gt;
			</geometry>
		</collision>
		<collision>
			<origin xyz="0 0 0" />
			<geometry>
				<mesh filename="/home/blake/kitchen-worlds/assets/models/OvenCounter/101773/textured_objs/original-69.obj" />/&gt;
			</geometry>
		</collision>
		<collision>
			<origin xyz="0 0 0" />
			<geometry>
				<mesh filename="/home/blake/kitchen-worlds/assets/models/OvenCounter/101773/textured_objs/original-38.obj" />/&gt;
			</geometry>
		</collision>
		<collision>
			<origin xyz="0 0 0" />
			<geometry>
				<mesh filename="/home/blake/kitchen-worlds/assets/models/OvenCounter/101773/textured_objs/original-68.obj" />/&gt;
			</geometry>
		</collision>
		<collision>
			<origin xyz="0 0 0" />
			<geometry>
				<mesh filename="/home/blake/kitchen-worlds/assets/models/OvenCounter/101773/textured_objs/original-80.obj" />/&gt;
			</geometry>
		</collision>
		<collision>
			<origin xyz="0 0 0" />
			<geometry>
				<mesh filename="/home/blake/kitchen-worlds/assets/models/OvenCounter/101773/textured_objs/original-34.obj" />/&gt;
			</geometry>
		</collision>
		<collision>
			<origin xyz="0 0 0" />
			<geometry>
				<mesh filename="/home/blake/kitchen-worlds/assets/models/OvenCounter/101773/textured_objs/original-18.obj" />/&gt;
			</geometry>
		</collision>
		<collision>
			<origin xyz="0 0 0" />
			<geometry>
				<mesh filename="/home/blake/kitchen-worlds/assets/models/OvenCounter/101773/textured_objs/original-70.obj" />/&gt;
			</geometry>
		</collision>
		<collision>
			<origin xyz="0 0 0" />
			<geometry>
				<mesh filename="/home/blake/kitchen-worlds/assets/models/OvenCounter/101773/textured_objs/original-74.obj" />/&gt;
			</geometry>
		</collision>
		<collision>
			<origin xyz="0 0 0" />
			<geometry>
				<mesh filename="/home/blake/kitchen-worlds/assets/models/OvenCounter/101773/textured_objs/original-91.obj" />/&gt;
			</geometry>
		</collision>
		<collision>
			<origin xyz="0 0 0" />
			<geometry>
				<mesh filename="/home/blake/kitchen-worlds/assets/models/OvenCounter/101773/textured_objs/original-25.obj" />/&gt;
			</geometry>
		</collision>
		<collision>
			<origin xyz="0 0 0" />
			<geometry>
				<mesh filename="/home/blake/kitchen-worlds/assets/models/OvenCounter/101773/textured_objs/original-73.obj" />/&gt;
			</geometry>
		</collision>
		<collision>
			<origin xyz="0 0 0" />
			<geometry>
				<mesh filename="/home/blake/kitchen-worlds/assets/models/OvenCounter/101773/textured_objs/original-92.obj" />/&gt;
			</geometry>
		</collision>
		<collision>
			<origin xyz="0 0 0" />
			<geometry>
				<mesh filename="/home/blake/kitchen-worlds/assets/models/OvenCounter/101773/textured_objs/original-79.obj" />/&gt;
			</geometry>
		</collision>
		<collision>
			<origin xyz="0 0 0" />
			<geometry>
				<mesh filename="/home/blake/kitchen-worlds/assets/models/OvenCounter/101773/textured_objs/original-20.obj" />/&gt;
			</geometry>
		</collision>
		<collision>
			<origin xyz="0 0 0" />
			<geometry>
				<mesh filename="/home/blake/kitchen-worlds/assets/models/OvenCounter/101773/textured_objs/original-88.obj" />/&gt;
			</geometry>
		</collision>
		<collision>
			<origin xyz="0 0 0" />
			<geometry>
				<mesh filename="/home/blake/kitchen-worlds/assets/models/OvenCounter/101773/textured_objs/original-32.obj" />/&gt;
			</geometry>
		</collision>
		<collision>
			<origin xyz="0 0 0" />
			<geometry>
				<mesh filename="/home/blake/kitchen-worlds/assets/models/OvenCounter/101773/textured_objs/original-95.obj" />/&gt;
			</geometry>
		</collision>
		<collision>
			<origin xyz="0 0 0" />
			<geometry>
				<mesh filename="/home/blake/kitchen-worlds/assets/models/OvenCounter/101773/textured_objs/original-105.obj" />/&gt;
			</geometry>
		</collision>
		<collision>
			<origin xyz="0 0 0" />
			<geometry>
				<mesh filename="/home/blake/kitchen-worlds/assets/models/OvenCounter/101773/textured_objs/original-81.obj" />/&gt;
			</geometry>
		</collision>
		<collision>
			<origin xyz="0 0 0" />
			<geometry>
				<mesh filename="/home/blake/kitchen-worlds/assets/models/OvenCounter/101773/textured_objs/original-84.obj" />/&gt;
			</geometry>
		</collision>
		<collision>
			<origin xyz="0 0 0" />
			<geometry>
				<mesh filename="/home/blake/kitchen-worlds/assets/models/OvenCounter/101773/textured_objs/original-94.obj" />/&gt;
			</geometry>
		</collision>
		<collision>
			<origin xyz="0 0 0" />
			<geometry>
				<mesh filename="/home/blake/kitchen-worlds/assets/models/OvenCounter/101773/textured_objs/original-78.obj" />/&gt;
			</geometry>
		</collision>
		<collision>
			<origin xyz="0 0 0" />
			<geometry>
				<mesh filename="/home/blake/kitchen-worlds/assets/models/OvenCounter/101773/textured_objs/original-97.obj" />/&gt;
			</geometry>
		</collision>
		<collision>
			<origin xyz="0 0 0" />
			<geometry>
				<mesh filename="/home/blake/kitchen-worlds/assets/models/OvenCounter/101773/textured_objs/original-89.obj" />/&gt;
			</geometry>
		</collision>
		<collision>
			<origin xyz="0 0 0" />
			<geometry>
				<mesh filename="/home/blake/kitchen-worlds/assets/models/OvenCounter/101773/textured_objs/original-10.obj" />/&gt;
			</geometry>
		</collision>
		<collision>
			<origin xyz="0 0 0" />
			<geometry>
				<mesh filename="/home/blake/kitchen-worlds/assets/models/OvenCounter/101773/textured_objs/original-82.obj" />/&gt;
			</geometry>
		</collision>
		<collision>
			<origin xyz="0 0 0" />
			<geometry>
				<mesh filename="/home/blake/kitchen-worlds/assets/models/OvenCounter/101773/textured_objs/original-60.obj" />/&gt;
			</geometry>
		</collision>
		<collision>
			<origin xyz="0 0 0" />
			<geometry>
				<mesh filename="/home/blake/kitchen-worlds/assets/models/OvenCounter/101773/textured_objs/original-19.obj" />/&gt;
			</geometry>
		</collision>
		<collision>
			<origin xyz="0 0 0" />
			<geometry>
				<mesh filename="/home/blake/kitchen-worlds/assets/models/OvenCounter/101773/textured_objs/original-90.obj" />/&gt;
			</geometry>
		</collision>
		<collision>
			<origin xyz="0 0 0" />
			<geometry>
				<mesh filename="/home/blake/kitchen-worlds/assets/models/OvenCounter/101773/textured_objs/original-40.obj" />/&gt;
			</geometry>
		</collision>
		<collision>
			<origin xyz="0 0 0" />
			<geometry>
				<mesh filename="/home/blake/kitchen-worlds/assets/models/OvenCounter/101773/textured_objs/original-57.obj" />/&gt;
			</geometry>
		</collision>
	</link>
	<joint name="joint_9" type="fixed">
		<origin rpy="1.570796326794897 0 -1.570796326794897" xyz="0 0 0" />
		<child link="link_9" />
		<parent link="base" />
	</joint>
</robot>