<?xml version='1.0' encoding='utf-8'?>
<robot name="partnet_5b7e61559ed415c6f893b5bc716a3fa">
	<link name="base" />
	<link name="link_0">
		<visual name="switch-8">
			<origin xyz="0.4423510009122008 -0.10507276771144802 0.12431165447847392" />
			<geometry>
				<mesh filename="/home/blake/kitchen-worlds/assets/models/Faucet/929/textured_objs/new-4.obj" />/&gt;
			</geometry>
		</visual>
		<collision>
			<origin xyz="0.4423510009122008 -0.10507276771144802 0.12431165447847392" />
			<geometry>
				<mesh filename="/home/blake/kitchen-worlds/assets/models/Faucet/929/textured_objs/new-4.obj" />/&gt;
			</geometry>
		</collision>
	</link>
	<joint name="joint_0" type="revolute">
		<origin xyz="-0.4423510009122008 0.10507276771144802 -0.12431165447847392" />
		<axis xyz="0 1 0" />
		<child link="link_0" />
		<parent link="link_2" />
		<limit lower="0.0" upper="1.5707963267948966" effort="10.0" velocity="1.0" />
	</joint>
	<link name="link_1">
		<visual name="switch-9">
			<origin xyz="-0.43286950650026546 -0.1053108308939481 0.12779398150907473" />
			<geometry>
				<mesh filename="/home/blake/kitchen-worlds/assets/models/Faucet/929/textured_objs/new-8.obj" />/&gt;
			</geometry>
		</visual>
		<collision>
			<origin xyz="-0.43286950650026546 -0.1053108308939481 0.12779398150907473" />
			<geometry>
				<mesh filename="/home/blake/kitchen-worlds/assets/models/Faucet/929/textured_objs/new-8.obj" />/&gt;
			</geometry>
		</collision>
	</link>
	<joint name="joint_1" type="revolute">
		<origin xyz="0.43286950650026546 0.1053108308939481 -0.12779398150907473" />
		<axis xyz="0 -1 0" />
		<child link="link_1" />
		<parent link="link_2" />
		<limit lower="-0.0" upper="1.5707963267948966" effort="10.0" velocity="1.0" />
	</joint>
	<link name="link_2">
		<visual name="surface_base-11">
			<origin xyz="0 0 0" />
			<geometry>
				<mesh filename="/home/blake/kitchen-worlds/assets/models/Faucet/929/textured_objs/new-11.obj" />/&gt;
			</geometry>
		</visual>
		<visual name="surface_base-11">
			<origin xyz="0 0 0" />
			<geometry>
				<mesh filename="/home/blake/kitchen-worlds/assets/models/Faucet/929/textured_objs/new-10.obj" />/&gt;
			</geometry>
		</visual>
		<visual name="vertical_support-15">
			<origin xyz="0 0 0" />
			<geometry>
				<mesh filename="/home/blake/kitchen-worlds/assets/models/Faucet/929/textured_objs/new-9.obj" />/&gt;
			</geometry>
		</visual>
		<visual name="surface_base-18">
			<origin xyz="0 0 0" />
			<geometry>
				<mesh filename="/home/blake/kitchen-worlds/assets/models/Faucet/929/textured_objs/new-7.obj" />/&gt;
			</geometry>
		</visual>
		<visual name="surface_base-18">
			<origin xyz="0 0 0" />
			<geometry>
				<mesh filename="/home/blake/kitchen-worlds/assets/models/Faucet/929/textured_objs/new-6.obj" />/&gt;
			</geometry>
		</visual>
		<visual name="vertical_support-19">
			<origin xyz="0 0 0" />
			<geometry>
				<mesh filename="/home/blake/kitchen-worlds/assets/models/Faucet/929/textured_objs/new-5.obj" />/&gt;
			</geometry>
		</visual>
		<visual name="vertical_support-21">
			<origin xyz="0 0 0" />
			<geometry>
				<mesh filename="/home/blake/kitchen-worlds/assets/models/Faucet/929/textured_objs/new-3.obj" />/&gt;
			</geometry>
		</visual>
		<visual name="tube-5">
			<origin xyz="0 0 0" />
			<geometry>
				<mesh filename="/home/blake/kitchen-worlds/assets/models/Faucet/929/textured_objs/new-2.obj" />/&gt;
			</geometry>
		</visual>
		<visual name="head-6">
			<origin xyz="0 0 0" />
			<geometry>
				<mesh filename="/home/blake/kitchen-worlds/assets/models/Faucet/929/textured_objs/new-1.obj" />/&gt;
			</geometry>
		</visual>
		<visual name="mouth-7">
			<origin xyz="0 0 0" />
			<geometry>
				<mesh filename="/home/blake/kitchen-worlds/assets/models/Faucet/929/textured_objs/new-0.obj" />/&gt;
			</geometry>
		</visual>
		<collision>
			<origin xyz="0 0 0" />
			<geometry>
				<mesh filename="/home/blake/kitchen-worlds/assets/models/Faucet/929/textured_objs/new-11.obj" />/&gt;
			</geometry>
		</collision>
		<collision>
			<origin xyz="0 0 0" />
			<geometry>
				<mesh filename="/home/blake/kitchen-worlds/assets/models/Faucet/929/textured_objs/new-10.obj" />/&gt;
			</geometry>
		</collision>
		<collision>
			<origin xyz="0 0 0" />
			<geometry>
				<mesh filename="/home/blake/kitchen-worlds/assets/models/Faucet/929/textured_objs/new-9.obj" />/&gt;
			</geometry>
		</collision>
		<collision>
			<origin xyz="0 0 0" />
			<geometry>
				<mesh filename="/home/blake/kitchen-worlds/assets/models/Faucet/929/textured_objs/new-7.obj" />/&gt;
			</geometry>
		</collision>
		<collision>
			<origin xyz="0 0 0" />
			<geometry>
				<mesh filename="/home/blake/kitchen-worlds/assets/models/Faucet/929/textured_objs/new-6.obj" />/&gt;
			</geometry>
		</collision>
		<collision>
			<origin xyz="0 0 0" />
			<geometry>
				<mesh filename="/home/blake/kitchen-worlds/assets/models/Faucet/929/textured_objs/new-5.obj" />/&gt;
			</geometry>
		</collision>
		<collision>
			<origin xyz="0 0 0" />
			<geometry>
				<mesh filename="/home/blake/kitchen-worlds/assets/models/Faucet/929/textured_objs/new-3.obj" />/&gt;
			</geometry>
		</collision>
		<collision>
			<origin xyz="0 0 0" />
			<geometry>
				<mesh filename="/home/blake/kitchen-worlds/assets/models/Faucet/929/textured_objs/new-2.obj" />/&gt;
			</geometry>
		</collision>
		<collision>
			<origin xyz="0 0 0" />
			<geometry>
				<mesh filename="/home/blake/kitchen-worlds/assets/models/Faucet/929/textured_objs/new-1.obj" />/&gt;
			</geometry>
		</collision>
		<collision>
			<origin xyz="0 0 0" />
			<geometry>
				<mesh filename="/home/blake/kitchen-worlds/assets/models/Faucet/929/textured_objs/new-0.obj" />/&gt;
			</geometry>
		</collision>
	</link>
	<joint name="joint_2" type="fixed">
		<origin rpy="1.570796326794897 0 -1.570796326794897" xyz="0 0 0" />
		<child link="link_2" />
		<parent link="base" />
	</joint>
</robot>