<?xml version='1.0' encoding='utf-8'?>
<robot name="partnet_f71397f01cab21ffaff7331733d1f0f5">
	<link name="base"><inertial><mass value="0.1" /><inertia ixx="0.01" iyy="0.01" izz="0.01" ixy="0" ixz="0" iyz="0" /></inertial></link>

	<link name="link_0_handle">
		<visual name="glass-20">
			<origin xyz="-0.2569944013908141 0.7078800201416013 -0.25011729958012885" />
			<geometry>
				<mesh filename="MiniFridge/11709/textured_objs/original-9-fixed.obj"/>
			</geometry>
		</visual>
		<collision>
			<origin xyz="-0.2569944013908141 0.7078800201416013 -0.19011729958012885" />
			<geometry>
				<mesh filename="MiniFridge/11709/textured_objs/original-9-fixed.obj"/>
			</geometry>
		</collision>
	<inertial><mass value="0.1" /><inertia ixx="0.01" iyy="0.01" izz="0.01" ixy="0" ixz="0" iyz="0" /></inertial></link>
	<joint name="joint_0_handle" type="fixed">
		<origin xyz="0 0 0" />
		<axis xyz="0 -1 0" />
		<child link="link_0_handle" />
		<parent link="link_0" />
	</joint>


	<link name="link_1_handle">
		<visual name="glass-19">
			<origin xyz="0.19707658594083446 0.7078800201416016 -0.24847328997979495" />
			<geometry>
				<mesh filename="MiniFridge/11709/textured_objs/original-8-fixed.obj"/>
			</geometry>
		</visual>
		<collision>
			<origin xyz="0.19707658594083446 0.7078800201416016 -0.19847328997979495" />
			<geometry>
				<mesh filename="MiniFridge/11709/textured_objs/original-8-fixed.obj"/>
			</geometry>
		</collision>
	<inertial><mass value="0.1" /><inertia ixx="0.01" iyy="0.01" izz="0.01" ixy="0" ixz="0" iyz="0" /></inertial></link>
	<joint name="joint_1_handle" type="fixed">
		<origin xyz="0 0 0" />
		<axis xyz="0 -1 0" />
		<child link="link_1_handle" />
		<parent link="link_1" />
	</joint>

	<link name="link_2_handle">
		<visual name="glass-18">
			<origin xyz="0.6384173208185699 0.7078800201416015 -0.24279461035976008" />
			<geometry>
				<mesh filename="MiniFridge/11709/textured_objs/original-7-fixed.obj"/>
			</geometry>
		</visual>
		<collision>
			<origin xyz="0.6384173208185699 0.7078800201416015 -0.19279461035976008" />
			<geometry>
				<mesh filename="MiniFridge/11709/textured_objs/original-7-fixed.obj"/>
			</geometry>
		</collision>
	<inertial><mass value="0.1" /><inertia ixx="0.01" iyy="0.01" izz="0.01" ixy="0" ixz="0" iyz="0" /></inertial></link>
	<joint name="joint_2_handle" type="fixed">
		<origin xyz="0 0 0" />
		<axis xyz="0 -1 0" />
		<child link="link_2_handle" />
		<parent link="link_2" />
	</joint>

	


	<link name="link_0">
		<visual name="glass-20">
			<origin xyz="-0.2569944013908141 0.7078800201416013 -0.25011729958012885" />
			<geometry>
				<mesh filename="MiniFridge/11709/textured_objs/original-9.obj"/>
			</geometry>
		</visual>
		<collision>
			<origin xyz="-0.2569944013908141 0.7078800201416013 -0.25011729958012885" />
			<geometry>
				<mesh filename="MiniFridge/11709/textured_objs/original-9.obj"/>
			</geometry>
		</collision>
	<inertial><mass value="0.1" /><inertia ixx="0.01" iyy="0.01" izz="0.01" ixy="0" ixz="0" iyz="0" /></inertial></link>
	<joint name="joint_0" type="revolute">
		<origin xyz="0.2569944013908141 -0.7078800201416013 0.25011729958012885" />
		<axis xyz="0 -1 0" />
		<child link="link_0" />
		<parent link="link_3" />
		<limit lower="0.0" upper="1.5707963267948966" effort="10.0" velocity="1.0" />
	</joint>

	<link name="link_1">
		<visual name="glass-19">
			<origin xyz="0.19707658594083446 0.7078800201416016 -0.24847328997979495" />
			<geometry>
				<mesh filename="MiniFridge/11709/textured_objs/original-8.obj"/>
			</geometry>
		</visual>
		<collision>
			<origin xyz="0.19707658594083446 0.7078800201416016 -0.24847328997979495" />
			<geometry>
				<mesh filename="MiniFridge/11709/textured_objs/original-8.obj"/>
			</geometry>
		</collision>
	<inertial><mass value="0.1" /><inertia ixx="0.01" iyy="0.01" izz="0.01" ixy="0" ixz="0" iyz="0" /></inertial></link>
	<joint name="joint_1" type="revolute">
		<origin xyz="-0.19707658594083446 -0.7078800201416016 0.24847328997979495" />
		<axis xyz="0 -1 0" />
		<child link="link_1" />
		<parent link="link_3" />
		<limit lower="0.0" upper="1.5707963267948966" effort="10.0" velocity="1.0" />
	</joint>

	<link name="link_2">
		<visual name="glass-18">
			<origin xyz="0.6384173208185699 0.7078800201416015 -0.24279461035976008" />
			<geometry>
				<mesh filename="MiniFridge/11709/textured_objs/original-7.obj"/>
			</geometry>
		</visual>
		<collision>
			<origin xyz="0.6384173208185699 0.7078800201416015 -0.24279461035976008" />
			<geometry>
				<mesh filename="MiniFridge/11709/textured_objs/original-7.obj"/>
			</geometry>
		</collision>
	<inertial><mass value="0.1" /><inertia ixx="0.01" iyy="0.01" izz="0.01" ixy="0" ixz="0" iyz="0" /></inertial></link>
	<joint name="joint_2" type="revolute">
		<origin xyz="-0.6384173208185699 -0.7078800201416015 0.24279461035976008" />
		<axis xyz="0 -1 0" />
		<child link="link_2" />
		<parent link="link_3" />
		<limit lower="0.0" upper="1.5707963267948966" effort="10.0" velocity="1.0" />
	</joint>

	

	<link name="link_3">
		<visual name="frame-10">
			<origin xyz="0 0 0" />
			<geometry>
				<mesh filename="MiniFridge/11709/textured_objs/original-128.obj"/>
			</geometry>
		</visual>
		<visual name="foot-4">
			<origin xyz="0 0 0" />
			<geometry>
				<mesh filename="MiniFridge/11709/textured_objs/original-3.obj"/>
			</geometry>
		</visual>
		<visual name="foot-5">
			<origin xyz="0 0 0" />
			<geometry>
				<mesh filename="MiniFridge/11709/textured_objs/original-6.obj"/>
			</geometry>
		</visual>
		<visual name="foot-6">
			<origin xyz="0 0 0" />
			<geometry>
				<mesh filename="MiniFridge/11709/textured_objs/original-2.obj"/>
			</geometry>
		</visual>
		<visual name="foot-7">
			<origin xyz="0 0 0" />
			<geometry>
				<mesh filename="MiniFridge/11709/textured_objs/original-1.obj"/>
			</geometry>
		</visual>
		<visual name="foot-8">
			<origin xyz="0 0 0" />
			<geometry>
				<mesh filename="MiniFridge/11709/textured_objs/original-5.obj"/>
			</geometry>
		</visual>
		<visual name="foot-9">
			<origin xyz="0 0 0" />
			<geometry>
				<mesh filename="MiniFridge/11709/textured_objs/original-4.obj"/>
			</geometry>
		</visual>
		

		

		
		
		


		<collision>
			<origin xyz="0 0 0" />
			<geometry>
				<mesh filename="MiniFridge/11709/textured_objs/original-128-left.obj"/>
			</geometry>
		</collision>
		<collision>
			<origin xyz="0 0 0" />
			<geometry>
				<mesh filename="MiniFridge/11709/textured_objs/original-128-right.obj"/>
			</geometry>
		</collision>
		<collision>
			<origin xyz="0 0 0" />
			<geometry>
				<mesh filename="MiniFridge/11709/textured_objs/original-128-top.obj"/>
			</geometry>
		</collision>
		<collision>
			<origin xyz="0 0 0" />
			<geometry>
				<mesh filename="MiniFridge/11709/textured_objs/original-128-bottom.obj"/>
			</geometry>
		</collision>
		<collision>
			<origin xyz="0 0 0" />
			<geometry>
				<mesh filename="MiniFridge/11709/textured_objs/original-128-back.obj"/>
			</geometry>
		</collision>


		<collision>
			<origin xyz="0 0 0" />
			<geometry>
				<mesh filename="MiniFridge/11709/textured_objs/original-3.obj"/>
			</geometry>
		</collision>
		<collision>
			<origin xyz="0 0 0" />
			<geometry>
				<mesh filename="MiniFridge/11709/textured_objs/original-6.obj"/>
			</geometry>
		</collision>
		<collision>
			<origin xyz="0 0 0" />
			<geometry>
				<mesh filename="MiniFridge/11709/textured_objs/original-2.obj"/>
			</geometry>
		</collision>
		<collision>
			<origin xyz="0 0 0" />
			<geometry>
				<mesh filename="MiniFridge/11709/textured_objs/original-1.obj"/>
			</geometry>
		</collision>
		<collision>
			<origin xyz="0 0 0" />
			<geometry>
				<mesh filename="MiniFridge/11709/textured_objs/original-5.obj"/>
			</geometry>
		</collision>
		<collision>
			<origin xyz="0 0 0" />
			<geometry>
				<mesh filename="MiniFridge/11709/textured_objs/original-4.obj"/>
			</geometry>
		</collision>
		

		

		
		
		
	<inertial><mass value="0.1" /><inertia ixx="0.01" iyy="0.01" izz="0.01" ixy="0" ixz="0" iyz="0" /></inertial></link>
	<joint name="joint_3" type="fixed">
		<origin rpy="1.570796326794897 0 -1.570796326794897" xyz="0 0 0" />
		<child link="link_3" />
		<parent link="base" />
	</joint>
</robot>