<?xml version='1.0' encoding='utf-8'?>
<robot name="partnet_7028b24b7d64efaf3194539af1047dcf">
	<link name="base" />

	<link name="handle">
		<visual name="handle-11">
			<origin xyz="-0.511112457240624 -0.7355 -0.49444429491836783" />
			<geometry>
				<mesh filename="/home/blake/kitchen-worlds/assets/models/MiniFridge/12252/textured_objs/original-16.obj" />/&gt;
			</geometry>
		</visual>
		<collision>
			<origin xyz="-0.511112457240624 -0.7355 -0.49444429491836783" />
			<geometry>
				<mesh filename="/home/blake/kitchen-worlds/assets/models/MiniFridge/12252/textured_objs/original-16.obj" />/&gt;
			</geometry>
		</collision>
	</link>
	<joint name="joint_handle" type="fixed">
		<origin xyz="0 0 0" />
		<axis xyz="0 1 0" />
		<child link="handle" />
		<parent link="link_0" />
	</joint>


	<link name="link_0">
		<visual name="door_frame-10">
			<origin xyz="-0.511112457240624 -0.7355 -0.49444429491836783" />
			<geometry>
				<mesh filename="/home/blake/kitchen-worlds/assets/models/MiniFridge/12252/textured_objs/original-5.obj" />/&gt;
			</geometry>
		</visual>
		<visual name="door_frame-10">
			<origin xyz="-0.511112457240624 -0.7355 -0.49444429491836783" />
			<geometry>
				<mesh filename="/home/blake/kitchen-worlds/assets/models/MiniFridge/12252/textured_objs/original-13.obj" />/&gt;
			</geometry>
		</visual>
		<visual name="door_frame-10">
			<origin xyz="-0.511112457240624 -0.7355 -0.49444429491836783" />
			<geometry>
				<mesh filename="/home/blake/kitchen-worlds/assets/models/MiniFridge/12252/textured_objs/original-4.obj" />/&gt;
			</geometry>
		</visual>
		<visual name="door_frame-10">
			<origin xyz="-0.511112457240624 -0.7355 -0.49444429491836783" />
			<geometry>
				<mesh filename="/home/blake/kitchen-worlds/assets/models/MiniFridge/12252/textured_objs/original-3.obj" />/&gt;
			</geometry>
		</visual>
		<visual name="door_frame-10">
			<origin xyz="-0.511112457240624 -0.7355 -0.49444429491836783" />
			<geometry>
				<mesh filename="/home/blake/kitchen-worlds/assets/models/MiniFridge/12252/textured_objs/original-11.obj" />/&gt;
			</geometry>
		</visual>
		<visual name="door_frame-10">
			<origin xyz="-0.511112457240624 -0.7355 -0.49444429491836783" />
			<geometry>
				<mesh filename="/home/blake/kitchen-worlds/assets/models/MiniFridge/12252/textured_objs/original-12.obj" />/&gt;
			</geometry>
		</visual>
		<visual name="handle-11">
			<origin xyz="-0.511112457240624 -0.7355 -0.49444429491836783" />
			<geometry>
				<mesh filename="/home/blake/kitchen-worlds/assets/models/MiniFridge/12252/textured_objs/original-15.obj" />/&gt;
			</geometry>
		</visual>
		
		<visual name="handle-11">
			<origin xyz="-0.511112457240624 -0.7355 -0.49444429491836783" />
			<geometry>
				<mesh filename="/home/blake/kitchen-worlds/assets/models/MiniFridge/12252/textured_objs/original-14.obj" />/&gt;
			</geometry>
		</visual>
		<collision>
			<origin xyz="-0.511112457240624 -0.7355 -0.49444429491836783" />
			<geometry>
				<mesh filename="/home/blake/kitchen-worlds/assets/models/MiniFridge/12252/textured_objs/original-5.obj" />/&gt;
			</geometry>
		</collision>
		<collision>
			<origin xyz="-0.511112457240624 -0.7355 -0.49444429491836783" />
			<geometry>
				<mesh filename="/home/blake/kitchen-worlds/assets/models/MiniFridge/12252/textured_objs/original-13.obj" />/&gt;
			</geometry>
		</collision>
		<collision>
			<origin xyz="-0.511112457240624 -0.7355 -0.49444429491836783" />
			<geometry>
				<mesh filename="/home/blake/kitchen-worlds/assets/models/MiniFridge/12252/textured_objs/original-4.obj" />/&gt;
			</geometry>
		</collision>
		<collision>
			<origin xyz="-0.511112457240624 -0.7355 -0.49444429491836783" />
			<geometry>
				<mesh filename="/home/blake/kitchen-worlds/assets/models/MiniFridge/12252/textured_objs/original-3.obj" />/&gt;
			</geometry>
		</collision>
		<collision>
			<origin xyz="-0.511112457240624 -0.7355 -0.49444429491836783" />
			<geometry>
				<mesh filename="/home/blake/kitchen-worlds/assets/models/MiniFridge/12252/textured_objs/original-11.obj" />/&gt;
			</geometry>
		</collision>
		<collision>
			<origin xyz="-0.511112457240624 -0.7355 -0.49444429491836783" />
			<geometry>
				<mesh filename="/home/blake/kitchen-worlds/assets/models/MiniFridge/12252/textured_objs/original-12.obj" />/&gt;
			</geometry>
		</collision>
		<collision>
			<origin xyz="-0.511112457240624 -0.7355 -0.49444429491836783" />
			<geometry>
				<mesh filename="/home/blake/kitchen-worlds/assets/models/MiniFridge/12252/textured_objs/original-15.obj" />/&gt;
			</geometry>
		</collision>
		
		<collision>
			<origin xyz="-0.511112457240624 -0.7355 -0.49444429491836783" />
			<geometry>
				<mesh filename="/home/blake/kitchen-worlds/assets/models/MiniFridge/12252/textured_objs/original-14.obj" />/&gt;
			</geometry>
		</collision>
	</link>
	<joint name="joint_0" type="revolute">
		<origin xyz="0.511112457240624 0.7355 0.49444429491836783" />
		<axis xyz="0 1 0" />
		<child link="link_0" />
		<parent link="link_1" />
		<limit lower="-0.0" upper="3.141592653589793" effort="10.0" velocity="1.0" />
	</joint>
	<link name="link_1">
		<visual name="frame-8">
			<origin xyz="0 0 0" />
			<geometry>
				<mesh filename="/home/blake/kitchen-worlds/assets/models/MiniFridge/12252/textured_objs/new-1.obj" />/&gt;
			</geometry>
		</visual>
		<visual name="frame-8">
			<origin xyz="0 0 0" />
			<geometry>
				<mesh filename="/home/blake/kitchen-worlds/assets/models/MiniFridge/12252/textured_objs/new-0.obj" />/&gt;
			</geometry>
		</visual>
		<visual name="foot-12">
			<origin xyz="0 0 0" />
			<geometry>
				<mesh filename="/home/blake/kitchen-worlds/assets/models/MiniFridge/12252/textured_objs/original-19.obj" />/&gt;
			</geometry>
		</visual>
		<visual name="foot-13">
			<origin xyz="0 0 0" />
			<geometry>
				<mesh filename="/home/blake/kitchen-worlds/assets/models/MiniFridge/12252/textured_objs/original-20.obj" />/&gt;
			</geometry>
		</visual>
		<visual name="foot-14">
			<origin xyz="0 0 0" />
			<geometry>
				<mesh filename="/home/blake/kitchen-worlds/assets/models/MiniFridge/12252/textured_objs/original-18.obj" />/&gt;
			</geometry>
		</visual>
		<visual name="foot-15">
			<origin xyz="0 0 0" />
			<geometry>
				<mesh filename="/home/blake/kitchen-worlds/assets/models/MiniFridge/12252/textured_objs/original-17.obj" />/&gt;
			</geometry>
		</visual>
		
		

		<collision>
			<origin xyz="0 0 0" />
			<geometry>
				<mesh filename="/home/blake/kitchen-worlds/assets/models/MiniFridge/12252/textured_objs/new-1-left.obj" />/&gt;
			</geometry>
		</collision>
		<collision>
			<origin xyz="0 0 0" />
			<geometry>
				<mesh filename="/home/blake/kitchen-worlds/assets/models/MiniFridge/12252/textured_objs/new-1-right.obj" />/&gt;
			</geometry>
		</collision>
		<collision>
			<origin xyz="0 0 0" />
			<geometry>
				<mesh filename="/home/blake/kitchen-worlds/assets/models/MiniFridge/12252/textured_objs/new-1-top.obj" />/&gt;
			</geometry>
		</collision>
		<collision>
			<origin xyz="0 0 0" />
			<geometry>
				<mesh filename="/home/blake/kitchen-worlds/assets/models/MiniFridge/12252/textured_objs/new-1-bottom.obj" />/&gt;
			</geometry>
		</collision>
		<collision>
			<origin xyz="0 0 0" />
			<geometry>
				<mesh filename="/home/blake/kitchen-worlds/assets/models/MiniFridge/12252/textured_objs/new-1-back.obj" />/&gt;
			</geometry>
		</collision>
		<collision>
			<origin xyz="0 0 0" />
			<geometry>
				<mesh filename="/home/blake/kitchen-worlds/assets/models/MiniFridge/12252/textured_objs/new-0.obj" />/&gt;
			</geometry>
		</collision>
		<collision>
			<origin xyz="0 0 0" />
			<geometry>
				<mesh filename="/home/blake/kitchen-worlds/assets/models/MiniFridge/12252/textured_objs/original-19.obj" />/&gt;
			</geometry>
		</collision>
		<collision>
			<origin xyz="0 0 0" />
			<geometry>
				<mesh filename="/home/blake/kitchen-worlds/assets/models/MiniFridge/12252/textured_objs/original-20.obj" />/&gt;
			</geometry>
		</collision>
		<collision>
			<origin xyz="0 0 0" />
			<geometry>
				<mesh filename="/home/blake/kitchen-worlds/assets/models/MiniFridge/12252/textured_objs/original-18.obj" />/&gt;
			</geometry>
		</collision>
		<collision>
			<origin xyz="0 0 0" />
			<geometry>
				<mesh filename="/home/blake/kitchen-worlds/assets/models/MiniFridge/12252/textured_objs/original-17.obj" />/&gt;
			</geometry>
		</collision>
	</link>
	<joint name="joint_1" type="fixed">
		<origin rpy="1.570796326794897 0 -1.570796326794897" xyz="0 0 0" />
		<child link="link_1" />
		<parent link="base" />
	</joint>
</robot>