<?xml version='1.0' encoding='utf-8'?>
<robot name="partnet_uadd97420-3888-4be8-89d3-15affc18968d">
	<link name="base" />
	<link name="link_0">
		<visual name="button-4">
			<origin xyz="-0.4436992781385788 -0.5452512270616645 0.15131970855936325" />
			<geometry>
				<mesh filename="/home/blake/kitchen-worlds/assets/models/CoffeeMachine/103127/textured_objs/original-53.obj" />/&gt;
			</geometry>
		</visual>
		<visual name="button-4">
			<origin xyz="-0.4436992781385788 -0.5452512270616645 0.15131970855936325" />
			<geometry>
				<mesh filename="/home/blake/kitchen-worlds/assets/models/CoffeeMachine/103127/textured_objs/original-54.obj" />/&gt;
			</geometry>
		</visual>
		<visual name="button-4">
			<origin xyz="-0.4436992781385788 -0.5452512270616645 0.15131970855936325" />
			<geometry>
				<mesh filename="/home/blake/kitchen-worlds/assets/models/CoffeeMachine/103127/textured_objs/original-55.obj" />/&gt;
			</geometry>
		</visual>
		<visual name="button-4">
			<origin xyz="-0.4436992781385788 -0.5452512270616645 0.15131970855936325" />
			<geometry>
				<mesh filename="/home/blake/kitchen-worlds/assets/models/CoffeeMachine/103127/textured_objs/original-56.obj" />/&gt;
			</geometry>
		</visual>
		<visual name="button-4">
			<origin xyz="-0.4436992781385788 -0.5452512270616645 0.15131970855936325" />
			<geometry>
				<mesh filename="/home/blake/kitchen-worlds/assets/models/CoffeeMachine/103127/textured_objs/original-24.obj" />/&gt;
			</geometry>
		</visual>
		<collision>
			<origin xyz="-0.4436992781385788 -0.5452512270616645 0.15131970855936325" />
			<geometry>
				<mesh filename="/home/blake/kitchen-worlds/assets/models/CoffeeMachine/103127/textured_objs/original-53.obj" />/&gt;
			</geometry>
		</collision>
		<collision>
			<origin xyz="-0.4436992781385788 -0.5452512270616645 0.15131970855936325" />
			<geometry>
				<mesh filename="/home/blake/kitchen-worlds/assets/models/CoffeeMachine/103127/textured_objs/original-54.obj" />/&gt;
			</geometry>
		</collision>
		<collision>
			<origin xyz="-0.4436992781385788 -0.5452512270616645 0.15131970855936325" />
			<geometry>
				<mesh filename="/home/blake/kitchen-worlds/assets/models/CoffeeMachine/103127/textured_objs/original-55.obj" />/&gt;
			</geometry>
		</collision>
		<collision>
			<origin xyz="-0.4436992781385788 -0.5452512270616645 0.15131970855936325" />
			<geometry>
				<mesh filename="/home/blake/kitchen-worlds/assets/models/CoffeeMachine/103127/textured_objs/original-56.obj" />/&gt;
			</geometry>
		</collision>
		<collision>
			<origin xyz="-0.4436992781385788 -0.5452512270616645 0.15131970855936325" />
			<geometry>
				<mesh filename="/home/blake/kitchen-worlds/assets/models/CoffeeMachine/103127/textured_objs/original-24.obj" />/&gt;
			</geometry>
		</collision>
	</link>
	<joint name="joint_0" type="prismatic">
		<origin xyz="0.4436992781385788 0.5452512270616645 -0.15131970855936325" />
		<axis xyz="-0.00013734745514960256 -0.26731207581450983 -0.9636100016393636" />
		<child link="link_0" />
		<parent link="link_4" />
		<limit lower="0" upper="0.008000000000000007" effort="10.0" velocity="1.0" />
	</joint>
	<link name="link_1">
		<visual name="button-5">
			<origin xyz="-0.44372643850484683 -0.43404430929768534 0.12038933277031239" />
			<geometry>
				<mesh filename="/home/blake/kitchen-worlds/assets/models/CoffeeMachine/103127/textured_objs/original-45.obj" />/&gt;
			</geometry>
		</visual>
		<visual name="button-5">
			<origin xyz="-0.44372643850484683 -0.43404430929768534 0.12038933277031239" />
			<geometry>
				<mesh filename="/home/blake/kitchen-worlds/assets/models/CoffeeMachine/103127/textured_objs/original-50.obj" />/&gt;
			</geometry>
		</visual>
		<visual name="button-5">
			<origin xyz="-0.44372643850484683 -0.43404430929768534 0.12038933277031239" />
			<geometry>
				<mesh filename="/home/blake/kitchen-worlds/assets/models/CoffeeMachine/103127/textured_objs/original-49.obj" />/&gt;
			</geometry>
		</visual>
		<visual name="button-5">
			<origin xyz="-0.44372643850484683 -0.43404430929768534 0.12038933277031239" />
			<geometry>
				<mesh filename="/home/blake/kitchen-worlds/assets/models/CoffeeMachine/103127/textured_objs/original-46.obj" />/&gt;
			</geometry>
		</visual>
		<visual name="button-5">
			<origin xyz="-0.44372643850484683 -0.43404430929768534 0.12038933277031239" />
			<geometry>
				<mesh filename="/home/blake/kitchen-worlds/assets/models/CoffeeMachine/103127/textured_objs/original-51.obj" />/&gt;
			</geometry>
		</visual>
		<visual name="button-5">
			<origin xyz="-0.44372643850484683 -0.43404430929768534 0.12038933277031239" />
			<geometry>
				<mesh filename="/home/blake/kitchen-worlds/assets/models/CoffeeMachine/103127/textured_objs/original-47.obj" />/&gt;
			</geometry>
		</visual>
		<visual name="button-5">
			<origin xyz="-0.44372643850484683 -0.43404430929768534 0.12038933277031239" />
			<geometry>
				<mesh filename="/home/blake/kitchen-worlds/assets/models/CoffeeMachine/103127/textured_objs/original-48.obj" />/&gt;
			</geometry>
		</visual>
		<visual name="button-5">
			<origin xyz="-0.44372643850484683 -0.43404430929768534 0.12038933277031239" />
			<geometry>
				<mesh filename="/home/blake/kitchen-worlds/assets/models/CoffeeMachine/103127/textured_objs/original-21.obj" />/&gt;
			</geometry>
		</visual>
		<collision>
			<origin xyz="-0.44372643850484683 -0.43404430929768534 0.12038933277031239" />
			<geometry>
				<mesh filename="/home/blake/kitchen-worlds/assets/models/CoffeeMachine/103127/textured_objs/original-45.obj" />/&gt;
			</geometry>
		</collision>
		<collision>
			<origin xyz="-0.44372643850484683 -0.43404430929768534 0.12038933277031239" />
			<geometry>
				<mesh filename="/home/blake/kitchen-worlds/assets/models/CoffeeMachine/103127/textured_objs/original-50.obj" />/&gt;
			</geometry>
		</collision>
		<collision>
			<origin xyz="-0.44372643850484683 -0.43404430929768534 0.12038933277031239" />
			<geometry>
				<mesh filename="/home/blake/kitchen-worlds/assets/models/CoffeeMachine/103127/textured_objs/original-49.obj" />/&gt;
			</geometry>
		</collision>
		<collision>
			<origin xyz="-0.44372643850484683 -0.43404430929768534 0.12038933277031239" />
			<geometry>
				<mesh filename="/home/blake/kitchen-worlds/assets/models/CoffeeMachine/103127/textured_objs/original-46.obj" />/&gt;
			</geometry>
		</collision>
		<collision>
			<origin xyz="-0.44372643850484683 -0.43404430929768534 0.12038933277031239" />
			<geometry>
				<mesh filename="/home/blake/kitchen-worlds/assets/models/CoffeeMachine/103127/textured_objs/original-51.obj" />/&gt;
			</geometry>
		</collision>
		<collision>
			<origin xyz="-0.44372643850484683 -0.43404430929768534 0.12038933277031239" />
			<geometry>
				<mesh filename="/home/blake/kitchen-worlds/assets/models/CoffeeMachine/103127/textured_objs/original-47.obj" />/&gt;
			</geometry>
		</collision>
		<collision>
			<origin xyz="-0.44372643850484683 -0.43404430929768534 0.12038933277031239" />
			<geometry>
				<mesh filename="/home/blake/kitchen-worlds/assets/models/CoffeeMachine/103127/textured_objs/original-48.obj" />/&gt;
			</geometry>
		</collision>
		<collision>
			<origin xyz="-0.44372643850484683 -0.43404430929768534 0.12038933277031239" />
			<geometry>
				<mesh filename="/home/blake/kitchen-worlds/assets/models/CoffeeMachine/103127/textured_objs/original-21.obj" />/&gt;
			</geometry>
		</collision>
	</link>
	<joint name="joint_1" type="prismatic">
		<origin xyz="0.44372643850484683 0.43404430929768534 -0.12038933277031239" />
		<axis xyz="6.478129607831412e-05 -0.2673373827497395 -0.9636029885735635" />
		<child link="link_1" />
		<parent link="link_4" />
		<limit lower="0" upper="0.008000000000000007" effort="10.0" velocity="1.0" />
	</joint>
	<link name="link_2">
		<visual name="button-6">
			<origin xyz="-0.37374515780952 -0.5452538444351923 0.15131046377688542" />
			<geometry>
				<mesh filename="/home/blake/kitchen-worlds/assets/models/CoffeeMachine/103127/textured_objs/original-14.obj" />/&gt;
			</geometry>
		</visual>
		<collision>
			<origin xyz="-0.37374515780952 -0.5452538444351923 0.15131046377688542" />
			<geometry>
				<mesh filename="/home/blake/kitchen-worlds/assets/models/CoffeeMachine/103127/textured_objs/original-14.obj" />/&gt;
			</geometry>
		</collision>
	</link>
	<joint name="joint_2" type="prismatic">
		<origin xyz="0.37374515780952 0.5452538444351923 -0.15131046377688542" />
		<axis xyz="-0.0001373474551496004 -0.26731207581450983 -0.9636100016393636" />
		<child link="link_2" />
		<parent link="link_4" />
		<limit lower="0" upper="0.008000000000000007" effort="10.0" velocity="1.0" />
	</joint>
	<link name="link_3">
		<visual name="button-7">
			<origin xyz="-0.5136910331753147 -0.5452872779364466 0.15119042588302403" />
			<geometry>
				<mesh filename="/home/blake/kitchen-worlds/assets/models/CoffeeMachine/103127/textured_objs/original-15.obj" />/&gt;
			</geometry>
		</visual>
		<collision>
			<origin xyz="-0.5136910331753147 -0.5452872779364466 0.15119042588302403" />
			<geometry>
				<mesh filename="/home/blake/kitchen-worlds/assets/models/CoffeeMachine/103127/textured_objs/original-15.obj" />/&gt;
			</geometry>
		</collision>
	</link>
	<joint name="joint_3" type="prismatic">
		<origin xyz="0.5136910331753147 0.5452872779364466 -0.15119042588302403" />
		<axis xyz="0.0001426425163397963 -0.2673120756163562 -0.9636100009250568" />
		<child link="link_3" />
		<parent link="link_4" />
		<limit lower="0" upper="0.008000000000000007" effort="10.0" velocity="1.0" />
	</joint>

	<link name="link_4">
		<visual name="base_body-8">
			<origin xyz="0 0 0" />
			<geometry>
				<mesh filename="/home/blake/kitchen-worlds/assets/models/CoffeeMachine/103127/textured_objs/original-29.obj" />/&gt;
			</geometry>
		</visual>
		<visual name="base_body-8">
			<origin xyz="0 0 0" />
			<geometry>
				<mesh filename="/home/blake/kitchen-worlds/assets/models/CoffeeMachine/103127/textured_objs/original-30.obj" />/&gt;
			</geometry>
		</visual>
		<visual name="base_body-8">
			<origin xyz="0 0 0" />
			<geometry>
				<mesh filename="/home/blake/kitchen-worlds/assets/models/CoffeeMachine/103127/textured_objs/original-36.obj" />/&gt;
			</geometry>
		</visual>
		<visual name="base_body-8">
			<origin xyz="0 0 0" />
			<geometry>
				<mesh filename="/home/blake/kitchen-worlds/assets/models/CoffeeMachine/103127/textured_objs/original-41.obj" />/&gt;
			</geometry>
		</visual>
		<visual name="base_body-8">
			<origin xyz="0 0 0" />
			<geometry>
				<mesh filename="/home/blake/kitchen-worlds/assets/models/CoffeeMachine/103127/textured_objs/original-28.obj" />/&gt;
			</geometry>
		</visual>
		<visual name="base_body-8">
			<origin xyz="0 0 0" />
			<geometry>
				<mesh filename="/home/blake/kitchen-worlds/assets/models/CoffeeMachine/103127/textured_objs/original-64.obj" />/&gt;
			</geometry>
		</visual>
		<visual name="base_body-8">
			<origin xyz="0 0 0" />
			<geometry>
				<mesh filename="/home/blake/kitchen-worlds/assets/models/CoffeeMachine/103127/textured_objs/original-43.obj" />/&gt;
			</geometry>
		</visual>
		<visual name="base_body-8">
			<origin xyz="0 0 0" />
			<geometry>
				<mesh filename="/home/blake/kitchen-worlds/assets/models/CoffeeMachine/103127/textured_objs/original-71.obj" />/&gt;
			</geometry>
		</visual>
		<visual name="base_body-8">
			<origin xyz="0 0 0" />
			<geometry>
				<mesh filename="/home/blake/kitchen-worlds/assets/models/CoffeeMachine/103127/textured_objs/original-22.obj" />/&gt;
			</geometry>
		</visual>
		<visual name="base_body-8">
			<origin xyz="0 0 0" />
			<geometry>
				<mesh filename="/home/blake/kitchen-worlds/assets/models/CoffeeMachine/103127/textured_objs/original-26.obj" />/&gt;
			</geometry>
		</visual>
		<visual name="base_body-8">
			<origin xyz="0 0 0" />
			<geometry>
				<mesh filename="/home/blake/kitchen-worlds/assets/models/CoffeeMachine/103127/textured_objs/original-4.obj" />/&gt;
			</geometry>
		</visual>
		<visual name="base_body-8">
			<origin xyz="0 0 0" />
			<geometry>
				<mesh filename="/home/blake/kitchen-worlds/assets/models/CoffeeMachine/103127/textured_objs/original-3.obj" />/&gt;
			</geometry>
		</visual>
		<visual name="base_body-8">
			<origin xyz="0 0 0" />
			<geometry>
				<mesh filename="/home/blake/kitchen-worlds/assets/models/CoffeeMachine/103127/textured_objs/original-65.obj" />/&gt;
			</geometry>
		</visual>
		<visual name="base_body-8">
			<origin xyz="0 0 0" />
			<geometry>
				<mesh filename="/home/blake/kitchen-worlds/assets/models/CoffeeMachine/103127/textured_objs/original-33.obj" />/&gt;
			</geometry>
		</visual>
		<visual name="base_body-8">
			<origin xyz="0 0 0" />
			<geometry>
				<mesh filename="/home/blake/kitchen-worlds/assets/models/CoffeeMachine/103127/textured_objs/original-2.obj" />/&gt;
			</geometry>
		</visual>
		<visual name="base_body-8">
			<origin xyz="0 0 0" />
			<geometry>
				<mesh filename="/home/blake/kitchen-worlds/assets/models/CoffeeMachine/103127/textured_objs/original-16.obj" />/&gt;
			</geometry>
		</visual>
		<visual name="base_body-8">
			<origin xyz="0 0 0" />
			<geometry>
				<mesh filename="/home/blake/kitchen-worlds/assets/models/CoffeeMachine/103127/textured_objs/original-8.obj" />/&gt;
			</geometry>
		</visual>
		<visual name="base_body-8">
			<origin xyz="0 0 0" />
			<geometry>
				<mesh filename="/home/blake/kitchen-worlds/assets/models/CoffeeMachine/103127/textured_objs/original-13.obj" />/&gt;
			</geometry>
		</visual>
		<visual name="base_body-8">
			<origin xyz="0 0 0" />
			<geometry>
				<mesh filename="/home/blake/kitchen-worlds/assets/models/CoffeeMachine/103127/textured_objs/original-9.obj" />/&gt;
			</geometry>
		</visual>
		<visual name="base_body-8">
			<origin xyz="0 0 0" />
			<geometry>
				<mesh filename="/home/blake/kitchen-worlds/assets/models/CoffeeMachine/103127/textured_objs/original-35.obj" />/&gt;
			</geometry>
		</visual>
		<visual name="base_body-8">
			<origin xyz="0 0 0" />
			<geometry>
				<mesh filename="/home/blake/kitchen-worlds/assets/models/CoffeeMachine/103127/textured_objs/original-61.obj" />/&gt;
			</geometry>
		</visual>
		<visual name="base_body-8">
			<origin xyz="0 0 0" />
			<geometry>
				<mesh filename="/home/blake/kitchen-worlds/assets/models/CoffeeMachine/103127/textured_objs/original-39.obj" />/&gt;
			</geometry>
		</visual>
		<visual name="base_body-8">
			<origin xyz="0 0 0" />
			<geometry>
				<mesh filename="/home/blake/kitchen-worlds/assets/models/CoffeeMachine/103127/textured_objs/original-59.obj" />/&gt;
			</geometry>
		</visual>

		<visual name="base_body-8">
			<origin xyz="0 0 0" />
			<geometry>
				<mesh filename="/home/blake/kitchen-worlds/assets/models/CoffeeMachine/103127/textured_objs/original-63.obj" />/&gt;
			</geometry>
		</visual>
		<visual name="base_body-8">
			<origin xyz="0 0 0" />
			<geometry>
				<mesh filename="/home/blake/kitchen-worlds/assets/models/CoffeeMachine/103127/textured_objs/original-27.obj" />/&gt;
			</geometry>
		</visual>
		<visual name="base_body-8">
			<origin xyz="0 0 0" />
			<geometry>
				<mesh filename="/home/blake/kitchen-worlds/assets/models/CoffeeMachine/103127/textured_objs/original-6.obj" />/&gt;
			</geometry>
		</visual>
		<visual name="base_body-8">
			<origin xyz="0 0 0" />
			<geometry>
				<mesh filename="/home/blake/kitchen-worlds/assets/models/CoffeeMachine/103127/textured_objs/original-31.obj" />/&gt;
			</geometry>
		</visual>
		<visual name="base_body-8">
			<origin xyz="0 0 0" />
			<geometry>
				<mesh filename="/home/blake/kitchen-worlds/assets/models/CoffeeMachine/103127/textured_objs/original-37.obj" />/&gt;
			</geometry>
		</visual>
		<visual name="base_body-8">
			<origin xyz="0 0 0" />
			<geometry>
				<mesh filename="/home/blake/kitchen-worlds/assets/models/CoffeeMachine/103127/textured_objs/original-72.obj" />/&gt;
			</geometry>
		</visual>
		<visual name="base_body-8">
			<origin xyz="0 0 0" />
			<geometry>
				<mesh filename="/home/blake/kitchen-worlds/assets/models/CoffeeMachine/103127/textured_objs/original-62.obj" />/&gt;
			</geometry>
		</visual>
		<visual name="base_body-8">
			<origin xyz="0 0 0" />
			<geometry>
				<mesh filename="/home/blake/kitchen-worlds/assets/models/CoffeeMachine/103127/textured_objs/original-23.obj" />/&gt;
			</geometry>
		</visual>
		<visual name="base_body-8">
			<origin xyz="0 0 0" />
			<geometry>
				<mesh filename="/home/blake/kitchen-worlds/assets/models/CoffeeMachine/103127/textured_objs/original-66.obj" />/&gt;
			</geometry>
		</visual>
		<visual name="base_body-8">
			<origin xyz="0 0 0" />
			<geometry>
				<mesh filename="/home/blake/kitchen-worlds/assets/models/CoffeeMachine/103127/textured_objs/original-58.obj" />/&gt;
			</geometry>
		</visual>
		<visual name="base_body-8">
			<origin xyz="0 0 0" />
			<geometry>
				<mesh filename="/home/blake/kitchen-worlds/assets/models/CoffeeMachine/103127/textured_objs/original-67.obj" />/&gt;
			</geometry>
		</visual>
		<visual name="base_body-8">
			<origin xyz="0 0 0" />
			<geometry>
				<mesh filename="/home/blake/kitchen-worlds/assets/models/CoffeeMachine/103127/textured_objs/original-69.obj" />/&gt;
			</geometry>
		</visual>
		<visual name="base_body-8">
			<origin xyz="0 0 0" />
			<geometry>
				<mesh filename="/home/blake/kitchen-worlds/assets/models/CoffeeMachine/103127/textured_objs/original-11.obj" />/&gt;
			</geometry>
		</visual>
		<visual name="base_body-8">
			<origin xyz="0 0 0" />
			<geometry>
				<mesh filename="/home/blake/kitchen-worlds/assets/models/CoffeeMachine/103127/textured_objs/original-38.obj" />/&gt;
			</geometry>
		</visual>
		<visual name="base_body-8">
			<origin xyz="0 0 0" />
			<geometry>
				<mesh filename="/home/blake/kitchen-worlds/assets/models/CoffeeMachine/103127/textured_objs/original-34.obj" />/&gt;
			</geometry>
		</visual>
		<visual name="base_body-8">
			<origin xyz="0 0 0" />
			<geometry>
				<mesh filename="/home/blake/kitchen-worlds/assets/models/CoffeeMachine/103127/textured_objs/original-18.obj" />/&gt;
			</geometry>
		</visual>
		<visual name="base_body-8">
			<origin xyz="0 0 0" />
			<geometry>
				<mesh filename="/home/blake/kitchen-worlds/assets/models/CoffeeMachine/103127/textured_objs/original-70.obj" />/&gt;
			</geometry>
		</visual>
		<visual name="base_body-8">
			<origin xyz="0 0 0" />
			<geometry>
				<mesh filename="/home/blake/kitchen-worlds/assets/models/CoffeeMachine/103127/textured_objs/original-17.obj" />/&gt;
			</geometry>
		</visual>
		<visual name="base_body-8">
			<origin xyz="0 0 0" />
			<geometry>
				<mesh filename="/home/blake/kitchen-worlds/assets/models/CoffeeMachine/103127/textured_objs/original-12.obj" />/&gt;
			</geometry>
		</visual>
		<visual name="base_body-8">
			<origin xyz="0 0 0" />
			<geometry>
				<mesh filename="/home/blake/kitchen-worlds/assets/models/CoffeeMachine/103127/textured_objs/original-42.obj" />/&gt;
			</geometry>
		</visual>
		<visual name="base_body-8">
			<origin xyz="0 0 0" />
			<geometry>
				<mesh filename="/home/blake/kitchen-worlds/assets/models/CoffeeMachine/103127/textured_objs/original-20.obj" />/&gt;
			</geometry>
		</visual>
		<visual name="base_body-8">
			<origin xyz="0 0 0" />
			<geometry>
				<mesh filename="/home/blake/kitchen-worlds/assets/models/CoffeeMachine/103127/textured_objs/original-32.obj" />/&gt;
			</geometry>
		</visual>
		<visual name="base_body-8">
			<origin xyz="0 0 0" />
			<geometry>
				<mesh filename="/home/blake/kitchen-worlds/assets/models/CoffeeMachine/103127/textured_objs/original-7.obj" />/&gt;
			</geometry>
		</visual>
		<visual name="base_body-8">
			<origin xyz="0 0 0" />
			<geometry>
				<mesh filename="/home/blake/kitchen-worlds/assets/models/CoffeeMachine/103127/textured_objs/original-10.obj" />/&gt;
			</geometry>
		</visual>
		<visual name="base_body-8">
			<origin xyz="0 0 0" />
			<geometry>
				<mesh filename="/home/blake/kitchen-worlds/assets/models/CoffeeMachine/103127/textured_objs/original-60.obj" />/&gt;
			</geometry>
		</visual>
		<visual name="base_body-8">
			<origin xyz="0 0 0" />
			<geometry>
				<mesh filename="/home/blake/kitchen-worlds/assets/models/CoffeeMachine/103127/textured_objs/original-19.obj" />/&gt;
			</geometry>
		</visual>
		<visual name="base_body-8">
			<origin xyz="0 0 0" />
			<geometry>
				<mesh filename="/home/blake/kitchen-worlds/assets/models/CoffeeMachine/103127/textured_objs/original-40.obj" />/&gt;
			</geometry>
		</visual>
		<collision>
			<origin xyz="0 0 0" />
			<geometry>
				<mesh filename="/home/blake/kitchen-worlds/assets/models/CoffeeMachine/103127/textured_objs/original-29.obj" />/&gt;
			</geometry>
		</collision>
		<collision>
			<origin xyz="0 0 0" />
			<geometry>
				<mesh filename="/home/blake/kitchen-worlds/assets/models/CoffeeMachine/103127/textured_objs/original-30.obj" />/&gt;
			</geometry>
		</collision>
		<collision>
			<origin xyz="0 0 0" />
			<geometry>
				<mesh filename="/home/blake/kitchen-worlds/assets/models/CoffeeMachine/103127/textured_objs/original-36.obj" />/&gt;
			</geometry>
		</collision>
		<collision>
			<origin xyz="0 0 0" />
			<geometry>
				<mesh filename="/home/blake/kitchen-worlds/assets/models/CoffeeMachine/103127/textured_objs/original-41.obj" />/&gt;
			</geometry>
		</collision>
		<collision>
			<origin xyz="0 0 0" />
			<geometry>
				<mesh filename="/home/blake/kitchen-worlds/assets/models/CoffeeMachine/103127/textured_objs/original-28.obj" />/&gt;
			</geometry>
		</collision>
		<collision>
			<origin xyz="0 0 0" />
			<geometry>
				<mesh filename="/home/blake/kitchen-worlds/assets/models/CoffeeMachine/103127/textured_objs/original-64.obj" />/&gt;
			</geometry>
		</collision>
		<collision>
			<origin xyz="0 0 0" />
			<geometry>
				<mesh filename="/home/blake/kitchen-worlds/assets/models/CoffeeMachine/103127/textured_objs/original-43.obj" />/&gt;
			</geometry>
		</collision>
		<collision>
			<origin xyz="0 0 0" />
			<geometry>
				<mesh filename="/home/blake/kitchen-worlds/assets/models/CoffeeMachine/103127/textured_objs/original-71.obj" />/&gt;
			</geometry>
		</collision>
		<collision>
			<origin xyz="0 0 0" />
			<geometry>
				<mesh filename="/home/blake/kitchen-worlds/assets/models/CoffeeMachine/103127/textured_objs/original-22.obj" />/&gt;
			</geometry>
		</collision>
		<collision>
			<origin xyz="0 0 0" />
			<geometry>
				<mesh filename="/home/blake/kitchen-worlds/assets/models/CoffeeMachine/103127/textured_objs/original-26.obj" />/&gt;
			</geometry>
		</collision>
		<collision>
			<origin xyz="0 0 0" />
			<geometry>
				<mesh filename="/home/blake/kitchen-worlds/assets/models/CoffeeMachine/103127/textured_objs/original-4.obj" />/&gt;
			</geometry>
		</collision>
		<collision>
			<origin xyz="0 0 0" />
			<geometry>
				<mesh filename="/home/blake/kitchen-worlds/assets/models/CoffeeMachine/103127/textured_objs/original-3.obj" />/&gt;
			</geometry>
		</collision>
		<collision>
			<origin xyz="0 0 0" />
			<geometry>
				<mesh filename="/home/blake/kitchen-worlds/assets/models/CoffeeMachine/103127/textured_objs/original-65.obj" />/&gt;
			</geometry>
		</collision>
		<collision>
			<origin xyz="0 0 0" />
			<geometry>
				<mesh filename="/home/blake/kitchen-worlds/assets/models/CoffeeMachine/103127/textured_objs/original-33.obj" />/&gt;
			</geometry>
		</collision>
		<collision>
			<origin xyz="0 0 0" />
			<geometry>
				<mesh filename="/home/blake/kitchen-worlds/assets/models/CoffeeMachine/103127/textured_objs/original-2.obj" />/&gt;
			</geometry>
		</collision>
		<collision>
			<origin xyz="0 0 0" />
			<geometry>
				<mesh filename="/home/blake/kitchen-worlds/assets/models/CoffeeMachine/103127/textured_objs/original-16.obj" />/&gt;
			</geometry>
		</collision>
		<collision>
			<origin xyz="0 0 0" />
			<geometry>
				<mesh filename="/home/blake/kitchen-worlds/assets/models/CoffeeMachine/103127/textured_objs/original-8.obj" />/&gt;
			</geometry>
		</collision>
		<collision>
			<origin xyz="0 0 0" />
			<geometry>
				<mesh filename="/home/blake/kitchen-worlds/assets/models/CoffeeMachine/103127/textured_objs/original-13.obj" />/&gt;
			</geometry>
		</collision>
		<collision>
			<origin xyz="0 0 0" />
			<geometry>
				<mesh filename="/home/blake/kitchen-worlds/assets/models/CoffeeMachine/103127/textured_objs/original-9.obj" />/&gt;
			</geometry>
		</collision>
		<collision>
			<origin xyz="0 0 0" />
			<geometry>
				<mesh filename="/home/blake/kitchen-worlds/assets/models/CoffeeMachine/103127/textured_objs/original-35.obj" />/&gt;
			</geometry>
		</collision>
		<collision>
			<origin xyz="0 0 0" />
			<geometry>
				<mesh filename="/home/blake/kitchen-worlds/assets/models/CoffeeMachine/103127/textured_objs/original-61.obj" />/&gt;
			</geometry>
		</collision>
		<collision>
			<origin xyz="0 0 0" />
			<geometry>
				<mesh filename="/home/blake/kitchen-worlds/assets/models/CoffeeMachine/103127/textured_objs/original-39.obj" />/&gt;
			</geometry>
		</collision>
		<collision>
			<origin xyz="0 0 0" />
			<geometry>
				<mesh filename="/home/blake/kitchen-worlds/assets/models/CoffeeMachine/103127/textured_objs/original-59.obj" />/&gt;
			</geometry>
		</collision>

		<collision>
			<origin xyz="0 0 0" />
			<geometry>
				<mesh filename="/home/blake/kitchen-worlds/assets/models/CoffeeMachine/103127/textured_objs/original-63.obj" />/&gt;
			</geometry>
		</collision>
		<collision>
			<origin xyz="0 0 0" />
			<geometry>
				<mesh filename="/home/blake/kitchen-worlds/assets/models/CoffeeMachine/103127/textured_objs/original-27.obj" />/&gt;
			</geometry>
		</collision>
		<collision>
			<origin xyz="0 0 0" />
			<geometry>
				<mesh filename="/home/blake/kitchen-worlds/assets/models/CoffeeMachine/103127/textured_objs/original-6.obj" />/&gt;
			</geometry>
		</collision>
		<collision>
			<origin xyz="0 0 0" />
			<geometry>
				<mesh filename="/home/blake/kitchen-worlds/assets/models/CoffeeMachine/103127/textured_objs/original-31.obj" />/&gt;
			</geometry>
		</collision>
		<collision>
			<origin xyz="0 0 0" />
			<geometry>
				<mesh filename="/home/blake/kitchen-worlds/assets/models/CoffeeMachine/103127/textured_objs/original-37.obj" />/&gt;
			</geometry>
		</collision>
		<collision>
			<origin xyz="0 0 0" />
			<geometry>
				<mesh filename="/home/blake/kitchen-worlds/assets/models/CoffeeMachine/103127/textured_objs/original-72.obj" />/&gt;
			</geometry>
		</collision>
		<collision>
			<origin xyz="0 0 0" />
			<geometry>
				<mesh filename="/home/blake/kitchen-worlds/assets/models/CoffeeMachine/103127/textured_objs/original-62.obj" />/&gt;
			</geometry>
		</collision>
		<collision>
			<origin xyz="0 0 0" />
			<geometry>
				<mesh filename="/home/blake/kitchen-worlds/assets/models/CoffeeMachine/103127/textured_objs/original-23.obj" />/&gt;
			</geometry>
		</collision>
		<collision>
			<origin xyz="0 0 0" />
			<geometry>
				<mesh filename="/home/blake/kitchen-worlds/assets/models/CoffeeMachine/103127/textured_objs/original-66.obj" />/&gt;
			</geometry>
		</collision>
		<collision>
			<origin xyz="0 0 0" />
			<geometry>
				<mesh filename="/home/blake/kitchen-worlds/assets/models/CoffeeMachine/103127/textured_objs/original-58.obj" />/&gt;
			</geometry>
		</collision>
		<collision>
			<origin xyz="0 0 0" />
			<geometry>
				<mesh filename="/home/blake/kitchen-worlds/assets/models/CoffeeMachine/103127/textured_objs/original-67.obj" />/&gt;
			</geometry>
		</collision>
		<collision>
			<origin xyz="0 0 0" />
			<geometry>
				<mesh filename="/home/blake/kitchen-worlds/assets/models/CoffeeMachine/103127/textured_objs/original-69.obj" />/&gt;
			</geometry>
		</collision>
		<collision>
			<origin xyz="0 0 0" />
			<geometry>
				<mesh filename="/home/blake/kitchen-worlds/assets/models/CoffeeMachine/103127/textured_objs/original-11.obj" />/&gt;
			</geometry>
		</collision>
		<collision>
			<origin xyz="0 0 0" />
			<geometry>
				<mesh filename="/home/blake/kitchen-worlds/assets/models/CoffeeMachine/103127/textured_objs/original-38.obj" />/&gt;
			</geometry>
		</collision>
		<collision>
			<origin xyz="0 0 0" />
			<geometry>
				<mesh filename="/home/blake/kitchen-worlds/assets/models/CoffeeMachine/103127/textured_objs/original-34.obj" />/&gt;
			</geometry>
		</collision>
		<collision>
			<origin xyz="0 0 0" />
			<geometry>
				<mesh filename="/home/blake/kitchen-worlds/assets/models/CoffeeMachine/103127/textured_objs/original-18.obj" />/&gt;
			</geometry>
		</collision>
		<collision>
			<origin xyz="0 0 0" />
			<geometry>
				<mesh filename="/home/blake/kitchen-worlds/assets/models/CoffeeMachine/103127/textured_objs/original-70.obj" />/&gt;
			</geometry>
		</collision>
		<collision>
			<origin xyz="0 0 0" />
			<geometry>
				<mesh filename="/home/blake/kitchen-worlds/assets/models/CoffeeMachine/103127/textured_objs/original-17.obj" />/&gt;
			</geometry>
		</collision>
		<collision>
			<origin xyz="0 0 0" />
			<geometry>
				<mesh filename="/home/blake/kitchen-worlds/assets/models/CoffeeMachine/103127/textured_objs/original-12.obj" />/&gt;
			</geometry>
		</collision>
		<collision>
			<origin xyz="0 0 0" />
			<geometry>
				<mesh filename="/home/blake/kitchen-worlds/assets/models/CoffeeMachine/103127/textured_objs/original-42.obj" />/&gt;
			</geometry>
		</collision>
		<collision>
			<origin xyz="0 0 0" />
			<geometry>
				<mesh filename="/home/blake/kitchen-worlds/assets/models/CoffeeMachine/103127/textured_objs/original-20.obj" />/&gt;
			</geometry>
		</collision>
		<collision>
			<origin xyz="0 0 0" />
			<geometry>
				<mesh filename="/home/blake/kitchen-worlds/assets/models/CoffeeMachine/103127/textured_objs/original-32.obj" />/&gt;
			</geometry>
		</collision>
		<collision>
			<origin xyz="0 0 0" />
			<geometry>
				<mesh filename="/home/blake/kitchen-worlds/assets/models/CoffeeMachine/103127/textured_objs/original-7.obj" />/&gt;
			</geometry>
		</collision>
		<collision>
			<origin xyz="0 0 0" />
			<geometry>
				<mesh filename="/home/blake/kitchen-worlds/assets/models/CoffeeMachine/103127/textured_objs/original-10.obj" />/&gt;
			</geometry>
		</collision>
		<collision>
			<origin xyz="0 0 0" />
			<geometry>
				<mesh filename="/home/blake/kitchen-worlds/assets/models/CoffeeMachine/103127/textured_objs/original-60.obj" />/&gt;
			</geometry>
		</collision>
		<collision>
			<origin xyz="0 0 0" />
			<geometry>
				<mesh filename="/home/blake/kitchen-worlds/assets/models/CoffeeMachine/103127/textured_objs/original-19.obj" />/&gt;
			</geometry>
		</collision>
		<collision>
			<origin xyz="0 0 0" />
			<geometry>
				<mesh filename="/home/blake/kitchen-worlds/assets/models/CoffeeMachine/103127/textured_objs/original-40.obj" />/&gt;
			</geometry>
		</collision>
	</link>
	<joint name="joint_4" type="fixed">
		<origin rpy="1.570796326794897 0 -1.570796326794897" xyz="0 0 0" />
		<child link="link_4" />
		<parent link="base" />
	</joint>

	<link name="link_4_original-5">
		<visual name="base_body-5">
			<origin xyz="0 0 0" />
			<geometry>
				<mesh filename="/home/blake/kitchen-worlds/assets/models/CoffeeMachine/103127/textured_objs/original-5.obj" />/&gt;
			</geometry>
		</visual>
		<collision>
			<origin xyz="0 0 0" />
			<geometry>
				<mesh filename="/home/blake/kitchen-worlds/assets/models/CoffeeMachine/103127/textured_objs/original-5.obj" />/&gt;
			</geometry>
		</collision>
	</link>
	<joint name="joint_4_original-5" type="fixed">
		<origin rpy="0 0 0" xyz="0 0 0" />
		<child link="link_4_original-5" />
		<parent link="link_4" />
	</joint>
</robot>