<?xml version='1.0' encoding='utf-8'?>
<robot name="partnet_8841a35812d5a95f98a4820926b2a786">
	<link name="base"><inertial><mass value="0.1" /><inertia ixx="0.01" iyy="0.01" izz="0.01" ixy="0" ixz="0" iyz="0" /></inertial></link>
	<link name="link_0">
		<visual name="seat-1">
			<origin xyz="0 0.10308522362873963 -0.1536175273582958" />
			<geometry>
				<mesh filename="DinerChair/100568/textured_objs/original-2.obj"/>
			</geometry>
		</visual>
		<collision>
			<origin xyz="0 0.10308522362873963 -0.1536175273582958" />
			<geometry>
				<mesh filename="DinerChair/100568/textured_objs/original-2.obj"/>
			</geometry>
		</collision>
	<inertial><mass value="0.1" /><inertia ixx="0.01" iyy="0.01" izz="0.01" ixy="0" ixz="0" iyz="0" /></inertial></link>
	<joint name="joint_0" type="revolute">
		<origin xyz="0 -0.10308522362873963 0.1536175273582958" />
		<axis xyz="-1 0 0" />
		<child link="link_0" />
		<parent link="link_1" />
		<limit lower="-0.0" upper="2.1928316722056755" effort="10.0" velocity="1.0" />
	</joint>
	<link name="link_1">
		<visual name="base_body-2">
			<origin xyz="0 0 0" />
			<geometry>
				<mesh filename="DinerChair/100568/textured_objs/original-4.obj"/>
			</geometry>
		</visual>
		<visual name="base_body-2">
			<origin xyz="0 0 0" />
			<geometry>
				<mesh filename="DinerChair/100568/textured_objs/original-3.obj"/>
			</geometry>
		</visual>
		<visual name="base_body-2">
			<origin xyz="0 0 0" />
			<geometry>
				<mesh filename="DinerChair/100568/textured_objs/original-8.obj"/>
			</geometry>
		</visual>
		<visual name="base_body-2">
			<origin xyz="0 0 0" />
			<geometry>
				<mesh filename="DinerChair/100568/textured_objs/original-5.obj"/>
			</geometry>
		</visual>
		<visual name="base_body-2">
			<origin xyz="0 0 0" />
			<geometry>
				<mesh filename="DinerChair/100568/textured_objs/original-6.obj"/>
			</geometry>
		</visual>
		<visual name="base_body-2">
			<origin xyz="0 0 0" />
			<geometry>
				<mesh filename="DinerChair/100568/textured_objs/original-7.obj"/>
			</geometry>
		</visual>
		<visual name="base_body-2">
			<origin xyz="0 0 0" />
			<geometry>
				<mesh filename="DinerChair/100568/textured_objs/original-1.obj"/>
			</geometry>
		</visual>
		<collision>
			<origin xyz="0 0 0" />
			<geometry>
				<mesh filename="DinerChair/100568/textured_objs/original-4.obj"/>
			</geometry>
		</collision>
		<collision>
			<origin xyz="0 0 0" />
			<geometry>
				<mesh filename="DinerChair/100568/textured_objs/original-3.obj"/>
			</geometry>
		</collision>
		<collision>
			<origin xyz="0 0 0" />
			<geometry>
				<mesh filename="DinerChair/100568/textured_objs/original-8.obj"/>
			</geometry>
		</collision>
		<collision>
			<origin xyz="0 0 0" />
			<geometry>
				<mesh filename="DinerChair/100568/textured_objs/original-5.obj"/>
			</geometry>
		</collision>
		<collision>
			<origin xyz="0 0 0" />
			<geometry>
				<mesh filename="DinerChair/100568/textured_objs/original-6.obj"/>
			</geometry>
		</collision>
		<collision>
			<origin xyz="0 0 0" />
			<geometry>
				<mesh filename="DinerChair/100568/textured_objs/original-7.obj"/>
			</geometry>
		</collision>
		<collision>
			<origin xyz="0 0 0" />
			<geometry>
				<mesh filename="DinerChair/100568/textured_objs/original-1.obj"/>
			</geometry>
		</collision>
	<inertial><mass value="0.1" /><inertia ixx="0.01" iyy="0.01" izz="0.01" ixy="0" ixz="0" iyz="0" /></inertial></link>
	<joint name="joint_1" type="fixed">
		<origin rpy="1.570796326794897 0 -1.570796326794897" xyz="0 0 0" />
		<child link="link_1" />
		<parent link="base" />
	</joint>
</robot>