<?xml version='1.0' encoding='utf-8'?>
<robot name="partnet_50f0ea68b77810121fbac718728a36d">
	<link name="base" />
	<link name="link_0">
		<visual name="cabinet_door_surface-19">
			<origin xyz="-0.19752811818160698 -0.9664890170097351 -0.27935307817195537" />
			<geometry>
				<mesh filename="/home/blake/kitchen-worlds/assets/models/CabinetTall/46236/textured_objs/original-34.obj" />/&gt;
			</geometry>
		</visual>
		<visual name="handle-20">
			<origin xyz="-0.19752811818160698 -0.9664890170097351 -0.27935307817195537" />
			<geometry>
				<mesh filename="/home/blake/kitchen-worlds/assets/models/CabinetTall/46236/textured_objs/original-29.obj" />/&gt;
			</geometry>
		</visual>
		<visual name="handle-20">
			<origin xyz="-0.19752811818160698 -0.9664890170097351 -0.27935307817195537" />
			<geometry>
				<mesh filename="/home/blake/kitchen-worlds/assets/models/CabinetTall/46236/textured_objs/original-32.obj" />/&gt;
			</geometry>
		</visual>
		<visual name="handle-20">
			<origin xyz="-0.19752811818160698 -0.9664890170097351 -0.27935307817195537" />
			<geometry>
				<mesh filename="/home/blake/kitchen-worlds/assets/models/CabinetTall/46236/textured_objs/original-31.obj" />/&gt;
			</geometry>
		</visual>
		<visual name="handle-20">
			<origin xyz="-0.19752811818160698 -0.9664890170097351 -0.27935307817195537" />
			<geometry>
				<mesh filename="/home/blake/kitchen-worlds/assets/models/CabinetTall/46236/textured_objs/original-33.obj" />/&gt;
			</geometry>
		</visual>
		<visual name="handle-20">
			<origin xyz="-0.19752811818160698 -0.9664890170097351 -0.27935307817195537" />
			<geometry>
				<mesh filename="/home/blake/kitchen-worlds/assets/models/CabinetTall/46236/textured_objs/original-28.obj" />/&gt;
			</geometry>
		</visual>
		<collision>
			<origin xyz="-0.19752811818160698 -0.9664890170097351 -0.27935307817195537" />
			<geometry>
				<mesh filename="/home/blake/kitchen-worlds/assets/models/CabinetTall/46236/textured_objs/original-34.obj" />/&gt;
			</geometry>
		</collision>
		<collision>
			<origin xyz="-0.19752811818160698 -0.9664890170097351 -0.27935307817195537" />
			<geometry>
				<mesh filename="/home/blake/kitchen-worlds/assets/models/CabinetTall/46236/textured_objs/original-29.obj" />/&gt;
			</geometry>
		</collision>
		<collision>
			<origin xyz="-0.19752811818160698 -0.9664890170097351 -0.27935307817195537" />
			<geometry>
				<mesh filename="/home/blake/kitchen-worlds/assets/models/CabinetTall/46236/textured_objs/original-32.obj" />/&gt;
			</geometry>
		</collision>
		<collision>
			<origin xyz="-0.19752811818160698 -0.9664890170097351 -0.27935307817195537" />
			<geometry>
				<mesh filename="/home/blake/kitchen-worlds/assets/models/CabinetTall/46236/textured_objs/original-31.obj" />/&gt;
			</geometry>
		</collision>
		<collision>
			<origin xyz="-0.19752811818160698 -0.9664890170097351 -0.27935307817195537" />
			<geometry>
				<mesh filename="/home/blake/kitchen-worlds/assets/models/CabinetTall/46236/textured_objs/original-33.obj" />/&gt;
			</geometry>
		</collision>
		<collision>
			<origin xyz="-0.19752811818160698 -0.9664890170097351 -0.27935307817195537" />
			<geometry>
				<mesh filename="/home/blake/kitchen-worlds/assets/models/CabinetTall/46236/textured_objs/original-28.obj" />/&gt;
			</geometry>
		</collision>
	</link>
	<joint name="joint_0" type="revolute">
		<origin xyz="0.19752811818160698 0.9664890170097351 0.27935307817195537" />
		<axis xyz="0 0.9999999999999999 0" />
		<child link="link_0" />
		<parent link="link_2" />
		<limit lower="0.0" upper="1.5707963267948966" effort="10.0" velocity="1.0" />
	</joint>
	<link name="link_1">
		<visual name="drawer_front-12">
			<origin xyz="0 0 0" />
			<geometry>
				<mesh filename="/home/blake/kitchen-worlds/assets/models/CabinetTall/46236/textured_objs/original-13.obj" />/&gt;
			</geometry>
		</visual>
		<visual name="drawer_side-13">
			<origin xyz="0 0 0" />
			<geometry>
				<mesh filename="/home/blake/kitchen-worlds/assets/models/CabinetTall/46236/textured_objs/original-12.obj" />/&gt;
			</geometry>
		</visual>
		<visual name="drawer_side-14">
			<origin xyz="0 0 0" />
			<geometry>
				<mesh filename="/home/blake/kitchen-worlds/assets/models/CabinetTall/46236/textured_objs/original-11.obj" />/&gt;
			</geometry>
		</visual>
		<visual name="drawer_back-15">
			<origin xyz="0 0 0" />
			<geometry>
				<mesh filename="/home/blake/kitchen-worlds/assets/models/CabinetTall/46236/textured_objs/original-10.obj" />/&gt;
			</geometry>
		</visual>
		<visual name="drawer_bottom-16">
			<origin xyz="0 0 0" />
			<geometry>
				<mesh filename="/home/blake/kitchen-worlds/assets/models/CabinetTall/46236/textured_objs/original-14.obj" />/&gt;
			</geometry>
		</visual>
		<visual name="handle-11">
			<origin xyz="0 0 0" />
			<geometry>
				<mesh filename="/home/blake/kitchen-worlds/assets/models/CabinetTall/46236/textured_objs/original-5.obj" />/&gt;
			</geometry>
		</visual>
		<visual name="handle-11">
			<origin xyz="0 0 0" />
			<geometry>
				<mesh filename="/home/blake/kitchen-worlds/assets/models/CabinetTall/46236/textured_objs/original-4.obj" />/&gt;
			</geometry>
		</visual>
		<visual name="handle-11">
			<origin xyz="0 0 0" />
			<geometry>
				<mesh filename="/home/blake/kitchen-worlds/assets/models/CabinetTall/46236/textured_objs/original-9.obj" />/&gt;
			</geometry>
		</visual>
		<visual name="handle-11">
			<origin xyz="0 0 0" />
			<geometry>
				<mesh filename="/home/blake/kitchen-worlds/assets/models/CabinetTall/46236/textured_objs/original-8.obj" />/&gt;
			</geometry>
		</visual>
		<visual name="handle-11">
			<origin xyz="0 0 0" />
			<geometry>
				<mesh filename="/home/blake/kitchen-worlds/assets/models/CabinetTall/46236/textured_objs/original-7.obj" />/&gt;
			</geometry>
		</visual>
		<collision>
			<origin xyz="0 0 0" />
			<geometry>
				<mesh filename="/home/blake/kitchen-worlds/assets/models/CabinetTall/46236/textured_objs/original-13.obj" />/&gt;
			</geometry>
		</collision>
		<collision>
			<origin xyz="0 0 0" />
			<geometry>
				<mesh filename="/home/blake/kitchen-worlds/assets/models/CabinetTall/46236/textured_objs/original-12.obj" />/&gt;
			</geometry>
		</collision>
		<collision>
			<origin xyz="0 0 0" />
			<geometry>
				<mesh filename="/home/blake/kitchen-worlds/assets/models/CabinetTall/46236/textured_objs/original-11.obj" />/&gt;
			</geometry>
		</collision>
		<collision>
			<origin xyz="0 0 0" />
			<geometry>
				<mesh filename="/home/blake/kitchen-worlds/assets/models/CabinetTall/46236/textured_objs/original-10.obj" />/&gt;
			</geometry>
		</collision>
		<collision>
			<origin xyz="0 0 0" />
			<geometry>
				<mesh filename="/home/blake/kitchen-worlds/assets/models/CabinetTall/46236/textured_objs/original-14.obj" />/&gt;
			</geometry>
		</collision>
		<collision>
			<origin xyz="0 0 0" />
			<geometry>
				<mesh filename="/home/blake/kitchen-worlds/assets/models/CabinetTall/46236/textured_objs/original-5.obj" />/&gt;
			</geometry>
		</collision>
		<collision>
			<origin xyz="0 0 0" />
			<geometry>
				<mesh filename="/home/blake/kitchen-worlds/assets/models/CabinetTall/46236/textured_objs/original-4.obj" />/&gt;
			</geometry>
		</collision>
		<collision>
			<origin xyz="0 0 0" />
			<geometry>
				<mesh filename="/home/blake/kitchen-worlds/assets/models/CabinetTall/46236/textured_objs/original-9.obj" />/&gt;
			</geometry>
		</collision>
		<collision>
			<origin xyz="0 0 0" />
			<geometry>
				<mesh filename="/home/blake/kitchen-worlds/assets/models/CabinetTall/46236/textured_objs/original-8.obj" />/&gt;
			</geometry>
		</collision>
		<collision>
			<origin xyz="0 0 0" />
			<geometry>
				<mesh filename="/home/blake/kitchen-worlds/assets/models/CabinetTall/46236/textured_objs/original-7.obj" />/&gt;
			</geometry>
		</collision>
	</link>
	<joint name="joint_1" type="prismatic">
		<origin xyz="0 0 0" />
		<axis xyz="0 0 1" />
		<child link="link_1" />
		<parent link="link_2" />
		<limit lower="0" upper="0.48" effort="10.0" velocity="1.0" />
	</joint>
	<link name="link_2">
		<visual name="shelf-3">
			<origin xyz="0 0 0" />
			<geometry>
				<mesh filename="/home/blake/kitchen-worlds/assets/models/CabinetTall/46236/textured_objs/original-20.obj" />/&gt;
			</geometry>
		</visual>
		<visual name="shelf-5">
			<origin xyz="0 0 0" />
			<geometry>
				<mesh filename="/home/blake/kitchen-worlds/assets/models/CabinetTall/46236/textured_objs/original-16.obj" />/&gt;
			</geometry>
		</visual>
		<visual name="shelf-6">
			<origin xyz="0 0 0" />
			<geometry>
				<mesh filename="/home/blake/kitchen-worlds/assets/models/CabinetTall/46236/textured_objs/original-15.obj" />/&gt;
			</geometry>
		</visual>
		<visual name="shelf-7">
			<origin xyz="0 0 0" />
			<geometry>
				<mesh filename="/home/blake/kitchen-worlds/assets/models/CabinetTall/46236/textured_objs/original-23.obj" />/&gt;
			</geometry>
		</visual>
		<visual name="vertical_side_panel-22">
			<origin xyz="0 0 0" />
			<geometry>
				<mesh filename="/home/blake/kitchen-worlds/assets/models/CabinetTall/46236/textured_objs/original-24.obj" />/&gt;
			</geometry>
		</visual>
		<visual name="vertical_side_panel-23">
			<origin xyz="0 0 0" />
			<geometry>
				<mesh filename="/home/blake/kitchen-worlds/assets/models/CabinetTall/46236/textured_objs/original-18.obj" />/&gt;
			</geometry>
		</visual>
		<visual name="back_panel-24">
			<origin xyz="0 0 0" />
			<geometry>
				<mesh filename="/home/blake/kitchen-worlds/assets/models/CabinetTall/46236/textured_objs/original-22.obj" />/&gt;
			</geometry>
		</visual>
		<visual name="bottom_panel-25">
			<origin xyz="0 0 0" />
			<geometry>
				<mesh filename="/home/blake/kitchen-worlds/assets/models/CabinetTall/46236/textured_objs/original-21.obj" />/&gt;
			</geometry>
		</visual>
		<visual name="top_panel-26">
			<origin xyz="0 0 0" />
			<geometry>
				<mesh filename="/home/blake/kitchen-worlds/assets/models/CabinetTall/46236/textured_objs/original-17.obj" />/&gt;
			</geometry>
		</visual>
		<visual name="frame_horizontal_bar-27">
			<origin xyz="0 0 0" />
			<geometry>
				<mesh filename="/home/blake/kitchen-worlds/assets/models/CabinetTall/46236/textured_objs/original-19.obj" />/&gt;
			</geometry>
		</visual>
		<collision>
			<origin xyz="0 0 0" />
			<geometry>
				<mesh filename="/home/blake/kitchen-worlds/assets/models/CabinetTall/46236/textured_objs/original-20.obj" />/&gt;
			</geometry>
		</collision>
		<collision>
			<origin xyz="0 0 0" />
			<geometry>
				<mesh filename="/home/blake/kitchen-worlds/assets/models/CabinetTall/46236/textured_objs/original-16.obj" />/&gt;
			</geometry>
		</collision>
		<collision>
			<origin xyz="0 0 0" />
			<geometry>
				<mesh filename="/home/blake/kitchen-worlds/assets/models/CabinetTall/46236/textured_objs/original-15.obj" />/&gt;
			</geometry>
		</collision>
		<collision>
			<origin xyz="0 0 0" />
			<geometry>
				<mesh filename="/home/blake/kitchen-worlds/assets/models/CabinetTall/46236/textured_objs/original-23.obj" />/&gt;
			</geometry>
		</collision>
		<collision>
			<origin xyz="0 0 0" />
			<geometry>
				<mesh filename="/home/blake/kitchen-worlds/assets/models/CabinetTall/46236/textured_objs/original-24.obj" />/&gt;
			</geometry>
		</collision>
		<collision>
			<origin xyz="0 0 0" />
			<geometry>
				<mesh filename="/home/blake/kitchen-worlds/assets/models/CabinetTall/46236/textured_objs/original-18.obj" />/&gt;
			</geometry>
		</collision>
		<collision>
			<origin xyz="0 0 0" />
			<geometry>
				<mesh filename="/home/blake/kitchen-worlds/assets/models/CabinetTall/46236/textured_objs/original-22.obj" />/&gt;
			</geometry>
		</collision>
		<collision>
			<origin xyz="0 0 0" />
			<geometry>
				<mesh filename="/home/blake/kitchen-worlds/assets/models/CabinetTall/46236/textured_objs/original-21.obj" />/&gt;
			</geometry>
		</collision>
		<collision>
			<origin xyz="0 0 0" />
			<geometry>
				<mesh filename="/home/blake/kitchen-worlds/assets/models/CabinetTall/46236/textured_objs/original-17.obj" />/&gt;
			</geometry>
		</collision>
		<collision>
			<origin xyz="0 0 0" />
			<geometry>
				<mesh filename="/home/blake/kitchen-worlds/assets/models/CabinetTall/46236/textured_objs/original-19.obj" />/&gt;
			</geometry>
		</collision>
	</link>
	<joint name="joint_2" type="fixed">
		<origin rpy="1.570796326794897 0 -1.570796326794897" xyz="0 0 0" />
		<child link="link_2" />
		<parent link="base" />
	</joint>
</robot>