<?xml version='1.0' encoding='utf-8'?>
<robot name="partnet_3800d2ab6bc278bcd5a3e6010c55b78e">
	<link name="base"><inertial><mass value="0.1" /><inertia ixx="0.01" iyy="0.01" izz="0.01" ixy="0" ixz="0" iyz="0" /></inertial></link>
	<link name="link_0">
		<visual name="body-1">
			<origin xyz="0 0 0" />
			<geometry>
				<mesh filename="Stapler/103100/textured_objs/original-4.obj"/>
			</geometry>
		</visual>
		<collision>
			<origin xyz="0 0 0" />
			<geometry>
				<mesh filename="Stapler/103100/textured_objs/original-4.obj"/>
			</geometry>
		</collision>
	<inertial><mass value="0.1" /><inertia ixx="0.01" iyy="0.01" izz="0.01" ixy="0" ixz="0" iyz="0" /></inertial></link>
	<joint name="joint_0" type="revolute">
		<origin xyz="0 0 0" />
		<axis xyz="1.0 -0.0 -0.0" />
		<child link="link_0" />
		<parent link="link_1" />
		<limit lower="-0.06981317007977318" upper="2.7960174616949156" effort="10.0" velocity="1.0" />
	</joint>
	<link name="link_1">
		<visual name="lid-2">
			<origin xyz="0 0 0" />
			<geometry>
				<mesh filename="Stapler/103100/textured_objs/original-3.obj"/>
			</geometry>
		</visual>
		<collision>
			<origin xyz="0 0 0" />
			<geometry>
				<mesh filename="Stapler/103100/textured_objs/original-3.obj"/>
			</geometry>
		</collision>
	<inertial><mass value="0.1" /><inertia ixx="0.01" iyy="0.01" izz="0.01" ixy="0" ixz="0" iyz="0" /></inertial></link>
	<joint name="joint_1" type="revolute">
		<origin xyz="0 0 0" />
		<axis xyz="-1.0 0.0 0.0" />
		<child link="link_1" />
		<parent link="link_2" />
		<limit lower="-0.17592918860102813" upper="1.9854865570687494" effort="10.0" velocity="1.0" />
	</joint>
	<link name="link_2">
		<visual name="base_body-3">
			<origin xyz="0 0 0" />
			<geometry>
				<mesh filename="Stapler/103100/textured_objs/original-5.obj"/>
			</geometry>
		</visual>
		<visual name="base_body-3">
			<origin xyz="0 0 0" />
			<geometry>
				<mesh filename="Stapler/103100/textured_objs/original-1.obj"/>
			</geometry>
		</visual>
		<collision>
			<origin xyz="0 0 0" />
			<geometry>
				<mesh filename="Stapler/103100/textured_objs/original-5.obj"/>
			</geometry>
		</collision>
		<collision>
			<origin xyz="0 0 0" />
			<geometry>
				<mesh filename="Stapler/103100/textured_objs/original-1.obj"/>
			</geometry>
		</collision>
	<inertial><mass value="0.1" /><inertia ixx="0.01" iyy="0.01" izz="0.01" ixy="0" ixz="0" iyz="0" /></inertial></link>
	<joint name="joint_2" type="fixed">
		<origin rpy="1.570796326794897 0 -1.570796326794897" xyz="0 0 0" />
		<child link="link_2" />
		<parent link="base" />
	</joint>
</robot>