<?xml version='1.0' encoding='utf-8'?>
<robot name="partnet_a18d795628d848a5589577ccf07b31e7">
	<link name="base" />
	<link name="link_0">
		<visual name="door-1">
			<origin xyz="-0.41501274567846813 -0.4795389999999998 -0.4691233558568922" />
			<geometry>
				<mesh filename="/home/blake/kitchen-worlds/assets/models/OvenCounter/101930/textured_objs/original-27.obj" />/&gt;
			</geometry>
		</visual>
		<visual name="door-1">
			<origin xyz="-0.41501274567846813 -0.4795389999999998 -0.4691233558568922" />
			<geometry>
				<mesh filename="/home/blake/kitchen-worlds/assets/models/OvenCounter/101930/textured_objs/original-166.obj" />/&gt;
			</geometry>
		</visual>
		<visual name="door-1">
			<origin xyz="-0.41501274567846813 -0.4795389999999998 -0.4691233558568922" />
			<geometry>
				<mesh filename="/home/blake/kitchen-worlds/assets/models/OvenCounter/101930/textured_objs/original-165.obj" />/&gt;
			</geometry>
		</visual>
		<visual name="door-1">
			<origin xyz="-0.41501274567846813 -0.4795389999999998 -0.4691233558568922" />
			<geometry>
				<mesh filename="/home/blake/kitchen-worlds/assets/models/OvenCounter/101930/textured_objs/original-98.obj" />/&gt;
			</geometry>
		</visual>
		<visual name="door-1">
			<origin xyz="-0.41501274567846813 -0.4795389999999998 -0.4691233558568922" />
			<geometry>
				<mesh filename="/home/blake/kitchen-worlds/assets/models/OvenCounter/101930/textured_objs/original-82.obj" />/&gt;
			</geometry>
		</visual>
		<visual name="door-1">
			<origin xyz="-0.41501274567846813 -0.4795389999999998 -0.4691233558568922" />
			<geometry>
				<mesh filename="/home/blake/kitchen-worlds/assets/models/OvenCounter/101930/textured_objs/original-95.obj" />/&gt;
			</geometry>
		</visual>
		<visual name="door-1">
			<origin xyz="-0.41501274567846813 -0.4795389999999998 -0.4691233558568922" />
			<geometry>
				<mesh filename="/home/blake/kitchen-worlds/assets/models/OvenCounter/101930/textured_objs/original-168.obj" />/&gt;
			</geometry>
		</visual>
		<visual name="door-1">
			<origin xyz="-0.41501274567846813 -0.4795389999999998 -0.4691233558568922" />
			<geometry>
				<mesh filename="/home/blake/kitchen-worlds/assets/models/OvenCounter/101930/textured_objs/original-86.obj" />/&gt;
			</geometry>
		</visual>
		<visual name="door-1">
			<origin xyz="-0.41501274567846813 -0.4795389999999998 -0.4691233558568922" />
			<geometry>
				<mesh filename="/home/blake/kitchen-worlds/assets/models/OvenCounter/101930/textured_objs/original-167.obj" />/&gt;
			</geometry>
		</visual>
		<collision>
			<origin xyz="-0.41501274567846813 -0.4795389999999998 -0.4691233558568922" />
			<geometry>
				<mesh filename="/home/blake/kitchen-worlds/assets/models/OvenCounter/101930/textured_objs/original-27.obj" />/&gt;
			</geometry>
		</collision>
		<collision>
			<origin xyz="-0.41501274567846813 -0.4795389999999998 -0.4691233558568922" />
			<geometry>
				<mesh filename="/home/blake/kitchen-worlds/assets/models/OvenCounter/101930/textured_objs/original-166.obj" />/&gt;
			</geometry>
		</collision>
		<collision>
			<origin xyz="-0.41501274567846813 -0.4795389999999998 -0.4691233558568922" />
			<geometry>
				<mesh filename="/home/blake/kitchen-worlds/assets/models/OvenCounter/101930/textured_objs/original-165.obj" />/&gt;
			</geometry>
		</collision>
		<collision>
			<origin xyz="-0.41501274567846813 -0.4795389999999998 -0.4691233558568922" />
			<geometry>
				<mesh filename="/home/blake/kitchen-worlds/assets/models/OvenCounter/101930/textured_objs/original-98.obj" />/&gt;
			</geometry>
		</collision>
		<collision>
			<origin xyz="-0.41501274567846813 -0.4795389999999998 -0.4691233558568922" />
			<geometry>
				<mesh filename="/home/blake/kitchen-worlds/assets/models/OvenCounter/101930/textured_objs/original-82.obj" />/&gt;
			</geometry>
		</collision>
		<collision>
			<origin xyz="-0.41501274567846813 -0.4795389999999998 -0.4691233558568922" />
			<geometry>
				<mesh filename="/home/blake/kitchen-worlds/assets/models/OvenCounter/101930/textured_objs/original-95.obj" />/&gt;
			</geometry>
		</collision>
		<collision>
			<origin xyz="-0.41501274567846813 -0.4795389999999998 -0.4691233558568922" />
			<geometry>
				<mesh filename="/home/blake/kitchen-worlds/assets/models/OvenCounter/101930/textured_objs/original-168.obj" />/&gt;
			</geometry>
		</collision>
		<collision>
			<origin xyz="-0.41501274567846813 -0.4795389999999998 -0.4691233558568922" />
			<geometry>
				<mesh filename="/home/blake/kitchen-worlds/assets/models/OvenCounter/101930/textured_objs/original-86.obj" />/&gt;
			</geometry>
		</collision>
		<collision>
			<origin xyz="-0.41501274567846813 -0.4795389999999998 -0.4691233558568922" />
			<geometry>
				<mesh filename="/home/blake/kitchen-worlds/assets/models/OvenCounter/101930/textured_objs/original-167.obj" />/&gt;
			</geometry>
		</collision>
	</link>
	<joint name="joint_0" type="revolute">
		<origin xyz="0.41501274567846813 0.4795389999999998 0.4691233558568922" />
		<axis xyz="0 1 0" />
		<child link="link_0" />
		<parent link="link_7" />
		<limit lower="-0.0" upper="1.5707963267948966" effort="10.0" velocity="1.0" />
	</joint>
	<link name="link_1">
		<visual name="knob-2">
			<origin xyz="-0.296529 -0.5745741353051864 0" />
			<geometry>
				<mesh filename="/home/blake/kitchen-worlds/assets/models/OvenCounter/101930/textured_objs/original-131.obj" />/&gt;
			</geometry>
		</visual>
		<visual name="knob-2">
			<origin xyz="-0.296529 -0.5745741353051864 0" />
			<geometry>
				<mesh filename="/home/blake/kitchen-worlds/assets/models/OvenCounter/101930/textured_objs/original-130.obj" />/&gt;
			</geometry>
		</visual>
		<visual name="knob-2">
			<origin xyz="-0.296529 -0.5745741353051864 0" />
			<geometry>
				<mesh filename="/home/blake/kitchen-worlds/assets/models/OvenCounter/101930/textured_objs/original-129.obj" />/&gt;
			</geometry>
		</visual>
		<visual name="knob-2">
			<origin xyz="-0.296529 -0.5745741353051864 0" />
			<geometry>
				<mesh filename="/home/blake/kitchen-worlds/assets/models/OvenCounter/101930/textured_objs/original-132.obj" />/&gt;
			</geometry>
		</visual>
		<collision>
			<origin xyz="-0.296529 -0.5745741353051864 0" />
			<geometry>
				<mesh filename="/home/blake/kitchen-worlds/assets/models/OvenCounter/101930/textured_objs/original-131.obj" />/&gt;
			</geometry>
		</collision>
		<collision>
			<origin xyz="-0.296529 -0.5745741353051864 0" />
			<geometry>
				<mesh filename="/home/blake/kitchen-worlds/assets/models/OvenCounter/101930/textured_objs/original-130.obj" />/&gt;
			</geometry>
		</collision>
		<collision>
			<origin xyz="-0.296529 -0.5745741353051864 0" />
			<geometry>
				<mesh filename="/home/blake/kitchen-worlds/assets/models/OvenCounter/101930/textured_objs/original-129.obj" />/&gt;
			</geometry>
		</collision>
		<collision>
			<origin xyz="-0.296529 -0.5745741353051864 0" />
			<geometry>
				<mesh filename="/home/blake/kitchen-worlds/assets/models/OvenCounter/101930/textured_objs/original-132.obj" />/&gt;
			</geometry>
		</collision>
	</link>
	<joint name="joint_1" type="continuous">
		<origin xyz="0.296529 0.5745741353051864 0" />
		<axis xyz="0 0 -1" />
		<child link="link_1" />
		<parent link="link_7" />
	</joint>
	<link name="link_2">
		<visual name="knob-3">
			<origin xyz="-0.1768225 -0.57457426486595 0" />
			<geometry>
				<mesh filename="/home/blake/kitchen-worlds/assets/models/OvenCounter/101930/textured_objs/original-144.obj" />/&gt;
			</geometry>
		</visual>
		<visual name="knob-3">
			<origin xyz="-0.1768225 -0.57457426486595 0" />
			<geometry>
				<mesh filename="/home/blake/kitchen-worlds/assets/models/OvenCounter/101930/textured_objs/original-143.obj" />/&gt;
			</geometry>
		</visual>
		<visual name="knob-3">
			<origin xyz="-0.1768225 -0.57457426486595 0" />
			<geometry>
				<mesh filename="/home/blake/kitchen-worlds/assets/models/OvenCounter/101930/textured_objs/original-141.obj" />/&gt;
			</geometry>
		</visual>
		<visual name="knob-3">
			<origin xyz="-0.1768225 -0.57457426486595 0" />
			<geometry>
				<mesh filename="/home/blake/kitchen-worlds/assets/models/OvenCounter/101930/textured_objs/original-142.obj" />/&gt;
			</geometry>
		</visual>
		<collision>
			<origin xyz="-0.1768225 -0.57457426486595 0" />
			<geometry>
				<mesh filename="/home/blake/kitchen-worlds/assets/models/OvenCounter/101930/textured_objs/original-144.obj" />/&gt;
			</geometry>
		</collision>
		<collision>
			<origin xyz="-0.1768225 -0.57457426486595 0" />
			<geometry>
				<mesh filename="/home/blake/kitchen-worlds/assets/models/OvenCounter/101930/textured_objs/original-143.obj" />/&gt;
			</geometry>
		</collision>
		<collision>
			<origin xyz="-0.1768225 -0.57457426486595 0" />
			<geometry>
				<mesh filename="/home/blake/kitchen-worlds/assets/models/OvenCounter/101930/textured_objs/original-141.obj" />/&gt;
			</geometry>
		</collision>
		<collision>
			<origin xyz="-0.1768225 -0.57457426486595 0" />
			<geometry>
				<mesh filename="/home/blake/kitchen-worlds/assets/models/OvenCounter/101930/textured_objs/original-142.obj" />/&gt;
			</geometry>
		</collision>
	</link>
	<joint name="joint_2" type="continuous">
		<origin xyz="0.1768225 0.57457426486595 0" />
		<axis xyz="0 0 -1" />
		<child link="link_2" />
		<parent link="link_7" />
	</joint>
	<link name="link_3">
		<visual name="knob-4">
			<origin xyz="-0.057116 -0.5745741353051864 0" />
			<geometry>
				<mesh filename="/home/blake/kitchen-worlds/assets/models/OvenCounter/101930/textured_objs/original-145.obj" />/&gt;
			</geometry>
		</visual>
		<visual name="knob-4">
			<origin xyz="-0.057116 -0.5745741353051864 0" />
			<geometry>
				<mesh filename="/home/blake/kitchen-worlds/assets/models/OvenCounter/101930/textured_objs/original-146.obj" />/&gt;
			</geometry>
		</visual>
		<visual name="knob-4">
			<origin xyz="-0.057116 -0.5745741353051864 0" />
			<geometry>
				<mesh filename="/home/blake/kitchen-worlds/assets/models/OvenCounter/101930/textured_objs/original-148.obj" />/&gt;
			</geometry>
		</visual>
		<visual name="knob-4">
			<origin xyz="-0.057116 -0.5745741353051864 0" />
			<geometry>
				<mesh filename="/home/blake/kitchen-worlds/assets/models/OvenCounter/101930/textured_objs/original-147.obj" />/&gt;
			</geometry>
		</visual>
		<collision>
			<origin xyz="-0.057116 -0.5745741353051864 0" />
			<geometry>
				<mesh filename="/home/blake/kitchen-worlds/assets/models/OvenCounter/101930/textured_objs/original-145.obj" />/&gt;
			</geometry>
		</collision>
		<collision>
			<origin xyz="-0.057116 -0.5745741353051864 0" />
			<geometry>
				<mesh filename="/home/blake/kitchen-worlds/assets/models/OvenCounter/101930/textured_objs/original-146.obj" />/&gt;
			</geometry>
		</collision>
		<collision>
			<origin xyz="-0.057116 -0.5745741353051864 0" />
			<geometry>
				<mesh filename="/home/blake/kitchen-worlds/assets/models/OvenCounter/101930/textured_objs/original-148.obj" />/&gt;
			</geometry>
		</collision>
		<collision>
			<origin xyz="-0.057116 -0.5745741353051864 0" />
			<geometry>
				<mesh filename="/home/blake/kitchen-worlds/assets/models/OvenCounter/101930/textured_objs/original-147.obj" />/&gt;
			</geometry>
		</collision>
	</link>
	<joint name="joint_3" type="continuous">
		<origin xyz="0.057116 0.5745741353051864 0" />
		<axis xyz="0 0 -1" />
		<child link="link_3" />
		<parent link="link_7" />
	</joint>
	<link name="link_4">
		<visual name="knob-5">
			<origin xyz="0.06259050000000001 -0.57457426486595 0" />
			<geometry>
				<mesh filename="/home/blake/kitchen-worlds/assets/models/OvenCounter/101930/textured_objs/original-149.obj" />/&gt;
			</geometry>
		</visual>
		<visual name="knob-5">
			<origin xyz="0.06259050000000001 -0.57457426486595 0" />
			<geometry>
				<mesh filename="/home/blake/kitchen-worlds/assets/models/OvenCounter/101930/textured_objs/original-150.obj" />/&gt;
			</geometry>
		</visual>
		<visual name="knob-5">
			<origin xyz="0.06259050000000001 -0.57457426486595 0" />
			<geometry>
				<mesh filename="/home/blake/kitchen-worlds/assets/models/OvenCounter/101930/textured_objs/original-151.obj" />/&gt;
			</geometry>
		</visual>
		<visual name="knob-5">
			<origin xyz="0.06259050000000001 -0.57457426486595 0" />
			<geometry>
				<mesh filename="/home/blake/kitchen-worlds/assets/models/OvenCounter/101930/textured_objs/original-152.obj" />/&gt;
			</geometry>
		</visual>
		<collision>
			<origin xyz="0.06259050000000001 -0.57457426486595 0" />
			<geometry>
				<mesh filename="/home/blake/kitchen-worlds/assets/models/OvenCounter/101930/textured_objs/original-149.obj" />/&gt;
			</geometry>
		</collision>
		<collision>
			<origin xyz="0.06259050000000001 -0.57457426486595 0" />
			<geometry>
				<mesh filename="/home/blake/kitchen-worlds/assets/models/OvenCounter/101930/textured_objs/original-150.obj" />/&gt;
			</geometry>
		</collision>
		<collision>
			<origin xyz="0.06259050000000001 -0.57457426486595 0" />
			<geometry>
				<mesh filename="/home/blake/kitchen-worlds/assets/models/OvenCounter/101930/textured_objs/original-151.obj" />/&gt;
			</geometry>
		</collision>
		<collision>
			<origin xyz="0.06259050000000001 -0.57457426486595 0" />
			<geometry>
				<mesh filename="/home/blake/kitchen-worlds/assets/models/OvenCounter/101930/textured_objs/original-152.obj" />/&gt;
			</geometry>
		</collision>
	</link>
	<joint name="joint_4" type="continuous">
		<origin xyz="-0.06259050000000001 0.57457426486595 0" />
		<axis xyz="0 0 -1" />
		<child link="link_4" />
		<parent link="link_7" />
	</joint>
	<link name="link_5">
		<visual name="knob-6">
			<origin xyz="0.182297 -0.5745741353051864 0" />
			<geometry>
				<mesh filename="/home/blake/kitchen-worlds/assets/models/OvenCounter/101930/textured_objs/original-133.obj" />/&gt;
			</geometry>
		</visual>
		<visual name="knob-6">
			<origin xyz="0.182297 -0.5745741353051864 0" />
			<geometry>
				<mesh filename="/home/blake/kitchen-worlds/assets/models/OvenCounter/101930/textured_objs/original-134.obj" />/&gt;
			</geometry>
		</visual>
		<visual name="knob-6">
			<origin xyz="0.182297 -0.5745741353051864 0" />
			<geometry>
				<mesh filename="/home/blake/kitchen-worlds/assets/models/OvenCounter/101930/textured_objs/original-135.obj" />/&gt;
			</geometry>
		</visual>
		<visual name="knob-6">
			<origin xyz="0.182297 -0.5745741353051864 0" />
			<geometry>
				<mesh filename="/home/blake/kitchen-worlds/assets/models/OvenCounter/101930/textured_objs/original-136.obj" />/&gt;
			</geometry>
		</visual>
		<collision>
			<origin xyz="0.182297 -0.5745741353051864 0" />
			<geometry>
				<mesh filename="/home/blake/kitchen-worlds/assets/models/OvenCounter/101930/textured_objs/original-133.obj" />/&gt;
			</geometry>
		</collision>
		<collision>
			<origin xyz="0.182297 -0.5745741353051864 0" />
			<geometry>
				<mesh filename="/home/blake/kitchen-worlds/assets/models/OvenCounter/101930/textured_objs/original-134.obj" />/&gt;
			</geometry>
		</collision>
		<collision>
			<origin xyz="0.182297 -0.5745741353051864 0" />
			<geometry>
				<mesh filename="/home/blake/kitchen-worlds/assets/models/OvenCounter/101930/textured_objs/original-135.obj" />/&gt;
			</geometry>
		</collision>
		<collision>
			<origin xyz="0.182297 -0.5745741353051864 0" />
			<geometry>
				<mesh filename="/home/blake/kitchen-worlds/assets/models/OvenCounter/101930/textured_objs/original-136.obj" />/&gt;
			</geometry>
		</collision>
	</link>
	<joint name="joint_5" type="continuous">
		<origin xyz="-0.182297 0.5745741353051864 0" />
		<axis xyz="0 0 -1" />
		<child link="link_5" />
		<parent link="link_7" />
	</joint>
	<link name="link_6">
		<visual name="knob-7">
			<origin xyz="0.3020035 -0.57457426486595 0" />
			<geometry>
				<mesh filename="/home/blake/kitchen-worlds/assets/models/OvenCounter/101930/textured_objs/original-140.obj" />/&gt;
			</geometry>
		</visual>
		<visual name="knob-7">
			<origin xyz="0.3020035 -0.57457426486595 0" />
			<geometry>
				<mesh filename="/home/blake/kitchen-worlds/assets/models/OvenCounter/101930/textured_objs/original-138.obj" />/&gt;
			</geometry>
		</visual>
		<visual name="knob-7">
			<origin xyz="0.3020035 -0.57457426486595 0" />
			<geometry>
				<mesh filename="/home/blake/kitchen-worlds/assets/models/OvenCounter/101930/textured_objs/original-137.obj" />/&gt;
			</geometry>
		</visual>
		<visual name="knob-7">
			<origin xyz="0.3020035 -0.57457426486595 0" />
			<geometry>
				<mesh filename="/home/blake/kitchen-worlds/assets/models/OvenCounter/101930/textured_objs/original-139.obj" />/&gt;
			</geometry>
		</visual>
		<collision>
			<origin xyz="0.3020035 -0.57457426486595 0" />
			<geometry>
				<mesh filename="/home/blake/kitchen-worlds/assets/models/OvenCounter/101930/textured_objs/original-140.obj" />/&gt;
			</geometry>
		</collision>
		<collision>
			<origin xyz="0.3020035 -0.57457426486595 0" />
			<geometry>
				<mesh filename="/home/blake/kitchen-worlds/assets/models/OvenCounter/101930/textured_objs/original-138.obj" />/&gt;
			</geometry>
		</collision>
		<collision>
			<origin xyz="0.3020035 -0.57457426486595 0" />
			<geometry>
				<mesh filename="/home/blake/kitchen-worlds/assets/models/OvenCounter/101930/textured_objs/original-137.obj" />/&gt;
			</geometry>
		</collision>
		<collision>
			<origin xyz="0.3020035 -0.57457426486595 0" />
			<geometry>
				<mesh filename="/home/blake/kitchen-worlds/assets/models/OvenCounter/101930/textured_objs/original-139.obj" />/&gt;
			</geometry>
		</collision>
	</link>
	<joint name="joint_6" type="continuous">
		<origin xyz="-0.3020035 0.57457426486595 0" />
		<axis xyz="0 0 -1" />
		<child link="link_6" />
		<parent link="link_7" />
	</joint>
	<link name="link_7">
		<visual name="base_body-8">
			<origin xyz="0 0 0" />
			<geometry>
				<mesh filename="/home/blake/kitchen-worlds/assets/models/OvenCounter/101930/textured_objs/original-103.obj" />/&gt;
			</geometry>
		</visual>
		<visual name="base_body-8">
			<origin xyz="0 0 0" />
			<geometry>
				<mesh filename="/home/blake/kitchen-worlds/assets/models/OvenCounter/101930/textured_objs/original-100.obj" />/&gt;
			</geometry>
		</visual>
		<visual name="base_body-8">
			<origin xyz="0 0 0" />
			<geometry>
				<mesh filename="/home/blake/kitchen-worlds/assets/models/OvenCounter/101930/textured_objs/original-123.obj" />/&gt;
			</geometry>
		</visual>
		<visual name="base_body-8">
			<origin xyz="0 0 0" />
			<geometry>
				<mesh filename="/home/blake/kitchen-worlds/assets/models/OvenCounter/101930/textured_objs/original-154.obj" />/&gt;
			</geometry>
		</visual>
		<visual name="base_body-8">
			<origin xyz="0 0 0" />
			<geometry>
				<mesh filename="/home/blake/kitchen-worlds/assets/models/OvenCounter/101930/textured_objs/original-126.obj" />/&gt;
			</geometry>
		</visual>
		<visual name="base_body-8">
			<origin xyz="0 0 0" />
			<geometry>
				<mesh filename="/home/blake/kitchen-worlds/assets/models/OvenCounter/101930/textured_objs/original-119.obj" />/&gt;
			</geometry>
		</visual>
		<visual name="base_body-8">
			<origin xyz="0 0 0" />
			<geometry>
				<mesh filename="/home/blake/kitchen-worlds/assets/models/OvenCounter/101930/textured_objs/original-28.obj" />/&gt;
			</geometry>
		</visual>
		<visual name="base_body-8">
			<origin xyz="0 0 0" />
			<geometry>
				<mesh filename="/home/blake/kitchen-worlds/assets/models/OvenCounter/101930/textured_objs/original-124.obj" />/&gt;
			</geometry>
		</visual>
		<visual name="base_body-8">
			<origin xyz="0 0 0" />
			<geometry>
				<mesh filename="/home/blake/kitchen-worlds/assets/models/OvenCounter/101930/textured_objs/original-96.obj" />/&gt;
			</geometry>
		</visual>
		<visual name="base_body-8">
			<origin xyz="0 0 0" />
			<geometry>
				<mesh filename="/home/blake/kitchen-worlds/assets/models/OvenCounter/101930/textured_objs/original-64.obj" />/&gt;
			</geometry>
		</visual>
		<visual name="base_body-8">
			<origin xyz="0 0 0" />
			<geometry>
				<mesh filename="/home/blake/kitchen-worlds/assets/models/OvenCounter/101930/textured_objs/original-52.obj" />/&gt;
			</geometry>
		</visual>
		<visual name="base_body-8">
			<origin xyz="0 0 0" />
			<geometry>
				<mesh filename="/home/blake/kitchen-worlds/assets/models/OvenCounter/101930/textured_objs/original-83.obj" />/&gt;
			</geometry>
		</visual>
		<visual name="base_body-8">
			<origin xyz="0 0 0" />
			<geometry>
				<mesh filename="/home/blake/kitchen-worlds/assets/models/OvenCounter/101930/textured_objs/original-117.obj" />/&gt;
			</geometry>
		</visual>
		<visual name="base_body-8">
			<origin xyz="0 0 0" />
			<geometry>
				<mesh filename="/home/blake/kitchen-worlds/assets/models/OvenCounter/101930/textured_objs/original-110.obj" />/&gt;
			</geometry>
		</visual>
		<visual name="base_body-8">
			<origin xyz="0 0 0" />
			<geometry>
				<mesh filename="/home/blake/kitchen-worlds/assets/models/OvenCounter/101930/textured_objs/original-153.obj" />/&gt;
			</geometry>
		</visual>
		<visual name="base_body-8">
			<origin xyz="0 0 0" />
			<geometry>
				<mesh filename="/home/blake/kitchen-worlds/assets/models/OvenCounter/101930/textured_objs/original-107.obj" />/&gt;
			</geometry>
		</visual>
		<visual name="base_body-8">
			<origin xyz="0 0 0" />
			<geometry>
				<mesh filename="/home/blake/kitchen-worlds/assets/models/OvenCounter/101930/textured_objs/original-160.obj" />/&gt;
			</geometry>
		</visual>
		<visual name="base_body-8">
			<origin xyz="0 0 0" />
			<geometry>
				<mesh filename="/home/blake/kitchen-worlds/assets/models/OvenCounter/101930/textured_objs/original-104.obj" />/&gt;
			</geometry>
		</visual>
		<visual name="base_body-8">
			<origin xyz="0 0 0" />
			<geometry>
				<mesh filename="/home/blake/kitchen-worlds/assets/models/OvenCounter/101930/textured_objs/original-128.obj" />/&gt;
			</geometry>
		</visual>
		<visual name="base_body-8">
			<origin xyz="0 0 0" />
			<geometry>
				<mesh filename="/home/blake/kitchen-worlds/assets/models/OvenCounter/101930/textured_objs/original-65.obj" />/&gt;
			</geometry>
		</visual>
		<visual name="base_body-8">
			<origin xyz="0 0 0" />
			<geometry>
				<mesh filename="/home/blake/kitchen-worlds/assets/models/OvenCounter/101930/textured_objs/original-2.obj" />/&gt;
			</geometry>
		</visual>
		<visual name="base_body-8">
			<origin xyz="0 0 0" />
			<geometry>
				<mesh filename="/home/blake/kitchen-worlds/assets/models/OvenCounter/101930/textured_objs/original-44.obj" />/&gt;
			</geometry>
		</visual>
		<visual name="base_body-8">
			<origin xyz="0 0 0" />
			<geometry>
				<mesh filename="/home/blake/kitchen-worlds/assets/models/OvenCounter/101930/textured_objs/original-112.obj" />/&gt;
			</geometry>
		</visual>
		<visual name="base_body-8">
			<origin xyz="0 0 0" />
			<geometry>
				<mesh filename="/home/blake/kitchen-worlds/assets/models/OvenCounter/101930/textured_objs/original-162.obj" />/&gt;
			</geometry>
		</visual>
		<visual name="base_body-8">
			<origin xyz="0 0 0" />
			<geometry>
				<mesh filename="/home/blake/kitchen-worlds/assets/models/OvenCounter/101930/textured_objs/original-106.obj" />/&gt;
			</geometry>
		</visual>
		<visual name="base_body-8">
			<origin xyz="0 0 0" />
			<geometry>
				<mesh filename="/home/blake/kitchen-worlds/assets/models/OvenCounter/101930/textured_objs/original-8.obj" />/&gt;
			</geometry>
		</visual>
		<visual name="base_body-8">
			<origin xyz="0 0 0" />
			<geometry>
				<mesh filename="/home/blake/kitchen-worlds/assets/models/OvenCounter/101930/textured_objs/original-109.obj" />/&gt;
			</geometry>
		</visual>
		<visual name="base_body-8">
			<origin xyz="0 0 0" />
			<geometry>
				<mesh filename="/home/blake/kitchen-worlds/assets/models/OvenCounter/101930/textured_objs/original-125.obj" />/&gt;
			</geometry>
		</visual>
		<visual name="base_body-8">
			<origin xyz="0 0 0" />
			<geometry>
				<mesh filename="/home/blake/kitchen-worlds/assets/models/OvenCounter/101930/textured_objs/original-156.obj" />/&gt;
			</geometry>
		</visual>
		<visual name="base_body-8">
			<origin xyz="0 0 0" />
			<geometry>
				<mesh filename="/home/blake/kitchen-worlds/assets/models/OvenCounter/101930/textured_objs/original-49.obj" />/&gt;
			</geometry>
		</visual>
		<visual name="base_body-8">
			<origin xyz="0 0 0" />
			<geometry>
				<mesh filename="/home/blake/kitchen-worlds/assets/models/OvenCounter/101930/textured_objs/original-93.obj" />/&gt;
			</geometry>
		</visual>
		<visual name="base_body-8">
			<origin xyz="0 0 0" />
			<geometry>
				<mesh filename="/home/blake/kitchen-worlds/assets/models/OvenCounter/101930/textured_objs/original-61.obj" />/&gt;
			</geometry>
		</visual>
		<visual name="base_body-8">
			<origin xyz="0 0 0" />
			<geometry>
				<mesh filename="/home/blake/kitchen-worlds/assets/models/OvenCounter/101930/textured_objs/original-120.obj" />/&gt;
			</geometry>
		</visual>
		<visual name="base_body-8">
			<origin xyz="0 0 0" />
			<geometry>
				<mesh filename="/home/blake/kitchen-worlds/assets/models/OvenCounter/101930/textured_objs/original-59.obj" />/&gt;
			</geometry>
		</visual>
		<visual name="base_body-8">
			<origin xyz="0 0 0" />
			<geometry>
				<mesh filename="/home/blake/kitchen-worlds/assets/models/OvenCounter/101930/textured_objs/original-77.obj" />/&gt;
			</geometry>
		</visual>
		<visual name="base_body-8">
			<origin xyz="0 0 0" />
			<geometry>
				<mesh filename="/home/blake/kitchen-worlds/assets/models/OvenCounter/101930/textured_objs/original-114.obj" />/&gt;
			</geometry>
		</visual>
		<visual name="base_body-8">
			<origin xyz="0 0 0" />
			<geometry>
				<mesh filename="/home/blake/kitchen-worlds/assets/models/OvenCounter/101930/textured_objs/original-54.obj" />/&gt;
			</geometry>
		</visual>
		<visual name="base_body-8">
			<origin xyz="0 0 0" />
			<geometry>
				<mesh filename="/home/blake/kitchen-worlds/assets/models/OvenCounter/101930/textured_objs/original-63.obj" />/&gt;
			</geometry>
		</visual>
		<visual name="base_body-8">
			<origin xyz="0 0 0" />
			<geometry>
				<mesh filename="/home/blake/kitchen-worlds/assets/models/OvenCounter/101930/textured_objs/original-159.obj" />/&gt;
			</geometry>
		</visual>
		<visual name="base_body-8">
			<origin xyz="0 0 0" />
			<geometry>
				<mesh filename="/home/blake/kitchen-worlds/assets/models/OvenCounter/101930/textured_objs/original-87.obj" />/&gt;
			</geometry>
		</visual>
		<visual name="base_body-8">
			<origin xyz="0 0 0" />
			<geometry>
				<mesh filename="/home/blake/kitchen-worlds/assets/models/OvenCounter/101930/textured_objs/original-51.obj" />/&gt;
			</geometry>
		</visual>
		<visual name="base_body-8">
			<origin xyz="0 0 0" />
			<geometry>
				<mesh filename="/home/blake/kitchen-worlds/assets/models/OvenCounter/101930/textured_objs/original-55.obj" />/&gt;
			</geometry>
		</visual>
		<visual name="base_body-8">
			<origin xyz="0 0 0" />
			<geometry>
				<mesh filename="/home/blake/kitchen-worlds/assets/models/OvenCounter/101930/textured_objs/original-163.obj" />/&gt;
			</geometry>
		</visual>
		<visual name="base_body-8">
			<origin xyz="0 0 0" />
			<geometry>
				<mesh filename="/home/blake/kitchen-worlds/assets/models/OvenCounter/101930/textured_objs/original-113.obj" />/&gt;
			</geometry>
		</visual>
		<visual name="base_body-8">
			<origin xyz="0 0 0" />
			<geometry>
				<mesh filename="/home/blake/kitchen-worlds/assets/models/OvenCounter/101930/textured_objs/original-50.obj" />/&gt;
			</geometry>
		</visual>
		<visual name="base_body-8">
			<origin xyz="0 0 0" />
			<geometry>
				<mesh filename="/home/blake/kitchen-worlds/assets/models/OvenCounter/101930/textured_objs/original-111.obj" />/&gt;
			</geometry>
		</visual>
		<visual name="base_body-8">
			<origin xyz="0 0 0" />
			<geometry>
				<mesh filename="/home/blake/kitchen-worlds/assets/models/OvenCounter/101930/textured_objs/original-48.obj" />/&gt;
			</geometry>
		</visual>
		<visual name="base_body-8">
			<origin xyz="0 0 0" />
			<geometry>
				<mesh filename="/home/blake/kitchen-worlds/assets/models/OvenCounter/101930/textured_objs/original-116.obj" />/&gt;
			</geometry>
		</visual>
		<visual name="base_body-8">
			<origin xyz="0 0 0" />
			<geometry>
				<mesh filename="/home/blake/kitchen-worlds/assets/models/OvenCounter/101930/textured_objs/original-85.obj" />/&gt;
			</geometry>
		</visual>
		<visual name="base_body-8">
			<origin xyz="0 0 0" />
			<geometry>
				<mesh filename="/home/blake/kitchen-worlds/assets/models/OvenCounter/101930/textured_objs/original-122.obj" />/&gt;
			</geometry>
		</visual>
		<visual name="base_body-8">
			<origin xyz="0 0 0" />
			<geometry>
				<mesh filename="/home/blake/kitchen-worlds/assets/models/OvenCounter/101930/textured_objs/original-56.obj" />/&gt;
			</geometry>
		</visual>
		<visual name="base_body-8">
			<origin xyz="0 0 0" />
			<geometry>
				<mesh filename="/home/blake/kitchen-worlds/assets/models/OvenCounter/101930/textured_objs/original-76.obj" />/&gt;
			</geometry>
		</visual>
		<visual name="base_body-8">
			<origin xyz="0 0 0" />
			<geometry>
				<mesh filename="/home/blake/kitchen-worlds/assets/models/OvenCounter/101930/textured_objs/original-108.obj" />/&gt;
			</geometry>
		</visual>
		<visual name="base_body-8">
			<origin xyz="0 0 0" />
			<geometry>
				<mesh filename="/home/blake/kitchen-worlds/assets/models/OvenCounter/101930/textured_objs/original-72.obj" />/&gt;
			</geometry>
		</visual>
		<visual name="base_body-8">
			<origin xyz="0 0 0" />
			<geometry>
				<mesh filename="/home/blake/kitchen-worlds/assets/models/OvenCounter/101930/textured_objs/original-99.obj" />/&gt;
			</geometry>
		</visual>
		<visual name="base_body-8">
			<origin xyz="0 0 0" />
			<geometry>
				<mesh filename="/home/blake/kitchen-worlds/assets/models/OvenCounter/101930/textured_objs/original-127.obj" />/&gt;
			</geometry>
		</visual>
		<visual name="base_body-8">
			<origin xyz="0 0 0" />
			<geometry>
				<mesh filename="/home/blake/kitchen-worlds/assets/models/OvenCounter/101930/textured_objs/original-62.obj" />/&gt;
			</geometry>
		</visual>
		<visual name="base_body-8">
			<origin xyz="0 0 0" />
			<geometry>
				<mesh filename="/home/blake/kitchen-worlds/assets/models/OvenCounter/101930/textured_objs/original-75.obj" />/&gt;
			</geometry>
		</visual>
		<visual name="base_body-8">
			<origin xyz="0 0 0" />
			<geometry>
				<mesh filename="/home/blake/kitchen-worlds/assets/models/OvenCounter/101930/textured_objs/original-158.obj" />/&gt;
			</geometry>
		</visual>
		<visual name="base_body-8">
			<origin xyz="0 0 0" />
			<geometry>
				<mesh filename="/home/blake/kitchen-worlds/assets/models/OvenCounter/101930/textured_objs/original-66.obj" />/&gt;
			</geometry>
		</visual>
		<visual name="base_body-8">
			<origin xyz="0 0 0" />
			<geometry>
				<mesh filename="/home/blake/kitchen-worlds/assets/models/OvenCounter/101930/textured_objs/original-58.obj" />/&gt;
			</geometry>
		</visual>
		<visual name="base_body-8">
			<origin xyz="0 0 0" />
			<geometry>
				<mesh filename="/home/blake/kitchen-worlds/assets/models/OvenCounter/101930/textured_objs/original-67.obj" />/&gt;
			</geometry>
		</visual>
		<visual name="base_body-8">
			<origin xyz="0 0 0" />
			<geometry>
				<mesh filename="/home/blake/kitchen-worlds/assets/models/OvenCounter/101930/textured_objs/original-69.obj" />/&gt;
			</geometry>
		</visual>
		<visual name="base_body-8">
			<origin xyz="0 0 0" />
			<geometry>
				<mesh filename="/home/blake/kitchen-worlds/assets/models/OvenCounter/101930/textured_objs/original-11.obj" />/&gt;
			</geometry>
		</visual>
		<visual name="base_body-8">
			<origin xyz="0 0 0" />
			<geometry>
				<mesh filename="/home/blake/kitchen-worlds/assets/models/OvenCounter/101930/textured_objs/original-38.obj" />/&gt;
			</geometry>
		</visual>
		<visual name="base_body-8">
			<origin xyz="0 0 0" />
			<geometry>
				<mesh filename="/home/blake/kitchen-worlds/assets/models/OvenCounter/101930/textured_objs/original-80.obj" />/&gt;
			</geometry>
		</visual>
		<visual name="base_body-8">
			<origin xyz="0 0 0" />
			<geometry>
				<mesh filename="/home/blake/kitchen-worlds/assets/models/OvenCounter/101930/textured_objs/original-161.obj" />/&gt;
			</geometry>
		</visual>
		<visual name="base_body-8">
			<origin xyz="0 0 0" />
			<geometry>
				<mesh filename="/home/blake/kitchen-worlds/assets/models/OvenCounter/101930/textured_objs/original-74.obj" />/&gt;
			</geometry>
		</visual>
		<visual name="base_body-8">
			<origin xyz="0 0 0" />
			<geometry>
				<mesh filename="/home/blake/kitchen-worlds/assets/models/OvenCounter/101930/textured_objs/original-118.obj" />/&gt;
			</geometry>
		</visual>
		<visual name="base_body-8">
			<origin xyz="0 0 0" />
			<geometry>
				<mesh filename="/home/blake/kitchen-worlds/assets/models/OvenCounter/101930/textured_objs/original-91.obj" />/&gt;
			</geometry>
		</visual>
		<visual name="base_body-8">
			<origin xyz="0 0 0" />
			<geometry>
				<mesh filename="/home/blake/kitchen-worlds/assets/models/OvenCounter/101930/textured_objs/original-25.obj" />/&gt;
			</geometry>
		</visual>
		<visual name="base_body-8">
			<origin xyz="0 0 0" />
			<geometry>
				<mesh filename="/home/blake/kitchen-worlds/assets/models/OvenCounter/101930/textured_objs/original-73.obj" />/&gt;
			</geometry>
		</visual>
		<visual name="base_body-8">
			<origin xyz="0 0 0" />
			<geometry>
				<mesh filename="/home/blake/kitchen-worlds/assets/models/OvenCounter/101930/textured_objs/original-12.obj" />/&gt;
			</geometry>
		</visual>
		<visual name="base_body-8">
			<origin xyz="0 0 0" />
			<geometry>
				<mesh filename="/home/blake/kitchen-worlds/assets/models/OvenCounter/101930/textured_objs/original-92.obj" />/&gt;
			</geometry>
		</visual>
		<visual name="base_body-8">
			<origin xyz="0 0 0" />
			<geometry>
				<mesh filename="/home/blake/kitchen-worlds/assets/models/OvenCounter/101930/textured_objs/original-42.obj" />/&gt;
			</geometry>
		</visual>
		<visual name="base_body-8">
			<origin xyz="0 0 0" />
			<geometry>
				<mesh filename="/home/blake/kitchen-worlds/assets/models/OvenCounter/101930/textured_objs/original-79.obj" />/&gt;
			</geometry>
		</visual>
		<visual name="base_body-8">
			<origin xyz="0 0 0" />
			<geometry>
				<mesh filename="/home/blake/kitchen-worlds/assets/models/OvenCounter/101930/textured_objs/original-102.obj" />/&gt;
			</geometry>
		</visual>
		<visual name="base_body-8">
			<origin xyz="0 0 0" />
			<geometry>
				<mesh filename="/home/blake/kitchen-worlds/assets/models/OvenCounter/101930/textured_objs/original-88.obj" />/&gt;
			</geometry>
		</visual>
		<visual name="base_body-8">
			<origin xyz="0 0 0" />
			<geometry>
				<mesh filename="/home/blake/kitchen-worlds/assets/models/OvenCounter/101930/textured_objs/original-115.obj" />/&gt;
			</geometry>
		</visual>
		<visual name="base_body-8">
			<origin xyz="0 0 0" />
			<geometry>
				<mesh filename="/home/blake/kitchen-worlds/assets/models/OvenCounter/101930/textured_objs/original-47.obj" />/&gt;
			</geometry>
		</visual>
		<visual name="base_body-8">
			<origin xyz="0 0 0" />
			<geometry>
				<mesh filename="/home/blake/kitchen-worlds/assets/models/OvenCounter/101930/textured_objs/original-53.obj" />/&gt;
			</geometry>
		</visual>
		<visual name="base_body-8">
			<origin xyz="0 0 0" />
			<geometry>
				<mesh filename="/home/blake/kitchen-worlds/assets/models/OvenCounter/101930/textured_objs/original-7.obj" />/&gt;
			</geometry>
		</visual>
		<visual name="base_body-8">
			<origin xyz="0 0 0" />
			<geometry>
				<mesh filename="/home/blake/kitchen-worlds/assets/models/OvenCounter/101930/textured_objs/original-105.obj" />/&gt;
			</geometry>
		</visual>
		<visual name="base_body-8">
			<origin xyz="0 0 0" />
			<geometry>
				<mesh filename="/home/blake/kitchen-worlds/assets/models/OvenCounter/101930/textured_objs/original-101.obj" />/&gt;
			</geometry>
		</visual>
		<visual name="base_body-8">
			<origin xyz="0 0 0" />
			<geometry>
				<mesh filename="/home/blake/kitchen-worlds/assets/models/OvenCounter/101930/textured_objs/original-81.obj" />/&gt;
			</geometry>
		</visual>
		<visual name="base_body-8">
			<origin xyz="0 0 0" />
			<geometry>
				<mesh filename="/home/blake/kitchen-worlds/assets/models/OvenCounter/101930/textured_objs/original-84.obj" />/&gt;
			</geometry>
		</visual>
		<visual name="base_body-8">
			<origin xyz="0 0 0" />
			<geometry>
				<mesh filename="/home/blake/kitchen-worlds/assets/models/OvenCounter/101930/textured_objs/original-121.obj" />/&gt;
			</geometry>
		</visual>
		<visual name="base_body-8">
			<origin xyz="0 0 0" />
			<geometry>
				<mesh filename="/home/blake/kitchen-worlds/assets/models/OvenCounter/101930/textured_objs/original-94.obj" />/&gt;
			</geometry>
		</visual>
		<visual name="base_body-8">
			<origin xyz="0 0 0" />
			<geometry>
				<mesh filename="/home/blake/kitchen-worlds/assets/models/OvenCounter/101930/textured_objs/original-78.obj" />/&gt;
			</geometry>
		</visual>
		<visual name="base_body-8">
			<origin xyz="0 0 0" />
			<geometry>
				<mesh filename="/home/blake/kitchen-worlds/assets/models/OvenCounter/101930/textured_objs/original-97.obj" />/&gt;
			</geometry>
		</visual>
		<visual name="base_body-8">
			<origin xyz="0 0 0" />
			<geometry>
				<mesh filename="/home/blake/kitchen-worlds/assets/models/OvenCounter/101930/textured_objs/original-157.obj" />/&gt;
			</geometry>
		</visual>
		<visual name="base_body-8">
			<origin xyz="0 0 0" />
			<geometry>
				<mesh filename="/home/blake/kitchen-worlds/assets/models/OvenCounter/101930/textured_objs/original-89.obj" />/&gt;
			</geometry>
		</visual>
		<visual name="base_body-8">
			<origin xyz="0 0 0" />
			<geometry>
				<mesh filename="/home/blake/kitchen-worlds/assets/models/OvenCounter/101930/textured_objs/original-60.obj" />/&gt;
			</geometry>
		</visual>
		<visual name="base_body-8">
			<origin xyz="0 0 0" />
			<geometry>
				<mesh filename="/home/blake/kitchen-worlds/assets/models/OvenCounter/101930/textured_objs/original-90.obj" />/&gt;
			</geometry>
		</visual>
		<visual name="base_body-8">
			<origin xyz="0 0 0" />
			<geometry>
				<mesh filename="/home/blake/kitchen-worlds/assets/models/OvenCounter/101930/textured_objs/original-155.obj" />/&gt;
			</geometry>
		</visual>
		<visual name="base_body-8">
			<origin xyz="0 0 0" />
			<geometry>
				<mesh filename="/home/blake/kitchen-worlds/assets/models/OvenCounter/101930/textured_objs/original-164.obj" />/&gt;
			</geometry>
		</visual>
		<collision>
			<origin xyz="0 0 0" />
			<geometry>
				<mesh filename="/home/blake/kitchen-worlds/assets/models/OvenCounter/101930/textured_objs/original-103.obj" />/&gt;
			</geometry>
		</collision>
		<collision>
			<origin xyz="0 0 0" />
			<geometry>
				<mesh filename="/home/blake/kitchen-worlds/assets/models/OvenCounter/101930/textured_objs/original-100.obj" />/&gt;
			</geometry>
		</collision>
		<collision>
			<origin xyz="0 0 0" />
			<geometry>
				<mesh filename="/home/blake/kitchen-worlds/assets/models/OvenCounter/101930/textured_objs/original-123.obj" />/&gt;
			</geometry>
		</collision>
		<collision>
			<origin xyz="0 0 0" />
			<geometry>
				<mesh filename="/home/blake/kitchen-worlds/assets/models/OvenCounter/101930/textured_objs/original-154.obj" />/&gt;
			</geometry>
		</collision>
		<collision>
			<origin xyz="0 0 0" />
			<geometry>
				<mesh filename="/home/blake/kitchen-worlds/assets/models/OvenCounter/101930/textured_objs/original-126.obj" />/&gt;
			</geometry>
		</collision>
		<collision>
			<origin xyz="0 0 0" />
			<geometry>
				<mesh filename="/home/blake/kitchen-worlds/assets/models/OvenCounter/101930/textured_objs/original-119.obj" />/&gt;
			</geometry>
		</collision>
		<collision>
			<origin xyz="0 0 0" />
			<geometry>
				<mesh filename="/home/blake/kitchen-worlds/assets/models/OvenCounter/101930/textured_objs/original-28.obj" />/&gt;
			</geometry>
		</collision>
		<collision>
			<origin xyz="0 0 0" />
			<geometry>
				<mesh filename="/home/blake/kitchen-worlds/assets/models/OvenCounter/101930/textured_objs/original-124.obj" />/&gt;
			</geometry>
		</collision>
		<collision>
			<origin xyz="0 0 0" />
			<geometry>
				<mesh filename="/home/blake/kitchen-worlds/assets/models/OvenCounter/101930/textured_objs/original-96.obj" />/&gt;
			</geometry>
		</collision>
		<collision>
			<origin xyz="0 0 0" />
			<geometry>
				<mesh filename="/home/blake/kitchen-worlds/assets/models/OvenCounter/101930/textured_objs/original-64.obj" />/&gt;
			</geometry>
		</collision>
		<collision>
			<origin xyz="0 0 0" />
			<geometry>
				<mesh filename="/home/blake/kitchen-worlds/assets/models/OvenCounter/101930/textured_objs/original-52.obj" />/&gt;
			</geometry>
		</collision>
		<collision>
			<origin xyz="0 0 0" />
			<geometry>
				<mesh filename="/home/blake/kitchen-worlds/assets/models/OvenCounter/101930/textured_objs/original-83.obj" />/&gt;
			</geometry>
		</collision>
		<collision>
			<origin xyz="0 0 0" />
			<geometry>
				<mesh filename="/home/blake/kitchen-worlds/assets/models/OvenCounter/101930/textured_objs/original-117.obj" />/&gt;
			</geometry>
		</collision>
		<collision>
			<origin xyz="0 0 0" />
			<geometry>
				<mesh filename="/home/blake/kitchen-worlds/assets/models/OvenCounter/101930/textured_objs/original-110.obj" />/&gt;
			</geometry>
		</collision>
		<collision>
			<origin xyz="0 0 0" />
			<geometry>
				<mesh filename="/home/blake/kitchen-worlds/assets/models/OvenCounter/101930/textured_objs/original-153.obj" />/&gt;
			</geometry>
		</collision>
		<collision>
			<origin xyz="0 0 0" />
			<geometry>
				<mesh filename="/home/blake/kitchen-worlds/assets/models/OvenCounter/101930/textured_objs/original-107.obj" />/&gt;
			</geometry>
		</collision>
		<collision>
			<origin xyz="0 0 0" />
			<geometry>
				<mesh filename="/home/blake/kitchen-worlds/assets/models/OvenCounter/101930/textured_objs/original-160.obj" />/&gt;
			</geometry>
		</collision>
		<collision>
			<origin xyz="0 0 0" />
			<geometry>
				<mesh filename="/home/blake/kitchen-worlds/assets/models/OvenCounter/101930/textured_objs/original-104.obj" />/&gt;
			</geometry>
		</collision>
		<collision>
			<origin xyz="0 0 0" />
			<geometry>
				<mesh filename="/home/blake/kitchen-worlds/assets/models/OvenCounter/101930/textured_objs/original-128.obj" />/&gt;
			</geometry>
		</collision>
		<collision>
			<origin xyz="0 0 0" />
			<geometry>
				<mesh filename="/home/blake/kitchen-worlds/assets/models/OvenCounter/101930/textured_objs/original-65.obj" />/&gt;
			</geometry>
		</collision>
		<collision>
			<origin xyz="0 0 0" />
			<geometry>
				<mesh filename="/home/blake/kitchen-worlds/assets/models/OvenCounter/101930/textured_objs/original-2.obj" />/&gt;
			</geometry>
		</collision>
		<collision>
			<origin xyz="0 0 0" />
			<geometry>
				<mesh filename="/home/blake/kitchen-worlds/assets/models/OvenCounter/101930/textured_objs/original-44.obj" />/&gt;
			</geometry>
		</collision>
		<collision>
			<origin xyz="0 0 0" />
			<geometry>
				<mesh filename="/home/blake/kitchen-worlds/assets/models/OvenCounter/101930/textured_objs/original-112.obj" />/&gt;
			</geometry>
		</collision>
		<collision>
			<origin xyz="0 0 0" />
			<geometry>
				<mesh filename="/home/blake/kitchen-worlds/assets/models/OvenCounter/101930/textured_objs/original-162.obj" />/&gt;
			</geometry>
		</collision>
		<collision>
			<origin xyz="0 0 0" />
			<geometry>
				<mesh filename="/home/blake/kitchen-worlds/assets/models/OvenCounter/101930/textured_objs/original-106.obj" />/&gt;
			</geometry>
		</collision>
		<collision>
			<origin xyz="0 0 0" />
			<geometry>
				<mesh filename="/home/blake/kitchen-worlds/assets/models/OvenCounter/101930/textured_objs/original-8.obj" />/&gt;
			</geometry>
		</collision>
		<collision>
			<origin xyz="0 0 0" />
			<geometry>
				<mesh filename="/home/blake/kitchen-worlds/assets/models/OvenCounter/101930/textured_objs/original-109.obj" />/&gt;
			</geometry>
		</collision>
		<collision>
			<origin xyz="0 0 0" />
			<geometry>
				<mesh filename="/home/blake/kitchen-worlds/assets/models/OvenCounter/101930/textured_objs/original-125.obj" />/&gt;
			</geometry>
		</collision>
		<collision>
			<origin xyz="0 0 0" />
			<geometry>
				<mesh filename="/home/blake/kitchen-worlds/assets/models/OvenCounter/101930/textured_objs/original-156.obj" />/&gt;
			</geometry>
		</collision>
		<collision>
			<origin xyz="0 0 0" />
			<geometry>
				<mesh filename="/home/blake/kitchen-worlds/assets/models/OvenCounter/101930/textured_objs/original-49.obj" />/&gt;
			</geometry>
		</collision>
		<collision>
			<origin xyz="0 0 0" />
			<geometry>
				<mesh filename="/home/blake/kitchen-worlds/assets/models/OvenCounter/101930/textured_objs/original-93.obj" />/&gt;
			</geometry>
		</collision>
		<collision>
			<origin xyz="0 0 0" />
			<geometry>
				<mesh filename="/home/blake/kitchen-worlds/assets/models/OvenCounter/101930/textured_objs/original-61.obj" />/&gt;
			</geometry>
		</collision>
		<collision>
			<origin xyz="0 0 0" />
			<geometry>
				<mesh filename="/home/blake/kitchen-worlds/assets/models/OvenCounter/101930/textured_objs/original-120.obj" />/&gt;
			</geometry>
		</collision>
		<collision>
			<origin xyz="0 0 0" />
			<geometry>
				<mesh filename="/home/blake/kitchen-worlds/assets/models/OvenCounter/101930/textured_objs/original-59.obj" />/&gt;
			</geometry>
		</collision>
		<collision>
			<origin xyz="0 0 0" />
			<geometry>
				<mesh filename="/home/blake/kitchen-worlds/assets/models/OvenCounter/101930/textured_objs/original-77.obj" />/&gt;
			</geometry>
		</collision>
		<collision>
			<origin xyz="0 0 0" />
			<geometry>
				<mesh filename="/home/blake/kitchen-worlds/assets/models/OvenCounter/101930/textured_objs/original-114.obj" />/&gt;
			</geometry>
		</collision>
		<collision>
			<origin xyz="0 0 0" />
			<geometry>
				<mesh filename="/home/blake/kitchen-worlds/assets/models/OvenCounter/101930/textured_objs/original-54.obj" />/&gt;
			</geometry>
		</collision>
		<collision>
			<origin xyz="0 0 0" />
			<geometry>
				<mesh filename="/home/blake/kitchen-worlds/assets/models/OvenCounter/101930/textured_objs/original-63.obj" />/&gt;
			</geometry>
		</collision>
		<collision>
			<origin xyz="0 0 0" />
			<geometry>
				<mesh filename="/home/blake/kitchen-worlds/assets/models/OvenCounter/101930/textured_objs/original-159.obj" />/&gt;
			</geometry>
		</collision>
		<collision>
			<origin xyz="0 0 0" />
			<geometry>
				<mesh filename="/home/blake/kitchen-worlds/assets/models/OvenCounter/101930/textured_objs/original-87.obj" />/&gt;
			</geometry>
		</collision>
		<collision>
			<origin xyz="0 0 0" />
			<geometry>
				<mesh filename="/home/blake/kitchen-worlds/assets/models/OvenCounter/101930/textured_objs/original-51.obj" />/&gt;
			</geometry>
		</collision>
		<collision>
			<origin xyz="0 0 0" />
			<geometry>
				<mesh filename="/home/blake/kitchen-worlds/assets/models/OvenCounter/101930/textured_objs/original-55.obj" />/&gt;
			</geometry>
		</collision>
		<collision>
			<origin xyz="0 0 0" />
			<geometry>
				<mesh filename="/home/blake/kitchen-worlds/assets/models/OvenCounter/101930/textured_objs/original-163.obj" />/&gt;
			</geometry>
		</collision>
		<collision>
			<origin xyz="0 0 0" />
			<geometry>
				<mesh filename="/home/blake/kitchen-worlds/assets/models/OvenCounter/101930/textured_objs/original-113.obj" />/&gt;
			</geometry>
		</collision>
		<collision>
			<origin xyz="0 0 0" />
			<geometry>
				<mesh filename="/home/blake/kitchen-worlds/assets/models/OvenCounter/101930/textured_objs/original-50.obj" />/&gt;
			</geometry>
		</collision>
		<collision>
			<origin xyz="0 0 0" />
			<geometry>
				<mesh filename="/home/blake/kitchen-worlds/assets/models/OvenCounter/101930/textured_objs/original-111.obj" />/&gt;
			</geometry>
		</collision>
		<collision>
			<origin xyz="0 0 0" />
			<geometry>
				<mesh filename="/home/blake/kitchen-worlds/assets/models/OvenCounter/101930/textured_objs/original-48.obj" />/&gt;
			</geometry>
		</collision>
		<collision>
			<origin xyz="0 0 0" />
			<geometry>
				<mesh filename="/home/blake/kitchen-worlds/assets/models/OvenCounter/101930/textured_objs/original-116.obj" />/&gt;
			</geometry>
		</collision>
		<collision>
			<origin xyz="0 0 0" />
			<geometry>
				<mesh filename="/home/blake/kitchen-worlds/assets/models/OvenCounter/101930/textured_objs/original-85.obj" />/&gt;
			</geometry>
		</collision>
		<collision>
			<origin xyz="0 0 0" />
			<geometry>
				<mesh filename="/home/blake/kitchen-worlds/assets/models/OvenCounter/101930/textured_objs/original-122.obj" />/&gt;
			</geometry>
		</collision>
		<collision>
			<origin xyz="0 0 0" />
			<geometry>
				<mesh filename="/home/blake/kitchen-worlds/assets/models/OvenCounter/101930/textured_objs/original-56.obj" />/&gt;
			</geometry>
		</collision>
		<collision>
			<origin xyz="0 0 0" />
			<geometry>
				<mesh filename="/home/blake/kitchen-worlds/assets/models/OvenCounter/101930/textured_objs/original-76.obj" />/&gt;
			</geometry>
		</collision>
		<collision>
			<origin xyz="0 0 0" />
			<geometry>
				<mesh filename="/home/blake/kitchen-worlds/assets/models/OvenCounter/101930/textured_objs/original-108.obj" />/&gt;
			</geometry>
		</collision>
		<collision>
			<origin xyz="0 0 0" />
			<geometry>
				<mesh filename="/home/blake/kitchen-worlds/assets/models/OvenCounter/101930/textured_objs/original-72.obj" />/&gt;
			</geometry>
		</collision>
		<collision>
			<origin xyz="0 0 0" />
			<geometry>
				<mesh filename="/home/blake/kitchen-worlds/assets/models/OvenCounter/101930/textured_objs/original-99.obj" />/&gt;
			</geometry>
		</collision>
		<collision>
			<origin xyz="0 0 0" />
			<geometry>
				<mesh filename="/home/blake/kitchen-worlds/assets/models/OvenCounter/101930/textured_objs/original-127.obj" />/&gt;
			</geometry>
		</collision>
		<collision>
			<origin xyz="0 0 0" />
			<geometry>
				<mesh filename="/home/blake/kitchen-worlds/assets/models/OvenCounter/101930/textured_objs/original-62.obj" />/&gt;
			</geometry>
		</collision>
		<collision>
			<origin xyz="0 0 0" />
			<geometry>
				<mesh filename="/home/blake/kitchen-worlds/assets/models/OvenCounter/101930/textured_objs/original-75.obj" />/&gt;
			</geometry>
		</collision>
		<collision>
			<origin xyz="0 0 0" />
			<geometry>
				<mesh filename="/home/blake/kitchen-worlds/assets/models/OvenCounter/101930/textured_objs/original-158.obj" />/&gt;
			</geometry>
		</collision>
		<collision>
			<origin xyz="0 0 0" />
			<geometry>
				<mesh filename="/home/blake/kitchen-worlds/assets/models/OvenCounter/101930/textured_objs/original-66.obj" />/&gt;
			</geometry>
		</collision>
		<collision>
			<origin xyz="0 0 0" />
			<geometry>
				<mesh filename="/home/blake/kitchen-worlds/assets/models/OvenCounter/101930/textured_objs/original-58.obj" />/&gt;
			</geometry>
		</collision>
		<collision>
			<origin xyz="0 0 0" />
			<geometry>
				<mesh filename="/home/blake/kitchen-worlds/assets/models/OvenCounter/101930/textured_objs/original-67.obj" />/&gt;
			</geometry>
		</collision>
		<collision>
			<origin xyz="0 0 0" />
			<geometry>
				<mesh filename="/home/blake/kitchen-worlds/assets/models/OvenCounter/101930/textured_objs/original-69.obj" />/&gt;
			</geometry>
		</collision>
		<collision>
			<origin xyz="0 0 0" />
			<geometry>
				<mesh filename="/home/blake/kitchen-worlds/assets/models/OvenCounter/101930/textured_objs/original-11.obj" />/&gt;
			</geometry>
		</collision>
		<collision>
			<origin xyz="0 0 0" />
			<geometry>
				<mesh filename="/home/blake/kitchen-worlds/assets/models/OvenCounter/101930/textured_objs/original-38.obj" />/&gt;
			</geometry>
		</collision>
		<collision>
			<origin xyz="0 0 0" />
			<geometry>
				<mesh filename="/home/blake/kitchen-worlds/assets/models/OvenCounter/101930/textured_objs/original-80.obj" />/&gt;
			</geometry>
		</collision>
		<collision>
			<origin xyz="0 0 0" />
			<geometry>
				<mesh filename="/home/blake/kitchen-worlds/assets/models/OvenCounter/101930/textured_objs/original-161.obj" />/&gt;
			</geometry>
		</collision>
		<collision>
			<origin xyz="0 0 0" />
			<geometry>
				<mesh filename="/home/blake/kitchen-worlds/assets/models/OvenCounter/101930/textured_objs/original-74.obj" />/&gt;
			</geometry>
		</collision>
		<collision>
			<origin xyz="0 0 0" />
			<geometry>
				<mesh filename="/home/blake/kitchen-worlds/assets/models/OvenCounter/101930/textured_objs/original-118.obj" />/&gt;
			</geometry>
		</collision>
		<collision>
			<origin xyz="0 0 0" />
			<geometry>
				<mesh filename="/home/blake/kitchen-worlds/assets/models/OvenCounter/101930/textured_objs/original-91.obj" />/&gt;
			</geometry>
		</collision>
		<collision>
			<origin xyz="0 0 0" />
			<geometry>
				<mesh filename="/home/blake/kitchen-worlds/assets/models/OvenCounter/101930/textured_objs/original-25.obj" />/&gt;
			</geometry>
		</collision>
		<collision>
			<origin xyz="0 0 0" />
			<geometry>
				<mesh filename="/home/blake/kitchen-worlds/assets/models/OvenCounter/101930/textured_objs/original-73.obj" />/&gt;
			</geometry>
		</collision>
		<collision>
			<origin xyz="0 0 0" />
			<geometry>
				<mesh filename="/home/blake/kitchen-worlds/assets/models/OvenCounter/101930/textured_objs/original-12.obj" />/&gt;
			</geometry>
		</collision>
		<collision>
			<origin xyz="0 0 0" />
			<geometry>
				<mesh filename="/home/blake/kitchen-worlds/assets/models/OvenCounter/101930/textured_objs/original-92.obj" />/&gt;
			</geometry>
		</collision>
		<collision>
			<origin xyz="0 0 0" />
			<geometry>
				<mesh filename="/home/blake/kitchen-worlds/assets/models/OvenCounter/101930/textured_objs/original-42.obj" />/&gt;
			</geometry>
		</collision>
		<collision>
			<origin xyz="0 0 0" />
			<geometry>
				<mesh filename="/home/blake/kitchen-worlds/assets/models/OvenCounter/101930/textured_objs/original-79.obj" />/&gt;
			</geometry>
		</collision>
		<collision>
			<origin xyz="0 0 0" />
			<geometry>
				<mesh filename="/home/blake/kitchen-worlds/assets/models/OvenCounter/101930/textured_objs/original-102.obj" />/&gt;
			</geometry>
		</collision>
		<collision>
			<origin xyz="0 0 0" />
			<geometry>
				<mesh filename="/home/blake/kitchen-worlds/assets/models/OvenCounter/101930/textured_objs/original-88.obj" />/&gt;
			</geometry>
		</collision>
		<collision>
			<origin xyz="0 0 0" />
			<geometry>
				<mesh filename="/home/blake/kitchen-worlds/assets/models/OvenCounter/101930/textured_objs/original-115.obj" />/&gt;
			</geometry>
		</collision>
		<collision>
			<origin xyz="0 0 0" />
			<geometry>
				<mesh filename="/home/blake/kitchen-worlds/assets/models/OvenCounter/101930/textured_objs/original-47.obj" />/&gt;
			</geometry>
		</collision>
		<collision>
			<origin xyz="0 0 0" />
			<geometry>
				<mesh filename="/home/blake/kitchen-worlds/assets/models/OvenCounter/101930/textured_objs/original-53.obj" />/&gt;
			</geometry>
		</collision>
		<collision>
			<origin xyz="0 0 0" />
			<geometry>
				<mesh filename="/home/blake/kitchen-worlds/assets/models/OvenCounter/101930/textured_objs/original-7.obj" />/&gt;
			</geometry>
		</collision>
		<collision>
			<origin xyz="0 0 0" />
			<geometry>
				<mesh filename="/home/blake/kitchen-worlds/assets/models/OvenCounter/101930/textured_objs/original-105.obj" />/&gt;
			</geometry>
		</collision>
		<collision>
			<origin xyz="0 0 0" />
			<geometry>
				<mesh filename="/home/blake/kitchen-worlds/assets/models/OvenCounter/101930/textured_objs/original-101.obj" />/&gt;
			</geometry>
		</collision>
		<collision>
			<origin xyz="0 0 0" />
			<geometry>
				<mesh filename="/home/blake/kitchen-worlds/assets/models/OvenCounter/101930/textured_objs/original-81.obj" />/&gt;
			</geometry>
		</collision>
		<collision>
			<origin xyz="0 0 0" />
			<geometry>
				<mesh filename="/home/blake/kitchen-worlds/assets/models/OvenCounter/101930/textured_objs/original-84.obj" />/&gt;
			</geometry>
		</collision>
		<collision>
			<origin xyz="0 0 0" />
			<geometry>
				<mesh filename="/home/blake/kitchen-worlds/assets/models/OvenCounter/101930/textured_objs/original-121.obj" />/&gt;
			</geometry>
		</collision>
		<collision>
			<origin xyz="0 0 0" />
			<geometry>
				<mesh filename="/home/blake/kitchen-worlds/assets/models/OvenCounter/101930/textured_objs/original-94.obj" />/&gt;
			</geometry>
		</collision>
		<collision>
			<origin xyz="0 0 0" />
			<geometry>
				<mesh filename="/home/blake/kitchen-worlds/assets/models/OvenCounter/101930/textured_objs/original-78.obj" />/&gt;
			</geometry>
		</collision>
		<collision>
			<origin xyz="0 0 0" />
			<geometry>
				<mesh filename="/home/blake/kitchen-worlds/assets/models/OvenCounter/101930/textured_objs/original-97.obj" />/&gt;
			</geometry>
		</collision>
		<collision>
			<origin xyz="0 0 0" />
			<geometry>
				<mesh filename="/home/blake/kitchen-worlds/assets/models/OvenCounter/101930/textured_objs/original-157.obj" />/&gt;
			</geometry>
		</collision>
		<collision>
			<origin xyz="0 0 0" />
			<geometry>
				<mesh filename="/home/blake/kitchen-worlds/assets/models/OvenCounter/101930/textured_objs/original-89.obj" />/&gt;
			</geometry>
		</collision>
		<collision>
			<origin xyz="0 0 0" />
			<geometry>
				<mesh filename="/home/blake/kitchen-worlds/assets/models/OvenCounter/101930/textured_objs/original-60.obj" />/&gt;
			</geometry>
		</collision>
		<collision>
			<origin xyz="0 0 0" />
			<geometry>
				<mesh filename="/home/blake/kitchen-worlds/assets/models/OvenCounter/101930/textured_objs/original-90.obj" />/&gt;
			</geometry>
		</collision>
		<collision>
			<origin xyz="0 0 0" />
			<geometry>
				<mesh filename="/home/blake/kitchen-worlds/assets/models/OvenCounter/101930/textured_objs/original-155.obj" />/&gt;
			</geometry>
		</collision>
		<collision>
			<origin xyz="0 0 0" />
			<geometry>
				<mesh filename="/home/blake/kitchen-worlds/assets/models/OvenCounter/101930/textured_objs/original-164.obj" />/&gt;
			</geometry>
		</collision>
	</link>
	<joint name="joint_7" type="fixed">
		<origin rpy="1.570796326794897 0 -1.570796326794897" xyz="0 0 0" />
		<child link="link_7" />
		<parent link="base" />
	</joint>
</robot>