<?xml version='1.0' encoding='utf-8'?>
<robot name="partnet_bdb10a17b04e2adbb7fb7f3ae74b618c">
	<link name="base" />
	<link name="link_0">
		<visual name="tray-25">
			<origin xyz="-0.025444607839528954 -0.5448650121688843 0.06190252020474296" />
			<geometry>
				<mesh filename="/home/blake/kitchen-worlds/assets/models/MicrowaveHanging/7296/textured_objs/original-8.obj" />/&gt;
			</geometry>
		</visual>
		<collision>
			<origin xyz="-0.025444607839528954 -0.5448650121688843 0.06190252020474296" />
			<geometry>
				<mesh filename="/home/blake/kitchen-worlds/assets/models/MicrowaveHanging/7296/textured_objs/original-8.obj" />/&gt;
			</geometry>
		</collision>
	</link>
	<joint name="joint_0" type="continuous">
		<origin xyz="0.025444607839528954 0.5448650121688843 -0.06190252020474296" />
		<axis xyz="0 1 0" />
		<child link="link_0" />
		<parent link="link_3" />
	</joint>
	<link name="link_1">
		<visual name="door_frame-11">
			<origin xyz="0.6241578416021474 0.48033899068832375 -0.46202588951920875" />
			<geometry>
				<mesh filename="/home/blake/kitchen-worlds/assets/models/MicrowaveHanging/7296/textured_objs/original-2.obj" />/&gt;
			</geometry>
		</visual>
		<visual name="door_frame-11">
			<origin xyz="0.6241578416021474 0.48033899068832375 -0.46202588951920875" />
			<geometry>
				<mesh filename="/home/blake/kitchen-worlds/assets/models/MicrowaveHanging/7296/textured_objs/original-4.obj" />/&gt;
			</geometry>
		</visual>
		<visual name="glass-12">
			<origin xyz="0.6241578416021474 0.48033899068832375 -0.46202588951920875" />
			<geometry>
				<mesh filename="/home/blake/kitchen-worlds/assets/models/MicrowaveHanging/7296/textured_objs/original-3.obj" />/&gt;
			</geometry>
		</visual>
		<collision>
			<origin xyz="0.6241578416021474 0.48033899068832375 -0.46202588951920875" />
			<geometry>
				<mesh filename="/home/blake/kitchen-worlds/assets/models/MicrowaveHanging/7296/textured_objs/original-2.obj" />/&gt;
			</geometry>
		</collision>
		<collision>
			<origin xyz="0.6241578416021474 0.48033899068832375 -0.46202588951920875" />
			<geometry>
				<mesh filename="/home/blake/kitchen-worlds/assets/models/MicrowaveHanging/7296/textured_objs/original-4.obj" />/&gt;
			</geometry>
		</collision>
		<collision>
			<origin xyz="0.6241578416021474 0.48033899068832375 -0.46202588951920875" />
			<geometry>
				<mesh filename="/home/blake/kitchen-worlds/assets/models/MicrowaveHanging/7296/textured_objs/original-3.obj" />/&gt;
			</geometry>
		</collision>
	</link>
	<joint name="joint_1" type="revolute">
		<origin xyz="-0.6241578416021474 -0.48033899068832375 0.46202588951920875" />
		<axis xyz="0 -1 0" />
		<child link="link_1" />
		<parent link="link_3" />
		<limit lower="0.0" upper="1.5707963267948966" effort="10.0" velocity="1.0" />
	</joint>
	<link name="link_2">
		<visual name="control_button-13">
			<origin xyz="-0.5966922340006632 0.004540807810886949 -0.571964979171753" />
			<geometry>
				<mesh filename="/home/blake/kitchen-worlds/assets/models/MicrowaveHanging/7296/textured_objs/original-22.obj" />/&gt;
			</geometry>
		</visual>
		<visual name="control_button-13">
			<origin xyz="-0.5966922340006632 0.004540807810886949 -0.571964979171753" />
			<geometry>
				<mesh filename="/home/blake/kitchen-worlds/assets/models/MicrowaveHanging/7296/textured_objs/original-21.obj" />/&gt;
			</geometry>
		</visual>
		<collision>
			<origin xyz="-0.5966922340006632 0.004540807810886949 -0.571964979171753" />
			<geometry>
				<mesh filename="/home/blake/kitchen-worlds/assets/models/MicrowaveHanging/7296/textured_objs/original-22.obj" />/&gt;
			</geometry>
		</collision>
		<collision>
			<origin xyz="-0.5966922340006632 0.004540807810886949 -0.571964979171753" />
			<geometry>
				<mesh filename="/home/blake/kitchen-worlds/assets/models/MicrowaveHanging/7296/textured_objs/original-21.obj" />/&gt;
			</geometry>
		</collision>
	</link>
	<joint name="joint_2" type="continuous">
		<origin xyz="0.5966922340006632 -0.004540807810886949 0.571964979171753" />
		<axis xyz="0 0 -1" />
		<child link="link_2" />
		<parent link="link_3" />
	</joint>
	<link name="link_3">
		<visual name="frame-8">
			<origin xyz="0 0 0" />
			<geometry>
				<mesh filename="/home/blake/kitchen-worlds/assets/models/MicrowaveHanging/7296/textured_objs/original-15.obj" />/&gt;
			</geometry>
		</visual>
		<visual name="frame-8">
			<origin xyz="0 0 0" />
			<geometry>
				<mesh filename="/home/blake/kitchen-worlds/assets/models/MicrowaveHanging/7296/textured_objs/original-1.obj" />/&gt;
			</geometry>
		</visual>
		<visual name="frame-8">
			<origin xyz="0 0 0" />
			<geometry>
				<mesh filename="/home/blake/kitchen-worlds/assets/models/MicrowaveHanging/7296/textured_objs/original-16.obj" />/&gt;
			</geometry>
		</visual>
		<visual name="frame-8">
			<origin xyz="0 0 0" />
			<geometry>
				<mesh filename="/home/blake/kitchen-worlds/assets/models/MicrowaveHanging/7296/textured_objs/original-6.obj" />/&gt;
			</geometry>
		</visual>
		<visual name="frame-8">
			<origin xyz="0 0 0" />
			<geometry>
				<mesh filename="/home/blake/kitchen-worlds/assets/models/MicrowaveHanging/7296/textured_objs/original-5.obj" />/&gt;
			</geometry>
		</visual>
		<visual name="frame-8">
			<origin xyz="0 0 0" />
			<geometry>
				<mesh filename="/home/blake/kitchen-worlds/assets/models/MicrowaveHanging/7296/textured_objs/original-7.obj" />/&gt;
			</geometry>
		</visual>
		<visual name="frame-8">
			<origin xyz="0 0 0" />
			<geometry>
				<mesh filename="/home/blake/kitchen-worlds/assets/models/MicrowaveHanging/7296/textured_objs/original-18.obj" />/&gt;
			</geometry>
		</visual>
		<visual name="frame-8">
			<origin xyz="0 0 0" />
			<geometry>
				<mesh filename="/home/blake/kitchen-worlds/assets/models/MicrowaveHanging/7296/textured_objs/original-9.obj" />/&gt;
			</geometry>
		</visual>
		<visual name="foot-4">
			<origin xyz="0 0 0" />
			<geometry>
				<mesh filename="/home/blake/kitchen-worlds/assets/models/MicrowaveHanging/7296/textured_objs/original-12.obj" />/&gt;
			</geometry>
		</visual>
		<visual name="foot-4">
			<origin xyz="0 0 0" />
			<geometry>
				<mesh filename="/home/blake/kitchen-worlds/assets/models/MicrowaveHanging/7296/textured_objs/original-11.obj" />/&gt;
			</geometry>
		</visual>
		<visual name="foot-5">
			<origin xyz="0 0 0" />
			<geometry>
				<mesh filename="/home/blake/kitchen-worlds/assets/models/MicrowaveHanging/7296/textured_objs/original-10.obj" />/&gt;
			</geometry>
		</visual>
		<visual name="foot-6">
			<origin xyz="0 0 0" />
			<geometry>
				<mesh filename="/home/blake/kitchen-worlds/assets/models/MicrowaveHanging/7296/textured_objs/original-14.obj" />/&gt;
			</geometry>
		</visual>
		<visual name="foot-7">
			<origin xyz="0 0 0" />
			<geometry>
				<mesh filename="/home/blake/kitchen-worlds/assets/models/MicrowaveHanging/7296/textured_objs/original-39.obj" />/&gt;
			</geometry>
		</visual>
		<visual name="foot-7">
			<origin xyz="0 0 0" />
			<geometry>
				<mesh filename="/home/blake/kitchen-worlds/assets/models/MicrowaveHanging/7296/textured_objs/original-13.obj" />/&gt;
			</geometry>
		</visual>
		<visual name="control_button-14">
			<origin xyz="0 0 0" />
			<geometry>
				<mesh filename="/home/blake/kitchen-worlds/assets/models/MicrowaveHanging/7296/textured_objs/original-38.obj" />/&gt;
			</geometry>
		</visual>
		<visual name="control_button-14">
			<origin xyz="0 0 0" />
			<geometry>
				<mesh filename="/home/blake/kitchen-worlds/assets/models/MicrowaveHanging/7296/textured_objs/original-37.obj" />/&gt;
			</geometry>
		</visual>
		<visual name="control_button-15">
			<origin xyz="0 0 0" />
			<geometry>
				<mesh filename="/home/blake/kitchen-worlds/assets/models/MicrowaveHanging/7296/textured_objs/original-35.obj" />/&gt;
			</geometry>
		</visual>
		<visual name="control_button-15">
			<origin xyz="0 0 0" />
			<geometry>
				<mesh filename="/home/blake/kitchen-worlds/assets/models/MicrowaveHanging/7296/textured_objs/original-36.obj" />/&gt;
			</geometry>
		</visual>
		<visual name="control_button-16">
			<origin xyz="0 0 0" />
			<geometry>
				<mesh filename="/home/blake/kitchen-worlds/assets/models/MicrowaveHanging/7296/textured_objs/original-33.obj" />/&gt;
			</geometry>
		</visual>
		<visual name="control_button-16">
			<origin xyz="0 0 0" />
			<geometry>
				<mesh filename="/home/blake/kitchen-worlds/assets/models/MicrowaveHanging/7296/textured_objs/original-34.obj" />/&gt;
			</geometry>
		</visual>
		<visual name="control_button-17">
			<origin xyz="0 0 0" />
			<geometry>
				<mesh filename="/home/blake/kitchen-worlds/assets/models/MicrowaveHanging/7296/textured_objs/original-31.obj" />/&gt;
			</geometry>
		</visual>
		<visual name="control_button-17">
			<origin xyz="0 0 0" />
			<geometry>
				<mesh filename="/home/blake/kitchen-worlds/assets/models/MicrowaveHanging/7296/textured_objs/original-32.obj" />/&gt;
			</geometry>
		</visual>
		<visual name="control_button-18">
			<origin xyz="0 0 0" />
			<geometry>
				<mesh filename="/home/blake/kitchen-worlds/assets/models/MicrowaveHanging/7296/textured_objs/original-29.obj" />/&gt;
			</geometry>
		</visual>
		<visual name="control_button-18">
			<origin xyz="0 0 0" />
			<geometry>
				<mesh filename="/home/blake/kitchen-worlds/assets/models/MicrowaveHanging/7296/textured_objs/original-30.obj" />/&gt;
			</geometry>
		</visual>
		<visual name="control_button-19">
			<origin xyz="0 0 0" />
			<geometry>
				<mesh filename="/home/blake/kitchen-worlds/assets/models/MicrowaveHanging/7296/textured_objs/original-27.obj" />/&gt;
			</geometry>
		</visual>
		<visual name="control_button-19">
			<origin xyz="0 0 0" />
			<geometry>
				<mesh filename="/home/blake/kitchen-worlds/assets/models/MicrowaveHanging/7296/textured_objs/original-28.obj" />/&gt;
			</geometry>
		</visual>
		<visual name="control_button-20">
			<origin xyz="0 0 0" />
			<geometry>
				<mesh filename="/home/blake/kitchen-worlds/assets/models/MicrowaveHanging/7296/textured_objs/original-25.obj" />/&gt;
			</geometry>
		</visual>
		<visual name="control_button-20">
			<origin xyz="0 0 0" />
			<geometry>
				<mesh filename="/home/blake/kitchen-worlds/assets/models/MicrowaveHanging/7296/textured_objs/original-26.obj" />/&gt;
			</geometry>
		</visual>
		<visual name="control_button-21">
			<origin xyz="0 0 0" />
			<geometry>
				<mesh filename="/home/blake/kitchen-worlds/assets/models/MicrowaveHanging/7296/textured_objs/original-24.obj" />/&gt;
			</geometry>
		</visual>
		<visual name="control_button-21">
			<origin xyz="0 0 0" />
			<geometry>
				<mesh filename="/home/blake/kitchen-worlds/assets/models/MicrowaveHanging/7296/textured_objs/original-23.obj" />/&gt;
			</geometry>
		</visual>
		<visual name="control_button-22">
			<origin xyz="0 0 0" />
			<geometry>
				<mesh filename="/home/blake/kitchen-worlds/assets/models/MicrowaveHanging/7296/textured_objs/original-20.obj" />/&gt;
			</geometry>
		</visual>
		<visual name="control_button-22">
			<origin xyz="0 0 0" />
			<geometry>
				<mesh filename="/home/blake/kitchen-worlds/assets/models/MicrowaveHanging/7296/textured_objs/original-19.obj" />/&gt;
			</geometry>
		</visual>
		<visual name="display_panel-23">
			<origin xyz="0 0 0" />
			<geometry>
				<mesh filename="/home/blake/kitchen-worlds/assets/models/MicrowaveHanging/7296/textured_objs/original-17.obj" />/&gt;
			</geometry>
		</visual>
		<collision>
			<origin xyz="0 0 0" />
			<geometry>
				<mesh filename="/home/blake/kitchen-worlds/assets/models/MicrowaveHanging/7296/textured_objs/original-15.obj" />/&gt;
			</geometry>
		</collision>
		<collision>
			<origin xyz="0 0 0" />
			<geometry>
				<mesh filename="/home/blake/kitchen-worlds/assets/models/MicrowaveHanging/7296/textured_objs/original-1.obj" />/&gt;
			</geometry>
		</collision>
		<collision>
			<origin xyz="0 0 0" />
			<geometry>
				<mesh filename="/home/blake/kitchen-worlds/assets/models/MicrowaveHanging/7296/textured_objs/original-16.obj" />/&gt;
			</geometry>
		</collision>
		<collision>
			<origin xyz="0 0 0" />
			<geometry>
				<mesh filename="/home/blake/kitchen-worlds/assets/models/MicrowaveHanging/7296/textured_objs/original-6.obj" />/&gt;
			</geometry>
		</collision>
		<collision>
			<origin xyz="0 0 0" />
			<geometry>
				<mesh filename="/home/blake/kitchen-worlds/assets/models/MicrowaveHanging/7296/textured_objs/original-5.obj" />/&gt;
			</geometry>
		</collision>
		<collision>
			<origin xyz="0 0 0" />
			<geometry>
				<mesh filename="/home/blake/kitchen-worlds/assets/models/MicrowaveHanging/7296/textured_objs/original-7.obj" />/&gt;
			</geometry>
		</collision>
		<collision>
			<origin xyz="0 0 0" />
			<geometry>
				<mesh filename="/home/blake/kitchen-worlds/assets/models/MicrowaveHanging/7296/textured_objs/original-18.obj" />/&gt;
			</geometry>
		</collision>
		<collision>
			<origin xyz="0 0 0" />
			<geometry>
				<mesh filename="/home/blake/kitchen-worlds/assets/models/MicrowaveHanging/7296/textured_objs/original-9.obj" />/&gt;
			</geometry>
		</collision>
		<collision>
			<origin xyz="0 0 0" />
			<geometry>
				<mesh filename="/home/blake/kitchen-worlds/assets/models/MicrowaveHanging/7296/textured_objs/original-12.obj" />/&gt;
			</geometry>
		</collision>
		<collision>
			<origin xyz="0 0 0" />
			<geometry>
				<mesh filename="/home/blake/kitchen-worlds/assets/models/MicrowaveHanging/7296/textured_objs/original-11.obj" />/&gt;
			</geometry>
		</collision>
		<collision>
			<origin xyz="0 0 0" />
			<geometry>
				<mesh filename="/home/blake/kitchen-worlds/assets/models/MicrowaveHanging/7296/textured_objs/original-10.obj" />/&gt;
			</geometry>
		</collision>
		<collision>
			<origin xyz="0 0 0" />
			<geometry>
				<mesh filename="/home/blake/kitchen-worlds/assets/models/MicrowaveHanging/7296/textured_objs/original-14.obj" />/&gt;
			</geometry>
		</collision>
		<collision>
			<origin xyz="0 0 0" />
			<geometry>
				<mesh filename="/home/blake/kitchen-worlds/assets/models/MicrowaveHanging/7296/textured_objs/original-39.obj" />/&gt;
			</geometry>
		</collision>
		<collision>
			<origin xyz="0 0 0" />
			<geometry>
				<mesh filename="/home/blake/kitchen-worlds/assets/models/MicrowaveHanging/7296/textured_objs/original-13.obj" />/&gt;
			</geometry>
		</collision>
		<collision>
			<origin xyz="0 0 0" />
			<geometry>
				<mesh filename="/home/blake/kitchen-worlds/assets/models/MicrowaveHanging/7296/textured_objs/original-38.obj" />/&gt;
			</geometry>
		</collision>
		<collision>
			<origin xyz="0 0 0" />
			<geometry>
				<mesh filename="/home/blake/kitchen-worlds/assets/models/MicrowaveHanging/7296/textured_objs/original-37.obj" />/&gt;
			</geometry>
		</collision>
		<collision>
			<origin xyz="0 0 0" />
			<geometry>
				<mesh filename="/home/blake/kitchen-worlds/assets/models/MicrowaveHanging/7296/textured_objs/original-35.obj" />/&gt;
			</geometry>
		</collision>
		<collision>
			<origin xyz="0 0 0" />
			<geometry>
				<mesh filename="/home/blake/kitchen-worlds/assets/models/MicrowaveHanging/7296/textured_objs/original-36.obj" />/&gt;
			</geometry>
		</collision>
		<collision>
			<origin xyz="0 0 0" />
			<geometry>
				<mesh filename="/home/blake/kitchen-worlds/assets/models/MicrowaveHanging/7296/textured_objs/original-33.obj" />/&gt;
			</geometry>
		</collision>
		<collision>
			<origin xyz="0 0 0" />
			<geometry>
				<mesh filename="/home/blake/kitchen-worlds/assets/models/MicrowaveHanging/7296/textured_objs/original-34.obj" />/&gt;
			</geometry>
		</collision>
		<collision>
			<origin xyz="0 0 0" />
			<geometry>
				<mesh filename="/home/blake/kitchen-worlds/assets/models/MicrowaveHanging/7296/textured_objs/original-31.obj" />/&gt;
			</geometry>
		</collision>
		<collision>
			<origin xyz="0 0 0" />
			<geometry>
				<mesh filename="/home/blake/kitchen-worlds/assets/models/MicrowaveHanging/7296/textured_objs/original-32.obj" />/&gt;
			</geometry>
		</collision>
		<collision>
			<origin xyz="0 0 0" />
			<geometry>
				<mesh filename="/home/blake/kitchen-worlds/assets/models/MicrowaveHanging/7296/textured_objs/original-29.obj" />/&gt;
			</geometry>
		</collision>
		<collision>
			<origin xyz="0 0 0" />
			<geometry>
				<mesh filename="/home/blake/kitchen-worlds/assets/models/MicrowaveHanging/7296/textured_objs/original-30.obj" />/&gt;
			</geometry>
		</collision>
		<collision>
			<origin xyz="0 0 0" />
			<geometry>
				<mesh filename="/home/blake/kitchen-worlds/assets/models/MicrowaveHanging/7296/textured_objs/original-27.obj" />/&gt;
			</geometry>
		</collision>
		<collision>
			<origin xyz="0 0 0" />
			<geometry>
				<mesh filename="/home/blake/kitchen-worlds/assets/models/MicrowaveHanging/7296/textured_objs/original-28.obj" />/&gt;
			</geometry>
		</collision>
		<collision>
			<origin xyz="0 0 0" />
			<geometry>
				<mesh filename="/home/blake/kitchen-worlds/assets/models/MicrowaveHanging/7296/textured_objs/original-25.obj" />/&gt;
			</geometry>
		</collision>
		<collision>
			<origin xyz="0 0 0" />
			<geometry>
				<mesh filename="/home/blake/kitchen-worlds/assets/models/MicrowaveHanging/7296/textured_objs/original-26.obj" />/&gt;
			</geometry>
		</collision>
		<collision>
			<origin xyz="0 0 0" />
			<geometry>
				<mesh filename="/home/blake/kitchen-worlds/assets/models/MicrowaveHanging/7296/textured_objs/original-24.obj" />/&gt;
			</geometry>
		</collision>
		<collision>
			<origin xyz="0 0 0" />
			<geometry>
				<mesh filename="/home/blake/kitchen-worlds/assets/models/MicrowaveHanging/7296/textured_objs/original-23.obj" />/&gt;
			</geometry>
		</collision>
		<collision>
			<origin xyz="0 0 0" />
			<geometry>
				<mesh filename="/home/blake/kitchen-worlds/assets/models/MicrowaveHanging/7296/textured_objs/original-20.obj" />/&gt;
			</geometry>
		</collision>
		<collision>
			<origin xyz="0 0 0" />
			<geometry>
				<mesh filename="/home/blake/kitchen-worlds/assets/models/MicrowaveHanging/7296/textured_objs/original-19.obj" />/&gt;
			</geometry>
		</collision>
		<collision>
			<origin xyz="0 0 0" />
			<geometry>
				<mesh filename="/home/blake/kitchen-worlds/assets/models/MicrowaveHanging/7296/textured_objs/original-17.obj" />/&gt;
			</geometry>
		</collision>
	</link>
	<joint name="joint_3" type="fixed">
		<origin rpy="1.570796326794897 0 -1.570796326794897" xyz="0 0 0" />
		<child link="link_3" />
		<parent link="base" />
	</joint>
</robot>