<?xml version='1.0' encoding='utf-8'?>
<robot name="partnet_60d7e8aba1f692a8c2185cc0ca1b306b">
	<link name="base" />
	<link name="link_0">
		<visual name="cabinet_door_surface-7">
			<origin xyz="-0.3639398108362385 0 -0.20719063543893496" />
			<geometry>
				<mesh filename="/home/blake/kitchen-worlds/assets/models/Cupboard/46563/textured_objs/original-6.obj" />/&gt;
			</geometry>
		</visual>
		<visual name="cabinet_door_surface-7">
			<origin xyz="-0.3639398108362385 0 -0.20719063543893496" />
			<geometry>
				<mesh filename="/home/blake/kitchen-worlds/assets/models/Cupboard/46563/textured_objs/original-16.obj" />/&gt;
			</geometry>
		</visual>
		<collision>
			<origin xyz="-0.3639398108362385 0 -0.20719063543893496" />
			<geometry>
				<mesh filename="/home/blake/kitchen-worlds/assets/models/Cupboard/46563/textured_objs/original-6.obj" />/&gt;
			</geometry>
		</collision>
		<collision>
			<origin xyz="-0.3639398108362385 0 -0.20719063543893496" />
			<geometry>
				<mesh filename="/home/blake/kitchen-worlds/assets/models/Cupboard/46563/textured_objs/original-16.obj" />/&gt;
			</geometry>
		</collision>
	</link>
	<joint name="joint_0" type="revolute">
		<origin xyz="0.3639398108362385 0 0.20719063543893496" />
		<axis xyz="0 1 0" />
		<child link="link_0" />
		<parent link="link_2" />
		<limit lower="0.0" upper="1.5707963267948966" effort="10.0" velocity="1.0" />
	</joint>
	<link name="link_1">
		<visual name="cabinet_door_surface-6">
			<origin xyz="0.36868020266827917 0 -0.21707589132878638" />
			<geometry>
				<mesh filename="/home/blake/kitchen-worlds/assets/models/Cupboard/46563/textured_objs/original-5.obj" />/&gt;
			</geometry>
		</visual>
		<visual name="cabinet_door_surface-6">
			<origin xyz="0.36868020266827917 0 -0.21707589132878638" />
			<geometry>
				<mesh filename="/home/blake/kitchen-worlds/assets/models/Cupboard/46563/textured_objs/original-9.obj" />/&gt;
			</geometry>
		</visual>
		<collision>
			<origin xyz="0.36868020266827917 0 -0.21707589132878638" />
			<geometry>
				<mesh filename="/home/blake/kitchen-worlds/assets/models/Cupboard/46563/textured_objs/original-5.obj" />/&gt;
			</geometry>
		</collision>
		<collision>
			<origin xyz="0.36868020266827917 0 -0.21707589132878638" />
			<geometry>
				<mesh filename="/home/blake/kitchen-worlds/assets/models/Cupboard/46563/textured_objs/original-9.obj" />/&gt;
			</geometry>
		</collision>
	</link>
	<joint name="joint_1" type="revolute">
		<origin xyz="-0.36868020266827917 0 0.21707589132878638" />
		<axis xyz="0 -1 0" />
		<child link="link_1" />
		<parent link="link_2" />
		<limit lower="-0.0" upper="1.5707963267948966" effort="10.0" velocity="1.0" />
	</joint>
	<link name="link_2">
		<visual name="vertical_side_panel-17">
			<origin xyz="0 0 0" />
			<geometry>
				<mesh filename="/home/blake/kitchen-worlds/assets/models/Cupboard/46563/textured_objs/original-7.obj" />/&gt;
			</geometry>
		</visual>
		<visual name="vertical_side_panel-18">
			<origin xyz="0 0 0" />
			<geometry>
				<mesh filename="/home/blake/kitchen-worlds/assets/models/Cupboard/46563/textured_objs/original-8.obj" />/&gt;
			</geometry>
		</visual>
		<visual name="back_panel-19">
			<origin xyz="0 0 0" />
			<geometry>
				<mesh filename="/home/blake/kitchen-worlds/assets/models/Cupboard/46563/textured_objs/original-4.obj" />/&gt;
			</geometry>
		</visual>
		<visual name="bottom_panel-20">
			<origin xyz="0 0 0" />
			<geometry>
				<mesh filename="/home/blake/kitchen-worlds/assets/models/Cupboard/46563/textured_objs/original-1.obj" />/&gt;
			</geometry>
		</visual>
		<visual name="top_panel-21">
			<origin xyz="0 0 0" />
			<geometry>
				<mesh filename="/home/blake/kitchen-worlds/assets/models/Cupboard/46563/textured_objs/original-2.obj" />/&gt;
			</geometry>
		</visual>
		<visual name="foot-9">
			<origin xyz="0 0 0" />
			<geometry>
				<mesh filename="/home/blake/kitchen-worlds/assets/models/Cupboard/46563/textured_objs/original-12.obj" />/&gt;
			</geometry>
		</visual>
		<visual name="foot-10">
			<origin xyz="0 0 0" />
			<geometry>
				<mesh filename="/home/blake/kitchen-worlds/assets/models/Cupboard/46563/textured_objs/original-11.obj" />/&gt;
			</geometry>
		</visual>
		<visual name="foot-11">
			<origin xyz="0 0 0" />
			<geometry>
				<mesh filename="/home/blake/kitchen-worlds/assets/models/Cupboard/46563/textured_objs/original-10.obj" />/&gt;
			</geometry>
		</visual>
		<visual name="foot-12">
			<origin xyz="0 0 0" />
			<geometry>
				<mesh filename="/home/blake/kitchen-worlds/assets/models/Cupboard/46563/textured_objs/original-15.obj" />/&gt;
			</geometry>
		</visual>
		<visual name="foot-13">
			<origin xyz="0 0 0" />
			<geometry>
				<mesh filename="/home/blake/kitchen-worlds/assets/models/Cupboard/46563/textured_objs/original-13.obj" />/&gt;
			</geometry>
		</visual>
		<visual name="foot-14">
			<origin xyz="0 0 0" />
			<geometry>
				<mesh filename="/home/blake/kitchen-worlds/assets/models/Cupboard/46563/textured_objs/original-14.obj" />/&gt;
			</geometry>
		</visual>
		<visual name="other_leaf-16">
			<origin xyz="0 0 0" />
			<geometry>
				<mesh filename="/home/blake/kitchen-worlds/assets/models/Cupboard/46563/textured_objs/original-3.obj" />/&gt;
			</geometry>
		</visual>
		<collision>
			<origin xyz="0 0 0" />
			<geometry>
				<mesh filename="/home/blake/kitchen-worlds/assets/models/Cupboard/46563/textured_objs/original-7.obj" />/&gt;
			</geometry>
		</collision>
		<collision>
			<origin xyz="0 0 0" />
			<geometry>
				<mesh filename="/home/blake/kitchen-worlds/assets/models/Cupboard/46563/textured_objs/original-8.obj" />/&gt;
			</geometry>
		</collision>
		<collision>
			<origin xyz="0 0 0" />
			<geometry>
				<mesh filename="/home/blake/kitchen-worlds/assets/models/Cupboard/46563/textured_objs/original-4.obj" />/&gt;
			</geometry>
		</collision>
		<collision>
			<origin xyz="0 0 0" />
			<geometry>
				<mesh filename="/home/blake/kitchen-worlds/assets/models/Cupboard/46563/textured_objs/original-1.obj" />/&gt;
			</geometry>
		</collision>
		<collision>
			<origin xyz="0 0 0" />
			<geometry>
				<mesh filename="/home/blake/kitchen-worlds/assets/models/Cupboard/46563/textured_objs/original-2.obj" />/&gt;
			</geometry>
		</collision>
		<collision>
			<origin xyz="0 0 0" />
			<geometry>
				<mesh filename="/home/blake/kitchen-worlds/assets/models/Cupboard/46563/textured_objs/original-12.obj" />/&gt;
			</geometry>
		</collision>
		<collision>
			<origin xyz="0 0 0" />
			<geometry>
				<mesh filename="/home/blake/kitchen-worlds/assets/models/Cupboard/46563/textured_objs/original-11.obj" />/&gt;
			</geometry>
		</collision>
		<collision>
			<origin xyz="0 0 0" />
			<geometry>
				<mesh filename="/home/blake/kitchen-worlds/assets/models/Cupboard/46563/textured_objs/original-10.obj" />/&gt;
			</geometry>
		</collision>
		<collision>
			<origin xyz="0 0 0" />
			<geometry>
				<mesh filename="/home/blake/kitchen-worlds/assets/models/Cupboard/46563/textured_objs/original-15.obj" />/&gt;
			</geometry>
		</collision>
		<collision>
			<origin xyz="0 0 0" />
			<geometry>
				<mesh filename="/home/blake/kitchen-worlds/assets/models/Cupboard/46563/textured_objs/original-13.obj" />/&gt;
			</geometry>
		</collision>
		<collision>
			<origin xyz="0 0 0" />
			<geometry>
				<mesh filename="/home/blake/kitchen-worlds/assets/models/Cupboard/46563/textured_objs/original-14.obj" />/&gt;
			</geometry>
		</collision>
		<collision>
			<origin xyz="0 0 0" />
			<geometry>
				<mesh filename="/home/blake/kitchen-worlds/assets/models/Cupboard/46563/textured_objs/original-3.obj" />/&gt;
			</geometry>
		</collision>
	</link>
	<joint name="joint_2" type="fixed">
		<origin rpy="1.570796326794897 0 -1.570796326794897" xyz="0 0 0" />
		<child link="link_2" />
		<parent link="base" />
	</joint>
</robot>