<?xml version='1.0' encoding='utf-8'?>
<robot name="partnet_1e25501b8930873129a50a2b3c5e5b6">
	<link name="base" />
	<link name="link_0">
		<visual name="cabinet_door_surface-8">
			<origin xyz="-0.646305488550088 -0.6707149744033813 -0.4367456519129983" />
			<geometry>
				<mesh filename="/home/blake/kitchen-worlds/assets/models/SinkBase/45305/textured_objs/original-31.obj" />/&gt;
			</geometry>
		</visual>
		<visual name="handle-9">
			<origin xyz="-0.646305488550088 -0.6707149744033813 -0.4367456519129983" />
			<geometry>
				<mesh filename="/home/blake/kitchen-worlds/assets/models/SinkBase/45305/textured_objs/original-35.obj" />/&gt;
			</geometry>
		</visual>
		<visual name="handle-9">
			<origin xyz="-0.646305488550088 -0.6707149744033813 -0.4367456519129983" />
			<geometry>
				<mesh filename="/home/blake/kitchen-worlds/assets/models/SinkBase/45305/textured_objs/original-33.obj" />/&gt;
			</geometry>
		</visual>
		<visual name="handle-9">
			<origin xyz="-0.646305488550088 -0.6707149744033813 -0.4367456519129983" />
			<geometry>
				<mesh filename="/home/blake/kitchen-worlds/assets/models/SinkBase/45305/textured_objs/original-34.obj" />/&gt;
			</geometry>
		</visual>
		<collision>
			<origin xyz="-0.646305488550088 -0.6707149744033813 -0.4367456519129983" />
			<geometry>
				<mesh filename="/home/blake/kitchen-worlds/assets/models/SinkBase/45305/textured_objs/original-31.obj" />/&gt;
			</geometry>
		</collision>
		<collision>
			<origin xyz="-0.646305488550088 -0.6707149744033813 -0.4367456519129983" />
			<geometry>
				<mesh filename="/home/blake/kitchen-worlds/assets/models/SinkBase/45305/textured_objs/original-35.obj" />/&gt;
			</geometry>
		</collision>
		<collision>
			<origin xyz="-0.646305488550088 -0.6707149744033813 -0.4367456519129983" />
			<geometry>
				<mesh filename="/home/blake/kitchen-worlds/assets/models/SinkBase/45305/textured_objs/original-33.obj" />/&gt;
			</geometry>
		</collision>
		<collision>
			<origin xyz="-0.646305488550088 -0.6707149744033813 -0.4367456519129983" />
			<geometry>
				<mesh filename="/home/blake/kitchen-worlds/assets/models/SinkBase/45305/textured_objs/original-34.obj" />/&gt;
			</geometry>
		</collision>
	</link>
	<joint name="joint_0" type="revolute">
		<origin xyz="0.646305488550088 0.6707149744033813 0.4367456519129983" />
		<axis xyz="0 1 0" />
		<child link="link_0" />
		<parent link="link_2" />
		<limit lower="0.0" upper="1.5833626974092556" effort="10.0" velocity="1.0" />
	</joint>
	<link name="link_1">
		<visual name="cabinet_door_surface-6">
			<origin xyz="0.6158288327231765 0.3939580023288727 -0.4353039942218538" />
			<geometry>
				<mesh filename="/home/blake/kitchen-worlds/assets/models/SinkBase/45305/textured_objs/original-25.obj" />/&gt;
			</geometry>
		</visual>
		<visual name="handle-7">
			<origin xyz="0.6158288327231765 0.3939580023288727 -0.4353039942218538" />
			<geometry>
				<mesh filename="/home/blake/kitchen-worlds/assets/models/SinkBase/45305/textured_objs/original-27.obj" />/&gt;
			</geometry>
		</visual>
		<visual name="handle-7">
			<origin xyz="0.6158288327231765 0.3939580023288727 -0.4353039942218538" />
			<geometry>
				<mesh filename="/home/blake/kitchen-worlds/assets/models/SinkBase/45305/textured_objs/original-28.obj" />/&gt;
			</geometry>
		</visual>
		<visual name="handle-7">
			<origin xyz="0.6158288327231765 0.3939580023288727 -0.4353039942218538" />
			<geometry>
				<mesh filename="/home/blake/kitchen-worlds/assets/models/SinkBase/45305/textured_objs/original-29.obj" />/&gt;
			</geometry>
		</visual>
		<collision>
			<origin xyz="0.6158288327231765 0.3939580023288727 -0.4353039942218538" />
			<geometry>
				<mesh filename="/home/blake/kitchen-worlds/assets/models/SinkBase/45305/textured_objs/original-25.obj" />/&gt;
			</geometry>
		</collision>
		<collision>
			<origin xyz="0.6158288327231765 0.3939580023288727 -0.4353039942218538" />
			<geometry>
				<mesh filename="/home/blake/kitchen-worlds/assets/models/SinkBase/45305/textured_objs/original-27.obj" />/&gt;
			</geometry>
		</collision>
		<collision>
			<origin xyz="0.6158288327231765 0.3939580023288727 -0.4353039942218538" />
			<geometry>
				<mesh filename="/home/blake/kitchen-worlds/assets/models/SinkBase/45305/textured_objs/original-28.obj" />/&gt;
			</geometry>
		</collision>
		<collision>
			<origin xyz="0.6158288327231765 0.3939580023288727 -0.4353039942218538" />
			<geometry>
				<mesh filename="/home/blake/kitchen-worlds/assets/models/SinkBase/45305/textured_objs/original-29.obj" />/&gt;
			</geometry>
		</collision>
	</link>
	<joint name="joint_1" type="revolute">
		<origin xyz="-0.6158288327231765 -0.3939580023288727 0.4353039942218538" />
		<axis xyz="0 -1 0" />
		<child link="link_1" />
		<parent link="link_2" />
		<limit lower="0.0" upper="1.5833626974092556" effort="10.0" velocity="1.0" />
	</joint>
	<link name="link_2">
		<visual name="vertical_side_panel-15">
			<origin xyz="0 0 0" />
			<geometry>
				<mesh filename="/home/blake/kitchen-worlds/assets/models/SinkBase/45305/textured_objs/original-9.obj" />/&gt;
			</geometry>
		</visual>
		<visual name="vertical_side_panel-16">
			<origin xyz="0 0 0" />
			<geometry>
				<mesh filename="/home/blake/kitchen-worlds/assets/models/SinkBase/45305/textured_objs/original-21.obj" />/&gt;
			</geometry>
		</visual>
		<visual name="back_panel-17">
			<origin xyz="0 0 0" />
			<geometry>
				<mesh filename="/home/blake/kitchen-worlds/assets/models/SinkBase/45305/textured_objs/original-16.obj" />/&gt;
			</geometry>
		</visual>
		<visual name="bottom_panel-18">
			<origin xyz="0 0 0" />
			<geometry>
				<mesh filename="/home/blake/kitchen-worlds/assets/models/SinkBase/45305/textured_objs/original-12.obj" />/&gt;
			</geometry>
		</visual>
		<visual name="frame_vertical_bar-19">
			<origin xyz="0 0 0" />
			<geometry>
				<mesh filename="/home/blake/kitchen-worlds/assets/models/SinkBase/45305/textured_objs/original-2.obj" />/&gt;
			</geometry>
		</visual>
		<visual name="frame_vertical_bar-20">
			<origin xyz="0 0 0" />
			<geometry>
				<mesh filename="/home/blake/kitchen-worlds/assets/models/SinkBase/45305/textured_objs/original-4.obj" />/&gt;
			</geometry>
		</visual>
		<visual name="frame_vertical_bar-21">
			<origin xyz="0 0 0" />
			<geometry>
				<mesh filename="/home/blake/kitchen-worlds/assets/models/SinkBase/45305/textured_objs/original-6.obj" />/&gt;
			</geometry>
		</visual>
		<visual name="frame_horizontal_bar-22">
			<origin xyz="0 0 0" />
			<geometry>
				<mesh filename="/home/blake/kitchen-worlds/assets/models/SinkBase/45305/textured_objs/original-15.obj" />/&gt;
			</geometry>
		</visual>
		<visual name="frame_horizontal_bar-23">
			<origin xyz="0 0 0" />
			<geometry>
				<mesh filename="/home/blake/kitchen-worlds/assets/models/SinkBase/45305/textured_objs/original-5.obj" />/&gt;
			</geometry>
		</visual>
		<visual name="frame_horizontal_bar-24">
			<origin xyz="0 0 0" />
			<geometry>
				<mesh filename="/home/blake/kitchen-worlds/assets/models/SinkBase/45305/textured_objs/original-3.obj" />/&gt;
			</geometry>
		</visual>
		<visual name="other_leaf-32">
			<origin xyz="0 0 0" />
			<geometry>
				<mesh filename="/home/blake/kitchen-worlds/assets/models/SinkBase/45305/textured_objs/original-13.obj" />/&gt;
			</geometry>
		</visual>
		<visual name="other_leaf-31">
			<origin xyz="0 0 0" />
			<geometry>
				<mesh filename="/home/blake/kitchen-worlds/assets/models/SinkBase/45305/textured_objs/original-17.obj" />/&gt;
			</geometry>
		</visual>
		<visual name="other_leaf-30">
			<origin xyz="0 0 0" />
			<geometry>
				<mesh filename="/home/blake/kitchen-worlds/assets/models/SinkBase/45305/textured_objs/original-23.obj" />/&gt;
			</geometry>
		</visual>
		<visual name="other_leaf-29">
			<origin xyz="0 0 0" />
			<geometry>
				<mesh filename="/home/blake/kitchen-worlds/assets/models/SinkBase/45305/textured_objs/original-14.obj" />/&gt;
			</geometry>
		</visual>
		<visual name="frame_vertical_bar-33">
			<origin xyz="0 0 0" />
			<geometry>
				<mesh filename="/home/blake/kitchen-worlds/assets/models/SinkBase/45305/textured_objs/original-20.obj" />/&gt;
			</geometry>
		</visual>
		<visual name="frame_vertical_bar-34">
			<origin xyz="0 0 0" />
			<geometry>
				<mesh filename="/home/blake/kitchen-worlds/assets/models/SinkBase/45305/textured_objs/original-8.obj" />/&gt;
			</geometry>
		</visual>
		<visual name="other_leaf-36">
			<origin xyz="0 0 0" />
			<geometry>
				<mesh filename="/home/blake/kitchen-worlds/assets/models/SinkBase/45305/textured_objs/original-36.obj" />/&gt;
			</geometry>
		</visual>
		<visual name="base_side_panel-11">
			<origin xyz="0 0 0" />
			<geometry>
				<mesh filename="/home/blake/kitchen-worlds/assets/models/SinkBase/45305/textured_objs/original-22.obj" />/&gt;
			</geometry>
		</visual>
		<visual name="base_side_panel-12">
			<origin xyz="0 0 0" />
			<geometry>
				<mesh filename="/home/blake/kitchen-worlds/assets/models/SinkBase/45305/textured_objs/original-18.obj" />/&gt;
			</geometry>
		</visual>
		<visual name="base_side_panel-13">
			<origin xyz="0 0 0" />
			<geometry>
				<mesh filename="/home/blake/kitchen-worlds/assets/models/SinkBase/45305/textured_objs/original-10.obj" />/&gt;
			</geometry>
		</visual>
		<visual name="base_side_panel-14">
			<origin xyz="0 0 0" />
			<geometry>
				<mesh filename="/home/blake/kitchen-worlds/assets/models/SinkBase/45305/textured_objs/original-11.obj" />/&gt;
			</geometry>
		</visual>
		<collision>
			<origin xyz="0 0 0" />
			<geometry>
				<mesh filename="/home/blake/kitchen-worlds/assets/models/SinkBase/45305/textured_objs/original-9.obj" />/&gt;
			</geometry>
		</collision>
		<collision>
			<origin xyz="0 0 0" />
			<geometry>
				<mesh filename="/home/blake/kitchen-worlds/assets/models/SinkBase/45305/textured_objs/original-21.obj" />/&gt;
			</geometry>
		</collision>
		<collision>
			<origin xyz="0 0 0" />
			<geometry>
				<mesh filename="/home/blake/kitchen-worlds/assets/models/SinkBase/45305/textured_objs/original-16.obj" />/&gt;
			</geometry>
		</collision>
		<collision>
			<origin xyz="0 0 0" />
			<geometry>
				<mesh filename="/home/blake/kitchen-worlds/assets/models/SinkBase/45305/textured_objs/original-12.obj" />/&gt;
			</geometry>
		</collision>
		<collision>
			<origin xyz="0 0 0" />
			<geometry>
				<mesh filename="/home/blake/kitchen-worlds/assets/models/SinkBase/45305/textured_objs/original-2.obj" />/&gt;
			</geometry>
		</collision>
		<collision>
			<origin xyz="0 0 0" />
			<geometry>
				<mesh filename="/home/blake/kitchen-worlds/assets/models/SinkBase/45305/textured_objs/original-4.obj" />/&gt;
			</geometry>
		</collision>
		<collision>
			<origin xyz="0 0 0" />
			<geometry>
				<mesh filename="/home/blake/kitchen-worlds/assets/models/SinkBase/45305/textured_objs/original-6.obj" />/&gt;
			</geometry>
		</collision>
		<collision>
			<origin xyz="0 0 0" />
			<geometry>
				<mesh filename="/home/blake/kitchen-worlds/assets/models/SinkBase/45305/textured_objs/original-15.obj" />/&gt;
			</geometry>
		</collision>
		<collision>
			<origin xyz="0 0 0" />
			<geometry>
				<mesh filename="/home/blake/kitchen-worlds/assets/models/SinkBase/45305/textured_objs/original-5.obj" />/&gt;
			</geometry>
		</collision>
		<collision>
			<origin xyz="0 0 0" />
			<geometry>
				<mesh filename="/home/blake/kitchen-worlds/assets/models/SinkBase/45305/textured_objs/original-3.obj" />/&gt;
			</geometry>
		</collision>
		<collision>
			<origin xyz="0 0 0" />
			<geometry>
				<mesh filename="/home/blake/kitchen-worlds/assets/models/SinkBase/45305/textured_objs/original-13.obj" />/&gt;
			</geometry>
		</collision>
		<collision>
			<origin xyz="0 0 0" />
			<geometry>
				<mesh filename="/home/blake/kitchen-worlds/assets/models/SinkBase/45305/textured_objs/original-17.obj" />/&gt;
			</geometry>
		</collision>
		<collision>
			<origin xyz="0 0 0" />
			<geometry>
				<mesh filename="/home/blake/kitchen-worlds/assets/models/SinkBase/45305/textured_objs/original-23.obj" />/&gt;
			</geometry>
		</collision>
		<collision>
			<origin xyz="0 0 0" />
			<geometry>
				<mesh filename="/home/blake/kitchen-worlds/assets/models/SinkBase/45305/textured_objs/original-14.obj" />/&gt;
			</geometry>
		</collision>
		<collision>
			<origin xyz="0 0 0" />
			<geometry>
				<mesh filename="/home/blake/kitchen-worlds/assets/models/SinkBase/45305/textured_objs/original-20.obj" />/&gt;
			</geometry>
		</collision>
		<collision>
			<origin xyz="0 0 0" />
			<geometry>
				<mesh filename="/home/blake/kitchen-worlds/assets/models/SinkBase/45305/textured_objs/original-8.obj" />/&gt;
			</geometry>
		</collision>
		<collision>
			<origin xyz="0 0 0" />
			<geometry>
				<mesh filename="/home/blake/kitchen-worlds/assets/models/SinkBase/45305/textured_objs/original-36.obj" />/&gt;
			</geometry>
		</collision>
		<collision>
			<origin xyz="0 0 0" />
			<geometry>
				<mesh filename="/home/blake/kitchen-worlds/assets/models/SinkBase/45305/textured_objs/original-22.obj" />/&gt;
			</geometry>
		</collision>
		<collision>
			<origin xyz="0 0 0" />
			<geometry>
				<mesh filename="/home/blake/kitchen-worlds/assets/models/SinkBase/45305/textured_objs/original-18.obj" />/&gt;
			</geometry>
		</collision>
		<collision>
			<origin xyz="0 0 0" />
			<geometry>
				<mesh filename="/home/blake/kitchen-worlds/assets/models/SinkBase/45305/textured_objs/original-10.obj" />/&gt;
			</geometry>
		</collision>
		<collision>
			<origin xyz="0 0 0" />
			<geometry>
				<mesh filename="/home/blake/kitchen-worlds/assets/models/SinkBase/45305/textured_objs/original-11.obj" />/&gt;
			</geometry>
		</collision>
	</link>
	<joint name="joint_2" type="fixed">
		<origin rpy="1.570796326794897 0 -1.570796326794897" xyz="0 0 0" />
		<child link="link_2" />
		<parent link="base" />
	</joint>
</robot>