<?xml version='1.0' encoding='utf-8'?>
<robot name="partnet_9af7a071bbd432baa5526f91aecc0c37">
	<link name="base" />
	<link name="link_0">
		<visual name="drawer_front-61">
			<origin xyz="0 0 0" />
			<geometry>
				<mesh filename="/home/blake/kitchen-worlds/assets/models/KitchenCounter/26387/textured_objs/original-16.obj" />/&gt;
			</geometry>
		</visual>
		<visual name="drawer_side-62">
			<origin xyz="0 0 0" />
			<geometry>
				<mesh filename="/home/blake/kitchen-worlds/assets/models/KitchenCounter/26387/textured_objs/original-18.obj" />/&gt;
			</geometry>
		</visual>
		<visual name="drawer_side-62">
			<origin xyz="0 0 0" />
			<geometry>
				<mesh filename="/home/blake/kitchen-worlds/assets/models/KitchenCounter/26387/textured_objs/original-37.obj" />/&gt;
			</geometry>
		</visual>
		<visual name="drawer_side-62">
			<origin xyz="0 0 0" />
			<geometry>
				<mesh filename="/home/blake/kitchen-worlds/assets/models/KitchenCounter/26387/textured_objs/original-25.obj" />/&gt;
			</geometry>
		</visual>
		<visual name="drawer_side-62">
			<origin xyz="0 0 0" />
			<geometry>
				<mesh filename="/home/blake/kitchen-worlds/assets/models/KitchenCounter/26387/textured_objs/original-23.obj" />/&gt;
			</geometry>
		</visual>
		<visual name="drawer_side-62">
			<origin xyz="0 0 0" />
			<geometry>
				<mesh filename="/home/blake/kitchen-worlds/assets/models/KitchenCounter/26387/textured_objs/original-22.obj" />/&gt;
			</geometry>
		</visual>
		<visual name="drawer_side-62">
			<origin xyz="0 0 0" />
			<geometry>
				<mesh filename="/home/blake/kitchen-worlds/assets/models/KitchenCounter/26387/textured_objs/original-20.obj" />/&gt;
			</geometry>
		</visual>
		<visual name="drawer_side-62">
			<origin xyz="0 0 0" />
			<geometry>
				<mesh filename="/home/blake/kitchen-worlds/assets/models/KitchenCounter/26387/textured_objs/original-24.obj" />/&gt;
			</geometry>
		</visual>
		<visual name="drawer_side-63">
			<origin xyz="0 0 0" />
			<geometry>
				<mesh filename="/home/blake/kitchen-worlds/assets/models/KitchenCounter/26387/textured_objs/original-17.obj" />/&gt;
			</geometry>
		</visual>
		<visual name="drawer_back-64">
			<origin xyz="0 0 0" />
			<geometry>
				<mesh filename="/home/blake/kitchen-worlds/assets/models/KitchenCounter/26387/textured_objs/original-19.obj" />/&gt;
			</geometry>
		</visual>
		<visual name="drawer_bottom-65">
			<origin xyz="0 0 0" />
			<geometry>
				<mesh filename="/home/blake/kitchen-worlds/assets/models/KitchenCounter/26387/textured_objs/original-21.obj" />/&gt;
			</geometry>
		</visual>
		<collision>
			<origin xyz="0 0 0" />
			<geometry>
				<mesh filename="/home/blake/kitchen-worlds/assets/models/KitchenCounter/26387/textured_objs/original-16.obj" />/&gt;
			</geometry>
		</collision>
		<collision>
			<origin xyz="0 0 0" />
			<geometry>
				<mesh filename="/home/blake/kitchen-worlds/assets/models/KitchenCounter/26387/textured_objs/original-18.obj" />/&gt;
			</geometry>
		</collision>
		<collision>
			<origin xyz="0 0 0" />
			<geometry>
				<mesh filename="/home/blake/kitchen-worlds/assets/models/KitchenCounter/26387/textured_objs/original-37.obj" />/&gt;
			</geometry>
		</collision>
		<collision>
			<origin xyz="0 0 0" />
			<geometry>
				<mesh filename="/home/blake/kitchen-worlds/assets/models/KitchenCounter/26387/textured_objs/original-25.obj" />/&gt;
			</geometry>
		</collision>
		<collision>
			<origin xyz="0 0 0" />
			<geometry>
				<mesh filename="/home/blake/kitchen-worlds/assets/models/KitchenCounter/26387/textured_objs/original-23.obj" />/&gt;
			</geometry>
		</collision>
		<collision>
			<origin xyz="0 0 0" />
			<geometry>
				<mesh filename="/home/blake/kitchen-worlds/assets/models/KitchenCounter/26387/textured_objs/original-22.obj" />/&gt;
			</geometry>
		</collision>
		<collision>
			<origin xyz="0 0 0" />
			<geometry>
				<mesh filename="/home/blake/kitchen-worlds/assets/models/KitchenCounter/26387/textured_objs/original-20.obj" />/&gt;
			</geometry>
		</collision>
		<collision>
			<origin xyz="0 0 0" />
			<geometry>
				<mesh filename="/home/blake/kitchen-worlds/assets/models/KitchenCounter/26387/textured_objs/original-24.obj" />/&gt;
			</geometry>
		</collision>
		<collision>
			<origin xyz="0 0 0" />
			<geometry>
				<mesh filename="/home/blake/kitchen-worlds/assets/models/KitchenCounter/26387/textured_objs/original-17.obj" />/&gt;
			</geometry>
		</collision>
		<collision>
			<origin xyz="0 0 0" />
			<geometry>
				<mesh filename="/home/blake/kitchen-worlds/assets/models/KitchenCounter/26387/textured_objs/original-19.obj" />/&gt;
			</geometry>
		</collision>
		<collision>
			<origin xyz="0 0 0" />
			<geometry>
				<mesh filename="/home/blake/kitchen-worlds/assets/models/KitchenCounter/26387/textured_objs/original-21.obj" />/&gt;
			</geometry>
		</collision>
	</link>
	<joint name="joint_0" type="prismatic">
		<origin xyz="0 0 0" />
		<axis xyz="0 0 -1" />
		<child link="link_0" />
		<parent link="link_3" />
		<limit lower="0" upper="0.252" effort="10.0" velocity="1.0" />
	</joint>
	<link name="link_1">
		<visual name="drawer_front-55">
			<origin xyz="0 0 0" />
			<geometry>
				<mesh filename="/home/blake/kitchen-worlds/assets/models/KitchenCounter/26387/textured_objs/original-27.obj" />/&gt;
			</geometry>
		</visual>
		<visual name="drawer_side-56">
			<origin xyz="0 0 0" />
			<geometry>
				<mesh filename="/home/blake/kitchen-worlds/assets/models/KitchenCounter/26387/textured_objs/original-28.obj" />/&gt;
			</geometry>
		</visual>
		<visual name="drawer_side-57">
			<origin xyz="0 0 0" />
			<geometry>
				<mesh filename="/home/blake/kitchen-worlds/assets/models/KitchenCounter/26387/textured_objs/original-29.obj" />/&gt;
			</geometry>
		</visual>
		<visual name="drawer_back-58">
			<origin xyz="0 0 0" />
			<geometry>
				<mesh filename="/home/blake/kitchen-worlds/assets/models/KitchenCounter/26387/textured_objs/original-30.obj" />/&gt;
			</geometry>
		</visual>
		<visual name="drawer_bottom-59">
			<origin xyz="0 0 0" />
			<geometry>
				<mesh filename="/home/blake/kitchen-worlds/assets/models/KitchenCounter/26387/textured_objs/original-31.obj" />/&gt;
			</geometry>
		</visual>
		<collision>
			<origin xyz="0 0 0" />
			<geometry>
				<mesh filename="/home/blake/kitchen-worlds/assets/models/KitchenCounter/26387/textured_objs/original-27.obj" />/&gt;
			</geometry>
		</collision>
		<collision>
			<origin xyz="0 0 0" />
			<geometry>
				<mesh filename="/home/blake/kitchen-worlds/assets/models/KitchenCounter/26387/textured_objs/original-28.obj" />/&gt;
			</geometry>
		</collision>
		<collision>
			<origin xyz="0 0 0" />
			<geometry>
				<mesh filename="/home/blake/kitchen-worlds/assets/models/KitchenCounter/26387/textured_objs/original-29.obj" />/&gt;
			</geometry>
		</collision>
		<collision>
			<origin xyz="0 0 0" />
			<geometry>
				<mesh filename="/home/blake/kitchen-worlds/assets/models/KitchenCounter/26387/textured_objs/original-30.obj" />/&gt;
			</geometry>
		</collision>
		<collision>
			<origin xyz="0 0 0" />
			<geometry>
				<mesh filename="/home/blake/kitchen-worlds/assets/models/KitchenCounter/26387/textured_objs/original-31.obj" />/&gt;
			</geometry>
		</collision>
	</link>
	<joint name="joint_1" type="prismatic">
		<origin xyz="0 0 0" />
		<axis xyz="0 0 -1" />
		<child link="link_1" />
		<parent link="link_3" />
		<limit lower="0" upper="0.252" effort="10.0" velocity="1.0" />
	</joint>
	<link name="link_2">
		<visual name="drawer_front-47">
			<origin xyz="0 0 0" />
			<geometry>
				<mesh filename="/home/blake/kitchen-worlds/assets/models/KitchenCounter/26387/textured_objs/original-8.obj" />/&gt;
			</geometry>
		</visual>
		<visual name="drawer_side-48">
			<origin xyz="0 0 0" />
			<geometry>
				<mesh filename="/home/blake/kitchen-worlds/assets/models/KitchenCounter/26387/textured_objs/original-9.obj" />/&gt;
			</geometry>
		</visual>
		<visual name="drawer_side-49">
			<origin xyz="0 0 0" />
			<geometry>
				<mesh filename="/home/blake/kitchen-worlds/assets/models/KitchenCounter/26387/textured_objs/original-10.obj" />/&gt;
			</geometry>
		</visual>
		<visual name="drawer_side-49">
			<origin xyz="0 0 0" />
			<geometry>
				<mesh filename="/home/blake/kitchen-worlds/assets/models/KitchenCounter/26387/textured_objs/original-33.obj" />/&gt;
			</geometry>
		</visual>
		<visual name="drawer_side-49">
			<origin xyz="0 0 0" />
			<geometry>
				<mesh filename="/home/blake/kitchen-worlds/assets/models/KitchenCounter/26387/textured_objs/original-14.obj" />/&gt;
			</geometry>
		</visual>
		<visual name="drawer_side-49">
			<origin xyz="0 0 0" />
			<geometry>
				<mesh filename="/home/blake/kitchen-worlds/assets/models/KitchenCounter/26387/textured_objs/original-12.obj" />/&gt;
			</geometry>
		</visual>
		<visual name="drawer_back-50">
			<origin xyz="0 0 0" />
			<geometry>
				<mesh filename="/home/blake/kitchen-worlds/assets/models/KitchenCounter/26387/textured_objs/original-11.obj" />/&gt;
			</geometry>
		</visual>
		<visual name="drawer_bottom-51">
			<origin xyz="0 0 0" />
			<geometry>
				<mesh filename="/home/blake/kitchen-worlds/assets/models/KitchenCounter/26387/textured_objs/original-13.obj" />/&gt;
			</geometry>
		</visual>
		<collision>
			<origin xyz="0 0 0" />
			<geometry>
				<mesh filename="/home/blake/kitchen-worlds/assets/models/KitchenCounter/26387/textured_objs/original-8.obj" />/&gt;
			</geometry>
		</collision>
		<collision>
			<origin xyz="0 0 0" />
			<geometry>
				<mesh filename="/home/blake/kitchen-worlds/assets/models/KitchenCounter/26387/textured_objs/original-9.obj" />/&gt;
			</geometry>
		</collision>
		<collision>
			<origin xyz="0 0 0" />
			<geometry>
				<mesh filename="/home/blake/kitchen-worlds/assets/models/KitchenCounter/26387/textured_objs/original-10.obj" />/&gt;
			</geometry>
		</collision>
		<collision>
			<origin xyz="0 0 0" />
			<geometry>
				<mesh filename="/home/blake/kitchen-worlds/assets/models/KitchenCounter/26387/textured_objs/original-33.obj" />/&gt;
			</geometry>
		</collision>
		<collision>
			<origin xyz="0 0 0" />
			<geometry>
				<mesh filename="/home/blake/kitchen-worlds/assets/models/KitchenCounter/26387/textured_objs/original-14.obj" />/&gt;
			</geometry>
		</collision>
		<collision>
			<origin xyz="0 0 0" />
			<geometry>
				<mesh filename="/home/blake/kitchen-worlds/assets/models/KitchenCounter/26387/textured_objs/original-12.obj" />/&gt;
			</geometry>
		</collision>
		<collision>
			<origin xyz="0 0 0" />
			<geometry>
				<mesh filename="/home/blake/kitchen-worlds/assets/models/KitchenCounter/26387/textured_objs/original-11.obj" />/&gt;
			</geometry>
		</collision>
		<collision>
			<origin xyz="0 0 0" />
			<geometry>
				<mesh filename="/home/blake/kitchen-worlds/assets/models/KitchenCounter/26387/textured_objs/original-13.obj" />/&gt;
			</geometry>
		</collision>
	</link>
	<joint name="joint_2" type="prismatic">
		<origin xyz="0 0 0" />
		<axis xyz="0 0 -1" />
		<child link="link_2" />
		<parent link="link_3" />
		<limit lower="0" upper="0.252" effort="10.0" velocity="1.0" />
	</joint>
	<link name="link_3">
		<visual name="board-74">
			<origin xyz="0 0 0" />
			<geometry>
				<mesh filename="/home/blake/kitchen-worlds/assets/models/KitchenCounter/26387/textured_objs/new-12.obj" />/&gt;
			</geometry>
		</visual>
		<visual name="board-74">
			<origin xyz="0 0 0" />
			<geometry>
				<mesh filename="/home/blake/kitchen-worlds/assets/models/KitchenCounter/26387/textured_objs/new-14.obj" />/&gt;
			</geometry>
		</visual>
		<visual name="bar-76">
			<origin xyz="0 0 0" />
			<geometry>
				<mesh filename="/home/blake/kitchen-worlds/assets/models/KitchenCounter/26387/textured_objs/new-13.obj" />/&gt;
			</geometry>
		</visual>
		<visual name="bar-77">
			<origin xyz="0 0 0" />
			<geometry>
				<mesh filename="/home/blake/kitchen-worlds/assets/models/KitchenCounter/26387/textured_objs/new-7.obj" />/&gt;
			</geometry>
		</visual>
		<visual name="bar-77">
			<origin xyz="0 0 0" />
			<geometry>
				<mesh filename="/home/blake/kitchen-worlds/assets/models/KitchenCounter/26387/textured_objs/new-10.obj" />/&gt;
			</geometry>
		</visual>
		<visual name="bar-78">
			<origin xyz="0 0 0" />
			<geometry>
				<mesh filename="/home/blake/kitchen-worlds/assets/models/KitchenCounter/26387/textured_objs/new-6.obj" />/&gt;
			</geometry>
		</visual>
		<visual name="bar-78">
			<origin xyz="0 0 0" />
			<geometry>
				<mesh filename="/home/blake/kitchen-worlds/assets/models/KitchenCounter/26387/textured_objs/new-11.obj" />/&gt;
			</geometry>
		</visual>
		<visual name="bar-79">
			<origin xyz="0 0 0" />
			<geometry>
				<mesh filename="/home/blake/kitchen-worlds/assets/models/KitchenCounter/26387/textured_objs/new-9.obj" />/&gt;
			</geometry>
		</visual>
		<visual name="bar-79">
			<origin xyz="0 0 0" />
			<geometry>
				<mesh filename="/home/blake/kitchen-worlds/assets/models/KitchenCounter/26387/textured_objs/new-5.obj" />/&gt;
			</geometry>
		</visual>
		<visual name="leg-34">
			<origin xyz="0 0 0" />
			<geometry>
				<mesh filename="/home/blake/kitchen-worlds/assets/models/KitchenCounter/26387/textured_objs/new-2.obj" />/&gt;
			</geometry>
		</visual>
		<visual name="leg-35">
			<origin xyz="0 0 0" />
			<geometry>
				<mesh filename="/home/blake/kitchen-worlds/assets/models/KitchenCounter/26387/textured_objs/new-3.obj" />/&gt;
			</geometry>
		</visual>
		<visual name="leg-36">
			<origin xyz="0 0 0" />
			<geometry>
				<mesh filename="/home/blake/kitchen-worlds/assets/models/KitchenCounter/26387/textured_objs/new-1.obj" />/&gt;
			</geometry>
		</visual>
		<visual name="leg-37">
			<origin xyz="0 0 0" />
			<geometry>
				<mesh filename="/home/blake/kitchen-worlds/assets/models/KitchenCounter/26387/textured_objs/new-0.obj" />/&gt;
			</geometry>
		</visual>
		<visual name="tabletop_connector-41">
			<origin xyz="0 0 0" />
			<geometry>
				<mesh filename="/home/blake/kitchen-worlds/assets/models/KitchenCounter/26387/textured_objs/original-2.obj" />/&gt;
			</geometry>
		</visual>
		<visual name="tabletop_connector-41">
			<origin xyz="0 0 0" />
			<geometry>
				<mesh filename="/home/blake/kitchen-worlds/assets/models/KitchenCounter/26387/textured_objs/original-3.obj" />/&gt;
			</geometry>
		</visual>
		<visual name="tabletop_connector-42">
			<origin xyz="0 0 0" />
			<geometry>
				<mesh filename="/home/blake/kitchen-worlds/assets/models/KitchenCounter/26387/textured_objs/original-5.obj" />/&gt;
			</geometry>
		</visual>
		<visual name="tabletop_connector-42">
			<origin xyz="0 0 0" />
			<geometry>
				<mesh filename="/home/blake/kitchen-worlds/assets/models/KitchenCounter/26387/textured_objs/original-4.obj" />/&gt;
			</geometry>
		</visual>
		<visual name="tabletop_connector-43">
			<origin xyz="0 0 0" />
			<geometry>
				<mesh filename="/home/blake/kitchen-worlds/assets/models/KitchenCounter/26387/textured_objs/new-4.obj" />/&gt;
			</geometry>
		</visual>
		<visual name="tabletop_connector-66">
			<origin xyz="0 0 0" />
			<geometry>
				<mesh filename="/home/blake/kitchen-worlds/assets/models/KitchenCounter/26387/textured_objs/original-32.obj" />/&gt;
			</geometry>
		</visual>
		<visual name="tabletop_connector-67">
			<origin xyz="0 0 0" />
			<geometry>
				<mesh filename="/home/blake/kitchen-worlds/assets/models/KitchenCounter/26387/textured_objs/original-34.obj" />/&gt;
			</geometry>
		</visual>
		<visual name="tabletop_connector-68">
			<origin xyz="0 0 0" />
			<geometry>
				<mesh filename="/home/blake/kitchen-worlds/assets/models/KitchenCounter/26387/textured_objs/original-35.obj" />/&gt;
			</geometry>
		</visual>
		<visual name="tabletop_connector-69">
			<origin xyz="0 0 0" />
			<geometry>
				<mesh filename="/home/blake/kitchen-worlds/assets/models/KitchenCounter/26387/textured_objs/original-36.obj" />/&gt;
			</geometry>
		</visual>
		<collision>
			<origin xyz="0 0 0" />
			<geometry>
				<mesh filename="/home/blake/kitchen-worlds/assets/models/KitchenCounter/26387/textured_objs/new-12.obj" />/&gt;
			</geometry>
		</collision>
		<collision>
			<origin xyz="0 0 0" />
			<geometry>
				<mesh filename="/home/blake/kitchen-worlds/assets/models/KitchenCounter/26387/textured_objs/new-14.obj" />/&gt;
			</geometry>
		</collision>
		<collision>
			<origin xyz="0 0 0" />
			<geometry>
				<mesh filename="/home/blake/kitchen-worlds/assets/models/KitchenCounter/26387/textured_objs/new-13.obj" />/&gt;
			</geometry>
		</collision>
		<collision>
			<origin xyz="0 0 0" />
			<geometry>
				<mesh filename="/home/blake/kitchen-worlds/assets/models/KitchenCounter/26387/textured_objs/new-7.obj" />/&gt;
			</geometry>
		</collision>
		<collision>
			<origin xyz="0 0 0" />
			<geometry>
				<mesh filename="/home/blake/kitchen-worlds/assets/models/KitchenCounter/26387/textured_objs/new-10.obj" />/&gt;
			</geometry>
		</collision>
		<collision>
			<origin xyz="0 0 0" />
			<geometry>
				<mesh filename="/home/blake/kitchen-worlds/assets/models/KitchenCounter/26387/textured_objs/new-6.obj" />/&gt;
			</geometry>
		</collision>
		<collision>
			<origin xyz="0 0 0" />
			<geometry>
				<mesh filename="/home/blake/kitchen-worlds/assets/models/KitchenCounter/26387/textured_objs/new-11.obj" />/&gt;
			</geometry>
		</collision>
		<collision>
			<origin xyz="0 0 0" />
			<geometry>
				<mesh filename="/home/blake/kitchen-worlds/assets/models/KitchenCounter/26387/textured_objs/new-9.obj" />/&gt;
			</geometry>
		</collision>
		<collision>
			<origin xyz="0 0 0" />
			<geometry>
				<mesh filename="/home/blake/kitchen-worlds/assets/models/KitchenCounter/26387/textured_objs/new-5.obj" />/&gt;
			</geometry>
		</collision>
		<collision>
			<origin xyz="0 0 0" />
			<geometry>
				<mesh filename="/home/blake/kitchen-worlds/assets/models/KitchenCounter/26387/textured_objs/new-2.obj" />/&gt;
			</geometry>
		</collision>
		<collision>
			<origin xyz="0 0 0" />
			<geometry>
				<mesh filename="/home/blake/kitchen-worlds/assets/models/KitchenCounter/26387/textured_objs/new-3.obj" />/&gt;
			</geometry>
		</collision>
		<collision>
			<origin xyz="0 0 0" />
			<geometry>
				<mesh filename="/home/blake/kitchen-worlds/assets/models/KitchenCounter/26387/textured_objs/new-1.obj" />/&gt;
			</geometry>
		</collision>
		<collision>
			<origin xyz="0 0 0" />
			<geometry>
				<mesh filename="/home/blake/kitchen-worlds/assets/models/KitchenCounter/26387/textured_objs/new-0.obj" />/&gt;
			</geometry>
		</collision>
		<collision>
			<origin xyz="0 0 0" />
			<geometry>
				<mesh filename="/home/blake/kitchen-worlds/assets/models/KitchenCounter/26387/textured_objs/original-2.obj" />/&gt;
			</geometry>
		</collision>
		<collision>
			<origin xyz="0 0 0" />
			<geometry>
				<mesh filename="/home/blake/kitchen-worlds/assets/models/KitchenCounter/26387/textured_objs/original-3.obj" />/&gt;
			</geometry>
		</collision>
		<collision>
			<origin xyz="0 0 0" />
			<geometry>
				<mesh filename="/home/blake/kitchen-worlds/assets/models/KitchenCounter/26387/textured_objs/original-5.obj" />/&gt;
			</geometry>
		</collision>
		<collision>
			<origin xyz="0 0 0" />
			<geometry>
				<mesh filename="/home/blake/kitchen-worlds/assets/models/KitchenCounter/26387/textured_objs/original-4.obj" />/&gt;
			</geometry>
		</collision>
		<collision>
			<origin xyz="0 0 0" />
			<geometry>
				<mesh filename="/home/blake/kitchen-worlds/assets/models/KitchenCounter/26387/textured_objs/new-4.obj" />/&gt;
			</geometry>
		</collision>
		<collision>
			<origin xyz="0 0 0" />
			<geometry>
				<mesh filename="/home/blake/kitchen-worlds/assets/models/KitchenCounter/26387/textured_objs/original-32.obj" />/&gt;
			</geometry>
		</collision>
		<collision>
			<origin xyz="0 0 0" />
			<geometry>
				<mesh filename="/home/blake/kitchen-worlds/assets/models/KitchenCounter/26387/textured_objs/original-34.obj" />/&gt;
			</geometry>
		</collision>
		<collision>
			<origin xyz="0 0 0" />
			<geometry>
				<mesh filename="/home/blake/kitchen-worlds/assets/models/KitchenCounter/26387/textured_objs/original-35.obj" />/&gt;
			</geometry>
		</collision>
		<collision>
			<origin xyz="0 0 0" />
			<geometry>
				<mesh filename="/home/blake/kitchen-worlds/assets/models/KitchenCounter/26387/textured_objs/original-36.obj" />/&gt;
			</geometry>
		</collision>
	</link>
	<joint name="joint_3" type="fixed">
		<origin rpy="1.570796326794897 0 -1.570796326794897" xyz="0 0 0" />
		<child link="link_3" />
		<parent link="base" />
	</joint>
</robot>