<?xml version='1.0' encoding='utf-8'?>
<robot name="partnet_721f7a03a70b1107c0b2397831029b54">
	<link name="base" />
	<link name="link_0">
		<visual name="cabinet_door_surface-4">
			<origin xyz="0.32102999154435496 0 -0.3294777073708565" />
			<geometry>
				<mesh filename="/home/blake/kitchen-worlds/assets/models/CabinetUpper/46889/textured_objs/original-12.obj" />/&gt;
			</geometry>
		</visual>
		<visual name="handle-5">
			<origin xyz="0.32102999154435496 0 -0.3294777073708565" />
			<geometry>
				<mesh filename="/home/blake/kitchen-worlds/assets/models/CabinetUpper/46889/textured_objs/original-15.obj" />/&gt;
			</geometry>
		</visual>
		<visual name="handle-5">
			<origin xyz="0.32102999154435496 0 -0.3294777073708565" />
			<geometry>
				<mesh filename="/home/blake/kitchen-worlds/assets/models/CabinetUpper/46889/textured_objs/original-16.obj" />/&gt;
			</geometry>
		</visual>
		<visual name="handle-5">
			<origin xyz="0.32102999154435496 0 -0.3294777073708565" />
			<geometry>
				<mesh filename="/home/blake/kitchen-worlds/assets/models/CabinetUpper/46889/textured_objs/original-14.obj" />/&gt;
			</geometry>
		</visual>
		<collision>
			<origin xyz="0.32102999154435496 0 -0.3294777073708565" />
			<geometry>
				<mesh filename="/home/blake/kitchen-worlds/assets/models/CabinetUpper/46889/textured_objs/original-12.obj" />/&gt;
			</geometry>
		</collision>
		<collision>
			<origin xyz="0.32102999154435496 0 -0.3294777073708565" />
			<geometry>
				<mesh filename="/home/blake/kitchen-worlds/assets/models/CabinetUpper/46889/textured_objs/original-15.obj" />/&gt;
			</geometry>
		</collision>
		<collision>
			<origin xyz="0.32102999154435496 0 -0.3294777073708565" />
			<geometry>
				<mesh filename="/home/blake/kitchen-worlds/assets/models/CabinetUpper/46889/textured_objs/original-16.obj" />/&gt;
			</geometry>
		</collision>
		<collision>
			<origin xyz="0.32102999154435496 0 -0.3294777073708565" />
			<geometry>
				<mesh filename="/home/blake/kitchen-worlds/assets/models/CabinetUpper/46889/textured_objs/original-14.obj" />/&gt;
			</geometry>
		</collision>
	</link>
	<joint name="joint_0" type="revolute">
		<origin xyz="-0.32102999154435496 0 0.3294777073708565" />
		<axis xyz="0 -1 0" />
		<child link="link_0" />
		<parent link="link_1" />
		<limit lower="-0.0" upper="1.5707963267948966" effort="10.0" velocity="1.0" />
	</joint>
	<link name="link_1">
		<visual name="shelf-7">
			<origin xyz="0 0 0" />
			<geometry>
				<mesh filename="/home/blake/kitchen-worlds/assets/models/CabinetUpper/46889/textured_objs/original-3.obj" />/&gt;
			</geometry>
		</visual>
		<visual name="shelf-8">
			<origin xyz="0 0 0" />
			<geometry>
				<mesh filename="/home/blake/kitchen-worlds/assets/models/CabinetUpper/46889/textured_objs/original-7.obj" />/&gt;
			</geometry>
		</visual>
		<visual name="shelf-9">
			<origin xyz="0 0 0" />
			<geometry>
				<mesh filename="/home/blake/kitchen-worlds/assets/models/CabinetUpper/46889/textured_objs/original-8.obj" />/&gt;
			</geometry>
		</visual>
		<visual name="vertical_side_panel-10">
			<origin xyz="0 0 0" />
			<geometry>
				<mesh filename="/home/blake/kitchen-worlds/assets/models/CabinetUpper/46889/textured_objs/original-2.obj" />/&gt;
			</geometry>
		</visual>
		<visual name="back_panel-12">
			<origin xyz="0 0 0" />
			<geometry>
				<mesh filename="/home/blake/kitchen-worlds/assets/models/CabinetUpper/46889/textured_objs/original-1.obj" />/&gt;
			</geometry>
		</visual>
		<visual name="bottom_panel-13">
			<origin xyz="0 0 0" />
			<geometry>
				<mesh filename="/home/blake/kitchen-worlds/assets/models/CabinetUpper/46889/textured_objs/original-4.obj" />/&gt;
			</geometry>
		</visual>
		<visual name="top_panel-14">
			<origin xyz="0 0 0" />
			<geometry>
				<mesh filename="/home/blake/kitchen-worlds/assets/models/CabinetUpper/46889/textured_objs/original-6.obj" />/&gt;
			</geometry>
		</visual>
		<visual name="vertical_side_panel-17">
			<origin xyz="0 0 0" />
			<geometry>
				<mesh filename="/home/blake/kitchen-worlds/assets/models/CabinetUpper/46889/textured_objs/original-5.obj" />/&gt;
			</geometry>
		</visual>
		<visual name="vertical_side_panel-17">
			<origin xyz="0 0 0" />
			<geometry>
				<mesh filename="/home/blake/kitchen-worlds/assets/models/CabinetUpper/46889/textured_objs/original-9.obj" />/&gt;
			</geometry>
		</visual>
		<visual name="other_leaf-19">
			<origin xyz="0 0 0" />
			<geometry>
				<mesh filename="/home/blake/kitchen-worlds/assets/models/CabinetUpper/46889/textured_objs/original-17.obj" />/&gt;
			</geometry>
		</visual>
		<collision>
			<origin xyz="0 0 0" />
			<geometry>
				<mesh filename="/home/blake/kitchen-worlds/assets/models/CabinetUpper/46889/textured_objs/original-3.obj" />/&gt;
			</geometry>
		</collision>
		<collision>
			<origin xyz="0 0 0" />
			<geometry>
				<mesh filename="/home/blake/kitchen-worlds/assets/models/CabinetUpper/46889/textured_objs/original-7.obj" />/&gt;
			</geometry>
		</collision>
		<collision>
			<origin xyz="0 0 0" />
			<geometry>
				<mesh filename="/home/blake/kitchen-worlds/assets/models/CabinetUpper/46889/textured_objs/original-8.obj" />/&gt;
			</geometry>
		</collision>
		<collision>
			<origin xyz="0 0 0" />
			<geometry>
				<mesh filename="/home/blake/kitchen-worlds/assets/models/CabinetUpper/46889/textured_objs/original-2.obj" />/&gt;
			</geometry>
		</collision>
		<collision>
			<origin xyz="0 0 0" />
			<geometry>
				<mesh filename="/home/blake/kitchen-worlds/assets/models/CabinetUpper/46889/textured_objs/original-1.obj" />/&gt;
			</geometry>
		</collision>
		<collision>
			<origin xyz="0 0 0" />
			<geometry>
				<mesh filename="/home/blake/kitchen-worlds/assets/models/CabinetUpper/46889/textured_objs/original-4.obj" />/&gt;
			</geometry>
		</collision>
		<collision>
			<origin xyz="0 0 0" />
			<geometry>
				<mesh filename="/home/blake/kitchen-worlds/assets/models/CabinetUpper/46889/textured_objs/original-6.obj" />/&gt;
			</geometry>
		</collision>
		<collision>
			<origin xyz="0 0 0" />
			<geometry>
				<mesh filename="/home/blake/kitchen-worlds/assets/models/CabinetUpper/46889/textured_objs/original-5.obj" />/&gt;
			</geometry>
		</collision>
		<collision>
			<origin xyz="0 0 0" />
			<geometry>
				<mesh filename="/home/blake/kitchen-worlds/assets/models/CabinetUpper/46889/textured_objs/original-9.obj" />/&gt;
			</geometry>
		</collision>
		<collision>
			<origin xyz="0 0 0" />
			<geometry>
				<mesh filename="/home/blake/kitchen-worlds/assets/models/CabinetUpper/46889/textured_objs/original-17.obj" />/&gt;
			</geometry>
		</collision>
	</link>
	<joint name="joint_1" type="fixed">
		<origin rpy="1.570796326794897 0 -1.570796326794897" xyz="0 0 0" />
		<child link="link_1" />
		<parent link="base" />
	</joint>
</robot>