<?xml version='1.0' encoding='utf-8'?>
<robot name="partnet_9191df20dc5559a38a68adc64e25938f">
	<link name="base" />
	<link name="link_0">
		<visual name="door-2">
			<origin xyz="-0.5489212254039852 0.20136937466374594 -0.3894739712377725" />
			<geometry>
				<mesh filename="/home/blake/kitchen-worlds/assets/models/Oven/101924/textured_objs/original-102.obj" />/&gt;
			</geometry>
		</visual>
		<visual name="door-2">
			<origin xyz="-0.5489212254039852 0.20136937466374594 -0.3894739712377725" />
			<geometry>
				<mesh filename="/home/blake/kitchen-worlds/assets/models/Oven/101924/textured_objs/original-49.obj" />/&gt;
			</geometry>
		</visual>
		<visual name="door-2">
			<origin xyz="-0.5489212254039852 0.20136937466374594 -0.3894739712377725" />
			<geometry>
				<mesh filename="/home/blake/kitchen-worlds/assets/models/Oven/101924/textured_objs/original-158.obj" />/&gt;
			</geometry>
		</visual>
		<visual name="door-2">
			<origin xyz="-0.5489212254039852 0.20136937466374594 -0.3894739712377725" />
			<geometry>
				<mesh filename="/home/blake/kitchen-worlds/assets/models/Oven/101924/textured_objs/original-159.obj" />/&gt;
			</geometry>
		</visual>
		<collision>
			<origin xyz="-0.5489212254039852 0.20136937466374594 -0.3894739712377725" />
			<geometry>
				<mesh filename="/home/blake/kitchen-worlds/assets/models/Oven/101924/textured_objs/original-102.obj" />/&gt;
			</geometry>
		</collision>
		<collision>
			<origin xyz="-0.5489212254039852 0.20136937466374594 -0.3894739712377725" />
			<geometry>
				<mesh filename="/home/blake/kitchen-worlds/assets/models/Oven/101924/textured_objs/original-49.obj" />/&gt;
			</geometry>
		</collision>
		<collision>
			<origin xyz="-0.5489212254039852 0.20136937466374594 -0.3894739712377725" />
			<geometry>
				<mesh filename="/home/blake/kitchen-worlds/assets/models/Oven/101924/textured_objs/original-158.obj" />/&gt;
			</geometry>
		</collision>
		<collision>
			<origin xyz="-0.5489212254039852 0.20136937466374594 -0.3894739712377725" />
			<geometry>
				<mesh filename="/home/blake/kitchen-worlds/assets/models/Oven/101924/textured_objs/original-159.obj" />/&gt;
			</geometry>
		</collision>
	</link>
	<joint name="joint_0" type="revolute">
		<origin xyz="0.5489212254039852 -0.20136937466374594 0.3894739712377725" />
		<axis xyz="1 0 0" />
		<child link="link_0" />
		<parent link="link_11" />
		<limit lower="0.0" upper="1.5707963267948966" effort="10.0" velocity="1.0" />
	</joint>
	<link name="link_1">
		<visual name="door-4">
			<origin xyz="-0.5489212254039852 0.20136937466374594 -0.3894739712377725" />
			<geometry>
				<mesh filename="/home/blake/kitchen-worlds/assets/models/Oven/101924/textured_objs/original-160.obj" />/&gt;
			</geometry>
		</visual>
		<visual name="door-4">
			<origin xyz="-0.5489212254039852 0.20136937466374594 -0.3894739712377725" />
			<geometry>
				<mesh filename="/home/blake/kitchen-worlds/assets/models/Oven/101924/textured_objs/original-50.obj" />/&gt;
			</geometry>
		</visual>
		<visual name="door-4">
			<origin xyz="-0.5489212254039852 0.20136937466374594 -0.3894739712377725" />
			<geometry>
				<mesh filename="/home/blake/kitchen-worlds/assets/models/Oven/101924/textured_objs/original-107.obj" />/&gt;
			</geometry>
		</visual>
		<visual name="door-4">
			<origin xyz="-0.5489212254039852 0.20136937466374594 -0.3894739712377725" />
			<geometry>
				<mesh filename="/home/blake/kitchen-worlds/assets/models/Oven/101924/textured_objs/original-161.obj" />/&gt;
			</geometry>
		</visual>
		<collision>
			<origin xyz="-0.5489212254039852 0.20136937466374594 -0.3894739712377725" />
			<geometry>
				<mesh filename="/home/blake/kitchen-worlds/assets/models/Oven/101924/textured_objs/original-160.obj" />/&gt;
			</geometry>
		</collision>
		<collision>
			<origin xyz="-0.5489212254039852 0.20136937466374594 -0.3894739712377725" />
			<geometry>
				<mesh filename="/home/blake/kitchen-worlds/assets/models/Oven/101924/textured_objs/original-50.obj" />/&gt;
			</geometry>
		</collision>
		<collision>
			<origin xyz="-0.5489212254039852 0.20136937466374594 -0.3894739712377725" />
			<geometry>
				<mesh filename="/home/blake/kitchen-worlds/assets/models/Oven/101924/textured_objs/original-107.obj" />/&gt;
			</geometry>
		</collision>
		<collision>
			<origin xyz="-0.5489212254039852 0.20136937466374594 -0.3894739712377725" />
			<geometry>
				<mesh filename="/home/blake/kitchen-worlds/assets/models/Oven/101924/textured_objs/original-161.obj" />/&gt;
			</geometry>
		</collision>
	</link>
	<joint name="joint_1" type="revolute">
		<origin xyz="0.5489212254039852 -0.20136937466374594 0.3894739712377725" />
		<axis xyz="1 0 0" />
		<child link="link_1" />
		<parent link="link_11" />
		<limit lower="0.0" upper="1.5707963267948966" effort="10.0" velocity="1.0" />
	</joint>
	<link name="link_2">
		<visual name="knob-5">
			<origin xyz="-0.3965274866293377 -0.229991298161458 0.061819660943966445" />
			<geometry>
				<mesh filename="/home/blake/kitchen-worlds/assets/models/Oven/101924/textured_objs/original-15.obj" />/&gt;
			</geometry>
		</visual>
		<visual name="knob-5">
			<origin xyz="-0.3965274866293377 -0.229991298161458 0.061819660943966445" />
			<geometry>
				<mesh filename="/home/blake/kitchen-worlds/assets/models/Oven/101924/textured_objs/original-112.obj" />/&gt;
			</geometry>
		</visual>
		<visual name="knob-5">
			<origin xyz="-0.3965274866293377 -0.229991298161458 0.061819660943966445" />
			<geometry>
				<mesh filename="/home/blake/kitchen-worlds/assets/models/Oven/101924/textured_objs/original-111.obj" />/&gt;
			</geometry>
		</visual>
		<collision>
			<origin xyz="-0.3965274866293377 -0.229991298161458 0.061819660943966445" />
			<geometry>
				<mesh filename="/home/blake/kitchen-worlds/assets/models/Oven/101924/textured_objs/original-15.obj" />/&gt;
			</geometry>
		</collision>
		<collision>
			<origin xyz="-0.3965274866293377 -0.229991298161458 0.061819660943966445" />
			<geometry>
				<mesh filename="/home/blake/kitchen-worlds/assets/models/Oven/101924/textured_objs/original-112.obj" />/&gt;
			</geometry>
		</collision>
		<collision>
			<origin xyz="-0.3965274866293377 -0.229991298161458 0.061819660943966445" />
			<geometry>
				<mesh filename="/home/blake/kitchen-worlds/assets/models/Oven/101924/textured_objs/original-111.obj" />/&gt;
			</geometry>
		</collision>
	</link>
	<joint name="joint_2" type="continuous">
		<origin xyz="0.3965274866293377 0.229991298161458 -0.061819660943966445" />
		<axis xyz="5.564038959584587e-05 -0.2586185789798998 -0.9659795171278553" />
		<child link="link_2" />
		<parent link="link_11" />
	</joint>
	<link name="link_3">
		<visual name="knob-6">
			<origin xyz="-0.3366339696288812 -0.22988625184047795 0.06187904115831878" />
			<geometry>
				<mesh filename="/home/blake/kitchen-worlds/assets/models/Oven/101924/textured_objs/original-23.obj" />/&gt;
			</geometry>
		</visual>
		<visual name="knob-6">
			<origin xyz="-0.3366339696288812 -0.22988625184047795 0.06187904115831878" />
			<geometry>
				<mesh filename="/home/blake/kitchen-worlds/assets/models/Oven/101924/textured_objs/original-128.obj" />/&gt;
			</geometry>
		</visual>
		<visual name="knob-6">
			<origin xyz="-0.3366339696288812 -0.22988625184047795 0.06187904115831878" />
			<geometry>
				<mesh filename="/home/blake/kitchen-worlds/assets/models/Oven/101924/textured_objs/original-127.obj" />/&gt;
			</geometry>
		</visual>
		<collision>
			<origin xyz="-0.3366339696288812 -0.22988625184047795 0.06187904115831878" />
			<geometry>
				<mesh filename="/home/blake/kitchen-worlds/assets/models/Oven/101924/textured_objs/original-23.obj" />/&gt;
			</geometry>
		</collision>
		<collision>
			<origin xyz="-0.3366339696288812 -0.22988625184047795 0.06187904115831878" />
			<geometry>
				<mesh filename="/home/blake/kitchen-worlds/assets/models/Oven/101924/textured_objs/original-128.obj" />/&gt;
			</geometry>
		</collision>
		<collision>
			<origin xyz="-0.3366339696288812 -0.22988625184047795 0.06187904115831878" />
			<geometry>
				<mesh filename="/home/blake/kitchen-worlds/assets/models/Oven/101924/textured_objs/original-127.obj" />/&gt;
			</geometry>
		</collision>
	</link>
	<joint name="joint_3" type="continuous">
		<origin xyz="0.3366339696288812 0.22988625184047795 -0.06187904115831878" />
		<axis xyz="-5.6777823230002025e-05 -0.2587933182907042 -0.9659327177316054" />
		<child link="link_3" />
		<parent link="link_11" />
	</joint>
	<link name="link_4">
		<visual name="knob-7">
			<origin xyz="-0.276793969615034 -0.22988713111276762 0.06187575931989689" />
			<geometry>
				<mesh filename="/home/blake/kitchen-worlds/assets/models/Oven/101924/textured_objs/original-18.obj" />/&gt;
			</geometry>
		</visual>
		<visual name="knob-7">
			<origin xyz="-0.276793969615034 -0.22988713111276762 0.06187575931989689" />
			<geometry>
				<mesh filename="/home/blake/kitchen-worlds/assets/models/Oven/101924/textured_objs/original-116.obj" />/&gt;
			</geometry>
		</visual>
		<visual name="knob-7">
			<origin xyz="-0.276793969615034 -0.22988713111276762 0.06187575931989689" />
			<geometry>
				<mesh filename="/home/blake/kitchen-worlds/assets/models/Oven/101924/textured_objs/original-115.obj" />/&gt;
			</geometry>
		</visual>
		<collision>
			<origin xyz="-0.276793969615034 -0.22988713111276762 0.06187575931989689" />
			<geometry>
				<mesh filename="/home/blake/kitchen-worlds/assets/models/Oven/101924/textured_objs/original-18.obj" />/&gt;
			</geometry>
		</collision>
		<collision>
			<origin xyz="-0.276793969615034 -0.22988713111276762 0.06187575931989689" />
			<geometry>
				<mesh filename="/home/blake/kitchen-worlds/assets/models/Oven/101924/textured_objs/original-116.obj" />/&gt;
			</geometry>
		</collision>
		<collision>
			<origin xyz="-0.276793969615034 -0.22988713111276762 0.06187575931989689" />
			<geometry>
				<mesh filename="/home/blake/kitchen-worlds/assets/models/Oven/101924/textured_objs/original-115.obj" />/&gt;
			</geometry>
		</collision>
	</link>
	<joint name="joint_4" type="continuous">
		<origin xyz="0.276793969615034 0.22988713111276762 -0.06187575931989689" />
		<axis xyz="-5.6777823230002025e-05 -0.2587933182907042 -0.9659327177316054" />
		<child link="link_4" />
		<parent link="link_11" />
	</joint>
	<link name="link_5">
		<visual name="knob-8">
			<origin xyz="-0.2172509913028825 -0.23016080379476836 0.06166470387233825" />
			<geometry>
				<mesh filename="/home/blake/kitchen-worlds/assets/models/Oven/101924/textured_objs/original-117.obj" />/&gt;
			</geometry>
		</visual>
		<visual name="knob-8">
			<origin xyz="-0.2172509913028825 -0.23016080379476836 0.06166470387233825" />
			<geometry>
				<mesh filename="/home/blake/kitchen-worlds/assets/models/Oven/101924/textured_objs/original-120.obj" />/&gt;
			</geometry>
		</visual>
		<collision>
			<origin xyz="-0.2172509913028825 -0.23016080379476836 0.06166470387233825" />
			<geometry>
				<mesh filename="/home/blake/kitchen-worlds/assets/models/Oven/101924/textured_objs/original-117.obj" />/&gt;
			</geometry>
		</collision>
		<collision>
			<origin xyz="-0.2172509913028825 -0.23016080379476836 0.06166470387233825" />
			<geometry>
				<mesh filename="/home/blake/kitchen-worlds/assets/models/Oven/101924/textured_objs/original-120.obj" />/&gt;
			</geometry>
		</collision>
	</link>
	<joint name="joint_5" type="continuous">
		<origin xyz="0.2172509913028825 0.23016080379476836 -0.06166470387233825" />
		<axis xyz="0 -0.2587928207036303 -0.9659328527140273" />
		<child link="link_5" />
		<parent link="link_11" />
	</joint>
	<link name="link_6">
		<visual name="knob-9">
			<origin xyz="0.0071486230960975715 -0.23013643181635182 0.061669596863122414" />
			<geometry>
				<mesh filename="/home/blake/kitchen-worlds/assets/models/Oven/101924/textured_objs/original-141.obj" />/&gt;
			</geometry>
		</visual>
		<visual name="knob-9">
			<origin xyz="0.0071486230960975715 -0.23013643181635182 0.061669596863122414" />
			<geometry>
				<mesh filename="/home/blake/kitchen-worlds/assets/models/Oven/101924/textured_objs/original-144.obj" />/&gt;
			</geometry>
		</visual>
		<collision>
			<origin xyz="0.0071486230960975715 -0.23013643181635182 0.061669596863122414" />
			<geometry>
				<mesh filename="/home/blake/kitchen-worlds/assets/models/Oven/101924/textured_objs/original-141.obj" />/&gt;
			</geometry>
		</collision>
		<collision>
			<origin xyz="0.0071486230960975715 -0.23013643181635182 0.061669596863122414" />
			<geometry>
				<mesh filename="/home/blake/kitchen-worlds/assets/models/Oven/101924/textured_objs/original-144.obj" />/&gt;
			</geometry>
		</collision>
	</link>
	<joint name="joint_6" type="continuous">
		<origin xyz="-0.0071486230960975715 0.23013643181635182 -0.061669596863122414" />
		<axis xyz="0 0.2588375585204928 0.9659208654435159" />
		<child link="link_6" />
		<parent link="link_11" />
	</joint>
	<link name="link_7">
		<visual name="knob-10">
			<origin xyz="0.277250302350674 -0.22989526432496335 0.061845402525703266" />
			<geometry>
				<mesh filename="/home/blake/kitchen-worlds/assets/models/Oven/101924/textured_objs/original-132.obj" />/&gt;
			</geometry>
		</visual>
		<visual name="knob-10">
			<origin xyz="0.277250302350674 -0.22989526432496335 0.061845402525703266" />
			<geometry>
				<mesh filename="/home/blake/kitchen-worlds/assets/models/Oven/101924/textured_objs/original-131.obj" />/&gt;
			</geometry>
		</visual>
		<visual name="knob-10">
			<origin xyz="0.277250302350674 -0.22989526432496335 0.061845402525703266" />
			<geometry>
				<mesh filename="/home/blake/kitchen-worlds/assets/models/Oven/101924/textured_objs/original-26.obj" />/&gt;
			</geometry>
		</visual>
		<collision>
			<origin xyz="0.277250302350674 -0.22989526432496335 0.061845402525703266" />
			<geometry>
				<mesh filename="/home/blake/kitchen-worlds/assets/models/Oven/101924/textured_objs/original-132.obj" />/&gt;
			</geometry>
		</collision>
		<collision>
			<origin xyz="0.277250302350674 -0.22989526432496335 0.061845402525703266" />
			<geometry>
				<mesh filename="/home/blake/kitchen-worlds/assets/models/Oven/101924/textured_objs/original-131.obj" />/&gt;
			</geometry>
		</collision>
		<collision>
			<origin xyz="0.277250302350674 -0.22989526432496335 0.061845402525703266" />
			<geometry>
				<mesh filename="/home/blake/kitchen-worlds/assets/models/Oven/101924/textured_objs/original-26.obj" />/&gt;
			</geometry>
		</collision>
	</link>
	<joint name="joint_7" type="continuous">
		<origin xyz="-0.277250302350674 0.22989526432496335 -0.061845402525703266" />
		<axis xyz="-5.677724057017104e-05 -0.2587933343973364 -0.9659327134163401" />
		<child link="link_7" />
		<parent link="link_11" />
	</joint>
	<link name="link_8">
		<visual name="knob-11">
			<origin xyz="0.3365650305268994 -0.22989614363904307 0.06184212053091609" />
			<geometry>
				<mesh filename="/home/blake/kitchen-worlds/assets/models/Oven/101924/textured_objs/original-29.obj" />/&gt;
			</geometry>
		</visual>
		<visual name="knob-11">
			<origin xyz="0.3365650305268994 -0.22989614363904307 0.06184212053091609" />
			<geometry>
				<mesh filename="/home/blake/kitchen-worlds/assets/models/Oven/101924/textured_objs/original-136.obj" />/&gt;
			</geometry>
		</visual>
		<visual name="knob-11">
			<origin xyz="0.3365650305268994 -0.22989614363904307 0.06184212053091609" />
			<geometry>
				<mesh filename="/home/blake/kitchen-worlds/assets/models/Oven/101924/textured_objs/original-135.obj" />/&gt;
			</geometry>
		</visual>
		<collision>
			<origin xyz="0.3365650305268994 -0.22989614363904307 0.06184212053091609" />
			<geometry>
				<mesh filename="/home/blake/kitchen-worlds/assets/models/Oven/101924/textured_objs/original-29.obj" />/&gt;
			</geometry>
		</collision>
		<collision>
			<origin xyz="0.3365650305268994 -0.22989614363904307 0.06184212053091609" />
			<geometry>
				<mesh filename="/home/blake/kitchen-worlds/assets/models/Oven/101924/textured_objs/original-136.obj" />/&gt;
			</geometry>
		</collision>
		<collision>
			<origin xyz="0.3365650305268994 -0.22989614363904307 0.06184212053091609" />
			<geometry>
				<mesh filename="/home/blake/kitchen-worlds/assets/models/Oven/101924/textured_objs/original-135.obj" />/&gt;
			</geometry>
		</collision>
	</link>
	<joint name="joint_8" type="continuous">
		<origin xyz="-0.3365650305268994 0.22989614363904307 -0.06184212053091609" />
		<axis xyz="-5.6777823230002025e-05 -0.2587933182907042 -0.9659327177316054" />
		<child link="link_8" />
		<parent link="link_11" />
	</joint>
	<link name="link_9">
		<visual name="knob-12">
			<origin xyz="0.3963515083547591 -0.2299798878029277 0.0618622732295198" />
			<geometry>
				<mesh filename="/home/blake/kitchen-worlds/assets/models/Oven/101924/textured_objs/original-32.obj" />/&gt;
			</geometry>
		</visual>
		<visual name="knob-12">
			<origin xyz="0.3963515083547591 -0.2299798878029277 0.0618622732295198" />
			<geometry>
				<mesh filename="/home/blake/kitchen-worlds/assets/models/Oven/101924/textured_objs/original-140.obj" />/&gt;
			</geometry>
		</visual>
		<visual name="knob-12">
			<origin xyz="0.3963515083547591 -0.2299798878029277 0.0618622732295198" />
			<geometry>
				<mesh filename="/home/blake/kitchen-worlds/assets/models/Oven/101924/textured_objs/original-139.obj" />/&gt;
			</geometry>
		</visual>
		<collision>
			<origin xyz="0.3963515083547591 -0.2299798878029277 0.0618622732295198" />
			<geometry>
				<mesh filename="/home/blake/kitchen-worlds/assets/models/Oven/101924/textured_objs/original-32.obj" />/&gt;
			</geometry>
		</collision>
		<collision>
			<origin xyz="0.3963515083547591 -0.2299798878029277 0.0618622732295198" />
			<geometry>
				<mesh filename="/home/blake/kitchen-worlds/assets/models/Oven/101924/textured_objs/original-140.obj" />/&gt;
			</geometry>
		</collision>
		<collision>
			<origin xyz="0.3963515083547591 -0.2299798878029277 0.0618622732295198" />
			<geometry>
				<mesh filename="/home/blake/kitchen-worlds/assets/models/Oven/101924/textured_objs/original-139.obj" />/&gt;
			</geometry>
		</collision>
	</link>
	<joint name="joint_9" type="continuous">
		<origin xyz="-0.3963515083547591 0.2299798878029277 -0.0618622732295198" />
		<axis xyz="5.56512975216049e-05 -0.25861857869836985 -0.9659795172026" />
		<child link="link_9" />
		<parent link="link_11" />
	</joint>
	<link name="link_10">
		<visual name="knob-13">
			<origin xyz="0.455948 -0.23016067880652694 0.06166467038547703" />
			<geometry>
				<mesh filename="/home/blake/kitchen-worlds/assets/models/Oven/101924/textured_objs/original-124.obj" />/&gt;
			</geometry>
		</visual>
		<visual name="knob-13">
			<origin xyz="0.455948 -0.23016067880652694 0.06166467038547703" />
			<geometry>
				<mesh filename="/home/blake/kitchen-worlds/assets/models/Oven/101924/textured_objs/original-121.obj" />/&gt;
			</geometry>
		</visual>
		<collision>
			<origin xyz="0.455948 -0.23016067880652694 0.06166467038547703" />
			<geometry>
				<mesh filename="/home/blake/kitchen-worlds/assets/models/Oven/101924/textured_objs/original-124.obj" />/&gt;
			</geometry>
		</collision>
		<collision>
			<origin xyz="0.455948 -0.23016067880652694 0.06166467038547703" />
			<geometry>
				<mesh filename="/home/blake/kitchen-worlds/assets/models/Oven/101924/textured_objs/original-121.obj" />/&gt;
			</geometry>
		</collision>
	</link>
	<joint name="joint_10" type="continuous">
		<origin xyz="-0.455948 0.23016067880652694 -0.06166467038547703" />
		<axis xyz="0 0.25879282070364895 0.9659328527140223" />
		<child link="link_10" />
		<parent link="link_11" />
	</joint>
	<link name="link_11">
		<visual name="door-1">
			<origin xyz="0 0 0" />
			<geometry>
				<mesh filename="/home/blake/kitchen-worlds/assets/models/Oven/101924/textured_objs/original-103.obj" />/&gt;
			</geometry>
		</visual>
		<visual name="door-1">
			<origin xyz="0 0 0" />
			<geometry>
				<mesh filename="/home/blake/kitchen-worlds/assets/models/Oven/101924/textured_objs/original-51.obj" />/&gt;
			</geometry>
		</visual>
		<visual name="door-3">
			<origin xyz="0 0 0" />
			<geometry>
				<mesh filename="/home/blake/kitchen-worlds/assets/models/Oven/101924/textured_objs/original-108.obj" />/&gt;
			</geometry>
		</visual>
		<visual name="door-3">
			<origin xyz="0 0 0" />
			<geometry>
				<mesh filename="/home/blake/kitchen-worlds/assets/models/Oven/101924/textured_objs/original-48.obj" />/&gt;
			</geometry>
		</visual>
		<visual name="base_body-14">
			<origin xyz="0 0 0" />
			<geometry>
				<mesh filename="/home/blake/kitchen-worlds/assets/models/Oven/101924/textured_objs/original-123.obj" />/&gt;
			</geometry>
		</visual>
		<visual name="base_body-14">
			<origin xyz="0 0 0" />
			<geometry>
				<mesh filename="/home/blake/kitchen-worlds/assets/models/Oven/101924/textured_objs/original-152.obj" />/&gt;
			</geometry>
		</visual>
		<visual name="base_body-14">
			<origin xyz="0 0 0" />
			<geometry>
				<mesh filename="/home/blake/kitchen-worlds/assets/models/Oven/101924/textured_objs/original-154.obj" />/&gt;
			</geometry>
		</visual>
		<visual name="base_body-14">
			<origin xyz="0 0 0" />
			<geometry>
				<mesh filename="/home/blake/kitchen-worlds/assets/models/Oven/101924/textured_objs/original-126.obj" />/&gt;
			</geometry>
		</visual>
		<visual name="base_body-14">
			<origin xyz="0 0 0" />
			<geometry>
				<mesh filename="/home/blake/kitchen-worlds/assets/models/Oven/101924/textured_objs/original-119.obj" />/&gt;
			</geometry>
		</visual>
		<visual name="base_body-14">
			<origin xyz="0 0 0" />
			<geometry>
				<mesh filename="/home/blake/kitchen-worlds/assets/models/Oven/101924/textured_objs/original-41.obj" />/&gt;
			</geometry>
		</visual>
		<visual name="base_body-14">
			<origin xyz="0 0 0" />
			<geometry>
				<mesh filename="/home/blake/kitchen-worlds/assets/models/Oven/101924/textured_objs/original-96.obj" />/&gt;
			</geometry>
		</visual>
		<visual name="base_body-14">
			<origin xyz="0 0 0" />
			<geometry>
				<mesh filename="/home/blake/kitchen-worlds/assets/models/Oven/101924/textured_objs/original-64.obj" />/&gt;
			</geometry>
		</visual>
		<visual name="base_body-14">
			<origin xyz="0 0 0" />
			<geometry>
				<mesh filename="/home/blake/kitchen-worlds/assets/models/Oven/101924/textured_objs/original-134.obj" />/&gt;
			</geometry>
		</visual>
		<visual name="base_body-14">
			<origin xyz="0 0 0" />
			<geometry>
				<mesh filename="/home/blake/kitchen-worlds/assets/models/Oven/101924/textured_objs/original-43.obj" />/&gt;
			</geometry>
		</visual>
		<visual name="base_body-14">
			<origin xyz="0 0 0" />
			<geometry>
				<mesh filename="/home/blake/kitchen-worlds/assets/models/Oven/101924/textured_objs/original-71.obj" />/&gt;
			</geometry>
		</visual>
		<visual name="base_body-14">
			<origin xyz="0 0 0" />
			<geometry>
				<mesh filename="/home/blake/kitchen-worlds/assets/models/Oven/101924/textured_objs/original-52.obj" />/&gt;
			</geometry>
		</visual>
		<visual name="base_body-14">
			<origin xyz="0 0 0" />
			<geometry>
				<mesh filename="/home/blake/kitchen-worlds/assets/models/Oven/101924/textured_objs/original-83.obj" />/&gt;
			</geometry>
		</visual>
		<visual name="base_body-14">
			<origin xyz="0 0 0" />
			<geometry>
				<mesh filename="/home/blake/kitchen-worlds/assets/models/Oven/101924/textured_objs/original-110.obj" />/&gt;
			</geometry>
		</visual>
		<visual name="base_body-14">
			<origin xyz="0 0 0" />
			<geometry>
				<mesh filename="/home/blake/kitchen-worlds/assets/models/Oven/101924/textured_objs/original-153.obj" />/&gt;
			</geometry>
		</visual>
		<visual name="base_body-14">
			<origin xyz="0 0 0" />
			<geometry>
				<mesh filename="/home/blake/kitchen-worlds/assets/models/Oven/101924/textured_objs/original-4.obj" />/&gt;
			</geometry>
		</visual>
		<visual name="base_body-14">
			<origin xyz="0 0 0" />
			<geometry>
				<mesh filename="/home/blake/kitchen-worlds/assets/models/Oven/101924/textured_objs/original-149.obj" />/&gt;
			</geometry>
		</visual>
		<visual name="base_body-14">
			<origin xyz="0 0 0" />
			<geometry>
				<mesh filename="/home/blake/kitchen-worlds/assets/models/Oven/101924/textured_objs/original-3.obj" />/&gt;
			</geometry>
		</visual>
		<visual name="base_body-14">
			<origin xyz="0 0 0" />
			<geometry>
				<mesh filename="/home/blake/kitchen-worlds/assets/models/Oven/101924/textured_objs/original-65.obj" />/&gt;
			</geometry>
		</visual>
		<visual name="base_body-14">
			<origin xyz="0 0 0" />
			<geometry>
				<mesh filename="/home/blake/kitchen-worlds/assets/models/Oven/101924/textured_objs/original-2.obj" />/&gt;
			</geometry>
		</visual>
		<visual name="base_body-14">
			<origin xyz="0 0 0" />
			<geometry>
				<mesh filename="/home/blake/kitchen-worlds/assets/models/Oven/101924/textured_objs/original-130.obj" />/&gt;
			</geometry>
		</visual>
		<visual name="base_body-14">
			<origin xyz="0 0 0" />
			<geometry>
				<mesh filename="/home/blake/kitchen-worlds/assets/models/Oven/101924/textured_objs/original-137.obj" />/&gt;
			</geometry>
		</visual>
		<visual name="base_body-14">
			<origin xyz="0 0 0" />
			<geometry>
				<mesh filename="/home/blake/kitchen-worlds/assets/models/Oven/101924/textured_objs/original-44.obj" />/&gt;
			</geometry>
		</visual>
		<visual name="base_body-14">
			<origin xyz="0 0 0" />
			<geometry>
				<mesh filename="/home/blake/kitchen-worlds/assets/models/Oven/101924/textured_objs/original-86.obj" />/&gt;
			</geometry>
		</visual>
		<visual name="base_body-14">
			<origin xyz="0 0 0" />
			<geometry>
				<mesh filename="/home/blake/kitchen-worlds/assets/models/Oven/101924/textured_objs/original-8.obj" />/&gt;
			</geometry>
		</visual>
		<visual name="base_body-14">
			<origin xyz="0 0 0" />
			<geometry>
				<mesh filename="/home/blake/kitchen-worlds/assets/models/Oven/101924/textured_objs/original-147.obj" />/&gt;
			</geometry>
		</visual>
		<visual name="base_body-14">
			<origin xyz="0 0 0" />
			<geometry>
				<mesh filename="/home/blake/kitchen-worlds/assets/models/Oven/101924/textured_objs/original-109.obj" />/&gt;
			</geometry>
		</visual>
		<visual name="base_body-14">
			<origin xyz="0 0 0" />
			<geometry>
				<mesh filename="/home/blake/kitchen-worlds/assets/models/Oven/101924/textured_objs/original-9.obj" />/&gt;
			</geometry>
		</visual>
		<visual name="base_body-14">
			<origin xyz="0 0 0" />
			<geometry>
				<mesh filename="/home/blake/kitchen-worlds/assets/models/Oven/101924/textured_objs/original-125.obj" />/&gt;
			</geometry>
		</visual>
		<visual name="base_body-14">
			<origin xyz="0 0 0" />
			<geometry>
				<mesh filename="/home/blake/kitchen-worlds/assets/models/Oven/101924/textured_objs/original-45.obj" />/&gt;
			</geometry>
		</visual>
		<visual name="base_body-14">
			<origin xyz="0 0 0" />
			<geometry>
				<mesh filename="/home/blake/kitchen-worlds/assets/models/Oven/101924/textured_objs/original-148.obj" />/&gt;
			</geometry>
		</visual>
		<visual name="base_body-14">
			<origin xyz="0 0 0" />
			<geometry>
				<mesh filename="/home/blake/kitchen-worlds/assets/models/Oven/101924/textured_objs/original-138.obj" />/&gt;
			</geometry>
		</visual>
		<visual name="base_body-14">
			<origin xyz="0 0 0" />
			<geometry>
				<mesh filename="/home/blake/kitchen-worlds/assets/models/Oven/101924/textured_objs/original-156.obj" />/&gt;
			</geometry>
		</visual>
		<visual name="base_body-14">
			<origin xyz="0 0 0" />
			<geometry>
				<mesh filename="/home/blake/kitchen-worlds/assets/models/Oven/101924/textured_objs/original-93.obj" />/&gt;
			</geometry>
		</visual>
		<visual name="base_body-14">
			<origin xyz="0 0 0" />
			<geometry>
				<mesh filename="/home/blake/kitchen-worlds/assets/models/Oven/101924/textured_objs/original-39.obj" />/&gt;
			</geometry>
		</visual>
		<visual name="base_body-14">
			<origin xyz="0 0 0" />
			<geometry>
				<mesh filename="/home/blake/kitchen-worlds/assets/models/Oven/101924/textured_objs/original-59.obj" />/&gt;
			</geometry>
		</visual>
		<visual name="base_body-14">
			<origin xyz="0 0 0" />
			<geometry>
				<mesh filename="/home/blake/kitchen-worlds/assets/models/Oven/101924/textured_objs/original-5.obj" />/&gt;
			</geometry>
		</visual>
		<visual name="base_body-14">
			<origin xyz="0 0 0" />
			<geometry>
				<mesh filename="/home/blake/kitchen-worlds/assets/models/Oven/101924/textured_objs/original-77.obj" />/&gt;
			</geometry>
		</visual>
		<visual name="base_body-14">
			<origin xyz="0 0 0" />
			<geometry>
				<mesh filename="/home/blake/kitchen-worlds/assets/models/Oven/101924/textured_objs/original-114.obj" />/&gt;
			</geometry>
		</visual>
		<visual name="base_body-14">
			<origin xyz="0 0 0" />
			<geometry>
				<mesh filename="/home/blake/kitchen-worlds/assets/models/Oven/101924/textured_objs/original-150.obj" />/&gt;
			</geometry>
		</visual>
		<visual name="base_body-14">
			<origin xyz="0 0 0" />
			<geometry>
				<mesh filename="/home/blake/kitchen-worlds/assets/models/Oven/101924/textured_objs/original-63.obj" />/&gt;
			</geometry>
		</visual>
		<visual name="base_body-14">
			<origin xyz="0 0 0" />
			<geometry>
				<mesh filename="/home/blake/kitchen-worlds/assets/models/Oven/101924/textured_objs/original-87.obj" />/&gt;
			</geometry>
		</visual>
		<visual name="base_body-14">
			<origin xyz="0 0 0" />
			<geometry>
				<mesh filename="/home/blake/kitchen-worlds/assets/models/Oven/101924/textured_objs/original-113.obj" />/&gt;
			</geometry>
		</visual>
		<visual name="base_body-14">
			<origin xyz="0 0 0" />
			<geometry>
				<mesh filename="/home/blake/kitchen-worlds/assets/models/Oven/101924/textured_objs/original-6.obj" />/&gt;
			</geometry>
		</visual>
		<visual name="base_body-14">
			<origin xyz="0 0 0" />
			<geometry>
				<mesh filename="/home/blake/kitchen-worlds/assets/models/Oven/101924/textured_objs/original-37.obj" />/&gt;
			</geometry>
		</visual>
		<visual name="base_body-14">
			<origin xyz="0 0 0" />
			<geometry>
				<mesh filename="/home/blake/kitchen-worlds/assets/models/Oven/101924/textured_objs/original-85.obj" />/&gt;
			</geometry>
		</visual>
		<visual name="base_body-14">
			<origin xyz="0 0 0" />
			<geometry>
				<mesh filename="/home/blake/kitchen-worlds/assets/models/Oven/101924/textured_objs/original-122.obj" />/&gt;
			</geometry>
		</visual>
		<visual name="base_body-14">
			<origin xyz="0 0 0" />
			<geometry>
				<mesh filename="/home/blake/kitchen-worlds/assets/models/Oven/101924/textured_objs/original-76.obj" />/&gt;
			</geometry>
		</visual>
		<visual name="base_body-14">
			<origin xyz="0 0 0" />
			<geometry>
				<mesh filename="/home/blake/kitchen-worlds/assets/models/Oven/101924/textured_objs/original-72.obj" />/&gt;
			</geometry>
		</visual>
		<visual name="base_body-14">
			<origin xyz="0 0 0" />
			<geometry>
				<mesh filename="/home/blake/kitchen-worlds/assets/models/Oven/101924/textured_objs/original-62.obj" />/&gt;
			</geometry>
		</visual>
		<visual name="base_body-14">
			<origin xyz="0 0 0" />
			<geometry>
				<mesh filename="/home/blake/kitchen-worlds/assets/models/Oven/101924/textured_objs/original-75.obj" />/&gt;
			</geometry>
		</visual>
		<visual name="base_body-14">
			<origin xyz="0 0 0" />
			<geometry>
				<mesh filename="/home/blake/kitchen-worlds/assets/models/Oven/101924/textured_objs/original-133.obj" />/&gt;
			</geometry>
		</visual>
		<visual name="base_body-14">
			<origin xyz="0 0 0" />
			<geometry>
				<mesh filename="/home/blake/kitchen-worlds/assets/models/Oven/101924/textured_objs/original-66.obj" />/&gt;
			</geometry>
		</visual>
		<visual name="base_body-14">
			<origin xyz="0 0 0" />
			<geometry>
				<mesh filename="/home/blake/kitchen-worlds/assets/models/Oven/101924/textured_objs/original-58.obj" />/&gt;
			</geometry>
		</visual>
		<visual name="base_body-14">
			<origin xyz="0 0 0" />
			<geometry>
				<mesh filename="/home/blake/kitchen-worlds/assets/models/Oven/101924/textured_objs/original-145.obj" />/&gt;
			</geometry>
		</visual>
		<visual name="base_body-14">
			<origin xyz="0 0 0" />
			<geometry>
				<mesh filename="/home/blake/kitchen-worlds/assets/models/Oven/101924/textured_objs/original-98.obj" />/&gt;
			</geometry>
		</visual>
		<visual name="base_body-14">
			<origin xyz="0 0 0" />
			<geometry>
				<mesh filename="/home/blake/kitchen-worlds/assets/models/Oven/101924/textured_objs/original-67.obj" />/&gt;
			</geometry>
		</visual>
		<visual name="base_body-14">
			<origin xyz="0 0 0" />
			<geometry>
				<mesh filename="/home/blake/kitchen-worlds/assets/models/Oven/101924/textured_objs/original-69.obj" />/&gt;
			</geometry>
		</visual>
		<visual name="base_body-14">
			<origin xyz="0 0 0" />
			<geometry>
				<mesh filename="/home/blake/kitchen-worlds/assets/models/Oven/101924/textured_objs/original-11.obj" />/&gt;
			</geometry>
		</visual>
		<visual name="base_body-14">
			<origin xyz="0 0 0" />
			<geometry>
				<mesh filename="/home/blake/kitchen-worlds/assets/models/Oven/101924/textured_objs/original-38.obj" />/&gt;
			</geometry>
		</visual>
		<visual name="base_body-14">
			<origin xyz="0 0 0" />
			<geometry>
				<mesh filename="/home/blake/kitchen-worlds/assets/models/Oven/101924/textured_objs/original-68.obj" />/&gt;
			</geometry>
		</visual>
		<visual name="base_body-14">
			<origin xyz="0 0 0" />
			<geometry>
				<mesh filename="/home/blake/kitchen-worlds/assets/models/Oven/101924/textured_objs/original-146.obj" />/&gt;
			</geometry>
		</visual>
		<visual name="base_body-14">
			<origin xyz="0 0 0" />
			<geometry>
				<mesh filename="/home/blake/kitchen-worlds/assets/models/Oven/101924/textured_objs/original-74.obj" />/&gt;
			</geometry>
		</visual>
		<visual name="base_body-14">
			<origin xyz="0 0 0" />
			<geometry>
				<mesh filename="/home/blake/kitchen-worlds/assets/models/Oven/101924/textured_objs/original-118.obj" />/&gt;
			</geometry>
		</visual>
		<visual name="base_body-14">
			<origin xyz="0 0 0" />
			<geometry>
				<mesh filename="/home/blake/kitchen-worlds/assets/models/Oven/101924/textured_objs/original-91.obj" />/&gt;
			</geometry>
		</visual>
		<visual name="base_body-14">
			<origin xyz="0 0 0" />
			<geometry>
				<mesh filename="/home/blake/kitchen-worlds/assets/models/Oven/101924/textured_objs/original-73.obj" />/&gt;
			</geometry>
		</visual>
		<visual name="base_body-14">
			<origin xyz="0 0 0" />
			<geometry>
				<mesh filename="/home/blake/kitchen-worlds/assets/models/Oven/101924/textured_objs/original-12.obj" />/&gt;
			</geometry>
		</visual>
		<visual name="base_body-14">
			<origin xyz="0 0 0" />
			<geometry>
				<mesh filename="/home/blake/kitchen-worlds/assets/models/Oven/101924/textured_objs/original-92.obj" />/&gt;
			</geometry>
		</visual>
		<visual name="base_body-14">
			<origin xyz="0 0 0" />
			<geometry>
				<mesh filename="/home/blake/kitchen-worlds/assets/models/Oven/101924/textured_objs/original-142.obj" />/&gt;
			</geometry>
		</visual>
		<visual name="base_body-14">
			<origin xyz="0 0 0" />
			<geometry>
				<mesh filename="/home/blake/kitchen-worlds/assets/models/Oven/101924/textured_objs/original-42.obj" />/&gt;
			</geometry>
		</visual>
		<visual name="base_body-14">
			<origin xyz="0 0 0" />
			<geometry>
				<mesh filename="/home/blake/kitchen-worlds/assets/models/Oven/101924/textured_objs/original-79.obj" />/&gt;
			</geometry>
		</visual>
		<visual name="base_body-14">
			<origin xyz="0 0 0" />
			<geometry>
				<mesh filename="/home/blake/kitchen-worlds/assets/models/Oven/101924/textured_objs/original-88.obj" />/&gt;
			</geometry>
		</visual>
		<visual name="base_body-14">
			<origin xyz="0 0 0" />
			<geometry>
				<mesh filename="/home/blake/kitchen-worlds/assets/models/Oven/101924/textured_objs/original-95.obj" />/&gt;
			</geometry>
		</visual>
		<visual name="base_body-14">
			<origin xyz="0 0 0" />
			<geometry>
				<mesh filename="/home/blake/kitchen-worlds/assets/models/Oven/101924/textured_objs/original-7.obj" />/&gt;
			</geometry>
		</visual>
		<visual name="base_body-14">
			<origin xyz="0 0 0" />
			<geometry>
				<mesh filename="/home/blake/kitchen-worlds/assets/models/Oven/101924/textured_objs/original-81.obj" />/&gt;
			</geometry>
		</visual>
		<visual name="base_body-14">
			<origin xyz="0 0 0" />
			<geometry>
				<mesh filename="/home/blake/kitchen-worlds/assets/models/Oven/101924/textured_objs/original-84.obj" />/&gt;
			</geometry>
		</visual>
		<visual name="base_body-14">
			<origin xyz="0 0 0" />
			<geometry>
				<mesh filename="/home/blake/kitchen-worlds/assets/models/Oven/101924/textured_objs/original-94.obj" />/&gt;
			</geometry>
		</visual>
		<visual name="base_body-14">
			<origin xyz="0 0 0" />
			<geometry>
				<mesh filename="/home/blake/kitchen-worlds/assets/models/Oven/101924/textured_objs/original-78.obj" />/&gt;
			</geometry>
		</visual>
		<visual name="base_body-14">
			<origin xyz="0 0 0" />
			<geometry>
				<mesh filename="/home/blake/kitchen-worlds/assets/models/Oven/101924/textured_objs/original-97.obj" />/&gt;
			</geometry>
		</visual>
		<visual name="base_body-14">
			<origin xyz="0 0 0" />
			<geometry>
				<mesh filename="/home/blake/kitchen-worlds/assets/models/Oven/101924/textured_objs/original-157.obj" />/&gt;
			</geometry>
		</visual>
		<visual name="base_body-14">
			<origin xyz="0 0 0" />
			<geometry>
				<mesh filename="/home/blake/kitchen-worlds/assets/models/Oven/101924/textured_objs/original-89.obj" />/&gt;
			</geometry>
		</visual>
		<visual name="base_body-14">
			<origin xyz="0 0 0" />
			<geometry>
				<mesh filename="/home/blake/kitchen-worlds/assets/models/Oven/101924/textured_objs/original-10.obj" />/&gt;
			</geometry>
		</visual>
		<visual name="base_body-14">
			<origin xyz="0 0 0" />
			<geometry>
				<mesh filename="/home/blake/kitchen-worlds/assets/models/Oven/101924/textured_objs/original-82.obj" />/&gt;
			</geometry>
		</visual>
		<visual name="base_body-14">
			<origin xyz="0 0 0" />
			<geometry>
				<mesh filename="/home/blake/kitchen-worlds/assets/models/Oven/101924/textured_objs/original-129.obj" />/&gt;
			</geometry>
		</visual>
		<visual name="base_body-14">
			<origin xyz="0 0 0" />
			<geometry>
				<mesh filename="/home/blake/kitchen-worlds/assets/models/Oven/101924/textured_objs/original-40.obj" />/&gt;
			</geometry>
		</visual>
		<visual name="base_body-14">
			<origin xyz="0 0 0" />
			<geometry>
				<mesh filename="/home/blake/kitchen-worlds/assets/models/Oven/101924/textured_objs/original-143.obj" />/&gt;
			</geometry>
		</visual>
		<visual name="base_body-14">
			<origin xyz="0 0 0" />
			<geometry>
				<mesh filename="/home/blake/kitchen-worlds/assets/models/Oven/101924/textured_objs/original-151.obj" />/&gt;
			</geometry>
		</visual>
		<visual name="base_body-14">
			<origin xyz="0 0 0" />
			<geometry>
				<mesh filename="/home/blake/kitchen-worlds/assets/models/Oven/101924/textured_objs/original-155.obj" />/&gt;
			</geometry>
		</visual>
		<visual name="base_body-14">
			<origin xyz="0 0 0" />
			<geometry>
				<mesh filename="/home/blake/kitchen-worlds/assets/models/Oven/101924/textured_objs/original-57.obj" />/&gt;
			</geometry>
		</visual>
		<collision>
			<origin xyz="0 0 0" />
			<geometry>
				<mesh filename="/home/blake/kitchen-worlds/assets/models/Oven/101924/textured_objs/original-103.obj" />/&gt;
			</geometry>
		</collision>
		<collision>
			<origin xyz="0 0 0" />
			<geometry>
				<mesh filename="/home/blake/kitchen-worlds/assets/models/Oven/101924/textured_objs/original-51.obj" />/&gt;
			</geometry>
		</collision>
		<collision>
			<origin xyz="0 0 0" />
			<geometry>
				<mesh filename="/home/blake/kitchen-worlds/assets/models/Oven/101924/textured_objs/original-108.obj" />/&gt;
			</geometry>
		</collision>
		<collision>
			<origin xyz="0 0 0" />
			<geometry>
				<mesh filename="/home/blake/kitchen-worlds/assets/models/Oven/101924/textured_objs/original-48.obj" />/&gt;
			</geometry>
		</collision>
		<collision>
			<origin xyz="0 0 0" />
			<geometry>
				<mesh filename="/home/blake/kitchen-worlds/assets/models/Oven/101924/textured_objs/original-123.obj" />/&gt;
			</geometry>
		</collision>
		<collision>
			<origin xyz="0 0 0" />
			<geometry>
				<mesh filename="/home/blake/kitchen-worlds/assets/models/Oven/101924/textured_objs/original-152.obj" />/&gt;
			</geometry>
		</collision>
		<collision>
			<origin xyz="0 0 0" />
			<geometry>
				<mesh filename="/home/blake/kitchen-worlds/assets/models/Oven/101924/textured_objs/original-154.obj" />/&gt;
			</geometry>
		</collision>
		<collision>
			<origin xyz="0 0 0" />
			<geometry>
				<mesh filename="/home/blake/kitchen-worlds/assets/models/Oven/101924/textured_objs/original-126.obj" />/&gt;
			</geometry>
		</collision>
		<collision>
			<origin xyz="0 0 0" />
			<geometry>
				<mesh filename="/home/blake/kitchen-worlds/assets/models/Oven/101924/textured_objs/original-119.obj" />/&gt;
			</geometry>
		</collision>
		<collision>
			<origin xyz="0 0 0" />
			<geometry>
				<mesh filename="/home/blake/kitchen-worlds/assets/models/Oven/101924/textured_objs/original-41.obj" />/&gt;
			</geometry>
		</collision>
		<collision>
			<origin xyz="0 0 0" />
			<geometry>
				<mesh filename="/home/blake/kitchen-worlds/assets/models/Oven/101924/textured_objs/original-96.obj" />/&gt;
			</geometry>
		</collision>
		<collision>
			<origin xyz="0 0 0" />
			<geometry>
				<mesh filename="/home/blake/kitchen-worlds/assets/models/Oven/101924/textured_objs/original-64.obj" />/&gt;
			</geometry>
		</collision>
		<collision>
			<origin xyz="0 0 0" />
			<geometry>
				<mesh filename="/home/blake/kitchen-worlds/assets/models/Oven/101924/textured_objs/original-134.obj" />/&gt;
			</geometry>
		</collision>
		<collision>
			<origin xyz="0 0 0" />
			<geometry>
				<mesh filename="/home/blake/kitchen-worlds/assets/models/Oven/101924/textured_objs/original-43.obj" />/&gt;
			</geometry>
		</collision>
		<collision>
			<origin xyz="0 0 0" />
			<geometry>
				<mesh filename="/home/blake/kitchen-worlds/assets/models/Oven/101924/textured_objs/original-71.obj" />/&gt;
			</geometry>
		</collision>
		<collision>
			<origin xyz="0 0 0" />
			<geometry>
				<mesh filename="/home/blake/kitchen-worlds/assets/models/Oven/101924/textured_objs/original-52.obj" />/&gt;
			</geometry>
		</collision>
		<collision>
			<origin xyz="0 0 0" />
			<geometry>
				<mesh filename="/home/blake/kitchen-worlds/assets/models/Oven/101924/textured_objs/original-83.obj" />/&gt;
			</geometry>
		</collision>
		<collision>
			<origin xyz="0 0 0" />
			<geometry>
				<mesh filename="/home/blake/kitchen-worlds/assets/models/Oven/101924/textured_objs/original-110.obj" />/&gt;
			</geometry>
		</collision>
		<collision>
			<origin xyz="0 0 0" />
			<geometry>
				<mesh filename="/home/blake/kitchen-worlds/assets/models/Oven/101924/textured_objs/original-153.obj" />/&gt;
			</geometry>
		</collision>
		<collision>
			<origin xyz="0 0 0" />
			<geometry>
				<mesh filename="/home/blake/kitchen-worlds/assets/models/Oven/101924/textured_objs/original-4.obj" />/&gt;
			</geometry>
		</collision>
		<collision>
			<origin xyz="0 0 0" />
			<geometry>
				<mesh filename="/home/blake/kitchen-worlds/assets/models/Oven/101924/textured_objs/original-149.obj" />/&gt;
			</geometry>
		</collision>
		<collision>
			<origin xyz="0 0 0" />
			<geometry>
				<mesh filename="/home/blake/kitchen-worlds/assets/models/Oven/101924/textured_objs/original-3.obj" />/&gt;
			</geometry>
		</collision>
		<collision>
			<origin xyz="0 0 0" />
			<geometry>
				<mesh filename="/home/blake/kitchen-worlds/assets/models/Oven/101924/textured_objs/original-65.obj" />/&gt;
			</geometry>
		</collision>
		<collision>
			<origin xyz="0 0 0" />
			<geometry>
				<mesh filename="/home/blake/kitchen-worlds/assets/models/Oven/101924/textured_objs/original-2.obj" />/&gt;
			</geometry>
		</collision>
		<collision>
			<origin xyz="0 0 0" />
			<geometry>
				<mesh filename="/home/blake/kitchen-worlds/assets/models/Oven/101924/textured_objs/original-130.obj" />/&gt;
			</geometry>
		</collision>
		<collision>
			<origin xyz="0 0 0" />
			<geometry>
				<mesh filename="/home/blake/kitchen-worlds/assets/models/Oven/101924/textured_objs/original-137.obj" />/&gt;
			</geometry>
		</collision>
		<collision>
			<origin xyz="0 0 0" />
			<geometry>
				<mesh filename="/home/blake/kitchen-worlds/assets/models/Oven/101924/textured_objs/original-44.obj" />/&gt;
			</geometry>
		</collision>
		<collision>
			<origin xyz="0 0 0" />
			<geometry>
				<mesh filename="/home/blake/kitchen-worlds/assets/models/Oven/101924/textured_objs/original-86.obj" />/&gt;
			</geometry>
		</collision>
		<collision>
			<origin xyz="0 0 0" />
			<geometry>
				<mesh filename="/home/blake/kitchen-worlds/assets/models/Oven/101924/textured_objs/original-8.obj" />/&gt;
			</geometry>
		</collision>
		<collision>
			<origin xyz="0 0 0" />
			<geometry>
				<mesh filename="/home/blake/kitchen-worlds/assets/models/Oven/101924/textured_objs/original-147.obj" />/&gt;
			</geometry>
		</collision>
		<collision>
			<origin xyz="0 0 0" />
			<geometry>
				<mesh filename="/home/blake/kitchen-worlds/assets/models/Oven/101924/textured_objs/original-109.obj" />/&gt;
			</geometry>
		</collision>
		<collision>
			<origin xyz="0 0 0" />
			<geometry>
				<mesh filename="/home/blake/kitchen-worlds/assets/models/Oven/101924/textured_objs/original-9.obj" />/&gt;
			</geometry>
		</collision>
		<collision>
			<origin xyz="0 0 0" />
			<geometry>
				<mesh filename="/home/blake/kitchen-worlds/assets/models/Oven/101924/textured_objs/original-125.obj" />/&gt;
			</geometry>
		</collision>
		<collision>
			<origin xyz="0 0 0" />
			<geometry>
				<mesh filename="/home/blake/kitchen-worlds/assets/models/Oven/101924/textured_objs/original-45.obj" />/&gt;
			</geometry>
		</collision>
		<collision>
			<origin xyz="0 0 0" />
			<geometry>
				<mesh filename="/home/blake/kitchen-worlds/assets/models/Oven/101924/textured_objs/original-148.obj" />/&gt;
			</geometry>
		</collision>
		<collision>
			<origin xyz="0 0 0" />
			<geometry>
				<mesh filename="/home/blake/kitchen-worlds/assets/models/Oven/101924/textured_objs/original-138.obj" />/&gt;
			</geometry>
		</collision>
		<collision>
			<origin xyz="0 0 0" />
			<geometry>
				<mesh filename="/home/blake/kitchen-worlds/assets/models/Oven/101924/textured_objs/original-156.obj" />/&gt;
			</geometry>
		</collision>
		<collision>
			<origin xyz="0 0 0" />
			<geometry>
				<mesh filename="/home/blake/kitchen-worlds/assets/models/Oven/101924/textured_objs/original-93.obj" />/&gt;
			</geometry>
		</collision>
		<collision>
			<origin xyz="0 0 0" />
			<geometry>
				<mesh filename="/home/blake/kitchen-worlds/assets/models/Oven/101924/textured_objs/original-39.obj" />/&gt;
			</geometry>
		</collision>
		<collision>
			<origin xyz="0 0 0" />
			<geometry>
				<mesh filename="/home/blake/kitchen-worlds/assets/models/Oven/101924/textured_objs/original-59.obj" />/&gt;
			</geometry>
		</collision>
		<collision>
			<origin xyz="0 0 0" />
			<geometry>
				<mesh filename="/home/blake/kitchen-worlds/assets/models/Oven/101924/textured_objs/original-5.obj" />/&gt;
			</geometry>
		</collision>
		<collision>
			<origin xyz="0 0 0" />
			<geometry>
				<mesh filename="/home/blake/kitchen-worlds/assets/models/Oven/101924/textured_objs/original-77.obj" />/&gt;
			</geometry>
		</collision>
		<collision>
			<origin xyz="0 0 0" />
			<geometry>
				<mesh filename="/home/blake/kitchen-worlds/assets/models/Oven/101924/textured_objs/original-114.obj" />/&gt;
			</geometry>
		</collision>
		<collision>
			<origin xyz="0 0 0" />
			<geometry>
				<mesh filename="/home/blake/kitchen-worlds/assets/models/Oven/101924/textured_objs/original-150.obj" />/&gt;
			</geometry>
		</collision>
		<collision>
			<origin xyz="0 0 0" />
			<geometry>
				<mesh filename="/home/blake/kitchen-worlds/assets/models/Oven/101924/textured_objs/original-63.obj" />/&gt;
			</geometry>
		</collision>
		<collision>
			<origin xyz="0 0 0" />
			<geometry>
				<mesh filename="/home/blake/kitchen-worlds/assets/models/Oven/101924/textured_objs/original-87.obj" />/&gt;
			</geometry>
		</collision>
		<collision>
			<origin xyz="0 0 0" />
			<geometry>
				<mesh filename="/home/blake/kitchen-worlds/assets/models/Oven/101924/textured_objs/original-113.obj" />/&gt;
			</geometry>
		</collision>
		<collision>
			<origin xyz="0 0 0" />
			<geometry>
				<mesh filename="/home/blake/kitchen-worlds/assets/models/Oven/101924/textured_objs/original-6.obj" />/&gt;
			</geometry>
		</collision>
		<collision>
			<origin xyz="0 0 0" />
			<geometry>
				<mesh filename="/home/blake/kitchen-worlds/assets/models/Oven/101924/textured_objs/original-37.obj" />/&gt;
			</geometry>
		</collision>
		<collision>
			<origin xyz="0 0 0" />
			<geometry>
				<mesh filename="/home/blake/kitchen-worlds/assets/models/Oven/101924/textured_objs/original-85.obj" />/&gt;
			</geometry>
		</collision>
		<collision>
			<origin xyz="0 0 0" />
			<geometry>
				<mesh filename="/home/blake/kitchen-worlds/assets/models/Oven/101924/textured_objs/original-122.obj" />/&gt;
			</geometry>
		</collision>
		<collision>
			<origin xyz="0 0 0" />
			<geometry>
				<mesh filename="/home/blake/kitchen-worlds/assets/models/Oven/101924/textured_objs/original-76.obj" />/&gt;
			</geometry>
		</collision>
		<collision>
			<origin xyz="0 0 0" />
			<geometry>
				<mesh filename="/home/blake/kitchen-worlds/assets/models/Oven/101924/textured_objs/original-72.obj" />/&gt;
			</geometry>
		</collision>
		<collision>
			<origin xyz="0 0 0" />
			<geometry>
				<mesh filename="/home/blake/kitchen-worlds/assets/models/Oven/101924/textured_objs/original-62.obj" />/&gt;
			</geometry>
		</collision>
		<collision>
			<origin xyz="0 0 0" />
			<geometry>
				<mesh filename="/home/blake/kitchen-worlds/assets/models/Oven/101924/textured_objs/original-75.obj" />/&gt;
			</geometry>
		</collision>
		<collision>
			<origin xyz="0 0 0" />
			<geometry>
				<mesh filename="/home/blake/kitchen-worlds/assets/models/Oven/101924/textured_objs/original-133.obj" />/&gt;
			</geometry>
		</collision>
		<collision>
			<origin xyz="0 0 0" />
			<geometry>
				<mesh filename="/home/blake/kitchen-worlds/assets/models/Oven/101924/textured_objs/original-66.obj" />/&gt;
			</geometry>
		</collision>
		<collision>
			<origin xyz="0 0 0" />
			<geometry>
				<mesh filename="/home/blake/kitchen-worlds/assets/models/Oven/101924/textured_objs/original-58.obj" />/&gt;
			</geometry>
		</collision>
		<collision>
			<origin xyz="0 0 0" />
			<geometry>
				<mesh filename="/home/blake/kitchen-worlds/assets/models/Oven/101924/textured_objs/original-145.obj" />/&gt;
			</geometry>
		</collision>
		<collision>
			<origin xyz="0 0 0" />
			<geometry>
				<mesh filename="/home/blake/kitchen-worlds/assets/models/Oven/101924/textured_objs/original-98.obj" />/&gt;
			</geometry>
		</collision>
		<collision>
			<origin xyz="0 0 0" />
			<geometry>
				<mesh filename="/home/blake/kitchen-worlds/assets/models/Oven/101924/textured_objs/original-67.obj" />/&gt;
			</geometry>
		</collision>
		<collision>
			<origin xyz="0 0 0" />
			<geometry>
				<mesh filename="/home/blake/kitchen-worlds/assets/models/Oven/101924/textured_objs/original-69.obj" />/&gt;
			</geometry>
		</collision>
		<collision>
			<origin xyz="0 0 0" />
			<geometry>
				<mesh filename="/home/blake/kitchen-worlds/assets/models/Oven/101924/textured_objs/original-11.obj" />/&gt;
			</geometry>
		</collision>
		<collision>
			<origin xyz="0 0 0" />
			<geometry>
				<mesh filename="/home/blake/kitchen-worlds/assets/models/Oven/101924/textured_objs/original-38.obj" />/&gt;
			</geometry>
		</collision>
		<collision>
			<origin xyz="0 0 0" />
			<geometry>
				<mesh filename="/home/blake/kitchen-worlds/assets/models/Oven/101924/textured_objs/original-68.obj" />/&gt;
			</geometry>
		</collision>
		<collision>
			<origin xyz="0 0 0" />
			<geometry>
				<mesh filename="/home/blake/kitchen-worlds/assets/models/Oven/101924/textured_objs/original-146.obj" />/&gt;
			</geometry>
		</collision>
		<collision>
			<origin xyz="0 0 0" />
			<geometry>
				<mesh filename="/home/blake/kitchen-worlds/assets/models/Oven/101924/textured_objs/original-74.obj" />/&gt;
			</geometry>
		</collision>
		<collision>
			<origin xyz="0 0 0" />
			<geometry>
				<mesh filename="/home/blake/kitchen-worlds/assets/models/Oven/101924/textured_objs/original-118.obj" />/&gt;
			</geometry>
		</collision>
		<collision>
			<origin xyz="0 0 0" />
			<geometry>
				<mesh filename="/home/blake/kitchen-worlds/assets/models/Oven/101924/textured_objs/original-91.obj" />/&gt;
			</geometry>
		</collision>
		<collision>
			<origin xyz="0 0 0" />
			<geometry>
				<mesh filename="/home/blake/kitchen-worlds/assets/models/Oven/101924/textured_objs/original-73.obj" />/&gt;
			</geometry>
		</collision>
		<collision>
			<origin xyz="0 0 0" />
			<geometry>
				<mesh filename="/home/blake/kitchen-worlds/assets/models/Oven/101924/textured_objs/original-12.obj" />/&gt;
			</geometry>
		</collision>
		<collision>
			<origin xyz="0 0 0" />
			<geometry>
				<mesh filename="/home/blake/kitchen-worlds/assets/models/Oven/101924/textured_objs/original-92.obj" />/&gt;
			</geometry>
		</collision>
		<collision>
			<origin xyz="0 0 0" />
			<geometry>
				<mesh filename="/home/blake/kitchen-worlds/assets/models/Oven/101924/textured_objs/original-142.obj" />/&gt;
			</geometry>
		</collision>
		<collision>
			<origin xyz="0 0 0" />
			<geometry>
				<mesh filename="/home/blake/kitchen-worlds/assets/models/Oven/101924/textured_objs/original-42.obj" />/&gt;
			</geometry>
		</collision>
		<collision>
			<origin xyz="0 0 0" />
			<geometry>
				<mesh filename="/home/blake/kitchen-worlds/assets/models/Oven/101924/textured_objs/original-79.obj" />/&gt;
			</geometry>
		</collision>
		<collision>
			<origin xyz="0 0 0" />
			<geometry>
				<mesh filename="/home/blake/kitchen-worlds/assets/models/Oven/101924/textured_objs/original-88.obj" />/&gt;
			</geometry>
		</collision>
		<collision>
			<origin xyz="0 0 0" />
			<geometry>
				<mesh filename="/home/blake/kitchen-worlds/assets/models/Oven/101924/textured_objs/original-95.obj" />/&gt;
			</geometry>
		</collision>
		<collision>
			<origin xyz="0 0 0" />
			<geometry>
				<mesh filename="/home/blake/kitchen-worlds/assets/models/Oven/101924/textured_objs/original-7.obj" />/&gt;
			</geometry>
		</collision>
		<collision>
			<origin xyz="0 0 0" />
			<geometry>
				<mesh filename="/home/blake/kitchen-worlds/assets/models/Oven/101924/textured_objs/original-81.obj" />/&gt;
			</geometry>
		</collision>
		<collision>
			<origin xyz="0 0 0" />
			<geometry>
				<mesh filename="/home/blake/kitchen-worlds/assets/models/Oven/101924/textured_objs/original-84.obj" />/&gt;
			</geometry>
		</collision>
		<collision>
			<origin xyz="0 0 0" />
			<geometry>
				<mesh filename="/home/blake/kitchen-worlds/assets/models/Oven/101924/textured_objs/original-94.obj" />/&gt;
			</geometry>
		</collision>
		<collision>
			<origin xyz="0 0 0" />
			<geometry>
				<mesh filename="/home/blake/kitchen-worlds/assets/models/Oven/101924/textured_objs/original-78.obj" />/&gt;
			</geometry>
		</collision>
		<collision>
			<origin xyz="0 0 0" />
			<geometry>
				<mesh filename="/home/blake/kitchen-worlds/assets/models/Oven/101924/textured_objs/original-97.obj" />/&gt;
			</geometry>
		</collision>
		<collision>
			<origin xyz="0 0 0" />
			<geometry>
				<mesh filename="/home/blake/kitchen-worlds/assets/models/Oven/101924/textured_objs/original-157.obj" />/&gt;
			</geometry>
		</collision>
		<collision>
			<origin xyz="0 0 0" />
			<geometry>
				<mesh filename="/home/blake/kitchen-worlds/assets/models/Oven/101924/textured_objs/original-89.obj" />/&gt;
			</geometry>
		</collision>
		<collision>
			<origin xyz="0 0 0" />
			<geometry>
				<mesh filename="/home/blake/kitchen-worlds/assets/models/Oven/101924/textured_objs/original-10.obj" />/&gt;
			</geometry>
		</collision>
		<collision>
			<origin xyz="0 0 0" />
			<geometry>
				<mesh filename="/home/blake/kitchen-worlds/assets/models/Oven/101924/textured_objs/original-82.obj" />/&gt;
			</geometry>
		</collision>
		<collision>
			<origin xyz="0 0 0" />
			<geometry>
				<mesh filename="/home/blake/kitchen-worlds/assets/models/Oven/101924/textured_objs/original-129.obj" />/&gt;
			</geometry>
		</collision>
		<collision>
			<origin xyz="0 0 0" />
			<geometry>
				<mesh filename="/home/blake/kitchen-worlds/assets/models/Oven/101924/textured_objs/original-40.obj" />/&gt;
			</geometry>
		</collision>
		<collision>
			<origin xyz="0 0 0" />
			<geometry>
				<mesh filename="/home/blake/kitchen-worlds/assets/models/Oven/101924/textured_objs/original-143.obj" />/&gt;
			</geometry>
		</collision>
		<collision>
			<origin xyz="0 0 0" />
			<geometry>
				<mesh filename="/home/blake/kitchen-worlds/assets/models/Oven/101924/textured_objs/original-151.obj" />/&gt;
			</geometry>
		</collision>
		<collision>
			<origin xyz="0 0 0" />
			<geometry>
				<mesh filename="/home/blake/kitchen-worlds/assets/models/Oven/101924/textured_objs/original-155.obj" />/&gt;
			</geometry>
		</collision>
		<collision>
			<origin xyz="0 0 0" />
			<geometry>
				<mesh filename="/home/blake/kitchen-worlds/assets/models/Oven/101924/textured_objs/original-57.obj" />/&gt;
			</geometry>
		</collision>
	</link>
	<joint name="joint_11" type="fixed">
		<origin rpy="1.570796326794897 0 -1.570796326794897" xyz="0 0 0" />
		<child link="link_11" />
		<parent link="base" />
	</joint>
</robot>