<?xml version='1.0' encoding='utf-8'?>
<robot name="partnet_1201cc45cd7348c94c3aee8e9d3a6ffa">
	<link name="base" />
	<link name="link_0">
		<visual name="cabinet_door_surface-14">
			<origin xyz="-0.5047340994860205 -0.8520619869232178 -0.23485030100379314" />
			<geometry>
				<mesh filename="/home/blake/kitchen-worlds/assets/models/Cupboard/41085/textured_objs/original-29.obj" />/&gt;
			</geometry>
		</visual>
		<visual name="handle-15">
			<origin xyz="-0.5047340994860205 -0.8520619869232178 -0.23485030100379314" />
			<geometry>
				<mesh filename="/home/blake/kitchen-worlds/assets/models/Cupboard/41085/textured_objs/original-33.obj" />/&gt;
			</geometry>
		</visual>
		<visual name="handle-15">
			<origin xyz="-0.5047340994860205 -0.8520619869232178 -0.23485030100379314" />
			<geometry>
				<mesh filename="/home/blake/kitchen-worlds/assets/models/Cupboard/41085/textured_objs/original-31.obj" />/&gt;
			</geometry>
		</visual>
		<visual name="handle-15">
			<origin xyz="-0.5047340994860205 -0.8520619869232178 -0.23485030100379314" />
			<geometry>
				<mesh filename="/home/blake/kitchen-worlds/assets/models/Cupboard/41085/textured_objs/original-32.obj" />/&gt;
			</geometry>
		</visual>
		<collision>
			<origin xyz="-0.5047340994860205 -0.8520619869232178 -0.23485030100379314" />
			<geometry>
				<mesh filename="/home/blake/kitchen-worlds/assets/models/Cupboard/41085/textured_objs/original-29.obj" />/&gt;
			</geometry>
		</collision>
		<collision>
			<origin xyz="-0.5047340994860205 -0.8520619869232178 -0.23485030100379314" />
			<geometry>
				<mesh filename="/home/blake/kitchen-worlds/assets/models/Cupboard/41085/textured_objs/original-33.obj" />/&gt;
			</geometry>
		</collision>
		<collision>
			<origin xyz="-0.5047340994860205 -0.8520619869232178 -0.23485030100379314" />
			<geometry>
				<mesh filename="/home/blake/kitchen-worlds/assets/models/Cupboard/41085/textured_objs/original-31.obj" />/&gt;
			</geometry>
		</collision>
		<collision>
			<origin xyz="-0.5047340994860205 -0.8520619869232178 -0.23485030100379314" />
			<geometry>
				<mesh filename="/home/blake/kitchen-worlds/assets/models/Cupboard/41085/textured_objs/original-32.obj" />/&gt;
			</geometry>
		</collision>
	</link>
	<joint name="joint_0" type="revolute">
		<origin xyz="0.5047340994860205 0.8520619869232178 0.23485030100379314" />
		<axis xyz="0 1 0" />
		<child link="link_0" />
		<parent link="link_4" />
		<limit lower="0.0" upper="1.5707963267948966" effort="10.0" velocity="1.0" />
	</joint>
	<link name="link_1">
		<visual name="cabinet_door_surface-10">
			<origin xyz="-0.5047340994860205 -0.8520619869232178 -0.23485030100379314" />
			<geometry>
				<mesh filename="/home/blake/kitchen-worlds/assets/models/Cupboard/41085/textured_objs/original-21.obj" />/&gt;
			</geometry>
		</visual>
		<visual name="handle-12">
			<origin xyz="-0.5047340994860205 -0.8520619869232178 -0.23485030100379314" />
			<geometry>
				<mesh filename="/home/blake/kitchen-worlds/assets/models/Cupboard/41085/textured_objs/original-23.obj" />/&gt;
			</geometry>
		</visual>
		<visual name="handle-12">
			<origin xyz="-0.5047340994860205 -0.8520619869232178 -0.23485030100379314" />
			<geometry>
				<mesh filename="/home/blake/kitchen-worlds/assets/models/Cupboard/41085/textured_objs/original-25.obj" />/&gt;
			</geometry>
		</visual>
		<visual name="handle-12">
			<origin xyz="-0.5047340994860205 -0.8520619869232178 -0.23485030100379314" />
			<geometry>
				<mesh filename="/home/blake/kitchen-worlds/assets/models/Cupboard/41085/textured_objs/original-24.obj" />/&gt;
			</geometry>
		</visual>
		<collision>
			<origin xyz="-0.5047340994860205 -0.8520619869232178 -0.23485030100379314" />
			<geometry>
				<mesh filename="/home/blake/kitchen-worlds/assets/models/Cupboard/41085/textured_objs/original-21.obj" />/&gt;
			</geometry>
		</collision>
		<collision>
			<origin xyz="-0.5047340994860205 -0.8520619869232178 -0.23485030100379314" />
			<geometry>
				<mesh filename="/home/blake/kitchen-worlds/assets/models/Cupboard/41085/textured_objs/original-23.obj" />/&gt;
			</geometry>
		</collision>
		<collision>
			<origin xyz="-0.5047340994860205 -0.8520619869232178 -0.23485030100379314" />
			<geometry>
				<mesh filename="/home/blake/kitchen-worlds/assets/models/Cupboard/41085/textured_objs/original-25.obj" />/&gt;
			</geometry>
		</collision>
		<collision>
			<origin xyz="-0.5047340994860205 -0.8520619869232178 -0.23485030100379314" />
			<geometry>
				<mesh filename="/home/blake/kitchen-worlds/assets/models/Cupboard/41085/textured_objs/original-24.obj" />/&gt;
			</geometry>
		</collision>
	</link>
	<joint name="joint_1" type="revolute">
		<origin xyz="0.5047340994860205 0.8520619869232178 0.23485030100379314" />
		<axis xyz="0 1 0" />
		<child link="link_1" />
		<parent link="link_4" />
		<limit lower="0.0" upper="1.5707963267948966" effort="10.0" velocity="1.0" />
	</joint>
	<link name="link_2">
		<visual name="cabinet_door_surface-34">
			<origin xyz="0.45879004987694044 -0.8520619869232178 -0.23567740142267388" />
			<geometry>
				<mesh filename="/home/blake/kitchen-worlds/assets/models/Cupboard/41085/textured_objs/original-45.obj" />/&gt;
			</geometry>
		</visual>
		<visual name="handle-35">
			<origin xyz="0.45879004987694044 -0.8520619869232178 -0.23567740142267388" />
			<geometry>
				<mesh filename="/home/blake/kitchen-worlds/assets/models/Cupboard/41085/textured_objs/original-49.obj" />/&gt;
			</geometry>
		</visual>
		<visual name="handle-35">
			<origin xyz="0.45879004987694044 -0.8520619869232178 -0.23567740142267388" />
			<geometry>
				<mesh filename="/home/blake/kitchen-worlds/assets/models/Cupboard/41085/textured_objs/original-47.obj" />/&gt;
			</geometry>
		</visual>
		<visual name="handle-35">
			<origin xyz="0.45879004987694044 -0.8520619869232178 -0.23567740142267388" />
			<geometry>
				<mesh filename="/home/blake/kitchen-worlds/assets/models/Cupboard/41085/textured_objs/original-48.obj" />/&gt;
			</geometry>
		</visual>
		<collision>
			<origin xyz="0.45879004987694044 -0.8520619869232178 -0.23567740142267388" />
			<geometry>
				<mesh filename="/home/blake/kitchen-worlds/assets/models/Cupboard/41085/textured_objs/original-45.obj" />/&gt;
			</geometry>
		</collision>
		<collision>
			<origin xyz="0.45879004987694044 -0.8520619869232178 -0.23567740142267388" />
			<geometry>
				<mesh filename="/home/blake/kitchen-worlds/assets/models/Cupboard/41085/textured_objs/original-49.obj" />/&gt;
			</geometry>
		</collision>
		<collision>
			<origin xyz="0.45879004987694044 -0.8520619869232178 -0.23567740142267388" />
			<geometry>
				<mesh filename="/home/blake/kitchen-worlds/assets/models/Cupboard/41085/textured_objs/original-47.obj" />/&gt;
			</geometry>
		</collision>
		<collision>
			<origin xyz="0.45879004987694044 -0.8520619869232178 -0.23567740142267388" />
			<geometry>
				<mesh filename="/home/blake/kitchen-worlds/assets/models/Cupboard/41085/textured_objs/original-48.obj" />/&gt;
			</geometry>
		</collision>
	</link>
	<joint name="joint_2" type="revolute">
		<origin xyz="-0.45879004987694044 0.8520619869232178 0.23567740142267388" />
		<axis xyz="0 -1 0" />
		<child link="link_2" />
		<parent link="link_4" />
		<limit lower="-0.0" upper="1.5707963267948966" effort="10.0" velocity="1.0" />
	</joint>
	<link name="link_3">
		<visual name="cabinet_door_surface-32">
			<origin xyz="0.45879004987694044 -0.8520619869232178 -0.23567740142267388" />
			<geometry>
				<mesh filename="/home/blake/kitchen-worlds/assets/models/Cupboard/41085/textured_objs/original-39.obj" />/&gt;
			</geometry>
		</visual>
		<visual name="handle-33">
			<origin xyz="0.45879004987694044 -0.8520619869232178 -0.23567740142267388" />
			<geometry>
				<mesh filename="/home/blake/kitchen-worlds/assets/models/Cupboard/41085/textured_objs/original-41.obj" />/&gt;
			</geometry>
		</visual>
		<visual name="handle-33">
			<origin xyz="0.45879004987694044 -0.8520619869232178 -0.23567740142267388" />
			<geometry>
				<mesh filename="/home/blake/kitchen-worlds/assets/models/Cupboard/41085/textured_objs/original-43.obj" />/&gt;
			</geometry>
		</visual>
		<visual name="handle-33">
			<origin xyz="0.45879004987694044 -0.8520619869232178 -0.23567740142267388" />
			<geometry>
				<mesh filename="/home/blake/kitchen-worlds/assets/models/Cupboard/41085/textured_objs/original-42.obj" />/&gt;
			</geometry>
		</visual>
		<collision>
			<origin xyz="0.45879004987694044 -0.8520619869232178 -0.23567740142267388" />
			<geometry>
				<mesh filename="/home/blake/kitchen-worlds/assets/models/Cupboard/41085/textured_objs/original-39.obj" />/&gt;
			</geometry>
		</collision>
		<collision>
			<origin xyz="0.45879004987694044 -0.8520619869232178 -0.23567740142267388" />
			<geometry>
				<mesh filename="/home/blake/kitchen-worlds/assets/models/Cupboard/41085/textured_objs/original-41.obj" />/&gt;
			</geometry>
		</collision>
		<collision>
			<origin xyz="0.45879004987694044 -0.8520619869232178 -0.23567740142267388" />
			<geometry>
				<mesh filename="/home/blake/kitchen-worlds/assets/models/Cupboard/41085/textured_objs/original-43.obj" />/&gt;
			</geometry>
		</collision>
		<collision>
			<origin xyz="0.45879004987694044 -0.8520619869232178 -0.23567740142267388" />
			<geometry>
				<mesh filename="/home/blake/kitchen-worlds/assets/models/Cupboard/41085/textured_objs/original-42.obj" />/&gt;
			</geometry>
		</collision>
	</link>
	<joint name="joint_3" type="revolute">
		<origin xyz="-0.45879004987694044 0.8520619869232178 0.23567740142267388" />
		<axis xyz="0 -1 0" />
		<child link="link_3" />
		<parent link="link_4" />
		<limit lower="-0.0" upper="1.5707963267948966" effort="10.0" velocity="1.0" />
	</joint>
	<link name="link_4">
		<visual name="shelf-3">
			<origin xyz="0 0 0" />
			<geometry>
				<mesh filename="/home/blake/kitchen-worlds/assets/models/Cupboard/41085/textured_objs/original-37.obj" />/&gt;
			</geometry>
		</visual>
		<visual name="shelf-4">
			<origin xyz="0 0 0" />
			<geometry>
				<mesh filename="/home/blake/kitchen-worlds/assets/models/Cupboard/41085/textured_objs/original-27.obj" />/&gt;
			</geometry>
		</visual>
		<visual name="shelf-5">
			<origin xyz="0 0 0" />
			<geometry>
				<mesh filename="/home/blake/kitchen-worlds/assets/models/Cupboard/41085/textured_objs/original-36.obj" />/&gt;
			</geometry>
		</visual>
		<visual name="shelf-6">
			<origin xyz="0 0 0" />
			<geometry>
				<mesh filename="/home/blake/kitchen-worlds/assets/models/Cupboard/41085/textured_objs/original-19.obj" />/&gt;
			</geometry>
		</visual>
		<visual name="vertical_side_panel-17">
			<origin xyz="0 0 0" />
			<geometry>
				<mesh filename="/home/blake/kitchen-worlds/assets/models/Cupboard/41085/textured_objs/original-4.obj" />/&gt;
			</geometry>
		</visual>
		<visual name="vertical_side_panel-18">
			<origin xyz="0 0 0" />
			<geometry>
				<mesh filename="/home/blake/kitchen-worlds/assets/models/Cupboard/41085/textured_objs/original-7.obj" />/&gt;
			</geometry>
		</visual>
		<visual name="back_panel-19">
			<origin xyz="0 0 0" />
			<geometry>
				<mesh filename="/home/blake/kitchen-worlds/assets/models/Cupboard/41085/textured_objs/original-12.obj" />/&gt;
			</geometry>
		</visual>
		<visual name="bottom_panel-20">
			<origin xyz="0 0 0" />
			<geometry>
				<mesh filename="/home/blake/kitchen-worlds/assets/models/Cupboard/41085/textured_objs/original-17.obj" />/&gt;
			</geometry>
		</visual>
		<visual name="top_panel-21">
			<origin xyz="0 0 0" />
			<geometry>
				<mesh filename="/home/blake/kitchen-worlds/assets/models/Cupboard/41085/textured_objs/original-10.obj" />/&gt;
			</geometry>
		</visual>
		<visual name="frame_horizontal_bar-22">
			<origin xyz="0 0 0" />
			<geometry>
				<mesh filename="/home/blake/kitchen-worlds/assets/models/Cupboard/41085/textured_objs/original-13.obj" />/&gt;
			</geometry>
		</visual>
		<visual name="frame_horizontal_bar-23">
			<origin xyz="0 0 0" />
			<geometry>
				<mesh filename="/home/blake/kitchen-worlds/assets/models/Cupboard/41085/textured_objs/original-11.obj" />/&gt;
			</geometry>
		</visual>
		<visual name="frame_horizontal_bar-24">
			<origin xyz="0 0 0" />
			<geometry>
				<mesh filename="/home/blake/kitchen-worlds/assets/models/Cupboard/41085/textured_objs/original-16.obj" />/&gt;
			</geometry>
		</visual>
		<visual name="frame_horizontal_bar-25">
			<origin xyz="0 0 0" />
			<geometry>
				<mesh filename="/home/blake/kitchen-worlds/assets/models/Cupboard/41085/textured_objs/original-35.obj" />/&gt;
			</geometry>
		</visual>
		<visual name="frame_horizontal_bar-26">
			<origin xyz="0 0 0" />
			<geometry>
				<mesh filename="/home/blake/kitchen-worlds/assets/models/Cupboard/41085/textured_objs/original-9.obj" />/&gt;
			</geometry>
		</visual>
		<visual name="frame_vertical_bar-27">
			<origin xyz="0 0 0" />
			<geometry>
				<mesh filename="/home/blake/kitchen-worlds/assets/models/Cupboard/41085/textured_objs/original-3.obj" />/&gt;
			</geometry>
		</visual>
		<visual name="frame_vertical_bar-28">
			<origin xyz="0 0 0" />
			<geometry>
				<mesh filename="/home/blake/kitchen-worlds/assets/models/Cupboard/41085/textured_objs/original-6.obj" />/&gt;
			</geometry>
		</visual>
		<visual name="frame_horizontal_bar-29">
			<origin xyz="0 0 0" />
			<geometry>
				<mesh filename="/home/blake/kitchen-worlds/assets/models/Cupboard/41085/textured_objs/original-14.obj" />/&gt;
			</geometry>
		</visual>
		<collision>
			<origin xyz="0 0 0" />
			<geometry>
				<mesh filename="/home/blake/kitchen-worlds/assets/models/Cupboard/41085/textured_objs/original-37.obj" />/&gt;
			</geometry>
		</collision>
		<collision>
			<origin xyz="0 0 0" />
			<geometry>
				<mesh filename="/home/blake/kitchen-worlds/assets/models/Cupboard/41085/textured_objs/original-27.obj" />/&gt;
			</geometry>
		</collision>
		<collision>
			<origin xyz="0 0 0" />
			<geometry>
				<mesh filename="/home/blake/kitchen-worlds/assets/models/Cupboard/41085/textured_objs/original-36.obj" />/&gt;
			</geometry>
		</collision>
		<collision>
			<origin xyz="0 0 0" />
			<geometry>
				<mesh filename="/home/blake/kitchen-worlds/assets/models/Cupboard/41085/textured_objs/original-19.obj" />/&gt;
			</geometry>
		</collision>
		<collision>
			<origin xyz="0 0 0" />
			<geometry>
				<mesh filename="/home/blake/kitchen-worlds/assets/models/Cupboard/41085/textured_objs/original-4.obj" />/&gt;
			</geometry>
		</collision>
		<collision>
			<origin xyz="0 0 0" />
			<geometry>
				<mesh filename="/home/blake/kitchen-worlds/assets/models/Cupboard/41085/textured_objs/original-7.obj" />/&gt;
			</geometry>
		</collision>
		<collision>
			<origin xyz="0 0 0" />
			<geometry>
				<mesh filename="/home/blake/kitchen-worlds/assets/models/Cupboard/41085/textured_objs/original-12.obj" />/&gt;
			</geometry>
		</collision>
		<collision>
			<origin xyz="0 0 0" />
			<geometry>
				<mesh filename="/home/blake/kitchen-worlds/assets/models/Cupboard/41085/textured_objs/original-17.obj" />/&gt;
			</geometry>
		</collision>
		<collision>
			<origin xyz="0 0 0" />
			<geometry>
				<mesh filename="/home/blake/kitchen-worlds/assets/models/Cupboard/41085/textured_objs/original-10.obj" />/&gt;
			</geometry>
		</collision>
		<collision>
			<origin xyz="0 0 0" />
			<geometry>
				<mesh filename="/home/blake/kitchen-worlds/assets/models/Cupboard/41085/textured_objs/original-13.obj" />/&gt;
			</geometry>
		</collision>
		<collision>
			<origin xyz="0 0 0" />
			<geometry>
				<mesh filename="/home/blake/kitchen-worlds/assets/models/Cupboard/41085/textured_objs/original-11.obj" />/&gt;
			</geometry>
		</collision>
		<collision>
			<origin xyz="0 0 0" />
			<geometry>
				<mesh filename="/home/blake/kitchen-worlds/assets/models/Cupboard/41085/textured_objs/original-16.obj" />/&gt;
			</geometry>
		</collision>
		<collision>
			<origin xyz="0 0 0" />
			<geometry>
				<mesh filename="/home/blake/kitchen-worlds/assets/models/Cupboard/41085/textured_objs/original-35.obj" />/&gt;
			</geometry>
		</collision>
		<collision>
			<origin xyz="0 0 0" />
			<geometry>
				<mesh filename="/home/blake/kitchen-worlds/assets/models/Cupboard/41085/textured_objs/original-9.obj" />/&gt;
			</geometry>
		</collision>
		<collision>
			<origin xyz="0 0 0" />
			<geometry>
				<mesh filename="/home/blake/kitchen-worlds/assets/models/Cupboard/41085/textured_objs/original-3.obj" />/&gt;
			</geometry>
		</collision>
		<collision>
			<origin xyz="0 0 0" />
			<geometry>
				<mesh filename="/home/blake/kitchen-worlds/assets/models/Cupboard/41085/textured_objs/original-6.obj" />/&gt;
			</geometry>
		</collision>
		<collision>
			<origin xyz="0 0 0" />
			<geometry>
				<mesh filename="/home/blake/kitchen-worlds/assets/models/Cupboard/41085/textured_objs/original-14.obj" />/&gt;
			</geometry>
		</collision>
	</link>
	<joint name="joint_4" type="fixed">
		<origin rpy="1.570796326794897 0 -1.570796326794897" xyz="0 0 0" />
		<child link="link_4" />
		<parent link="base" />
	</joint>
</robot>