<?xml version='1.0' encoding='utf-8'?>
<robot name="partnet_5bf29b17ff338ef4c3aee8e9d3a6ffa">
	<link name="base" />
	<link name="link_0">
		<visual name="cabinet_door_surface-7">
			<origin xyz="-0.5568378988128383 0 -0.26716946744853437" />
			<geometry>
				<mesh filename="/home/blake/kitchen-worlds/assets/models/Cupboard/46490/textured_objs/original-29.obj" />/&gt;
			</geometry>
		</visual>
		<visual name="handle-8">
			<origin xyz="-0.5568378988128383 0 -0.26716946744853437" />
			<geometry>
				<mesh filename="/home/blake/kitchen-worlds/assets/models/Cupboard/46490/textured_objs/original-31.obj" />/&gt;
			</geometry>
		</visual>
		<visual name="handle-8">
			<origin xyz="-0.5568378988128383 0 -0.26716946744853437" />
			<geometry>
				<mesh filename="/home/blake/kitchen-worlds/assets/models/Cupboard/46490/textured_objs/original-32.obj" />/&gt;
			</geometry>
		</visual>
		<visual name="handle-8">
			<origin xyz="-0.5568378988128383 0 -0.26716946744853437" />
			<geometry>
				<mesh filename="/home/blake/kitchen-worlds/assets/models/Cupboard/46490/textured_objs/original-33.obj" />/&gt;
			</geometry>
		</visual>
		<collision>
			<origin xyz="-0.5568378988128383 0 -0.26716946744853437" />
			<geometry>
				<mesh filename="/home/blake/kitchen-worlds/assets/models/Cupboard/46490/textured_objs/original-29.obj" />/&gt;
			</geometry>
		</collision>
		<collision>
			<origin xyz="-0.5568378988128383 0 -0.26716946744853437" />
			<geometry>
				<mesh filename="/home/blake/kitchen-worlds/assets/models/Cupboard/46490/textured_objs/original-31.obj" />/&gt;
			</geometry>
		</collision>
		<collision>
			<origin xyz="-0.5568378988128383 0 -0.26716946744853437" />
			<geometry>
				<mesh filename="/home/blake/kitchen-worlds/assets/models/Cupboard/46490/textured_objs/original-32.obj" />/&gt;
			</geometry>
		</collision>
		<collision>
			<origin xyz="-0.5568378988128383 0 -0.26716946744853437" />
			<geometry>
				<mesh filename="/home/blake/kitchen-worlds/assets/models/Cupboard/46490/textured_objs/original-33.obj" />/&gt;
			</geometry>
		</collision>
	</link>
	<joint name="joint_0" type="revolute">
		<origin xyz="0.5568378988128383 0 0.26716946744853437" />
		<axis xyz="0 1 0" />
		<child link="link_0" />
		<parent link="link_2" />
		<limit lower="0.0" upper="1.5707963267948966" effort="10.0" velocity="1.0" />
	</joint>
	<link name="link_1">
		<visual name="cabinet_door_surface-5">
			<origin xyz="0.5505441576616547 0 -0.2585040087401204" />
			<geometry>
				<mesh filename="/home/blake/kitchen-worlds/assets/models/Cupboard/46490/textured_objs/original-21.obj" />/&gt;
			</geometry>
		</visual>
		<visual name="handle-6">
			<origin xyz="0.5505441576616547 0 -0.2585040087401204" />
			<geometry>
				<mesh filename="/home/blake/kitchen-worlds/assets/models/Cupboard/46490/textured_objs/original-23.obj" />/&gt;
			</geometry>
		</visual>
		<visual name="handle-6">
			<origin xyz="0.5505441576616547 0 -0.2585040087401204" />
			<geometry>
				<mesh filename="/home/blake/kitchen-worlds/assets/models/Cupboard/46490/textured_objs/original-24.obj" />/&gt;
			</geometry>
		</visual>
		<visual name="handle-6">
			<origin xyz="0.5505441576616547 0 -0.2585040087401204" />
			<geometry>
				<mesh filename="/home/blake/kitchen-worlds/assets/models/Cupboard/46490/textured_objs/original-25.obj" />/&gt;
			</geometry>
		</visual>
		<collision>
			<origin xyz="0.5505441576616547 0 -0.2585040087401204" />
			<geometry>
				<mesh filename="/home/blake/kitchen-worlds/assets/models/Cupboard/46490/textured_objs/original-21.obj" />/&gt;
			</geometry>
		</collision>
		<collision>
			<origin xyz="0.5505441576616547 0 -0.2585040087401204" />
			<geometry>
				<mesh filename="/home/blake/kitchen-worlds/assets/models/Cupboard/46490/textured_objs/original-23.obj" />/&gt;
			</geometry>
		</collision>
		<collision>
			<origin xyz="0.5505441576616547 0 -0.2585040087401204" />
			<geometry>
				<mesh filename="/home/blake/kitchen-worlds/assets/models/Cupboard/46490/textured_objs/original-24.obj" />/&gt;
			</geometry>
		</collision>
		<collision>
			<origin xyz="0.5505441576616547 0 -0.2585040087401204" />
			<geometry>
				<mesh filename="/home/blake/kitchen-worlds/assets/models/Cupboard/46490/textured_objs/original-25.obj" />/&gt;
			</geometry>
		</collision>
	</link>
	<joint name="joint_1" type="revolute">
		<origin xyz="-0.5505441576616547 0 0.2585040087401204" />
		<axis xyz="0 -1 0" />
		<child link="link_1" />
		<parent link="link_2" />
		<limit lower="-0.0" upper="1.5707963267948966" effort="10.0" velocity="1.0" />
	</joint>
	<link name="link_2">
		<visual name="shelf-10">
			<origin xyz="0 0 0" />
			<geometry>
				<mesh filename="/home/blake/kitchen-worlds/assets/models/Cupboard/46490/textured_objs/original-19.obj" />/&gt;
			</geometry>
		</visual>
		<visual name="shelf-11">
			<origin xyz="0 0 0" />
			<geometry>
				<mesh filename="/home/blake/kitchen-worlds/assets/models/Cupboard/46490/textured_objs/original-26.obj" />/&gt;
			</geometry>
		</visual>
		<visual name="shelf-12">
			<origin xyz="0 0 0" />
			<geometry>
				<mesh filename="/home/blake/kitchen-worlds/assets/models/Cupboard/46490/textured_objs/original-27.obj" />/&gt;
			</geometry>
		</visual>
		<visual name="vertical_side_panel-13">
			<origin xyz="0 0 0" />
			<geometry>
				<mesh filename="/home/blake/kitchen-worlds/assets/models/Cupboard/46490/textured_objs/original-7.obj" />/&gt;
			</geometry>
		</visual>
		<visual name="vertical_side_panel-13">
			<origin xyz="0 0 0" />
			<geometry>
				<mesh filename="/home/blake/kitchen-worlds/assets/models/Cupboard/46490/textured_objs/original-6.obj" />/&gt;
			</geometry>
		</visual>
		<visual name="vertical_side_panel-14">
			<origin xyz="0 0 0" />
			<geometry>
				<mesh filename="/home/blake/kitchen-worlds/assets/models/Cupboard/46490/textured_objs/original-4.obj" />/&gt;
			</geometry>
		</visual>
		<visual name="vertical_side_panel-14">
			<origin xyz="0 0 0" />
			<geometry>
				<mesh filename="/home/blake/kitchen-worlds/assets/models/Cupboard/46490/textured_objs/original-3.obj" />/&gt;
			</geometry>
		</visual>
		<visual name="back_panel-15">
			<origin xyz="0 0 0" />
			<geometry>
				<mesh filename="/home/blake/kitchen-worlds/assets/models/Cupboard/46490/textured_objs/original-12.obj" />/&gt;
			</geometry>
		</visual>
		<visual name="bottom_panel-16">
			<origin xyz="0 0 0" />
			<geometry>
				<mesh filename="/home/blake/kitchen-worlds/assets/models/Cupboard/46490/textured_objs/original-10.obj" />/&gt;
			</geometry>
		</visual>
		<visual name="bottom_panel-16">
			<origin xyz="0 0 0" />
			<geometry>
				<mesh filename="/home/blake/kitchen-worlds/assets/models/Cupboard/46490/textured_objs/original-9.obj" />/&gt;
			</geometry>
		</visual>
		<visual name="top_panel-17">
			<origin xyz="0 0 0" />
			<geometry>
				<mesh filename="/home/blake/kitchen-worlds/assets/models/Cupboard/46490/textured_objs/original-16.obj" />/&gt;
			</geometry>
		</visual>
		<visual name="top_panel-17">
			<origin xyz="0 0 0" />
			<geometry>
				<mesh filename="/home/blake/kitchen-worlds/assets/models/Cupboard/46490/textured_objs/original-17.obj" />/&gt;
			</geometry>
		</visual>
		<visual name="frame_horizontal_bar-20">
			<origin xyz="0 0 0" />
			<geometry>
				<mesh filename="/home/blake/kitchen-worlds/assets/models/Cupboard/46490/textured_objs/original-14.obj" />/&gt;
			</geometry>
		</visual>
		<visual name="frame_horizontal_bar-21">
			<origin xyz="0 0 0" />
			<geometry>
				<mesh filename="/home/blake/kitchen-worlds/assets/models/Cupboard/46490/textured_objs/original-11.obj" />/&gt;
			</geometry>
		</visual>
		<visual name="frame_horizontal_bar-22">
			<origin xyz="0 0 0" />
			<geometry>
				<mesh filename="/home/blake/kitchen-worlds/assets/models/Cupboard/46490/textured_objs/original-13.obj" />/&gt;
			</geometry>
		</visual>
		<collision>
			<origin xyz="0 0 0" />
			<geometry>
				<mesh filename="/home/blake/kitchen-worlds/assets/models/Cupboard/46490/textured_objs/original-19.obj" />/&gt;
			</geometry>
		</collision>
		<collision>
			<origin xyz="0 0 0" />
			<geometry>
				<mesh filename="/home/blake/kitchen-worlds/assets/models/Cupboard/46490/textured_objs/original-26.obj" />/&gt;
			</geometry>
		</collision>
		<collision>
			<origin xyz="0 0 0" />
			<geometry>
				<mesh filename="/home/blake/kitchen-worlds/assets/models/Cupboard/46490/textured_objs/original-27.obj" />/&gt;
			</geometry>
		</collision>
		<collision>
			<origin xyz="0 0 0" />
			<geometry>
				<mesh filename="/home/blake/kitchen-worlds/assets/models/Cupboard/46490/textured_objs/original-7.obj" />/&gt;
			</geometry>
		</collision>
		<collision>
			<origin xyz="0 0 0" />
			<geometry>
				<mesh filename="/home/blake/kitchen-worlds/assets/models/Cupboard/46490/textured_objs/original-6.obj" />/&gt;
			</geometry>
		</collision>
		<collision>
			<origin xyz="0 0 0" />
			<geometry>
				<mesh filename="/home/blake/kitchen-worlds/assets/models/Cupboard/46490/textured_objs/original-4.obj" />/&gt;
			</geometry>
		</collision>
		<collision>
			<origin xyz="0 0 0" />
			<geometry>
				<mesh filename="/home/blake/kitchen-worlds/assets/models/Cupboard/46490/textured_objs/original-3.obj" />/&gt;
			</geometry>
		</collision>
		<collision>
			<origin xyz="0 0 0" />
			<geometry>
				<mesh filename="/home/blake/kitchen-worlds/assets/models/Cupboard/46490/textured_objs/original-12.obj" />/&gt;
			</geometry>
		</collision>
		<collision>
			<origin xyz="0 0 0" />
			<geometry>
				<mesh filename="/home/blake/kitchen-worlds/assets/models/Cupboard/46490/textured_objs/original-10.obj" />/&gt;
			</geometry>
		</collision>
		<collision>
			<origin xyz="0 0 0" />
			<geometry>
				<mesh filename="/home/blake/kitchen-worlds/assets/models/Cupboard/46490/textured_objs/original-9.obj" />/&gt;
			</geometry>
		</collision>
		<collision>
			<origin xyz="0 0 0" />
			<geometry>
				<mesh filename="/home/blake/kitchen-worlds/assets/models/Cupboard/46490/textured_objs/original-16.obj" />/&gt;
			</geometry>
		</collision>
		<collision>
			<origin xyz="0 0 0" />
			<geometry>
				<mesh filename="/home/blake/kitchen-worlds/assets/models/Cupboard/46490/textured_objs/original-17.obj" />/&gt;
			</geometry>
		</collision>
		<collision>
			<origin xyz="0 0 0" />
			<geometry>
				<mesh filename="/home/blake/kitchen-worlds/assets/models/Cupboard/46490/textured_objs/original-14.obj" />/&gt;
			</geometry>
		</collision>
		<collision>
			<origin xyz="0 0 0" />
			<geometry>
				<mesh filename="/home/blake/kitchen-worlds/assets/models/Cupboard/46490/textured_objs/original-11.obj" />/&gt;
			</geometry>
		</collision>
		<collision>
			<origin xyz="0 0 0" />
			<geometry>
				<mesh filename="/home/blake/kitchen-worlds/assets/models/Cupboard/46490/textured_objs/original-13.obj" />/&gt;
			</geometry>
		</collision>
	</link>
	<joint name="joint_2" type="fixed">
		<origin rpy="1.570796326794897 0 -1.570796326794897" xyz="0 0 0" />
		<child link="link_2" />
		<parent link="base" />
	</joint>
</robot>