<?xml version='1.0' encoding='utf-8'?>
<robot name="partnet_3c275368d3e30e775517495984cceec">
	<link name="base" />
	<link name="link_0">
		<visual name="cabinet_door_surface-36">
			<origin xyz="-0.6547441727548523 0.3148759999999995 -0.1625649816693806" />
			<geometry>
				<mesh filename="/home/blake/kitchen-worlds/assets/models/_todo/KitchenCounter/33457/textured_objs/original-25.obj" />/&gt;
			</geometry>
		</visual>
		<visual name="handle-37">
			<origin xyz="-0.6547441727548523 0.3148759999999995 -0.1625649816693806" />
			<geometry>
				<mesh filename="/home/blake/kitchen-worlds/assets/models/_todo/KitchenCounter/33457/textured_objs/original-24.obj" />/&gt;
			</geometry>
		</visual>
		<collision>
			<origin xyz="-0.6547441727548523 0.3148759999999995 -0.1625649816693806" />
			<geometry>
				<mesh filename="/home/blake/kitchen-worlds/assets/models/_todo/KitchenCounter/33457/textured_objs/original-25.obj" />/&gt;
			</geometry>
		</collision>
		<collision>
			<origin xyz="-0.6547441727548523 0.3148759999999995 -0.1625649816693806" />
			<geometry>
				<mesh filename="/home/blake/kitchen-worlds/assets/models/_todo/KitchenCounter/33457/textured_objs/original-24.obj" />/&gt;
			</geometry>
		</collision>
	</link>
	<joint name="joint_0" type="revolute">
		<origin xyz="0.6547441727548523 -0.3148759999999995 0.1625649816693806" />
		<axis xyz="0 1 0" />
		<child link="link_0" />
		<parent link="link_3" />
		<limit lower="0.0" upper="1.5707963267948966" effort="10.0" velocity="1.0" />
	</joint>
	<link name="link_1">
		<visual name="drawer_front-53">
			<origin xyz="0 0 0" />
			<geometry>
				<mesh filename="/home/blake/kitchen-worlds/assets/models/_todo/KitchenCounter/33457/textured_objs/original-6.obj" />/&gt;
			</geometry>
		</visual>
		<visual name="drawer_front-53">
			<origin xyz="0 0 0" />
			<geometry>
				<mesh filename="/home/blake/kitchen-worlds/assets/models/_todo/KitchenCounter/33457/textured_objs/new-16.obj" />/&gt;
			</geometry>
		</visual>
		<visual name="drawer_side-54">
			<origin xyz="0 0 0" />
			<geometry>
				<mesh filename="/home/blake/kitchen-worlds/assets/models/_todo/KitchenCounter/33457/textured_objs/new-15.obj" />/&gt;
			</geometry>
		</visual>
		<visual name="drawer_side-55">
			<origin xyz="0 0 0" />
			<geometry>
				<mesh filename="/home/blake/kitchen-worlds/assets/models/_todo/KitchenCounter/33457/textured_objs/new-17.obj" />/&gt;
			</geometry>
		</visual>
		<visual name="drawer_back-56">
			<origin xyz="0 0 0" />
			<geometry>
				<mesh filename="/home/blake/kitchen-worlds/assets/models/_todo/KitchenCounter/33457/textured_objs/new-18.obj" />/&gt;
			</geometry>
		</visual>
		<visual name="drawer_bottom-57">
			<origin xyz="0 0 0" />
			<geometry>
				<mesh filename="/home/blake/kitchen-worlds/assets/models/_todo/KitchenCounter/33457/textured_objs/new-19.obj" />/&gt;
			</geometry>
		</visual>
		<visual name="drawer_bottom-57">
			<origin xyz="0 0 0" />
			<geometry>
				<mesh filename="/home/blake/kitchen-worlds/assets/models/_todo/KitchenCounter/33457/textured_objs/original-31.obj" />/&gt;
			</geometry>
		</visual>
		<visual name="drawer_bottom-57">
			<origin xyz="0 0 0" />
			<geometry>
				<mesh filename="/home/blake/kitchen-worlds/assets/models/_todo/KitchenCounter/33457/textured_objs/original-37.obj" />/&gt;
			</geometry>
		</visual>
		<visual name="drawer_bottom-57">
			<origin xyz="0 0 0" />
			<geometry>
				<mesh filename="/home/blake/kitchen-worlds/assets/models/_todo/KitchenCounter/33457/textured_objs/original-34.obj" />/&gt;
			</geometry>
		</visual>
		<visual name="drawer_bottom-57">
			<origin xyz="0 0 0" />
			<geometry>
				<mesh filename="/home/blake/kitchen-worlds/assets/models/_todo/KitchenCounter/33457/textured_objs/original-28.obj" />/&gt;
			</geometry>
		</visual>
		<visual name="handle-44">
			<origin xyz="0 0 0" />
			<geometry>
				<mesh filename="/home/blake/kitchen-worlds/assets/models/_todo/KitchenCounter/33457/textured_objs/original-9.obj" />/&gt;
			</geometry>
		</visual>
		<visual name="handle-44">
			<origin xyz="0 0 0" />
			<geometry>
				<mesh filename="/home/blake/kitchen-worlds/assets/models/_todo/KitchenCounter/33457/textured_objs/original-8.obj" />/&gt;
			</geometry>
		</visual>
		<collision>
			<origin xyz="0 0 0" />
			<geometry>
				<mesh filename="/home/blake/kitchen-worlds/assets/models/_todo/KitchenCounter/33457/textured_objs/original-6.obj" />/&gt;
			</geometry>
		</collision>
		<collision>
			<origin xyz="0 0 0" />
			<geometry>
				<mesh filename="/home/blake/kitchen-worlds/assets/models/_todo/KitchenCounter/33457/textured_objs/new-16.obj" />/&gt;
			</geometry>
		</collision>
		<collision>
			<origin xyz="0 0 0" />
			<geometry>
				<mesh filename="/home/blake/kitchen-worlds/assets/models/_todo/KitchenCounter/33457/textured_objs/new-15.obj" />/&gt;
			</geometry>
		</collision>
		<collision>
			<origin xyz="0 0 0" />
			<geometry>
				<mesh filename="/home/blake/kitchen-worlds/assets/models/_todo/KitchenCounter/33457/textured_objs/new-17.obj" />/&gt;
			</geometry>
		</collision>
		<collision>
			<origin xyz="0 0 0" />
			<geometry>
				<mesh filename="/home/blake/kitchen-worlds/assets/models/_todo/KitchenCounter/33457/textured_objs/new-18.obj" />/&gt;
			</geometry>
		</collision>
		<collision>
			<origin xyz="0 0 0" />
			<geometry>
				<mesh filename="/home/blake/kitchen-worlds/assets/models/_todo/KitchenCounter/33457/textured_objs/new-19.obj" />/&gt;
			</geometry>
		</collision>
		<collision>
			<origin xyz="0 0 0" />
			<geometry>
				<mesh filename="/home/blake/kitchen-worlds/assets/models/_todo/KitchenCounter/33457/textured_objs/original-31.obj" />/&gt;
			</geometry>
		</collision>
		<collision>
			<origin xyz="0 0 0" />
			<geometry>
				<mesh filename="/home/blake/kitchen-worlds/assets/models/_todo/KitchenCounter/33457/textured_objs/original-37.obj" />/&gt;
			</geometry>
		</collision>
		<collision>
			<origin xyz="0 0 0" />
			<geometry>
				<mesh filename="/home/blake/kitchen-worlds/assets/models/_todo/KitchenCounter/33457/textured_objs/original-34.obj" />/&gt;
			</geometry>
		</collision>
		<collision>
			<origin xyz="0 0 0" />
			<geometry>
				<mesh filename="/home/blake/kitchen-worlds/assets/models/_todo/KitchenCounter/33457/textured_objs/original-28.obj" />/&gt;
			</geometry>
		</collision>
		<collision>
			<origin xyz="0 0 0" />
			<geometry>
				<mesh filename="/home/blake/kitchen-worlds/assets/models/_todo/KitchenCounter/33457/textured_objs/original-9.obj" />/&gt;
			</geometry>
		</collision>
		<collision>
			<origin xyz="0 0 0" />
			<geometry>
				<mesh filename="/home/blake/kitchen-worlds/assets/models/_todo/KitchenCounter/33457/textured_objs/original-8.obj" />/&gt;
			</geometry>
		</collision>
	</link>
	<joint name="joint_1" type="prismatic">
		<origin xyz="0 0 0" />
		<axis xyz="1 0 0" />
		<child link="link_1" />
		<parent link="link_3" />
		<limit lower="0" upper="0.20400000000000018" effort="10.0" velocity="1.0" />
	</joint>
	<link name="link_2">
		<visual name="drawer_front-51">
			<origin xyz="0 0 0" />
			<geometry>
				<mesh filename="/home/blake/kitchen-worlds/assets/models/_todo/KitchenCounter/33457/textured_objs/original-18.obj" />/&gt;
			</geometry>
		</visual>
		<visual name="drawer_front-51">
			<origin xyz="0 0 0" />
			<geometry>
				<mesh filename="/home/blake/kitchen-worlds/assets/models/_todo/KitchenCounter/33457/textured_objs/original-16.obj" />/&gt;
			</geometry>
		</visual>
		<visual name="drawer_bottom-52">
			<origin xyz="0 0 0" />
			<geometry>
				<mesh filename="/home/blake/kitchen-worlds/assets/models/_todo/KitchenCounter/33457/textured_objs/original-19.obj" />/&gt;
			</geometry>
		</visual>
		<visual name="handle-50">
			<origin xyz="0 0 0" />
			<geometry>
				<mesh filename="/home/blake/kitchen-worlds/assets/models/_todo/KitchenCounter/33457/textured_objs/original-17.obj" />/&gt;
			</geometry>
		</visual>
		<collision>
			<origin xyz="0 0 0" />
			<geometry>
				<mesh filename="/home/blake/kitchen-worlds/assets/models/_todo/KitchenCounter/33457/textured_objs/original-18.obj" />/&gt;
			</geometry>
		</collision>
		<collision>
			<origin xyz="0 0 0" />
			<geometry>
				<mesh filename="/home/blake/kitchen-worlds/assets/models/_todo/KitchenCounter/33457/textured_objs/original-16.obj" />/&gt;
			</geometry>
		</collision>
		<collision>
			<origin xyz="0 0 0" />
			<geometry>
				<mesh filename="/home/blake/kitchen-worlds/assets/models/_todo/KitchenCounter/33457/textured_objs/original-19.obj" />/&gt;
			</geometry>
		</collision>
		<collision>
			<origin xyz="0 0 0" />
			<geometry>
				<mesh filename="/home/blake/kitchen-worlds/assets/models/_todo/KitchenCounter/33457/textured_objs/original-17.obj" />/&gt;
			</geometry>
		</collision>
	</link>
	<joint name="joint_2" type="prismatic">
		<origin xyz="0 0 0" />
		<axis xyz="0 0 1" />
		<child link="link_2" />
		<parent link="link_3" />
		<limit lower="0" upper="0.2320000000000002" effort="10.0" velocity="1.0" />
	</joint>
	<link name="link_3">
		<visual name="board-46">
			<origin xyz="0 0 0" />
			<geometry>
				<mesh filename="/home/blake/kitchen-worlds/assets/models/_todo/KitchenCounter/33457/textured_objs/original-20.obj" />/&gt;
			</geometry>
		</visual>
		<visual name="leg-14">
			<origin xyz="0 0 0" />
			<geometry>
				<mesh filename="/home/blake/kitchen-worlds/assets/models/_todo/KitchenCounter/33457/textured_objs/new-0.obj" />/&gt;
			</geometry>
		</visual>
		<visual name="leg-15">
			<origin xyz="0 0 0" />
			<geometry>
				<mesh filename="/home/blake/kitchen-worlds/assets/models/_todo/KitchenCounter/33457/textured_objs/new-1.obj" />/&gt;
			</geometry>
		</visual>
		<visual name="leg-16">
			<origin xyz="0 0 0" />
			<geometry>
				<mesh filename="/home/blake/kitchen-worlds/assets/models/_todo/KitchenCounter/33457/textured_objs/new-2.obj" />/&gt;
			</geometry>
		</visual>
		<visual name="leg-17">
			<origin xyz="0 0 0" />
			<geometry>
				<mesh filename="/home/blake/kitchen-worlds/assets/models/_todo/KitchenCounter/33457/textured_objs/new-3.obj" />/&gt;
			</geometry>
		</visual>
		<visual name="leg-18">
			<origin xyz="0 0 0" />
			<geometry>
				<mesh filename="/home/blake/kitchen-worlds/assets/models/_todo/KitchenCounter/33457/textured_objs/original-36.obj" />/&gt;
			</geometry>
		</visual>
		<visual name="leg-19">
			<origin xyz="0 0 0" />
			<geometry>
				<mesh filename="/home/blake/kitchen-worlds/assets/models/_todo/KitchenCounter/33457/textured_objs/original-33.obj" />/&gt;
			</geometry>
		</visual>
		<visual name="leg-20">
			<origin xyz="0 0 0" />
			<geometry>
				<mesh filename="/home/blake/kitchen-worlds/assets/models/_todo/KitchenCounter/33457/textured_objs/original-30.obj" />/&gt;
			</geometry>
		</visual>
		<visual name="leg-21">
			<origin xyz="0 0 0" />
			<geometry>
				<mesh filename="/home/blake/kitchen-worlds/assets/models/_todo/KitchenCounter/33457/textured_objs/original-27.obj" />/&gt;
			</geometry>
		</visual>
		<visual name="back_panel-25">
			<origin xyz="0 0 0" />
			<geometry>
				<mesh filename="/home/blake/kitchen-worlds/assets/models/_todo/KitchenCounter/33457/textured_objs/new-4.obj" />/&gt;
			</geometry>
		</visual>
		<visual name="back_panel-25">
			<origin xyz="0 0 0" />
			<geometry>
				<mesh filename="/home/blake/kitchen-worlds/assets/models/_todo/KitchenCounter/33457/textured_objs/original-38.obj" />/&gt;
			</geometry>
		</visual>
		<visual name="back_panel-25">
			<origin xyz="0 0 0" />
			<geometry>
				<mesh filename="/home/blake/kitchen-worlds/assets/models/_todo/KitchenCounter/33457/textured_objs/original-4.obj" />/&gt;
			</geometry>
		</visual>
		<visual name="back_panel-25">
			<origin xyz="0 0 0" />
			<geometry>
				<mesh filename="/home/blake/kitchen-worlds/assets/models/_todo/KitchenCounter/33457/textured_objs/new-8.obj" />/&gt;
			</geometry>
		</visual>
		<visual name="vertical_side_panel-26">
			<origin xyz="0 0 0" />
			<geometry>
				<mesh filename="/home/blake/kitchen-worlds/assets/models/_todo/KitchenCounter/33457/textured_objs/original-1.obj" />/&gt;
			</geometry>
		</visual>
		<visual name="vertical_side_panel-27">
			<origin xyz="0 0 0" />
			<geometry>
				<mesh filename="/home/blake/kitchen-worlds/assets/models/_todo/KitchenCounter/33457/textured_objs/original-3.obj" />/&gt;
			</geometry>
		</visual>
		<visual name="vertical_side_panel-28">
			<origin xyz="0 0 0" />
			<geometry>
				<mesh filename="/home/blake/kitchen-worlds/assets/models/_todo/KitchenCounter/33457/textured_objs/new-12.obj" />/&gt;
			</geometry>
		</visual>
		<visual name="vertical_side_panel-29">
			<origin xyz="0 0 0" />
			<geometry>
				<mesh filename="/home/blake/kitchen-worlds/assets/models/_todo/KitchenCounter/33457/textured_objs/new-13.obj" />/&gt;
			</geometry>
		</visual>
		<visual name="vertical_front_panel-30">
			<origin xyz="0 0 0" />
			<geometry>
				<mesh filename="/home/blake/kitchen-worlds/assets/models/_todo/KitchenCounter/33457/textured_objs/new-11.obj" />/&gt;
			</geometry>
		</visual>
		<visual name="vertical_front_panel-34">
			<origin xyz="0 0 0" />
			<geometry>
				<mesh filename="/home/blake/kitchen-worlds/assets/models/_todo/KitchenCounter/33457/textured_objs/original-11.obj" />/&gt;
			</geometry>
		</visual>
		<visual name="vertical_front_panel-35">
			<origin xyz="0 0 0" />
			<geometry>
				<mesh filename="/home/blake/kitchen-worlds/assets/models/_todo/KitchenCounter/33457/textured_objs/original-2.obj" />/&gt;
			</geometry>
		</visual>
		<visual name="base_side_panel-40">
			<origin xyz="0 0 0" />
			<geometry>
				<mesh filename="/home/blake/kitchen-worlds/assets/models/_todo/KitchenCounter/33457/textured_objs/new-6.obj" />/&gt;
			</geometry>
		</visual>
		<visual name="base_side_panel-41">
			<origin xyz="0 0 0" />
			<geometry>
				<mesh filename="/home/blake/kitchen-worlds/assets/models/_todo/KitchenCounter/33457/textured_objs/new-7.obj" />/&gt;
			</geometry>
		</visual>
		<visual name="base_side_panel-42">
			<origin xyz="0 0 0" />
			<geometry>
				<mesh filename="/home/blake/kitchen-worlds/assets/models/_todo/KitchenCounter/33457/textured_objs/new-5.obj" />/&gt;
			</geometry>
		</visual>
		<visual name="bottom_panel-48">
			<origin xyz="0 0 0" />
			<geometry>
				<mesh filename="/home/blake/kitchen-worlds/assets/models/_todo/KitchenCounter/33457/textured_objs/new-10.obj" />/&gt;
			</geometry>
		</visual>
		<visual name="bottom_panel-48">
			<origin xyz="0 0 0" />
			<geometry>
				<mesh filename="/home/blake/kitchen-worlds/assets/models/_todo/KitchenCounter/33457/textured_objs/new-9.obj" />/&gt;
			</geometry>
		</visual>
		<visual name="bottom_panel-48">
			<origin xyz="0 0 0" />
			<geometry>
				<mesh filename="/home/blake/kitchen-worlds/assets/models/_todo/KitchenCounter/33457/textured_objs/new-14.obj" />/&gt;
			</geometry>
		</visual>
		<visual name="bottom_panel-48">
			<origin xyz="0 0 0" />
			<geometry>
				<mesh filename="/home/blake/kitchen-worlds/assets/models/_todo/KitchenCounter/33457/textured_objs/original-23.obj" />/&gt;
			</geometry>
		</visual>
		<collision>
			<origin xyz="0 0 0" />
			<geometry>
				<mesh filename="/home/blake/kitchen-worlds/assets/models/_todo/KitchenCounter/33457/textured_objs/original-20.obj" />/&gt;
			</geometry>
		</collision>
		<collision>
			<origin xyz="0 0 0" />
			<geometry>
				<mesh filename="/home/blake/kitchen-worlds/assets/models/_todo/KitchenCounter/33457/textured_objs/new-0.obj" />/&gt;
			</geometry>
		</collision>
		<collision>
			<origin xyz="0 0 0" />
			<geometry>
				<mesh filename="/home/blake/kitchen-worlds/assets/models/_todo/KitchenCounter/33457/textured_objs/new-1.obj" />/&gt;
			</geometry>
		</collision>
		<collision>
			<origin xyz="0 0 0" />
			<geometry>
				<mesh filename="/home/blake/kitchen-worlds/assets/models/_todo/KitchenCounter/33457/textured_objs/new-2.obj" />/&gt;
			</geometry>
		</collision>
		<collision>
			<origin xyz="0 0 0" />
			<geometry>
				<mesh filename="/home/blake/kitchen-worlds/assets/models/_todo/KitchenCounter/33457/textured_objs/new-3.obj" />/&gt;
			</geometry>
		</collision>
		<collision>
			<origin xyz="0 0 0" />
			<geometry>
				<mesh filename="/home/blake/kitchen-worlds/assets/models/_todo/KitchenCounter/33457/textured_objs/original-36.obj" />/&gt;
			</geometry>
		</collision>
		<collision>
			<origin xyz="0 0 0" />
			<geometry>
				<mesh filename="/home/blake/kitchen-worlds/assets/models/_todo/KitchenCounter/33457/textured_objs/original-33.obj" />/&gt;
			</geometry>
		</collision>
		<collision>
			<origin xyz="0 0 0" />
			<geometry>
				<mesh filename="/home/blake/kitchen-worlds/assets/models/_todo/KitchenCounter/33457/textured_objs/original-30.obj" />/&gt;
			</geometry>
		</collision>
		<collision>
			<origin xyz="0 0 0" />
			<geometry>
				<mesh filename="/home/blake/kitchen-worlds/assets/models/_todo/KitchenCounter/33457/textured_objs/original-27.obj" />/&gt;
			</geometry>
		</collision>
		<collision>
			<origin xyz="0 0 0" />
			<geometry>
				<mesh filename="/home/blake/kitchen-worlds/assets/models/_todo/KitchenCounter/33457/textured_objs/new-4.obj" />/&gt;
			</geometry>
		</collision>
		<collision>
			<origin xyz="0 0 0" />
			<geometry>
				<mesh filename="/home/blake/kitchen-worlds/assets/models/_todo/KitchenCounter/33457/textured_objs/original-38.obj" />/&gt;
			</geometry>
		</collision>
		<collision>
			<origin xyz="0 0 0" />
			<geometry>
				<mesh filename="/home/blake/kitchen-worlds/assets/models/_todo/KitchenCounter/33457/textured_objs/original-4.obj" />/&gt;
			</geometry>
		</collision>
		<collision>
			<origin xyz="0 0 0" />
			<geometry>
				<mesh filename="/home/blake/kitchen-worlds/assets/models/_todo/KitchenCounter/33457/textured_objs/new-8.obj" />/&gt;
			</geometry>
		</collision>
		<collision>
			<origin xyz="0 0 0" />
			<geometry>
				<mesh filename="/home/blake/kitchen-worlds/assets/models/_todo/KitchenCounter/33457/textured_objs/original-1.obj" />/&gt;
			</geometry>
		</collision>
		<collision>
			<origin xyz="0 0 0" />
			<geometry>
				<mesh filename="/home/blake/kitchen-worlds/assets/models/_todo/KitchenCounter/33457/textured_objs/original-3.obj" />/&gt;
			</geometry>
		</collision>
		<collision>
			<origin xyz="0 0 0" />
			<geometry>
				<mesh filename="/home/blake/kitchen-worlds/assets/models/_todo/KitchenCounter/33457/textured_objs/new-12.obj" />/&gt;
			</geometry>
		</collision>
		<collision>
			<origin xyz="0 0 0" />
			<geometry>
				<mesh filename="/home/blake/kitchen-worlds/assets/models/_todo/KitchenCounter/33457/textured_objs/new-13.obj" />/&gt;
			</geometry>
		</collision>
		<collision>
			<origin xyz="0 0 0" />
			<geometry>
				<mesh filename="/home/blake/kitchen-worlds/assets/models/_todo/KitchenCounter/33457/textured_objs/new-11.obj" />/&gt;
			</geometry>
		</collision>
		<collision>
			<origin xyz="0 0 0" />
			<geometry>
				<mesh filename="/home/blake/kitchen-worlds/assets/models/_todo/KitchenCounter/33457/textured_objs/original-11.obj" />/&gt;
			</geometry>
		</collision>
		<collision>
			<origin xyz="0 0 0" />
			<geometry>
				<mesh filename="/home/blake/kitchen-worlds/assets/models/_todo/KitchenCounter/33457/textured_objs/original-2.obj" />/&gt;
			</geometry>
		</collision>
		<collision>
			<origin xyz="0 0 0" />
			<geometry>
				<mesh filename="/home/blake/kitchen-worlds/assets/models/_todo/KitchenCounter/33457/textured_objs/new-6.obj" />/&gt;
			</geometry>
		</collision>
		<collision>
			<origin xyz="0 0 0" />
			<geometry>
				<mesh filename="/home/blake/kitchen-worlds/assets/models/_todo/KitchenCounter/33457/textured_objs/new-7.obj" />/&gt;
			</geometry>
		</collision>
		<collision>
			<origin xyz="0 0 0" />
			<geometry>
				<mesh filename="/home/blake/kitchen-worlds/assets/models/_todo/KitchenCounter/33457/textured_objs/new-5.obj" />/&gt;
			</geometry>
		</collision>
		<collision>
			<origin xyz="0 0 0" />
			<geometry>
				<mesh filename="/home/blake/kitchen-worlds/assets/models/_todo/KitchenCounter/33457/textured_objs/new-10.obj" />/&gt;
			</geometry>
		</collision>
		<collision>
			<origin xyz="0 0 0" />
			<geometry>
				<mesh filename="/home/blake/kitchen-worlds/assets/models/_todo/KitchenCounter/33457/textured_objs/new-9.obj" />/&gt;
			</geometry>
		</collision>
		<collision>
			<origin xyz="0 0 0" />
			<geometry>
				<mesh filename="/home/blake/kitchen-worlds/assets/models/_todo/KitchenCounter/33457/textured_objs/new-14.obj" />/&gt;
			</geometry>
		</collision>
		<collision>
			<origin xyz="0 0 0" />
			<geometry>
				<mesh filename="/home/blake/kitchen-worlds/assets/models/_todo/KitchenCounter/33457/textured_objs/original-23.obj" />/&gt;
			</geometry>
		</collision>
	</link>
	<joint name="joint_3" type="fixed">
		<origin rpy="1.570796326794897 0 -1.570796326794897" xyz="0 0 0" />
		<child link="link_3" />
		<parent link="base" />
	</joint>
</robot>