<?xml version='1.0' encoding='utf-8'?>
<robot name="partnet_dfc438f9-f828-4fc0-a098-3fd60da79acb">
	<link name="base" />
	<link name="link_0">
		<visual name="lens-1">
			<origin xyz="0.0039693170910203406 0.03559881267303164 0" />
			<geometry>
				<mesh filename="/home/blake/kitchen-worlds/assets/models/Camera/102873/textured_objs/original-7.obj" />/&gt;
			</geometry>
		</visual>
		<visual name="lens-1">
			<origin xyz="0.0039693170910203406 0.03559881267303164 0" />
			<geometry>
				<mesh filename="/home/blake/kitchen-worlds/assets/models/Camera/102873/textured_objs/original-6.obj" />/&gt;
			</geometry>
		</visual>
		<visual name="lens-1">
			<origin xyz="0.0039693170910203406 0.03559881267303164 0" />
			<geometry>
				<mesh filename="/home/blake/kitchen-worlds/assets/models/Camera/102873/textured_objs/original-5.obj" />/&gt;
			</geometry>
		</visual>
		<collision>
			<origin xyz="0.0039693170910203406 0.03559881267303164 0" />
			<geometry>
				<mesh filename="/home/blake/kitchen-worlds/assets/models/Camera/102873/textured_objs/original-7.obj" />/&gt;
			</geometry>
		</collision>
		<collision>
			<origin xyz="0.0039693170910203406 0.03559881267303164 0" />
			<geometry>
				<mesh filename="/home/blake/kitchen-worlds/assets/models/Camera/102873/textured_objs/original-6.obj" />/&gt;
			</geometry>
		</collision>
		<collision>
			<origin xyz="0.0039693170910203406 0.03559881267303164 0" />
			<geometry>
				<mesh filename="/home/blake/kitchen-worlds/assets/models/Camera/102873/textured_objs/original-5.obj" />/&gt;
			</geometry>
		</collision>
	</link>
	<joint name="joint_0" type="continuous">
		<origin xyz="-0.0039693170910203406 -0.03559881267303164 0" />
		<axis xyz="0 0 1" />
		<child link="link_0" />
		<parent link="link_3" />
	</joint>
	<link name="link_1">
		<visual name="button-2">
			<origin xyz="0 0 0" />
			<geometry>
				<mesh filename="/home/blake/kitchen-worlds/assets/models/Camera/102873/textured_objs/original-11.obj" />/&gt;
			</geometry>
		</visual>
		<collision>
			<origin xyz="0 0 0" />
			<geometry>
				<mesh filename="/home/blake/kitchen-worlds/assets/models/Camera/102873/textured_objs/original-11.obj" />/&gt;
			</geometry>
		</collision>
	</link>
	<joint name="joint_1" type="prismatic">
		<origin xyz="0 0 0" />
		<axis xyz="0 -1 0" />
		<child link="link_1" />
		<parent link="link_3" />
		<limit lower="0" upper="0.03600000000000003" effort="10.0" velocity="1.0" />
	</joint>
	<link name="link_2">
		<visual name="button-3">
			<origin xyz="0 0 0" />
			<geometry>
				<mesh filename="/home/blake/kitchen-worlds/assets/models/Camera/102873/textured_objs/original-10.obj" />/&gt;
			</geometry>
		</visual>
		<collision>
			<origin xyz="0 0 0" />
			<geometry>
				<mesh filename="/home/blake/kitchen-worlds/assets/models/Camera/102873/textured_objs/original-10.obj" />/&gt;
			</geometry>
		</collision>
	</link>
	<joint name="joint_2" type="prismatic">
		<origin xyz="0 0 0" />
		<axis xyz="0 -1 0" />
		<child link="link_2" />
		<parent link="link_3" />
		<limit lower="0" upper="0.040000000000000036" effort="10.0" velocity="1.0" />
	</joint>
	<link name="link_3">
		<visual name="base_body-4">
			<origin xyz="0 0 0" />
			<geometry>
				<mesh filename="/home/blake/kitchen-worlds/assets/models/Camera/102873/textured_objs/original-4.obj" />/&gt;
			</geometry>
		</visual>
		<visual name="base_body-4">
			<origin xyz="0 0 0" />
			<geometry>
				<mesh filename="/home/blake/kitchen-worlds/assets/models/Camera/102873/textured_objs/original-3.obj" />/&gt;
			</geometry>
		</visual>
		<visual name="base_body-4">
			<origin xyz="0 0 0" />
			<geometry>
				<mesh filename="/home/blake/kitchen-worlds/assets/models/Camera/102873/textured_objs/original-2.obj" />/&gt;
			</geometry>
		</visual>
		<visual name="base_body-4">
			<origin xyz="0 0 0" />
			<geometry>
				<mesh filename="/home/blake/kitchen-worlds/assets/models/Camera/102873/textured_objs/original-8.obj" />/&gt;
			</geometry>
		</visual>
		<visual name="base_body-4">
			<origin xyz="0 0 0" />
			<geometry>
				<mesh filename="/home/blake/kitchen-worlds/assets/models/Camera/102873/textured_objs/original-9.obj" />/&gt;
			</geometry>
		</visual>
		<visual name="base_body-4">
			<origin xyz="0 0 0" />
			<geometry>
				<mesh filename="/home/blake/kitchen-worlds/assets/models/Camera/102873/textured_objs/original-12.obj" />/&gt;
			</geometry>
		</visual>
		<visual name="base_body-4">
			<origin xyz="0 0 0" />
			<geometry>
				<mesh filename="/home/blake/kitchen-worlds/assets/models/Camera/102873/textured_objs/original-1.obj" />/&gt;
			</geometry>
		</visual>
		<collision>
			<origin xyz="0 0 0" />
			<geometry>
				<mesh filename="/home/blake/kitchen-worlds/assets/models/Camera/102873/textured_objs/original-4.obj" />/&gt;
			</geometry>
		</collision>
		<collision>
			<origin xyz="0 0 0" />
			<geometry>
				<mesh filename="/home/blake/kitchen-worlds/assets/models/Camera/102873/textured_objs/original-3.obj" />/&gt;
			</geometry>
		</collision>
		<collision>
			<origin xyz="0 0 0" />
			<geometry>
				<mesh filename="/home/blake/kitchen-worlds/assets/models/Camera/102873/textured_objs/original-2.obj" />/&gt;
			</geometry>
		</collision>
		<collision>
			<origin xyz="0 0 0" />
			<geometry>
				<mesh filename="/home/blake/kitchen-worlds/assets/models/Camera/102873/textured_objs/original-8.obj" />/&gt;
			</geometry>
		</collision>
		<collision>
			<origin xyz="0 0 0" />
			<geometry>
				<mesh filename="/home/blake/kitchen-worlds/assets/models/Camera/102873/textured_objs/original-9.obj" />/&gt;
			</geometry>
		</collision>
		<collision>
			<origin xyz="0 0 0" />
			<geometry>
				<mesh filename="/home/blake/kitchen-worlds/assets/models/Camera/102873/textured_objs/original-12.obj" />/&gt;
			</geometry>
		</collision>
		<collision>
			<origin xyz="0 0 0" />
			<geometry>
				<mesh filename="/home/blake/kitchen-worlds/assets/models/Camera/102873/textured_objs/original-1.obj" />/&gt;
			</geometry>
		</collision>
	</link>
	<joint name="joint_3" type="fixed">
		<origin rpy="1.570796326794897 0 -1.570796326794897" xyz="0 0 0" />
		<child link="link_3" />
		<parent link="base" />
	</joint>
</robot>